File: Alban repo/Quiz 1/suction cup instron tests/july-2020-time-vs-viscosity_raw-data/d30e10-01-10-5-80grit-2800kg-test1.raw
Operator: 1

Date,Time,Specimen#
07/07/20,12:31:56,1

---------------------------------------


Area (mm^2):,      1.00,Flat,     25.40,     25.40,     25.40
Gage Len (mm):,     25.40


LOAD (N),STRAIN 1 (mm),STRAIN 2 (mm),STRESS (MPa),POSITION (mm),TIME (min)
       5.9,      0.000,      0.000,         0,      0.3415,      0.0005
       9.5,      0.000,      0.000,         0,      0.6831,      0.0010
      13.1,      0.000,      0.000,         0,      1.0247,      0.0016
      16.4,      0.000,      0.000,         0,      1.3664,      0.0021
      19.5,      0.000,      0.000,         0,      1.7083,      0.0026
      22.3,      0.000,      0.000,         0,      2.0501,      0.0031
      24.9,      0.000,      0.000,         0,      2.3921,      0.0036
      27.3,      0.000,      0.000,         0,      2.7341,      0.0042
      28.6,      0.000,      0.000,         0,      3.0766,      0.0047
      27.9,      0.000,      0.000,         0,      3.4184,      0.0052
      27.0,      0.000,      0.000,         0,      3.7611,      0.0057
      27.8,      0.000,      0.000,         0,      4.1030,      0.0063
      28.2,      0.000,      0.000,         0,      4.4454,      0.0068
      27.8,      0.000,      0.000,         0,      4.7879,      0.0073
      27.8,      0.000,      0.000,         0,      5.1304,      0.0078
      28.2,      0.000,      0.000,         0,      5.4730,      0.0083
      28.2,      0.000,      0.000,         0,      5.8156,      0.0089
      28.1,      0.000,      0.000,         0,      6.1583,      0.0094
      28.3,      0.000,      0.000,         0,      6.5011,      0.0099
      28.4,      0.000,      0.000,         0,      6.8438,      0.0104
      28.5,      0.000,      0.000,         0,      7.1866,      0.0109
      28.5,      0.000,      0.000,         0,      7.5294,      0.0115
      28.6,      0.000,      0.000,         0,      7.8723,      0.0120
      28.7,      0.000,      0.000,         0,      8.3866,      0.0127
      28.7,      0.000,      0.000,         0,      8.7510,      0.0133
      28.9,      0.000,      0.000,         0,      9.1154,      0.0139
      28.9,      0.000,      0.000,         0,      9.4587,      0.0144
      28.5,      0.000,      0.000,         0,      9.7099,      0.0150
      28.5,      0.000,      0.000,         0,      9.8827,      0.0155
      28.9,      0.000,      0.000,         0,     10.0036,      0.0161
      29.0,      0.000,      0.000,         0,     10.0886,      0.0166
      28.7,      0.000,      0.000,         0,     10.1483,      0.0172
      28.9,      0.000,      0.000,         0,     10.1905,      0.0177
      29.0,      0.000,      0.000,         0,     10.2203,      0.0183
      28.9,      0.000,      0.000,         0,     10.2413,      0.0188
      28.8,      0.000,      0.000,         0,     10.2563,      0.0194
      28.9,      0.000,      0.000,         0,     10.2669,      0.0199
      28.9,      0.000,      0.000,         0,     10.2745,      0.0205
      28.8,      0.000,      0.000,         0,     10.2798,      0.0210
      28.8,      0.000,      0.000,         0,     10.2838,      0.0216
      28.9,      0.000,      0.000,         0,     10.2863,      0.0222
      28.8,      0.000,      0.000,         0,     10.2882,      0.0227
      28.8,      0.000,      0.000,         0,     10.2896,      0.0233
      28.8,      0.000,      0.000,         0,     10.2908,      0.0238
      28.8,      0.000,      0.000,         0,     10.2918,      0.0244
      28.8,      0.000,      0.000,         0,     10.2925,      0.0249
      28.8,      0.000,      0.000,         0,     10.2929,      0.0255
      28.8,      0.000,      0.000,         0,     10.2933,      0.0260
      28.8,      0.000,      0.000,         0,     10.2938,      0.0266
      28.7,      0.000,      0.000,         0,     10.2942,      0.0271
      28.7,      0.000,      0.000,         0,     10.2943,      0.0277
      28.7,      0.000,      0.000,         0,     10.2943,      0.0282
      28.7,      0.000,      0.000,         0,     10.2943,      0.0288
      28.7,      0.000,      0.000,         0,     10.2943,      0.0293
      28.7,      0.000,      0.000,         0,     10.2943,      0.0299
      28.7,      0.000,      0.000,         0,     10.2943,      0.0305
      28.7,      0.000,      0.000,         0,     10.2943,      0.0310
      28.7,      0.000,      0.000,         0,     10.2943,      0.0316
      28.7,      0.000,      0.000,         0,     10.2943,      0.0321
      28.7,      0.000,      0.000,         0,     10.2944,      0.0327
      28.6,      0.000,      0.000,         0,     10.2944,      0.0332
      28.6,      0.000,      0.000,         0,     10.2944,      0.0338
      28.6,      0.000,      0.000,         0,     10.2944,      0.0343
      28.6,      0.000,      0.000,         0,     10.2944,      0.0349
      28.6,      0.000,      0.000,         0,     10.2944,      0.0354
      28.6,      0.000,      0.000,         0,     10.2944,      0.0360
      28.6,      0.000,      0.000,         0,     10.2944,      0.0365
      28.6,      0.000,      0.000,         0,     10.2944,      0.0371
      28.6,      0.000,      0.000,         0,     10.2945,      0.0376
      28.5,      0.000,      0.000,         0,     10.2945,      0.0382
      28.5,      0.000,      0.000,         0,     10.2945,      0.0388
      28.5,      0.000,      0.000,         0,     10.2945,      0.0393
      28.5,      0.000,      0.000,         0,     10.2945,      0.0399
      28.5,      0.000,      0.000,         0,     10.2945,      0.0404
      28.5,      0.000,      0.000,         0,     10.2945,      0.0410
      28.5,      0.000,      0.000,         0,     10.2945,      0.0415
      28.5,      0.000,      0.000,         0,     10.2945,      0.0421
      28.5,      0.000,      0.000,         0,     10.2945,      0.0426
      28.5,      0.000,      0.000,         0,     10.2945,      0.0432
      28.5,      0.000,      0.000,         0,     10.2945,      0.0437
      28.5,      0.000,      0.000,         0,     10.2945,      0.0443
      28.5,      0.000,      0.000,         0,     10.2946,      0.0448
      28.5,      0.000,      0.000,         0,     10.2946,      0.0454
      28.4,      0.000,      0.000,         0,     10.2946,      0.0459
      28.3,      0.000,      0.000,         0,     10.2946,      0.0465
      28.3,      0.000,      0.000,         0,     10.2946,      0.0471
      28.2,      0.000,      0.000,         0,     10.2946,      0.0476
      14.9,      0.000,      0.000,         0,     10.2946,      0.0482
       0.5,      0.000,      0.000,         0,     10.2946,      0.0487
      -0.1,      0.000,      0.000,         0,     10.2947,      0.0493
       0.0,      0.000,      0.000,         0,     10.2947,      0.0498
       0.0,      0.000,      0.000,         0,     10.2947,      0.0504
       0.0,      0.000,      0.000,         0,     10.2947,      0.0509
       0.1,      0.000,      0.000,         0,     10.2947,      0.0515
       0.0,      0.000,      0.000,         0,     10.2947,      0.0520
       0.1,      0.000,      0.000,         0,     10.2947,      0.0526
       0.0,      0.000,      0.000,         0,     10.2947,      0.0531
       0.0,      0.000,      0.000,         0,     10.2947,      0.0537
       0.0,      0.000,      0.000,         0,     10.2947,      0.0542
       0.0,      0.000,      0.000,         0,     10.2947,      0.0548
       0.0,      0.000,      0.000,         0,     10.2947,      0.0554
       0.0,      0.000,      0.000,         0,     10.2948,      0.0559
       0.0,      0.000,      0.000,         0,     10.2948,      0.0565
       0.0,      0.000,      0.000,         0,     10.2948,      0.0570
       0.0,      0.000,      0.000,         0,     10.2948,      0.0576
       0.0,      0.000,      0.000,         0,     10.2948,      0.0581
       0.0,      0.000,      0.000,         0,     10.2948,      0.0587
       0.0,      0.000,      0.000,         0,     10.2949,      0.0592
       0.0,      0.000,      0.000,         0,     10.2949,      0.0598
       0.0,      0.000,      0.000,         0,     10.2949,      0.0603
       0.0,      0.000,      0.000,         0,     10.2949,      0.0609
       0.0,      0.000,      0.000,         0,     10.2950,      0.0614
       0.0,      0.000,      0.000,         0,     10.2950,      0.0620
       0.0,      0.000,      0.000,         0,     10.2950,      0.0625
       0.0,      0.000,      0.000,         0,     10.2951,      0.0631
       0.0,      0.000,      0.000,         0,     10.2952,      0.0637
       0.0,      0.000,      0.000,         0,     10.2954,      0.0642
       0.0,      0.000,      0.000,         0,     10.2957,      0.0648
       0.0,      0.000,      0.000,         0,     10.2960,      0.0653
       0.0,      0.000,      0.000,         0,     10.2963,      0.0659
       0.0,      0.000,      0.000,         0,     10.2965,      0.0664
       0.0,      0.000,      0.000,         0,     10.2966,      0.0670
       0.0,      0.000,      0.000,         0,     10.2966,      0.0675
       0.0,      0.000,      0.000,         0,     10.2965,      0.0681
       0.0,      0.000,      0.000,         0,     10.2965,      0.0686
       0.0,      0.000,      0.000,         0,     10.2965,      0.0692
       0.0,      0.000,      0.000,         0,     10.2965,      0.0697
       0.0,      0.000,      0.000,         0,     10.2965,      0.0703
       0.0,      0.000,      0.000,         0,     10.2965,      0.0708
       0.0,      0.000,      0.000,         0,     10.2965,      0.0714
       0.0,      0.000,      0.000,         0,     10.2965,      0.0720
       0.0,      0.000,      0.000,         0,     10.2965,      0.0725
       0.0,      0.000,      0.000,         0,     10.2965,      0.0731
       0.0,      0.000,      0.000,         0,     10.2966,      0.0736
       0.0,      0.000,      0.000,         0,     10.2965,      0.0742
       0.0,      0.000,      0.000,         0,     10.2965,      0.0747
       0.0,      0.000,      0.000,         0,     10.2966,      0.0753
       0.0,      0.000,      0.000,         0,     10.2965,      0.0758
       0.0,      0.000,      0.000,         0,     10.2965,      0.0764
       0.0,      0.000,      0.000,         0,     10.2965,      0.0769
       0.0,      0.000,      0.000,         0,     10.2966,      0.0775
       0.0,      0.000,      0.000,         0,     10.2965,      0.0780
       0.0,      0.000,      0.000,         0,     10.2965,      0.0786
       0.0,      0.000,      0.000,         0,     10.2966,      0.0792
       0.0,      0.000,      0.000,         0,     10.2966,      0.0797
       0.0,      0.000,      0.000,         0,     10.2965,      0.0803
       0.0,      0.000,      0.000,         0,     10.2965,      0.0808
       0.0,      0.000,      0.000,         0,     10.2966,      0.0814
       0.0,      0.000,      0.000,         0,     10.2965,      0.0819
       0.0,      0.000,      0.000,         0,     10.2965,      0.0825
       0.0,      0.000,      0.000,         0,     10.2966,      0.0830
       0.0,      0.000,      0.000,         0,     10.2965,      0.0836
       0.0,      0.000,      0.000,         0,     10.2965,      0.0841
       0.0,      0.000,      0.000,         0,     10.2965,      0.0847
       0.0,      0.000,      0.000,         0,     10.2965,      0.0852
       0.0,      0.000,      0.000,         0,     10.2965,      0.0858
       0.0,      0.000,      0.000,         0,     10.2965,      0.0863
       0.0,      0.000,      0.000,         0,     10.2965,      0.0869
       0.0,      0.000,      0.000,         0,     10.2965,      0.0875
       0.0,      0.000,      0.000,         0,     10.2965,      0.0880
       0.0,      0.000,      0.000,         0,     10.2965,      0.0886
       0.0,      0.000,      0.000,         0,     10.2965,      0.0891
       0.0,      0.000,      0.000,         0,     10.2964,      0.0897
       0.0,      0.000,      0.000,         0,     10.2965,      0.0902
       0.0,      0.000,      0.000,         0,     10.2965,      0.0908
       0.0,      0.000,      0.000,         0,     10.2965,      0.0913
       0.0,      0.000,      0.000,         0,     10.2965,      0.0919
       0.0,      0.000,      0.000,         0,     10.2965,      0.0924
       0.0,      0.000,      0.000,         0,     10.2965,      0.0930
       0.0,      0.000,      0.000,         0,     10.2965,      0.0935
       0.0,      0.000,      0.000,         0,     10.2965,      0.0941
       0.0,      0.000,      0.000,         0,     10.2965,      0.0946
       0.0,      0.000,      0.000,         0,     10.2964,      0.0952
       0.0,      0.000,      0.000,         0,     10.2964,      0.0958
       0.0,      0.000,      0.000,         0,     10.2965,      0.0963
       0.0,      0.000,      0.000,         0,     10.2965,      0.0969
       0.0,      0.000,      0.000,         0,     10.2965,      0.0974
       0.0,      0.000,      0.000,         0,     10.2965,      0.0980
       0.0,      0.000,      0.000,         0,     10.2965,      0.0985
       0.0,      0.000,      0.000,         0,     10.2965,      0.0991
       0.0,      0.000,      0.000,         0,     10.2965,      0.0996
       0.0,      0.000,      0.000,         0,     10.2965,      0.1002
       0.0,      0.000,      0.000,         0,     10.2965,      0.1007
       0.0,      0.000,      0.000,         0,     10.2964,      0.1013
       0.0,      0.000,      0.000,         0,     10.2965,      0.1018
       0.0,      0.000,      0.000,         0,     10.2965,      0.1024
       0.0,      0.000,      0.000,         0,     10.2965,      0.1029
       0.0,      0.000,      0.000,         0,     10.2965,      0.1035
       0.0,      0.000,      0.000,         0,     10.2965,      0.1041
       0.0,      0.000,      0.000,         0,     10.2965,      0.1046
       0.0,      0.000,      0.000,         0,     10.2964,      0.1052
       0.0,      0.000,      0.000,         0,     10.2965,      0.1057
       0.0,      0.000,      0.000,         0,     10.2964,      0.1063
       0.0,      0.000,      0.000,         0,     10.2965,      0.1068
       0.0,      0.000,      0.000,         0,     10.2965,      0.1074
       0.0,      0.000,      0.000,         0,     10.2965,      0.1079
       0.0,      0.000,      0.000,         0,     10.2965,      0.1085
       0.0,      0.000,      0.000,         0,     10.2965,      0.1090
       0.0,      0.000,      0.000,         0,     10.2965,      0.1096
       0.0,      0.000,      0.000,         0,     10.2965,      0.1101
       0.0,      0.000,      0.000,         0,     10.2965,      0.1107
       0.0,      0.000,      0.000,         0,     10.2965,      0.1112
       0.0,      0.000,      0.000,         0,     10.2965,      0.1118