File: Alban repo/Quiz 1/suction cup instron tests/july-2020-time-vs-viscosity_raw-data/d30e10-01-10-1-80grit-2800kg-test1.raw
Operator: 1

Date,Time,Specimen#
07/23/20,11:40:40,1

---------------------------------------


Area (mm^2):,      1.00,Flat,     25.40,     25.40,     25.40
Gage Len (mm):,     25.40


LOAD (N),STRAIN 1 (mm),STRAIN 2 (mm),STRESS (MPa),POSITION (mm),TIME (min)
      12.2,      0.000,      0.000,         0,      3.3348,      0.0200
      23.6,      0.000,      0.000,         0,      7.9999,      1.5446
      23.6,      0.000,      0.000,         0,      8.0000,      3.5446
      23.6,      0.000,      0.000,         0,      8.0000,      5.5446
      23.6,      0.000,      0.000,         0,      8.0000,      7.5446
      23.6,      0.000,      0.000,         0,      8.0000,      9.5446
      23.6,      0.000,      0.000,         0,      8.0000,     11.5446
      23.6,      0.000,      0.000,         0,      8.0000,     13.5446
      23.6,      0.000,      0.000,         0,      7.9999,     15.5446
      23.6,      0.000,      0.000,         0,      8.0000,     17.5446
      23.6,      0.000,      0.000,         0,      8.0000,     19.5446
      23.6,      0.000,      0.000,         0,      8.0000,     21.5446
      23.6,      0.000,      0.000,         0,      8.0000,     23.5446
      23.6,      0.000,      0.000,         0,      8.0000,     25.5446
      23.6,      0.000,      0.000,         0,      7.9999,     27.5446
      23.6,      0.000,      0.000,         0,      8.0000,     29.5446
      23.6,      0.000,      0.000,         0,      8.0000,     31.5446
      23.6,      0.000,      0.000,         0,      8.0000,     33.5446
      23.6,      0.000,      0.000,         0,      8.0000,     35.5446
      23.6,      0.000,      0.000,         0,      8.0001,     37.5446
      23.6,      0.000,      0.000,         0,      8.0000,     39.5446
      23.6,      0.000,      0.000,         0,      7.9999,     41.5446
      23.6,      0.000,      0.000,         0,      8.0000,     43.5446
      23.6,      0.000,      0.000,         0,      8.0000,     45.5446
      23.6,      0.000,      0.000,         0,      8.0001,     47.5446
      23.6,      0.000,      0.000,         0,      8.0000,     49.5446
      23.6,      0.000,      0.000,         0,      8.0000,     51.5446
      23.6,      0.000,      0.000,         0,      8.0000,     53.5446
      23.6,      0.000,      0.000,         0,      7.9999,     55.5446
      23.6,      0.000,      0.000,         0,      8.0000,     57.5446
      23.6,      0.000,      0.000,         0,      8.0000,     59.5446
      23.6,      0.000,      0.000,         0,      8.0001,     61.5446
      23.6,      0.000,      0.000,         0,      8.0000,     63.5446
      23.6,      0.000,      0.000,         0,      8.0000,     65.5446
      23.6,      0.000,      0.000,         0,      8.0000,     67.5446
      23.6,      0.000,      0.000,         0,      8.0000,     69.5446
      23.6,      0.000,      0.000,         0,      8.0000,     71.5446
      23.6,      0.000,      0.000,         0,      7.9999,     73.5446
      23.6,      0.000,      0.000,         0,      8.0000,     75.5446
      23.6,      0.000,      0.000,         0,      8.0000,     77.5446
      23.6,      0.000,      0.000,         0,      8.0000,     79.5446
      23.6,      0.000,      0.000,         0,      8.0000,     81.5446
      23.6,      0.000,      0.000,         0,      8.0000,     83.5446
      23.6,      0.000,      0.000,         0,      8.0001,     85.5446
       0.0,      0.000,      0.000,         0,      8.0000,     87.5446
       0.0,      0.000,      0.000,         0,      8.0000,     89.5446
       0.0,      0.000,      0.000,         0,      8.0001,     91.5446
       0.0,      0.000,      0.000,         0,      8.0000,     93.5446
       0.0,      0.000,      0.000,         0,      8.0000,     95.5446
       0.0,      0.000,      0.000,         0,      8.0000,     97.5446
       0.0,      0.000,      0.000,         0,      8.0000,     99.5446
       0.0,      0.000,      0.000,         0,      8.0000,    101.5446
       0.0,      0.000,      0.000,         0,      8.0000,    103.5446
       0.0,      0.000,      0.000,         0,      8.0000,    105.5446
       0.0,      0.000,      0.000,         0,      8.0000,    107.5446
       0.0,      0.000,      0.000,         0,      8.0000,    109.5446
       0.0,      0.000,      0.000,         0,      7.9999,    111.5446
       0.0,      0.000,      0.000,         0,      8.0000,    113.5446
       0.0,      0.000,      0.000,         0,      8.0001,    115.5446
       0.0,      0.000,      0.000,         0,      8.0000,    117.5446
       0.0,      0.000,      0.000,         0,      8.0000,    119.5446
       0.0,      0.000,      0.000,         0,      8.0000,    121.5446
       0.0,      0.000,      0.000,         0,      8.0000,    123.5446
       0.0,      0.000,      0.000,         0,      8.0000,    125.5446
       0.0,      0.000,      0.000,         0,      8.0001,    127.5446
       0.0,      0.000,      0.000,         0,      8.0000,    129.5446
       0.0,      0.000,      0.000,         0,      8.0000,    131.5446
       0.0,      0.000,      0.000,         0,      8.0000,    133.5446
       0.0,      0.000,      0.000,         0,      8.0000,    135.5446
       0.0,      0.000,      0.000,         0,      8.0000,    137.5446
       0.0,      0.000,      0.000,         0,      8.0000,    139.5446
       0.0,      0.000,      0.000,         0,      8.0001,    141.5446
       0.0,      0.000,      0.000,         0,      8.0000,    143.5446
       0.0,      0.000,      0.000,         0,      8.0000,    145.5446
       0.0,      0.000,      0.000,         0,      8.0000,    147.5446
       0.0,      0.000,      0.000,         0,      8.0000,    149.5446
       0.0,      0.000,      0.000,         0,      8.0000,    151.5446
       0.0,      0.000,      0.000,         0,      8.0000,    153.5446
       0.0,      0.000,      0.000,         0,      8.0000,    155.5446
       0.0,      0.000,      0.000,         0,      8.0000,    157.5446
       0.0,      0.000,      0.000,         0,      8.0000,    159.5446
       0.0,      0.000,      0.000,         0,      8.0000,    161.5446
       0.0,      0.000,      0.000,         0,      8.0000,    163.5446
       0.0,      0.000,      0.000,         0,      8.0000,    165.5446
       0.0,      0.000,      0.000,         0,      8.0000,    167.5446
       0.0,      0.000,      0.000,         0,      8.0000,    169.5446
       0.0,      0.000,      0.000,         0,      8.0000,    171.5446
       0.0,      0.000,      0.000,         0,      7.9999,    173.5446
       0.0,      0.000,      0.000,         0,      8.0001,    175.5446
       0.0,      0.000,      0.000,         0,      8.0000,    177.5446
       0.0,      0.000,      0.000,         0,      8.0000,    179.5446
       0.0,      0.000,      0.000,         0,      8.0001,    181.5446
       0.0,      0.000,      0.000,         0,      7.9999,    183.5446
       0.0,      0.000,      0.000,         0,      8.0000,    185.5446
       0.0,      0.000,      0.000,         0,      8.0000,    187.5446
       0.0,      0.000,      0.000,         0,      8.0000,    189.5446
       0.0,      0.000,      0.000,         0,      8.0000,    191.5446
       0.0,      0.000,      0.000,         0,      8.0000,    193.5446
       0.0,      0.000,      0.000,         0,      8.0000,    195.5446
       0.0,      0.000,      0.000,         0,      8.0000,    197.5446
       0.0,      0.000,      0.000,         0,      7.9999,    199.5446
       0.0,      0.000,      0.000,         0,      8.0000,    201.5446
       0.0,      0.000,      0.000,         0,      8.0000,    203.5446
       0.0,      0.000,      0.000,         0,      8.0000,    205.5446
       0.0,      0.000,      0.000,         0,      8.0000,    207.5446
       0.0,      0.000,      0.000,         0,      8.0000,    209.5446
       0.0,      0.000,      0.000,         0,      8.0000,    211.5446
       0.0,      0.000,      0.000,         0,      8.0000,    213.5446
       0.0,      0.000,      0.000,         0,      7.9999,    215.5446
       0.0,      0.000,      0.000,         0,      8.0000,    217.5446
       0.0,      0.000,      0.000,         0,      8.0000,    219.5446
       0.0,      0.000,      0.000,         0,      8.0000,    221.5446
       0.0,      0.000,      0.000,         0,      8.0001,    223.5446
       0.0,      0.000,      0.000,         0,      8.0000,    225.5446
       0.0,      0.000,      0.000,         0,      8.0000,    227.5446
       0.0,      0.000,      0.000,         0,      8.0000,    229.5446
       0.0,      0.000,      0.000,         0,      8.0000,    231.5446
       0.0,      0.000,      0.000,         0,      8.0000,    233.5446
       0.0,      0.000,      0.000,         0,      8.0000,    235.5446
       0.0,      0.000,      0.000,         0,      8.0000,    237.5446
       0.0,      0.000,      0.000,         0,      8.0000,    239.5446
       0.0,      0.000,      0.000,         0,      8.0000,    241.5446
       0.0,      0.000,      0.000,         0,      8.0000,    243.5446
       0.0,      0.000,      0.000,         0,      8.0000,    245.5446
       0.0,      0.000,      0.000,         0,      8.0000,    247.5446
       0.0,      0.000,      0.000,         0,      8.0000,    249.5446
       0.0,      0.000,      0.000,         0,      8.0000,    251.5446
       0.0,      0.000,      0.000,         0,      8.0000,    253.5446
       0.0,      0.000,      0.000,         0,      8.0000,    255.5446
       0.0,      0.000,      0.000,         0,      8.0000,    257.5446
       0.0,      0.000,      0.000,         0,      8.0000,    259.5446
       0.0,      0.000,      0.000,         0,      8.0000,    261.5446
       0.0,      0.000,      0.000,         0,      7.9999,    263.5446
       0.0,      0.000,      0.000,         0,      8.0001,    265.5446
       0.0,      0.000,      0.000,         0,      8.0000,    267.5446
       0.0,      0.000,      0.000,         0,      8.0000,    269.5446
       0.0,      0.000,      0.000,         0,      8.0000,    271.5446
       0.0,      0.000,      0.000,         0,      7.9999,    273.5446
       0.0,      0.000,      0.000,         0,      8.0000,    275.5446
       0.0,      0.000,      0.000,         0,      8.0000,    277.5446
       0.0,      0.000,      0.000,         0,      8.0000,    279.5446
       0.0,      0.000,      0.000,         0,      8.0000,    281.5446
       0.0,      0.000,      0.000,         0,      8.0000,    283.5446
       0.0,      0.000,      0.000,         0,      8.0000,    285.5446
       0.0,      0.000,      0.000,         0,      7.9999,    287.5446
       0.0,      0.000,      0.000,         0,      8.0000,    289.5446
       0.0,      0.000,      0.000,         0,      8.0000,    291.5446
       0.0,      0.000,      0.000,         0,      8.0000,    293.5446
       0.0,      0.000,      0.000,         0,      8.0000,    295.5446
       0.0,      0.000,      0.000,         0,      8.0000,    297.5446
       0.0,      0.000,      0.000,         0,      8.0000,    299.5446
       0.0,      0.000,      0.000,         0,      7.9999,    301.5446
       0.0,      0.000,      0.000,         0,      8.0000,    303.5446
       0.0,      0.000,      0.000,         0,      8.0000,    305.5446
       0.0,      0.000,      0.000,         0,      8.0000,    307.5446
       0.0,      0.000,      0.000,         0,      8.0000,    309.5446
       0.0,      0.000,      0.000,         0,      7.9999,    311.5446
       0.0,      0.000,      0.000,         0,      8.0000,    313.5446
       0.0,      0.000,      0.000,         0,      8.0000,    315.5446
       0.0,      0.000,      0.000,         0,      8.0000,    317.5446
       0.0,      0.000,      0.000,         0,      8.0000,    319.5446
       0.0,      0.000,      0.000,         0,      8.0000,    321.5446
       0.0,      0.000,      0.000,         0,      8.0000,    323.5446
       0.0,      0.000,      0.000,         0,      8.0000,    325.5446
       0.0,      0.000,      0.000,         0,      8.0001,    327.5446
       0.0,      0.000,      0.000,         0,      8.0000,    329.5446
       0.0,      0.000,      0.000,         0,      8.0000,    331.5446
       0.0,      0.000,      0.000,         0,      7.9999,    333.5446
       0.0,      0.000,      0.000,         0,      8.0001,    335.5446
       0.0,      0.000,      0.000,         0,      8.0000,    337.5446
       0.0,      0.000,      0.000,         0,      8.0000,    339.5446
       0.0,      0.000,      0.000,         0,      8.0000,    341.5446
       0.0,      0.000,      0.000,         0,      8.0000,    343.5446
       0.0,      0.000,      0.000,         0,      8.0000,    345.5446
       0.0,      0.000,      0.000,         0,      8.0000,    347.5446
       0.0,      0.000,      0.000,         0,      8.0001,    349.5446
       0.0,      0.000,      0.000,         0,      8.0000,    351.5446
       0.0,      0.000,      0.000,         0,      8.0000,    353.5446
       0.0,      0.000,      0.000,         0,      8.0001,    355.5446
       0.0,      0.000,      0.000,         0,      8.0000,    357.5446
       0.0,      0.000,      0.000,         0,      8.0000,    359.5446
       0.0,      0.000,      0.000,         0,      8.0000,    361.5446
       0.0,      0.000,      0.000,         0,      8.0000,    363.5446
       0.0,      0.000,      0.000,         0,      8.0000,    365.5446
       0.0,      0.000,      0.000,         0,      8.0000,    367.5446
       0.0,      0.000,      0.000,         0,      8.0000,    369.5446
       0.0,      0.000,      0.000,         0,      8.0000,    371.5446
       0.0,      0.000,      0.000,         0,      8.0000,    373.5446
       0.0,      0.000,      0.000,         0,      7.9999,    375.5446
       0.0,      0.000,      0.000,         0,      8.0000,    377.5446
       0.0,      0.000,      0.000,         0,      8.0000,    379.5446
       0.0,      0.000,      0.000,         0,      8.0000,    381.5446
       0.0,      0.000,      0.000,         0,      8.0001,    383.5446
       0.0,      0.000,      0.000,         0,      8.0000,    385.5446
       0.0,      0.000,      0.000,         0,      8.0000,    387.5446
       0.0,      0.000,      0.000,         0,      8.0000,    389.5446
       0.0,      0.000,      0.000,         0,      8.0000,    391.5446
       0.0,      0.000,      0.000,         0,      8.0000,    393.5446
       0.0,      0.000,      0.000,         0,      8.0000,    395.5446
       0.0,      0.000,      0.000,         0,      8.0000,    397.5446
       0.0,      0.000,      0.000,         0,      8.0001,    399.5446
       0.0,      0.000,      0.000,         0,      8.0000,    401.5446
       0.0,      0.000,      0.000,         0,      8.0000,    403.5446
       0.0,      0.000,      0.000,         0,      8.0000,    405.5446
       0.0,      0.000,      0.000,         0,      8.0000,    407.5446
       0.0,      0.000,      0.000,         0,      8.0000,    409.5446
       0.0,      0.000,      0.000,         0,      8.0000,    411.5446
       0.0,      0.000,      0.000,         0,      8.0001,    413.5446
       0.0,      0.000,      0.000,         0,      8.0000,    415.5446
       0.0,      0.000,      0.000,         0,      8.0000,    417.5446
       0.0,      0.000,      0.000,         0,      8.0000,    419.5446
       0.0,      0.000,      0.000,         0,      8.0000,    421.5446
       0.0,      0.000,      0.000,         0,      8.0000,    423.5446
       0.0,      0.000,      0.000,         0,      8.0000,    425.5446
       0.0,      0.000,      0.000,         0,      8.0001,    427.5446
       0.0,      0.000,      0.000,         0,      8.0000,    429.5446
       0.0,      0.000,      0.000,         0,      8.0000,    431.5446
       0.0,      0.000,      0.000,         0,      8.0000,    433.5446
       0.0,      0.000,      0.000,         0,      8.0000,    435.5446
       0.0,      0.000,      0.000,         0,      8.0000,    437.5446
       0.0,      0.000,      0.000,         0,      8.0000,    439.5446
       0.0,      0.000,      0.000,         0,      8.0000,    441.5446
       0.0,      0.000,      0.000,         0,      8.0000,    443.5446
       0.0,      0.000,      0.000,         0,      8.0000,    445.5446
       0.0,      0.000,      0.000,         0,      8.0000,    447.5446
       0.0,      0.000,      0.000,         0,      8.0000,    449.5446
       0.0,      0.000,      0.000,         0,      8.0001,    451.5446
       0.0,      0.000,      0.000,         0,      8.0000,    453.5446
       0.0,      0.000,      0.000,         0,      8.0000,    455.5446
       0.0,      0.000,      0.000,         0,      8.0000,    457.5446
       0.0,      0.000,      0.000,         0,      8.0000,    459.5446
       0.0,      0.000,      0.000,         0,      8.0000,    461.5446
       0.0,      0.000,      0.000,         0,      8.0000,    463.5446
       0.0,      0.000,      0.000,         0,      8.0000,    465.5446
       0.0,      0.000,      0.000,         0,      8.0000,    467.5446
       0.0,      0.000,      0.000,         0,      8.0000,    469.5446
       0.0,      0.000,      0.000,         0,      7.9999,    471.5446
       0.0,      0.000,      0.000,         0,      8.0000,    473.5446
       0.0,      0.000,      0.000,         0,      8.0000,    475.5446
       0.0,      0.000,      0.000,         0,      8.0000,    477.5446
       0.0,      0.000,      0.000,         0,      8.0000,    479.5446
       0.0,      0.000,      0.000,         0,      8.0000,    481.5446
       0.0,      0.000,      0.000,         0,      8.0000,    483.5446
       0.0,      0.000,      0.000,         0,      8.0000,    485.5446
       0.0,      0.000,      0.000,         0,      8.0000,    487.5446
       0.0,      0.000,      0.000,         0,      8.0000,    489.5446
       0.0,      0.000,      0.000,         0,      8.0001,    491.5446
       0.0,      0.000,      0.000,         0,      8.0000,    493.5446
       0.0,      0.000,      0.000,         0,      8.0000,    495.5446
       0.0,      0.000,      0.000,         0,      8.0000,    497.5446
       0.0,      0.000,      0.000,         0,      8.0000,    499.5446
       0.0,      0.000,      0.000,         0,      8.0000,    501.5446
       0.0,      0.000,      0.000,         0,      7.9999,    503.5446
       0.0,      0.000,      0.000,         0,      8.0000,    505.5446
       0.0,      0.000,      0.000,         0,      8.0000,    507.5446
       0.0,      0.000,      0.000,         0,      8.0001,    509.5446
       0.0,      0.000,      0.000,         0,      8.0000,    511.5446
       0.0,      0.000,      0.000,         0,      7.9999,    513.5446
       0.0,      0.000,      0.000,         0,      8.0000,    515.5446
       0.0,      0.000,      0.000,         0,      8.0000,    517.5446
       0.0,      0.000,      0.000,         0,      8.0000,    519.5446
       0.0,      0.000,      0.000,         0,      8.0000,    521.5446
       0.0,      0.000,      0.000,         0,      8.0000,    523.5446
       0.0,      0.000,      0.000,         0,      8.0000,    525.5446
       0.0,      0.000,      0.000,         0,      7.9999,    527.5446
       0.0,      0.000,      0.000,         0,      7.9999,    529.5446
       0.0,      0.000,      0.000,         0,      8.0000,    531.5446
       0.0,      0.000,      0.000,         0,      8.0000,    533.5446
       0.0,      0.000,      0.000,         0,      8.0000,    535.5446
       0.0,      0.000,      0.000,         0,      8.0000,    537.5446
       0.0,      0.000,      0.000,         0,      8.0000,    539.5446
       0.0,      0.000,      0.000,         0,      8.0000,    541.5446
       0.0,      0.000,      0.000,         0,      8.0000,    543.5446
       0.0,      0.000,      0.000,         0,      7.9999,    545.5446
       0.0,      0.000,      0.000,         0,      8.0000,    547.5446
       0.0,      0.000,      0.000,         0,      8.0000,    549.5446
       0.0,      0.000,      0.000,         0,      8.0000,    551.5446
       0.0,      0.000,      0.000,         0,      8.0000,    553.5446
       0.0,      0.000,      0.000,         0,      8.0000,    555.5446
       0.0,      0.000,      0.000,         0,      8.0000,    557.5446
       0.0,      0.000,      0.000,         0,      8.0000,    559.5446
       0.0,      0.000,      0.000,         0,      8.0000,    561.5446
       0.0,      0.000,      0.000,         0,      8.0000,    563.5446
       0.0,      0.000,      0.000,         0,      8.0000,    565.5446
       0.0,      0.000,      0.000,         0,      8.0000,    567.5446
       0.0,      0.000,      0.000,         0,      8.0001,    569.5446
       0.0,      0.000,      0.000,         0,      7.9999,    571.5446
       0.0,      0.000,      0.000,         0,      7.9999,    573.5446
       0.0,      0.000,      0.000,         0,      8.0000,    575.5446
       0.0,      0.000,      0.000,         0,      8.0000,    577.5446
       0.0,      0.000,      0.000,         0,      7.9999,    579.5446
       0.0,      0.000,      0.000,         0,      8.0000,    581.5446
       0.0,      0.000,      0.000,         0,      7.9999,    583.5446
       0.0,      0.000,      0.000,         0,      8.0000,    585.5446
       0.0,      0.000,      0.000,         0,      8.0001,    587.5446
       0.0,      0.000,      0.000,         0,      8.0000,    589.5446
       0.0,      0.000,      0.000,         0,      8.0001,    591.5446
       0.0,      0.000,      0.000,         0,      7.9999,    593.5446
       0.0,      0.000,      0.000,         0,      8.0000,    595.5446
       0.0,      0.000,      0.000,         0,      8.0000,    597.5446
       0.0,      0.000,      0.000,         0,      8.0000,    599.5446
       0.0,      0.000,      0.000,         0,      8.0000,    601.5446
       0.0,      0.000,      0.000,         0,      8.0000,    603.5446
       0.0,      0.000,      0.000,         0,      8.0000,    605.5446
       0.0,      0.000,      0.000,         0,      8.0000,    607.5446
       0.0,      0.000,      0.000,         0,      8.0000,    609.5446
       0.0,      0.000,      0.000,         0,      8.0000,    611.5446
       0.0,      0.000,      0.000,         0,      8.0000,    613.5446
       0.0,      0.000,      0.000,         0,      8.0000,    615.5446
       0.0,      0.000,      0.000,         0,      8.0000,    617.5446
       0.0,      0.000,      0.000,         0,      8.0001,    619.5446
       0.0,      0.000,      0.000,         0,      8.0000,    621.5446
       0.0,      0.000,      0.000,         0,      8.0000,    623.5446
       0.0,      0.000,      0.000,         0,      8.0000,    625.5446
       0.0,      0.000,      0.000,         0,      8.0000,    627.5446
       0.0,      0.000,      0.000,         0,      8.0000,    629.5446
       0.0,      0.000,      0.000,         0,      8.0000,    631.5446
       0.0,      0.000,      0.000,         0,      8.0001,    633.5446
       0.0,      0.000,      0.000,         0,      8.0000,    635.5446
       0.0,      0.000,      0.000,         0,      7.9999,    637.5446
       0.0,      0.000,      0.000,         0,      8.0000,    639.5446
       0.0,      0.000,      0.000,         0,      8.0000,    641.5446
       0.0,      0.000,      0.000,         0,      8.0001,    643.5446
       0.0,      0.000,      0.000,         0,      8.0000,    645.5446
       0.0,      0.000,      0.000,         0,      8.0001,    647.5446
       0.0,      0.000,      0.000,         0,      8.0000,    649.5446
       0.0,      0.000,      0.000,         0,      8.0000,    651.5446
       0.0,      0.000,      0.000,         0,      8.0000,    653.5446
       0.0,      0.000,      0.000,         0,      8.0000,    655.5446
       0.0,      0.000,      0.000,         0,      8.0000,    657.5446
       0.0,      0.000,      0.000,         0,      8.0000,    659.5446
       0.0,      0.000,      0.000,         0,      8.0000,    661.5446
       0.0,      0.000,      0.000,         0,      8.0000,    663.5446
       0.0,      0.000,      0.000,         0,      8.0000,    665.5446
       0.0,      0.000,      0.000,         0,      8.0000,    667.5446
       0.0,      0.000,      0.000,         0,      8.0000,    669.5446
       0.0,      0.000,      0.000,         0,      8.0000,    671.5446
       0.0,      0.000,      0.000,         0,      8.0000,    673.5446
       0.0,      0.000,      0.000,         0,      8.0000,    675.5446
       0.0,      0.000,      0.000,         0,      8.0000,    677.5446
       0.0,      0.000,      0.000,         0,      8.0000,    679.5446
       0.0,      0.000,      0.000,         0,      8.0000,    681.5446
       0.0,      0.000,      0.000,         0,      8.0000,    683.5446
       0.0,      0.000,      0.000,         0,      8.0001,    685.5446
       0.0,      0.000,      0.000,         0,      8.0001,    687.5446
       0.0,      0.000,      0.000,         0,      8.0000,    689.5446
       0.0,      0.000,      0.000,         0,      8.0000,    691.5446
       0.0,      0.000,      0.000,         0,      8.0000,    693.5446
       0.0,      0.000,      0.000,         0,      8.0000,    695.5446
       0.0,      0.000,      0.000,         0,      8.0000,    697.5446
       0.0,      0.000,      0.000,         0,      7.9999,    699.5446
       0.0,      0.000,      0.000,         0,      8.0000,    701.5446
       0.0,      0.000,      0.000,         0,      8.0000,    703.5446
       0.0,      0.000,      0.000,         0,      8.0000,    705.5446
       0.0,      0.000,      0.000,         0,      8.0000,    707.5446
       0.0,      0.000,      0.000,         0,      8.0000,    709.5446
       0.0,      0.000,      0.000,         0,      8.0000,    711.5446
       0.0,      0.000,      0.000,         0,      8.0000,    713.5446
       0.0,      0.000,      0.000,         0,      8.0000,    715.5446
       0.0,      0.000,      0.000,         0,      8.0000,    717.5446
       0.0,      0.000,      0.000,         0,      7.9999,    719.5446
       0.0,      0.000,      0.000,         0,      8.0000,    721.5446
       0.0,      0.000,      0.000,         0,      7.9999,    723.5446
       0.0,      0.000,      0.000,         0,      8.0000,    725.5446
       0.0,      0.000,      0.000,         0,      8.0000,    727.5446
       0.0,      0.000,      0.000,         0,      8.0000,    729.5446
       0.0,      0.000,      0.000,         0,      8.0000,    731.5446
       0.0,      0.000,      0.000,         0,      8.0000,    733.5446
       0.0,      0.000,      0.000,         0,      7.9999,    735.5446
       0.0,      0.000,      0.000,         0,      8.0000,    737.5446
       0.0,      0.000,      0.000,         0,      8.0000,    739.5446
       0.0,      0.000,      0.000,         0,      8.0000,    741.5446
       0.0,      0.000,      0.000,         0,      8.0000,    743.5446
       0.0,      0.000,      0.000,         0,      8.0000,    745.5446
       0.0,      0.000,      0.000,         0,      7.9999,    747.5446
       0.0,      0.000,      0.000,         0,      8.0000,    749.5446
       0.0,      0.000,      0.000,         0,      8.0000,    751.5446
       0.0,      0.000,      0.000,         0,      8.0001,    753.5446
       0.0,      0.000,      0.000,         0,      8.0000,    755.5446
       0.0,      0.000,      0.000,         0,      8.0000,    757.5446
       0.0,      0.000,      0.000,         0,      8.0000,    759.5446
       0.0,      0.000,      0.000,         0,      8.0000,    761.5446
       0.0,      0.000,      0.000,         0,      8.0000,    763.5446
       0.0,      0.000,      0.000,         0,      8.0001,    765.5446
       0.0,      0.000,      0.000,         0,      8.0000,    767.5446
       0.0,      0.000,      0.000,         0,      8.0000,    769.5446
       0.0,      0.000,      0.000,         0,      8.0000,    771.5446
       0.0,      0.000,      0.000,         0,      8.0000,    773.5446
       0.0,      0.000,      0.000,         0,      8.0000,    775.5446
       0.0,      0.000,      0.000,         0,      8.0000,    777.5446
       0.0,      0.000,      0.000,         0,      8.0000,    779.5446
       0.0,      0.000,      0.000,         0,      8.0000,    781.5446
       0.0,      0.000,      0.000,         0,      8.0000,    783.5446
       0.0,      0.000,      0.000,         0,      8.0000,    785.5446
       0.0,      0.000,      0.000,         0,      7.9999,    787.5446
       0.0,      0.000,      0.000,         0,      7.9999,    789.5446
       0.0,      0.000,      0.000,         0,      8.0001,    791.5446
       0.0,      0.000,      0.000,         0,      8.0000,    793.5446
       0.0,      0.000,      0.000,         0,      8.0000,    795.5446
       0.0,      0.000,      0.000,         0,      8.0001,    797.5446
       0.0,      0.000,      0.000,         0,      8.0001,    799.5446
       0.0,      0.000,      0.000,         0,      8.0000,    801.5446
       0.0,      0.000,      0.000,         0,      8.0000,    803.5446
       0.0,      0.000,      0.000,         0,      8.0000,    805.5446
       0.0,      0.000,      0.000,         0,      7.9999,    807.5446
       0.0,      0.000,      0.000,         0,      8.0000,    809.5446
       0.0,      0.000,      0.000,         0,      8.0001,    811.5446
       0.0,      0.000,      0.000,         0,      8.0000,    813.5446
       0.0,      0.000,      0.000,         0,      8.0000,    815.5446
       0.0,      0.000,      0.000,         0,      8.0000,    817.5446
       0.0,      0.000,      0.000,         0,      8.0000,    819.5446
       0.0,      0.000,      0.000,         0,      8.0000,    821.5446
       0.0,      0.000,      0.000,         0,      8.0000,    823.5446
       0.0,      0.000,      0.000,         0,      8.0000,    825.5446
       0.0,      0.000,      0.000,         0,      8.0000,    827.5446
       0.0,      0.000,      0.000,         0,      8.0000,    829.5446
       0.0,      0.000,      0.000,         0,      8.0000,    831.5446
       0.0,      0.000,      0.000,         0,      8.0000,    833.5446
       0.0,      0.000,      0.000,         0,      8.0001,    835.5446
       0.0,      0.000,      0.000,         0,      8.0000,    837.5446
       0.0,      0.000,      0.000,         0,      8.0000,    839.5446
       0.0,      0.000,      0.000,         0,      8.0000,    841.5446
       0.0,      0.000,      0.000,         0,      8.0000,    843.5446
       0.0,      0.000,      0.000,         0,      8.0000,    845.5446
       0.0,      0.000,      0.000,         0,      8.0000,    847.5446
       0.0,      0.000,      0.000,         0,      8.0000,    849.5446
       0.0,      0.000,      0.000,         0,      8.0000,    851.5446
       0.0,      0.000,      0.000,         0,      8.0000,    853.5446
       0.0,      0.000,      0.000,         0,      8.0000,    855.5446
       0.0,      0.000,      0.000,         0,      7.9999,    857.5446
       0.0,      0.000,      0.000,         0,      8.0000,    859.5446
       0.0,      0.000,      0.000,         0,      8.0000,    861.5446
       0.0,      0.000,      0.000,         0,      8.0000,    863.5446
       0.0,      0.000,      0.000,         0,      8.0000,    865.5446
       0.0,      0.000,      0.000,         0,      8.0000,    867.5446
       0.0,      0.000,      0.000,         0,      8.0000,    869.5446
       0.0,      0.000,      0.000,         0,      8.0000,    871.5446
       0.0,      0.000,      0.000,         0,      8.0000,    873.5446
       0.0,      0.000,      0.000,         0,      8.0000,    875.5446
       0.0,      0.000,      0.000,         0,      8.0000,    877.5446
       0.0,      0.000,      0.000,         0,      8.0000,    879.5446
       0.0,      0.000,      0.000,         0,      8.0000,    881.5446
       0.0,      0.000,      0.000,         0,      8.0000,    883.5446
       0.0,      0.000,      0.000,         0,      8.0000,    885.5446
       0.0,      0.000,      0.000,         0,      8.0000,    887.5446
       0.0,      0.000,      0.000,         0,      8.0000,    889.5446
       0.0,      0.000,      0.000,         0,      8.0000,    891.5446
       0.0,      0.000,      0.000,         0,      8.0000,    893.5446
       0.0,      0.000,      0.000,         0,      8.0000,    895.5446
       0.0,      0.000,      0.000,         0,      8.0000,    897.5446
       0.0,      0.000,      0.000,         0,      8.0000,    899.5446
       0.0,      0.000,      0.000,         0,      8.0000,    901.5446
       0.0,      0.000,      0.000,         0,      8.0000,    903.5446
       0.0,      0.000,      0.000,         0,      8.0000,    905.5446
       0.0,      0.000,      0.000,         0,      8.0000,    907.5446
       0.0,      0.000,      0.000,         0,      8.0000,    909.5446
       0.0,      0.000,      0.000,         0,      8.0000,    911.5446
       0.0,      0.000,      0.000,         0,      8.0000,    913.5446
       0.0,      0.000,      0.000,         0,      7.9999,    915.5446
       0.0,      0.000,      0.000,         0,      8.0000,    917.5446
       0.0,      0.000,      0.000,         0,      7.9999,    919.5446
       0.0,      0.000,      0.000,         0,      8.0000,    921.5446
       0.0,      0.000,      0.000,         0,      7.9999,    923.5446
       0.0,      0.000,      0.000,         0,      8.0000,    925.5446
       0.0,      0.000,      0.000,         0,      8.0000,    927.5446
       0.0,      0.000,      0.000,         0,      8.0000,    929.5446
       0.0,      0.000,      0.000,         0,      7.9999,    931.5446
       0.0,      0.000,      0.000,         0,      8.0000,    933.5446
       0.0,      0.000,      0.000,         0,      8.0000,    935.5446
       0.0,      0.000,      0.000,         0,      8.0000,    937.5446
       0.0,      0.000,      0.000,         0,      8.0000,    939.5446
       0.0,      0.000,      0.000,         0,      8.0000,    941.5446
       0.0,      0.000,      0.000,         0,      7.9999,    943.5446
       0.0,      0.000,      0.000,         0,      8.0001,    945.5446
       0.0,      0.000,      0.000,         0,      8.0000,    947.5446
       0.0,      0.000,      0.000,         0,      8.0000,    949.5446
       0.0,      0.000,      0.000,         0,      8.0000,    951.5446
       0.0,      0.000,      0.000,         0,      8.0000,    953.5446
       0.0,      0.000,      0.000,         0,      8.0000,    955.5446
       0.0,      0.000,      0.000,         0,      8.0000,    957.5446
       0.0,      0.000,      0.000,         0,      8.0001,    959.5446
       0.0,      0.000,      0.000,         0,      8.0001,    961.5446
       0.0,      0.000,      0.000,         0,      8.0000,    963.5446
       0.0,      0.000,      0.000,         0,      8.0000,    965.5446
       0.0,      0.000,      0.000,         0,      8.0000,    967.5446
       0.0,      0.000,      0.000,         0,      8.0000,    969.5446
       0.0,      0.000,      0.000,         0,      8.0000,    971.5446
       0.0,      0.000,      0.000,         0,      8.0001,    973.5446
       0.0,      0.000,      0.000,         0,      8.0000,    975.5446
       0.0,      0.000,      0.000,         0,      8.0000,    977.5446
       0.0,      0.000,      0.000,         0,      7.9999,    979.5446
       0.0,      0.000,      0.000,         0,      7.9999,    981.5446
       0.0,      0.000,      0.000,         0,      8.0000,    983.5446
       0.0,      0.000,      0.000,         0,      8.0000,    985.5446
       0.0,      0.000,      0.000,         0,      8.0001,    987.5446
       0.0,      0.000,      0.000,         0,      8.0000,    989.5446
       0.0,      0.000,      0.000,         0,      8.0000,    991.5446
       0.0,      0.000,      0.000,         0,      8.0000,    993.5446
       0.0,      0.000,      0.000,         0,      8.0000,    995.5446
       0.0,      0.000,      0.000,         0,      8.0000,    997.5446
       0.0,      0.000,      0.000,         0,      8.0000,    999.5446
       0.0,      0.000,      0.000,         0,      8.0000,   1001.5446
       0.0,      0.000,      0.000,         0,      8.0000,   1003.5446
       0.0,      0.000,      0.000,         0,      8.0000,   1005.5446
       0.0,      0.000,      0.000,         0,      8.0000,   1007.5446
       0.0,      0.000,      0.000,         0,      8.0001,   1009.5446
       0.0,      0.000,      0.000,         0,      8.0000,   1011.5446
       0.0,      0.000,      0.000,         0,      8.0000,   1013.5446
       0.0,      0.000,      0.000,         0,      8.0000,   1015.5446
       0.0,      0.000,      0.000,         0,      8.0000,   1017.5446
       0.0,      0.000,      0.000,         0,      8.0000,   1019.5446
       0.0,      0.000,      0.000,         0,      8.0000,   1021.5446
       0.0,      0.000,      0.000,         0,      8.0000,   1023.5446
       0.0,      0.000,      0.000,         0,      8.0000,   1025.5446
       0.0,      0.000,      0.000,         0,      8.0000,   1027.5446
       0.0,      0.000,      0.000,         0,      8.0000,   1029.5446
       0.0,      0.000,      0.000,         0,      8.0000,   1031.5446
       0.0,      0.000,      0.000,         0,      8.0000,   1033.5446
       0.0,      0.000,      0.000,         0,      8.0000,   1035.5446
       0.0,      0.000,      0.000,         0,      8.0000,   1037.5446
       0.0,      0.000,      0.000,         0,      8.0000,   1039.5446
       0.0,      0.000,      0.000,         0,      8.0001,   1041.5446
       0.0,      0.000,      0.000,         0,      8.0000,   1043.5446
       0.0,      0.000,      0.000,         0,      8.0001,   1045.5446
       0.0,      0.000,      0.000,         0,      8.0000,   1047.5446
       0.0,      0.000,      0.000,         0,      8.0000,   1049.5446
       0.0,      0.000,      0.000,         0,      7.9999,   1051.5446
       0.0,      0.000,      0.000,         0,      7.9999,   1053.5446
       0.0,      0.000,      0.000,         0,      8.0000,   1055.5446
       0.0,      0.000,      0.000,         0,      8.0000,   1057.5446
       0.0,      0.000,      0.000,         0,      8.0000,   1059.5446
       0.0,      0.000,      0.000,         0,      8.0000,   1061.5446
       0.0,      0.000,      0.000,         0,      8.0000,   1063.5446
       0.0,      0.000,      0.000,         0,      8.0000,   1065.5446
       0.0,      0.000,      0.000,         0,      8.0000,   1067.5446
       0.0,      0.000,      0.000,         0,      7.9999,   1069.5446
       0.0,      0.000,      0.000,         0,      8.0000,   1071.5446
       0.0,      0.000,      0.000,         0,      8.0000,   1073.5446
       0.0,      0.000,      0.000,         0,      8.0000,   1075.5446
       0.0,      0.000,      0.000,         0,      8.0000,   1077.5446
       0.0,      0.000,      0.000,         0,      8.0000,   1079.5446
       0.0,      0.000,      0.000,         0,      8.0000,   1081.5446
       0.0,      0.000,      0.000,         0,      8.0000,   1083.5446
       0.0,      0.000,      0.000,         0,      8.0000,   1085.5446
       0.0,      0.000,      0.000,         0,      8.0001,   1087.5446
       0.0,      0.000,      0.000,         0,      8.0000,   1089.5446
       0.0,      0.000,      0.000,         0,      8.0000,   1091.0446