File: Alban repo/Quiz 1/suction cup instron tests/july-2020-time-vs-viscosity_raw-data/d30e10-01-10-5-80grit-2800kg-test2.raw
Operator: 1

Date,Time,Specimen#
07/07/20,12:35:39,1

---------------------------------------


Area (mm^2):,      1.00,Flat,     25.40,     25.40,     25.40
Gage Len (mm):,     25.40


LOAD (N),STRAIN 1 (mm),STRAIN 2 (mm),STRESS (MPa),POSITION (mm),TIME (min)
       6.1,      0.000,      0.000,         0,      0.3419,      0.0005
       9.8,      0.000,      0.000,         0,      0.6840,      0.0010
      13.3,      0.000,      0.000,         0,      1.0260,      0.0016
      16.5,      0.000,      0.000,         0,      1.3681,      0.0021
      19.6,      0.000,      0.000,         0,      1.7103,      0.0026
      22.5,      0.000,      0.000,         0,      2.0525,      0.0031
      25.2,      0.000,      0.000,         0,      2.3948,      0.0036
      27.6,      0.000,      0.000,         0,      2.7371,      0.0042
      29.4,      0.000,      0.000,         0,      3.0794,      0.0047
      29.6,      0.000,      0.000,         0,      3.4220,      0.0052
      28.3,      0.000,      0.000,         0,      3.7645,      0.0057
      28.3,      0.000,      0.000,         0,      4.1071,      0.0063
      29.4,      0.000,      0.000,         0,      4.4441,      0.0068
      29.3,      0.000,      0.000,         0,      4.7924,      0.0073
      28.7,      0.000,      0.000,         0,      5.1352,      0.0078
      29.0,      0.000,      0.000,         0,      5.4779,      0.0083
      29.5,      0.000,      0.000,         0,      5.8207,      0.0089
      29.4,      0.000,      0.000,         0,      6.1636,      0.0094
      29.1,      0.000,      0.000,         0,      6.5066,      0.0099
      29.4,      0.000,      0.000,         0,      6.8494,      0.0104
      29.4,      0.000,      0.000,         0,      7.1924,      0.0109
      29.2,      0.000,      0.000,         0,      7.5354,      0.0115
      29.3,      0.000,      0.000,         0,      7.8784,      0.0120
      29.3,      0.000,      0.000,         0,      8.4037,      0.0128
      29.3,      0.000,      0.000,         0,      8.7688,      0.0133
      29.4,      0.000,      0.000,         0,      9.1328,      0.0139
      29.3,      0.000,      0.000,         0,      9.4710,      0.0144
      28.8,      0.000,      0.000,         0,      9.7133,      0.0150
      28.9,      0.000,      0.000,         0,      9.8800,      0.0155
      29.4,      0.000,      0.000,         0,      9.9965,      0.0161
      29.2,      0.000,      0.000,         0,     10.0786,      0.0166
      29.1,      0.000,      0.000,         0,     10.1362,      0.0172
      29.4,      0.000,      0.000,         0,     10.1771,      0.0177
      29.3,      0.000,      0.000,         0,     10.2061,      0.0183
      29.2,      0.000,      0.000,         0,     10.2266,      0.0188
      29.4,      0.000,      0.000,         0,     10.2412,      0.0194
      29.3,      0.000,      0.000,         0,     10.2514,      0.0200
      29.2,      0.000,      0.000,         0,     10.2589,      0.0205
      29.3,      0.000,      0.000,         0,     10.2640,      0.0211
      29.3,      0.000,      0.000,         0,     10.2675,      0.0216
      29.3,      0.000,      0.000,         0,     10.2701,      0.0222
      29.3,      0.000,      0.000,         0,     10.2721,      0.0227
      29.3,      0.000,      0.000,         0,     10.2737,      0.0233
      29.3,      0.000,      0.000,         0,     10.2747,      0.0238
      29.3,      0.000,      0.000,         0,     10.2756,      0.0244
      29.3,      0.000,      0.000,         0,     10.2760,      0.0249
      29.3,      0.000,      0.000,         0,     10.2763,      0.0255
      29.3,      0.000,      0.000,         0,     10.2768,      0.0260
      29.3,      0.000,      0.000,         0,     10.2772,      0.0266
      29.3,      0.000,      0.000,         0,     10.2776,      0.0271
      29.3,      0.000,      0.000,         0,     10.2776,      0.0277
      29.3,      0.000,      0.000,         0,     10.2776,      0.0283
      29.3,      0.000,      0.000,         0,     10.2776,      0.0288
      29.3,      0.000,      0.000,         0,     10.2776,      0.0294
      29.3,      0.000,      0.000,         0,     10.2776,      0.0299
      29.3,      0.000,      0.000,         0,     10.2776,      0.0305
      29.3,      0.000,      0.000,         0,     10.2776,      0.0310
      29.3,      0.000,      0.000,         0,     10.2777,      0.0316
      29.3,      0.000,      0.000,         0,     10.2777,      0.0321
      29.3,      0.000,      0.000,         0,     10.2777,      0.0327
      29.3,      0.000,      0.000,         0,     10.2777,      0.0332
      29.3,      0.000,      0.000,         0,     10.2777,      0.0338
      29.3,      0.000,      0.000,         0,     10.2777,      0.0343
      29.3,      0.000,      0.000,         0,     10.2777,      0.0349
      29.3,      0.000,      0.000,         0,     10.2777,      0.0354
      29.3,      0.000,      0.000,         0,     10.2777,      0.0360
      29.3,      0.000,      0.000,         0,     10.2777,      0.0366
      29.3,      0.000,      0.000,         0,     10.2777,      0.0371
      29.3,      0.000,      0.000,         0,     10.2777,      0.0377
      29.3,      0.000,      0.000,         0,     10.2777,      0.0382
      29.3,      0.000,      0.000,         0,     10.2778,      0.0388
      29.3,      0.000,      0.000,         0,     10.2778,      0.0393
      29.3,      0.000,      0.000,         0,     10.2778,      0.0399
      29.3,      0.000,      0.000,         0,     10.2778,      0.0404
      29.3,      0.000,      0.000,         0,     10.2778,      0.0410
      29.3,      0.000,      0.000,         0,     10.2778,      0.0415
      29.3,      0.000,      0.000,         0,     10.2778,      0.0421
      29.3,      0.000,      0.000,         0,     10.2778,      0.0426
      29.3,      0.000,      0.000,         0,     10.2778,      0.0432
      29.3,      0.000,      0.000,         0,     10.2778,      0.0438
      29.3,      0.000,      0.000,         0,     10.2778,      0.0443
      29.3,      0.000,      0.000,         0,     10.2779,      0.0449
      29.3,      0.000,      0.000,         0,     10.2779,      0.0454
      29.3,      0.000,      0.000,         0,     10.2779,      0.0460
      29.3,      0.000,      0.000,         0,     10.2779,      0.0465
      29.3,      0.000,      0.000,         0,     10.2779,      0.0471
      29.3,      0.000,      0.000,         0,     10.2779,      0.0476
      29.3,      0.000,      0.000,         0,     10.2779,      0.0482
      29.3,      0.000,      0.000,         0,     10.2779,      0.0487
      29.1,      0.000,      0.000,         0,     10.2779,      0.0493
      18.4,      0.000,      0.000,         0,     10.2779,      0.0498
       0.9,      0.000,      0.000,         0,     10.2779,      0.0504
       0.1,      0.000,      0.000,         0,     10.2780,      0.0509
       0.1,      0.000,      0.000,         0,     10.2780,      0.0515
      -0.1,      0.000,      0.000,         0,     10.2780,      0.0521
       0.0,      0.000,      0.000,         0,     10.2780,      0.0526
       0.0,      0.000,      0.000,         0,     10.2780,      0.0532
      -0.1,      0.000,      0.000,         0,     10.2780,      0.0537
       0.0,      0.000,      0.000,         0,     10.2780,      0.0543
       0.0,      0.000,      0.000,         0,     10.2780,      0.0548
       0.0,      0.000,      0.000,         0,     10.2780,      0.0554
       0.1,      0.000,      0.000,         0,     10.2780,      0.0559
       0.0,      0.000,      0.000,         0,     10.2780,      0.0565
       0.0,      0.000,      0.000,         0,     10.2780,      0.0570
       0.0,      0.000,      0.000,         0,     10.2780,      0.0576
       0.0,      0.000,      0.000,         0,     10.2780,      0.0581
       0.0,      0.000,      0.000,         0,     10.2781,      0.0587
       0.0,      0.000,      0.000,         0,     10.2781,      0.0592
       0.0,      0.000,      0.000,         0,     10.2781,      0.0598
       0.0,      0.000,      0.000,         0,     10.2781,      0.0604
       0.0,      0.000,      0.000,         0,     10.2781,      0.0609
       0.0,      0.000,      0.000,         0,     10.2781,      0.0615
       0.0,      0.000,      0.000,         0,     10.2781,      0.0620
       0.0,      0.000,      0.000,         0,     10.2781,      0.0626
       0.0,      0.000,      0.000,         0,     10.2782,      0.0631
       0.0,      0.000,      0.000,         0,     10.2782,      0.0637
       0.0,      0.000,      0.000,         0,     10.2782,      0.0642
       0.0,      0.000,      0.000,         0,     10.2782,      0.0648
       0.0,      0.000,      0.000,         0,     10.2783,      0.0653
       0.0,      0.000,      0.000,         0,     10.2783,      0.0659
       0.0,      0.000,      0.000,         0,     10.2784,      0.0664
       0.0,      0.000,      0.000,         0,     10.2786,      0.0670
       0.0,      0.000,      0.000,         0,     10.2788,      0.0675
       0.0,      0.000,      0.000,         0,     10.2792,      0.0681
       0.0,      0.000,      0.000,         0,     10.2796,      0.0687
       0.0,      0.000,      0.000,         0,     10.2798,      0.0692
       0.0,      0.000,      0.000,         0,     10.2798,      0.0698
       0.0,      0.000,      0.000,         0,     10.2798,      0.0703
       0.0,      0.000,      0.000,         0,     10.2798,      0.0709
       0.0,      0.000,      0.000,         0,     10.2798,      0.0714
       0.0,      0.000,      0.000,         0,     10.2798,      0.0720
       0.0,      0.000,      0.000,         0,     10.2798,      0.0725
       0.0,      0.000,      0.000,         0,     10.2798,      0.0731
       0.0,      0.000,      0.000,         0,     10.2798,      0.0736
       0.0,      0.000,      0.000,         0,     10.2798,      0.0742
       0.0,      0.000,      0.000,         0,     10.2798,      0.0747
       0.0,      0.000,      0.000,         0,     10.2798,      0.0753
       0.0,      0.000,      0.000,         0,     10.2798,      0.0758
       0.0,      0.000,      0.000,         0,     10.2798,      0.0764
       0.0,      0.000,      0.000,         0,     10.2798,      0.0770
       0.0,      0.000,      0.000,         0,     10.2797,      0.0775
       0.0,      0.000,      0.000,         0,     10.2798,      0.0781
       0.0,      0.000,      0.000,         0,     10.2798,      0.0786
       0.0,      0.000,      0.000,         0,     10.2798,      0.0792
       0.0,      0.000,      0.000,         0,     10.2797,      0.0797
       0.0,      0.000,      0.000,         0,     10.2797,      0.0803
       0.0,      0.000,      0.000,         0,     10.2798,      0.0808
       0.0,      0.000,      0.000,         0,     10.2798,      0.0814
       0.0,      0.000,      0.000,         0,     10.2797,      0.0819
       0.0,      0.000,      0.000,         0,     10.2798,      0.0825
       0.0,      0.000,      0.000,         0,     10.2797,      0.0830
       0.0,      0.000,      0.000,         0,     10.2798,      0.0836
       0.0,      0.000,      0.000,         0,     10.2798,      0.0841
       0.0,      0.000,      0.000,         0,     10.2797,      0.0847
       0.0,      0.000,      0.000,         0,     10.2798,      0.0853
       0.0,      0.000,      0.000,         0,     10.2798,      0.0858
       0.0,      0.000,      0.000,         0,     10.2797,      0.0864
       0.0,      0.000,      0.000,         0,     10.2797,      0.0869
       0.0,      0.000,      0.000,         0,     10.2798,      0.0875
       0.0,      0.000,      0.000,         0,     10.2798,      0.0880
       0.0,      0.000,      0.000,         0,     10.2797,      0.0886
       0.0,      0.000,      0.000,         0,     10.2798,      0.0891
       0.0,      0.000,      0.000,         0,     10.2798,      0.0897
       0.0,      0.000,      0.000,         0,     10.2797,      0.0902
       0.0,      0.000,      0.000,         0,     10.2797,      0.0908
       0.0,      0.000,      0.000,         0,     10.2798,      0.0913
       0.0,      0.000,      0.000,         0,     10.2797,      0.0919
       0.0,      0.000,      0.000,         0,     10.2797,      0.0924
       0.0,      0.000,      0.000,         0,     10.2797,      0.0930
       0.0,      0.000,      0.000,         0,     10.2797,      0.0936
       0.0,      0.000,      0.000,         0,     10.2797,      0.0941
       0.0,      0.000,      0.000,         0,     10.2797,      0.0947
       0.0,      0.000,      0.000,         0,     10.2797,      0.0952
       0.0,      0.000,      0.000,         0,     10.2798,      0.0958
       0.0,      0.000,      0.000,         0,     10.2798,      0.0963
       0.0,      0.000,      0.000,         0,     10.2797,      0.0969
       0.0,      0.000,      0.000,         0,     10.2797,      0.0974
       0.0,      0.000,      0.000,         0,     10.2797,      0.0980
       0.0,      0.000,      0.000,         0,     10.2797,      0.0985
       0.0,      0.000,      0.000,         0,     10.2797,      0.0991
       0.0,      0.000,      0.000,         0,     10.2797,      0.0996
       0.0,      0.000,      0.000,         0,     10.2797,      0.1002
       0.0,      0.000,      0.000,         0,     10.2797,      0.1007
       0.0,      0.000,      0.000,         0,     10.2798,      0.1013
       0.0,      0.000,      0.000,         0,     10.2797,      0.1019
       0.0,      0.000,      0.000,         0,     10.2797,      0.1024
       0.0,      0.000,      0.000,         0,     10.2797,      0.1030
       0.0,      0.000,      0.000,         0,     10.2797,      0.1035
       0.0,      0.000,      0.000,         0,     10.2798,      0.1041
       0.0,      0.000,      0.000,         0,     10.2797,      0.1046
       0.0,      0.000,      0.000,         0,     10.2797,      0.1052
       0.0,      0.000,      0.000,         0,     10.2797,      0.1057
       0.0,      0.000,      0.000,         0,     10.2797,      0.1063
       0.0,      0.000,      0.000,         0,     10.2797,      0.1068
       0.0,      0.000,      0.000,         0,     10.2797,      0.1074
       0.0,      0.000,      0.000,         0,     10.2798,      0.1079
       0.0,      0.000,      0.000,         0,     10.2797,      0.1085
       0.0,      0.000,      0.000,         0,     10.2798,      0.1090
       0.0,      0.000,      0.000,         0,     10.2798,      0.1096
       0.0,      0.000,      0.000,         0,     10.2797,      0.1102
       0.0,      0.000,      0.000,         0,     10.2797,      0.1107
       0.0,      0.000,      0.000,         0,     10.2797,      0.1113
       0.0,      0.000,      0.000,         0,     10.2798,      0.1118