File: Alban repo/Quiz 1/suction cup instron tests/july-2020-time-vs-viscosity_raw-data/d30e10-01-10-5-80grit-2800kg-test5.raw
Operator: 1

Date,Time,Specimen#
07/07/20,12:39:58,1

---------------------------------------


Area (mm^2):,      1.00,Flat,     25.40,     25.40,     25.40
Gage Len (mm):,     25.40


LOAD (N),STRAIN 1 (mm),STRAIN 2 (mm),STRESS (MPa),POSITION (mm),TIME (min)
       6.2,      0.000,      0.000,         0,      0.3415,      0.0005
       9.9,      0.000,      0.000,         0,      0.6831,      0.0010
      13.3,      0.000,      0.000,         0,      1.0247,      0.0016
      16.6,      0.000,      0.000,         0,      1.3664,      0.0021
      19.6,      0.000,      0.000,         0,      1.7082,      0.0026
      22.5,      0.000,      0.000,         0,      2.0501,      0.0031
      25.2,      0.000,      0.000,         0,      2.3920,      0.0036
      27.7,      0.000,      0.000,         0,      2.7340,      0.0042
      29.6,      0.000,      0.000,         0,      3.0761,      0.0047
      30.0,      0.000,      0.000,         0,      3.4183,      0.0052
      28.6,      0.000,      0.000,         0,      3.7606,      0.0057
      28.3,      0.000,      0.000,         0,      4.1029,      0.0063
      29.5,      0.000,      0.000,         0,      4.4458,      0.0068
      29.6,      0.000,      0.000,         0,      4.7878,      0.0073
      28.9,      0.000,      0.000,         0,      5.1308,      0.0078
      29.1,      0.000,      0.000,         0,      5.4728,      0.0083
      29.6,      0.000,      0.000,         0,      5.8154,      0.0089
      29.3,      0.000,      0.000,         0,      6.1581,      0.0094
      29.1,      0.000,      0.000,         0,      6.5009,      0.0099
      29.4,      0.000,      0.000,         0,      6.8436,      0.0104
      29.4,      0.000,      0.000,         0,      7.1864,      0.0109
      29.2,      0.000,      0.000,         0,      7.5292,      0.0115
      29.3,      0.000,      0.000,         0,      7.8721,      0.0120
      29.3,      0.000,      0.000,         0,      8.3864,      0.0127
      29.2,      0.000,      0.000,         0,      8.7509,      0.0133
      29.4,      0.000,      0.000,         0,      9.1159,      0.0139
      29.3,      0.000,      0.000,         0,      9.4587,      0.0144
      28.8,      0.000,      0.000,         0,      9.7101,      0.0150
      28.9,      0.000,      0.000,         0,      9.8832,      0.0155
      29.3,      0.000,      0.000,         0,     10.0040,      0.0161
      29.2,      0.000,      0.000,         0,     10.0891,      0.0166
      29.1,      0.000,      0.000,         0,     10.1489,      0.0172
      29.4,      0.000,      0.000,         0,     10.1910,      0.0177
      29.3,      0.000,      0.000,         0,     10.2207,      0.0183
      29.2,      0.000,      0.000,         0,     10.2417,      0.0188
      29.3,      0.000,      0.000,         0,     10.2567,      0.0194
      29.3,      0.000,      0.000,         0,     10.2674,      0.0199
      29.2,      0.000,      0.000,         0,     10.2750,      0.0205
      29.3,      0.000,      0.000,         0,     10.2801,      0.0210
      29.3,      0.000,      0.000,         0,     10.2839,      0.0216
      29.3,      0.000,      0.000,         0,     10.2868,      0.0222
      29.3,      0.000,      0.000,         0,     10.2889,      0.0227
      29.3,      0.000,      0.000,         0,     10.2905,      0.0233
      29.3,      0.000,      0.000,         0,     10.2916,      0.0238
      29.3,      0.000,      0.000,         0,     10.2926,      0.0244
      29.3,      0.000,      0.000,         0,     10.2931,      0.0249
      29.3,      0.000,      0.000,         0,     10.2935,      0.0255
      29.3,      0.000,      0.000,         0,     10.2939,      0.0260
      29.3,      0.000,      0.000,         0,     10.2942,      0.0266
      29.3,      0.000,      0.000,         0,     10.2946,      0.0271
      29.3,      0.000,      0.000,         0,     10.2946,      0.0277
      29.3,      0.000,      0.000,         0,     10.2946,      0.0282
      29.3,      0.000,      0.000,         0,     10.2946,      0.0288
      29.3,      0.000,      0.000,         0,     10.2946,      0.0293
      29.3,      0.000,      0.000,         0,     10.2946,      0.0299
      29.3,      0.000,      0.000,         0,     10.2946,      0.0305
      29.3,      0.000,      0.000,         0,     10.2946,      0.0310
      29.3,      0.000,      0.000,         0,     10.2946,      0.0316
      29.3,      0.000,      0.000,         0,     10.2946,      0.0321
      29.3,      0.000,      0.000,         0,     10.2946,      0.0327
      29.3,      0.000,      0.000,         0,     10.2946,      0.0332
      29.3,      0.000,      0.000,         0,     10.2946,      0.0338
      29.3,      0.000,      0.000,         0,     10.2946,      0.0343
      29.3,      0.000,      0.000,         0,     10.2946,      0.0349
      29.3,      0.000,      0.000,         0,     10.2946,      0.0354
      29.3,      0.000,      0.000,         0,     10.2946,      0.0360
      29.3,      0.000,      0.000,         0,     10.2946,      0.0365
      29.3,      0.000,      0.000,         0,     10.2947,      0.0371
      29.3,      0.000,      0.000,         0,     10.2947,      0.0376
      29.3,      0.000,      0.000,         0,     10.2947,      0.0382
      29.3,      0.000,      0.000,         0,     10.2947,      0.0388
      29.3,      0.000,      0.000,         0,     10.2947,      0.0393
      29.3,      0.000,      0.000,         0,     10.2947,      0.0399
      29.3,      0.000,      0.000,         0,     10.2947,      0.0404
      29.3,      0.000,      0.000,         0,     10.2947,      0.0410
      29.3,      0.000,      0.000,         0,     10.2947,      0.0415
      29.3,      0.000,      0.000,         0,     10.2947,      0.0421
      29.3,      0.000,      0.000,         0,     10.2947,      0.0426
      29.3,      0.000,      0.000,         0,     10.2947,      0.0432
      29.3,      0.000,      0.000,         0,     10.2947,      0.0437
      29.3,      0.000,      0.000,         0,     10.2947,      0.0443
      29.3,      0.000,      0.000,         0,     10.2947,      0.0448
      29.3,      0.000,      0.000,         0,     10.2947,      0.0454
      29.3,      0.000,      0.000,         0,     10.2947,      0.0459
      29.3,      0.000,      0.000,         0,     10.2947,      0.0465
      29.3,      0.000,      0.000,         0,     10.2947,      0.0471
      29.3,      0.000,      0.000,         0,     10.2947,      0.0476
      29.3,      0.000,      0.000,         0,     10.2947,      0.0482
      29.3,      0.000,      0.000,         0,     10.2948,      0.0487
      29.3,      0.000,      0.000,         0,     10.2948,      0.0493
      29.3,      0.000,      0.000,         0,     10.2948,      0.0498
      29.3,      0.000,      0.000,         0,     10.2948,      0.0504
      29.3,      0.000,      0.000,         0,     10.2948,      0.0509
      29.3,      0.000,      0.000,         0,     10.2948,      0.0515
      29.1,      0.000,      0.000,         0,     10.2948,      0.0520
      12.8,      0.000,      0.000,         0,     10.2948,      0.0526
       0.2,      0.000,      0.000,         0,     10.2948,      0.0531
      -0.1,      0.000,      0.000,         0,     10.2948,      0.0537
       0.0,      0.000,      0.000,         0,     10.2949,      0.0542
       0.0,      0.000,      0.000,         0,     10.2949,      0.0548
       0.0,      0.000,      0.000,         0,     10.2949,      0.0554
       0.1,      0.000,      0.000,         0,     10.2949,      0.0559
       0.0,      0.000,      0.000,         0,     10.2949,      0.0565
       0.1,      0.000,      0.000,         0,     10.2949,      0.0570
       0.0,      0.000,      0.000,         0,     10.2949,      0.0576
       0.0,      0.000,      0.000,         0,     10.2949,      0.0581
       0.0,      0.000,      0.000,         0,     10.2949,      0.0587
       0.0,      0.000,      0.000,         0,     10.2949,      0.0592
       0.0,      0.000,      0.000,         0,     10.2949,      0.0598
       0.0,      0.000,      0.000,         0,     10.2949,      0.0603
       0.0,      0.000,      0.000,         0,     10.2949,      0.0609
       0.0,      0.000,      0.000,         0,     10.2949,      0.0614
       0.0,      0.000,      0.000,         0,     10.2949,      0.0620
       0.0,      0.000,      0.000,         0,     10.2949,      0.0625
       0.0,      0.000,      0.000,         0,     10.2949,      0.0631
       0.0,      0.000,      0.000,         0,     10.2949,      0.0637
       0.0,      0.000,      0.000,         0,     10.2949,      0.0642
       0.0,      0.000,      0.000,         0,     10.2949,      0.0648
       0.0,      0.000,      0.000,         0,     10.2950,      0.0653
       0.0,      0.000,      0.000,         0,     10.2950,      0.0659
       0.0,      0.000,      0.000,         0,     10.2950,      0.0664
       0.0,      0.000,      0.000,         0,     10.2950,      0.0670
       0.0,      0.000,      0.000,         0,     10.2950,      0.0675
       0.0,      0.000,      0.000,         0,     10.2950,      0.0681
       0.0,      0.000,      0.000,         0,     10.2950,      0.0686
       0.0,      0.000,      0.000,         0,     10.2950,      0.0692
       0.0,      0.000,      0.000,         0,     10.2950,      0.0697
       0.0,      0.000,      0.000,         0,     10.2950,      0.0703
       0.0,      0.000,      0.000,         0,     10.2950,      0.0708
       0.0,      0.000,      0.000,         0,     10.2950,      0.0714
       0.0,      0.000,      0.000,         0,     10.2950,      0.0720
       0.0,      0.000,      0.000,         0,     10.2951,      0.0725
       0.0,      0.000,      0.000,         0,     10.2951,      0.0731
       0.0,      0.000,      0.000,         0,     10.2951,      0.0736
       0.0,      0.000,      0.000,         0,     10.2951,      0.0742
       0.0,      0.000,      0.000,         0,     10.2951,      0.0747
       0.0,      0.000,      0.000,         0,     10.2951,      0.0753
       0.0,      0.000,      0.000,         0,     10.2951,      0.0758
       0.0,      0.000,      0.000,         0,     10.2951,      0.0764
       0.0,      0.000,      0.000,         0,     10.2951,      0.0769
       0.0,      0.000,      0.000,         0,     10.2951,      0.0775
       0.0,      0.000,      0.000,         0,     10.2951,      0.0780
       0.0,      0.000,      0.000,         0,     10.2951,      0.0786
       0.0,      0.000,      0.000,         0,     10.2951,      0.0792
       0.0,      0.000,      0.000,         0,     10.2951,      0.0797
       0.0,      0.000,      0.000,         0,     10.2952,      0.0803
       0.0,      0.000,      0.000,         0,     10.2952,      0.0808
       0.0,      0.000,      0.000,         0,     10.2952,      0.0814
       0.0,      0.000,      0.000,         0,     10.2952,      0.0819
       0.0,      0.000,      0.000,         0,     10.2952,      0.0825
       0.0,      0.000,      0.000,         0,     10.2953,      0.0830
       0.0,      0.000,      0.000,         0,     10.2953,      0.0836
       0.0,      0.000,      0.000,         0,     10.2953,      0.0841
       0.0,      0.000,      0.000,         0,     10.2954,      0.0847
       0.0,      0.000,      0.000,         0,     10.2955,      0.0852
       0.0,      0.000,      0.000,         0,     10.2957,      0.0858
       0.0,      0.000,      0.000,         0,     10.2960,      0.0863
       0.0,      0.000,      0.000,         0,     10.2964,      0.0869
       0.0,      0.000,      0.000,         0,     10.2967,      0.0875
       0.0,      0.000,      0.000,         0,     10.2969,      0.0880
       0.0,      0.000,      0.000,         0,     10.2969,      0.0886
       0.0,      0.000,      0.000,         0,     10.2969,      0.0891
       0.0,      0.000,      0.000,         0,     10.2969,      0.0897
       0.0,      0.000,      0.000,         0,     10.2969,      0.0902
       0.0,      0.000,      0.000,         0,     10.2969,      0.0908
       0.0,      0.000,      0.000,         0,     10.2969,      0.0913
       0.0,      0.000,      0.000,         0,     10.2969,      0.0919
       0.0,      0.000,      0.000,         0,     10.2969,      0.0924
       0.0,      0.000,      0.000,         0,     10.2969,      0.0930
       0.0,      0.000,      0.000,         0,     10.2969,      0.0935
       0.0,      0.000,      0.000,         0,     10.2969,      0.0941
       0.0,      0.000,      0.000,         0,     10.2969,      0.0946
       0.0,      0.000,      0.000,         0,     10.2969,      0.0952
       0.0,      0.000,      0.000,         0,     10.2969,      0.0958
       0.0,      0.000,      0.000,         0,     10.2969,      0.0963
       0.0,      0.000,      0.000,         0,     10.2968,      0.0969
       0.0,      0.000,      0.000,         0,     10.2968,      0.0974
       0.0,      0.000,      0.000,         0,     10.2969,      0.0980
       0.0,      0.000,      0.000,         0,     10.2968,      0.0985
       0.0,      0.000,      0.000,         0,     10.2969,      0.0991
       0.0,      0.000,      0.000,         0,     10.2968,      0.0996
       0.0,      0.000,      0.000,         0,     10.2969,      0.1002
       0.0,      0.000,      0.000,         0,     10.2969,      0.1007
       0.0,      0.000,      0.000,         0,     10.2969,      0.1013
       0.0,      0.000,      0.000,         0,     10.2969,      0.1018
       0.0,      0.000,      0.000,         0,     10.2969,      0.1024
       0.0,      0.000,      0.000,         0,     10.2969,      0.1029
       0.0,      0.000,      0.000,         0,     10.2968,      0.1035
       0.0,      0.000,      0.000,         0,     10.2969,      0.1041
       0.0,      0.000,      0.000,         0,     10.2969,      0.1046
       0.0,      0.000,      0.000,         0,     10.2968,      0.1052
       0.0,      0.000,      0.000,         0,     10.2969,      0.1057
       0.0,      0.000,      0.000,         0,     10.2969,      0.1063
       0.0,      0.000,      0.000,         0,     10.2968,      0.1068
       0.0,      0.000,      0.000,         0,     10.2968,      0.1074
       0.0,      0.000,      0.000,         0,     10.2969,      0.1079
       0.0,      0.000,      0.000,         0,     10.2968,      0.1085
       0.0,      0.000,      0.000,         0,     10.2968,      0.1090
       0.0,      0.000,      0.000,         0,     10.2969,      0.1096
       0.0,      0.000,      0.000,         0,     10.2969,      0.1101
       0.0,      0.000,      0.000,         0,     10.2968,      0.1107
       0.0,      0.000,      0.000,         0,     10.2968,      0.1112
       0.0,      0.000,      0.000,         0,     10.2969,      0.1118