File: Alban repo/Quiz 1/suction cup instron tests/oct-dec-2019_raw-data/d30e10-01-inair-on80grit-diaphragmpump-10mm-test1.raw
Operator: 1

Date,Time,Specimen#
10/25/19,18:14:27,1

---------------------------------------


Area (mm^2):,      1.00,Flat,     25.40,     25.40,     25.40
Gage Len (mm):,     25.40


LOAD (N),STRAIN 1 (mm),STRAIN 2 (mm),STRESS (MPa),POSITION (mm),TIME (min)
      13.6,      0.000,      0.000,         0,     -0.1620,      0.0083
      13.3,      0.000,      0.000,         0,     -0.3289,      0.0167
      12.9,      0.000,      0.000,         0,     -0.4954,      0.0250
      12.4,      0.000,      0.000,         0,     -0.6621,      0.0333
      12.0,      0.000,      0.000,         0,     -0.8287,      0.0417
      11.6,      0.000,      0.000,         0,     -0.9954,      0.0500
      11.1,      0.000,      0.000,         0,     -1.1620,      0.0583
      10.7,      0.000,      0.000,         0,     -1.3287,      0.0667
      10.3,      0.000,      0.000,         0,     -1.4952,      0.0750
       9.9,      0.000,      0.000,         0,     -1.6620,      0.0833
       9.5,      0.000,      0.000,         0,     -1.8286,      0.0917
       9.1,      0.000,      0.000,         0,     -1.9952,      0.1000
       8.7,      0.000,      0.000,         0,     -2.1621,      0.1083
       8.3,      0.000,      0.000,         0,     -2.3286,      0.1167
       8.0,      0.000,      0.000,         0,     -2.4953,      0.1250
       7.6,      0.000,      0.000,         0,     -2.6621,      0.1333
       7.2,      0.000,      0.000,         0,     -2.8287,      0.1417
       6.8,      0.000,      0.000,         0,     -2.9954,      0.1500
       6.3,      0.000,      0.000,         0,     -3.1947,      0.1600
       5.8,      0.000,      0.000,         0,     -3.3872,      0.1696
       5.3,      0.000,      0.000,         0,     -3.5539,      0.1779
       4.8,      0.000,      0.000,         0,     -3.7206,      0.1863
       3.9,      0.000,      0.000,         0,     -4.0529,      0.2029
       3.3,      0.000,      0.000,         0,     -4.2507,      0.2128
       2.8,      0.000,      0.000,         0,     -4.4376,      0.2221
       2.2,      0.000,      0.000,         0,     -4.6300,      0.2317
       1.5,      0.000,      0.000,         0,     -4.8382,      0.2422
       0.9,      0.000,      0.000,         0,     -5.0167,      0.2511
       0.2,      0.000,      0.000,         0,     -5.2176,      0.2611
      -0.7,      0.000,      0.000,         0,     -5.4155,      0.2710
      -1.6,      0.000,      0.000,         0,     -5.6126,      0.2809
      -2.5,      0.000,      0.000,         0,     -5.8105,      0.2908
      -3.4,      0.000,      0.000,         0,     -6.0030,      0.3004
      -4.5,      0.000,      0.000,         0,     -6.2005,      0.3103
      -5.5,      0.000,      0.000,         0,     -6.3672,      0.3186
      -6.7,      0.000,      0.000,         0,     -6.5338,      0.3269
      -8.1,      0.000,      0.000,         0,     -6.7006,      0.3353
     -10.2,      0.000,      0.000,         0,     -6.8671,      0.3436
     -13.1,      0.000,      0.000,         0,     -7.0340,      0.3519
     -15.5,      0.000,      0.000,         0,     -7.1579,      0.3731
     -15.3,      0.000,      0.000,         0,     -7.1579,      0.3897
     -15.2,      0.000,      0.000,         0,     -7.1579,      0.4064
     -15.1,      0.000,      0.000,         0,     -7.1579,      0.4231
     -15.0,      0.000,      0.000,         0,     -7.1578,      0.4397
     -15.0,      0.000,      0.000,         0,     -7.1577,      0.4564
     -14.9,      0.000,      0.000,         0,     -7.1576,      0.4731
     -14.9,      0.000,      0.000,         0,     -7.1575,      0.4897
     -14.9,      0.000,      0.000,         0,     -7.1573,      0.5064
     -14.8,      0.000,      0.000,         0,     -7.1337,      0.5231
     -14.7,      0.000,      0.000,         0,     -7.1267,      0.5397
     -14.6,      0.000,      0.000,         0,     -7.1254,      0.5564
     -14.6,      0.000,      0.000,         0,     -7.1251,      0.5731
     -14.6,      0.000,      0.000,         0,     -7.1240,      0.5897
     -14.5,      0.000,      0.000,         0,     -7.1232,      0.6064
     -12.8,      0.000,      0.000,         0,     -7.0587,      0.6147
     -10.9,      0.000,      0.000,         0,     -6.9753,      0.6231
      -9.3,      0.000,      0.000,         0,     -6.8912,      0.6314
      -8.0,      0.000,      0.000,         0,     -6.8066,      0.6397
      -7.0,      0.000,      0.000,         0,     -6.7231,      0.6481
      -6.2,      0.000,      0.000,         0,     -6.6400,      0.6564
      -5.5,      0.000,      0.000,         0,     -6.5564,      0.6647
      -4.9,      0.000,      0.000,         0,     -6.4732,      0.6731
      -4.4,      0.000,      0.000,         0,     -6.3898,      0.6814
      -3.9,      0.000,      0.000,         0,     -6.3063,      0.6897
      -3.4,      0.000,      0.000,         0,     -6.2230,      0.6981
      -2.9,      0.000,      0.000,         0,     -6.1397,      0.7064
      -2.4,      0.000,      0.000,         0,     -6.0563,      0.7147
      -2.0,      0.000,      0.000,         0,     -5.9731,      0.7231
      -1.6,      0.000,      0.000,         0,     -5.8899,      0.7314
      -1.1,      0.000,      0.000,         0,     -5.8063,      0.7397
      -0.7,      0.000,      0.000,         0,     -5.7232,      0.7481
      -0.3,      0.000,      0.000,         0,     -5.6399,      0.7564
       0.0,      0.000,      0.000,         0,     -5.5565,      0.7647
       0.4,      0.000,      0.000,         0,     -5.4731,      0.7731
       0.7,      0.000,      0.000,         0,     -5.3897,      0.7814
       1.1,      0.000,      0.000,         0,     -5.3065,      0.7897
       1.4,      0.000,      0.000,         0,     -5.2230,      0.7981
       1.7,      0.000,      0.000,         0,     -5.1397,      0.8064
       2.0,      0.000,      0.000,         0,     -5.0567,      0.8147
       2.3,      0.000,      0.000,         0,     -4.9731,      0.8231
       2.6,      0.000,      0.000,         0,     -4.8898,      0.8314
       2.9,      0.000,      0.000,         0,     -4.8066,      0.8397
       3.2,      0.000,      0.000,         0,     -4.7231,      0.8481
       3.4,      0.000,      0.000,         0,     -4.6398,      0.8564
       3.7,      0.000,      0.000,         0,     -4.5564,      0.8647
       4.0,      0.000,      0.000,         0,     -4.4734,      0.8731
       4.2,      0.000,      0.000,         0,     -4.3898,      0.8814
       4.4,      0.000,      0.000,         0,     -4.3065,      0.8897
       4.7,      0.000,      0.000,         0,     -4.2230,      0.8981
       4.9,      0.000,      0.000,         0,     -4.1399,      0.9064
       5.1,      0.000,      0.000,         0,     -4.0566,      0.9147
       5.3,      0.000,      0.000,         0,     -3.9731,      0.9231
       5.7,      0.000,      0.000,         0,     -3.8897,      0.9314
       6.0,      0.000,      0.000,         0,     -3.8066,      0.9397
       6.3,      0.000,      0.000,         0,     -3.7231,      0.9481
       6.5,      0.000,      0.000,         0,     -3.6398,      0.9564
       6.7,      0.000,      0.000,         0,     -3.5566,      0.9647
       6.9,      0.000,      0.000,         0,     -3.4731,      0.9731
       7.0,      0.000,      0.000,         0,     -3.3899,      0.9814
       7.2,      0.000,      0.000,         0,     -3.3065,      0.9897
       7.4,      0.000,      0.000,         0,     -3.2233,      0.9981
       7.6,      0.000,      0.000,         0,     -3.1398,      1.0064
       7.8,      0.000,      0.000,         0,     -3.0567,      1.0147
       8.0,      0.000,      0.000,         0,     -2.9732,      1.0231
       8.2,      0.000,      0.000,         0,     -2.8898,      1.0314
       8.4,      0.000,      0.000,         0,     -2.8064,      1.0397
       8.5,      0.000,      0.000,         0,     -2.7233,      1.0481
       8.7,      0.000,      0.000,         0,     -2.6400,      1.0564
       8.9,      0.000,      0.000,         0,     -2.5564,      1.0647
       9.1,      0.000,      0.000,         0,     -2.4732,      1.0731
       9.3,      0.000,      0.000,         0,     -2.3900,      1.0814
       9.5,      0.000,      0.000,         0,     -2.3065,      1.0897
       9.6,      0.000,      0.000,         0,     -2.2230,      1.0981
       9.8,      0.000,      0.000,         0,     -2.1399,      1.1064
      10.0,      0.000,      0.000,         0,     -2.0567,      1.1147
      10.2,      0.000,      0.000,         0,     -1.9731,      1.1231
      10.3,      0.000,      0.000,         0,     -1.8899,      1.1314
      10.5,      0.000,      0.000,         0,     -1.8067,      1.1397
      10.7,      0.000,      0.000,         0,     -1.7233,      1.1481
      10.9,      0.000,      0.000,         0,     -1.6398,      1.1564
      11.0,      0.000,      0.000,         0,     -1.5566,      1.1647
      11.2,      0.000,      0.000,         0,     -1.4733,      1.1731
      11.4,      0.000,      0.000,         0,     -1.3900,      1.1814
      11.5,      0.000,      0.000,         0,     -1.3064,      1.1897
      11.7,      0.000,      0.000,         0,     -1.2234,      1.1981
      11.9,      0.000,      0.000,         0,     -1.1399,      1.2064
      12.1,      0.000,      0.000,         0,     -1.0566,      1.2147
      12.2,      0.000,      0.000,         0,     -0.9733,      1.2231
      12.4,      0.000,      0.000,         0,     -0.8900,      1.2314
      12.6,      0.000,      0.000,         0,     -0.8066,      1.2397
      12.8,      0.000,      0.000,         0,     -0.7232,      1.2481
      12.9,      0.000,      0.000,         0,     -0.6399,      1.2564
      13.1,      0.000,      0.000,         0,     -0.5567,      1.2647
      13.3,      0.000,      0.000,         0,     -0.4733,      1.2731
      13.4,      0.000,      0.000,         0,     -0.3900,      1.2814
      13.6,      0.000,      0.000,         0,     -0.3067,      1.2897
      13.8,      0.000,      0.000,         0,     -0.2232,      1.2981
      13.9,      0.000,      0.000,         0,     -0.1400,      1.3064
      14.1,      0.000,      0.000,         0,     -0.0567,      1.3147
      14.3,      0.000,      0.000,         0,      0.0266,      1.3231
      14.4,      0.000,      0.000,         0,      0.1100,      1.3314
      14.6,      0.000,      0.000,         0,      0.1932,      1.3397
      14.8,      0.000,      0.000,         0,      0.2766,      1.3481
      14.9,      0.000,      0.000,         0,      0.3601,      1.3564
      15.1,      0.000,      0.000,         0,      0.4435,      1.3647
      15.2,      0.000,      0.000,         0,      0.5266,      1.3731
      15.3,      0.000,      0.000,         0,      0.6099,      1.3814
      15.5,      0.000,      0.000,         0,      0.6933,      1.3897
      15.7,      0.000,      0.000,         0,      0.7766,      1.3981
      15.9,      0.000,      0.000,         0,      0.8599,      1.4064
      16.0,      0.000,      0.000,         0,      0.9434,      1.4147
      16.2,      0.000,      0.000,         0,      1.0268,      1.4231
      16.4,      0.000,      0.000,         0,      1.1100,      1.4314
      16.5,      0.000,      0.000,         0,      1.1931,      1.4397
      16.7,      0.000,      0.000,         0,      1.2764,      1.4481
      16.8,      0.000,      0.000,         0,      1.3600,      1.4564
      17.0,      0.000,      0.000,         0,      1.4432,      1.4647
      17.1,      0.000,      0.000,         0,      1.5267,      1.4731
      17.3,      0.000,      0.000,         0,      1.6098,      1.4814
      17.4,      0.000,      0.000,         0,      1.6931,      1.4897
      17.6,      0.000,      0.000,         0,      1.7764,      1.4981
      17.7,      0.000,      0.000,         0,      1.8600,      1.5064
      17.9,      0.000,      0.000,         0,      1.9432,      1.5147
      18.0,      0.000,      0.000,         0,      2.0263,      1.5231
      18.2,      0.000,      0.000,         0,      2.1099,      1.5314
      18.3,      0.000,      0.000,         0,      2.1933,      1.5397
      18.5,      0.000,      0.000,         0,      2.2765,      1.5481
      18.6,      0.000,      0.000,         0,      2.3598,      1.5564
      18.8,      0.000,      0.000,         0,      2.4433,      1.5647
      18.9,      0.000,      0.000,         0,      2.5263,      1.5731
      19.0,      0.000,      0.000,         0,      2.6097,      1.5814
      19.2,      0.000,      0.000,         0,      2.6932,      1.5897
      19.3,      0.000,      0.000,         0,      2.7767,      1.5981
      19.4,      0.000,      0.000,         0,      2.8599,      1.6064
      19.6,      0.000,      0.000,         0,      2.9432,      1.6147
      19.7,      0.000,      0.000,         0,      3.0266,      1.6231
      19.8,      0.000,      0.000,         0,      3.1099,      1.6314
      19.9,      0.000,      0.000,         0,      3.1932,      1.6397
      20.0,      0.000,      0.000,         0,      3.2765,      1.6481
      20.2,      0.000,      0.000,         0,      3.3599,      1.6564
      20.2,      0.000,      0.000,         0,      3.4429,      1.6647
      20.4,      0.000,      0.000,         0,      3.5265,      1.6731
      20.5,      0.000,      0.000,         0,      3.6099,      1.6814
      20.6,      0.000,      0.000,         0,      3.6933,      1.6897
      20.6,      0.000,      0.000,         0,      3.7764,      1.6981
      20.7,      0.000,      0.000,         0,      3.8598,      1.7064
      20.8,      0.000,      0.000,         0,      3.9431,      1.7147
      20.8,      0.000,      0.000,         0,      4.0266,      1.7231
      20.9,      0.000,      0.000,         0,      4.1098,      1.7314
      21.0,      0.000,      0.000,         0,      4.1932,      1.7397
      21.1,      0.000,      0.000,         0,      4.2766,      1.7481
      21.2,      0.000,      0.000,         0,      4.3598,      1.7564
      21.2,      0.000,      0.000,         0,      4.4431,      1.7647
      21.3,      0.000,      0.000,         0,      4.5263,      1.7731
      21.5,      0.000,      0.000,         0,      4.6099,      1.7814
      21.6,      0.000,      0.000,         0,      4.6930,      1.7897
      21.7,      0.000,      0.000,         0,      4.7765,      1.7981
      21.2,      0.000,      0.000,         0,      4.8596,      1.8064
       0.0,      0.000,      0.000,         0,      4.9432,      1.8147
       0.0,      0.000,      0.000,         0,      5.0264,      1.8231
       0.0,      0.000,      0.000,         0,      5.1098,      1.8314
       0.0,      0.000,      0.000,         0,      5.1930,      1.8397
       0.0,      0.000,      0.000,         0,      5.2764,      1.8481
       0.0,      0.000,      0.000,         0,      5.3598,      1.8564
       0.0,      0.000,      0.000,         0,      5.4432,      1.8647
       0.0,      0.000,      0.000,         0,      5.5264,      1.8731
       0.0,      0.000,      0.000,         0,      5.6096,      1.8814
       0.0,      0.000,      0.000,         0,      5.6933,      1.8897
       0.0,      0.000,      0.000,         0,      5.7764,      1.8981
       0.0,      0.000,      0.000,         0,      5.8596,      1.9064