File: Alban repo/Quiz 1/suction cup instron tests/oct-dec-2019_raw-data/d30e10-01-inwater-onwhiteplatic-diaphragmpump-100mm-test2.raw
Operator: 1

Date,Time,Specimen#
10/25/19,17:35:58,1

---------------------------------------


Area (mm^2):,      1.00,Flat,     25.40,     25.40,     25.40
Gage Len (mm):,     25.40


LOAD (N),STRAIN 1 (mm),STRAIN 2 (mm),STRESS (MPa),POSITION (mm),TIME (min)
      18.0,      0.000,      0.000,         0,     -0.1620,      0.0083
      20.9,      0.000,      0.000,         0,     -0.3288,      0.0167
      21.2,      0.000,      0.000,         0,     -0.4954,      0.0250
      21.0,      0.000,      0.000,         0,     -0.6619,      0.0333
      20.7,      0.000,      0.000,         0,     -0.8287,      0.0417
      20.4,      0.000,      0.000,         0,     -0.9955,      0.0500
      20.0,      0.000,      0.000,         0,     -1.1619,      0.0583
      19.6,      0.000,      0.000,         0,     -1.3288,      0.0667
      19.2,      0.000,      0.000,         0,     -1.4954,      0.0750
      18.8,      0.000,      0.000,         0,     -1.6620,      0.0833
      18.4,      0.000,      0.000,         0,     -1.8288,      0.0917
      18.0,      0.000,      0.000,         0,     -1.9953,      0.1000
      17.6,      0.000,      0.000,         0,     -2.1620,      0.1083
      17.2,      0.000,      0.000,         0,     -2.3287,      0.1167
      16.8,      0.000,      0.000,         0,     -2.4952,      0.1250
      16.3,      0.000,      0.000,         0,     -2.6620,      0.1333
      15.9,      0.000,      0.000,         0,     -2.8284,      0.1417
      15.5,      0.000,      0.000,         0,     -2.9955,      0.1500
      15.0,      0.000,      0.000,         0,     -3.1619,      0.1583
      14.5,      0.000,      0.000,         0,     -3.3287,      0.1667
      14.1,      0.000,      0.000,         0,     -3.4952,      0.1750
      13.6,      0.000,      0.000,         0,     -3.6620,      0.1833
      13.1,      0.000,      0.000,         0,     -3.8286,      0.1917
      12.5,      0.000,      0.000,         0,     -3.9952,      0.2000
      12.0,      0.000,      0.000,         0,     -4.1618,      0.2083
      11.4,      0.000,      0.000,         0,     -4.3286,      0.2167
      10.8,      0.000,      0.000,         0,     -4.4954,      0.2250
      10.2,      0.000,      0.000,         0,     -4.6618,      0.2333
       9.6,      0.000,      0.000,         0,     -4.8284,      0.2417
       9.0,      0.000,      0.000,         0,     -4.9951,      0.2500
       8.3,      0.000,      0.000,         0,     -5.1619,      0.2583
       7.6,      0.000,      0.000,         0,     -5.3286,      0.2667
       6.9,      0.000,      0.000,         0,     -5.4951,      0.2750
       6.2,      0.000,      0.000,         0,     -5.6620,      0.2833
       5.4,      0.000,      0.000,         0,     -5.8286,      0.2917
       4.6,      0.000,      0.000,         0,     -5.9953,      0.3000
       3.7,      0.000,      0.000,         0,     -6.1619,      0.3083
       2.7,      0.000,      0.000,         0,     -6.3284,      0.3167
       1.6,      0.000,      0.000,         0,     -6.4951,      0.3250
       0.3,      0.000,      0.000,         0,     -6.6618,      0.3333
      -1.7,      0.000,      0.000,         0,     -6.8284,      0.3417
      -3.6,      0.000,      0.000,         0,     -6.9951,      0.3500
      -5.2,      0.000,      0.000,         0,     -7.1618,      0.3583
      -8.4,      0.000,      0.000,         0,     -7.3285,      0.3667
     -11.7,      0.000,      0.000,         0,     -7.4951,      0.3750
     -14.1,      0.000,      0.000,         0,     -7.6798,      0.3992
     -13.2,      0.000,      0.000,         0,     -7.6799,      0.4158
     -12.7,      0.000,      0.000,         0,     -7.6799,      0.4325
     -12.4,      0.000,      0.000,         0,     -7.6798,      0.4492
     -12.1,      0.000,      0.000,         0,     -7.6798,      0.4658
     -11.9,      0.000,      0.000,         0,     -7.6797,      0.4825
     -11.7,      0.000,      0.000,         0,     -7.6796,      0.4992
     -11.6,      0.000,      0.000,         0,     -7.6794,      0.5158
     -11.4,      0.000,      0.000,         0,     -7.6792,      0.5325
     -11.3,      0.000,      0.000,         0,     -7.6547,      0.5492
     -11.0,      0.000,      0.000,         0,     -7.6481,      0.5658
     -10.9,      0.000,      0.000,         0,     -7.6464,      0.5825
     -10.8,      0.000,      0.000,         0,     -7.6458,      0.5992
     -10.7,      0.000,      0.000,         0,     -7.6445,      0.6158
     -10.7,      0.000,      0.000,         0,     -7.6446,      0.6325
       4.7,      0.000,      0.000,         0,     -6.9756,      0.6408
      13.6,      0.000,      0.000,         0,     -6.1420,      0.6492
      19.2,      0.000,      0.000,         0,     -5.3085,      0.6575
      23.1,      0.000,      0.000,         0,     -4.4747,      0.6658
      25.9,      0.000,      0.000,         0,     -3.6400,      0.6742
      28.3,      0.000,      0.000,         0,     -2.8066,      0.6825
      30.7,      0.000,      0.000,         0,     -1.9734,      0.6908
      33.1,      0.000,      0.000,         0,     -1.1399,      0.6992
      35.6,      0.000,      0.000,         0,     -0.3069,      0.7075
      37.7,      0.000,      0.000,         0,      0.5266,      0.7158
      40.2,      0.000,      0.000,         0,      1.3599,      0.7242
      42.7,      0.000,      0.000,         0,      2.1930,      0.7325
      45.2,      0.000,      0.000,         0,      3.0264,      0.7408
      47.5,      0.000,      0.000,         0,      3.8597,      0.7492
      49.6,      0.000,      0.000,         0,      4.6929,      0.7575
      51.4,      0.000,      0.000,         0,      5.5262,      0.7658
      52.5,      0.000,      0.000,         0,      6.3595,      0.7742
       3.9,      0.000,      0.000,         0,      7.1929,      0.7825
       0.1,      0.000,      0.000,         0,      8.0261,      0.7908
       0.1,      0.000,      0.000,         0,      8.8592,      0.7992
       0.1,      0.000,      0.000,         0,      9.6927,      0.8075
       0.1,      0.000,      0.000,         0,     10.5259,      0.8158
       0.1,      0.000,      0.000,         0,     11.3592,      0.8242
       0.2,      0.000,      0.000,         0,     12.1923,      0.8325
       0.2,      0.000,      0.000,         0,     13.0258,      0.8408
       0.2,      0.000,      0.000,         0,     13.8590,      0.8492