File: Alban repo/Quiz 1/suction cup instron tests/oct-dec-2019_raw-data/d30e10-01-inair-onwhiteplatic-diaphragmpump-10mm-test2.raw
Operator: 1

Date,Time,Specimen#
10/25/19,16:19:53,1

---------------------------------------


Area (mm^2):,      1.00,Flat,     25.40,     25.40,     25.40
Gage Len (mm):,     25.40


LOAD (N),STRAIN 1 (mm),STRAIN 2 (mm),STRESS (MPa),POSITION (mm),TIME (min)
      14.1,      0.000,      0.000,         0,     -0.1621,      0.0083
      13.8,      0.000,      0.000,         0,     -0.3289,      0.0167
      13.4,      0.000,      0.000,         0,     -0.4954,      0.0250
      13.0,      0.000,      0.000,         0,     -0.6622,      0.0333
      12.5,      0.000,      0.000,         0,     -0.8287,      0.0417
      12.1,      0.000,      0.000,         0,     -0.9954,      0.0500
      11.7,      0.000,      0.000,         0,     -1.1622,      0.0583
      11.3,      0.000,      0.000,         0,     -1.3286,      0.0667
      10.9,      0.000,      0.000,         0,     -1.4955,      0.0750
      10.4,      0.000,      0.000,         0,     -1.6619,      0.0833
      10.0,      0.000,      0.000,         0,     -1.8289,      0.0917
       9.6,      0.000,      0.000,         0,     -1.9955,      0.1000
       9.2,      0.000,      0.000,         0,     -2.1622,      0.1083
       8.9,      0.000,      0.000,         0,     -2.3287,      0.1167
       8.5,      0.000,      0.000,         0,     -2.4955,      0.1250
       8.1,      0.000,      0.000,         0,     -2.6619,      0.1333
       7.7,      0.000,      0.000,         0,     -2.8287,      0.1417
       7.4,      0.000,      0.000,         0,     -2.9953,      0.1500
       7.0,      0.000,      0.000,         0,     -3.1619,      0.1583
       6.6,      0.000,      0.000,         0,     -3.3286,      0.1667
       6.2,      0.000,      0.000,         0,     -3.4952,      0.1750
       5.8,      0.000,      0.000,         0,     -3.6619,      0.1833
       5.4,      0.000,      0.000,         0,     -3.8287,      0.1917
       4.9,      0.000,      0.000,         0,     -3.9953,      0.2000
       4.5,      0.000,      0.000,         0,     -4.1621,      0.2083
       4.0,      0.000,      0.000,         0,     -4.3285,      0.2167
       3.6,      0.000,      0.000,         0,     -4.4953,      0.2250
       3.1,      0.000,      0.000,         0,     -4.6620,      0.2333
       2.5,      0.000,      0.000,         0,     -4.8286,      0.2417
       2.0,      0.000,      0.000,         0,     -4.9952,      0.2500
       1.4,      0.000,      0.000,         0,     -5.1619,      0.2583
       0.8,      0.000,      0.000,         0,     -5.3286,      0.2667
       0.1,      0.000,      0.000,         0,     -5.4953,      0.2750
      -0.5,      0.000,      0.000,         0,     -5.6619,      0.2833
      -1.3,      0.000,      0.000,         0,     -5.8286,      0.2917
      -2.0,      0.000,      0.000,         0,     -5.9953,      0.3000
      -2.8,      0.000,      0.000,         0,     -6.1619,      0.3083
      -3.5,      0.000,      0.000,         0,     -6.3287,      0.3167
      -3.8,      0.000,      0.000,         0,     -6.4951,      0.3250
      -5.0,      0.000,      0.000,         0,     -6.6619,      0.3333
      -6.1,      0.000,      0.000,         0,     -6.8286,      0.3417
      -7.4,      0.000,      0.000,         0,     -6.9951,      0.3500
     -10.1,      0.000,      0.000,         0,     -7.1619,      0.3583
     -13.7,      0.000,      0.000,         0,     -7.3285,      0.3667
     -15.5,      0.000,      0.000,         0,     -7.4201,      0.3860
     -15.2,      0.000,      0.000,         0,     -7.4202,      0.4027
     -15.0,      0.000,      0.000,         0,     -7.4201,      0.4194
     -14.9,      0.000,      0.000,         0,     -7.4201,      0.4360
     -14.8,      0.000,      0.000,         0,     -7.4201,      0.4527
     -14.7,      0.000,      0.000,         0,     -7.4200,      0.4694
     -14.6,      0.000,      0.000,         0,     -7.4200,      0.4860
     -14.6,      0.000,      0.000,         0,     -7.4199,      0.5027
     -14.6,      0.000,      0.000,         0,     -7.4198,      0.5194
     -14.5,      0.000,      0.000,         0,     -7.3929,      0.5360
     -14.2,      0.000,      0.000,         0,     -7.3839,      0.5527
     -14.1,      0.000,      0.000,         0,     -7.3834,      0.5694
     -14.1,      0.000,      0.000,         0,     -7.3832,      0.5860
     -14.1,      0.000,      0.000,         0,     -7.3825,      0.6027
     -14.0,      0.000,      0.000,         0,     -7.3812,      0.6194
     -12.1,      0.000,      0.000,         0,     -7.3186,      0.6277
     -10.0,      0.000,      0.000,         0,     -7.2350,      0.6360
      -8.2,      0.000,      0.000,         0,     -7.1508,      0.6444
      -6.7,      0.000,      0.000,         0,     -7.0681,      0.6527
      -5.3,      0.000,      0.000,         0,     -6.9832,      0.6610
      -4.0,      0.000,      0.000,         0,     -6.9000,      0.6694
      -3.3,      0.000,      0.000,         0,     -6.8166,      0.6777
      -2.9,      0.000,      0.000,         0,     -6.7332,      0.6860
      -2.4,      0.000,      0.000,         0,     -6.6500,      0.6944
      -2.0,      0.000,      0.000,         0,     -6.5667,      0.7027
      -1.5,      0.000,      0.000,         0,     -6.4833,      0.7110
      -1.1,      0.000,      0.000,         0,     -6.4002,      0.7194
      -0.6,      0.000,      0.000,         0,     -6.3166,      0.7277
      -0.2,      0.000,      0.000,         0,     -6.2333,      0.7360
       0.3,      0.000,      0.000,         0,     -6.1499,      0.7444
       0.7,      0.000,      0.000,         0,     -6.0666,      0.7527
       1.1,      0.000,      0.000,         0,     -5.9833,      0.7610
       1.2,      0.000,      0.000,         0,     -5.8999,      0.7694
       1.3,      0.000,      0.000,         0,     -5.8167,      0.7777
       1.7,      0.000,      0.000,         0,     -5.7333,      0.7860
       2.1,      0.000,      0.000,         0,     -5.6499,      0.7944
       2.5,      0.000,      0.000,         0,     -5.5667,      0.8027
       2.9,      0.000,      0.000,         0,     -5.4834,      0.8110
       3.2,      0.000,      0.000,         0,     -5.4000,      0.8194
       3.5,      0.000,      0.000,         0,     -5.3166,      0.8277
       3.9,      0.000,      0.000,         0,     -5.2333,      0.8360
       4.2,      0.000,      0.000,         0,     -5.1501,      0.8444
       4.5,      0.000,      0.000,         0,     -5.0666,      0.8527
       4.8,      0.000,      0.000,         0,     -4.9833,      0.8610
       5.0,      0.000,      0.000,         0,     -4.9001,      0.8694
       5.3,      0.000,      0.000,         0,     -4.8168,      0.8777
       5.6,      0.000,      0.000,         0,     -4.7333,      0.8860
       5.8,      0.000,      0.000,         0,     -4.6500,      0.8944
       6.1,      0.000,      0.000,         0,     -4.5668,      0.9027
       6.3,      0.000,      0.000,         0,     -4.4834,      0.9110
       6.5,      0.000,      0.000,         0,     -4.4000,      0.9194
       6.7,      0.000,      0.000,         0,     -4.3167,      0.9277
       7.0,      0.000,      0.000,         0,     -4.2335,      0.9360
       7.2,      0.000,      0.000,         0,     -4.1499,      0.9444
       7.4,      0.000,      0.000,         0,     -4.0666,      0.9527
       7.6,      0.000,      0.000,         0,     -3.9835,      0.9610
       7.8,      0.000,      0.000,         0,     -3.9001,      0.9694
       8.0,      0.000,      0.000,         0,     -3.8166,      0.9777
       8.1,      0.000,      0.000,         0,     -3.7335,      0.9860
       8.3,      0.000,      0.000,         0,     -3.6502,      0.9944
       8.5,      0.000,      0.000,         0,     -3.5667,      1.0027
       8.7,      0.000,      0.000,         0,     -3.4834,      1.0110
       8.9,      0.000,      0.000,         0,     -3.4002,      1.0194
       9.1,      0.000,      0.000,         0,     -3.3169,      1.0277
       9.3,      0.000,      0.000,         0,     -3.2332,      1.0360
       9.4,      0.000,      0.000,         0,     -3.1503,      1.0444
       9.6,      0.000,      0.000,         0,     -3.0667,      1.0527
       9.8,      0.000,      0.000,         0,     -2.9833,      1.0610
      10.0,      0.000,      0.000,         0,     -2.9000,      1.0694
      10.2,      0.000,      0.000,         0,     -2.8171,      1.0777
      10.3,      0.000,      0.000,         0,     -2.7334,      1.0860
      10.5,      0.000,      0.000,         0,     -2.6501,      1.0944
      10.7,      0.000,      0.000,         0,     -2.5668,      1.1027
      10.9,      0.000,      0.000,         0,     -2.4836,      1.1110
      11.0,      0.000,      0.000,         0,     -2.4001,      1.1194
      11.2,      0.000,      0.000,         0,     -2.3167,      1.1277
      11.3,      0.000,      0.000,         0,     -2.2335,      1.1360
      11.5,      0.000,      0.000,         0,     -2.1501,      1.1444
      11.7,      0.000,      0.000,         0,     -2.0667,      1.1527
      11.8,      0.000,      0.000,         0,     -1.9834,      1.1610
      12.0,      0.000,      0.000,         0,     -1.9002,      1.1694
      12.1,      0.000,      0.000,         0,     -1.8167,      1.1777
      12.3,      0.000,      0.000,         0,     -1.7335,      1.1860
      12.5,      0.000,      0.000,         0,     -1.6501,      1.1944
      12.6,      0.000,      0.000,         0,     -1.5670,      1.2027
      12.8,      0.000,      0.000,         0,     -1.4836,      1.2110
      13.0,      0.000,      0.000,         0,     -1.4002,      1.2194
      13.1,      0.000,      0.000,         0,     -1.3168,      1.2277
      13.3,      0.000,      0.000,         0,     -1.2335,      1.2360
      13.5,      0.000,      0.000,         0,     -1.1504,      1.2444
      13.6,      0.000,      0.000,         0,     -1.0668,      1.2527
      13.8,      0.000,      0.000,         0,     -0.9837,      1.2610
      14.0,      0.000,      0.000,         0,     -0.9000,      1.2694
      14.1,      0.000,      0.000,         0,     -0.8169,      1.2777
      14.3,      0.000,      0.000,         0,     -0.7335,      1.2860
      14.4,      0.000,      0.000,         0,     -0.6503,      1.2944
      14.6,      0.000,      0.000,         0,     -0.5668,      1.3027
      14.7,      0.000,      0.000,         0,     -0.4837,      1.3110
      14.9,      0.000,      0.000,         0,     -0.4002,      1.3194
      15.0,      0.000,      0.000,         0,     -0.3168,      1.3277
      15.2,      0.000,      0.000,         0,     -0.2335,      1.3360
      15.3,      0.000,      0.000,         0,     -0.1502,      1.3444
      15.5,      0.000,      0.000,         0,     -0.0669,      1.3527
      15.6,      0.000,      0.000,         0,      0.0166,      1.3610
      15.8,      0.000,      0.000,         0,      0.0997,      1.3694
      16.0,      0.000,      0.000,         0,      0.1831,      1.3777
      16.1,      0.000,      0.000,         0,      0.2665,      1.3860
      16.3,      0.000,      0.000,         0,      0.3498,      1.3944
      16.4,      0.000,      0.000,         0,      0.4329,      1.4027
      16.6,      0.000,      0.000,         0,      0.5164,      1.4110
      16.7,      0.000,      0.000,         0,      0.5998,      1.4194
      16.9,      0.000,      0.000,         0,      0.6830,      1.4277
      17.0,      0.000,      0.000,         0,      0.7663,      1.4360
      17.2,      0.000,      0.000,         0,      0.8497,      1.4444
      17.3,      0.000,      0.000,         0,      0.9331,      1.4527
      17.5,      0.000,      0.000,         0,      1.0165,      1.4610
      17.6,      0.000,      0.000,         0,      1.0998,      1.4694
      17.8,      0.000,      0.000,         0,      1.1832,      1.4777
      17.9,      0.000,      0.000,         0,      1.2662,      1.4860
      18.1,      0.000,      0.000,         0,      1.3497,      1.4944
      18.2,      0.000,      0.000,         0,      1.4331,      1.5027
      18.4,      0.000,      0.000,         0,      1.5162,      1.5110
      18.5,      0.000,      0.000,         0,      1.5998,      1.5194
      18.6,      0.000,      0.000,         0,      1.6829,      1.5277
      18.8,      0.000,      0.000,         0,      1.7664,      1.5360
      18.9,      0.000,      0.000,         0,      1.8496,      1.5444
      19.1,      0.000,      0.000,         0,      1.9330,      1.5527
      19.2,      0.000,      0.000,         0,      2.0164,      1.5610
      19.3,      0.000,      0.000,         0,      2.0997,      1.5694
      19.4,      0.000,      0.000,         0,      2.1831,      1.5777
      19.6,      0.000,      0.000,         0,      2.2664,      1.5860
      19.7,      0.000,      0.000,         0,      2.3498,      1.5944
      19.8,      0.000,      0.000,         0,      2.4329,      1.6027
      19.9,      0.000,      0.000,         0,      2.5163,      1.6110
      20.0,      0.000,      0.000,         0,      2.5996,      1.6194
      20.1,      0.000,      0.000,         0,      2.6832,      1.6277
      20.1,      0.000,      0.000,         0,      2.7662,      1.6360
      20.2,      0.000,      0.000,         0,      2.8494,      1.6444
      20.3,      0.000,      0.000,         0,      2.9331,      1.6527
      20.3,      0.000,      0.000,         0,      3.0163,      1.6610
      20.4,      0.000,      0.000,         0,      3.0996,      1.6694
      20.4,      0.000,      0.000,         0,      3.1829,      1.6777
      20.5,      0.000,      0.000,         0,      3.2665,      1.6860
      20.6,      0.000,      0.000,         0,      3.3496,      1.6944
      20.6,      0.000,      0.000,         0,      3.4329,      1.7027
      20.7,      0.000,      0.000,         0,      3.5163,      1.7110
      20.7,      0.000,      0.000,         0,      3.5997,      1.7194
      20.8,      0.000,      0.000,         0,      3.6828,      1.7277
      20.8,      0.000,      0.000,         0,      3.7663,      1.7360
      20.9,      0.000,      0.000,         0,      3.8496,      1.7444
      20.9,      0.000,      0.000,         0,      3.9330,      1.7527
      21.0,      0.000,      0.000,         0,      4.0162,      1.7610
      21.0,      0.000,      0.000,         0,      4.0997,      1.7694
      21.0,      0.000,      0.000,         0,      4.1829,      1.7777
      21.0,      0.000,      0.000,         0,      4.2663,      1.7860
      21.0,      0.000,      0.000,         0,      4.3495,      1.7944
       0.0,      0.000,      0.000,         0,      4.4330,      1.8027
       0.0,      0.000,      0.000,         0,      4.5163,      1.8110
       0.0,      0.000,      0.000,         0,      4.5996,      1.8194
       0.0,      0.000,      0.000,         0,      4.6830,      1.8277
       0.0,      0.000,      0.000,         0,      4.7661,      1.8360
       0.0,      0.000,      0.000,         0,      4.8495,      1.8444
       0.0,      0.000,      0.000,         0,      4.9330,      1.8527
       0.0,      0.000,      0.000,         0,      5.0163,      1.8610
       0.0,      0.000,      0.000,         0,      5.0994,      1.8694
       0.0,      0.000,      0.000,         0,      5.1829,      1.8777
       0.0,      0.000,      0.000,         0,      5.2662,      1.8860
       0.0,      0.000,      0.000,         0,      5.3495,      1.8944
       0.0,      0.000,      0.000,         0,      5.4327,      1.9027
       0.0,      0.000,      0.000,         0,      5.5163,      1.9110
       0.0,      0.000,      0.000,         0,      5.5997,      1.9194
       0.0,      0.000,      0.000,         0,      5.6827,      1.9277
       0.0,      0.000,      0.000,         0,      5.7663,      1.9360
       0.0,      0.000,      0.000,         0,      5.8495,      1.9444
       0.0,      0.000,      0.000,         0,      5.9329,      1.9527
       0.0,      0.000,      0.000,         0,      6.0162,      1.9610
       0.0,      0.000,      0.000,         0,      6.0994,      1.9694
       0.0,      0.000,      0.000,         0,      6.1829,      1.9777
       0.0,      0.000,      0.000,         0,      6.2662,      1.9860