File: Alban repo/Quiz 1/suction cup instron tests/oct-dec-2019_raw-data/d30e10-01-inwater-onwhiteplatic-nopump-10mm-test3.raw
Operator: 1

Date,Time,Specimen#
10/25/19,16:57:39,1

---------------------------------------


Area (mm^2):,      1.00,Flat,     25.40,     25.40,     25.40
Gage Len (mm):,     25.40


LOAD (N),STRAIN 1 (mm),STRAIN 2 (mm),STRESS (MPa),POSITION (mm),TIME (min)
       2.7,      0.000,      0.000,         0,      0.0807,      0.0083
       3.2,      0.000,      0.000,         0,      0.1641,      0.0167
       3.7,      0.000,      0.000,         0,      0.2475,      0.0250
       3.5,      0.000,      0.000,         0,      0.3308,      0.0333
       3.7,      0.000,      0.000,         0,      0.4141,      0.0417
       4.1,      0.000,      0.000,         0,      0.4974,      0.0500
       4.8,      0.000,      0.000,         0,      0.5806,      0.0583
       5.5,      0.000,      0.000,         0,      0.6641,      0.0667
       6.2,      0.000,      0.000,         0,      0.7472,      0.0750
       6.9,      0.000,      0.000,         0,      0.8308,      0.0833
       7.6,      0.000,      0.000,         0,      0.9141,      0.0917
       8.2,      0.000,      0.000,         0,      0.9974,      0.1000
       8.9,      0.000,      0.000,         0,      1.0808,      0.1083
       9.5,      0.000,      0.000,         0,      1.1641,      0.1167
      10.2,      0.000,      0.000,         0,      1.2474,      0.1250
      10.8,      0.000,      0.000,         0,      1.3307,      0.1333
      11.4,      0.000,      0.000,         0,      1.4142,      0.1417
      12.0,      0.000,      0.000,         0,      1.4973,      0.1500
      12.5,      0.000,      0.000,         0,      1.5806,      0.1583
      13.1,      0.000,      0.000,         0,      1.6640,      0.1667
      13.7,      0.000,      0.000,         0,      1.7475,      0.1750
      14.2,      0.000,      0.000,         0,      1.8307,      0.1833
      14.8,      0.000,      0.000,         0,      1.9140,      0.1917
      15.3,      0.000,      0.000,         0,      1.9976,      0.2000
      15.8,      0.000,      0.000,         0,      2.0807,      0.2083
      16.3,      0.000,      0.000,         0,      2.1639,      0.2167
      16.8,      0.000,      0.000,         0,      2.2472,      0.2250
      17.2,      0.000,      0.000,         0,      2.3309,      0.2333
      17.7,      0.000,      0.000,         0,      2.4140,      0.2417
      18.1,      0.000,      0.000,         0,      2.4973,      0.2500
      18.6,      0.000,      0.000,         0,      2.5807,      0.2583
      19.0,      0.000,      0.000,         0,      2.6641,      0.2667
      19.4,      0.000,      0.000,         0,      2.7472,      0.2750
      19.8,      0.000,      0.000,         0,      2.8306,      0.2833
      20.1,      0.000,      0.000,         0,      2.9139,      0.2917
      20.5,      0.000,      0.000,         0,      2.9973,      0.3000
      20.9,      0.000,      0.000,         0,      3.0806,      0.3083
      21.3,      0.000,      0.000,         0,      3.1640,      0.3167
      21.6,      0.000,      0.000,         0,      3.2474,      0.3250
      22.0,      0.000,      0.000,         0,      3.3306,      0.3333
      22.3,      0.000,      0.000,         0,      3.4138,      0.3417
      22.7,      0.000,      0.000,         0,      3.4973,      0.3500
      23.0,      0.000,      0.000,         0,      3.5807,      0.3583
      23.3,      0.000,      0.000,         0,      3.6639,      0.3667
      23.6,      0.000,      0.000,         0,      3.7473,      0.3750
      23.9,      0.000,      0.000,         0,      3.8304,      0.3833
      24.3,      0.000,      0.000,         0,      3.9140,      0.3917
      24.6,      0.000,      0.000,         0,      3.9972,      0.4000
      24.9,      0.000,      0.000,         0,      4.0807,      0.4083
      25.2,      0.000,      0.000,         0,      4.1639,      0.4167
      25.5,      0.000,      0.000,         0,      4.2472,      0.4250
      25.8,      0.000,      0.000,         0,      4.3305,      0.4333
      26.0,      0.000,      0.000,         0,      4.4139,      0.4417
      26.3,      0.000,      0.000,         0,      4.4972,      0.4500
      26.6,      0.000,      0.000,         0,      4.5805,      0.4583
      26.9,      0.000,      0.000,         0,      4.6641,      0.4667
      27.2,      0.000,      0.000,         0,      4.7473,      0.4750
      27.5,      0.000,      0.000,         0,      4.8305,      0.4833
      27.7,      0.000,      0.000,         0,      4.9138,      0.4917
      28.0,      0.000,      0.000,         0,      4.9974,      0.5000
      28.3,      0.000,      0.000,         0,      5.0804,      0.5083
      28.6,      0.000,      0.000,         0,      5.1637,      0.5167
      28.8,      0.000,      0.000,         0,      5.2473,      0.5250
      29.1,      0.000,      0.000,         0,      5.3306,      0.5333
      29.4,      0.000,      0.000,         0,      5.4137,      0.5417
      29.6,      0.000,      0.000,         0,      5.4971,      0.5500
      29.9,      0.000,      0.000,         0,      5.5806,      0.5583
      30.2,      0.000,      0.000,         0,      5.6637,      0.5667
      30.4,      0.000,      0.000,         0,      5.7471,      0.5750
      30.7,      0.000,      0.000,         0,      5.8305,      0.5833
      31.0,      0.000,      0.000,         0,      5.9139,      0.5917
      31.3,      0.000,      0.000,         0,      5.9971,      0.6000
      31.6,      0.000,      0.000,         0,      6.0805,      0.6083
      31.9,      0.000,      0.000,         0,      6.1639,      0.6167
      32.1,      0.000,      0.000,         0,      6.2471,      0.6250
      32.4,      0.000,      0.000,         0,      6.3303,      0.6333
      32.7,      0.000,      0.000,         0,      6.4139,      0.6417
      33.0,      0.000,      0.000,         0,      6.4971,      0.6500
      33.3,      0.000,      0.000,         0,      6.5804,      0.6583
      33.5,      0.000,      0.000,         0,      6.6639,      0.6667
      33.8,      0.000,      0.000,         0,      6.7472,      0.6750
      34.1,      0.000,      0.000,         0,      6.8304,      0.6833
      34.4,      0.000,      0.000,         0,      6.9138,      0.6917
      34.7,      0.000,      0.000,         0,      6.9972,      0.7000
      35.0,      0.000,      0.000,         0,      7.0803,      0.7083
      35.3,      0.000,      0.000,         0,      7.1636,      0.7167
      35.5,      0.000,      0.000,         0,      7.2471,      0.7250
      35.8,      0.000,      0.000,         0,      7.3306,      0.7333
      36.1,      0.000,      0.000,         0,      7.4136,      0.7417
      36.4,      0.000,      0.000,         0,      7.4972,      0.7500
      36.6,      0.000,      0.000,         0,      7.5805,      0.7583
      36.9,      0.000,      0.000,         0,      7.6637,      0.7667
      37.2,      0.000,      0.000,         0,      7.7471,      0.7750
      37.4,      0.000,      0.000,         0,      7.8304,      0.7833
      37.7,      0.000,      0.000,         0,      7.9137,      0.7917
      37.9,      0.000,      0.000,         0,      7.9971,      0.8000
      38.2,      0.000,      0.000,         0,      8.0803,      0.8083
      38.4,      0.000,      0.000,         0,      8.1636,      0.8167
      38.7,      0.000,      0.000,         0,      8.2471,      0.8250
      38.9,      0.000,      0.000,         0,      8.3304,      0.8333
      39.2,      0.000,      0.000,         0,      8.4137,      0.8417
      39.4,      0.000,      0.000,         0,      8.4971,      0.8500
      39.7,      0.000,      0.000,         0,      8.5803,      0.8583
      40.0,      0.000,      0.000,         0,      8.6637,      0.8667
      40.2,      0.000,      0.000,         0,      8.7470,      0.8750
      40.4,      0.000,      0.000,         0,      8.8304,      0.8833
      40.7,      0.000,      0.000,         0,      8.9137,      0.8917
      40.9,      0.000,      0.000,         0,      8.9970,      0.9000
      41.2,      0.000,      0.000,         0,      9.0804,      0.9083
      41.4,      0.000,      0.000,         0,      9.1637,      0.9167
      41.6,      0.000,      0.000,         0,      9.2469,      0.9250
      41.9,      0.000,      0.000,         0,      9.3304,      0.9333
      42.1,      0.000,      0.000,         0,      9.4137,      0.9417
      42.4,      0.000,      0.000,         0,      9.4970,      0.9500
      42.6,      0.000,      0.000,         0,      9.5803,      0.9583
      42.8,      0.000,      0.000,         0,      9.6638,      0.9667
      43.1,      0.000,      0.000,         0,      9.7469,      0.9750
      43.3,      0.000,      0.000,         0,      9.8302,      0.9833
      43.6,      0.000,      0.000,         0,      9.9137,      0.9917
      43.8,      0.000,      0.000,         0,      9.9969,      1.0000
      44.0,      0.000,      0.000,         0,     10.0802,      1.0083
      44.3,      0.000,      0.000,         0,     10.1637,      1.0167
      44.5,      0.000,      0.000,         0,     10.2471,      1.0250
      44.7,      0.000,      0.000,         0,     10.3302,      1.0333
      45.0,      0.000,      0.000,         0,     10.4137,      1.0417
      45.2,      0.000,      0.000,         0,     10.4969,      1.0500
      45.4,      0.000,      0.000,         0,     10.5804,      1.0583
      45.6,      0.000,      0.000,         0,     10.6636,      1.0667
      45.9,      0.000,      0.000,         0,     10.7470,      1.0750
      46.1,      0.000,      0.000,         0,     10.8303,      1.0833
      46.3,      0.000,      0.000,         0,     10.9137,      1.0917
      46.5,      0.000,      0.000,         0,     10.9969,      1.1000
      46.8,      0.000,      0.000,         0,     11.0804,      1.1083
      47.0,      0.000,      0.000,         0,     11.1636,      1.1167
      47.2,      0.000,      0.000,         0,     11.2470,      1.1250
      47.4,      0.000,      0.000,         0,     11.3304,      1.1333
      47.6,      0.000,      0.000,         0,     11.4135,      1.1417
      47.8,      0.000,      0.000,         0,     11.4970,      1.1500
      48.0,      0.000,      0.000,         0,     11.5803,      1.1583
      48.3,      0.000,      0.000,         0,     11.6636,      1.1667
      48.5,      0.000,      0.000,         0,     11.7469,      1.1750
      48.7,      0.000,      0.000,         0,     11.8303,      1.1833
      48.9,      0.000,      0.000,         0,     11.9136,      1.1917
      49.1,      0.000,      0.000,         0,     11.9970,      1.2000
      49.4,      0.000,      0.000,         0,     12.0800,      1.2083
      49.5,      0.000,      0.000,         0,     12.1636,      1.2167
      49.8,      0.000,      0.000,         0,     12.2469,      1.2250
      50.0,      0.000,      0.000,         0,     12.3302,      1.2333
      50.2,      0.000,      0.000,         0,     12.4135,      1.2417
      50.4,      0.000,      0.000,         0,     12.4969,      1.2500
      50.6,      0.000,      0.000,         0,     12.5802,      1.2583
      50.8,      0.000,      0.000,         0,     12.6635,      1.2667
      51.0,      0.000,      0.000,         0,     12.7469,      1.2750
      51.2,      0.000,      0.000,         0,     12.8301,      1.2833
      51.4,      0.000,      0.000,         0,     12.9136,      1.2917
      51.6,      0.000,      0.000,         0,     12.9968,      1.3000
      51.8,      0.000,      0.000,         0,     13.0801,      1.3083
      52.0,      0.000,      0.000,         0,     13.1634,      1.3167
      52.2,      0.000,      0.000,         0,     13.2469,      1.3250
      52.4,      0.000,      0.000,         0,     13.3302,      1.3333
      52.5,      0.000,      0.000,         0,     13.4134,      1.3417
      52.6,      0.000,      0.000,         0,     13.4969,      1.3500
      52.6,      0.000,      0.000,         0,     13.5802,      1.3583
      52.6,      0.000,      0.000,         0,     13.6635,      1.3667
      52.3,      0.000,      0.000,         0,     13.7467,      1.3750
      51.8,      0.000,      0.000,         0,     13.8303,      1.3833
      42.6,      0.000,      0.000,         0,     13.9134,      1.3917
       0.0,      0.000,      0.000,         0,     13.9968,      1.4000
       0.0,      0.000,      0.000,         0,     14.0801,      1.4083
       0.0,      0.000,      0.000,         0,     14.1635,      1.4167
       0.0,      0.000,      0.000,         0,     14.2467,      1.4250
       0.0,      0.000,      0.000,         0,     14.3302,      1.4333
       0.0,      0.000,      0.000,         0,     14.4135,      1.4417
       0.0,      0.000,      0.000,         0,     14.4967,      1.4500
       0.0,      0.000,      0.000,         0,     14.5801,      1.4583
       0.0,      0.000,      0.000,         0,     14.6634,      1.4667
       0.0,      0.000,      0.000,         0,     14.7468,      1.4750
       0.0,      0.000,      0.000,         0,     14.8302,      1.4833
       0.0,      0.000,      0.000,         0,     14.9136,      1.4917
       0.0,      0.000,      0.000,         0,     14.9968,      1.5000
       0.0,      0.000,      0.000,         0,     15.0801,      1.5083
       0.0,      0.000,      0.000,         0,     15.1635,      1.5167