File: Alban repo/Quiz 1/suction cup instron tests/oct-dec-2019_raw-data/d30e10-01-inwater-on36grit-nopump-100mm-test2.raw
Operator: 1

Date,Time,Specimen#
11/09/19,17:39:32,1

---------------------------------------


Area (mm^2):,      1.00,Flat,     25.40,     25.40,     25.40
Gage Len (mm):,     25.40


LOAD (N),STRAIN 1 (mm),STRAIN 2 (mm),STRESS (MPa),POSITION (mm),TIME (min)
       9.4,      0.000,      0.000,         0,      0.8098,      0.0083
      15.9,      0.000,      0.000,         0,      1.6431,      0.0167
      20.9,      0.000,      0.000,         0,      2.4776,      0.0250
      24.9,      0.000,      0.000,         0,      3.3108,      0.0333
      28.4,      0.000,      0.000,         0,      4.1441,      0.0417
      31.7,      0.000,      0.000,         0,      4.9774,      0.0500
      34.8,      0.000,      0.000,         0,      5.8109,      0.0583
      38.1,      0.000,      0.000,         0,      6.6442,      0.0667
      41.4,      0.000,      0.000,         0,      7.4775,      0.0750
      44.5,      0.000,      0.000,         0,      8.3107,      0.0833
      47.5,      0.000,      0.000,         0,      9.1438,      0.0917
      50.6,      0.000,      0.000,         0,      9.9773,      0.1000
      53.5,      0.000,      0.000,         0,     10.8106,      0.1083
      56.2,      0.000,      0.000,         0,     11.6439,      0.1167
      58.8,      0.000,      0.000,         0,     12.4770,      0.1250
      61.2,      0.000,      0.000,         0,     13.3104,      0.1333
      63.3,      0.000,      0.000,         0,     14.1435,      0.1417
      65.1,      0.000,      0.000,         0,     14.9770,      0.1500
      66.0,      0.000,      0.000,         0,     15.8101,      0.1583
      33.4,      0.000,      0.000,         0,     16.6434,      0.1667
       0.1,      0.000,      0.000,         0,     17.4768,      0.1750
       0.1,      0.000,      0.000,         0,     18.3099,      0.1833
       0.1,      0.000,      0.000,         0,     19.1432,      0.1917
       0.1,      0.000,      0.000,         0,     19.9765,      0.2000