File: Alban repo/Quiz 1/suction cup instron tests/oct-dec-2019_raw-data/d30e10-01-inwater-on36grit-nopump-10mm-test2.raw
Operator: 1

Date,Time,Specimen#
11/09/19,17:08:31,1

---------------------------------------


Area (mm^2):,      1.00,Flat,     25.40,     25.40,     25.40
Gage Len (mm):,     25.40


LOAD (N),STRAIN 1 (mm),STRAIN 2 (mm),STRESS (MPa),POSITION (mm),TIME (min)
       2.4,      0.000,      0.000,         0,      0.0812,      0.0083
       2.8,      0.000,      0.000,         0,      0.1643,      0.0167
       3.2,      0.000,      0.000,         0,      0.2477,      0.0250
       3.6,      0.000,      0.000,         0,      0.3310,      0.0333
       4.0,      0.000,      0.000,         0,      0.4145,      0.0417
       4.4,      0.000,      0.000,         0,      0.4976,      0.0500
       4.8,      0.000,      0.000,         0,      0.5812,      0.0583
       5.2,      0.000,      0.000,         0,      0.6645,      0.0667
       5.5,      0.000,      0.000,         0,      0.7476,      0.0750
       5.9,      0.000,      0.000,         0,      0.8308,      0.0833
       6.3,      0.000,      0.000,         0,      0.9145,      0.0917
       6.6,      0.000,      0.000,         0,      0.9978,      0.1000
       7.0,      0.000,      0.000,         0,      1.0809,      0.1083
       7.3,      0.000,      0.000,         0,      1.1643,      0.1167
       7.7,      0.000,      0.000,         0,      1.2478,      0.1250
       8.0,      0.000,      0.000,         0,      1.3309,      0.1333
       8.4,      0.000,      0.000,         0,      1.4143,      0.1417
       8.7,      0.000,      0.000,         0,      1.4978,      0.1500
       9.0,      0.000,      0.000,         0,      1.5811,      0.1583
       9.4,      0.000,      0.000,         0,      1.6642,      0.1667
       9.7,      0.000,      0.000,         0,      1.7478,      0.1750
      10.0,      0.000,      0.000,         0,      1.8311,      0.1833
      10.3,      0.000,      0.000,         0,      1.9142,      0.1917
      10.6,      0.000,      0.000,         0,      1.9977,      0.2000
      10.9,      0.000,      0.000,         0,      2.0809,      0.2083
      11.2,      0.000,      0.000,         0,      2.1640,      0.2167
      11.5,      0.000,      0.000,         0,      2.2475,      0.2250
      11.8,      0.000,      0.000,         0,      2.3309,      0.2333
      12.1,      0.000,      0.000,         0,      2.4144,      0.2417
      12.3,      0.000,      0.000,         0,      2.4977,      0.2500
      12.6,      0.000,      0.000,         0,      2.5810,      0.2583
      12.9,      0.000,      0.000,         0,      2.6644,      0.2667
      13.1,      0.000,      0.000,         0,      2.7477,      0.2750
      13.4,      0.000,      0.000,         0,      2.8308,      0.2833
      13.7,      0.000,      0.000,         0,      2.9144,      0.2917
      13.9,      0.000,      0.000,         0,      2.9975,      0.3000
      14.2,      0.000,      0.000,         0,      3.0810,      0.3083
      14.4,      0.000,      0.000,         0,      3.1643,      0.3167
      14.7,      0.000,      0.000,         0,      3.2475,      0.3250
      14.9,      0.000,      0.000,         0,      3.3308,      0.3333
      15.1,      0.000,      0.000,         0,      3.4141,      0.3417
      15.4,      0.000,      0.000,         0,      3.4975,      0.3500
      15.6,      0.000,      0.000,         0,      3.5810,      0.3583
      15.8,      0.000,      0.000,         0,      3.6643,      0.3667
      16.1,      0.000,      0.000,         0,      3.7476,      0.3750
      16.3,      0.000,      0.000,         0,      3.8310,      0.3833
      16.5,      0.000,      0.000,         0,      3.9143,      0.3917
      16.7,      0.000,      0.000,         0,      3.9976,      0.4000
      17.0,      0.000,      0.000,         0,      4.0808,      0.4083
      17.2,      0.000,      0.000,         0,      4.1639,      0.4167
      17.4,      0.000,      0.000,         0,      4.2476,      0.4250
      17.6,      0.000,      0.000,         0,      4.3309,      0.4333
      17.8,      0.000,      0.000,         0,      4.4141,      0.4417
      18.1,      0.000,      0.000,         0,      4.4976,      0.4500
      18.3,      0.000,      0.000,         0,      4.5809,      0.4583
      18.5,      0.000,      0.000,         0,      4.6641,      0.4667
      18.7,      0.000,      0.000,         0,      4.7474,      0.4750
      18.9,      0.000,      0.000,         0,      4.8309,      0.4833
      19.0,      0.000,      0.000,         0,      4.9142,      0.4917
      19.2,      0.000,      0.000,         0,      4.9976,      0.5000
      19.4,      0.000,      0.000,         0,      5.0809,      0.5083
      19.6,      0.000,      0.000,         0,      5.1640,      0.5167
      19.8,      0.000,      0.000,         0,      5.2475,      0.5250
      20.0,      0.000,      0.000,         0,      5.3309,      0.5333
      20.2,      0.000,      0.000,         0,      5.4142,      0.5417
      20.4,      0.000,      0.000,         0,      5.4973,      0.5500
      20.7,      0.000,      0.000,         0,      5.5809,      0.5583
      20.9,      0.000,      0.000,         0,      5.6642,      0.5667
      21.1,      0.000,      0.000,         0,      5.7475,      0.5750
      21.3,      0.000,      0.000,         0,      5.8307,      0.5833
      21.5,      0.000,      0.000,         0,      5.9142,      0.5917
      21.8,      0.000,      0.000,         0,      5.9975,      0.6000
      22.0,      0.000,      0.000,         0,      6.0808,      0.6083
      22.2,      0.000,      0.000,         0,      6.1642,      0.6167
      22.4,      0.000,      0.000,         0,      6.2475,      0.6250
      22.6,      0.000,      0.000,         0,      6.3308,      0.6333
      22.8,      0.000,      0.000,         0,      6.4139,      0.6417
      23.1,      0.000,      0.000,         0,      6.4973,      0.6500
      23.3,      0.000,      0.000,         0,      6.5808,      0.6583
      23.5,      0.000,      0.000,         0,      6.6641,      0.6667
      23.7,      0.000,      0.000,         0,      6.7475,      0.6750
      23.9,      0.000,      0.000,         0,      6.8308,      0.6833
      24.1,      0.000,      0.000,         0,      6.9139,      0.6917
      24.4,      0.000,      0.000,         0,      6.9974,      0.7000
      24.6,      0.000,      0.000,         0,      7.0808,      0.7083
      24.8,      0.000,      0.000,         0,      7.1639,      0.7167
      25.0,      0.000,      0.000,         0,      7.2474,      0.7250
      25.2,      0.000,      0.000,         0,      7.3308,      0.7333
      25.4,      0.000,      0.000,         0,      7.4141,      0.7417
      25.6,      0.000,      0.000,         0,      7.4972,      0.7500
      25.9,      0.000,      0.000,         0,      7.5807,      0.7583
      26.1,      0.000,      0.000,         0,      7.6639,      0.7667
      26.3,      0.000,      0.000,         0,      7.7474,      0.7750
      26.5,      0.000,      0.000,         0,      7.8305,      0.7833
      26.7,      0.000,      0.000,         0,      7.9141,      0.7917
      26.9,      0.000,      0.000,         0,      7.9974,      0.8000
      27.1,      0.000,      0.000,         0,      8.0807,      0.8083
      27.4,      0.000,      0.000,         0,      8.1640,      0.8167
      27.6,      0.000,      0.000,         0,      8.2476,      0.8250
      27.8,      0.000,      0.000,         0,      8.3307,      0.8333
      28.0,      0.000,      0.000,         0,      8.4140,      0.8417
      28.2,      0.000,      0.000,         0,      8.4973,      0.8500
      28.4,      0.000,      0.000,         0,      8.5807,      0.8583
      28.6,      0.000,      0.000,         0,      8.6642,      0.8667
      28.8,      0.000,      0.000,         0,      8.7473,      0.8750
      29.0,      0.000,      0.000,         0,      8.8309,      0.8833
      29.2,      0.000,      0.000,         0,      8.9140,      0.8917
      29.4,      0.000,      0.000,         0,      8.9973,      0.9000
      29.6,      0.000,      0.000,         0,      9.0806,      0.9083
      29.8,      0.000,      0.000,         0,      9.1640,      0.9167
      30.0,      0.000,      0.000,         0,      9.2471,      0.9250
      30.2,      0.000,      0.000,         0,      9.3304,      0.9333
      30.4,      0.000,      0.000,         0,      9.4140,      0.9417
      30.6,      0.000,      0.000,         0,      9.4973,      0.9500
      30.8,      0.000,      0.000,         0,      9.5806,      0.9583
      31.0,      0.000,      0.000,         0,      9.6639,      0.9667
      31.2,      0.000,      0.000,         0,      9.7475,      0.9750
      31.4,      0.000,      0.000,         0,      9.8300,      0.9833
      31.6,      0.000,      0.000,         0,      9.9139,      0.9917
      31.8,      0.000,      0.000,         0,      9.9975,      1.0000
      32.0,      0.000,      0.000,         0,     10.0808,      1.0083
      32.1,      0.000,      0.000,         0,     10.1639,      1.0167
      32.3,      0.000,      0.000,         0,     10.2472,      1.0250
      32.5,      0.000,      0.000,         0,     10.3306,      1.0333
      32.7,      0.000,      0.000,         0,     10.4137,      1.0417
      32.9,      0.000,      0.000,         0,     10.4970,      1.0500
      33.1,      0.000,      0.000,         0,     10.5806,      1.0583
      33.3,      0.000,      0.000,         0,     10.6639,      1.0667
      33.4,      0.000,      0.000,         0,     10.7472,      1.0750
      33.6,      0.000,      0.000,         0,     10.8307,      1.0833
      33.8,      0.000,      0.000,         0,     10.9139,      1.0917
      34.0,      0.000,      0.000,         0,     10.9974,      1.1000
      34.1,      0.000,      0.000,         0,     11.0805,      1.1083
      34.3,      0.000,      0.000,         0,     11.1639,      1.1167
      34.5,      0.000,      0.000,         0,     11.2472,      1.1250
      34.7,      0.000,      0.000,         0,     11.3305,      1.1333
      34.8,      0.000,      0.000,         0,     11.4138,      1.1417
      35.0,      0.000,      0.000,         0,     11.4972,      1.1500
      35.1,      0.000,      0.000,         0,     11.5807,      1.1583
      35.1,      0.000,      0.000,         0,     11.6640,      1.1667
      35.2,      0.000,      0.000,         0,     11.7472,      1.1750
      35.2,      0.000,      0.000,         0,     11.8305,      1.1833
      35.3,      0.000,      0.000,         0,     11.9140,      1.1917
      35.3,      0.000,      0.000,         0,     11.9971,      1.2000
      35.4,      0.000,      0.000,         0,     12.0805,      1.2083
      35.4,      0.000,      0.000,         0,     12.1638,      1.2167
      35.4,      0.000,      0.000,         0,     12.2473,      1.2250
      35.1,      0.000,      0.000,         0,     12.3306,      1.2333
      34.4,      0.000,      0.000,         0,     12.4140,      1.2417
      33.2,      0.000,      0.000,         0,     12.4971,      1.2500
      28.1,      0.000,      0.000,         0,     12.5806,      1.2583
       0.1,      0.000,      0.000,         0,     12.6636,      1.2667
       0.1,      0.000,      0.000,         0,     12.7473,      1.2750
       0.1,      0.000,      0.000,         0,     12.8306,      1.2833
       0.1,      0.000,      0.000,         0,     12.9137,      1.2917
       0.1,      0.000,      0.000,         0,     12.9973,      1.3000
       0.1,      0.000,      0.000,         0,     13.0802,      1.3083
       0.1,      0.000,      0.000,         0,     13.1639,      1.3167
       0.1,      0.000,      0.000,         0,     13.2473,      1.3250
       0.1,      0.000,      0.000,         0,     13.3306,      1.3333
       0.1,      0.000,      0.000,         0,     13.4135,      1.3417
       0.1,      0.000,      0.000,         0,     13.4972,      1.3500
       0.1,      0.000,      0.000,         0,     13.5722,      1.3593
       0.1,      0.000,      0.000,         0,     13.5746,      1.3626
       0.1,      0.000,      0.000,         0,     13.5746,      1.3659
       0.1,      0.000,      0.000,         0,     13.5744,      1.3693
       0.1,      0.000,      0.000,         0,     13.5744,      1.3726
       0.1,      0.000,      0.000,         0,     13.5744,      1.3759
       0.1,      0.000,      0.000,         0,     13.5744,      1.3793
       0.1,      0.000,      0.000,         0,     13.5746,      1.3826
       0.1,      0.000,      0.000,         0,     13.5744,      1.3860
       0.1,      0.000,      0.000,         0,     13.5744,      1.3893
       0.1,      0.000,      0.000,         0,     13.5744,      1.3926
       0.1,      0.000,      0.000,         0,     13.5744,      1.3960
       0.1,      0.000,      0.000,         0,     13.5744,      1.3993
       0.1,      0.000,      0.000,         0,     13.5744,      1.4026
       0.1,      0.000,      0.000,         0,     13.5744,      1.4060
       0.1,      0.000,      0.000,         0,     13.5744,      1.4093
       0.1,      0.000,      0.000,         0,     13.5744,      1.4126
       0.1,      0.000,      0.000,         0,     13.5744,      1.4160
       0.1,      0.000,      0.000,         0,     13.5744,      1.4193
       0.1,      0.000,      0.000,         0,     13.5744,      1.4227
       0.1,      0.000,      0.000,         0,     13.5744,      1.4260
       0.1,      0.000,      0.000,         0,     13.5744,      1.4293
       0.1,      0.000,      0.000,         0,     13.5744,      1.4327
       0.1,      0.000,      0.000,         0,     13.5744,      1.4360
       0.1,      0.000,      0.000,         0,     13.5744,      1.4393
       0.1,      0.000,      0.000,         0,     13.5744,      1.4427
       0.1,      0.000,      0.000,         0,     13.5744,      1.4460
       0.1,      0.000,      0.000,         0,     13.5744,      1.4493
       0.1,      0.000,      0.000,         0,     13.5744,      1.4527
       0.1,      0.000,      0.000,         0,     13.5744,      1.4560
       0.1,      0.000,      0.000,         0,     13.5744,      1.4594
       0.1,      0.000,      0.000,         0,     13.5744,      1.4627
       0.1,      0.000,      0.000,         0,     13.5744,      1.4660
       0.1,      0.000,      0.000,         0,     13.5744,      1.4694
       0.1,      0.000,      0.000,         0,     13.5744,      1.4727
       0.1,      0.000,      0.000,         0,     13.5744,      1.4760
       0.1,      0.000,      0.000,         0,     13.5744,      1.4794
       0.1,      0.000,      0.000,         0,     13.5744,      1.4827
       0.1,      0.000,      0.000,         0,     13.5744,      1.4861
       0.1,      0.000,      0.000,         0,     13.5744,      1.4894
       0.1,      0.000,      0.000,         0,     13.5744,      1.4927
       0.1,      0.000,      0.000,         0,     13.5744,      1.4961
       0.1,      0.000,      0.000,         0,     13.5744,      1.4994
       0.1,      0.000,      0.000,         0,     13.5744,      1.5027
       0.1,      0.000,      0.000,         0,     13.5744,      1.5061
       0.1,      0.000,      0.000,         0,     13.5744,      1.5094
       0.1,      0.000,      0.000,         0,     13.5744,      1.5127
       0.1,      0.000,      0.000,         0,     13.5744,      1.5161
       0.1,      0.000,      0.000,         0,     13.5709,      1.5194
       0.1,      0.000,      0.000,         0,     13.5643,      1.5228
       0.1,      0.000,      0.000,         0,     13.5624,      1.5261
       0.1,      0.000,      0.000,         0,     13.5608,      1.5294
       0.1,      0.000,      0.000,         0,     13.5598,      1.5328
       0.1,      0.000,      0.000,         0,     13.5585,      1.5361
       0.1,      0.000,      0.000,         0,     13.5579,      1.5394
       0.1,      0.000,      0.000,         0,     13.5563,      1.5428
       0.1,      0.000,      0.000,         0,     13.5563,      1.5461
       0.1,      0.000,      0.000,         0,     13.5563,      1.5494
       0.1,      0.000,      0.000,         0,     13.5563,      1.5528
       0.1,      0.000,      0.000,         0,     13.5563,      1.5561
       0.1,      0.000,      0.000,         0,     13.5563,      1.5595
       0.1,      0.000,      0.000,         0,     13.5563,      1.5628
       0.1,      0.000,      0.000,         0,     13.5563,      1.5661
       0.1,      0.000,      0.000,         0,     13.5563,      1.5695
       0.1,      0.000,      0.000,         0,     13.5563,      1.5728
       0.1,      0.000,      0.000,         0,     13.5563,      1.5761
       0.1,      0.000,      0.000,         0,     13.5563,      1.5795
       0.1,      0.000,      0.000,         0,     13.5563,      1.5828
       0.1,      0.000,      0.000,         0,     13.5563,      1.5861
       0.1,      0.000,      0.000,         0,     13.5563,      1.5895
       0.1,      0.000,      0.000,         0,     13.5563,      1.5928
       0.1,      0.000,      0.000,         0,     13.5563,      1.5962
       0.1,      0.000,      0.000,         0,     13.5563,      1.5995
       0.1,      0.000,      0.000,         0,     13.5563,      1.6028
       0.1,      0.000,      0.000,         0,     13.5563,      1.6062
       0.1,      0.000,      0.000,         0,     13.5563,      1.6095
       0.1,      0.000,      0.000,         0,     13.5563,      1.6128
       0.1,      0.000,      0.000,         0,     13.5563,      1.6162
       0.1,      0.000,      0.000,         0,     13.5563,      1.6195
       0.1,      0.000,      0.000,         0,     13.5563,      1.6229
       0.1,      0.000,      0.000,         0,     13.5563,      1.6262
       0.1,      0.000,      0.000,         0,     13.5563,      1.6295
       0.1,      0.000,      0.000,         0,     13.5563,      1.6329
       0.1,      0.000,      0.000,         0,     13.5563,      1.6362
       0.1,      0.000,      0.000,         0,     13.5563,      1.6395
       0.1,      0.000,      0.000,         0,     13.5563,      1.6429
       0.1,      0.000,      0.000,         0,     13.5563,      1.6462
       0.0,      0.000,      0.000,         0,     13.5563,      1.6495
       0.1,      0.000,      0.000,         0,     13.5563,      1.6529
       0.1,      0.000,      0.000,         0,     13.5563,      1.6562
       0.0,      0.000,      0.000,         0,     13.5563,      1.6596
       0.0,      0.000,      0.000,         0,     13.5563,      1.6629
       0.0,      0.000,      0.000,         0,     13.5563,      1.6662
       0.0,      0.000,      0.000,         0,     13.5563,      1.6696
       0.0,      0.000,      0.000,         0,     13.5563,      1.6729
       0.0,      0.000,      0.000,         0,     13.5563,      1.6762
       0.0,      0.000,      0.000,         0,     13.5563,      1.6796
       0.0,      0.000,      0.000,         0,     13.5563,      1.6829
       0.0,      0.000,      0.000,         0,     13.5563,      1.6862
       0.0,      0.000,      0.000,         0,     13.5563,      1.6896
       0.0,      0.000,      0.000,         0,     13.5563,      1.6929
       0.0,      0.000,      0.000,         0,     13.5563,      1.6963
       0.0,      0.000,      0.000,         0,     13.5563,      1.6996
       0.0,      0.000,      0.000,         0,     13.5563,      1.7029
       0.0,      0.000,      0.000,         0,     13.5563,      1.7063
       0.0,      0.000,      0.000,         0,     13.5563,      1.7096
       0.0,      0.000,      0.000,         0,     13.5563,      1.7129
       0.0,      0.000,      0.000,         0,     13.5563,      1.7163
       0.0,      0.000,      0.000,         0,     13.5563,      1.7196
       0.0,      0.000,      0.000,         0,     13.5563,      1.7229
       0.0,      0.000,      0.000,         0,     13.5563,      1.7263
       0.0,      0.000,      0.000,         0,     13.5563,      1.7296
       0.0,      0.000,      0.000,         0,     13.5563,      1.7330
       0.0,      0.000,      0.000,         0,     13.5563,      1.7363
       0.0,      0.000,      0.000,         0,     13.5563,      1.7396
       0.0,      0.000,      0.000,         0,     13.5563,      1.7430
       0.0,      0.000,      0.000,         0,     13.5563,      1.7463
       0.0,      0.000,      0.000,         0,     13.5563,      1.7496
       0.0,      0.000,      0.000,         0,     13.5563,      1.7530
       0.0,      0.000,      0.000,         0,     13.5563,      1.7563
       0.0,      0.000,      0.000,         0,     13.5563,      1.7597
       0.0,      0.000,      0.000,         0,     13.5563,      1.7630
       0.0,      0.000,      0.000,         0,     13.5563,      1.7663
       0.0,      0.000,      0.000,         0,     13.5563,      1.7697
       0.0,      0.000,      0.000,         0,     13.5563,      1.7730
       0.0,      0.000,      0.000,         0,     13.5563,      1.7763
       0.0,      0.000,      0.000,         0,     13.5563,      1.7797
       0.0,      0.000,      0.000,         0,     13.5563,      1.7830
       0.0,      0.000,      0.000,         0,     13.5563,      1.7863
       0.0,      0.000,      0.000,         0,     13.5563,      1.7897
       0.0,      0.000,      0.000,         0,     13.5563,      1.7930
       0.0,      0.000,      0.000,         0,     13.5563,      1.7964
       0.0,      0.000,      0.000,         0,     13.5563,      1.7997
       0.0,      0.000,      0.000,         0,     13.5563,      1.8030
       0.0,      0.000,      0.000,         0,     13.5563,      1.8064
       0.0,      0.000,      0.000,         0,     13.5563,      1.8097
       0.0,      0.000,      0.000,         0,     13.5563,      1.8130
       0.0,      0.000,      0.000,         0,     13.5563,      1.8164
       0.0,      0.000,      0.000,         0,     13.5563,      1.8197
       0.0,      0.000,      0.000,         0,     13.5563,      1.8230
       0.0,      0.000,      0.000,         0,     13.5563,      1.8264
       0.0,      0.000,      0.000,         0,     13.5563,      1.8297
       0.0,      0.000,      0.000,         0,     13.5563,      1.8331
       0.0,      0.000,      0.000,         0,     13.5563,      1.8364
       0.0,      0.000,      0.000,         0,     13.5563,      1.8397
       0.0,      0.000,      0.000,         0,     13.5563,      1.8431
       0.0,      0.000,      0.000,         0,     13.5563,      1.8464
       0.0,      0.000,      0.000,         0,     13.5563,      1.8497
       0.0,      0.000,      0.000,         0,     13.5563,      1.8531
       0.0,      0.000,      0.000,         0,     13.5563,      1.8564
       0.0,      0.000,      0.000,         0,     13.5563,      1.8597
       0.0,      0.000,      0.000,         0,     13.5563,      1.8631
       0.0,      0.000,      0.000,         0,     13.5563,      1.8664
       0.0,      0.000,      0.000,         0,     13.5563,      1.8698
       0.0,      0.000,      0.000,         0,     13.5563,      1.8731
       0.0,      0.000,      0.000,         0,     13.5563,      1.8764
       0.0,      0.000,      0.000,         0,     13.5563,      1.8798
       0.0,      0.000,      0.000,         0,     13.5563,      1.8831
       0.0,      0.000,      0.000,         0,     13.5563,      1.8864
       0.0,      0.000,      0.000,         0,     13.5563,      1.8898
       0.0,      0.000,      0.000,         0,     13.5563,      1.8931
       0.0,      0.000,      0.000,         0,     13.5563,      1.8965
       0.0,      0.000,      0.000,         0,     13.5563,      1.8998
       0.0,      0.000,      0.000,         0,     13.5563,      1.9031
       0.0,      0.000,      0.000,         0,     13.5563,      1.9065
       0.0,      0.000,      0.000,         0,     13.5563,      1.9098
       0.0,      0.000,      0.000,         0,     13.5563,      1.9131
       0.0,      0.000,      0.000,         0,     13.5563,      1.9165
       0.0,      0.000,      0.000,         0,     13.5563,      1.9198
       0.0,      0.000,      0.000,         0,     13.5563,      1.9231
       0.0,      0.000,      0.000,         0,     13.5563,      1.9265
       0.0,      0.000,      0.000,         0,     13.5563,      1.9298
       0.0,      0.000,      0.000,         0,     13.5563,      1.9332
       0.0,      0.000,      0.000,         0,     13.5563,      1.9365
       0.0,      0.000,      0.000,         0,     13.5563,      1.9398
       0.0,      0.000,      0.000,         0,     13.5563,      1.9432
       0.0,      0.000,      0.000,         0,     13.5563,      1.9465
       0.0,      0.000,      0.000,         0,     13.5563,      1.9498
       0.0,      0.000,      0.000,         0,     13.5563,      1.9532
       0.0,      0.000,      0.000,         0,     13.5563,      1.9565
       0.0,      0.000,      0.000,         0,     13.5563,      1.9598
       0.0,      0.000,      0.000,         0,     13.5563,      1.9632
       0.0,      0.000,      0.000,         0,     13.5563,      1.9665
       0.0,      0.000,      0.000,         0,     13.5563,      1.9699
       0.0,      0.000,      0.000,         0,     13.5563,      1.9732
       0.0,      0.000,      0.000,         0,     13.5563,      1.9765
       0.0,      0.000,      0.000,         0,     13.5563,      1.9799
       0.0,      0.000,      0.000,         0,     13.5563,      1.9832
       0.0,      0.000,      0.000,         0,     13.5563,      1.9865
       0.0,      0.000,      0.000,         0,     13.5563,      1.9899
       0.0,      0.000,      0.000,         0,     13.5563,      1.9932
       0.0,      0.000,      0.000,         0,     13.5563,      1.9965
       0.0,      0.000,      0.000,         0,     13.5563,      1.9999
       0.0,      0.000,      0.000,         0,     13.5563,      2.0032
       0.0,      0.000,      0.000,         0,     13.5563,      2.0066
       0.0,      0.000,      0.000,         0,     13.5563,      2.0099
       0.0,      0.000,      0.000,         0,     13.5563,      2.0132
       0.0,      0.000,      0.000,         0,     13.5563,      2.0166
       0.0,      0.000,      0.000,         0,     13.5563,      2.0199
       0.0,      0.000,      0.000,         0,     13.5563,      2.0232
       0.0,      0.000,      0.000,         0,     13.5563,      2.0266
       0.0,      0.000,      0.000,         0,     13.5563,      2.0299
       0.0,      0.000,      0.000,         0,     13.5563,      2.0333
       0.0,      0.000,      0.000,         0,     13.5563,      2.0366
       0.0,      0.000,      0.000,         0,     13.5563,      2.0399
       0.0,      0.000,      0.000,         0,     13.5563,      2.0433
       0.0,      0.000,      0.000,         0,     13.5563,      2.0466
       0.0,      0.000,      0.000,         0,     13.5563,      2.0499
       0.0,      0.000,      0.000,         0,     13.5563,      2.0533
       0.0,      0.000,      0.000,         0,     13.5563,      2.0566
       0.0,      0.000,      0.000,         0,     13.5563,      2.0599
       0.0,      0.000,      0.000,         0,     13.5563,      2.0633
       0.0,      0.000,      0.000,         0,     13.5563,      2.0666
       0.0,      0.000,      0.000,         0,     13.5563,      2.0700
       0.0,      0.000,      0.000,         0,     13.5563,      2.0733
       0.0,      0.000,      0.000,         0,     13.5563,      2.0766
       0.0,      0.000,      0.000,         0,     13.5563,      2.0800
       0.0,      0.000,      0.000,         0,     13.5563,      2.0833
       0.0,      0.000,      0.000,         0,     13.5563,      2.0866
       0.0,      0.000,      0.000,         0,     13.5563,      2.0900
       0.0,      0.000,      0.000,         0,     13.5563,      2.0933
       0.0,      0.000,      0.000,         0,     13.5563,      2.0966
       0.0,      0.000,      0.000,         0,     13.5563,      2.1000
       0.0,      0.000,      0.000,         0,     13.5563,      2.1033
       0.0,      0.000,      0.000,         0,     13.5563,      2.1067
       0.0,      0.000,      0.000,         0,     13.5563,      2.1100
       0.0,      0.000,      0.000,         0,     13.5563,      2.1133
       0.0,      0.000,      0.000,         0,     13.5563,      2.1167
       0.0,      0.000,      0.000,         0,     13.5563,      2.1200
       0.0,      0.000,      0.000,         0,     13.5563,      2.1233
       0.0,      0.000,      0.000,         0,     13.5563,      2.1267
       0.0,      0.000,      0.000,         0,     13.5563,      2.1300
       0.0,      0.000,      0.000,         0,     13.5563,      2.1333
       0.0,      0.000,      0.000,         0,     13.5563,      2.1367
       0.0,      0.000,      0.000,         0,     13.5563,      2.1400
       0.0,      0.000,      0.000,         0,     13.5563,      2.1434
       0.0,      0.000,      0.000,         0,     13.5563,      2.1467