File: Alban repo/Quiz 1/suction cup instron tests/oct-dec-2019_raw-data/d30e10-01-inwater-on80grit-diaphragmpump-10mm-test2.raw
Operator: 1

Date,Time,Specimen#
10/25/19,18:51:36,1

---------------------------------------


Area (mm^2):,      1.00,Flat,     25.40,     25.40,     25.40
Gage Len (mm):,     25.40


LOAD (N),STRAIN 1 (mm),STRAIN 2 (mm),STRESS (MPa),POSITION (mm),TIME (min)
      17.3,      0.000,      0.000,         0,     -0.1610,      0.0083
      20.9,      0.000,      0.000,         0,     -0.3276,      0.0167
      21.3,      0.000,      0.000,         0,     -0.4943,      0.0250
      21.1,      0.000,      0.000,         0,     -0.6610,      0.0333
      20.8,      0.000,      0.000,         0,     -0.8276,      0.0417
      20.4,      0.000,      0.000,         0,     -0.9942,      0.0500
      20.1,      0.000,      0.000,         0,     -1.1608,      0.0583
      19.6,      0.000,      0.000,         0,     -1.3276,      0.0667
      19.2,      0.000,      0.000,         0,     -1.4943,      0.0750
      18.8,      0.000,      0.000,         0,     -1.6609,      0.0833
      18.3,      0.000,      0.000,         0,     -1.8277,      0.0917
      17.9,      0.000,      0.000,         0,     -1.9943,      0.1000
      17.5,      0.000,      0.000,         0,     -2.1609,      0.1083
      17.1,      0.000,      0.000,         0,     -2.3278,      0.1167
      16.6,      0.000,      0.000,         0,     -2.4943,      0.1250
      16.2,      0.000,      0.000,         0,     -2.6611,      0.1333
      15.8,      0.000,      0.000,         0,     -2.8276,      0.1417
      15.3,      0.000,      0.000,         0,     -2.9942,      0.1500
      14.9,      0.000,      0.000,         0,     -3.1610,      0.1583
      14.4,      0.000,      0.000,         0,     -3.3276,      0.1667
      13.9,      0.000,      0.000,         0,     -3.4941,      0.1750
      13.4,      0.000,      0.000,         0,     -3.6610,      0.1833
      12.9,      0.000,      0.000,         0,     -3.8276,      0.1917
      12.4,      0.000,      0.000,         0,     -3.9942,      0.2000
      11.8,      0.000,      0.000,         0,     -4.1608,      0.2083
      11.3,      0.000,      0.000,         0,     -4.3274,      0.2167
      10.7,      0.000,      0.000,         0,     -4.4943,      0.2250
      10.0,      0.000,      0.000,         0,     -4.6609,      0.2333
       9.4,      0.000,      0.000,         0,     -4.8276,      0.2417
       8.7,      0.000,      0.000,         0,     -4.9941,      0.2500
       8.0,      0.000,      0.000,         0,     -5.1607,      0.2583
       7.2,      0.000,      0.000,         0,     -5.3276,      0.2667
       6.4,      0.000,      0.000,         0,     -5.4939,      0.2750
       5.5,      0.000,      0.000,         0,     -5.6609,      0.2833
       4.6,      0.000,      0.000,         0,     -5.8273,      0.2917
       3.6,      0.000,      0.000,         0,     -5.9941,      0.3000
       2.5,      0.000,      0.000,         0,     -6.1607,      0.3083
       1.3,      0.000,      0.000,         0,     -6.3273,      0.3167
      -0.2,      0.000,      0.000,         0,     -6.4941,      0.3250
      -1.9,      0.000,      0.000,         0,     -6.6608,      0.3333
      -4.2,      0.000,      0.000,         0,     -6.8275,      0.3417
      -7.2,      0.000,      0.000,         0,     -6.9941,      0.3500
     -10.9,      0.000,      0.000,         0,     -7.1607,      0.3583
     -15.3,      0.000,      0.000,         0,     -7.3591,      0.3830
     -15.0,      0.000,      0.000,         0,     -7.3592,      0.3997
     -14.8,      0.000,      0.000,         0,     -7.3592,      0.4163
     -14.6,      0.000,      0.000,         0,     -7.3592,      0.4330
     -14.5,      0.000,      0.000,         0,     -7.3591,      0.4497
     -14.4,      0.000,      0.000,         0,     -7.3590,      0.4663
     -14.4,      0.000,      0.000,         0,     -7.3589,      0.4830
     -14.3,      0.000,      0.000,         0,     -7.3588,      0.4997
     -14.2,      0.000,      0.000,         0,     -7.3586,      0.5163
     -14.1,      0.000,      0.000,         0,     -7.3309,      0.5330
     -13.9,      0.000,      0.000,         0,     -7.3235,      0.5497
     -13.8,      0.000,      0.000,         0,     -7.3218,      0.5663
     -13.8,      0.000,      0.000,         0,     -7.3215,      0.5830
     -13.6,      0.000,      0.000,         0,     -7.3201,      0.5997
     -13.6,      0.000,      0.000,         0,     -7.3196,      0.6163
     -11.5,      0.000,      0.000,         0,     -7.2549,      0.6247
      -9.0,      0.000,      0.000,         0,     -7.1701,      0.6330
      -6.7,      0.000,      0.000,         0,     -7.0863,      0.6413
      -4.5,      0.000,      0.000,         0,     -7.0029,      0.6497
      -2.5,      0.000,      0.000,         0,     -6.9194,      0.6580
      -0.9,      0.000,      0.000,         0,     -6.8360,      0.6663
       0.4,      0.000,      0.000,         0,     -6.7529,      0.6747
       1.5,      0.000,      0.000,         0,     -6.6696,      0.6830
       2.5,      0.000,      0.000,         0,     -6.5864,      0.6913
       3.4,      0.000,      0.000,         0,     -6.5029,      0.6997
       4.2,      0.000,      0.000,         0,     -6.4197,      0.7080
       5.0,      0.000,      0.000,         0,     -6.3361,      0.7163
       5.8,      0.000,      0.000,         0,     -6.2528,      0.7247
       6.5,      0.000,      0.000,         0,     -6.1696,      0.7330
       7.2,      0.000,      0.000,         0,     -6.0861,      0.7413
       7.8,      0.000,      0.000,         0,     -6.0029,      0.7497
       8.5,      0.000,      0.000,         0,     -5.9194,      0.7580
       9.1,      0.000,      0.000,         0,     -5.8364,      0.7663
       9.7,      0.000,      0.000,         0,     -5.7528,      0.7747
      10.3,      0.000,      0.000,         0,     -5.6695,      0.7830
      10.8,      0.000,      0.000,         0,     -5.5861,      0.7913
      11.4,      0.000,      0.000,         0,     -5.5028,      0.7997
      11.9,      0.000,      0.000,         0,     -5.4195,      0.8080
      12.4,      0.000,      0.000,         0,     -5.3363,      0.8163
      12.8,      0.000,      0.000,         0,     -5.2528,      0.8247
      13.3,      0.000,      0.000,         0,     -5.1695,      0.8330
      13.7,      0.000,      0.000,         0,     -5.0862,      0.8413
      14.2,      0.000,      0.000,         0,     -5.0028,      0.8497
      14.6,      0.000,      0.000,         0,     -4.9196,      0.8580
      15.0,      0.000,      0.000,         0,     -4.8361,      0.8663
      15.4,      0.000,      0.000,         0,     -4.7529,      0.8747
      15.8,      0.000,      0.000,         0,     -4.6695,      0.8830
      16.1,      0.000,      0.000,         0,     -4.5863,      0.8913
      16.5,      0.000,      0.000,         0,     -4.5028,      0.8997
      16.8,      0.000,      0.000,         0,     -4.4196,      0.9080
      17.2,      0.000,      0.000,         0,     -4.3363,      0.9163
      17.5,      0.000,      0.000,         0,     -4.2529,      0.9247
      17.9,      0.000,      0.000,         0,     -4.1694,      0.9330
      18.2,      0.000,      0.000,         0,     -4.0862,      0.9413
      18.5,      0.000,      0.000,         0,     -4.0031,      0.9497
      18.8,      0.000,      0.000,         0,     -3.9196,      0.9580
      19.1,      0.000,      0.000,         0,     -3.8362,      0.9663
      19.3,      0.000,      0.000,         0,     -3.7533,      0.9747
      19.6,      0.000,      0.000,         0,     -3.6696,      0.9830
      19.9,      0.000,      0.000,         0,     -3.5862,      0.9913
      20.1,      0.000,      0.000,         0,     -3.5031,      0.9997
      20.4,      0.000,      0.000,         0,     -3.4197,      1.0080
      20.6,      0.000,      0.000,         0,     -3.3365,      1.0163
      20.9,      0.000,      0.000,         0,     -3.2528,      1.0247
      21.1,      0.000,      0.000,         0,     -3.1697,      1.0330
      21.3,      0.000,      0.000,         0,     -3.0864,      1.0413
      21.6,      0.000,      0.000,         0,     -3.0029,      1.0497
      21.8,      0.000,      0.000,         0,     -2.9197,      1.0580
      22.0,      0.000,      0.000,         0,     -2.8365,      1.0663
      22.2,      0.000,      0.000,         0,     -2.7529,      1.0747
      22.5,      0.000,      0.000,         0,     -2.6696,      1.0830
      22.7,      0.000,      0.000,         0,     -2.5865,      1.0913
      22.9,      0.000,      0.000,         0,     -2.5029,      1.0997
      23.1,      0.000,      0.000,         0,     -2.4197,      1.1080
      23.3,      0.000,      0.000,         0,     -2.3364,      1.1163
      23.6,      0.000,      0.000,         0,     -2.2531,      1.1247
      23.8,      0.000,      0.000,         0,     -2.1697,      1.1330
      24.0,      0.000,      0.000,         0,     -2.0863,      1.1413
      24.2,      0.000,      0.000,         0,     -2.0031,      1.1497
      24.4,      0.000,      0.000,         0,     -1.9196,      1.1580
      24.6,      0.000,      0.000,         0,     -1.8363,      1.1663
      24.8,      0.000,      0.000,         0,     -1.7530,      1.1747
      25.0,      0.000,      0.000,         0,     -1.6697,      1.1830
      25.3,      0.000,      0.000,         0,     -1.5862,      1.1913
      25.5,      0.000,      0.000,         0,     -1.5031,      1.1997
      25.7,      0.000,      0.000,         0,     -1.4199,      1.2080
      26.0,      0.000,      0.000,         0,     -1.3364,      1.2163
      26.2,      0.000,      0.000,         0,     -1.2528,      1.2247
      26.4,      0.000,      0.000,         0,     -1.1700,      1.2330
      26.7,      0.000,      0.000,         0,     -1.0863,      1.2413
      26.9,      0.000,      0.000,         0,     -1.0031,      1.2497
      27.1,      0.000,      0.000,         0,     -0.9197,      1.2580
      27.4,      0.000,      0.000,         0,     -0.8363,      1.2663
      27.6,      0.000,      0.000,         0,     -0.7531,      1.2747
      27.8,      0.000,      0.000,         0,     -0.6696,      1.2830
      28.1,      0.000,      0.000,         0,     -0.5863,      1.2913
      28.3,      0.000,      0.000,         0,     -0.5031,      1.2997
      28.6,      0.000,      0.000,         0,     -0.4198,      1.3080
      28.8,      0.000,      0.000,         0,     -0.3364,      1.3163
      29.1,      0.000,      0.000,         0,     -0.2531,      1.3247
      29.3,      0.000,      0.000,         0,     -0.1699,      1.3330
      29.6,      0.000,      0.000,         0,     -0.0867,      1.3413
      29.8,      0.000,      0.000,         0,     -0.0030,      1.3497
      30.1,      0.000,      0.000,         0,      0.0802,      1.3580
      30.4,      0.000,      0.000,         0,      0.1636,      1.3663
      30.6,      0.000,      0.000,         0,      0.2469,      1.3747
      30.9,      0.000,      0.000,         0,      0.3302,      1.3830
      31.0,      0.000,      0.000,         0,      0.4135,      1.3913
      31.1,      0.000,      0.000,         0,      0.4970,      1.3997
      31.2,      0.000,      0.000,         0,      0.5802,      1.4080
      31.4,      0.000,      0.000,         0,      0.6635,      1.4163
      31.6,      0.000,      0.000,         0,      0.7470,      1.4247
      31.8,      0.000,      0.000,         0,      0.8302,      1.4330
      32.1,      0.000,      0.000,         0,      0.9134,      1.4413
      32.3,      0.000,      0.000,         0,      0.9966,      1.4497
      32.5,      0.000,      0.000,         0,      1.0804,      1.4580
      32.8,      0.000,      0.000,         0,      1.1635,      1.4663
      33.1,      0.000,      0.000,         0,      1.2467,      1.4747
      33.3,      0.000,      0.000,         0,      1.3302,      1.4830
      33.6,      0.000,      0.000,         0,      1.4136,      1.4913
      33.8,      0.000,      0.000,         0,      1.4969,      1.4997
      34.1,      0.000,      0.000,         0,      1.5802,      1.5080
      34.3,      0.000,      0.000,         0,      1.6638,      1.5163
      34.6,      0.000,      0.000,         0,      1.7469,      1.5247
      34.8,      0.000,      0.000,         0,      1.8301,      1.5330
      35.0,      0.000,      0.000,         0,      1.9130,      1.5413
      35.3,      0.000,      0.000,         0,      1.9969,      1.5497
      35.5,      0.000,      0.000,         0,      2.0801,      1.5580
      35.8,      0.000,      0.000,         0,      2.1635,      1.5663
      36.0,      0.000,      0.000,         0,      2.2469,      1.5747
      36.3,      0.000,      0.000,         0,      2.3302,      1.5830
      36.5,      0.000,      0.000,         0,      2.4135,      1.5913
      36.8,      0.000,      0.000,         0,      2.4967,      1.5997
      37.0,      0.000,      0.000,         0,      2.5800,      1.6080
      37.3,      0.000,      0.000,         0,      2.6635,      1.6163
      37.5,      0.000,      0.000,         0,      2.7468,      1.6247
      37.8,      0.000,      0.000,         0,      2.8302,      1.6330
      38.0,      0.000,      0.000,         0,      2.9135,      1.6413
      38.3,      0.000,      0.000,         0,      2.9968,      1.6497
      38.5,      0.000,      0.000,         0,      3.0802,      1.6580
      38.7,      0.000,      0.000,         0,      3.1633,      1.6663
      39.0,      0.000,      0.000,         0,      3.2467,      1.6747
      39.2,      0.000,      0.000,         0,      3.3300,      1.6830
      39.5,      0.000,      0.000,         0,      3.4135,      1.6913
      39.7,      0.000,      0.000,         0,      3.4966,      1.6997
      39.9,      0.000,      0.000,         0,      3.5800,      1.7080
      40.2,      0.000,      0.000,         0,      3.6632,      1.7163
      40.4,      0.000,      0.000,         0,      3.7468,      1.7247
      40.7,      0.000,      0.000,         0,      3.8301,      1.7330
      40.9,      0.000,      0.000,         0,      3.9132,      1.7413
      41.1,      0.000,      0.000,         0,      3.9968,      1.7497
      41.4,      0.000,      0.000,         0,      4.0802,      1.7580
      41.6,      0.000,      0.000,         0,      4.1633,      1.7663
      41.9,      0.000,      0.000,         0,      4.2467,      1.7747
      42.1,      0.000,      0.000,         0,      4.3303,      1.7830
      42.3,      0.000,      0.000,         0,      4.4134,      1.7913
      42.6,      0.000,      0.000,         0,      4.4966,      1.7997
      42.8,      0.000,      0.000,         0,      4.5800,      1.8080
      43.1,      0.000,      0.000,         0,      4.6634,      1.8163
      43.3,      0.000,      0.000,         0,      4.7466,      1.8247
      43.6,      0.000,      0.000,         0,      4.8299,      1.8330
      43.8,      0.000,      0.000,         0,      4.9136,      1.8413
      44.0,      0.000,      0.000,         0,      4.9967,      1.8497
      44.2,      0.000,      0.000,         0,      5.0801,      1.8580
      44.4,      0.000,      0.000,         0,      5.1633,      1.8663
      44.7,      0.000,      0.000,         0,      5.2469,      1.8747
      44.9,      0.000,      0.000,         0,      5.3299,      1.8830
      45.1,      0.000,      0.000,         0,      5.4133,      1.8913
      45.3,      0.000,      0.000,         0,      5.4966,      1.8997
      45.5,      0.000,      0.000,         0,      5.5799,      1.9080
      45.7,      0.000,      0.000,         0,      5.6631,      1.9163
      45.8,      0.000,      0.000,         0,      5.7468,      1.9247
      45.9,      0.000,      0.000,         0,      5.8300,      1.9330
      46.0,      0.000,      0.000,         0,      5.9134,      1.9413
      46.0,      0.000,      0.000,         0,      5.9967,      1.9497
      46.0,      0.000,      0.000,         0,      6.0801,      1.9580
      46.0,      0.000,      0.000,         0,      6.1631,      1.9663
      45.9,      0.000,      0.000,         0,      6.2466,      1.9747
       0.1,      0.000,      0.000,         0,      6.3300,      1.9830
       0.1,      0.000,      0.000,         0,      6.4132,      1.9913
       0.1,      0.000,      0.000,         0,      6.4966,      1.9997
       0.1,      0.000,      0.000,         0,      6.5799,      2.0080
       0.1,      0.000,      0.000,         0,      6.6633,      2.0163
       0.1,      0.000,      0.000,         0,      6.7464,      2.0247
       0.1,      0.000,      0.000,         0,      6.8299,      2.0330
       0.1,      0.000,      0.000,         0,      6.9132,      2.0413
       0.1,      0.000,      0.000,         0,      6.9966,      2.0497
       0.1,      0.000,      0.000,         0,      7.0799,      2.0580
       0.1,      0.000,      0.000,         0,      7.1633,      2.0663
       0.1,      0.000,      0.000,         0,      7.2465,      2.0747
       0.1,      0.000,      0.000,         0,      7.3300,      2.0830
       0.1,      0.000,      0.000,         0,      7.4133,      2.0913
       0.1,      0.000,      0.000,         0,      7.4964,      2.0997
       0.1,      0.000,      0.000,         0,      7.5799,      2.1080
       0.1,      0.000,      0.000,         0,      7.6632,      2.1163
       0.1,      0.000,      0.000,         0,      7.7466,      2.1247
       0.1,      0.000,      0.000,         0,      7.8298,      2.1330
       0.1,      0.000,      0.000,         0,      7.9134,      2.1413