File: Alban repo/Quiz 1/suction cup instron tests/oct-dec-2019_raw-data/d30e10-01-inwater-on80grit-diaphragmpump-10mm-test1.raw
Operator: 1

Date,Time,Specimen#
10/25/19,18:45:34,1

---------------------------------------


Area (mm^2):,      1.00,Flat,     25.40,     25.40,     25.40
Gage Len (mm):,     25.40


LOAD (N),STRAIN 1 (mm),STRAIN 2 (mm),STRESS (MPa),POSITION (mm),TIME (min)
      18.2,      0.000,      0.000,         0,     -0.1631,      0.0083
      21.4,      0.000,      0.000,         0,     -0.3297,      0.0167
      21.5,      0.000,      0.000,         0,     -0.4962,      0.0250
      21.3,      0.000,      0.000,         0,     -0.6630,      0.0333
      21.0,      0.000,      0.000,         0,     -0.8296,      0.0417
      20.6,      0.000,      0.000,         0,     -0.9964,      0.0500
      20.3,      0.000,      0.000,         0,     -1.1631,      0.0583
      19.9,      0.000,      0.000,         0,     -1.3297,      0.0667
      19.5,      0.000,      0.000,         0,     -1.4962,      0.0750
      19.1,      0.000,      0.000,         0,     -1.6629,      0.0833
      18.6,      0.000,      0.000,         0,     -1.8296,      0.0917
      18.2,      0.000,      0.000,         0,     -1.9963,      0.1000
      17.8,      0.000,      0.000,         0,     -2.1629,      0.1083
      17.3,      0.000,      0.000,         0,     -2.3296,      0.1167
      16.9,      0.000,      0.000,         0,     -2.4962,      0.1250
      16.4,      0.000,      0.000,         0,     -2.6630,      0.1333
      16.0,      0.000,      0.000,         0,     -2.8297,      0.1417
      15.5,      0.000,      0.000,         0,     -2.9963,      0.1500
      15.1,      0.000,      0.000,         0,     -3.1630,      0.1583
      14.6,      0.000,      0.000,         0,     -3.3296,      0.1667
      14.1,      0.000,      0.000,         0,     -3.4962,      0.1750
      13.6,      0.000,      0.000,         0,     -3.6631,      0.1833
      13.1,      0.000,      0.000,         0,     -3.8296,      0.1917
      12.6,      0.000,      0.000,         0,     -3.9962,      0.2000
      12.1,      0.000,      0.000,         0,     -4.1629,      0.2083
      11.4,      0.000,      0.000,         0,     -4.3295,      0.2167
      10.8,      0.000,      0.000,         0,     -4.4962,      0.2250
      10.2,      0.000,      0.000,         0,     -4.6629,      0.2333
       9.6,      0.000,      0.000,         0,     -4.8295,      0.2417
       8.9,      0.000,      0.000,         0,     -4.9962,      0.2500
       8.1,      0.000,      0.000,         0,     -5.1629,      0.2583
       7.4,      0.000,      0.000,         0,     -5.3295,      0.2667
       6.6,      0.000,      0.000,         0,     -5.4961,      0.2750
       5.7,      0.000,      0.000,         0,     -5.6628,      0.2833
       4.8,      0.000,      0.000,         0,     -5.8295,      0.2917
       3.7,      0.000,      0.000,         0,     -5.9961,      0.3000
       2.6,      0.000,      0.000,         0,     -6.1627,      0.3083
       1.4,      0.000,      0.000,         0,     -6.3295,      0.3167
      -0.1,      0.000,      0.000,         0,     -6.4959,      0.3250
      -1.8,      0.000,      0.000,         0,     -6.6629,      0.3333
      -4.2,      0.000,      0.000,         0,     -6.8294,      0.3417
      -7.2,      0.000,      0.000,         0,     -6.9960,      0.3500
     -10.8,      0.000,      0.000,         0,     -7.1626,      0.3583
     -15.0,      0.000,      0.000,         0,     -7.3295,      0.3667
     -15.4,      0.000,      0.000,         0,     -7.3684,      0.3835
     -15.0,      0.000,      0.000,         0,     -7.3684,      0.4002
     -14.8,      0.000,      0.000,         0,     -7.3684,      0.4169
     -14.7,      0.000,      0.000,         0,     -7.3684,      0.4335
     -14.6,      0.000,      0.000,         0,     -7.3683,      0.4502
     -15.0,      0.000,      0.000,         0,     -7.3683,      0.4669
     -14.6,      0.000,      0.000,         0,     -7.3682,      0.4835
     -14.5,      0.000,      0.000,         0,     -7.3680,      0.5002
     -14.2,      0.000,      0.000,         0,     -7.3679,      0.5169
     -14.1,      0.000,      0.000,         0,     -7.3437,      0.5335
     -13.9,      0.000,      0.000,         0,     -7.3370,      0.5502
     -13.8,      0.000,      0.000,         0,     -7.3351,      0.5669
     -13.8,      0.000,      0.000,         0,     -7.3348,      0.5835
     -13.7,      0.000,      0.000,         0,     -7.3336,      0.6002
     -13.6,      0.000,      0.000,         0,     -7.3329,      0.6169
     -11.6,      0.000,      0.000,         0,     -7.2681,      0.6252
      -9.2,      0.000,      0.000,         0,     -7.1831,      0.6335
      -6.9,      0.000,      0.000,         0,     -7.0997,      0.6419
      -4.3,      0.000,      0.000,         0,     -7.0160,      0.6502
      -2.3,      0.000,      0.000,         0,     -6.9327,      0.6585
      -0.7,      0.000,      0.000,         0,     -6.8491,      0.6669
       0.5,      0.000,      0.000,         0,     -6.7660,      0.6752
       1.6,      0.000,      0.000,         0,     -6.6827,      0.6835
       2.6,      0.000,      0.000,         0,     -6.5994,      0.6919
       3.5,      0.000,      0.000,         0,     -6.5160,      0.7002
       4.4,      0.000,      0.000,         0,     -6.4327,      0.7085
       5.2,      0.000,      0.000,         0,     -6.3494,      0.7169
       5.9,      0.000,      0.000,         0,     -6.2658,      0.7252
       6.7,      0.000,      0.000,         0,     -6.1827,      0.7335
       7.4,      0.000,      0.000,         0,     -6.0992,      0.7419
       8.1,      0.000,      0.000,         0,     -6.0161,      0.7502
       8.8,      0.000,      0.000,         0,     -5.9326,      0.7585
       9.4,      0.000,      0.000,         0,     -5.8494,      0.7669
      10.0,      0.000,      0.000,         0,     -5.7660,      0.7752
      10.6,      0.000,      0.000,         0,     -5.6828,      0.7835
      11.2,      0.000,      0.000,         0,     -5.5994,      0.7919
      11.7,      0.000,      0.000,         0,     -5.5159,      0.8002
      12.2,      0.000,      0.000,         0,     -5.4327,      0.8085
      12.7,      0.000,      0.000,         0,     -5.3495,      0.8169
      13.2,      0.000,      0.000,         0,     -5.2662,      0.8252
      13.7,      0.000,      0.000,         0,     -5.1826,      0.8335
      14.1,      0.000,      0.000,         0,     -5.0994,      0.8419
      14.6,      0.000,      0.000,         0,     -5.0161,      0.8502
      15.0,      0.000,      0.000,         0,     -4.9328,      0.8585
      15.4,      0.000,      0.000,         0,     -4.8493,      0.8669
      15.8,      0.000,      0.000,         0,     -4.7662,      0.8752
      16.2,      0.000,      0.000,         0,     -4.6829,      0.8835
      16.6,      0.000,      0.000,         0,     -4.5995,      0.8919
      16.9,      0.000,      0.000,         0,     -4.5161,      0.9002
      17.3,      0.000,      0.000,         0,     -4.4330,      0.9085
      17.6,      0.000,      0.000,         0,     -4.3494,      0.9169
      18.0,      0.000,      0.000,         0,     -4.2662,      0.9252
      18.3,      0.000,      0.000,         0,     -4.1827,      0.9335
      18.6,      0.000,      0.000,         0,     -4.0994,      0.9419
      18.9,      0.000,      0.000,         0,     -4.0162,      0.9502
      19.2,      0.000,      0.000,         0,     -3.9326,      0.9585
      19.5,      0.000,      0.000,         0,     -3.8494,      0.9669
      19.8,      0.000,      0.000,         0,     -3.7663,      0.9752
      20.1,      0.000,      0.000,         0,     -3.6828,      0.9835
      20.3,      0.000,      0.000,         0,     -3.5993,      0.9919
      20.6,      0.000,      0.000,         0,     -3.5162,      1.0002
      20.8,      0.000,      0.000,         0,     -3.4328,      1.0085
      21.1,      0.000,      0.000,         0,     -3.3496,      1.0169
      21.3,      0.000,      0.000,         0,     -3.2660,      1.0252
      21.6,      0.000,      0.000,         0,     -3.1828,      1.0335
      21.8,      0.000,      0.000,         0,     -3.0996,      1.0419
      22.0,      0.000,      0.000,         0,     -3.0161,      1.0502
      22.2,      0.000,      0.000,         0,     -2.9328,      1.0585
      22.5,      0.000,      0.000,         0,     -2.8494,      1.0669
      22.7,      0.000,      0.000,         0,     -2.7661,      1.0752
      22.9,      0.000,      0.000,         0,     -2.6828,      1.0835
      23.1,      0.000,      0.000,         0,     -2.5996,      1.0919
      23.4,      0.000,      0.000,         0,     -2.5162,      1.1002
      23.6,      0.000,      0.000,         0,     -2.4328,      1.1085
      23.8,      0.000,      0.000,         0,     -2.3496,      1.1169
      24.0,      0.000,      0.000,         0,     -2.2662,      1.1252
      24.2,      0.000,      0.000,         0,     -2.1828,      1.1335
      24.4,      0.000,      0.000,         0,     -2.0995,      1.1419
      24.6,      0.000,      0.000,         0,     -2.0163,      1.1502
      24.8,      0.000,      0.000,         0,     -1.9327,      1.1585
      25.1,      0.000,      0.000,         0,     -1.8495,      1.1669
      25.3,      0.000,      0.000,         0,     -1.7662,      1.1752
      25.5,      0.000,      0.000,         0,     -1.6828,      1.1835
      25.7,      0.000,      0.000,         0,     -1.5995,      1.1919
      25.9,      0.000,      0.000,         0,     -1.5163,      1.2002
      26.2,      0.000,      0.000,         0,     -1.4331,      1.2085
      26.4,      0.000,      0.000,         0,     -1.3496,      1.2169
      26.6,      0.000,      0.000,         0,     -1.2661,      1.2252
      26.9,      0.000,      0.000,         0,     -1.1831,      1.2335
      27.1,      0.000,      0.000,         0,     -1.0996,      1.2419
      27.3,      0.000,      0.000,         0,     -1.0162,      1.2502
      27.6,      0.000,      0.000,         0,     -0.9329,      1.2585
      27.8,      0.000,      0.000,         0,     -0.8496,      1.2669
      28.0,      0.000,      0.000,         0,     -0.7662,      1.2752
      28.3,      0.000,      0.000,         0,     -0.6828,      1.2835
      28.5,      0.000,      0.000,         0,     -0.5996,      1.2919
      28.7,      0.000,      0.000,         0,     -0.5162,      1.3002
      29.0,      0.000,      0.000,         0,     -0.4329,      1.3085
      29.2,      0.000,      0.000,         0,     -0.3496,      1.3169
      29.5,      0.000,      0.000,         0,     -0.2663,      1.3252
      29.7,      0.000,      0.000,         0,     -0.1829,      1.3335
      30.0,      0.000,      0.000,         0,     -0.0998,      1.3419
      30.2,      0.000,      0.000,         0,     -0.0163,      1.3502
      30.5,      0.000,      0.000,         0,      0.0671,      1.3585
      30.7,      0.000,      0.000,         0,      0.1504,      1.3669
      30.9,      0.000,      0.000,         0,      0.2337,      1.3752
      31.2,      0.000,      0.000,         0,      0.3169,      1.3835
      31.3,      0.000,      0.000,         0,      0.4004,      1.3919
      31.5,      0.000,      0.000,         0,      0.4837,      1.4002
      31.6,      0.000,      0.000,         0,      0.5671,      1.4085
      31.8,      0.000,      0.000,         0,      0.6503,      1.4169
      32.0,      0.000,      0.000,         0,      0.7338,      1.4252
      32.2,      0.000,      0.000,         0,      0.8170,      1.4335
      32.4,      0.000,      0.000,         0,      0.9003,      1.4419
      32.6,      0.000,      0.000,         0,      0.9837,      1.4502
      32.9,      0.000,      0.000,         0,      1.0672,      1.4585
      33.2,      0.000,      0.000,         0,      1.1502,      1.4669
      33.4,      0.000,      0.000,         0,      1.2335,      1.4752
      33.6,      0.000,      0.000,         0,      1.3170,      1.4835
      33.9,      0.000,      0.000,         0,      1.4004,      1.4919
      34.1,      0.000,      0.000,         0,      1.4836,      1.5002
      34.4,      0.000,      0.000,         0,      1.5670,      1.5085
      34.6,      0.000,      0.000,         0,      1.6505,      1.5169
      34.9,      0.000,      0.000,         0,      1.7337,      1.5252
      35.1,      0.000,      0.000,         0,      1.8169,      1.5335
      35.4,      0.000,      0.000,         0,      1.8998,      1.5419
      35.6,      0.000,      0.000,         0,      1.9837,      1.5502
      35.9,      0.000,      0.000,         0,      2.0669,      1.5585
      36.1,      0.000,      0.000,         0,      2.1503,      1.5669
      36.4,      0.000,      0.000,         0,      2.2336,      1.5752
      36.6,      0.000,      0.000,         0,      2.3170,      1.5835
      36.9,      0.000,      0.000,         0,      2.4003,      1.5919
      37.1,      0.000,      0.000,         0,      2.4837,      1.6002
      37.4,      0.000,      0.000,         0,      2.5669,      1.6085
      37.7,      0.000,      0.000,         0,      2.6502,      1.6169
      37.9,      0.000,      0.000,         0,      2.7337,      1.6252
      38.2,      0.000,      0.000,         0,      2.8170,      1.6335
      38.4,      0.000,      0.000,         0,      2.9003,      1.6419
      38.7,      0.000,      0.000,         0,      2.9836,      1.6502
      38.9,      0.000,      0.000,         0,      3.0672,      1.6585
      39.2,      0.000,      0.000,         0,      3.1501,      1.6669
      39.4,      0.000,      0.000,         0,      3.2335,      1.6752
      39.6,      0.000,      0.000,         0,      3.3168,      1.6835
      39.9,      0.000,      0.000,         0,      3.4003,      1.6919
      40.1,      0.000,      0.000,         0,      3.4833,      1.7002
      40.4,      0.000,      0.000,         0,      3.5669,      1.7085
      40.6,      0.000,      0.000,         0,      3.6502,      1.7169
      40.8,      0.000,      0.000,         0,      3.7337,      1.7252
      41.1,      0.000,      0.000,         0,      3.8168,      1.7335
      41.3,      0.000,      0.000,         0,      3.9001,      1.7419
      41.5,      0.000,      0.000,         0,      3.9836,      1.7502
      41.8,      0.000,      0.000,         0,      4.0670,      1.7585
      42.0,      0.000,      0.000,         0,      4.1502,      1.7669
      42.2,      0.000,      0.000,         0,      4.2335,      1.7752
      42.5,      0.000,      0.000,         0,      4.3170,      1.7835
      42.7,      0.000,      0.000,         0,      4.4000,      1.7919
      42.9,      0.000,      0.000,         0,      4.4834,      1.8002
      43.2,      0.000,      0.000,         0,      4.5666,      1.8085
      43.4,      0.000,      0.000,         0,      4.6502,      1.8169
      43.6,      0.000,      0.000,         0,      4.7334,      1.8252
      43.9,      0.000,      0.000,         0,      4.8168,      1.8335
      44.1,      0.000,      0.000,         0,      4.9003,      1.8419
      44.3,      0.000,      0.000,         0,      4.9835,      1.8502
      44.6,      0.000,      0.000,         0,      5.0667,      1.8585
      44.8,      0.000,      0.000,         0,      5.1502,      1.8669
      45.0,      0.000,      0.000,         0,      5.2335,      1.8752
      45.2,      0.000,      0.000,         0,      5.3167,      1.8835
      45.4,      0.000,      0.000,         0,      5.4002,      1.8919
      45.6,      0.000,      0.000,         0,      5.4835,      1.9002
      45.8,      0.000,      0.000,         0,      5.5667,      1.9085
      46.0,      0.000,      0.000,         0,      5.6500,      1.9169
      46.1,      0.000,      0.000,         0,      5.7335,      1.9252
      46.2,      0.000,      0.000,         0,      5.8166,      1.9335
      46.3,      0.000,      0.000,         0,      5.9001,      1.9419
      46.3,      0.000,      0.000,         0,      5.9835,      1.9502
      46.3,      0.000,      0.000,         0,      6.0669,      1.9585
      46.3,      0.000,      0.000,         0,      6.1500,      1.9669
      46.0,      0.000,      0.000,         0,      6.2334,      1.9752
       0.1,      0.000,      0.000,         0,      6.3170,      1.9835
       0.1,      0.000,      0.000,         0,      6.4001,      1.9919
       0.1,      0.000,      0.000,         0,      6.4834,      2.0002
       0.1,      0.000,      0.000,         0,      6.5667,      2.0085
       0.1,      0.000,      0.000,         0,      6.6502,      2.0169
       0.1,      0.000,      0.000,         0,      6.7331,      2.0252
       0.1,      0.000,      0.000,         0,      6.8167,      2.0335
       0.1,      0.000,      0.000,         0,      6.9001,      2.0419
       0.1,      0.000,      0.000,         0,      6.9834,      2.0502
       0.1,      0.000,      0.000,         0,      7.0668,      2.0585
       0.1,      0.000,      0.000,         0,      7.1501,      2.0669
       0.1,      0.000,      0.000,         0,      7.2333,      2.0752
       0.1,      0.000,      0.000,         0,      7.3167,      2.0835
       0.1,      0.000,      0.000,         0,      7.4000,      2.0919
       0.1,      0.000,      0.000,         0,      7.4834,      2.1002
       0.1,      0.000,      0.000,         0,      7.5667,      2.1085
       0.1,      0.000,      0.000,         0,      7.6499,      2.1169
       0.1,      0.000,      0.000,         0,      7.7334,      2.1252
       0.1,      0.000,      0.000,         0,      7.8165,      2.1335
       0.1,      0.000,      0.000,         0,      7.9001,      2.1419
       0.1,      0.000,      0.000,         0,      7.9832,      2.1502