File: Alban repo/Quiz 1/suction cup instron tests/oct-dec-2019_raw-data/d30e10-01-inwater-on36grit-nopump-100mm-test1.raw
Operator: 1

Date,Time,Specimen#
11/09/19,17:34:04,1

---------------------------------------


Area (mm^2):,      1.00,Flat,     25.40,     25.40,     25.40
Gage Len (mm):,     25.40


LOAD (N),STRAIN 1 (mm),STRAIN 2 (mm),STRESS (MPa),POSITION (mm),TIME (min)
       8.9,      0.000,      0.000,         0,      0.8100,      0.0083
      15.1,      0.000,      0.000,         0,      1.6435,      0.0167
      19.9,      0.000,      0.000,         0,      2.4776,      0.0250
      23.8,      0.000,      0.000,         0,      3.3108,      0.0333
      27.1,      0.000,      0.000,         0,      4.1443,      0.0417
      30.2,      0.000,      0.000,         0,      4.9774,      0.0500
      33.2,      0.000,      0.000,         0,      5.8109,      0.0583
      36.4,      0.000,      0.000,         0,      6.6440,      0.0667
      39.7,      0.000,      0.000,         0,      7.4775,      0.0750
      42.8,      0.000,      0.000,         0,      8.3107,      0.0833
      45.8,      0.000,      0.000,         0,      9.1438,      0.0917
      48.9,      0.000,      0.000,         0,      9.9771,      0.1000
      51.9,      0.000,      0.000,         0,     10.8104,      0.1083
      54.5,      0.000,      0.000,         0,     11.6437,      0.1167
      57.0,      0.000,      0.000,         0,     12.4770,      0.1250
      59.4,      0.000,      0.000,         0,     13.3102,      0.1333
      61.6,      0.000,      0.000,         0,     14.1435,      0.1417
      63.4,      0.000,      0.000,         0,     14.9768,      0.1500
      64.4,      0.000,      0.000,         0,     15.8101,      0.1583
      19.0,      0.000,      0.000,         0,     16.6436,      0.1667
       0.1,      0.000,      0.000,         0,     17.4766,      0.1750
       0.2,      0.000,      0.000,         0,     18.3101,      0.1833
       0.2,      0.000,      0.000,         0,     19.1432,      0.1917
       0.2,      0.000,      0.000,         0,     19.9765,      0.2000