File: Alban repo/Quiz 1/suction cup instron tests/oct-dec-2019_raw-data/d30e10-01-inwater-onwhiteplatic-diaphragmpump-10mm-test3.raw
Operator: 1

Date,Time,Specimen#
10/25/19,17:22:51,1

---------------------------------------


Area (mm^2):,      1.00,Flat,     25.40,     25.40,     25.40
Gage Len (mm):,     25.40


LOAD (N),STRAIN 1 (mm),STRAIN 2 (mm),STRESS (MPa),POSITION (mm),TIME (min)
      17.5,      0.000,      0.000,         0,     -0.1621,      0.0083
      20.7,      0.000,      0.000,         0,     -0.3288,      0.0167
      20.9,      0.000,      0.000,         0,     -0.4954,      0.0250
      20.8,      0.000,      0.000,         0,     -0.6621,      0.0333
      20.6,      0.000,      0.000,         0,     -0.8287,      0.0417
      20.2,      0.000,      0.000,         0,     -0.9954,      0.0500
      19.9,      0.000,      0.000,         0,     -1.1618,      0.0583
      19.5,      0.000,      0.000,         0,     -1.3288,      0.0667
      19.1,      0.000,      0.000,         0,     -1.4953,      0.0750
      18.7,      0.000,      0.000,         0,     -1.6619,      0.0833
      18.2,      0.000,      0.000,         0,     -1.8286,      0.0917
      17.8,      0.000,      0.000,         0,     -1.9953,      0.1000
      17.4,      0.000,      0.000,         0,     -2.1620,      0.1083
      17.0,      0.000,      0.000,         0,     -2.3286,      0.1167
      16.6,      0.000,      0.000,         0,     -2.4952,      0.1250
      16.1,      0.000,      0.000,         0,     -2.6619,      0.1333
      15.7,      0.000,      0.000,         0,     -2.8285,      0.1417
      15.2,      0.000,      0.000,         0,     -2.9955,      0.1500
      14.8,      0.000,      0.000,         0,     -3.1619,      0.1583
      14.3,      0.000,      0.000,         0,     -3.3286,      0.1667
      13.8,      0.000,      0.000,         0,     -3.4951,      0.1750
      13.3,      0.000,      0.000,         0,     -3.6618,      0.1833
      12.8,      0.000,      0.000,         0,     -3.8285,      0.1917
      12.3,      0.000,      0.000,         0,     -3.9952,      0.2000
      11.7,      0.000,      0.000,         0,     -4.1620,      0.2083
      11.1,      0.000,      0.000,         0,     -4.3286,      0.2167
      10.6,      0.000,      0.000,         0,     -4.4951,      0.2250
       9.9,      0.000,      0.000,         0,     -4.6618,      0.2333
       9.3,      0.000,      0.000,         0,     -4.8286,      0.2417
       8.7,      0.000,      0.000,         0,     -4.9953,      0.2500
       8.0,      0.000,      0.000,         0,     -5.1619,      0.2583
       7.3,      0.000,      0.000,         0,     -5.3286,      0.2667
       6.6,      0.000,      0.000,         0,     -5.4951,      0.2750
       5.9,      0.000,      0.000,         0,     -5.6618,      0.2833
       5.1,      0.000,      0.000,         0,     -5.8284,      0.2917
       4.3,      0.000,      0.000,         0,     -5.9951,      0.3000
       3.4,      0.000,      0.000,         0,     -6.1616,      0.3083
       2.5,      0.000,      0.000,         0,     -6.3285,      0.3167
       1.4,      0.000,      0.000,         0,     -6.4950,      0.3250
       0.1,      0.000,      0.000,         0,     -6.6618,      0.3333
      -1.8,      0.000,      0.000,         0,     -6.8285,      0.3417
      -3.7,      0.000,      0.000,         0,     -6.9951,      0.3500
      -5.3,      0.000,      0.000,         0,     -7.1618,      0.3583
      -8.4,      0.000,      0.000,         0,     -7.3284,      0.3667
     -11.8,      0.000,      0.000,         0,     -7.4950,      0.3750
     -14.2,      0.000,      0.000,         0,     -7.6795,      0.3990
     -13.4,      0.000,      0.000,         0,     -7.6795,      0.4157
     -12.9,      0.000,      0.000,         0,     -7.6795,      0.4324
     -12.5,      0.000,      0.000,         0,     -7.6795,      0.4490
     -12.3,      0.000,      0.000,         0,     -7.6794,      0.4657
     -12.1,      0.000,      0.000,         0,     -7.6793,      0.4824
     -11.9,      0.000,      0.000,         0,     -7.6792,      0.4990
     -11.8,      0.000,      0.000,         0,     -7.6791,      0.5157
     -11.6,      0.000,      0.000,         0,     -7.6790,      0.5324
     -11.5,      0.000,      0.000,         0,     -7.6526,      0.5490
     -11.1,      0.000,      0.000,         0,     -7.6440,      0.5657
     -11.1,      0.000,      0.000,         0,     -7.6437,      0.5824
     -11.0,      0.000,      0.000,         0,     -7.6433,      0.5990
     -10.9,      0.000,      0.000,         0,     -7.6425,      0.6157
     -10.8,      0.000,      0.000,         0,     -7.6416,      0.6324
      -8.6,      0.000,      0.000,         0,     -7.5769,      0.6407
      -6.1,      0.000,      0.000,         0,     -7.4925,      0.6490
      -3.7,      0.000,      0.000,         0,     -7.4079,      0.6574
      -1.5,      0.000,      0.000,         0,     -7.3246,      0.6657
       0.6,      0.000,      0.000,         0,     -7.2412,      0.6740
       1.3,      0.000,      0.000,         0,     -7.1580,      0.6824
       1.7,      0.000,      0.000,         0,     -7.0747,      0.6907
       3.5,      0.000,      0.000,         0,     -6.9913,      0.6990
       4.9,      0.000,      0.000,         0,     -6.9080,      0.7074
       5.9,      0.000,      0.000,         0,     -6.8247,      0.7157
       6.7,      0.000,      0.000,         0,     -6.7414,      0.7240
       7.6,      0.000,      0.000,         0,     -6.6580,      0.7324
       8.3,      0.000,      0.000,         0,     -6.5749,      0.7407
       9.0,      0.000,      0.000,         0,     -6.4913,      0.7490
       9.7,      0.000,      0.000,         0,     -6.4080,      0.7574
      10.3,      0.000,      0.000,         0,     -6.3246,      0.7657
      10.9,      0.000,      0.000,         0,     -6.2415,      0.7740
      11.5,      0.000,      0.000,         0,     -6.1581,      0.7824
      12.1,      0.000,      0.000,         0,     -6.0749,      0.7907
      12.7,      0.000,      0.000,         0,     -5.9914,      0.7990
      13.2,      0.000,      0.000,         0,     -5.9080,      0.8074
      13.7,      0.000,      0.000,         0,     -5.8247,      0.8157
      14.2,      0.000,      0.000,         0,     -5.7413,      0.8240
      14.7,      0.000,      0.000,         0,     -5.6581,      0.8324
      15.2,      0.000,      0.000,         0,     -5.5748,      0.8407
      15.7,      0.000,      0.000,         0,     -5.4913,      0.8490
      16.1,      0.000,      0.000,         0,     -5.4081,      0.8574
      16.6,      0.000,      0.000,         0,     -5.3250,      0.8657
      17.0,      0.000,      0.000,         0,     -5.2414,      0.8740
      17.4,      0.000,      0.000,         0,     -5.1581,      0.8824
      17.8,      0.000,      0.000,         0,     -5.0749,      0.8907
      18.2,      0.000,      0.000,         0,     -4.9916,      0.8990
      18.6,      0.000,      0.000,         0,     -4.9081,      0.9074
      18.9,      0.000,      0.000,         0,     -4.8248,      0.9157
      19.3,      0.000,      0.000,         0,     -4.7415,      0.9240
      19.6,      0.000,      0.000,         0,     -4.6581,      0.9324
      20.0,      0.000,      0.000,         0,     -4.5748,      0.9407
      20.3,      0.000,      0.000,         0,     -4.4914,      0.9490
      20.6,      0.000,      0.000,         0,     -4.4082,      0.9574
      20.9,      0.000,      0.000,         0,     -4.3250,      0.9657
      21.2,      0.000,      0.000,         0,     -4.2416,      0.9740
      21.5,      0.000,      0.000,         0,     -4.1581,      0.9824
      21.8,      0.000,      0.000,         0,     -4.0748,      0.9907
      22.0,      0.000,      0.000,         0,     -3.9916,      0.9990
      22.3,      0.000,      0.000,         0,     -3.9082,      1.0074
      22.6,      0.000,      0.000,         0,     -3.8249,      1.0157
      22.8,      0.000,      0.000,         0,     -3.7415,      1.0240
      23.1,      0.000,      0.000,         0,     -3.6582,      1.0324
      23.3,      0.000,      0.000,         0,     -3.5749,      1.0407
      23.6,      0.000,      0.000,         0,     -3.4914,      1.0490
      23.8,      0.000,      0.000,         0,     -3.4082,      1.0574
      24.0,      0.000,      0.000,         0,     -3.3250,      1.0657
      24.3,      0.000,      0.000,         0,     -3.2414,      1.0740
      24.5,      0.000,      0.000,         0,     -3.1582,      1.0824
      24.8,      0.000,      0.000,         0,     -3.0747,      1.0907
      25.0,      0.000,      0.000,         0,     -2.9917,      1.0990
      25.2,      0.000,      0.000,         0,     -2.9082,      1.1074
      25.4,      0.000,      0.000,         0,     -2.8248,      1.1157
      25.6,      0.000,      0.000,         0,     -2.7416,      1.1240
      25.9,      0.000,      0.000,         0,     -2.6583,      1.1324
      26.1,      0.000,      0.000,         0,     -2.5747,      1.1407
      26.3,      0.000,      0.000,         0,     -2.4916,      1.1490
      26.4,      0.000,      0.000,         0,     -2.4083,      1.1574
      26.6,      0.000,      0.000,         0,     -2.3250,      1.1657
      26.9,      0.000,      0.000,         0,     -2.2414,      1.1740
      27.1,      0.000,      0.000,         0,     -2.1582,      1.1824
      27.3,      0.000,      0.000,         0,     -2.0750,      1.1907
      27.5,      0.000,      0.000,         0,     -1.9914,      1.1990
      27.8,      0.000,      0.000,         0,     -1.9082,      1.2074
      28.0,      0.000,      0.000,         0,     -1.8249,      1.2157
      28.2,      0.000,      0.000,         0,     -1.7418,      1.2240
      28.4,      0.000,      0.000,         0,     -1.6581,      1.2324
      28.7,      0.000,      0.000,         0,     -1.5750,      1.2407
      28.9,      0.000,      0.000,         0,     -1.4917,      1.2490
      29.1,      0.000,      0.000,         0,     -1.4084,      1.2574
      29.3,      0.000,      0.000,         0,     -1.3251,      1.2657
      29.6,      0.000,      0.000,         0,     -1.2416,      1.2740
      29.8,      0.000,      0.000,         0,     -1.1583,      1.2824
      30.0,      0.000,      0.000,         0,     -1.0749,      1.2907
      30.2,      0.000,      0.000,         0,     -0.9919,      1.2990
      30.5,      0.000,      0.000,         0,     -0.9082,      1.3074
      30.7,      0.000,      0.000,         0,     -0.8249,      1.3157
      30.9,      0.000,      0.000,         0,     -0.7418,      1.3240
      31.1,      0.000,      0.000,         0,     -0.6584,      1.3324
      31.3,      0.000,      0.000,         0,     -0.5750,      1.3407
      31.5,      0.000,      0.000,         0,     -0.4916,      1.3490
      31.7,      0.000,      0.000,         0,     -0.4084,      1.3574
      31.9,      0.000,      0.000,         0,     -0.3249,      1.3657
      32.2,      0.000,      0.000,         0,     -0.2417,      1.3740
      32.4,      0.000,      0.000,         0,     -0.1584,      1.3824
      32.6,      0.000,      0.000,         0,     -0.0750,      1.3907
      32.9,      0.000,      0.000,         0,      0.0084,      1.3990
      33.1,      0.000,      0.000,         0,      0.0917,      1.4074
      33.3,      0.000,      0.000,         0,      0.1750,      1.4157
      33.6,      0.000,      0.000,         0,      0.2584,      1.4240
      33.8,      0.000,      0.000,         0,      0.3417,      1.4324
      34.1,      0.000,      0.000,         0,      0.4251,      1.4407
      34.3,      0.000,      0.000,         0,      0.5084,      1.4490
      34.5,      0.000,      0.000,         0,      0.5916,      1.4574
      34.7,      0.000,      0.000,         0,      0.6750,      1.4657
      34.9,      0.000,      0.000,         0,      0.7584,      1.4740
      35.2,      0.000,      0.000,         0,      0.8416,      1.4824
      35.4,      0.000,      0.000,         0,      0.9249,      1.4907
      35.6,      0.000,      0.000,         0,      1.0082,      1.4990
      35.9,      0.000,      0.000,         0,      1.0917,      1.5074
      36.1,      0.000,      0.000,         0,      1.1749,      1.5157
      36.3,      0.000,      0.000,         0,      1.2584,      1.5240
      36.6,      0.000,      0.000,         0,      1.3415,      1.5324
      36.8,      0.000,      0.000,         0,      1.4249,      1.5407
      37.1,      0.000,      0.000,         0,      1.5081,      1.5490
      37.3,      0.000,      0.000,         0,      1.5918,      1.5574
      37.5,      0.000,      0.000,         0,      1.6748,      1.5657
      37.8,      0.000,      0.000,         0,      1.7582,      1.5740
      38.0,      0.000,      0.000,         0,      1.8414,      1.5824
      38.3,      0.000,      0.000,         0,      1.9249,      1.5907
      38.5,      0.000,      0.000,         0,      2.0082,      1.5990
      38.8,      0.000,      0.000,         0,      2.0916,      1.6074
      39.0,      0.000,      0.000,         0,      2.1750,      1.6157
      39.3,      0.000,      0.000,         0,      2.2582,      1.6240
      39.5,      0.000,      0.000,         0,      2.3416,      1.6324
      39.7,      0.000,      0.000,         0,      2.4249,      1.6407
      39.9,      0.000,      0.000,         0,      2.5082,      1.6490
      40.2,      0.000,      0.000,         0,      2.5914,      1.6574
      40.4,      0.000,      0.000,         0,      2.6750,      1.6657
      40.6,      0.000,      0.000,         0,      2.7583,      1.6740
      40.8,      0.000,      0.000,         0,      2.8416,      1.6824
      41.0,      0.000,      0.000,         0,      2.9246,      1.6907
      41.2,      0.000,      0.000,         0,      3.0081,      1.6990
      41.5,      0.000,      0.000,         0,      3.0915,      1.7074
      41.7,      0.000,      0.000,         0,      3.1749,      1.7157
      41.9,      0.000,      0.000,         0,      3.2582,      1.7240
      42.1,      0.000,      0.000,         0,      3.3415,      1.7324
      42.4,      0.000,      0.000,         0,      3.4249,      1.7407
      42.6,      0.000,      0.000,         0,      3.5083,      1.7490
      42.8,      0.000,      0.000,         0,      3.5916,      1.7574
      43.1,      0.000,      0.000,         0,      3.6748,      1.7657
      43.3,      0.000,      0.000,         0,      3.7582,      1.7740
      43.5,      0.000,      0.000,         0,      3.8416,      1.7824
      43.7,      0.000,      0.000,         0,      3.9249,      1.7907
      43.9,      0.000,      0.000,         0,      4.0081,      1.7990
      44.1,      0.000,      0.000,         0,      4.0914,      1.8074
      44.4,      0.000,      0.000,         0,      4.1748,      1.8157
      44.6,      0.000,      0.000,         0,      4.2581,      1.8240
      44.8,      0.000,      0.000,         0,      4.3415,      1.8324
      45.0,      0.000,      0.000,         0,      4.4249,      1.8407
      45.2,      0.000,      0.000,         0,      4.5082,      1.8490
      45.5,      0.000,      0.000,         0,      4.5913,      1.8574
      45.7,      0.000,      0.000,         0,      4.6748,      1.8657
      45.9,      0.000,      0.000,         0,      4.7581,      1.8740
      46.1,      0.000,      0.000,         0,      4.8415,      1.8824
      46.3,      0.000,      0.000,         0,      4.9247,      1.8907
      46.5,      0.000,      0.000,         0,      5.0082,      1.8990
      46.7,      0.000,      0.000,         0,      5.0913,      1.9074
      46.8,      0.000,      0.000,         0,      5.1747,      1.9157
      47.0,      0.000,      0.000,         0,      5.2581,      1.9240
      47.1,      0.000,      0.000,         0,      5.3415,      1.9324
      47.2,      0.000,      0.000,         0,      5.4249,      1.9407
      47.2,      0.000,      0.000,         0,      5.5080,      1.9490
      47.2,      0.000,      0.000,         0,      5.5915,      1.9574
      47.2,      0.000,      0.000,         0,      5.6748,      1.9657
      47.0,      0.000,      0.000,         0,      5.7582,      1.9740
      46.8,      0.000,      0.000,         0,      5.8413,      1.9824
      46.5,      0.000,      0.000,         0,      5.9249,      1.9907
      45.2,      0.000,      0.000,         0,      6.0080,      1.9990
       0.0,      0.000,      0.000,         0,      6.0914,      2.0074
       0.0,      0.000,      0.000,         0,      6.1746,      2.0157
       0.0,      0.000,      0.000,         0,      6.2581,      2.0240
       0.0,      0.000,      0.000,         0,      6.3414,      2.0324
       0.0,      0.000,      0.000,         0,      6.4248,      2.0407
       0.0,      0.000,      0.000,         0,      6.5077,      2.0490
       0.0,      0.000,      0.000,         0,      6.5914,      2.0574
       0.0,      0.000,      0.000,         0,      6.6746,      2.0657
       0.0,      0.000,      0.000,         0,      6.7580,      2.0740
       0.0,      0.000,      0.000,         0,      6.8414,      2.0824
       0.0,      0.000,      0.000,         0,      6.9247,      2.0907
       0.0,      0.000,      0.000,         0,      7.0082,      2.0990
       0.0,      0.000,      0.000,         0,      7.0913,      2.1074