File: Alban repo/Quiz 1/suction cup instron tests/oct-dec-2019_raw-data/d30e10-01-inwater-onwhiteplatic-nopump-10mm-test4.raw
Operator: 1

Date,Time,Specimen#
10/25/19,17:11:15,1

---------------------------------------


Area (mm^2):,      1.00,Flat,     25.40,     25.40,     25.40
Gage Len (mm):,     25.40


LOAD (N),STRAIN 1 (mm),STRAIN 2 (mm),STRESS (MPa),POSITION (mm),TIME (min)
       2.6,      0.000,      0.000,         0,      0.0808,      0.0083
       3.1,      0.000,      0.000,         0,      0.1642,      0.0167
       3.2,      0.000,      0.000,         0,      0.2476,      0.0250
       3.2,      0.000,      0.000,         0,      0.3310,      0.0333
       3.2,      0.000,      0.000,         0,      0.4143,      0.0417
       3.4,      0.000,      0.000,         0,      0.4975,      0.0500
       3.9,      0.000,      0.000,         0,      0.5807,      0.0583
       4.4,      0.000,      0.000,         0,      0.6641,      0.0667
       5.0,      0.000,      0.000,         0,      0.7475,      0.0750
       5.6,      0.000,      0.000,         0,      0.8308,      0.0833
       6.1,      0.000,      0.000,         0,      0.9142,      0.0917
       6.6,      0.000,      0.000,         0,      0.9976,      0.1000
       7.2,      0.000,      0.000,         0,      1.0809,      0.1083
       7.7,      0.000,      0.000,         0,      1.1641,      0.1167
       8.2,      0.000,      0.000,         0,      1.2475,      0.1250
       8.7,      0.000,      0.000,         0,      1.3309,      0.1333
       9.2,      0.000,      0.000,         0,      1.4142,      0.1417
       9.7,      0.000,      0.000,         0,      1.4975,      0.1500
      10.2,      0.000,      0.000,         0,      1.5808,      0.1583
      10.7,      0.000,      0.000,         0,      1.6641,      0.1667
      11.1,      0.000,      0.000,         0,      1.7475,      0.1750
      11.6,      0.000,      0.000,         0,      1.8308,      0.1833
      12.1,      0.000,      0.000,         0,      1.9142,      0.1917
      12.5,      0.000,      0.000,         0,      1.9975,      0.2000
      12.9,      0.000,      0.000,         0,      2.0807,      0.2083
      13.4,      0.000,      0.000,         0,      2.1641,      0.2167
      13.8,      0.000,      0.000,         0,      2.2474,      0.2250
      14.2,      0.000,      0.000,         0,      2.3308,      0.2333
      14.6,      0.000,      0.000,         0,      2.4141,      0.2417
      15.0,      0.000,      0.000,         0,      2.4975,      0.2500
      15.4,      0.000,      0.000,         0,      2.5807,      0.2583
      15.7,      0.000,      0.000,         0,      2.6641,      0.2667
      16.1,      0.000,      0.000,         0,      2.7474,      0.2750
      16.4,      0.000,      0.000,         0,      2.8307,      0.2833
      16.8,      0.000,      0.000,         0,      2.9140,      0.2917
      17.1,      0.000,      0.000,         0,      2.9974,      0.3000
      17.5,      0.000,      0.000,         0,      3.0809,      0.3083
      17.8,      0.000,      0.000,         0,      3.1641,      0.3167
      18.2,      0.000,      0.000,         0,      3.2475,      0.3250
      18.5,      0.000,      0.000,         0,      3.3309,      0.3333
      18.9,      0.000,      0.000,         0,      3.4140,      0.3417
      19.2,      0.000,      0.000,         0,      3.4971,      0.3500
      19.5,      0.000,      0.000,         0,      3.5809,      0.3583
      19.9,      0.000,      0.000,         0,      3.6640,      0.3667
      20.2,      0.000,      0.000,         0,      3.7474,      0.3750
      20.5,      0.000,      0.000,         0,      3.8307,      0.3833
      20.8,      0.000,      0.000,         0,      3.9140,      0.3917
      21.1,      0.000,      0.000,         0,      3.9973,      0.4000
      21.4,      0.000,      0.000,         0,      4.0807,      0.4083
      21.7,      0.000,      0.000,         0,      4.1641,      0.4167
      22.0,      0.000,      0.000,         0,      4.2474,      0.4250
      22.3,      0.000,      0.000,         0,      4.3307,      0.4333
      22.6,      0.000,      0.000,         0,      4.4141,      0.4417
      22.8,      0.000,      0.000,         0,      4.4974,      0.4500
      23.1,      0.000,      0.000,         0,      4.5806,      0.4583
      23.4,      0.000,      0.000,         0,      4.6642,      0.4667
      23.6,      0.000,      0.000,         0,      4.7472,      0.4750
      23.9,      0.000,      0.000,         0,      4.8306,      0.4833
      24.1,      0.000,      0.000,         0,      4.9138,      0.4917
      24.4,      0.000,      0.000,         0,      4.9974,      0.5000
      24.7,      0.000,      0.000,         0,      5.0807,      0.5083
      25.0,      0.000,      0.000,         0,      5.1639,      0.5167
      25.3,      0.000,      0.000,         0,      5.2473,      0.5250
      25.5,      0.000,      0.000,         0,      5.3307,      0.5333
      25.8,      0.000,      0.000,         0,      5.4138,      0.5417
      26.1,      0.000,      0.000,         0,      5.4973,      0.5500
      26.3,      0.000,      0.000,         0,      5.5806,      0.5583
      26.6,      0.000,      0.000,         0,      5.6641,      0.5667
      26.9,      0.000,      0.000,         0,      5.7473,      0.5750
      27.1,      0.000,      0.000,         0,      5.8306,      0.5833
      27.4,      0.000,      0.000,         0,      5.9140,      0.5917
      27.7,      0.000,      0.000,         0,      5.9973,      0.6000
      27.9,      0.000,      0.000,         0,      6.0806,      0.6083
      28.2,      0.000,      0.000,         0,      6.1638,      0.6167
      28.4,      0.000,      0.000,         0,      6.2475,      0.6250
      28.7,      0.000,      0.000,         0,      6.3305,      0.6333
      29.0,      0.000,      0.000,         0,      6.4139,      0.6417
      29.2,      0.000,      0.000,         0,      6.4971,      0.6500
      29.5,      0.000,      0.000,         0,      6.5807,      0.6583
      29.8,      0.000,      0.000,         0,      6.6638,      0.6667
      30.1,      0.000,      0.000,         0,      6.7472,      0.6750
      30.4,      0.000,      0.000,         0,      6.8306,      0.6833
      30.7,      0.000,      0.000,         0,      6.9139,      0.6917
      31.0,      0.000,      0.000,         0,      6.9972,      0.7000
      31.3,      0.000,      0.000,         0,      7.0806,      0.7083
      31.6,      0.000,      0.000,         0,      7.1639,      0.7167
      31.8,      0.000,      0.000,         0,      7.2470,      0.7250
      32.1,      0.000,      0.000,         0,      7.3306,      0.7333
      32.4,      0.000,      0.000,         0,      7.4140,      0.7417
      32.7,      0.000,      0.000,         0,      7.4972,      0.7500
      32.9,      0.000,      0.000,         0,      7.5805,      0.7583
      33.2,      0.000,      0.000,         0,      7.6640,      0.7667
      33.4,      0.000,      0.000,         0,      7.7473,      0.7750
      33.7,      0.000,      0.000,         0,      7.8302,      0.7833
      33.9,      0.000,      0.000,         0,      7.9139,      0.7917
      34.2,      0.000,      0.000,         0,      7.9972,      0.8000
      34.5,      0.000,      0.000,         0,      8.0805,      0.8083
      34.7,      0.000,      0.000,         0,      8.1638,      0.8167
      35.0,      0.000,      0.000,         0,      8.2473,      0.8250
      35.3,      0.000,      0.000,         0,      8.3305,      0.8333
      35.5,      0.000,      0.000,         0,      8.4139,      0.8417
      35.8,      0.000,      0.000,         0,      8.4972,      0.8500
      36.1,      0.000,      0.000,         0,      8.5805,      0.8583
      36.3,      0.000,      0.000,         0,      8.6637,      0.8667
      36.6,      0.000,      0.000,         0,      8.7472,      0.8750
      36.8,      0.000,      0.000,         0,      8.8305,      0.8833
      37.1,      0.000,      0.000,         0,      8.9139,      0.8917
      37.3,      0.000,      0.000,         0,      8.9972,      0.9000
      37.5,      0.000,      0.000,         0,      9.0804,      0.9083
      37.8,      0.000,      0.000,         0,      9.1634,      0.9167
      38.0,      0.000,      0.000,         0,      9.2471,      0.9250
      38.3,      0.000,      0.000,         0,      9.3305,      0.9333
      38.5,      0.000,      0.000,         0,      9.4138,      0.9417
      38.7,      0.000,      0.000,         0,      9.4972,      0.9500
      39.0,      0.000,      0.000,         0,      9.5803,      0.9583
      39.2,      0.000,      0.000,         0,      9.6638,      0.9667
      39.5,      0.000,      0.000,         0,      9.7471,      0.9750
      39.7,      0.000,      0.000,         0,      9.8306,      0.9833
      40.0,      0.000,      0.000,         0,      9.9137,      0.9917
      40.2,      0.000,      0.000,         0,      9.9971,      1.0000
      40.4,      0.000,      0.000,         0,     10.0801,      1.0083
      40.7,      0.000,      0.000,         0,     10.1636,      1.0167
      40.9,      0.000,      0.000,         0,     10.2470,      1.0250
      41.2,      0.000,      0.000,         0,     10.3306,      1.0333
      41.5,      0.000,      0.000,         0,     10.4139,      1.0417
      41.7,      0.000,      0.000,         0,     10.4968,      1.0500
      42.0,      0.000,      0.000,         0,     10.5806,      1.0583
      42.2,      0.000,      0.000,         0,     10.6638,      1.0667
      42.4,      0.000,      0.000,         0,     10.7470,      1.0750
      42.6,      0.000,      0.000,         0,     10.8303,      1.0833
      42.8,      0.000,      0.000,         0,     10.9139,      1.0917
      43.0,      0.000,      0.000,         0,     10.9970,      1.1000
      43.2,      0.000,      0.000,         0,     11.0803,      1.1083
      43.5,      0.000,      0.000,         0,     11.1636,      1.1167
      43.7,      0.000,      0.000,         0,     11.2472,      1.1250
      43.9,      0.000,      0.000,         0,     11.3303,      1.1333
      44.1,      0.000,      0.000,         0,     11.4136,      1.1417
      44.4,      0.000,      0.000,         0,     11.4972,      1.1500
      44.6,      0.000,      0.000,         0,     11.5805,      1.1583
      44.8,      0.000,      0.000,         0,     11.6636,      1.1667
      45.0,      0.000,      0.000,         0,     11.7471,      1.1750
      45.3,      0.000,      0.000,         0,     11.8304,      1.1833
      45.5,      0.000,      0.000,         0,     11.9135,      1.1917
      45.7,      0.000,      0.000,         0,     11.9970,      1.2000
      45.9,      0.000,      0.000,         0,     12.0804,      1.2083
      46.1,      0.000,      0.000,         0,     12.1638,      1.2167
      46.3,      0.000,      0.000,         0,     12.2470,      1.2250
      46.5,      0.000,      0.000,         0,     12.3304,      1.2333
      46.7,      0.000,      0.000,         0,     12.4136,      1.2417
      46.9,      0.000,      0.000,         0,     12.4969,      1.2500
      47.1,      0.000,      0.000,         0,     12.5803,      1.2583
      47.4,      0.000,      0.000,         0,     12.6636,      1.2667
      47.5,      0.000,      0.000,         0,     12.7470,      1.2750
      47.7,      0.000,      0.000,         0,     12.8303,      1.2833
      47.9,      0.000,      0.000,         0,     12.9137,      1.2917
      48.1,      0.000,      0.000,         0,     12.9969,      1.3000
      48.3,      0.000,      0.000,         0,     13.0803,      1.3083
      48.5,      0.000,      0.000,         0,     13.1635,      1.3167
      48.6,      0.000,      0.000,         0,     13.2470,      1.3250
      48.8,      0.000,      0.000,         0,     13.3301,      1.3333
      48.9,      0.000,      0.000,         0,     13.4135,      1.3417
      49.0,      0.000,      0.000,         0,     13.4969,      1.3500
      49.0,      0.000,      0.000,         0,     13.5804,      1.3583
      49.0,      0.000,      0.000,         0,     13.6637,      1.3667
      48.8,      0.000,      0.000,         0,     13.7468,      1.3750
      48.5,      0.000,      0.000,         0,     13.8303,      1.3833
      37.3,      0.000,      0.000,         0,     13.9137,      1.3917
       0.0,      0.000,      0.000,         0,     13.9969,      1.4000
       0.0,      0.000,      0.000,         0,     14.0801,      1.4083
       0.0,      0.000,      0.000,         0,     14.1638,      1.4167
       0.0,      0.000,      0.000,         0,     14.2469,      1.4250
       0.0,      0.000,      0.000,         0,     14.3301,      1.4333
       0.0,      0.000,      0.000,         0,     14.4135,      1.4417
       0.0,      0.000,      0.000,         0,     14.4970,      1.4500
       0.0,      0.000,      0.000,         0,     14.5801,      1.4583
       0.0,      0.000,      0.000,         0,     14.6634,      1.4667
       0.0,      0.000,      0.000,         0,     14.7469,      1.4750
       0.0,      0.000,      0.000,         0,     14.8302,      1.4833
       0.0,      0.000,      0.000,         0,     14.9136,      1.4917
       0.0,      0.000,      0.000,         0,     14.9969,      1.5000
       0.0,      0.000,      0.000,         0,     15.0802,      1.5083
       0.0,      0.000,      0.000,         0,     15.1634,      1.5167
       0.0,      0.000,      0.000,         0,     15.2469,      1.5250
       0.0,      0.000,      0.000,         0,     15.3303,      1.5333
       0.0,      0.000,      0.000,         0,     15.4135,      1.5417
       0.0,      0.000,      0.000,         0,     15.4967,      1.5500
       0.0,      0.000,      0.000,         0,     15.5803,      1.5583
       0.0,      0.000,      0.000,         0,     15.6635,      1.5667
       0.0,      0.000,      0.000,         0,     15.7465,      1.5750
       0.0,      0.000,      0.000,         0,     15.8301,      1.5833
       0.0,      0.000,      0.000,         0,     15.9137,      1.5917