File: Alban repo/Quiz 1/suction cup instron tests/oct-dec-2019_raw-data/d30e10-01-inwater-on36grit-diaphragmpump-100mm-test2.raw
Operator: 1

Date,Time,Specimen#
11/09/19,17:50:23,1

---------------------------------------


Area (mm^2):,      1.00,Flat,     25.40,     25.40,     25.40
Gage Len (mm):,     25.40


LOAD (N),STRAIN 1 (mm),STRAIN 2 (mm),STRESS (MPa),POSITION (mm),TIME (min)
      18.8,      0.000,      0.000,         0,     -0.1622,      0.0083
      20.2,      0.000,      0.000,         0,     -0.3287,      0.0167
      20.1,      0.000,      0.000,         0,     -0.4953,      0.0250
      19.7,      0.000,      0.000,         0,     -0.6622,      0.0333
      19.3,      0.000,      0.000,         0,     -0.8286,      0.0417
      18.9,      0.000,      0.000,         0,     -0.9953,      0.0500
      18.5,      0.000,      0.000,         0,     -1.1619,      0.0583
      18.0,      0.000,      0.000,         0,     -1.3288,      0.0667
      17.6,      0.000,      0.000,         0,     -1.4955,      0.0750
      17.2,      0.000,      0.000,         0,     -1.6621,      0.0833
      16.7,      0.000,      0.000,         0,     -1.8288,      0.0917
      16.3,      0.000,      0.000,         0,     -1.9954,      0.1000
      15.8,      0.000,      0.000,         0,     -2.1621,      0.1083
      15.4,      0.000,      0.000,         0,     -2.3287,      0.1167
      15.0,      0.000,      0.000,         0,     -2.4954,      0.1250
      14.5,      0.000,      0.000,         0,     -2.6620,      0.1333
      14.1,      0.000,      0.000,         0,     -2.8285,      0.1417
      13.6,      0.000,      0.000,         0,     -2.9952,      0.1500
      13.1,      0.000,      0.000,         0,     -3.1622,      0.1583
      12.6,      0.000,      0.000,         0,     -3.3287,      0.1667
      12.1,      0.000,      0.000,         0,     -3.4953,      0.1750
      11.6,      0.000,      0.000,         0,     -3.6618,      0.1833
      11.0,      0.000,      0.000,         0,     -3.8286,      0.1917
      10.5,      0.000,      0.000,         0,     -3.9953,      0.2000
       9.8,      0.000,      0.000,         0,     -4.1621,      0.2083
       9.2,      0.000,      0.000,         0,     -4.3284,      0.2167
       8.5,      0.000,      0.000,         0,     -4.4953,      0.2250
       7.8,      0.000,      0.000,         0,     -4.6619,      0.2333
       7.1,      0.000,      0.000,         0,     -4.8286,      0.2417
       6.4,      0.000,      0.000,         0,     -4.9952,      0.2500
       5.5,      0.000,      0.000,         0,     -5.1617,      0.2583
       4.6,      0.000,      0.000,         0,     -5.3286,      0.2667
       3.6,      0.000,      0.000,         0,     -5.4950,      0.2750
       2.5,      0.000,      0.000,         0,     -5.6619,      0.2833
       1.3,      0.000,      0.000,         0,     -5.8285,      0.2917
      -0.1,      0.000,      0.000,         0,     -5.9954,      0.3000
      -1.8,      0.000,      0.000,         0,     -6.1620,      0.3083
      -3.8,      0.000,      0.000,         0,     -6.3285,      0.3167
      -6.1,      0.000,      0.000,         0,     -6.4951,      0.3250
      -8.8,      0.000,      0.000,         0,     -6.6618,      0.3333
     -11.7,      0.000,      0.000,         0,     -6.8287,      0.3417
     -14.7,      0.000,      0.000,         0,     -6.9951,      0.3500
     -14.2,      0.000,      0.000,         0,     -7.0496,      0.3676
     -13.5,      0.000,      0.000,         0,     -7.0494,      0.3842
     -13.0,      0.000,      0.000,         0,     -7.0494,      0.4009
     -12.6,      0.000,      0.000,         0,     -7.0494,      0.4176
     -12.3,      0.000,      0.000,         0,     -7.0494,      0.4342
     -12.0,      0.000,      0.000,         0,     -7.0492,      0.4509
     -11.8,      0.000,      0.000,         0,     -7.0490,      0.4676
     -11.6,      0.000,      0.000,         0,     -7.0488,      0.4842
     -11.5,      0.000,      0.000,         0,     -7.0486,      0.5009
     -11.3,      0.000,      0.000,         0,     -7.0219,      0.5176
     -11.0,      0.000,      0.000,         0,     -7.0151,      0.5342
     -10.9,      0.000,      0.000,         0,     -7.0139,      0.5509
     -10.8,      0.000,      0.000,         0,     -7.0124,      0.5676
     -10.7,      0.000,      0.000,         0,     -7.0124,      0.5842
     -10.6,      0.000,      0.000,         0,     -7.0124,      0.6009
       2.9,      0.000,      0.000,         0,     -6.3424,      0.6092
      11.7,      0.000,      0.000,         0,     -5.5084,      0.6176
      17.5,      0.000,      0.000,         0,     -4.6739,      0.6259
      21.4,      0.000,      0.000,         0,     -3.8399,      0.6342
      24.2,      0.000,      0.000,         0,     -3.0052,      0.6426
      26.6,      0.000,      0.000,         0,     -2.1722,      0.6509
      29.0,      0.000,      0.000,         0,     -1.3387,      0.6592
      31.4,      0.000,      0.000,         0,     -0.5054,      0.6676
      33.6,      0.000,      0.000,         0,      0.3277,      0.6759
      36.0,      0.000,      0.000,         0,      1.1612,      0.6842
      38.5,      0.000,      0.000,         0,      1.9945,      0.6926
      41.1,      0.000,      0.000,         0,      2.8275,      0.7009
      43.6,      0.000,      0.000,         0,      3.6610,      0.7092
      46.1,      0.000,      0.000,         0,      4.4941,      0.7176
      48.4,      0.000,      0.000,         0,      5.3276,      0.7259
      50.7,      0.000,      0.000,         0,      6.1609,      0.7342
      52.9,      0.000,      0.000,         0,      6.9940,      0.7426
      54.7,      0.000,      0.000,         0,      7.8270,      0.7509
      55.8,      0.000,      0.000,         0,      8.6607,      0.7592
       0.1,      0.000,      0.000,         0,      9.4938,      0.7676
       0.1,      0.000,      0.000,         0,     10.3271,      0.7759
       0.1,      0.000,      0.000,         0,     11.1604,      0.7842
       0.1,      0.000,      0.000,         0,     11.9936,      0.7926
       0.1,      0.000,      0.000,         0,     12.8269,      0.8009
       0.1,      0.000,      0.000,         0,     13.6602,      0.8092
       0.1,      0.000,      0.000,         0,     14.4935,      0.8176
       0.2,      0.000,      0.000,         0,     15.3268,      0.8259