File: Alban repo/Quiz 1/suction cup instron tests/oct-dec-2019_raw-data/d30e10-01-inwater-onwhiteplatic-nopump-100mm-test2.raw
Operator: 1

Date,Time,Specimen#
10/25/19,17:31:12,1

---------------------------------------


Area (mm^2):,      1.00,Flat,     25.40,     25.40,     25.40
Gage Len (mm):,     25.40


LOAD (N),STRAIN 1 (mm),STRAIN 2 (mm),STRESS (MPa),POSITION (mm),TIME (min)
       9.9,      0.000,      0.000,         0,      0.8098,      0.0083
      15.9,      0.000,      0.000,         0,      1.6426,      0.0167
      21.1,      0.000,      0.000,         0,      2.4767,      0.0250
      24.8,      0.000,      0.000,         0,      3.3109,      0.0333
      27.8,      0.000,      0.000,         0,      4.1442,      0.0417
      30.5,      0.000,      0.000,         0,      4.9774,      0.0500
      33.2,      0.000,      0.000,         0,      5.8108,      0.0583
      36.0,      0.000,      0.000,         0,      6.6439,      0.0667
      38.7,      0.000,      0.000,         0,      7.4772,      0.0750
      41.3,      0.000,      0.000,         0,      8.3105,      0.0833
      44.0,      0.000,      0.000,         0,      9.1439,      0.0917
      46.7,      0.000,      0.000,         0,      9.9771,      0.1000
      49.2,      0.000,      0.000,         0,     10.8104,      0.1083
      51.7,      0.000,      0.000,         0,     11.6436,      0.1167
      54.2,      0.000,      0.000,         0,     12.4770,      0.1250
      56.6,      0.000,      0.000,         0,     13.3103,      0.1333
      58.3,      0.000,      0.000,         0,     14.1435,      0.1417
      55.4,      0.000,      0.000,         0,     14.9768,      0.1500
       0.0,      0.000,      0.000,         0,     15.8102,      0.1583
       0.0,      0.000,      0.000,         0,     16.6434,      0.1667
       0.0,      0.000,      0.000,         0,     17.4766,      0.1750
       0.0,      0.000,      0.000,         0,     18.3099,      0.1833
       0.0,      0.000,      0.000,         0,     19.1432,      0.1917
       0.0,      0.000,      0.000,         0,     19.9766,      0.2000