File: Alban repo/Quiz 1/suction cup instron tests/oct-dec-2019_raw-data/d30e10-01-inwater-on80grit-nopump-10mm-test3.raw
Operator: 1

Date,Time,Specimen#
10/25/19,18:42:10,1

---------------------------------------


Area (mm^2):,      1.00,Flat,     25.40,     25.40,     25.40
Gage Len (mm):,     25.40


LOAD (N),STRAIN 1 (mm),STRAIN 2 (mm),STRESS (MPa),POSITION (mm),TIME (min)
       2.6,      0.000,      0.000,         0,      0.0809,      0.0083
       3.3,      0.000,      0.000,         0,      0.1643,      0.0167
       3.9,      0.000,      0.000,         0,      0.2476,      0.0250
       4.6,      0.000,      0.000,         0,      0.3307,      0.0333
       5.2,      0.000,      0.000,         0,      0.4142,      0.0417
       5.8,      0.000,      0.000,         0,      0.4976,      0.0500
       6.4,      0.000,      0.000,         0,      0.5810,      0.0583
       7.0,      0.000,      0.000,         0,      0.6640,      0.0667
       7.6,      0.000,      0.000,         0,      0.7477,      0.0750
       8.2,      0.000,      0.000,         0,      0.8310,      0.0833
       8.8,      0.000,      0.000,         0,      0.9143,      0.0917
       9.4,      0.000,      0.000,         0,      0.9976,      0.1000
       9.9,      0.000,      0.000,         0,      1.0808,      0.1083
      10.5,      0.000,      0.000,         0,      1.1644,      0.1167
      11.0,      0.000,      0.000,         0,      1.2475,      0.1250
      11.6,      0.000,      0.000,         0,      1.3308,      0.1333
      12.1,      0.000,      0.000,         0,      1.4142,      0.1417
      12.6,      0.000,      0.000,         0,      1.4976,      0.1500
      13.1,      0.000,      0.000,         0,      1.5809,      0.1583
      13.6,      0.000,      0.000,         0,      1.6640,      0.1667
      14.1,      0.000,      0.000,         0,      1.7475,      0.1750
      14.5,      0.000,      0.000,         0,      1.8309,      0.1833
      15.0,      0.000,      0.000,         0,      1.9140,      0.1917
      15.4,      0.000,      0.000,         0,      1.9975,      0.2000
      15.9,      0.000,      0.000,         0,      2.0808,      0.2083
      16.3,      0.000,      0.000,         0,      2.1641,      0.2167
      16.7,      0.000,      0.000,         0,      2.2475,      0.2250
      17.0,      0.000,      0.000,         0,      2.3308,      0.2333
      17.4,      0.000,      0.000,         0,      2.4144,      0.2417
      17.8,      0.000,      0.000,         0,      2.4974,      0.2500
      18.2,      0.000,      0.000,         0,      2.5807,      0.2583
      18.6,      0.000,      0.000,         0,      2.6642,      0.2667
      18.9,      0.000,      0.000,         0,      2.7475,      0.2750
      19.3,      0.000,      0.000,         0,      2.8308,      0.2833
      19.6,      0.000,      0.000,         0,      2.9143,      0.2917
      19.9,      0.000,      0.000,         0,      2.9974,      0.3000
      20.3,      0.000,      0.000,         0,      3.0808,      0.3083
      20.6,      0.000,      0.000,         0,      3.1641,      0.3167
      20.9,      0.000,      0.000,         0,      3.2476,      0.3250
      21.2,      0.000,      0.000,         0,      3.3308,      0.3333
      21.5,      0.000,      0.000,         0,      3.4141,      0.3417
      21.8,      0.000,      0.000,         0,      3.4976,      0.3500
      22.1,      0.000,      0.000,         0,      3.5806,      0.3583
      22.4,      0.000,      0.000,         0,      3.6641,      0.3667
      22.7,      0.000,      0.000,         0,      3.7475,      0.3750
      23.0,      0.000,      0.000,         0,      3.8308,      0.3833
      23.3,      0.000,      0.000,         0,      3.9139,      0.3917
      23.6,      0.000,      0.000,         0,      3.9974,      0.4000
      23.9,      0.000,      0.000,         0,      4.0808,      0.4083
      24.3,      0.000,      0.000,         0,      4.1641,      0.4167
      24.6,      0.000,      0.000,         0,      4.2473,      0.4250
      24.9,      0.000,      0.000,         0,      4.3307,      0.4333
      25.2,      0.000,      0.000,         0,      4.4141,      0.4417
      25.5,      0.000,      0.000,         0,      4.4973,      0.4500
      25.8,      0.000,      0.000,         0,      4.5807,      0.4583
      26.1,      0.000,      0.000,         0,      4.6642,      0.4667
      26.3,      0.000,      0.000,         0,      4.7475,      0.4750
      26.6,      0.000,      0.000,         0,      4.8307,      0.4833
      26.9,      0.000,      0.000,         0,      4.9140,      0.4917
      27.2,      0.000,      0.000,         0,      4.9974,      0.5000
      27.5,      0.000,      0.000,         0,      5.0808,      0.5083
      27.8,      0.000,      0.000,         0,      5.1640,      0.5167
      28.1,      0.000,      0.000,         0,      5.2474,      0.5250
      28.4,      0.000,      0.000,         0,      5.3307,      0.5333
      28.7,      0.000,      0.000,         0,      5.4141,      0.5417
      29.0,      0.000,      0.000,         0,      5.4974,      0.5500
      29.2,      0.000,      0.000,         0,      5.5806,      0.5583
      29.5,      0.000,      0.000,         0,      5.6640,      0.5667
      29.8,      0.000,      0.000,         0,      5.7473,      0.5750
      30.1,      0.000,      0.000,         0,      5.8307,      0.5833
      30.4,      0.000,      0.000,         0,      5.9140,      0.5917
      30.7,      0.000,      0.000,         0,      5.9973,      0.6000
      31.0,      0.000,      0.000,         0,      6.0806,      0.6083
      31.3,      0.000,      0.000,         0,      6.1641,      0.6167
      31.6,      0.000,      0.000,         0,      6.2472,      0.6250
      31.9,      0.000,      0.000,         0,      6.3305,      0.6333
      32.2,      0.000,      0.000,         0,      6.4140,      0.6417
      32.5,      0.000,      0.000,         0,      6.4975,      0.6500
      32.8,      0.000,      0.000,         0,      6.5805,      0.6583
      33.1,      0.000,      0.000,         0,      6.6640,      0.6667
      33.4,      0.000,      0.000,         0,      6.7474,      0.6750
      33.8,      0.000,      0.000,         0,      6.8306,      0.6833
      34.1,      0.000,      0.000,         0,      6.9140,      0.6917
      34.4,      0.000,      0.000,         0,      6.9973,      0.7000
      34.7,      0.000,      0.000,         0,      7.0808,      0.7083
      35.0,      0.000,      0.000,         0,      7.1637,      0.7167
      35.3,      0.000,      0.000,         0,      7.2473,      0.7250
      35.7,      0.000,      0.000,         0,      7.3307,      0.7333
      36.0,      0.000,      0.000,         0,      7.4140,      0.7417
      36.3,      0.000,      0.000,         0,      7.4972,      0.7500
      36.6,      0.000,      0.000,         0,      7.5806,      0.7583
      36.8,      0.000,      0.000,         0,      7.6637,      0.7667
      37.1,      0.000,      0.000,         0,      7.7473,      0.7750
      37.4,      0.000,      0.000,         0,      7.8306,      0.7833
      37.8,      0.000,      0.000,         0,      7.9140,      0.7917
      38.1,      0.000,      0.000,         0,      7.9972,      0.8000
      38.4,      0.000,      0.000,         0,      8.0805,      0.8083
      38.7,      0.000,      0.000,         0,      8.1640,      0.8167
      38.9,      0.000,      0.000,         0,      8.2470,      0.8250
      39.2,      0.000,      0.000,         0,      8.3305,      0.8333
      39.4,      0.000,      0.000,         0,      8.4139,      0.8417
      39.7,      0.000,      0.000,         0,      8.4973,      0.8500
      40.0,      0.000,      0.000,         0,      8.5805,      0.8583
      40.3,      0.000,      0.000,         0,      8.6640,      0.8667
      40.5,      0.000,      0.000,         0,      8.7473,      0.8750
      40.8,      0.000,      0.000,         0,      8.8305,      0.8833
      41.1,      0.000,      0.000,         0,      8.9138,      0.8917
      41.3,      0.000,      0.000,         0,      8.9973,      0.9000
      41.6,      0.000,      0.000,         0,      9.0806,      0.9083
      41.9,      0.000,      0.000,         0,      9.1637,      0.9167
      42.2,      0.000,      0.000,         0,      9.2473,      0.9250
      42.4,      0.000,      0.000,         0,      9.3305,      0.9333
      42.7,      0.000,      0.000,         0,      9.4140,      0.9417
      43.0,      0.000,      0.000,         0,      9.4971,      0.9500
      43.2,      0.000,      0.000,         0,      9.5806,      0.9583
      43.5,      0.000,      0.000,         0,      9.6638,      0.9667
      43.8,      0.000,      0.000,         0,      9.7472,      0.9750
      44.1,      0.000,      0.000,         0,      9.8305,      0.9833
      44.4,      0.000,      0.000,         0,      9.9139,      0.9917
      44.6,      0.000,      0.000,         0,      9.9973,      1.0000
      44.9,      0.000,      0.000,         0,     10.0805,      1.0083
      45.2,      0.000,      0.000,         0,     10.1638,      1.0167
      45.5,      0.000,      0.000,         0,     10.2470,      1.0250
      45.8,      0.000,      0.000,         0,     10.3305,      1.0333
      46.0,      0.000,      0.000,         0,     10.4138,      1.0417
      46.3,      0.000,      0.000,         0,     10.4973,      1.0500
      46.6,      0.000,      0.000,         0,     10.5805,      1.0583
      46.8,      0.000,      0.000,         0,     10.6638,      1.0667
      47.1,      0.000,      0.000,         0,     10.7471,      1.0750
      47.3,      0.000,      0.000,         0,     10.8305,      1.0833
      47.6,      0.000,      0.000,         0,     10.9137,      1.0917
      47.9,      0.000,      0.000,         0,     10.9971,      1.1000
      48.1,      0.000,      0.000,         0,     11.0804,      1.1083
      48.3,      0.000,      0.000,         0,     11.1638,      1.1167
      48.5,      0.000,      0.000,         0,     11.2471,      1.1250
      48.8,      0.000,      0.000,         0,     11.3304,      1.1333
      49.0,      0.000,      0.000,         0,     11.4139,      1.1417
      49.2,      0.000,      0.000,         0,     11.4971,      1.1500
      49.5,      0.000,      0.000,         0,     11.5804,      1.1583
      49.7,      0.000,      0.000,         0,     11.6638,      1.1667
      49.9,      0.000,      0.000,         0,     11.7472,      1.1750
      50.2,      0.000,      0.000,         0,     11.8303,      1.1833
      50.4,      0.000,      0.000,         0,     11.9138,      1.1917
      50.6,      0.000,      0.000,         0,     11.9971,      1.2000
      50.8,      0.000,      0.000,         0,     12.0804,      1.2083
      51.0,      0.000,      0.000,         0,     12.1637,      1.2167
      51.3,      0.000,      0.000,         0,     12.2471,      1.2250
      51.5,      0.000,      0.000,         0,     12.3304,      1.2333
      51.7,      0.000,      0.000,         0,     12.4137,      1.2417
      51.9,      0.000,      0.000,         0,     12.4970,      1.2500
      52.1,      0.000,      0.000,         0,     12.5803,      1.2583
      52.4,      0.000,      0.000,         0,     12.6637,      1.2667
      52.6,      0.000,      0.000,         0,     12.7471,      1.2750
      52.8,      0.000,      0.000,         0,     12.8304,      1.2833
      53.1,      0.000,      0.000,         0,     12.9135,      1.2917
      53.3,      0.000,      0.000,         0,     12.9971,      1.3000
      53.6,      0.000,      0.000,         0,     13.0803,      1.3083
      53.8,      0.000,      0.000,         0,     13.1637,      1.3167
      54.1,      0.000,      0.000,         0,     13.2470,      1.3250
      54.3,      0.000,      0.000,         0,     13.3304,      1.3333
      54.5,      0.000,      0.000,         0,     13.4136,      1.3417
      54.7,      0.000,      0.000,         0,     13.4970,      1.3500
      54.9,      0.000,      0.000,         0,     13.5804,      1.3583
      55.1,      0.000,      0.000,         0,     13.6637,      1.3667
      55.3,      0.000,      0.000,         0,     13.7470,      1.3750
      55.4,      0.000,      0.000,         0,     13.8303,      1.3833
      55.6,      0.000,      0.000,         0,     13.9134,      1.3917
      55.7,      0.000,      0.000,         0,     13.9969,      1.4000
      55.9,      0.000,      0.000,         0,     14.0802,      1.4083
      56.0,      0.000,      0.000,         0,     14.1636,      1.4167
      56.2,      0.000,      0.000,         0,     14.2470,      1.4250
      56.3,      0.000,      0.000,         0,     14.3304,      1.4333
      56.2,      0.000,      0.000,         0,     14.4138,      1.4417
      56.1,      0.000,      0.000,         0,     14.4970,      1.4500
      55.6,      0.000,      0.000,         0,     14.5803,      1.4583
      46.9,      0.000,      0.000,         0,     14.6636,      1.4667
       0.1,      0.000,      0.000,         0,     14.7468,      1.4750
       0.1,      0.000,      0.000,         0,     14.8299,      1.4833
       0.1,      0.000,      0.000,         0,     14.9136,      1.4917
       0.1,      0.000,      0.000,         0,     14.9971,      1.5000
       0.1,      0.000,      0.000,         0,     15.0801,      1.5083
       0.1,      0.000,      0.000,         0,     15.1636,      1.5167
       0.1,      0.000,      0.000,         0,     15.2468,      1.5250
       0.1,      0.000,      0.000,         0,     15.3304,      1.5333
       0.1,      0.000,      0.000,         0,     15.4135,      1.5417
       0.1,      0.000,      0.000,         0,     15.4971,      1.5500
       0.1,      0.000,      0.000,         0,     15.5802,      1.5583
       0.1,      0.000,      0.000,         0,     15.6636,      1.5667
       0.1,      0.000,      0.000,         0,     15.7468,      1.5750
       0.1,      0.000,      0.000,         0,     15.8301,      1.5833
       0.1,      0.000,      0.000,         0,     15.9136,      1.5917