File: Alban repo/Quiz 1/suction cup instron tests/oct-dec-2019_raw-data/d30e10-01-inair-onwhiteplatic-diaphragmpump-10mm-test3.raw
Operator: 1

Date,Time,Specimen#
10/25/19,16:26:28,1

---------------------------------------


Area (mm^2):,      1.00,Flat,     25.40,     25.40,     25.40
Gage Len (mm):,     25.40


LOAD (N),STRAIN 1 (mm),STRAIN 2 (mm),STRESS (MPa),POSITION (mm),TIME (min)
      13.9,      0.000,      0.000,         0,     -0.1622,      0.0083
      13.5,      0.000,      0.000,         0,     -0.3290,      0.0167
      13.0,      0.000,      0.000,         0,     -0.4956,      0.0250
      12.5,      0.000,      0.000,         0,     -0.6622,      0.0333
      12.1,      0.000,      0.000,         0,     -0.8290,      0.0417
      11.7,      0.000,      0.000,         0,     -0.9955,      0.0500
      11.3,      0.000,      0.000,         0,     -1.1622,      0.0583
      10.9,      0.000,      0.000,         0,     -1.3289,      0.0667
      10.5,      0.000,      0.000,         0,     -1.4955,      0.0750
      10.1,      0.000,      0.000,         0,     -1.6622,      0.0833
       9.7,      0.000,      0.000,         0,     -1.8289,      0.0917
       9.3,      0.000,      0.000,         0,     -1.9955,      0.1000
       8.9,      0.000,      0.000,         0,     -2.1622,      0.1083
       8.6,      0.000,      0.000,         0,     -2.3288,      0.1167
       8.2,      0.000,      0.000,         0,     -2.4954,      0.1250
       7.8,      0.000,      0.000,         0,     -2.6621,      0.1333
       7.4,      0.000,      0.000,         0,     -2.8288,      0.1417
       7.0,      0.000,      0.000,         0,     -2.9955,      0.1500
       6.6,      0.000,      0.000,         0,     -3.1621,      0.1583
       6.3,      0.000,      0.000,         0,     -3.3288,      0.1667
       5.9,      0.000,      0.000,         0,     -3.4954,      0.1750
       5.5,      0.000,      0.000,         0,     -3.6621,      0.1833
       5.0,      0.000,      0.000,         0,     -3.8287,      0.1917
       4.6,      0.000,      0.000,         0,     -3.9953,      0.2000
       4.1,      0.000,      0.000,         0,     -4.1620,      0.2083
       3.6,      0.000,      0.000,         0,     -4.3287,      0.2167
       3.2,      0.000,      0.000,         0,     -4.4954,      0.2250
       2.6,      0.000,      0.000,         0,     -4.6622,      0.2333
       2.1,      0.000,      0.000,         0,     -4.8285,      0.2417
       1.5,      0.000,      0.000,         0,     -4.9954,      0.2500
       0.9,      0.000,      0.000,         0,     -5.1619,      0.2583
       0.2,      0.000,      0.000,         0,     -5.3286,      0.2667
      -0.4,      0.000,      0.000,         0,     -5.4955,      0.2750
      -1.2,      0.000,      0.000,         0,     -5.6621,      0.2833
      -1.9,      0.000,      0.000,         0,     -5.8286,      0.2917
      -2.7,      0.000,      0.000,         0,     -5.9953,      0.3000
      -3.4,      0.000,      0.000,         0,     -6.1619,      0.3083
      -4.3,      0.000,      0.000,         0,     -6.3287,      0.3167
      -4.8,      0.000,      0.000,         0,     -6.4952,      0.3250
      -5.9,      0.000,      0.000,         0,     -6.6619,      0.3333
      -7.1,      0.000,      0.000,         0,     -6.8285,      0.3417
      -9.6,      0.000,      0.000,         0,     -6.9954,      0.3500
     -13.1,      0.000,      0.000,         0,     -7.1620,      0.3583
     -15.3,      0.000,      0.000,         0,     -7.2720,      0.3788
     -15.0,      0.000,      0.000,         0,     -7.2719,      0.3955
     -14.8,      0.000,      0.000,         0,     -7.2719,      0.4121
     -14.7,      0.000,      0.000,         0,     -7.2719,      0.4288
     -14.6,      0.000,      0.000,         0,     -7.2718,      0.4455
     -14.5,      0.000,      0.000,         0,     -7.2716,      0.4621
     -14.5,      0.000,      0.000,         0,     -7.2716,      0.4788
     -14.4,      0.000,      0.000,         0,     -7.2716,      0.4955
     -14.4,      0.000,      0.000,         0,     -7.2716,      0.5121
     -14.3,      0.000,      0.000,         0,     -7.2486,      0.5288
     -14.1,      0.000,      0.000,         0,     -7.2419,      0.5455
     -14.0,      0.000,      0.000,         0,     -7.2400,      0.5621
     -14.0,      0.000,      0.000,         0,     -7.2398,      0.5788
     -13.9,      0.000,      0.000,         0,     -7.2381,      0.5955
     -13.9,      0.000,      0.000,         0,     -7.2378,      0.6121
     -12.0,      0.000,      0.000,         0,     -7.1751,      0.6205
      -9.8,      0.000,      0.000,         0,     -7.0920,      0.6288
      -8.0,      0.000,      0.000,         0,     -7.0087,      0.6371
      -6.4,      0.000,      0.000,         0,     -6.9237,      0.6455
      -5.0,      0.000,      0.000,         0,     -6.8400,      0.6538
      -3.7,      0.000,      0.000,         0,     -6.7566,      0.6621
      -3.2,      0.000,      0.000,         0,     -6.6731,      0.6705
      -2.6,      0.000,      0.000,         0,     -6.5898,      0.6788
      -2.2,      0.000,      0.000,         0,     -6.5066,      0.6871
      -1.9,      0.000,      0.000,         0,     -6.4231,      0.6955
      -1.4,      0.000,      0.000,         0,     -6.3399,      0.7038
      -0.9,      0.000,      0.000,         0,     -6.2565,      0.7121
      -0.5,      0.000,      0.000,         0,     -6.1732,      0.7205
       0.0,      0.000,      0.000,         0,     -6.0900,      0.7288
       0.4,      0.000,      0.000,         0,     -6.0066,      0.7371
       0.8,      0.000,      0.000,         0,     -5.9232,      0.7455
       1.2,      0.000,      0.000,         0,     -5.8398,      0.7538
       1.3,      0.000,      0.000,         0,     -5.7565,      0.7621
       1.4,      0.000,      0.000,         0,     -5.6732,      0.7705
       1.8,      0.000,      0.000,         0,     -5.5899,      0.7788
       2.2,      0.000,      0.000,         0,     -5.5065,      0.7871
       2.6,      0.000,      0.000,         0,     -5.4234,      0.7955
       2.9,      0.000,      0.000,         0,     -5.3399,      0.8038
       3.3,      0.000,      0.000,         0,     -5.2565,      0.8121
       3.6,      0.000,      0.000,         0,     -5.1732,      0.8205
       3.9,      0.000,      0.000,         0,     -5.0900,      0.8288
       4.2,      0.000,      0.000,         0,     -5.0066,      0.8371
       4.5,      0.000,      0.000,         0,     -4.9233,      0.8455
       4.8,      0.000,      0.000,         0,     -4.8399,      0.8538
       5.1,      0.000,      0.000,         0,     -4.7567,      0.8621
       5.3,      0.000,      0.000,         0,     -4.6734,      0.8705
       5.6,      0.000,      0.000,         0,     -4.5899,      0.8788
       5.9,      0.000,      0.000,         0,     -4.5066,      0.8871
       6.1,      0.000,      0.000,         0,     -4.4232,      0.8955
       6.4,      0.000,      0.000,         0,     -4.3400,      0.9038
       6.6,      0.000,      0.000,         0,     -4.2565,      0.9121
       6.8,      0.000,      0.000,         0,     -4.1733,      0.9205
       7.0,      0.000,      0.000,         0,     -4.0900,      0.9288
       7.3,      0.000,      0.000,         0,     -4.0067,      0.9371
       7.5,      0.000,      0.000,         0,     -3.9232,      0.9455
       7.7,      0.000,      0.000,         0,     -3.8399,      0.9538
       7.8,      0.000,      0.000,         0,     -3.7567,      0.9621
       8.0,      0.000,      0.000,         0,     -3.6733,      0.9705
       8.2,      0.000,      0.000,         0,     -3.5900,      0.9788
       8.4,      0.000,      0.000,         0,     -3.5067,      0.9871
       8.6,      0.000,      0.000,         0,     -3.4233,      0.9955
       8.8,      0.000,      0.000,         0,     -3.3399,      1.0038
       9.0,      0.000,      0.000,         0,     -3.2567,      1.0121
       9.2,      0.000,      0.000,         0,     -3.1734,      1.0205
       9.3,      0.000,      0.000,         0,     -3.0900,      1.0288
       9.5,      0.000,      0.000,         0,     -3.0066,      1.0371
       9.7,      0.000,      0.000,         0,     -2.9234,      1.0455
       9.8,      0.000,      0.000,         0,     -2.8399,      1.0538
      10.0,      0.000,      0.000,         0,     -2.7571,      1.0621
      10.1,      0.000,      0.000,         0,     -2.6734,      1.0705
      10.3,      0.000,      0.000,         0,     -2.5900,      1.0788
      10.5,      0.000,      0.000,         0,     -2.5066,      1.0871
      10.6,      0.000,      0.000,         0,     -2.4234,      1.0955
      10.8,      0.000,      0.000,         0,     -2.3401,      1.1038
      11.0,      0.000,      0.000,         0,     -2.2566,      1.1121
      11.1,      0.000,      0.000,         0,     -2.1735,      1.1205
      11.3,      0.000,      0.000,         0,     -2.0900,      1.1288
      11.4,      0.000,      0.000,         0,     -2.0067,      1.1371
      11.6,      0.000,      0.000,         0,     -1.9233,      1.1455
      11.8,      0.000,      0.000,         0,     -1.8401,      1.1538
      11.9,      0.000,      0.000,         0,     -1.7567,      1.1621
      12.1,      0.000,      0.000,         0,     -1.6735,      1.1705
      12.2,      0.000,      0.000,         0,     -1.5900,      1.1788
      12.4,      0.000,      0.000,         0,     -1.5067,      1.1871
      12.5,      0.000,      0.000,         0,     -1.4234,      1.1955
      12.7,      0.000,      0.000,         0,     -1.3400,      1.2038
      12.9,      0.000,      0.000,         0,     -1.2567,      1.2121
      13.0,      0.000,      0.000,         0,     -1.1733,      1.2205
      13.2,      0.000,      0.000,         0,     -1.0901,      1.2288
      13.3,      0.000,      0.000,         0,     -1.0067,      1.2371
      13.5,      0.000,      0.000,         0,     -0.9233,      1.2455
      13.7,      0.000,      0.000,         0,     -0.8400,      1.2538
      13.8,      0.000,      0.000,         0,     -0.7569,      1.2621
      14.0,      0.000,      0.000,         0,     -0.6733,      1.2705
      14.1,      0.000,      0.000,         0,     -0.5901,      1.2788
      14.3,      0.000,      0.000,         0,     -0.5068,      1.2871
      14.5,      0.000,      0.000,         0,     -0.4237,      1.2955
      14.6,      0.000,      0.000,         0,     -0.3400,      1.3038
      14.8,      0.000,      0.000,         0,     -0.2568,      1.3121
      15.0,      0.000,      0.000,         0,     -0.1734,      1.3205
      15.1,      0.000,      0.000,         0,     -0.0901,      1.3288
      15.3,      0.000,      0.000,         0,     -0.0069,      1.3371
      15.4,      0.000,      0.000,         0,      0.0765,      1.3455
      15.6,      0.000,      0.000,         0,      0.1599,      1.3538
      15.7,      0.000,      0.000,         0,      0.2433,      1.3621
      15.9,      0.000,      0.000,         0,      0.3265,      1.3705
      16.0,      0.000,      0.000,         0,      0.4099,      1.3788
      16.2,      0.000,      0.000,         0,      0.4932,      1.3871
      16.3,      0.000,      0.000,         0,      0.5766,      1.3955
      16.5,      0.000,      0.000,         0,      0.6598,      1.4038
      16.6,      0.000,      0.000,         0,      0.7432,      1.4121
      16.8,      0.000,      0.000,         0,      0.8266,      1.4205
      16.9,      0.000,      0.000,         0,      0.9097,      1.4288
      17.1,      0.000,      0.000,         0,      0.9933,      1.4371
      17.2,      0.000,      0.000,         0,      1.0764,      1.4455
      17.4,      0.000,      0.000,         0,      1.1598,      1.4538
      17.6,      0.000,      0.000,         0,      1.2431,      1.4621
      17.7,      0.000,      0.000,         0,      1.3266,      1.4705
      17.8,      0.000,      0.000,         0,      1.4098,      1.4788
      18.0,      0.000,      0.000,         0,      1.4932,      1.4871
      18.1,      0.000,      0.000,         0,      1.5765,      1.4955
      18.3,      0.000,      0.000,         0,      1.6598,      1.5038
      18.4,      0.000,      0.000,         0,      1.7431,      1.5121
      18.5,      0.000,      0.000,         0,      1.8264,      1.5205
      18.7,      0.000,      0.000,         0,      1.9098,      1.5288
      18.8,      0.000,      0.000,         0,      1.9932,      1.5371
      18.9,      0.000,      0.000,         0,      2.0766,      1.5455
      19.0,      0.000,      0.000,         0,      2.1597,      1.5538
      19.1,      0.000,      0.000,         0,      2.2431,      1.5621
      19.3,      0.000,      0.000,         0,      2.3265,      1.5705
      19.4,      0.000,      0.000,         0,      2.4098,      1.5788
      19.5,      0.000,      0.000,         0,      2.4930,      1.5871
      19.6,      0.000,      0.000,         0,      2.5766,      1.5955
      19.7,      0.000,      0.000,         0,      2.6597,      1.6038
      19.8,      0.000,      0.000,         0,      2.7430,      1.6121
      19.8,      0.000,      0.000,         0,      2.8264,      1.6205
      19.9,      0.000,      0.000,         0,      2.9094,      1.6288
      20.0,      0.000,      0.000,         0,      2.9931,      1.6371
      20.1,      0.000,      0.000,         0,      3.0765,      1.6455
      20.1,      0.000,      0.000,         0,      3.1598,      1.6538
      20.2,      0.000,      0.000,         0,      3.2431,      1.6621
      20.3,      0.000,      0.000,         0,      3.3263,      1.6705
      20.3,      0.000,      0.000,         0,      3.4098,      1.6788
      20.4,      0.000,      0.000,         0,      3.4931,      1.6871
      20.4,      0.000,      0.000,         0,      3.5762,      1.6955
      20.5,      0.000,      0.000,         0,      3.6598,      1.7038
      20.6,      0.000,      0.000,         0,      3.7431,      1.7121
      20.6,      0.000,      0.000,         0,      3.8262,      1.7205
      20.6,      0.000,      0.000,         0,      3.9096,      1.7288
      20.7,      0.000,      0.000,         0,      3.9932,      1.7371
      20.7,      0.000,      0.000,         0,      4.0765,      1.7455
      20.7,      0.000,      0.000,         0,      4.1597,      1.7538
      20.8,      0.000,      0.000,         0,      4.2429,      1.7621
      20.8,      0.000,      0.000,         0,      4.3264,      1.7705
      20.8,      0.000,      0.000,         0,      4.4098,      1.7788
      20.8,      0.000,      0.000,         0,      4.4929,      1.7871
       0.0,      0.000,      0.000,         0,      4.5764,      1.7955
       0.0,      0.000,      0.000,         0,      4.6597,      1.8038
       0.0,      0.000,      0.000,         0,      4.7430,      1.8121
       0.0,      0.000,      0.000,         0,      4.8264,      1.8205
       0.0,      0.000,      0.000,         0,      4.9097,      1.8288
       0.0,      0.000,      0.000,         0,      4.9930,      1.8371
       0.0,      0.000,      0.000,         0,      5.0763,      1.8455
       0.0,      0.000,      0.000,         0,      5.1596,      1.8538
       0.0,      0.000,      0.000,         0,      5.2430,      1.8621
       0.0,      0.000,      0.000,         0,      5.3264,      1.8705
       0.0,      0.000,      0.000,         0,      5.4097,      1.8788
       0.0,      0.000,      0.000,         0,      5.4930,      1.8871
       0.0,      0.000,      0.000,         0,      5.5762,      1.8955
       0.0,      0.000,      0.000,         0,      5.6596,      1.9038
       0.0,      0.000,      0.000,         0,      5.7429,      1.9121
       0.0,      0.000,      0.000,         0,      5.8263,      1.9205
       0.0,      0.000,      0.000,         0,      5.9094,      1.9288
       0.0,      0.000,      0.000,         0,      5.9929,      1.9371
       0.0,      0.000,      0.000,         0,      6.0762,      1.9455
       0.0,      0.000,      0.000,         0,      6.1596,      1.9538