File: Alban repo/Quiz 1/suction cup instron tests/oct-dec-2019_raw-data/d30e10-01-inwater-on36grit-diaphragmpump-10mm-test3.raw
Operator: 1

Date,Time,Specimen#
11/09/19,17:30:15,1

---------------------------------------


Area (mm^2):,      1.00,Flat,     25.40,     25.40,     25.40
Gage Len (mm):,     25.40


LOAD (N),STRAIN 1 (mm),STRAIN 2 (mm),STRESS (MPa),POSITION (mm),TIME (min)
      18.5,      0.000,      0.000,         0,     -0.1614,      0.0083
      20.1,      0.000,      0.000,         0,     -0.3279,      0.0167
      20.0,      0.000,      0.000,         0,     -0.4945,      0.0250
      19.6,      0.000,      0.000,         0,     -0.6614,      0.0333
      19.2,      0.000,      0.000,         0,     -0.8279,      0.0417
      18.8,      0.000,      0.000,         0,     -0.9945,      0.0500
      18.3,      0.000,      0.000,         0,     -1.1612,      0.0583
      17.9,      0.000,      0.000,         0,     -1.3278,      0.0667
      17.5,      0.000,      0.000,         0,     -1.4945,      0.0750
      17.1,      0.000,      0.000,         0,     -1.6613,      0.0833
      16.6,      0.000,      0.000,         0,     -1.8278,      0.0917
      16.2,      0.000,      0.000,         0,     -1.9945,      0.1000
      15.8,      0.000,      0.000,         0,     -2.1613,      0.1083
      15.3,      0.000,      0.000,         0,     -2.3278,      0.1167
      14.9,      0.000,      0.000,         0,     -2.4946,      0.1250
      14.5,      0.000,      0.000,         0,     -2.6613,      0.1333
      14.0,      0.000,      0.000,         0,     -2.8277,      0.1417
      13.5,      0.000,      0.000,         0,     -2.9944,      0.1500
      13.1,      0.000,      0.000,         0,     -3.1610,      0.1583
      12.6,      0.000,      0.000,         0,     -3.3277,      0.1667
      12.1,      0.000,      0.000,         0,     -3.4944,      0.1750
      11.6,      0.000,      0.000,         0,     -3.6612,      0.1833
      11.0,      0.000,      0.000,         0,     -3.8279,      0.1917
      10.5,      0.000,      0.000,         0,     -3.9945,      0.2000
       9.9,      0.000,      0.000,         0,     -4.1612,      0.2083
       9.3,      0.000,      0.000,         0,     -4.3278,      0.2167
       8.7,      0.000,      0.000,         0,     -4.4945,      0.2250
       8.0,      0.000,      0.000,         0,     -4.6610,      0.2333
       7.3,      0.000,      0.000,         0,     -4.8278,      0.2417
       6.5,      0.000,      0.000,         0,     -4.9945,      0.2500
       5.7,      0.000,      0.000,         0,     -5.1611,      0.2583
       4.9,      0.000,      0.000,         0,     -5.3278,      0.2667
       4.0,      0.000,      0.000,         0,     -5.4942,      0.2750
       2.9,      0.000,      0.000,         0,     -5.6609,      0.2833
       1.8,      0.000,      0.000,         0,     -5.8277,      0.2917
       0.6,      0.000,      0.000,         0,     -5.9942,      0.3000
      -0.9,      0.000,      0.000,         0,     -6.1611,      0.3083
      -2.6,      0.000,      0.000,         0,     -6.3277,      0.3167
      -4.6,      0.000,      0.000,         0,     -6.4944,      0.3250
      -7.0,      0.000,      0.000,         0,     -6.6610,      0.3333
      -9.8,      0.000,      0.000,         0,     -6.8277,      0.3417
     -12.8,      0.000,      0.000,         0,     -6.9943,      0.3500
     -14.3,      0.000,      0.000,         0,     -7.1587,      0.3730
     -13.5,      0.000,      0.000,         0,     -7.1585,      0.3896
     -13.1,      0.000,      0.000,         0,     -7.1585,      0.4063
     -12.7,      0.000,      0.000,         0,     -7.1585,      0.4230
     -12.4,      0.000,      0.000,         0,     -7.1585,      0.4396
     -12.2,      0.000,      0.000,         0,     -7.1583,      0.4563
     -12.0,      0.000,      0.000,         0,     -7.1583,      0.4730
     -11.9,      0.000,      0.000,         0,     -7.1581,      0.4896
     -11.7,      0.000,      0.000,         0,     -7.1579,      0.5063
     -11.5,      0.000,      0.000,         0,     -7.1296,      0.5230
     -11.2,      0.000,      0.000,         0,     -7.1211,      0.5396
     -11.1,      0.000,      0.000,         0,     -7.1207,      0.5563
     -11.0,      0.000,      0.000,         0,     -7.1189,      0.5730
     -10.9,      0.000,      0.000,         0,     -7.1189,      0.5896
     -10.9,      0.000,      0.000,         0,     -7.1189,      0.6063
      -9.2,      0.000,      0.000,         0,     -7.0565,      0.6146
      -7.2,      0.000,      0.000,         0,     -6.9730,      0.6230
      -5.4,      0.000,      0.000,         0,     -6.8899,      0.6313
      -3.8,      0.000,      0.000,         0,     -6.8056,      0.6396
      -2.5,      0.000,      0.000,         0,     -6.7209,      0.6480
      -1.3,      0.000,      0.000,         0,     -6.6376,      0.6563
      -0.3,      0.000,      0.000,         0,     -6.5543,      0.6646
       0.6,      0.000,      0.000,         0,     -6.4709,      0.6730
       1.5,      0.000,      0.000,         0,     -6.3876,      0.6813
       2.3,      0.000,      0.000,         0,     -6.3045,      0.6896
       3.0,      0.000,      0.000,         0,     -6.2209,      0.6980
       3.7,      0.000,      0.000,         0,     -6.1376,      0.7063
       4.4,      0.000,      0.000,         0,     -6.0543,      0.7146
       5.0,      0.000,      0.000,         0,     -5.9710,      0.7230
       5.6,      0.000,      0.000,         0,     -5.8878,      0.7313
       6.1,      0.000,      0.000,         0,     -5.8045,      0.7396
       6.7,      0.000,      0.000,         0,     -5.7210,      0.7480
       7.2,      0.000,      0.000,         0,     -5.6376,      0.7563
       7.7,      0.000,      0.000,         0,     -5.5543,      0.7646
       8.2,      0.000,      0.000,         0,     -5.4710,      0.7730
       8.7,      0.000,      0.000,         0,     -5.3878,      0.7813
       9.1,      0.000,      0.000,         0,     -5.3045,      0.7896
       9.6,      0.000,      0.000,         0,     -5.2212,      0.7980
      10.0,      0.000,      0.000,         0,     -5.1377,      0.8063
      10.4,      0.000,      0.000,         0,     -5.0543,      0.8146
      10.8,      0.000,      0.000,         0,     -4.9710,      0.8230
      11.2,      0.000,      0.000,         0,     -4.8879,      0.8313
      11.6,      0.000,      0.000,         0,     -4.8046,      0.8396
      11.9,      0.000,      0.000,         0,     -4.7212,      0.8480
      12.3,      0.000,      0.000,         0,     -4.6377,      0.8563
      12.6,      0.000,      0.000,         0,     -4.5544,      0.8646
      13.0,      0.000,      0.000,         0,     -4.4710,      0.8730
      13.3,      0.000,      0.000,         0,     -4.3875,      0.8813
      13.7,      0.000,      0.000,         0,     -4.3044,      0.8896
      14.0,      0.000,      0.000,         0,     -4.2213,      0.8980
      14.3,      0.000,      0.000,         0,     -4.1377,      0.9063
      14.6,      0.000,      0.000,         0,     -4.0544,      0.9146
      14.9,      0.000,      0.000,         0,     -3.9711,      0.9230
      15.2,      0.000,      0.000,         0,     -3.8879,      0.9313
      15.5,      0.000,      0.000,         0,     -3.8042,      0.9396
      15.7,      0.000,      0.000,         0,     -3.7211,      0.9480
      16.0,      0.000,      0.000,         0,     -3.6380,      0.9563
      16.3,      0.000,      0.000,         0,     -3.5546,      0.9646
      16.5,      0.000,      0.000,         0,     -3.4709,      0.9730
      16.7,      0.000,      0.000,         0,     -3.3878,      0.9813
      17.0,      0.000,      0.000,         0,     -3.3044,      0.9896
      17.2,      0.000,      0.000,         0,     -3.2211,      0.9980
      17.5,      0.000,      0.000,         0,     -3.1378,      1.0063
      17.7,      0.000,      0.000,         0,     -3.0547,      1.0146
      17.9,      0.000,      0.000,         0,     -2.9711,      1.0230
      18.2,      0.000,      0.000,         0,     -2.8878,      1.0313
      18.4,      0.000,      0.000,         0,     -2.8045,      1.0396
      18.6,      0.000,      0.000,         0,     -2.7212,      1.0480
      18.8,      0.000,      0.000,         0,     -2.6378,      1.0563
      19.0,      0.000,      0.000,         0,     -2.5547,      1.0646
      19.2,      0.000,      0.000,         0,     -2.4714,      1.0730
      19.4,      0.000,      0.000,         0,     -2.3876,      1.0813
      19.7,      0.000,      0.000,         0,     -2.3045,      1.0896
      19.9,      0.000,      0.000,         0,     -2.2212,      1.0980
      20.1,      0.000,      0.000,         0,     -2.1379,      1.1063
      20.3,      0.000,      0.000,         0,     -2.0543,      1.1146
      20.5,      0.000,      0.000,         0,     -1.9714,      1.1230
      20.7,      0.000,      0.000,         0,     -1.8879,      1.1313
      20.9,      0.000,      0.000,         0,     -1.8045,      1.1396
      21.0,      0.000,      0.000,         0,     -1.7212,      1.1480
      21.2,      0.000,      0.000,         0,     -1.6381,      1.1563
      21.4,      0.000,      0.000,         0,     -1.5546,      1.1646
      21.6,      0.000,      0.000,         0,     -1.4712,      1.1730
      21.8,      0.000,      0.000,         0,     -1.3879,      1.1813
      22.0,      0.000,      0.000,         0,     -1.3046,      1.1896
      22.2,      0.000,      0.000,         0,     -1.2212,      1.1980
      22.4,      0.000,      0.000,         0,     -1.1377,      1.2063
      22.6,      0.000,      0.000,         0,     -1.0546,      1.2146
      22.8,      0.000,      0.000,         0,     -0.9713,      1.2230
      23.0,      0.000,      0.000,         0,     -0.8879,      1.2313
      23.2,      0.000,      0.000,         0,     -0.8044,      1.2396
      23.3,      0.000,      0.000,         0,     -0.7213,      1.2480
      23.5,      0.000,      0.000,         0,     -0.6381,      1.2563
      23.7,      0.000,      0.000,         0,     -0.5546,      1.2646
      23.9,      0.000,      0.000,         0,     -0.4711,      1.2730
      24.1,      0.000,      0.000,         0,     -0.3880,      1.2813
      24.3,      0.000,      0.000,         0,     -0.3046,      1.2896
      24.5,      0.000,      0.000,         0,     -0.2215,      1.2980
      24.7,      0.000,      0.000,         0,     -0.1380,      1.3063
      24.9,      0.000,      0.000,         0,     -0.0546,      1.3146
      25.1,      0.000,      0.000,         0,      0.0287,      1.3230
      25.3,      0.000,      0.000,         0,      0.1120,      1.3313
      25.5,      0.000,      0.000,         0,      0.1953,      1.3396
      25.7,      0.000,      0.000,         0,      0.2787,      1.3480
      25.9,      0.000,      0.000,         0,      0.3620,      1.3563
      26.1,      0.000,      0.000,         0,      0.4453,      1.3646
      26.3,      0.000,      0.000,         0,      0.5286,      1.3730
      26.5,      0.000,      0.000,         0,      0.6120,      1.3813
      26.7,      0.000,      0.000,         0,      0.6951,      1.3896
      26.9,      0.000,      0.000,         0,      0.7786,      1.3980
      27.2,      0.000,      0.000,         0,      0.8622,      1.4063
      27.4,      0.000,      0.000,         0,      0.9453,      1.4146
      27.6,      0.000,      0.000,         0,      1.0286,      1.4230
      27.8,      0.000,      0.000,         0,      1.1119,      1.4313
      28.1,      0.000,      0.000,         0,      1.1953,      1.4396
      28.3,      0.000,      0.000,         0,      1.2786,      1.4480
      28.5,      0.000,      0.000,         0,      1.3619,      1.4563
      28.7,      0.000,      0.000,         0,      1.4453,      1.4646
      28.9,      0.000,      0.000,         0,      1.5288,      1.4730
      29.1,      0.000,      0.000,         0,      1.6119,      1.4813
      29.3,      0.000,      0.000,         0,      1.6952,      1.4896
      29.5,      0.000,      0.000,         0,      1.7786,      1.4980
      29.7,      0.000,      0.000,         0,      1.8619,      1.5063
      30.0,      0.000,      0.000,         0,      1.9452,      1.5146
      30.2,      0.000,      0.000,         0,      2.0286,      1.5230
      30.4,      0.000,      0.000,         0,      2.1119,      1.5313
      30.6,      0.000,      0.000,         0,      2.1952,      1.5396
      30.8,      0.000,      0.000,         0,      2.2787,      1.5480
      31.0,      0.000,      0.000,         0,      2.3619,      1.5563
      31.3,      0.000,      0.000,         0,      2.4454,      1.5646
      31.5,      0.000,      0.000,         0,      2.5285,      1.5730
      31.8,      0.000,      0.000,         0,      2.6119,      1.5813
      32.0,      0.000,      0.000,         0,      2.6952,      1.5896
      32.3,      0.000,      0.000,         0,      2.7787,      1.5980
      32.5,      0.000,      0.000,         0,      2.8618,      1.6063
      32.8,      0.000,      0.000,         0,      2.9454,      1.6146
      33.0,      0.000,      0.000,         0,      3.0283,      1.6230
      33.2,      0.000,      0.000,         0,      3.1118,      1.6313
      33.5,      0.000,      0.000,         0,      3.1953,      1.6396
      33.7,      0.000,      0.000,         0,      3.2787,      1.6480
      33.9,      0.000,      0.000,         0,      3.3618,      1.6563
      34.2,      0.000,      0.000,         0,      3.4453,      1.6646
      34.4,      0.000,      0.000,         0,      3.5287,      1.6730
      34.6,      0.000,      0.000,         0,      3.6120,      1.6813
      34.8,      0.000,      0.000,         0,      3.6951,      1.6896
      34.9,      0.000,      0.000,         0,      3.7785,      1.6980
      35.1,      0.000,      0.000,         0,      3.8620,      1.7063
      35.3,      0.000,      0.000,         0,      3.9397,      1.7146
      35.5,      0.000,      0.000,         0,      4.0282,      1.7230
      35.7,      0.000,      0.000,         0,      4.1120,      1.7313
      36.0,      0.000,      0.000,         0,      4.1953,      1.7396
      36.2,      0.000,      0.000,         0,      4.2784,      1.7480
      36.4,      0.000,      0.000,         0,      4.3617,      1.7563
      36.7,      0.000,      0.000,         0,      4.4453,      1.7646
      36.9,      0.000,      0.000,         0,      4.5286,      1.7730
      37.1,      0.000,      0.000,         0,      4.6119,      1.7813
      37.3,      0.000,      0.000,         0,      4.6953,      1.7896
      37.5,      0.000,      0.000,         0,      4.7786,      1.7980
      37.8,      0.000,      0.000,         0,      4.8619,      1.8063
      38.0,      0.000,      0.000,         0,      4.9450,      1.8146
      38.2,      0.000,      0.000,         0,      5.0286,      1.8230
      38.4,      0.000,      0.000,         0,      5.1119,      1.8313
      38.6,      0.000,      0.000,         0,      5.1952,      1.8396
      38.8,      0.000,      0.000,         0,      5.2786,      1.8480
      39.1,      0.000,      0.000,         0,      5.3617,      1.8563
      39.3,      0.000,      0.000,         0,      5.4450,      1.8646
      39.5,      0.000,      0.000,         0,      5.5287,      1.8730
      39.7,      0.000,      0.000,         0,      5.6119,      1.8813
      39.9,      0.000,      0.000,         0,      5.6950,      1.8896
      40.1,      0.000,      0.000,         0,      5.7783,      1.8980
      40.3,      0.000,      0.000,         0,      5.8619,      1.9063
      40.5,      0.000,      0.000,         0,      5.9450,      1.9146
      40.7,      0.000,      0.000,         0,      6.0285,      1.9230
      40.9,      0.000,      0.000,         0,      6.1118,      1.9313
      41.1,      0.000,      0.000,         0,      6.1952,      1.9396
      41.3,      0.000,      0.000,         0,      6.2783,      1.9480
      41.5,      0.000,      0.000,         0,      6.3618,      1.9563
      41.7,      0.000,      0.000,         0,      6.4451,      1.9646
      41.9,      0.000,      0.000,         0,      6.5285,      1.9730
      42.1,      0.000,      0.000,         0,      6.6118,      1.9813
      42.3,      0.000,      0.000,         0,      6.6949,      1.9896
      42.5,      0.000,      0.000,         0,      6.7785,      1.9980
      42.7,      0.000,      0.000,         0,      6.8618,      2.0063
      42.9,      0.000,      0.000,         0,      6.9451,      2.0146
      43.0,      0.000,      0.000,         0,      7.0284,      2.0230
      43.2,      0.000,      0.000,         0,      7.1118,      2.0313
      43.4,      0.000,      0.000,         0,      7.1949,      2.0396
      43.5,      0.000,      0.000,         0,      7.2784,      2.0480
      43.7,      0.000,      0.000,         0,      7.3616,      2.0563
      43.8,      0.000,      0.000,         0,      7.4453,      2.0646
      44.0,      0.000,      0.000,         0,      7.5282,      2.0730
      44.1,      0.000,      0.000,         0,      7.6117,      2.0813
      44.2,      0.000,      0.000,         0,      7.6949,      2.0896
      44.4,      0.000,      0.000,         0,      7.7784,      2.0980
      44.5,      0.000,      0.000,         0,      7.8617,      2.1063
      44.3,      0.000,      0.000,         0,      7.9451,      2.1146
      44.4,      0.000,      0.000,         0,      8.0284,      2.1230
      44.4,      0.000,      0.000,         0,      8.1117,      2.1313
      44.2,      0.000,      0.000,         0,      8.1950,      2.1396
      41.8,      0.000,      0.000,         0,      8.2782,      2.1480
       0.1,      0.000,      0.000,         0,      8.3617,      2.1563
       0.1,      0.000,      0.000,         0,      8.4450,      2.1646
       0.1,      0.000,      0.000,         0,      8.5284,      2.1730
       0.1,      0.000,      0.000,         0,      8.6117,      2.1813
       0.1,      0.000,      0.000,         0,      8.6948,      2.1896
       0.1,      0.000,      0.000,         0,      8.7783,      2.1980
       0.1,      0.000,      0.000,         0,      8.8617,      2.2063
       0.1,      0.000,      0.000,         0,      8.9448,      2.2146
       0.1,      0.000,      0.000,         0,      9.0283,      2.2230
       0.1,      0.000,      0.000,         0,      9.1118,      2.2313