File: Alban repo/Quiz 1/suction cup instron tests/oct-dec-2019_raw-data/d30e10-01-inwater-on36grit-nopump-10mm-test3.raw
Operator: 1

Date,Time,Specimen#
11/09/19,17:11:51,1

---------------------------------------


Area (mm^2):,      1.00,Flat,     25.40,     25.40,     25.40
Gage Len (mm):,     25.40


LOAD (N),STRAIN 1 (mm),STRAIN 2 (mm),STRESS (MPa),POSITION (mm),TIME (min)
       2.4,      0.000,      0.000,         0,      0.0810,      0.0083
       2.7,      0.000,      0.000,         0,      0.1643,      0.0167
       3.1,      0.000,      0.000,         0,      0.2477,      0.0250
       3.5,      0.000,      0.000,         0,      0.3310,      0.0333
       3.8,      0.000,      0.000,         0,      0.4143,      0.0417
       4.2,      0.000,      0.000,         0,      0.4976,      0.0500
       4.5,      0.000,      0.000,         0,      0.5810,      0.0583
       4.9,      0.000,      0.000,         0,      0.6643,      0.0667
       5.2,      0.000,      0.000,         0,      0.7478,      0.0750
       5.6,      0.000,      0.000,         0,      0.8310,      0.0833
       5.9,      0.000,      0.000,         0,      0.9143,      0.0917
       6.3,      0.000,      0.000,         0,      0.9974,      0.1000
       6.6,      0.000,      0.000,         0,      1.0809,      0.1083
       6.9,      0.000,      0.000,         0,      1.1643,      0.1167
       7.2,      0.000,      0.000,         0,      1.2478,      0.1250
       7.6,      0.000,      0.000,         0,      1.3311,      0.1333
       7.9,      0.000,      0.000,         0,      1.4143,      0.1417
       8.2,      0.000,      0.000,         0,      1.4976,      0.1500
       8.5,      0.000,      0.000,         0,      1.5811,      0.1583
       8.8,      0.000,      0.000,         0,      1.6642,      0.1667
       9.1,      0.000,      0.000,         0,      1.7474,      0.1750
       9.4,      0.000,      0.000,         0,      1.8311,      0.1833
       9.7,      0.000,      0.000,         0,      1.9144,      0.1917
      10.0,      0.000,      0.000,         0,      1.9976,      0.2000
      10.3,      0.000,      0.000,         0,      2.0811,      0.2083
      10.5,      0.000,      0.000,         0,      2.1644,      0.2167
      10.8,      0.000,      0.000,         0,      2.2477,      0.2250
      11.1,      0.000,      0.000,         0,      2.3309,      0.2333
      11.4,      0.000,      0.000,         0,      2.4144,      0.2417
      11.6,      0.000,      0.000,         0,      2.4977,      0.2500
      11.9,      0.000,      0.000,         0,      2.5810,      0.2583
      12.1,      0.000,      0.000,         0,      2.6642,      0.2667
      12.4,      0.000,      0.000,         0,      2.7475,      0.2750
      12.6,      0.000,      0.000,         0,      2.8308,      0.2833
      12.8,      0.000,      0.000,         0,      2.9142,      0.2917
      13.1,      0.000,      0.000,         0,      2.9975,      0.3000
      13.3,      0.000,      0.000,         0,      3.0808,      0.3083
      13.6,      0.000,      0.000,         0,      3.1641,      0.3167
      13.8,      0.000,      0.000,         0,      3.2475,      0.3250
      14.0,      0.000,      0.000,         0,      3.3310,      0.3333
      14.3,      0.000,      0.000,         0,      3.4141,      0.3417
      14.5,      0.000,      0.000,         0,      3.4977,      0.3500
      14.7,      0.000,      0.000,         0,      3.5808,      0.3583
      14.9,      0.000,      0.000,         0,      3.6641,      0.3667
      15.2,      0.000,      0.000,         0,      3.7474,      0.3750
      15.4,      0.000,      0.000,         0,      3.8308,      0.3833
      15.6,      0.000,      0.000,         0,      3.9143,      0.3917
      15.8,      0.000,      0.000,         0,      3.9976,      0.4000
      16.0,      0.000,      0.000,         0,      4.0808,      0.4083
      16.3,      0.000,      0.000,         0,      4.1641,      0.4167
      16.5,      0.000,      0.000,         0,      4.2476,      0.4250
      16.7,      0.000,      0.000,         0,      4.3307,      0.4333
      16.9,      0.000,      0.000,         0,      4.4141,      0.4417
      17.1,      0.000,      0.000,         0,      4.4974,      0.4500
      17.3,      0.000,      0.000,         0,      4.5809,      0.4583
      17.5,      0.000,      0.000,         0,      4.6641,      0.4667
      17.7,      0.000,      0.000,         0,      4.7474,      0.4750
      17.9,      0.000,      0.000,         0,      4.8309,      0.4833
      18.1,      0.000,      0.000,         0,      4.9140,      0.4917
      18.3,      0.000,      0.000,         0,      4.9974,      0.5000
      18.5,      0.000,      0.000,         0,      5.0809,      0.5083
      18.7,      0.000,      0.000,         0,      5.1640,      0.5167
      18.9,      0.000,      0.000,         0,      5.2475,      0.5250
      19.1,      0.000,      0.000,         0,      5.3307,      0.5333
      19.3,      0.000,      0.000,         0,      5.4142,      0.5417
      19.5,      0.000,      0.000,         0,      5.4975,      0.5500
      19.7,      0.000,      0.000,         0,      5.5807,      0.5583
      19.9,      0.000,      0.000,         0,      5.6640,      0.5667
      20.1,      0.000,      0.000,         0,      5.7473,      0.5750
      20.2,      0.000,      0.000,         0,      5.8308,      0.5833
      20.4,      0.000,      0.000,         0,      5.9142,      0.5917
      20.6,      0.000,      0.000,         0,      5.9973,      0.6000
      20.8,      0.000,      0.000,         0,      6.0806,      0.6083
      21.0,      0.000,      0.000,         0,      6.1642,      0.6167
      21.2,      0.000,      0.000,         0,      6.2475,      0.6250
      21.4,      0.000,      0.000,         0,      6.3308,      0.6333
      21.6,      0.000,      0.000,         0,      6.4139,      0.6417
      21.8,      0.000,      0.000,         0,      6.4975,      0.6500
      22.0,      0.000,      0.000,         0,      6.5808,      0.6583
      22.2,      0.000,      0.000,         0,      6.6641,      0.6667
      22.4,      0.000,      0.000,         0,      6.7475,      0.6750
      22.6,      0.000,      0.000,         0,      6.8308,      0.6833
      22.7,      0.000,      0.000,         0,      6.9141,      0.6917
      22.9,      0.000,      0.000,         0,      6.9974,      0.7000
      23.1,      0.000,      0.000,         0,      7.0808,      0.7083
      23.3,      0.000,      0.000,         0,      7.1641,      0.7167
      23.5,      0.000,      0.000,         0,      7.2474,      0.7250
      23.7,      0.000,      0.000,         0,      7.3308,      0.7333
      23.9,      0.000,      0.000,         0,      7.4141,      0.7417
      24.0,      0.000,      0.000,         0,      7.4974,      0.7500
      24.2,      0.000,      0.000,         0,      7.5807,      0.7583
      24.4,      0.000,      0.000,         0,      7.6641,      0.7667
      24.6,      0.000,      0.000,         0,      7.7472,      0.7750
      24.8,      0.000,      0.000,         0,      7.8307,      0.7833
      25.0,      0.000,      0.000,         0,      7.9139,      0.7917
      25.1,      0.000,      0.000,         0,      7.9974,      0.8000
      25.3,      0.000,      0.000,         0,      8.0805,      0.8083
      25.5,      0.000,      0.000,         0,      8.1640,      0.8167
      25.7,      0.000,      0.000,         0,      8.2472,      0.8250
      25.9,      0.000,      0.000,         0,      8.3307,      0.8333
      26.0,      0.000,      0.000,         0,      8.4140,      0.8417
      26.2,      0.000,      0.000,         0,      8.4973,      0.8500
      26.4,      0.000,      0.000,         0,      8.5807,      0.8583
      26.5,      0.000,      0.000,         0,      8.6640,      0.8667
      26.7,      0.000,      0.000,         0,      8.7473,      0.8750
      26.8,      0.000,      0.000,         0,      8.8305,      0.8833
      27.0,      0.000,      0.000,         0,      8.9140,      0.8917
      27.1,      0.000,      0.000,         0,      8.9973,      0.9000
      27.3,      0.000,      0.000,         0,      9.0806,      0.9083
      27.4,      0.000,      0.000,         0,      9.1640,      0.9167
      27.6,      0.000,      0.000,         0,      9.2475,      0.9250
      27.7,      0.000,      0.000,         0,      9.3304,      0.9333
      27.9,      0.000,      0.000,         0,      9.4140,      0.9417
      28.1,      0.000,      0.000,         0,      9.4973,      0.9500
      28.2,      0.000,      0.000,         0,      9.5806,      0.9583
      28.3,      0.000,      0.000,         0,      9.6639,      0.9667
      28.5,      0.000,      0.000,         0,      9.7473,      0.9750
      28.6,      0.000,      0.000,         0,      9.8306,      0.9833
      28.8,      0.000,      0.000,         0,      9.9139,      0.9917
      28.9,      0.000,      0.000,         0,      9.9971,      1.0000
      29.1,      0.000,      0.000,         0,     10.0806,      1.0083
      29.2,      0.000,      0.000,         0,     10.1639,      1.0167
      29.3,      0.000,      0.000,         0,     10.2470,      1.0250
      29.4,      0.000,      0.000,         0,     10.3306,      1.0333
      29.5,      0.000,      0.000,         0,     10.4139,      1.0417
      29.6,      0.000,      0.000,         0,     10.4972,      1.0500
      29.7,      0.000,      0.000,         0,     10.5806,      1.0583
      29.8,      0.000,      0.000,         0,     10.6641,      1.0667
      29.8,      0.000,      0.000,         0,     10.7470,      1.0750
      29.9,      0.000,      0.000,         0,     10.8307,      1.0833
      29.9,      0.000,      0.000,         0,     10.9139,      1.0917
      29.9,      0.000,      0.000,         0,     10.9972,      1.1000
      29.4,      0.000,      0.000,         0,     11.0805,      1.1083
      28.3,      0.000,      0.000,         0,     11.1639,      1.1167
       7.1,      0.000,      0.000,         0,     11.2472,      1.1250
       0.0,      0.000,      0.000,         0,     11.3303,      1.1333
       0.0,      0.000,      0.000,         0,     11.4140,      1.1417
       0.0,      0.000,      0.000,         0,     11.4972,      1.1500
       0.0,      0.000,      0.000,         0,     11.5805,      1.1583
       0.0,      0.000,      0.000,         0,     11.6636,      1.1667
       0.0,      0.000,      0.000,         0,     11.7473,      1.1750
       0.0,      0.000,      0.000,         0,     11.8305,      1.1833
       0.0,      0.000,      0.000,         0,     11.9138,      1.1917
       0.0,      0.000,      0.000,         0,     11.9971,      1.2000
       0.0,      0.000,      0.000,         0,     12.0504,      1.2071
       0.0,      0.000,      0.000,         0,     12.0531,      1.2105
       0.0,      0.000,      0.000,         0,     12.0533,      1.2138
       0.0,      0.000,      0.000,         0,     12.0531,      1.2171
       0.0,      0.000,      0.000,         0,     12.0531,      1.2205
       0.0,      0.000,      0.000,         0,     12.0531,      1.2238
       0.0,      0.000,      0.000,         0,     12.0531,      1.2271
       0.0,      0.000,      0.000,         0,     12.0531,      1.2305
       0.0,      0.000,      0.000,         0,     12.0531,      1.2338
       0.0,      0.000,      0.000,         0,     12.0531,      1.2372
       0.0,      0.000,      0.000,         0,     12.0531,      1.2405
       0.0,      0.000,      0.000,         0,     12.0531,      1.2438
       0.0,      0.000,      0.000,         0,     12.0531,      1.2472
       0.0,      0.000,      0.000,         0,     12.0531,      1.2505
       0.0,      0.000,      0.000,         0,     12.0531,      1.2538
       0.0,      0.000,      0.000,         0,     12.0531,      1.2572
       0.0,      0.000,      0.000,         0,     12.0531,      1.2605
       0.0,      0.000,      0.000,         0,     12.0531,      1.2639
       0.0,      0.000,      0.000,         0,     12.0531,      1.2672
       0.0,      0.000,      0.000,         0,     12.0531,      1.2705
       0.0,      0.000,      0.000,         0,     12.0531,      1.2739
       0.0,      0.000,      0.000,         0,     12.0531,      1.2772
       0.0,      0.000,      0.000,         0,     12.0531,      1.2805
       0.0,      0.000,      0.000,         0,     12.0531,      1.2839
       0.0,      0.000,      0.000,         0,     12.0531,      1.2872
       0.0,      0.000,      0.000,         0,     12.0531,      1.2905
       0.0,      0.000,      0.000,         0,     12.0531,      1.2939
       0.0,      0.000,      0.000,         0,     12.0531,      1.2972
       0.0,      0.000,      0.000,         0,     12.0531,      1.3006
       0.0,      0.000,      0.000,         0,     12.0531,      1.3039
       0.0,      0.000,      0.000,         0,     12.0531,      1.3072
       0.0,      0.000,      0.000,         0,     12.0531,      1.3106
       0.0,      0.000,      0.000,         0,     12.0531,      1.3139
       0.0,      0.000,      0.000,         0,     12.0531,      1.3172
       0.0,      0.000,      0.000,         0,     12.0531,      1.3206
       0.0,      0.000,      0.000,         0,     12.0531,      1.3239
       0.0,      0.000,      0.000,         0,     12.0531,      1.3272
       0.0,      0.000,      0.000,         0,     12.0531,      1.3306
       0.0,      0.000,      0.000,         0,     12.0531,      1.3339
       0.0,      0.000,      0.000,         0,     12.0531,      1.3373
       0.0,      0.000,      0.000,         0,     12.0531,      1.3406
       0.0,      0.000,      0.000,         0,     12.0531,      1.3439
       0.0,      0.000,      0.000,         0,     12.0531,      1.3473
       0.0,      0.000,      0.000,         0,     12.0531,      1.3506
       0.0,      0.000,      0.000,         0,     12.0531,      1.3539
       0.0,      0.000,      0.000,         0,     12.0531,      1.3573
       0.0,      0.000,      0.000,         0,     12.0531,      1.3606
       0.0,      0.000,      0.000,         0,     12.0531,      1.3639
       0.0,      0.000,      0.000,         0,     12.0491,      1.3673
       0.0,      0.000,      0.000,         0,     12.0417,      1.3706
       0.0,      0.000,      0.000,         0,     12.0404,      1.3740
       0.0,      0.000,      0.000,         0,     12.0394,      1.3773
       0.0,      0.000,      0.000,         0,     12.0384,      1.3806
       0.0,      0.000,      0.000,         0,     12.0373,      1.3840
       0.0,      0.000,      0.000,         0,     12.0371,      1.3873
       0.0,      0.000,      0.000,         0,     12.0361,      1.3906
       0.0,      0.000,      0.000,         0,     12.0351,      1.3940
       0.0,      0.000,      0.000,         0,     12.0351,      1.3973
       0.0,      0.000,      0.000,         0,     12.0351,      1.4007
       0.0,      0.000,      0.000,         0,     12.0351,      1.4040
       0.0,      0.000,      0.000,         0,     12.0351,      1.4073
       0.0,      0.000,      0.000,         0,     12.0351,      1.4107
       0.0,      0.000,      0.000,         0,     12.0351,      1.4140
       0.0,      0.000,      0.000,         0,     12.0351,      1.4173
       0.0,      0.000,      0.000,         0,     12.0351,      1.4207
       0.0,      0.000,      0.000,         0,     12.0351,      1.4240
       0.0,      0.000,      0.000,         0,     12.0351,      1.4273
       0.0,      0.000,      0.000,         0,     12.0351,      1.4307
       0.0,      0.000,      0.000,         0,     12.0351,      1.4340
       0.0,      0.000,      0.000,         0,     12.0351,      1.4374
       0.0,      0.000,      0.000,         0,     12.0351,      1.4407
       0.0,      0.000,      0.000,         0,     12.0351,      1.4440
       0.0,      0.000,      0.000,         0,     12.0351,      1.4474
       0.0,      0.000,      0.000,         0,     12.0351,      1.4507
       0.0,      0.000,      0.000,         0,     12.0351,      1.4540
       0.0,      0.000,      0.000,         0,     12.0351,      1.4574
       0.0,      0.000,      0.000,         0,     12.0351,      1.4607
       0.0,      0.000,      0.000,         0,     12.0351,      1.4640
       0.0,      0.000,      0.000,         0,     12.0351,      1.4674
       0.0,      0.000,      0.000,         0,     12.0351,      1.4707
       0.0,      0.000,      0.000,         0,     12.0351,      1.4741
       0.0,      0.000,      0.000,         0,     12.0351,      1.4774
       0.0,      0.000,      0.000,         0,     12.0351,      1.4807
       0.0,      0.000,      0.000,         0,     12.0351,      1.4841
       0.0,      0.000,      0.000,         0,     12.0351,      1.4874
       0.0,      0.000,      0.000,         0,     12.0351,      1.4907
       0.0,      0.000,      0.000,         0,     12.0351,      1.4941
       0.0,      0.000,      0.000,         0,     12.0351,      1.4974
       0.0,      0.000,      0.000,         0,     12.0351,      1.5007
       0.0,      0.000,      0.000,         0,     12.0351,      1.5041
       0.0,      0.000,      0.000,         0,     12.0351,      1.5074
       0.0,      0.000,      0.000,         0,     12.0351,      1.5108
       0.0,      0.000,      0.000,         0,     12.0351,      1.5141
       0.0,      0.000,      0.000,         0,     12.0351,      1.5174
       0.0,      0.000,      0.000,         0,     12.0351,      1.5208
       0.0,      0.000,      0.000,         0,     12.0351,      1.5241
       0.0,      0.000,      0.000,         0,     12.0351,      1.5274
       0.0,      0.000,      0.000,         0,     12.0351,      1.5308
       0.0,      0.000,      0.000,         0,     12.0351,      1.5341
       0.0,      0.000,      0.000,         0,     12.0351,      1.5375
       0.0,      0.000,      0.000,         0,     12.0351,      1.5408
       0.0,      0.000,      0.000,         0,     12.0351,      1.5441
       0.0,      0.000,      0.000,         0,     12.0351,      1.5475
       0.0,      0.000,      0.000,         0,     12.0351,      1.5508
       0.0,      0.000,      0.000,         0,     12.0351,      1.5541
       0.0,      0.000,      0.000,         0,     12.0351,      1.5575
       0.0,      0.000,      0.000,         0,     12.0351,      1.5608
       0.0,      0.000,      0.000,         0,     12.0351,      1.5641
       0.0,      0.000,      0.000,         0,     12.0351,      1.5675
       0.0,      0.000,      0.000,         0,     12.0351,      1.5708
       0.0,      0.000,      0.000,         0,     12.0351,      1.5742
       0.0,      0.000,      0.000,         0,     12.0351,      1.5775
       0.0,      0.000,      0.000,         0,     12.0351,      1.5808
       0.0,      0.000,      0.000,         0,     12.0351,      1.5842
       0.0,      0.000,      0.000,         0,     12.0351,      1.5875
       0.0,      0.000,      0.000,         0,     12.0351,      1.5908
       0.0,      0.000,      0.000,         0,     12.0351,      1.5942
       0.0,      0.000,      0.000,         0,     12.0351,      1.5975
       0.0,      0.000,      0.000,         0,     12.0351,      1.6008
       0.0,      0.000,      0.000,         0,     12.0351,      1.6042
       0.0,      0.000,      0.000,         0,     12.0351,      1.6075
       0.0,      0.000,      0.000,         0,     12.0351,      1.6109
       0.0,      0.000,      0.000,         0,     12.0351,      1.6142
       0.0,      0.000,      0.000,         0,     12.0351,      1.6175
       0.0,      0.000,      0.000,         0,     12.0351,      1.6209
       0.0,      0.000,      0.000,         0,     12.0351,      1.6242
       0.0,      0.000,      0.000,         0,     12.0351,      1.6275
       0.0,      0.000,      0.000,         0,     12.0351,      1.6309
       0.0,      0.000,      0.000,         0,     12.0351,      1.6342
       0.0,      0.000,      0.000,         0,     12.0351,      1.6375
       0.0,      0.000,      0.000,         0,     12.0351,      1.6409
       0.0,      0.000,      0.000,         0,     12.0351,      1.6442
       0.0,      0.000,      0.000,         0,     12.0351,      1.6476
       0.0,      0.000,      0.000,         0,     12.0351,      1.6509
       0.0,      0.000,      0.000,         0,     12.0351,      1.6542
       0.0,      0.000,      0.000,         0,     12.0351,      1.6576
       0.0,      0.000,      0.000,         0,     12.0351,      1.6609
       0.0,      0.000,      0.000,         0,     12.0351,      1.6642
       0.0,      0.000,      0.000,         0,     12.0351,      1.6676
       0.0,      0.000,      0.000,         0,     12.0351,      1.6709
       0.0,      0.000,      0.000,         0,     12.0351,      1.6743
       0.0,      0.000,      0.000,         0,     12.0351,      1.6776
       0.0,      0.000,      0.000,         0,     12.0351,      1.6809
       0.0,      0.000,      0.000,         0,     12.0351,      1.6843
       0.0,      0.000,      0.000,         0,     12.0351,      1.6876
       0.0,      0.000,      0.000,         0,     12.0351,      1.6909
       0.0,      0.000,      0.000,         0,     12.0351,      1.6943
       0.0,      0.000,      0.000,         0,     12.0351,      1.6976
       0.0,      0.000,      0.000,         0,     12.0351,      1.7009
       0.0,      0.000,      0.000,         0,     12.0351,      1.7043
       0.0,      0.000,      0.000,         0,     12.0351,      1.7076
       0.0,      0.000,      0.000,         0,     12.0351,      1.7110
       0.0,      0.000,      0.000,         0,     12.0351,      1.7143
       0.0,      0.000,      0.000,         0,     12.0351,      1.7176
       0.0,      0.000,      0.000,         0,     12.0351,      1.7210
       0.0,      0.000,      0.000,         0,     12.0351,      1.7243
       0.0,      0.000,      0.000,         0,     12.0351,      1.7276
       0.0,      0.000,      0.000,         0,     12.0351,      1.7310
       0.0,      0.000,      0.000,         0,     12.0351,      1.7343
       0.0,      0.000,      0.000,         0,     12.0351,      1.7376
       0.0,      0.000,      0.000,         0,     12.0351,      1.7410