File: Alban repo/Quiz 1/suction cup instron tests/oct-dec-2019_raw-data/d30e10-01-inwater-onwhiteplatic-nopump-10mm-test1.raw
Operator: 1

Date,Time,Specimen#
10/25/19,16:50:00,1

---------------------------------------


Area (mm^2):,      1.00,Flat,     25.40,     25.40,     25.40
Gage Len (mm):,     25.40


LOAD (N),STRAIN 1 (mm),STRAIN 2 (mm),STRESS (MPa),POSITION (mm),TIME (min)
       2.4,      0.000,      0.000,         0,      0.0811,      0.0083
       2.8,      0.000,      0.000,         0,      0.1642,      0.0167
       3.1,      0.000,      0.000,         0,      0.2476,      0.0250
       3.5,      0.000,      0.000,         0,      0.3311,      0.0333
       4.0,      0.000,      0.000,         0,      0.4143,      0.0417
       3.6,      0.000,      0.000,         0,      0.4975,      0.0500
       4.0,      0.000,      0.000,         0,      0.5807,      0.0583
       4.5,      0.000,      0.000,         0,      0.6643,      0.0667
       5.0,      0.000,      0.000,         0,      0.7475,      0.0750
       5.6,      0.000,      0.000,         0,      0.8311,      0.0833
       6.1,      0.000,      0.000,         0,      0.9144,      0.0917
       6.7,      0.000,      0.000,         0,      0.9976,      0.1000
       7.2,      0.000,      0.000,         0,      1.0809,      0.1083
       7.7,      0.000,      0.000,         0,      1.1644,      0.1167
       8.2,      0.000,      0.000,         0,      1.2477,      0.1250
       8.7,      0.000,      0.000,         0,      1.3309,      0.1333
       9.2,      0.000,      0.000,         0,      1.4143,      0.1417
       9.8,      0.000,      0.000,         0,      1.4976,      0.1500
      10.3,      0.000,      0.000,         0,      1.5810,      0.1583
      10.8,      0.000,      0.000,         0,      1.6642,      0.1667
      11.3,      0.000,      0.000,         0,      1.7477,      0.1750
      11.7,      0.000,      0.000,         0,      1.8309,      0.1833
      12.2,      0.000,      0.000,         0,      1.9142,      0.1917
      12.6,      0.000,      0.000,         0,      1.9976,      0.2000
      13.1,      0.000,      0.000,         0,      2.0810,      0.2083
      13.5,      0.000,      0.000,         0,      2.1642,      0.2167
      13.9,      0.000,      0.000,         0,      2.2475,      0.2250
      14.3,      0.000,      0.000,         0,      2.3311,      0.2333
      14.8,      0.000,      0.000,         0,      2.4142,      0.2417
      15.2,      0.000,      0.000,         0,      2.4977,      0.2500
      15.5,      0.000,      0.000,         0,      2.5808,      0.2583
      15.9,      0.000,      0.000,         0,      2.6643,      0.2667
      16.3,      0.000,      0.000,         0,      2.7474,      0.2750
      16.7,      0.000,      0.000,         0,      2.8308,      0.2833
      17.1,      0.000,      0.000,         0,      2.9142,      0.2917
      17.4,      0.000,      0.000,         0,      2.9977,      0.3000
      17.8,      0.000,      0.000,         0,      3.0809,      0.3083
      18.1,      0.000,      0.000,         0,      3.1641,      0.3167
      18.5,      0.000,      0.000,         0,      3.2476,      0.3250
      18.8,      0.000,      0.000,         0,      3.3309,      0.3333
      19.1,      0.000,      0.000,         0,      3.4138,      0.3417
      19.4,      0.000,      0.000,         0,      3.4975,      0.3500
      19.8,      0.000,      0.000,         0,      3.5811,      0.3583
      20.1,      0.000,      0.000,         0,      3.6641,      0.3667
      20.4,      0.000,      0.000,         0,      3.7475,      0.3750
      20.7,      0.000,      0.000,         0,      3.8306,      0.3833
      21.0,      0.000,      0.000,         0,      3.9144,      0.3917
      21.3,      0.000,      0.000,         0,      3.9975,      0.4000
      21.6,      0.000,      0.000,         0,      4.0808,      0.4083
      21.9,      0.000,      0.000,         0,      4.1642,      0.4167
      22.2,      0.000,      0.000,         0,      4.2476,      0.4250
      22.5,      0.000,      0.000,         0,      4.3308,      0.4333
      22.8,      0.000,      0.000,         0,      4.4143,      0.4417
      23.1,      0.000,      0.000,         0,      4.4976,      0.4500
      23.4,      0.000,      0.000,         0,      4.5808,      0.4583
      23.6,      0.000,      0.000,         0,      4.6643,      0.4667
      23.9,      0.000,      0.000,         0,      4.7474,      0.4750
      24.2,      0.000,      0.000,         0,      4.8308,      0.4833
      24.5,      0.000,      0.000,         0,      4.9140,      0.4917
      24.8,      0.000,      0.000,         0,      4.9976,      0.5000
      25.1,      0.000,      0.000,         0,      5.0808,      0.5083
      25.3,      0.000,      0.000,         0,      5.1641,      0.5167
      25.6,      0.000,      0.000,         0,      5.2475,      0.5250
      25.9,      0.000,      0.000,         0,      5.3309,      0.5333
      26.2,      0.000,      0.000,         0,      5.4141,      0.5417
      26.5,      0.000,      0.000,         0,      5.4974,      0.5500
      26.7,      0.000,      0.000,         0,      5.5810,      0.5583
      27.0,      0.000,      0.000,         0,      5.6640,      0.5667
      27.3,      0.000,      0.000,         0,      5.7473,      0.5750
      27.6,      0.000,      0.000,         0,      5.8307,      0.5833
      27.9,      0.000,      0.000,         0,      5.9142,      0.5917
      28.1,      0.000,      0.000,         0,      5.9971,      0.6000
      28.4,      0.000,      0.000,         0,      6.0808,      0.6083
      28.7,      0.000,      0.000,         0,      6.1641,      0.6167
      28.9,      0.000,      0.000,         0,      6.2474,      0.6250
      29.2,      0.000,      0.000,         0,      6.3308,      0.6333
      29.5,      0.000,      0.000,         0,      6.4140,      0.6417
      29.8,      0.000,      0.000,         0,      6.4974,      0.6500
      30.0,      0.000,      0.000,         0,      6.5808,      0.6583
      30.3,      0.000,      0.000,         0,      6.6641,      0.6667
      30.6,      0.000,      0.000,         0,      6.7475,      0.6750
      30.8,      0.000,      0.000,         0,      6.8307,      0.6833
      31.1,      0.000,      0.000,         0,      6.9141,      0.6917
      31.4,      0.000,      0.000,         0,      6.9973,      0.7000
      31.7,      0.000,      0.000,         0,      7.0806,      0.7083
      31.9,      0.000,      0.000,         0,      7.1641,      0.7167
      32.2,      0.000,      0.000,         0,      7.2473,      0.7250
      32.5,      0.000,      0.000,         0,      7.3308,      0.7333
      32.8,      0.000,      0.000,         0,      7.4140,      0.7417
      33.1,      0.000,      0.000,         0,      7.4973,      0.7500
      33.3,      0.000,      0.000,         0,      7.5806,      0.7583
      33.6,      0.000,      0.000,         0,      7.6641,      0.7667
      33.9,      0.000,      0.000,         0,      7.7473,      0.7750
      34.2,      0.000,      0.000,         0,      7.8306,      0.7833
      34.5,      0.000,      0.000,         0,      7.9141,      0.7917
      34.7,      0.000,      0.000,         0,      7.9974,      0.8000
      35.0,      0.000,      0.000,         0,      8.0807,      0.8083
      35.3,      0.000,      0.000,         0,      8.1639,      0.8167
      35.5,      0.000,      0.000,         0,      8.2475,      0.8250
      35.8,      0.000,      0.000,         0,      8.3306,      0.8333
      36.1,      0.000,      0.000,         0,      8.4139,      0.8417
      36.3,      0.000,      0.000,         0,      8.4973,      0.8500
      36.6,      0.000,      0.000,         0,      8.5807,      0.8583
      36.9,      0.000,      0.000,         0,      8.6640,      0.8667
      37.2,      0.000,      0.000,         0,      8.7473,      0.8750
      37.4,      0.000,      0.000,         0,      8.8308,      0.8833
      37.7,      0.000,      0.000,         0,      8.9140,      0.8917
      38.0,      0.000,      0.000,         0,      8.9973,      0.9000
      38.2,      0.000,      0.000,         0,      9.0802,      0.9083
      38.5,      0.000,      0.000,         0,      9.1641,      0.9167
      38.8,      0.000,      0.000,         0,      9.2472,      0.9250
      39.1,      0.000,      0.000,         0,      9.3306,      0.9333
      39.4,      0.000,      0.000,         0,      9.4140,      0.9417
      39.7,      0.000,      0.000,         0,      9.4973,      0.9500
      39.9,      0.000,      0.000,         0,      9.5806,      0.9583
      40.1,      0.000,      0.000,         0,      9.6639,      0.9667
      40.3,      0.000,      0.000,         0,      9.7472,      0.9750
      40.6,      0.000,      0.000,         0,      9.8305,      0.9833
      40.9,      0.000,      0.000,         0,      9.9139,      0.9917
      41.1,      0.000,      0.000,         0,      9.9972,      1.0000
      41.4,      0.000,      0.000,         0,     10.0805,      1.0083
      41.6,      0.000,      0.000,         0,     10.1638,      1.0167
      41.9,      0.000,      0.000,         0,     10.2473,      1.0250
      42.2,      0.000,      0.000,         0,     10.3306,      1.0333
      42.4,      0.000,      0.000,         0,     10.4140,      1.0417
      42.7,      0.000,      0.000,         0,     10.4971,      1.0500
      42.9,      0.000,      0.000,         0,     10.5807,      1.0583
      43.2,      0.000,      0.000,         0,     10.6637,      1.0667
      43.4,      0.000,      0.000,         0,     10.7472,      1.0750
      43.7,      0.000,      0.000,         0,     10.8306,      1.0833
      43.9,      0.000,      0.000,         0,     10.9139,      1.0917
      44.2,      0.000,      0.000,         0,     10.9972,      1.1000
      44.4,      0.000,      0.000,         0,     11.0805,      1.1083
      44.6,      0.000,      0.000,         0,     11.1640,      1.1167
      44.9,      0.000,      0.000,         0,     11.2472,      1.1250
      45.1,      0.000,      0.000,         0,     11.3306,      1.1333
      45.4,      0.000,      0.000,         0,     11.4138,      1.1417
      45.6,      0.000,      0.000,         0,     11.4974,      1.1500
      45.8,      0.000,      0.000,         0,     11.5806,      1.1583
      46.1,      0.000,      0.000,         0,     11.6638,      1.1667
      46.3,      0.000,      0.000,         0,     11.7470,      1.1750
      46.5,      0.000,      0.000,         0,     11.8306,      1.1833
      46.8,      0.000,      0.000,         0,     11.9139,      1.1917
      47.0,      0.000,      0.000,         0,     11.9971,      1.2000
      47.2,      0.000,      0.000,         0,     12.0805,      1.2083
      47.4,      0.000,      0.000,         0,     12.1638,      1.2167
      47.6,      0.000,      0.000,         0,     12.2472,      1.2250
      47.9,      0.000,      0.000,         0,     12.3304,      1.2333
      48.1,      0.000,      0.000,         0,     12.4139,      1.2417
      48.3,      0.000,      0.000,         0,     12.4970,      1.2500
      48.5,      0.000,      0.000,         0,     12.5805,      1.2583
      48.7,      0.000,      0.000,         0,     12.6638,      1.2667
      48.9,      0.000,      0.000,         0,     12.7471,      1.2750
      49.1,      0.000,      0.000,         0,     12.8305,      1.2833
      49.2,      0.000,      0.000,         0,     12.9138,      1.2917
      49.4,      0.000,      0.000,         0,     12.9971,      1.3000
      49.6,      0.000,      0.000,         0,     13.0804,      1.3083
      49.7,      0.000,      0.000,         0,     13.1639,      1.3167
      49.9,      0.000,      0.000,         0,     13.2472,      1.3250
      50.0,      0.000,      0.000,         0,     13.3303,      1.3333
      50.1,      0.000,      0.000,         0,     13.4136,      1.3417
      50.1,      0.000,      0.000,         0,     13.4972,      1.3500
      50.1,      0.000,      0.000,         0,     13.5805,      1.3583
      50.0,      0.000,      0.000,         0,     13.6637,      1.3667
      49.7,      0.000,      0.000,         0,     13.7470,      1.3750
      49.2,      0.000,      0.000,         0,     13.8306,      1.3833
       0.5,      0.000,      0.000,         0,     13.9135,      1.3917
       0.1,      0.000,      0.000,         0,     13.9970,      1.4000
       0.1,      0.000,      0.000,         0,     14.0804,      1.4083
       0.1,      0.000,      0.000,         0,     14.1638,      1.4167
       0.1,      0.000,      0.000,         0,     14.2470,      1.4250
       0.1,      0.000,      0.000,         0,     14.3304,      1.4333
       0.1,      0.000,      0.000,         0,     14.4138,      1.4417
       0.1,      0.000,      0.000,         0,     14.4970,      1.4500
       0.1,      0.000,      0.000,         0,     14.5804,      1.4583
       0.1,      0.000,      0.000,         0,     14.6637,      1.4667
       0.1,      0.000,      0.000,         0,     14.7470,      1.4750
       0.1,      0.000,      0.000,         0,     14.8303,      1.4833
       0.1,      0.000,      0.000,         0,     14.9137,      1.4917
       0.1,      0.000,      0.000,         0,     14.9969,      1.5000
       0.1,      0.000,      0.000,         0,     15.0804,      1.5083
       0.1,      0.000,      0.000,         0,     15.1637,      1.5167
       0.1,      0.000,      0.000,         0,     15.2471,      1.5250
       0.1,      0.000,      0.000,         0,     15.3301,      1.5333
       0.1,      0.000,      0.000,         0,     15.4136,      1.5417
       0.1,      0.000,      0.000,         0,     15.4970,      1.5500
       0.1,      0.000,      0.000,         0,     15.5804,      1.5583
       0.1,      0.000,      0.000,         0,     15.6632,      1.5667
       0.1,      0.000,      0.000,         0,     15.7470,      1.5750
       0.1,      0.000,      0.000,         0,     15.8304,      1.5833
       0.1,      0.000,      0.000,         0,     15.9136,      1.5917
       0.1,      0.000,      0.000,         0,     15.9970,      1.6000
       0.1,      0.000,      0.000,         0,     16.0803,      1.6083
       0.1,      0.000,      0.000,         0,     16.1637,      1.6167
       0.1,      0.000,      0.000,         0,     16.2470,      1.6250
       0.1,      0.000,      0.000,         0,     16.3302,      1.6333
       0.1,      0.000,      0.000,         0,     16.4137,      1.6417
       0.1,      0.000,      0.000,         0,     16.4971,      1.6500
       0.1,      0.000,      0.000,         0,     16.5803,      1.6583
       0.1,      0.000,      0.000,         0,     16.6636,      1.6667
       0.1,      0.000,      0.000,         0,     16.7470,      1.6750
       0.1,      0.000,      0.000,         0,     16.8304,      1.6833
       0.1,      0.000,      0.000,         0,     16.9136,      1.6917
       0.1,      0.000,      0.000,         0,     16.9967,      1.7000
       0.1,      0.000,      0.000,         0,     17.0805,      1.7083
       0.1,      0.000,      0.000,         0,     17.1637,      1.7167
       0.1,      0.000,      0.000,         0,     17.2470,      1.7250
       0.1,      0.000,      0.000,         0,     17.3303,      1.7333
       0.1,      0.000,      0.000,         0,     17.4136,      1.7417
       0.1,      0.000,      0.000,         0,     17.4969,      1.7500