File: Alban repo/Quiz 1/suction cup instron tests/oct-dec-2019_raw-data/d30e10-01-inwater-on36grit-diaphragmpump-100mm-test1.raw
Operator: 1

Date,Time,Specimen#
11/09/19,17:36:46,1

---------------------------------------


Area (mm^2):,      1.00,Flat,     25.40,     25.40,     25.40
Gage Len (mm):,     25.40


LOAD (N),STRAIN 1 (mm),STRAIN 2 (mm),STRESS (MPa),POSITION (mm),TIME (min)
      18.9,      0.000,      0.000,         0,     -0.1612,      0.0083
      20.4,      0.000,      0.000,         0,     -0.3279,      0.0167
      20.2,      0.000,      0.000,         0,     -0.4947,      0.0250
      19.9,      0.000,      0.000,         0,     -0.6612,      0.0333
      19.4,      0.000,      0.000,         0,     -0.8279,      0.0417
      19.0,      0.000,      0.000,         0,     -0.9945,      0.0500
      18.6,      0.000,      0.000,         0,     -1.1612,      0.0583
      18.1,      0.000,      0.000,         0,     -1.3280,      0.0667
      17.7,      0.000,      0.000,         0,     -1.4945,      0.0750
      17.3,      0.000,      0.000,         0,     -1.6611,      0.0833
      16.8,      0.000,      0.000,         0,     -1.8280,      0.0917
      16.4,      0.000,      0.000,         0,     -1.9945,      0.1000
      15.9,      0.000,      0.000,         0,     -2.1613,      0.1083
      15.5,      0.000,      0.000,         0,     -2.3278,      0.1167
      15.0,      0.000,      0.000,         0,     -2.4946,      0.1250
      14.6,      0.000,      0.000,         0,     -2.6613,      0.1333
      14.1,      0.000,      0.000,         0,     -2.8279,      0.1417
      13.7,      0.000,      0.000,         0,     -2.9946,      0.1500
      13.2,      0.000,      0.000,         0,     -3.1612,      0.1583
      12.7,      0.000,      0.000,         0,     -3.3277,      0.1667
      12.2,      0.000,      0.000,         0,     -3.4946,      0.1750
      11.7,      0.000,      0.000,         0,     -3.6610,      0.1833
      11.1,      0.000,      0.000,         0,     -3.8279,      0.1917
      10.5,      0.000,      0.000,         0,     -3.9943,      0.2000
       9.9,      0.000,      0.000,         0,     -4.1610,      0.2083
       9.3,      0.000,      0.000,         0,     -4.3278,      0.2167
       8.6,      0.000,      0.000,         0,     -4.4945,      0.2250
       8.0,      0.000,      0.000,         0,     -4.6610,      0.2333
       7.2,      0.000,      0.000,         0,     -4.8278,      0.2417
       6.4,      0.000,      0.000,         0,     -4.9945,      0.2500
       5.6,      0.000,      0.000,         0,     -5.1611,      0.2583
       4.7,      0.000,      0.000,         0,     -5.3278,      0.2667
       3.7,      0.000,      0.000,         0,     -5.4944,      0.2750
       2.6,      0.000,      0.000,         0,     -5.6611,      0.2833
       1.4,      0.000,      0.000,         0,     -5.8276,      0.2917
       0.0,      0.000,      0.000,         0,     -5.9944,      0.3000
      -1.7,      0.000,      0.000,         0,     -6.1611,      0.3083
      -3.6,      0.000,      0.000,         0,     -6.3277,      0.3167
      -5.9,      0.000,      0.000,         0,     -6.4944,      0.3250
      -8.6,      0.000,      0.000,         0,     -6.6608,      0.3333
     -11.4,      0.000,      0.000,         0,     -6.8277,      0.3417
     -14.5,      0.000,      0.000,         0,     -6.9943,      0.3500
     -14.2,      0.000,      0.000,         0,     -7.0616,      0.3681
     -13.4,      0.000,      0.000,         0,     -7.0616,      0.3848
     -12.9,      0.000,      0.000,         0,     -7.0616,      0.4014
     -12.5,      0.000,      0.000,         0,     -7.0614,      0.4181
     -12.3,      0.000,      0.000,         0,     -7.0614,      0.4348
     -12.0,      0.000,      0.000,         0,     -7.0614,      0.4514
     -11.8,      0.000,      0.000,         0,     -7.0612,      0.4681
     -11.7,      0.000,      0.000,         0,     -7.0610,      0.4848
     -11.5,      0.000,      0.000,         0,     -7.0608,      0.5014
     -11.3,      0.000,      0.000,         0,     -7.0325,      0.5181
     -11.0,      0.000,      0.000,         0,     -7.0253,      0.5348
     -10.9,      0.000,      0.000,         0,     -7.0240,      0.5514
     -10.8,      0.000,      0.000,         0,     -7.0238,      0.5681
     -10.7,      0.000,      0.000,         0,     -7.0221,      0.5848
     -10.7,      0.000,      0.000,         0,     -7.0219,      0.6014
       2.7,      0.000,      0.000,         0,     -6.3504,      0.6098
      11.1,      0.000,      0.000,         0,     -5.5169,      0.6181
      16.7,      0.000,      0.000,         0,     -4.6834,      0.6264
      20.6,      0.000,      0.000,         0,     -3.8488,      0.6348
      23.5,      0.000,      0.000,         0,     -3.0149,      0.6431
      25.9,      0.000,      0.000,         0,     -2.1816,      0.6514
      28.3,      0.000,      0.000,         0,     -1.3484,      0.6598
      30.9,      0.000,      0.000,         0,     -0.5151,      0.6681
      33.1,      0.000,      0.000,         0,      0.3184,      0.6764
      35.6,      0.000,      0.000,         0,      1.1515,      0.6848
      38.2,      0.000,      0.000,         0,      1.9848,      0.6931
      40.8,      0.000,      0.000,         0,      2.8179,      0.7014
      43.4,      0.000,      0.000,         0,      3.6513,      0.7098
      45.9,      0.000,      0.000,         0,      4.4846,      0.7181
      48.4,      0.000,      0.000,         0,      5.3179,      0.7264
      50.8,      0.000,      0.000,         0,      6.1512,      0.7348
      53.1,      0.000,      0.000,         0,      6.9845,      0.7431
      55.0,      0.000,      0.000,         0,      7.8177,      0.7514
      56.3,      0.000,      0.000,         0,      8.6510,      0.7598
       0.1,      0.000,      0.000,         0,      9.4843,      0.7681
       0.1,      0.000,      0.000,         0,     10.3176,      0.7764
       0.1,      0.000,      0.000,         0,     11.1509,      0.7848
       0.1,      0.000,      0.000,         0,     11.9842,      0.7931
       0.1,      0.000,      0.000,         0,     12.8174,      0.8014
       0.1,      0.000,      0.000,         0,     13.6507,      0.8098
       0.1,      0.000,      0.000,         0,     14.4840,      0.8181
       0.2,      0.000,      0.000,         0,     15.3173,      0.8264
       0.2,      0.000,      0.000,         0,     16.1508,      0.8348