File: Alban repo/Quiz 1/suction cup instron tests/oct-dec-2019_raw-data/d30e10-01-inwater-onwhiteplatic-diaphragmpump-100mm-test1.raw
Operator: 1

Date,Time,Specimen#
10/25/19,17:33:37,1

---------------------------------------


Area (mm^2):,      1.00,Flat,     25.40,     25.40,     25.40
Gage Len (mm):,     25.40


LOAD (N),STRAIN 1 (mm),STRAIN 2 (mm),STRESS (MPa),POSITION (mm),TIME (min)
      16.8,      0.000,      0.000,         0,     -0.1607,      0.0083
      20.6,      0.000,      0.000,         0,     -0.3273,      0.0167
      20.8,      0.000,      0.000,         0,     -0.4941,      0.0250
      20.8,      0.000,      0.000,         0,     -0.6606,      0.0333
      20.6,      0.000,      0.000,         0,     -0.8272,      0.0417
      20.2,      0.000,      0.000,         0,     -0.9939,      0.0500
      19.9,      0.000,      0.000,         0,     -1.1605,      0.0583
      19.5,      0.000,      0.000,         0,     -1.3272,      0.0667
      19.1,      0.000,      0.000,         0,     -1.4939,      0.0750
      18.7,      0.000,      0.000,         0,     -1.6607,      0.0833
      18.3,      0.000,      0.000,         0,     -1.8273,      0.0917
      18.0,      0.000,      0.000,         0,     -1.9939,      0.1000
      17.6,      0.000,      0.000,         0,     -2.1607,      0.1083
      17.2,      0.000,      0.000,         0,     -2.3272,      0.1167
      16.7,      0.000,      0.000,         0,     -2.4940,      0.1250
      16.3,      0.000,      0.000,         0,     -2.6606,      0.1333
      15.9,      0.000,      0.000,         0,     -2.8272,      0.1417
      15.4,      0.000,      0.000,         0,     -2.9939,      0.1500
      15.0,      0.000,      0.000,         0,     -3.1606,      0.1583
      14.5,      0.000,      0.000,         0,     -3.3272,      0.1667
      14.0,      0.000,      0.000,         0,     -3.4938,      0.1750
      13.5,      0.000,      0.000,         0,     -3.6604,      0.1833
      13.0,      0.000,      0.000,         0,     -3.8272,      0.1917
      12.4,      0.000,      0.000,         0,     -3.9937,      0.2000
      11.9,      0.000,      0.000,         0,     -4.1605,      0.2083
      11.3,      0.000,      0.000,         0,     -4.3272,      0.2167
      10.7,      0.000,      0.000,         0,     -4.4938,      0.2250
      10.1,      0.000,      0.000,         0,     -4.6606,      0.2333
       9.4,      0.000,      0.000,         0,     -4.8271,      0.2417
       8.7,      0.000,      0.000,         0,     -4.9938,      0.2500
       8.0,      0.000,      0.000,         0,     -5.1605,      0.2583
       7.4,      0.000,      0.000,         0,     -5.3270,      0.2667
       6.6,      0.000,      0.000,         0,     -5.4939,      0.2750
       5.8,      0.000,      0.000,         0,     -5.6604,      0.2833
       5.0,      0.000,      0.000,         0,     -5.8271,      0.2917
       4.2,      0.000,      0.000,         0,     -5.9937,      0.3000
       3.3,      0.000,      0.000,         0,     -6.1604,      0.3083
       2.3,      0.000,      0.000,         0,     -6.3269,      0.3167
       1.1,      0.000,      0.000,         0,     -6.4939,      0.3250
      -0.5,      0.000,      0.000,         0,     -6.6603,      0.3333
      -2.7,      0.000,      0.000,         0,     -6.8271,      0.3417
      -3.4,      0.000,      0.000,         0,     -6.9937,      0.3500
      -6.6,      0.000,      0.000,         0,     -7.1603,      0.3583
      -9.8,      0.000,      0.000,         0,     -7.3271,      0.3667
     -13.2,      0.000,      0.000,         0,     -7.4937,      0.3750
     -14.2,      0.000,      0.000,         0,     -7.6113,      0.3957
     -13.4,      0.000,      0.000,         0,     -7.6113,      0.4124
     -12.9,      0.000,      0.000,         0,     -7.6112,      0.4291
     -12.6,      0.000,      0.000,         0,     -7.6112,      0.4457
     -12.3,      0.000,      0.000,         0,     -7.6111,      0.4624
     -12.1,      0.000,      0.000,         0,     -7.6110,      0.4791
     -11.9,      0.000,      0.000,         0,     -7.6109,      0.4957
     -11.8,      0.000,      0.000,         0,     -7.6109,      0.5124
     -11.6,      0.000,      0.000,         0,     -7.6109,      0.5291
     -11.5,      0.000,      0.000,         0,     -7.5865,      0.5457
     -11.2,      0.000,      0.000,         0,     -7.5792,      0.5624
     -11.1,      0.000,      0.000,         0,     -7.5770,      0.5791
     -11.0,      0.000,      0.000,         0,     -7.5763,      0.5957
     -10.9,      0.000,      0.000,         0,     -7.5748,      0.6124
     -10.9,      0.000,      0.000,         0,     -7.5749,      0.6291
       4.6,      0.000,      0.000,         0,     -6.9058,      0.6374
      13.5,      0.000,      0.000,         0,     -6.0721,      0.6457
      19.2,      0.000,      0.000,         0,     -5.2388,      0.6541
      23.0,      0.000,      0.000,         0,     -4.4050,      0.6624
      25.8,      0.000,      0.000,         0,     -3.5703,      0.6707
      28.3,      0.000,      0.000,         0,     -2.7369,      0.6791
      30.6,      0.000,      0.000,         0,     -1.9037,      0.6874
      33.1,      0.000,      0.000,         0,     -1.0703,      0.6957
      35.4,      0.000,      0.000,         0,     -0.2372,      0.7041
      37.6,      0.000,      0.000,         0,      0.5963,      0.7124
      40.1,      0.000,      0.000,         0,      1.4294,      0.7207
      42.6,      0.000,      0.000,         0,      2.2627,      0.7291
      45.0,      0.000,      0.000,         0,      3.0960,      0.7374
      47.3,      0.000,      0.000,         0,      3.9294,      0.7457
      49.4,      0.000,      0.000,         0,      4.7627,      0.7541
      51.2,      0.000,      0.000,         0,      5.5960,      0.7624
      52.2,      0.000,      0.000,         0,      6.4292,      0.7707
       0.2,      0.000,      0.000,         0,      7.2623,      0.7791
       0.0,      0.000,      0.000,         0,      8.0955,      0.7874
       0.0,      0.000,      0.000,         0,      8.9288,      0.7957
       0.0,      0.000,      0.000,         0,      9.7623,      0.8041
       0.0,      0.000,      0.000,         0,     10.5957,      0.8124
       0.0,      0.000,      0.000,         0,     11.4289,      0.8207
       0.0,      0.000,      0.000,         0,     12.2620,      0.8291
       0.0,      0.000,      0.000,         0,     13.0954,      0.8374
       0.0,      0.000,      0.000,         0,     13.9287,      0.8457
       0.0,      0.000,      0.000,         0,     14.7620,      0.8541
       0.0,      0.000,      0.000,         0,     15.5953,      0.8624
       0.1,      0.000,      0.000,         0,     16.4286,      0.8707
       0.1,      0.000,      0.000,         0,     17.2618,      0.8791
       0.1,      0.000,      0.000,         0,     18.0951,      0.8874
       0.1,      0.000,      0.000,         0,     18.9283,      0.8957
       0.1,      0.000,      0.000,         0,     19.7615,      0.9041