File: Alban repo/Quiz 1/suction cup instron tests/oct-dec-2019_raw-data/d30e10-01-inwater-onwhiteplatic-nopump-10mm-test5.raw
Operator: 1

Date,Time,Specimen#
10/25/19,17:16:00,1

---------------------------------------


Area (mm^2):,      1.00,Flat,     25.40,     25.40,     25.40
Gage Len (mm):,     25.40


LOAD (N),STRAIN 1 (mm),STRAIN 2 (mm),STRESS (MPa),POSITION (mm),TIME (min)
       1.9,      0.000,      0.000,         0,      0.0809,      0.0083
       2.4,      0.000,      0.000,         0,      0.1643,      0.0167
       3.0,      0.000,      0.000,         0,      0.2478,      0.0250
       3.5,      0.000,      0.000,         0,      0.3311,      0.0333
       3.9,      0.000,      0.000,         0,      0.4143,      0.0417
       3.7,      0.000,      0.000,         0,      0.4975,      0.0500
       4.2,      0.000,      0.000,         0,      0.5811,      0.0583
       4.8,      0.000,      0.000,         0,      0.6645,      0.0667
       5.5,      0.000,      0.000,         0,      0.7475,      0.0750
       6.1,      0.000,      0.000,         0,      0.8311,      0.0833
       6.7,      0.000,      0.000,         0,      0.9145,      0.0917
       7.2,      0.000,      0.000,         0,      0.9976,      0.1000
       7.8,      0.000,      0.000,         0,      1.0809,      0.1083
       8.4,      0.000,      0.000,         0,      1.1644,      0.1167
       9.0,      0.000,      0.000,         0,      1.2478,      0.1250
       9.5,      0.000,      0.000,         0,      1.3309,      0.1333
      10.0,      0.000,      0.000,         0,      1.4143,      0.1417
      10.6,      0.000,      0.000,         0,      1.4979,      0.1500
      11.1,      0.000,      0.000,         0,      1.5810,      0.1583
      11.6,      0.000,      0.000,         0,      1.6644,      0.1667
      12.0,      0.000,      0.000,         0,      1.7477,      0.1750
      12.5,      0.000,      0.000,         0,      1.8312,      0.1833
      12.9,      0.000,      0.000,         0,      1.9142,      0.1917
      13.4,      0.000,      0.000,         0,      1.9977,      0.2000
      13.9,      0.000,      0.000,         0,      2.0811,      0.2083
      14.4,      0.000,      0.000,         0,      2.1644,      0.2167
      14.9,      0.000,      0.000,         0,      2.2476,      0.2250
      15.3,      0.000,      0.000,         0,      2.3312,      0.2333
      15.8,      0.000,      0.000,         0,      2.4141,      0.2417
      16.2,      0.000,      0.000,         0,      2.4976,      0.2500
      16.6,      0.000,      0.000,         0,      2.5810,      0.2583
      17.1,      0.000,      0.000,         0,      2.6643,      0.2667
      17.5,      0.000,      0.000,         0,      2.7476,      0.2750
      17.9,      0.000,      0.000,         0,      2.8309,      0.2833
      18.2,      0.000,      0.000,         0,      2.9145,      0.2917
      18.6,      0.000,      0.000,         0,      2.9975,      0.3000
      19.0,      0.000,      0.000,         0,      3.0809,      0.3083
      19.3,      0.000,      0.000,         0,      3.1642,      0.3167
      19.7,      0.000,      0.000,         0,      3.2476,      0.3250
      20.0,      0.000,      0.000,         0,      3.3305,      0.3333
      20.4,      0.000,      0.000,         0,      3.4142,      0.3417
      20.7,      0.000,      0.000,         0,      3.4977,      0.3500
      21.0,      0.000,      0.000,         0,      3.5810,      0.3583
      21.3,      0.000,      0.000,         0,      3.6643,      0.3667
      21.6,      0.000,      0.000,         0,      3.7476,      0.3750
      22.0,      0.000,      0.000,         0,      3.8310,      0.3833
      22.3,      0.000,      0.000,         0,      3.9142,      0.3917
      22.6,      0.000,      0.000,         0,      3.9975,      0.4000
      22.8,      0.000,      0.000,         0,      4.0808,      0.4083
      23.1,      0.000,      0.000,         0,      4.1644,      0.4167
      23.4,      0.000,      0.000,         0,      4.2474,      0.4250
      23.7,      0.000,      0.000,         0,      4.3308,      0.4333
      24.0,      0.000,      0.000,         0,      4.4142,      0.4417
      24.3,      0.000,      0.000,         0,      4.4976,      0.4500
      24.6,      0.000,      0.000,         0,      4.5808,      0.4583
      24.8,      0.000,      0.000,         0,      4.6642,      0.4667
      25.1,      0.000,      0.000,         0,      4.7474,      0.4750
      25.4,      0.000,      0.000,         0,      4.8309,      0.4833
      25.7,      0.000,      0.000,         0,      4.9142,      0.4917
      25.9,      0.000,      0.000,         0,      4.9976,      0.5000
      26.2,      0.000,      0.000,         0,      5.0809,      0.5083
      26.5,      0.000,      0.000,         0,      5.1640,      0.5167
      26.7,      0.000,      0.000,         0,      5.2475,      0.5250
      27.0,      0.000,      0.000,         0,      5.3308,      0.5333
      27.3,      0.000,      0.000,         0,      5.4142,      0.5417
      27.5,      0.000,      0.000,         0,      5.4975,      0.5500
      27.8,      0.000,      0.000,         0,      5.5810,      0.5583
      28.1,      0.000,      0.000,         0,      5.6641,      0.5667
      28.3,      0.000,      0.000,         0,      5.7475,      0.5750
      28.6,      0.000,      0.000,         0,      5.8309,      0.5833
      28.9,      0.000,      0.000,         0,      5.9141,      0.5917
      29.1,      0.000,      0.000,         0,      5.9974,      0.6000
      29.4,      0.000,      0.000,         0,      6.0808,      0.6083
      29.7,      0.000,      0.000,         0,      6.1643,      0.6167
      29.9,      0.000,      0.000,         0,      6.2475,      0.6250
      30.2,      0.000,      0.000,         0,      6.3308,      0.6333
      30.5,      0.000,      0.000,         0,      6.4141,      0.6417
      30.8,      0.000,      0.000,         0,      6.4976,      0.6500
      31.1,      0.000,      0.000,         0,      6.5806,      0.6583
      31.4,      0.000,      0.000,         0,      6.6641,      0.6667
      31.7,      0.000,      0.000,         0,      6.7475,      0.6750
      32.0,      0.000,      0.000,         0,      6.8307,      0.6833
      32.3,      0.000,      0.000,         0,      6.9140,      0.6917
      32.6,      0.000,      0.000,         0,      6.9973,      0.7000
      32.8,      0.000,      0.000,         0,      7.0806,      0.7083
      33.1,      0.000,      0.000,         0,      7.1640,      0.7167
      33.4,      0.000,      0.000,         0,      7.2474,      0.7250
      33.6,      0.000,      0.000,         0,      7.3308,      0.7333
      33.9,      0.000,      0.000,         0,      7.4141,      0.7417
      34.2,      0.000,      0.000,         0,      7.4973,      0.7500
      34.4,      0.000,      0.000,         0,      7.5806,      0.7583
      34.7,      0.000,      0.000,         0,      7.6640,      0.7667
      34.9,      0.000,      0.000,         0,      7.7474,      0.7750
      35.2,      0.000,      0.000,         0,      7.8307,      0.7833
      35.5,      0.000,      0.000,         0,      7.9141,      0.7917
      35.7,      0.000,      0.000,         0,      7.9972,      0.8000
      36.0,      0.000,      0.000,         0,      8.0806,      0.8083
      36.2,      0.000,      0.000,         0,      8.1640,      0.8167
      36.5,      0.000,      0.000,         0,      8.2474,      0.8250
      36.8,      0.000,      0.000,         0,      8.3307,      0.8333
      37.0,      0.000,      0.000,         0,      8.4139,      0.8417
      37.3,      0.000,      0.000,         0,      8.4974,      0.8500
      37.6,      0.000,      0.000,         0,      8.5808,      0.8583
      37.8,      0.000,      0.000,         0,      8.6640,      0.8667
      38.1,      0.000,      0.000,         0,      8.7472,      0.8750
      38.4,      0.000,      0.000,         0,      8.8309,      0.8833
      38.6,      0.000,      0.000,         0,      8.9139,      0.8917
      38.9,      0.000,      0.000,         0,      8.9969,      0.9000
      39.1,      0.000,      0.000,         0,      9.0806,      0.9083
      39.4,      0.000,      0.000,         0,      9.1641,      0.9167
      39.6,      0.000,      0.000,         0,      9.2472,      0.9250
      39.9,      0.000,      0.000,         0,      9.3306,      0.9333
      40.2,      0.000,      0.000,         0,      9.4142,      0.9417
      40.4,      0.000,      0.000,         0,      9.4972,      0.9500
      40.7,      0.000,      0.000,         0,      9.5806,      0.9583
      40.9,      0.000,      0.000,         0,      9.6639,      0.9667
      41.1,      0.000,      0.000,         0,      9.7475,      0.9750
      41.3,      0.000,      0.000,         0,      9.8305,      0.9833
      41.5,      0.000,      0.000,         0,      9.9139,      0.9917
      41.7,      0.000,      0.000,         0,      9.9974,      1.0000
      41.9,      0.000,      0.000,         0,     10.0805,      1.0083
      42.2,      0.000,      0.000,         0,     10.1640,      1.0167
      42.4,      0.000,      0.000,         0,     10.2473,      1.0250
      42.6,      0.000,      0.000,         0,     10.3303,      1.0333
      42.8,      0.000,      0.000,         0,     10.4139,      1.0417
      43.0,      0.000,      0.000,         0,     10.4974,      1.0500
      43.3,      0.000,      0.000,         0,     10.5807,      1.0583
      43.5,      0.000,      0.000,         0,     10.6639,      1.0667
      43.7,      0.000,      0.000,         0,     10.7473,      1.0750
      44.0,      0.000,      0.000,         0,     10.8307,      1.0833
      44.2,      0.000,      0.000,         0,     10.9139,      1.0917
      44.4,      0.000,      0.000,         0,     10.9973,      1.1000
      44.6,      0.000,      0.000,         0,     11.0805,      1.1083
      44.9,      0.000,      0.000,         0,     11.1640,      1.1167
      45.1,      0.000,      0.000,         0,     11.2471,      1.1250
      45.3,      0.000,      0.000,         0,     11.3306,      1.1333
      45.5,      0.000,      0.000,         0,     11.4138,      1.1417
      45.7,      0.000,      0.000,         0,     11.4973,      1.1500
      46.0,      0.000,      0.000,         0,     11.5805,      1.1583
      46.2,      0.000,      0.000,         0,     11.6638,      1.1667
      46.4,      0.000,      0.000,         0,     11.7472,      1.1750
      46.6,      0.000,      0.000,         0,     11.8305,      1.1833
      46.9,      0.000,      0.000,         0,     11.9138,      1.1917
      47.1,      0.000,      0.000,         0,     11.9970,      1.2000
      47.3,      0.000,      0.000,         0,     12.0807,      1.2083
      47.5,      0.000,      0.000,         0,     12.1638,      1.2167
      47.8,      0.000,      0.000,         0,     12.2471,      1.2250
      48.0,      0.000,      0.000,         0,     12.3304,      1.2333
      48.2,      0.000,      0.000,         0,     12.4139,      1.2417
      48.4,      0.000,      0.000,         0,     12.4972,      1.2500
      48.6,      0.000,      0.000,         0,     12.5805,      1.2583
      48.9,      0.000,      0.000,         0,     12.6640,      1.2667
      49.1,      0.000,      0.000,         0,     12.7471,      1.2750
      49.3,      0.000,      0.000,         0,     12.8304,      1.2833
      49.5,      0.000,      0.000,         0,     12.9139,      1.2917
      49.7,      0.000,      0.000,         0,     12.9973,      1.3000
      49.9,      0.000,      0.000,         0,     13.0805,      1.3083
      50.1,      0.000,      0.000,         0,     13.1640,      1.3167
      50.3,      0.000,      0.000,         0,     13.2472,      1.3250
      50.4,      0.000,      0.000,         0,     13.3306,      1.3333
      50.5,      0.000,      0.000,         0,     13.4138,      1.3417
      50.6,      0.000,      0.000,         0,     13.4973,      1.3500
      50.6,      0.000,      0.000,         0,     13.5804,      1.3583
      50.5,      0.000,      0.000,         0,     13.6638,      1.3667
      50.2,      0.000,      0.000,         0,     13.7472,      1.3750
      49.4,      0.000,      0.000,         0,     13.8305,      1.3833
       0.0,      0.000,      0.000,         0,     13.9137,      1.3917
       0.0,      0.000,      0.000,         0,     13.9970,      1.4000
       0.0,      0.000,      0.000,         0,     14.0806,      1.4083
       0.0,      0.000,      0.000,         0,     14.1637,      1.4167
       0.0,      0.000,      0.000,         0,     14.2470,      1.4250
       0.0,      0.000,      0.000,         0,     14.3304,      1.4333
       0.0,      0.000,      0.000,         0,     14.4138,      1.4417
       0.0,      0.000,      0.000,         0,     14.4969,      1.4500
       0.0,      0.000,      0.000,         0,     14.5804,      1.4583
       0.0,      0.000,      0.000,         0,     14.6637,      1.4667
       0.0,      0.000,      0.000,         0,     14.7471,      1.4750
       0.0,      0.000,      0.000,         0,     14.8304,      1.4833
       0.0,      0.000,      0.000,         0,     14.9138,      1.4917
       0.0,      0.000,      0.000,         0,     14.9971,      1.5000
       0.0,      0.000,      0.000,         0,     15.0804,      1.5083
       0.0,      0.000,      0.000,         0,     15.1638,      1.5167
       0.0,      0.000,      0.000,         0,     15.2471,      1.5250
       0.0,      0.000,      0.000,         0,     15.3305,      1.5333
       0.0,      0.000,      0.000,         0,     15.4138,      1.5417
       0.0,      0.000,      0.000,         0,     15.4970,      1.5500
       0.0,      0.000,      0.000,         0,     15.5802,      1.5583
       0.0,      0.000,      0.000,         0,     15.6638,      1.5667