File: Alban repo/Quiz 1/suction cup instron tests/oct-dec-2019_raw-data/d30e10-01-inwater-onwhiteplatic-nopump-10mm-test2.raw
Operator: 1

Date,Time,Specimen#
10/25/19,16:54:01,1

---------------------------------------


Area (mm^2):,      1.00,Flat,     25.40,     25.40,     25.40
Gage Len (mm):,     25.40


LOAD (N),STRAIN 1 (mm),STRAIN 2 (mm),STRESS (MPa),POSITION (mm),TIME (min)
       2.5,      0.000,      0.000,         0,      0.0802,      0.0083
       3.1,      0.000,      0.000,         0,      0.1637,      0.0167
       3.3,      0.000,      0.000,         0,      0.2470,      0.0250
       3.4,      0.000,      0.000,         0,      0.3303,      0.0333
       3.9,      0.000,      0.000,         0,      0.4137,      0.0417
       4.1,      0.000,      0.000,         0,      0.4970,      0.0500
       4.8,      0.000,      0.000,         0,      0.5802,      0.0583
       5.4,      0.000,      0.000,         0,      0.6637,      0.0667
       6.1,      0.000,      0.000,         0,      0.7470,      0.0750
       6.7,      0.000,      0.000,         0,      0.8304,      0.0833
       7.4,      0.000,      0.000,         0,      0.9137,      0.0917
       8.1,      0.000,      0.000,         0,      0.9969,      0.1000
       8.7,      0.000,      0.000,         0,      1.0804,      0.1083
       9.3,      0.000,      0.000,         0,      1.1635,      0.1167
       9.9,      0.000,      0.000,         0,      1.2472,      0.1250
      10.5,      0.000,      0.000,         0,      1.3302,      0.1333
      11.1,      0.000,      0.000,         0,      1.4135,      0.1417
      11.7,      0.000,      0.000,         0,      1.4969,      0.1500
      12.2,      0.000,      0.000,         0,      1.5802,      0.1583
      12.8,      0.000,      0.000,         0,      1.6637,      0.1667
      13.3,      0.000,      0.000,         0,      1.7469,      0.1750
      13.9,      0.000,      0.000,         0,      1.8303,      0.1833
      14.4,      0.000,      0.000,         0,      1.9136,      0.1917
      14.9,      0.000,      0.000,         0,      1.9969,      0.2000
      15.4,      0.000,      0.000,         0,      2.0802,      0.2083
      15.9,      0.000,      0.000,         0,      2.1636,      0.2167
      16.4,      0.000,      0.000,         0,      2.2470,      0.2250
      16.8,      0.000,      0.000,         0,      2.3303,      0.2333
      17.3,      0.000,      0.000,         0,      2.4135,      0.2417
      17.7,      0.000,      0.000,         0,      2.4969,      0.2500
      18.1,      0.000,      0.000,         0,      2.5802,      0.2583
      18.5,      0.000,      0.000,         0,      2.6635,      0.2667
      18.9,      0.000,      0.000,         0,      2.7466,      0.2750
      19.3,      0.000,      0.000,         0,      2.8301,      0.2833
      19.7,      0.000,      0.000,         0,      2.9134,      0.2917
      20.1,      0.000,      0.000,         0,      2.9969,      0.3000
      20.4,      0.000,      0.000,         0,      3.0802,      0.3083
      20.8,      0.000,      0.000,         0,      3.1635,      0.3167
      21.1,      0.000,      0.000,         0,      3.2470,      0.3250
      21.5,      0.000,      0.000,         0,      3.3303,      0.3333
      21.8,      0.000,      0.000,         0,      3.4134,      0.3417
      22.2,      0.000,      0.000,         0,      3.4968,      0.3500
      22.5,      0.000,      0.000,         0,      3.5802,      0.3583
      22.8,      0.000,      0.000,         0,      3.6634,      0.3667
      23.1,      0.000,      0.000,         0,      3.7469,      0.3750
      23.4,      0.000,      0.000,         0,      3.8301,      0.3833
      23.7,      0.000,      0.000,         0,      3.9135,      0.3917
      24.0,      0.000,      0.000,         0,      3.9968,      0.4000
      24.3,      0.000,      0.000,         0,      4.0802,      0.4083
      24.6,      0.000,      0.000,         0,      4.1637,      0.4167
      24.9,      0.000,      0.000,         0,      4.2468,      0.4250
      25.2,      0.000,      0.000,         0,      4.3301,      0.4333
      25.5,      0.000,      0.000,         0,      4.4135,      0.4417
      25.8,      0.000,      0.000,         0,      4.4969,      0.4500
      26.1,      0.000,      0.000,         0,      4.5800,      0.4583
      26.4,      0.000,      0.000,         0,      4.6635,      0.4667
      26.7,      0.000,      0.000,         0,      4.7467,      0.4750
      27.0,      0.000,      0.000,         0,      4.8301,      0.4833
      27.3,      0.000,      0.000,         0,      4.9135,      0.4917
      27.5,      0.000,      0.000,         0,      4.9969,      0.5000
      27.8,      0.000,      0.000,         0,      5.0801,      0.5083
      28.1,      0.000,      0.000,         0,      5.1633,      0.5167
      28.4,      0.000,      0.000,         0,      5.2469,      0.5250
      28.6,      0.000,      0.000,         0,      5.3301,      0.5333
      28.9,      0.000,      0.000,         0,      5.4133,      0.5417
      29.2,      0.000,      0.000,         0,      5.4967,      0.5500
      29.5,      0.000,      0.000,         0,      5.5802,      0.5583
      29.7,      0.000,      0.000,         0,      5.6633,      0.5667
      30.0,      0.000,      0.000,         0,      5.7468,      0.5750
      30.3,      0.000,      0.000,         0,      5.8301,      0.5833
      30.6,      0.000,      0.000,         0,      5.9135,      0.5917
      30.8,      0.000,      0.000,         0,      5.9966,      0.6000
      31.1,      0.000,      0.000,         0,      6.0801,      0.6083
      31.4,      0.000,      0.000,         0,      6.1635,      0.6167
      31.7,      0.000,      0.000,         0,      6.2468,      0.6250
      32.0,      0.000,      0.000,         0,      6.3301,      0.6333
      32.2,      0.000,      0.000,         0,      6.4135,      0.6417
      32.5,      0.000,      0.000,         0,      6.4967,      0.6500
      32.8,      0.000,      0.000,         0,      6.5801,      0.6583
      33.1,      0.000,      0.000,         0,      6.6635,      0.6667
      33.4,      0.000,      0.000,         0,      6.7466,      0.6750
      33.7,      0.000,      0.000,         0,      6.8301,      0.6833
      34.0,      0.000,      0.000,         0,      6.9133,      0.6917
      34.2,      0.000,      0.000,         0,      6.9968,      0.7000
      34.5,      0.000,      0.000,         0,      7.0798,      0.7083
      34.8,      0.000,      0.000,         0,      7.1634,      0.7167
      35.1,      0.000,      0.000,         0,      7.2467,      0.7250
      35.4,      0.000,      0.000,         0,      7.3300,      0.7333
      35.7,      0.000,      0.000,         0,      7.4134,      0.7417
      35.9,      0.000,      0.000,         0,      7.4967,      0.7500
      36.2,      0.000,      0.000,         0,      7.5800,      0.7583
      36.4,      0.000,      0.000,         0,      7.6634,      0.7667
      36.7,      0.000,      0.000,         0,      7.7467,      0.7750
      36.9,      0.000,      0.000,         0,      7.8299,      0.7833
      37.2,      0.000,      0.000,         0,      7.9134,      0.7917
      37.5,      0.000,      0.000,         0,      7.9968,      0.8000
      37.7,      0.000,      0.000,         0,      8.0798,      0.8083
      38.0,      0.000,      0.000,         0,      8.1632,      0.8167
      38.3,      0.000,      0.000,         0,      8.2467,      0.8250
      38.5,      0.000,      0.000,         0,      8.3300,      0.8333
      38.8,      0.000,      0.000,         0,      8.4131,      0.8417
      39.0,      0.000,      0.000,         0,      8.4966,      0.8500
      39.3,      0.000,      0.000,         0,      8.5799,      0.8583
      39.5,      0.000,      0.000,         0,      8.6632,      0.8667
      39.8,      0.000,      0.000,         0,      8.7466,      0.8750
      40.1,      0.000,      0.000,         0,      8.8300,      0.8833
      40.3,      0.000,      0.000,         0,      8.9133,      0.8917
      40.6,      0.000,      0.000,         0,      8.9966,      0.9000
      40.8,      0.000,      0.000,         0,      9.0795,      0.9083
      41.1,      0.000,      0.000,         0,      9.1634,      0.9167
      41.3,      0.000,      0.000,         0,      9.2466,      0.9250
      41.5,      0.000,      0.000,         0,      9.3300,      0.9333
      41.8,      0.000,      0.000,         0,      9.4132,      0.9417
      42.0,      0.000,      0.000,         0,      9.4966,      0.9500
      42.3,      0.000,      0.000,         0,      9.5798,      0.9583
      42.5,      0.000,      0.000,         0,      9.6632,      0.9667
      42.7,      0.000,      0.000,         0,      9.7465,      0.9750
      43.0,      0.000,      0.000,         0,      9.8299,      0.9833
      43.2,      0.000,      0.000,         0,      9.9133,      0.9917
      43.5,      0.000,      0.000,         0,      9.9965,      1.0000
      43.7,      0.000,      0.000,         0,     10.0799,      1.0083
      43.9,      0.000,      0.000,         0,     10.1631,      1.0167
      44.2,      0.000,      0.000,         0,     10.2467,      1.0250
      44.4,      0.000,      0.000,         0,     10.3297,      1.0333
      44.6,      0.000,      0.000,         0,     10.4132,      1.0417
      44.8,      0.000,      0.000,         0,     10.4964,      1.0500
      45.1,      0.000,      0.000,         0,     10.5798,      1.0583
      45.3,      0.000,      0.000,         0,     10.6629,      1.0667
      45.5,      0.000,      0.000,         0,     10.7465,      1.0750
      45.8,      0.000,      0.000,         0,     10.8299,      1.0833
      46.0,      0.000,      0.000,         0,     10.9133,      1.0917
      46.2,      0.000,      0.000,         0,     10.9966,      1.1000
      46.5,      0.000,      0.000,         0,     11.0798,      1.1083
      46.7,      0.000,      0.000,         0,     11.1632,      1.1167
      46.9,      0.000,      0.000,         0,     11.2466,      1.1250
      47.2,      0.000,      0.000,         0,     11.3298,      1.1333
      47.4,      0.000,      0.000,         0,     11.4131,      1.1417
      47.6,      0.000,      0.000,         0,     11.4967,      1.1500
      47.8,      0.000,      0.000,         0,     11.5799,      1.1583
      48.0,      0.000,      0.000,         0,     11.6631,      1.1667
      48.2,      0.000,      0.000,         0,     11.7463,      1.1750
      48.5,      0.000,      0.000,         0,     11.8300,      1.1833
      48.7,      0.000,      0.000,         0,     11.9131,      1.1917
      48.9,      0.000,      0.000,         0,     11.9965,      1.2000
      49.1,      0.000,      0.000,         0,     12.0799,      1.2083
      49.3,      0.000,      0.000,         0,     12.1631,      1.2167
      49.6,      0.000,      0.000,         0,     12.2464,      1.2250
      49.8,      0.000,      0.000,         0,     12.3298,      1.2333
      50.0,      0.000,      0.000,         0,     12.4132,      1.2417
      50.2,      0.000,      0.000,         0,     12.4964,      1.2500
      50.4,      0.000,      0.000,         0,     12.5798,      1.2583
      50.6,      0.000,      0.000,         0,     12.6632,      1.2667
      50.8,      0.000,      0.000,         0,     12.7463,      1.2750
      51.0,      0.000,      0.000,         0,     12.8296,      1.2833
      51.2,      0.000,      0.000,         0,     12.9131,      1.2917
      51.3,      0.000,      0.000,         0,     12.9965,      1.3000
      51.5,      0.000,      0.000,         0,     13.0798,      1.3083
      51.7,      0.000,      0.000,         0,     13.1632,      1.3167
      51.9,      0.000,      0.000,         0,     13.2465,      1.3250
      52.0,      0.000,      0.000,         0,     13.3296,      1.3333
      52.1,      0.000,      0.000,         0,     13.4130,      1.3417
      52.2,      0.000,      0.000,         0,     13.4965,      1.3500
      52.2,      0.000,      0.000,         0,     13.5798,      1.3583
      52.2,      0.000,      0.000,         0,     13.6631,      1.3667
      52.0,      0.000,      0.000,         0,     13.7464,      1.3750
      51.5,      0.000,      0.000,         0,     13.8298,      1.3833
      47.9,      0.000,      0.000,         0,     13.9128,      1.3917
       0.0,      0.000,      0.000,         0,     13.9964,      1.4000
       0.0,      0.000,      0.000,         0,     14.0797,      1.4083
       0.0,      0.000,      0.000,         0,     14.1631,      1.4167
       0.0,      0.000,      0.000,         0,     14.2464,      1.4250
       0.0,      0.000,      0.000,         0,     14.3296,      1.4333
       0.0,      0.000,      0.000,         0,     14.4131,      1.4417
       0.0,      0.000,      0.000,         0,     14.4964,      1.4500
       0.0,      0.000,      0.000,         0,     14.5797,      1.4583
       0.0,      0.000,      0.000,         0,     14.6629,      1.4667
       0.0,      0.000,      0.000,         0,     14.7464,      1.4750
       0.0,      0.000,      0.000,         0,     14.8296,      1.4833
       0.0,      0.000,      0.000,         0,     14.9130,      1.4917
       0.0,      0.000,      0.000,         0,     14.9963,      1.5000
       0.0,      0.000,      0.000,         0,     15.0798,      1.5083
       0.0,      0.000,      0.000,         0,     15.1630,      1.5167
       0.0,      0.000,      0.000,         0,     15.2464,      1.5250