File: Alban repo/Quiz 1/suction cup instron tests/oct-dec-2019_raw-data/d30e10-01-inwater-onwhiteplatic-diaphragmpump-10mm-test2.raw
Operator: 1

Date,Time,Specimen#
10/25/19,17:19:12,1

---------------------------------------


Area (mm^2):,      1.00,Flat,     25.40,     25.40,     25.40
Gage Len (mm):,     25.40


LOAD (N),STRAIN 1 (mm),STRAIN 2 (mm),STRESS (MPa),POSITION (mm),TIME (min)
      17.0,      0.000,      0.000,         0,     -0.1630,      0.0083
      20.7,      0.000,      0.000,         0,     -0.3297,      0.0167
      21.0,      0.000,      0.000,         0,     -0.4963,      0.0250
      21.0,      0.000,      0.000,         0,     -0.6630,      0.0333
      20.8,      0.000,      0.000,         0,     -0.8295,      0.0417
      20.4,      0.000,      0.000,         0,     -0.9963,      0.0500
      20.1,      0.000,      0.000,         0,     -1.1628,      0.0583
      19.7,      0.000,      0.000,         0,     -1.3295,      0.0667
      19.3,      0.000,      0.000,         0,     -1.4961,      0.0750
      18.9,      0.000,      0.000,         0,     -1.6630,      0.0833
      18.4,      0.000,      0.000,         0,     -1.8295,      0.0917
      18.0,      0.000,      0.000,         0,     -1.9963,      0.1000
      17.6,      0.000,      0.000,         0,     -2.1629,      0.1083
      17.2,      0.000,      0.000,         0,     -2.3296,      0.1167
      16.7,      0.000,      0.000,         0,     -2.4961,      0.1250
      16.3,      0.000,      0.000,         0,     -2.6629,      0.1333
      15.9,      0.000,      0.000,         0,     -2.8296,      0.1417
      15.4,      0.000,      0.000,         0,     -2.9960,      0.1500
      15.0,      0.000,      0.000,         0,     -3.1628,      0.1583
      14.5,      0.000,      0.000,         0,     -3.3295,      0.1667
      14.0,      0.000,      0.000,         0,     -3.4961,      0.1750
      13.5,      0.000,      0.000,         0,     -3.6628,      0.1833
      13.0,      0.000,      0.000,         0,     -3.8295,      0.1917
      12.5,      0.000,      0.000,         0,     -3.9961,      0.2000
      11.9,      0.000,      0.000,         0,     -4.1629,      0.2083
      11.3,      0.000,      0.000,         0,     -4.3294,      0.2167
      10.7,      0.000,      0.000,         0,     -4.4961,      0.2250
      10.1,      0.000,      0.000,         0,     -4.6628,      0.2333
       9.5,      0.000,      0.000,         0,     -4.8294,      0.2417
       8.8,      0.000,      0.000,         0,     -4.9961,      0.2500
       8.1,      0.000,      0.000,         0,     -5.1628,      0.2583
       7.4,      0.000,      0.000,         0,     -5.3295,      0.2667
       6.7,      0.000,      0.000,         0,     -5.4960,      0.2750
       5.9,      0.000,      0.000,         0,     -5.6627,      0.2833
       5.1,      0.000,      0.000,         0,     -5.8294,      0.2917
       4.2,      0.000,      0.000,         0,     -5.9960,      0.3000
       3.3,      0.000,      0.000,         0,     -6.1627,      0.3083
       2.3,      0.000,      0.000,         0,     -6.3294,      0.3167
       1.1,      0.000,      0.000,         0,     -6.4961,      0.3250
      -0.5,      0.000,      0.000,         0,     -6.6627,      0.3333
      -2.7,      0.000,      0.000,         0,     -6.8293,      0.3417
      -3.8,      0.000,      0.000,         0,     -6.9961,      0.3500
      -6.5,      0.000,      0.000,         0,     -7.1627,      0.3583
      -9.8,      0.000,      0.000,         0,     -7.3292,      0.3667
     -13.3,      0.000,      0.000,         0,     -7.4961,      0.3750
     -14.1,      0.000,      0.000,         0,     -7.6078,      0.3954
     -13.3,      0.000,      0.000,         0,     -7.6078,      0.4121
     -12.8,      0.000,      0.000,         0,     -7.6077,      0.4288
     -12.4,      0.000,      0.000,         0,     -7.6076,      0.4454
     -12.2,      0.000,      0.000,         0,     -7.6075,      0.4621
     -12.0,      0.000,      0.000,         0,     -7.6074,      0.4788
     -11.8,      0.000,      0.000,         0,     -7.6074,      0.4954
     -11.6,      0.000,      0.000,         0,     -7.6074,      0.5121
     -11.5,      0.000,      0.000,         0,     -7.6074,      0.5288
     -11.4,      0.000,      0.000,         0,     -7.5834,      0.5454
     -11.1,      0.000,      0.000,         0,     -7.5755,      0.5621
     -10.9,      0.000,      0.000,         0,     -7.5735,      0.5788
     -10.9,      0.000,      0.000,         0,     -7.5732,      0.5954
     -10.7,      0.000,      0.000,         0,     -7.5713,      0.6121
     -10.7,      0.000,      0.000,         0,     -7.5713,      0.6288
      -8.6,      0.000,      0.000,         0,     -7.5089,      0.6371
      -6.1,      0.000,      0.000,         0,     -7.4246,      0.6454
      -3.7,      0.000,      0.000,         0,     -7.3402,      0.6538
      -1.4,      0.000,      0.000,         0,     -7.2567,      0.6621
       0.8,      0.000,      0.000,         0,     -7.1735,      0.6704
       1.4,      0.000,      0.000,         0,     -7.0900,      0.6788
       1.8,      0.000,      0.000,         0,     -7.0067,      0.6871
       3.6,      0.000,      0.000,         0,     -6.9236,      0.6954
       5.0,      0.000,      0.000,         0,     -6.8401,      0.7038
       6.0,      0.000,      0.000,         0,     -6.7567,      0.7121
       6.9,      0.000,      0.000,         0,     -6.6734,      0.7204
       7.8,      0.000,      0.000,         0,     -6.5901,      0.7288
       8.6,      0.000,      0.000,         0,     -6.5066,      0.7371
       9.3,      0.000,      0.000,         0,     -6.4234,      0.7454
      10.0,      0.000,      0.000,         0,     -6.3402,      0.7538
      10.6,      0.000,      0.000,         0,     -6.2570,      0.7621
      11.2,      0.000,      0.000,         0,     -6.1734,      0.7704
      11.8,      0.000,      0.000,         0,     -6.0902,      0.7788
      12.4,      0.000,      0.000,         0,     -6.0068,      0.7871
      13.0,      0.000,      0.000,         0,     -5.9234,      0.7954
      13.6,      0.000,      0.000,         0,     -5.8401,      0.8038
      14.1,      0.000,      0.000,         0,     -5.7567,      0.8121
      14.6,      0.000,      0.000,         0,     -5.6734,      0.8204
      15.1,      0.000,      0.000,         0,     -5.5902,      0.8288
      15.6,      0.000,      0.000,         0,     -5.5068,      0.8371
      16.1,      0.000,      0.000,         0,     -5.4234,      0.8454
      16.5,      0.000,      0.000,         0,     -5.3401,      0.8538
      17.0,      0.000,      0.000,         0,     -5.2568,      0.8621
      17.4,      0.000,      0.000,         0,     -5.1735,      0.8704
      17.8,      0.000,      0.000,         0,     -5.0901,      0.8788
      18.2,      0.000,      0.000,         0,     -5.0067,      0.8871
      18.6,      0.000,      0.000,         0,     -4.9236,      0.8954
      19.0,      0.000,      0.000,         0,     -4.8400,      0.9038
      19.4,      0.000,      0.000,         0,     -4.7569,      0.9121
      19.7,      0.000,      0.000,         0,     -4.6735,      0.9204
      20.0,      0.000,      0.000,         0,     -4.5902,      0.9288
      20.4,      0.000,      0.000,         0,     -4.5066,      0.9371
      20.7,      0.000,      0.000,         0,     -4.4236,      0.9454
      21.0,      0.000,      0.000,         0,     -4.3401,      0.9538
      21.3,      0.000,      0.000,         0,     -4.2569,      0.9621
      21.6,      0.000,      0.000,         0,     -4.1734,      0.9704
      21.9,      0.000,      0.000,         0,     -4.0903,      0.9788
      22.2,      0.000,      0.000,         0,     -4.0068,      0.9871
      22.4,      0.000,      0.000,         0,     -3.9236,      0.9954
      22.7,      0.000,      0.000,         0,     -3.8403,      1.0038
      22.9,      0.000,      0.000,         0,     -3.7568,      1.0121
      23.2,      0.000,      0.000,         0,     -3.6736,      1.0204
      23.4,      0.000,      0.000,         0,     -3.5902,      1.0288
      23.7,      0.000,      0.000,         0,     -3.5069,      1.0371
      23.9,      0.000,      0.000,         0,     -3.4235,      1.0454
      24.1,      0.000,      0.000,         0,     -3.3403,      1.0538
      24.4,      0.000,      0.000,         0,     -3.2569,      1.0621
      24.6,      0.000,      0.000,         0,     -3.1735,      1.0704
      24.8,      0.000,      0.000,         0,     -3.0902,      1.0788
      25.1,      0.000,      0.000,         0,     -3.0070,      1.0871
      25.3,      0.000,      0.000,         0,     -2.9236,      1.0954
      25.5,      0.000,      0.000,         0,     -2.8404,      1.1038
      25.8,      0.000,      0.000,         0,     -2.7569,      1.1121
      26.0,      0.000,      0.000,         0,     -2.6737,      1.1204
      26.2,      0.000,      0.000,         0,     -2.5903,      1.1288
      26.4,      0.000,      0.000,         0,     -2.5070,      1.1371
      26.6,      0.000,      0.000,         0,     -2.4236,      1.1454
      26.8,      0.000,      0.000,         0,     -2.3402,      1.1538
      27.0,      0.000,      0.000,         0,     -2.2571,      1.1621
      27.2,      0.000,      0.000,         0,     -2.1736,      1.1704
      27.5,      0.000,      0.000,         0,     -2.0903,      1.1788
      27.7,      0.000,      0.000,         0,     -2.0070,      1.1871
      27.9,      0.000,      0.000,         0,     -1.9237,      1.1954
      28.1,      0.000,      0.000,         0,     -1.8402,      1.2038
      28.3,      0.000,      0.000,         0,     -1.7570,      1.2121
      28.6,      0.000,      0.000,         0,     -1.6736,      1.2204
      28.8,      0.000,      0.000,         0,     -1.5904,      1.2288
      29.0,      0.000,      0.000,         0,     -1.5069,      1.2371
      29.3,      0.000,      0.000,         0,     -1.4238,      1.2454
      29.5,      0.000,      0.000,         0,     -1.3404,      1.2538
      29.7,      0.000,      0.000,         0,     -1.2569,      1.2621
      29.9,      0.000,      0.000,         0,     -1.1739,      1.2704
      30.2,      0.000,      0.000,         0,     -1.0904,      1.2788
      30.4,      0.000,      0.000,         0,     -1.0071,      1.2871
      30.6,      0.000,      0.000,         0,     -0.9237,      1.2954
      30.8,      0.000,      0.000,         0,     -0.8405,      1.3038
      31.0,      0.000,      0.000,         0,     -0.7570,      1.3121
      31.2,      0.000,      0.000,         0,     -0.6736,      1.3204
      31.4,      0.000,      0.000,         0,     -0.5904,      1.3288
      31.6,      0.000,      0.000,         0,     -0.5071,      1.3371
      31.8,      0.000,      0.000,         0,     -0.4237,      1.3454
      32.0,      0.000,      0.000,         0,     -0.3404,      1.3538
      32.2,      0.000,      0.000,         0,     -0.2570,      1.3621
      32.4,      0.000,      0.000,         0,     -0.1737,      1.3704
      32.6,      0.000,      0.000,         0,     -0.0903,      1.3788
      32.9,      0.000,      0.000,         0,     -0.0070,      1.3871
      33.1,      0.000,      0.000,         0,      0.0762,      1.3954
      33.4,      0.000,      0.000,         0,      0.1597,      1.4038
      33.6,      0.000,      0.000,         0,      0.2430,      1.4121
      33.8,      0.000,      0.000,         0,      0.3262,      1.4204
      34.0,      0.000,      0.000,         0,      0.4095,      1.4288
      34.3,      0.000,      0.000,         0,      0.4931,      1.4371
      34.5,      0.000,      0.000,         0,      0.5760,      1.4454
      34.7,      0.000,      0.000,         0,      0.6596,      1.4538
      34.9,      0.000,      0.000,         0,      0.7429,      1.4621
      35.2,      0.000,      0.000,         0,      0.8262,      1.4704
      35.4,      0.000,      0.000,         0,      0.9094,      1.4788
      35.6,      0.000,      0.000,         0,      0.9929,      1.4871
      35.9,      0.000,      0.000,         0,      1.0763,      1.4954
      36.1,      0.000,      0.000,         0,      1.1596,      1.5038
      36.3,      0.000,      0.000,         0,      1.2429,      1.5121
      36.6,      0.000,      0.000,         0,      1.3261,      1.5204
      36.8,      0.000,      0.000,         0,      1.4097,      1.5288
      37.1,      0.000,      0.000,         0,      1.4929,      1.5371
      37.3,      0.000,      0.000,         0,      1.5763,      1.5454
      37.6,      0.000,      0.000,         0,      1.6594,      1.5538
      37.9,      0.000,      0.000,         0,      1.7429,      1.5621
      38.1,      0.000,      0.000,         0,      1.8261,      1.5704
      38.4,      0.000,      0.000,         0,      1.9095,      1.5788
      38.6,      0.000,      0.000,         0,      1.9928,      1.5871
      38.9,      0.000,      0.000,         0,      2.0761,      1.5954
      39.1,      0.000,      0.000,         0,      2.1596,      1.6038
      39.4,      0.000,      0.000,         0,      2.2429,      1.6121
      39.6,      0.000,      0.000,         0,      2.3259,      1.6204
      39.9,      0.000,      0.000,         0,      2.4093,      1.6288
      40.1,      0.000,      0.000,         0,      2.4929,      1.6371
      40.4,      0.000,      0.000,         0,      2.5762,      1.6454
      40.6,      0.000,      0.000,         0,      2.6594,      1.6538
      40.7,      0.000,      0.000,         0,      2.7429,      1.6621
      40.9,      0.000,      0.000,         0,      2.8263,      1.6704
      41.1,      0.000,      0.000,         0,      2.9096,      1.6788
      41.3,      0.000,      0.000,         0,      2.9926,      1.6871
      41.5,      0.000,      0.000,         0,      3.0762,      1.6954
      41.7,      0.000,      0.000,         0,      3.1596,      1.7038
      42.0,      0.000,      0.000,         0,      3.2427,      1.7121
      42.2,      0.000,      0.000,         0,      3.3261,      1.7204
      42.4,      0.000,      0.000,         0,      3.4097,      1.7288
      42.6,      0.000,      0.000,         0,      3.4927,      1.7371
      42.8,      0.000,      0.000,         0,      3.5761,      1.7454
      43.0,      0.000,      0.000,         0,      3.6593,      1.7538
      43.2,      0.000,      0.000,         0,      3.7428,      1.7621
      43.5,      0.000,      0.000,         0,      3.8260,      1.7704
      43.7,      0.000,      0.000,         0,      3.9095,      1.7788
      43.9,      0.000,      0.000,         0,      3.9928,      1.7871
      44.1,      0.000,      0.000,         0,      4.0761,      1.7954
      44.3,      0.000,      0.000,         0,      4.1594,      1.8038
      44.5,      0.000,      0.000,         0,      4.2428,      1.8121
      44.8,      0.000,      0.000,         0,      4.3260,      1.8204
      45.0,      0.000,      0.000,         0,      4.4094,      1.8288
      45.2,      0.000,      0.000,         0,      4.4928,      1.8371
      45.4,      0.000,      0.000,         0,      4.5761,      1.8454
      45.6,      0.000,      0.000,         0,      4.6593,      1.8538
      45.8,      0.000,      0.000,         0,      4.7427,      1.8621
      46.0,      0.000,      0.000,         0,      4.8262,      1.8704
      46.2,      0.000,      0.000,         0,      4.9093,      1.8788
      46.4,      0.000,      0.000,         0,      4.9928,      1.8871
      46.5,      0.000,      0.000,         0,      5.0760,      1.8954
      46.7,      0.000,      0.000,         0,      5.1594,      1.9038
      46.8,      0.000,      0.000,         0,      5.2427,      1.9121
      47.0,      0.000,      0.000,         0,      5.3260,      1.9204
      47.0,      0.000,      0.000,         0,      5.4094,      1.9288
      47.1,      0.000,      0.000,         0,      5.4928,      1.9371
      47.1,      0.000,      0.000,         0,      5.5761,      1.9454
      47.0,      0.000,      0.000,         0,      5.6592,      1.9538
      46.9,      0.000,      0.000,         0,      5.7428,      1.9621
      46.7,      0.000,      0.000,         0,      5.8261,      1.9704
      46.4,      0.000,      0.000,         0,      5.9093,      1.9788
      45.8,      0.000,      0.000,         0,      5.9927,      1.9871
       0.0,      0.000,      0.000,         0,      6.0762,      1.9954
       0.0,      0.000,      0.000,         0,      6.1593,      2.0038
       0.0,      0.000,      0.000,         0,      6.2426,      2.0121
       0.0,      0.000,      0.000,         0,      6.3261,      2.0204
       0.0,      0.000,      0.000,         0,      6.4094,      2.0288
       0.0,      0.000,      0.000,         0,      6.4926,      2.0371
       0.0,      0.000,      0.000,         0,      6.5760,      2.0454
       0.0,      0.000,      0.000,         0,      6.6594,      2.0538
       0.0,      0.000,      0.000,         0,      6.7426,      2.0621
       0.0,      0.000,      0.000,         0,      6.8259,      2.0704
       0.0,      0.000,      0.000,         0,      6.9094,      2.0788
       0.0,      0.000,      0.000,         0,      6.9927,      2.0871
       0.0,      0.000,      0.000,         0,      7.0758,      2.0954
       0.0,      0.000,      0.000,         0,      7.1594,      2.1038