File: Alban repo/Quiz 1/suction cup instron tests/oct-dec-2019_raw-data/d30e10-01-inair-on80grit-nopump-100mm-test1.raw
Operator: 1

Date,Time,Specimen#
10/25/19,17:58:32,1

---------------------------------------


Area (mm^2):,      1.00,Flat,     25.40,     25.40,     25.40
Gage Len (mm):,     25.40


LOAD (N),STRAIN 1 (mm),STRAIN 2 (mm),STRESS (MPa),POSITION (mm),TIME (min)
       3.8,      0.000,      0.000,         0,      0.8056,      0.0083
       5.6,      0.000,      0.000,         0,      1.6390,      0.0167
       7.2,      0.000,      0.000,         0,      2.4721,      0.0250
       8.8,      0.000,      0.000,         0,      3.3053,      0.0333
      10.2,      0.000,      0.000,         0,      4.1387,      0.0417
      11.4,      0.000,      0.000,         0,      4.9720,      0.0500
       0.0,      0.000,      0.000,         0,      5.8053,      0.0583
       0.0,      0.000,      0.000,         0,      6.6385,      0.0667
       0.0,      0.000,      0.000,         0,      7.4718,      0.0750
       0.0,      0.000,      0.000,         0,      8.3052,      0.0833
       0.0,      0.000,      0.000,         0,      9.1383,      0.0917
       0.0,      0.000,      0.000,         0,      9.9717,      0.1000
       0.1,      0.000,      0.000,         0,     10.8049,      0.1083
       0.1,      0.000,      0.000,         0,     11.6381,      0.1167
       0.1,      0.000,      0.000,         0,     12.4714,      0.1250