File: Alban repo/Quiz 1/suction cup instron tests/oct-dec-2019_raw-data/d30e10-01-inwater-on80grit-diaphragmpump-10mm-test3.raw
Operator: 1

Date,Time,Specimen#
10/25/19,18:54:21,1

---------------------------------------


Area (mm^2):,      1.00,Flat,     25.40,     25.40,     25.40
Gage Len (mm):,     25.40


LOAD (N),STRAIN 1 (mm),STRAIN 2 (mm),STRESS (MPa),POSITION (mm),TIME (min)
      18.1,      0.000,      0.000,         0,     -0.1618,      0.0083
      20.7,      0.000,      0.000,         0,     -0.3288,      0.0167
      20.9,      0.000,      0.000,         0,     -0.4952,      0.0250
      20.7,      0.000,      0.000,         0,     -0.6620,      0.0333
      20.4,      0.000,      0.000,         0,     -0.8286,      0.0417
      20.0,      0.000,      0.000,         0,     -0.9952,      0.0500
      19.6,      0.000,      0.000,         0,     -1.1618,      0.0583
      19.2,      0.000,      0.000,         0,     -1.3286,      0.0667
      18.8,      0.000,      0.000,         0,     -1.4952,      0.0750
      18.3,      0.000,      0.000,         0,     -1.6620,      0.0833
      17.9,      0.000,      0.000,         0,     -1.8284,      0.0917
      17.5,      0.000,      0.000,         0,     -1.9951,      0.1000
      17.1,      0.000,      0.000,         0,     -2.1617,      0.1083
      16.7,      0.000,      0.000,         0,     -2.3285,      0.1167
      16.3,      0.000,      0.000,         0,     -2.4952,      0.1250
      15.8,      0.000,      0.000,         0,     -2.6619,      0.1333
      15.4,      0.000,      0.000,         0,     -2.8285,      0.1417
      15.0,      0.000,      0.000,         0,     -2.9952,      0.1500
      14.5,      0.000,      0.000,         0,     -3.1616,      0.1583
      14.1,      0.000,      0.000,         0,     -3.3286,      0.1667
      13.6,      0.000,      0.000,         0,     -3.4951,      0.1750
      13.1,      0.000,      0.000,         0,     -3.6618,      0.1833
      12.6,      0.000,      0.000,         0,     -3.8284,      0.1917
      12.0,      0.000,      0.000,         0,     -3.9951,      0.2000
      11.5,      0.000,      0.000,         0,     -4.1617,      0.2083
      10.9,      0.000,      0.000,         0,     -4.3285,      0.2167
      10.4,      0.000,      0.000,         0,     -4.4950,      0.2250
       9.7,      0.000,      0.000,         0,     -4.6618,      0.2333
       9.1,      0.000,      0.000,         0,     -4.8284,      0.2417
       8.4,      0.000,      0.000,         0,     -4.9951,      0.2500
       7.6,      0.000,      0.000,         0,     -5.1618,      0.2583
       6.9,      0.000,      0.000,         0,     -5.3284,      0.2667
       6.0,      0.000,      0.000,         0,     -5.4951,      0.2750
       5.2,      0.000,      0.000,         0,     -5.6618,      0.2833
       4.2,      0.000,      0.000,         0,     -5.8282,      0.2917
       3.2,      0.000,      0.000,         0,     -5.9951,      0.3000
       2.1,      0.000,      0.000,         0,     -6.1616,      0.3083
       0.8,      0.000,      0.000,         0,     -6.3284,      0.3167
      -0.6,      0.000,      0.000,         0,     -6.4950,      0.3250
      -2.4,      0.000,      0.000,         0,     -6.6616,      0.3333
      -4.8,      0.000,      0.000,         0,     -6.8282,      0.3417
      -7.9,      0.000,      0.000,         0,     -6.9950,      0.3500
     -11.7,      0.000,      0.000,         0,     -7.1616,      0.3583
     -15.3,      0.000,      0.000,         0,     -7.3267,      0.3814
     -14.9,      0.000,      0.000,         0,     -7.3267,      0.3981
     -14.7,      0.000,      0.000,         0,     -7.3266,      0.4148
     -14.6,      0.000,      0.000,         0,     -7.3266,      0.4314
     -14.5,      0.000,      0.000,         0,     -7.3265,      0.4481
     -14.4,      0.000,      0.000,         0,     -7.3264,      0.4648
     -14.4,      0.000,      0.000,         0,     -7.3262,      0.4814
     -14.3,      0.000,      0.000,         0,     -7.3260,      0.4981
     -14.2,      0.000,      0.000,         0,     -7.3257,      0.5148
     -14.1,      0.000,      0.000,         0,     -7.2991,      0.5314
     -13.9,      0.000,      0.000,         0,     -7.2934,      0.5481
     -13.9,      0.000,      0.000,         0,     -7.2915,      0.5648
     -13.9,      0.000,      0.000,         0,     -7.2906,      0.5814
     -13.7,      0.000,      0.000,         0,     -7.2894,      0.5981
     -13.6,      0.000,      0.000,         0,     -7.2895,      0.6148
     -11.6,      0.000,      0.000,         0,     -7.2247,      0.6231
      -9.1,      0.000,      0.000,         0,     -7.1410,      0.6314
      -6.8,      0.000,      0.000,         0,     -7.0581,      0.6398
      -4.6,      0.000,      0.000,         0,     -6.9744,      0.6481
      -2.6,      0.000,      0.000,         0,     -6.8893,      0.6564
      -1.0,      0.000,      0.000,         0,     -6.8060,      0.6648
       0.3,      0.000,      0.000,         0,     -6.7225,      0.6731
       1.3,      0.000,      0.000,         0,     -6.6395,      0.6814
       2.3,      0.000,      0.000,         0,     -6.5560,      0.6898
       3.3,      0.000,      0.000,         0,     -6.4725,      0.6981
       4.1,      0.000,      0.000,         0,     -6.3891,      0.7064
       4.9,      0.000,      0.000,         0,     -6.3060,      0.7148
       5.7,      0.000,      0.000,         0,     -6.2226,      0.7231
       6.4,      0.000,      0.000,         0,     -6.1393,      0.7314
       7.0,      0.000,      0.000,         0,     -6.0560,      0.7398
       7.7,      0.000,      0.000,         0,     -5.9727,      0.7481
       8.3,      0.000,      0.000,         0,     -5.8893,      0.7564
       9.0,      0.000,      0.000,         0,     -5.8058,      0.7648
       9.6,      0.000,      0.000,         0,     -5.7227,      0.7731
      10.1,      0.000,      0.000,         0,     -5.6394,      0.7814
      10.7,      0.000,      0.000,         0,     -5.5558,      0.7898
      11.2,      0.000,      0.000,         0,     -5.4726,      0.7981
      11.7,      0.000,      0.000,         0,     -5.3893,      0.8064
      12.2,      0.000,      0.000,         0,     -5.3062,      0.8148
      12.7,      0.000,      0.000,         0,     -5.2225,      0.8231
      13.2,      0.000,      0.000,         0,     -5.1394,      0.8314
      13.6,      0.000,      0.000,         0,     -5.0559,      0.8398
      14.1,      0.000,      0.000,         0,     -4.9726,      0.8481
      14.5,      0.000,      0.000,         0,     -4.8893,      0.8564
      14.9,      0.000,      0.000,         0,     -4.8060,      0.8648
      15.3,      0.000,      0.000,         0,     -4.7227,      0.8731
      15.7,      0.000,      0.000,         0,     -4.6395,      0.8814
      16.0,      0.000,      0.000,         0,     -4.5561,      0.8898
      16.4,      0.000,      0.000,         0,     -4.4725,      0.8981
      16.8,      0.000,      0.000,         0,     -4.3895,      0.9064
      17.1,      0.000,      0.000,         0,     -4.3060,      0.9148
      17.4,      0.000,      0.000,         0,     -4.2227,      0.9231
      17.8,      0.000,      0.000,         0,     -4.1393,      0.9314
      18.1,      0.000,      0.000,         0,     -4.0561,      0.9398
      18.4,      0.000,      0.000,         0,     -3.9726,      0.9481
      18.7,      0.000,      0.000,         0,     -3.8895,      0.9564
      19.0,      0.000,      0.000,         0,     -3.8061,      0.9648
      19.3,      0.000,      0.000,         0,     -3.7230,      0.9731
      19.5,      0.000,      0.000,         0,     -3.6394,      0.9814
      19.8,      0.000,      0.000,         0,     -3.5561,      0.9898
      20.1,      0.000,      0.000,         0,     -3.4727,      0.9981
      20.3,      0.000,      0.000,         0,     -3.3894,      1.0064
      20.6,      0.000,      0.000,         0,     -3.3062,      1.0148
      20.8,      0.000,      0.000,         0,     -3.2227,      1.0231
      21.1,      0.000,      0.000,         0,     -3.1393,      1.0314
      21.3,      0.000,      0.000,         0,     -3.0561,      1.0398
      21.5,      0.000,      0.000,         0,     -2.9728,      1.0481
      21.8,      0.000,      0.000,         0,     -2.8894,      1.0564
      22.0,      0.000,      0.000,         0,     -2.8061,      1.0648
      22.2,      0.000,      0.000,         0,     -2.7228,      1.0731
      22.5,      0.000,      0.000,         0,     -2.6396,      1.0814
      22.6,      0.000,      0.000,         0,     -2.5560,      1.0898
      22.8,      0.000,      0.000,         0,     -2.4727,      1.0981
      23.1,      0.000,      0.000,         0,     -2.3896,      1.1064
      23.3,      0.000,      0.000,         0,     -2.3063,      1.1148
      23.5,      0.000,      0.000,         0,     -2.2228,      1.1231
      23.7,      0.000,      0.000,         0,     -2.1395,      1.1314
      23.9,      0.000,      0.000,         0,     -2.0561,      1.1398
      24.1,      0.000,      0.000,         0,     -1.9728,      1.1481
      24.3,      0.000,      0.000,         0,     -1.8895,      1.1564
      24.6,      0.000,      0.000,         0,     -1.8061,      1.1648
      24.8,      0.000,      0.000,         0,     -1.7228,      1.1731
      25.0,      0.000,      0.000,         0,     -1.6395,      1.1814
      25.2,      0.000,      0.000,         0,     -1.5563,      1.1898
      25.4,      0.000,      0.000,         0,     -1.4727,      1.1981
      25.7,      0.000,      0.000,         0,     -1.3898,      1.2064
      25.9,      0.000,      0.000,         0,     -1.3062,      1.2148
      26.1,      0.000,      0.000,         0,     -1.2228,      1.2231
      26.3,      0.000,      0.000,         0,     -1.1396,      1.2314
      26.6,      0.000,      0.000,         0,     -1.0561,      1.2398
      26.8,      0.000,      0.000,         0,     -0.9728,      1.2481
      27.1,      0.000,      0.000,         0,     -0.8894,      1.2564
      27.3,      0.000,      0.000,         0,     -0.8062,      1.2648
      27.5,      0.000,      0.000,         0,     -0.7228,      1.2731
      27.7,      0.000,      0.000,         0,     -0.6395,      1.2814
      28.0,      0.000,      0.000,         0,     -0.5562,      1.2898
      28.2,      0.000,      0.000,         0,     -0.4730,      1.2981
      28.5,      0.000,      0.000,         0,     -0.3896,      1.3064
      28.7,      0.000,      0.000,         0,     -0.3062,      1.3148
      29.0,      0.000,      0.000,         0,     -0.2229,      1.3231
      29.3,      0.000,      0.000,         0,     -0.1395,      1.3314
      29.5,      0.000,      0.000,         0,     -0.0562,      1.3398
      29.8,      0.000,      0.000,         0,      0.0270,      1.3481
      30.0,      0.000,      0.000,         0,      0.1105,      1.3564
      30.3,      0.000,      0.000,         0,      0.1938,      1.3648
      30.5,      0.000,      0.000,         0,      0.2771,      1.3731
      30.8,      0.000,      0.000,         0,      0.3604,      1.3814
      31.0,      0.000,      0.000,         0,      0.4437,      1.3898
      31.3,      0.000,      0.000,         0,      0.5271,      1.3981
      31.2,      0.000,      0.000,         0,      0.6103,      1.4064
      31.3,      0.000,      0.000,         0,      0.6938,      1.4148
      31.6,      0.000,      0.000,         0,      0.7770,      1.4231
      31.8,      0.000,      0.000,         0,      0.8604,      1.4314
      32.1,      0.000,      0.000,         0,      0.9435,      1.4398
      32.3,      0.000,      0.000,         0,      1.0272,      1.4481
      32.6,      0.000,      0.000,         0,      1.1104,      1.4564
      32.8,      0.000,      0.000,         0,      1.1937,      1.4648
      33.0,      0.000,      0.000,         0,      1.2770,      1.4731
      33.3,      0.000,      0.000,         0,      1.3604,      1.4814
      33.5,      0.000,      0.000,         0,      1.4437,      1.4898
      33.8,      0.000,      0.000,         0,      1.5271,      1.4981
      34.1,      0.000,      0.000,         0,      1.6104,      1.5064
      34.3,      0.000,      0.000,         0,      1.6937,      1.5148
      34.6,      0.000,      0.000,         0,      1.7770,      1.5231
      34.8,      0.000,      0.000,         0,      1.8603,      1.5314
      35.0,      0.000,      0.000,         0,      1.9432,      1.5398
      35.2,      0.000,      0.000,         0,      2.0271,      1.5481
      35.5,      0.000,      0.000,         0,      2.1104,      1.5564
      35.7,      0.000,      0.000,         0,      2.1937,      1.5648
      36.0,      0.000,      0.000,         0,      2.2770,      1.5731
      36.2,      0.000,      0.000,         0,      2.3604,      1.5814
      36.5,      0.000,      0.000,         0,      2.4436,      1.5898
      36.7,      0.000,      0.000,         0,      2.5271,      1.5981
      37.0,      0.000,      0.000,         0,      2.6103,      1.6064
      37.3,      0.000,      0.000,         0,      2.6937,      1.6148
      37.5,      0.000,      0.000,         0,      2.7769,      1.6231
      37.8,      0.000,      0.000,         0,      2.8603,      1.6314
      38.0,      0.000,      0.000,         0,      2.9436,      1.6398
      38.3,      0.000,      0.000,         0,      3.0269,      1.6481
      38.5,      0.000,      0.000,         0,      3.1102,      1.6564
      38.8,      0.000,      0.000,         0,      3.1937,      1.6648
      39.0,      0.000,      0.000,         0,      3.2768,      1.6731
      39.3,      0.000,      0.000,         0,      3.3603,      1.6814
      39.5,      0.000,      0.000,         0,      3.4438,      1.6898
      39.7,      0.000,      0.000,         0,      3.5269,      1.6981
      40.0,      0.000,      0.000,         0,      3.6103,      1.7064
      40.2,      0.000,      0.000,         0,      3.6936,      1.7148
      40.4,      0.000,      0.000,         0,      3.7770,      1.7231
      40.7,      0.000,      0.000,         0,      3.8601,      1.7314
      40.9,      0.000,      0.000,         0,      3.9437,      1.7398
      41.1,      0.000,      0.000,         0,      4.0269,      1.7481
      41.3,      0.000,      0.000,         0,      4.1103,      1.7564
      41.5,      0.000,      0.000,         0,      4.1933,      1.7648
      41.7,      0.000,      0.000,         0,      4.2769,      1.7731
      42.0,      0.000,      0.000,         0,      4.3603,      1.7814
      42.2,      0.000,      0.000,         0,      4.4436,      1.7898
      42.5,      0.000,      0.000,         0,      4.5269,      1.7981
      42.8,      0.000,      0.000,         0,      4.6102,      1.8064
      43.0,      0.000,      0.000,         0,      4.6935,      1.8148
      43.2,      0.000,      0.000,         0,      4.7767,      1.8231
      43.5,      0.000,      0.000,         0,      4.8603,      1.8314
      43.7,      0.000,      0.000,         0,      4.9436,      1.8398
      44.0,      0.000,      0.000,         0,      5.0270,      1.8481
      44.2,      0.000,      0.000,         0,      5.1102,      1.8564
      44.4,      0.000,      0.000,         0,      5.1935,      1.8648
      44.6,      0.000,      0.000,         0,      5.2768,      1.8731
      44.9,      0.000,      0.000,         0,      5.3602,      1.8814
      45.1,      0.000,      0.000,         0,      5.4435,      1.8898
      45.3,      0.000,      0.000,         0,      5.5268,      1.8981
      45.4,      0.000,      0.000,         0,      5.6101,      1.9064
      45.6,      0.000,      0.000,         0,      5.6935,      1.9148
      45.7,      0.000,      0.000,         0,      5.7768,      1.9231
      45.8,      0.000,      0.000,         0,      5.8602,      1.9314
      45.8,      0.000,      0.000,         0,      5.9435,      1.9398
      45.8,      0.000,      0.000,         0,      6.0269,      1.9481
      45.8,      0.000,      0.000,         0,      6.1102,      1.9564
      45.7,      0.000,      0.000,         0,      6.1935,      1.9648
       0.1,      0.000,      0.000,         0,      6.2768,      1.9731
       0.1,      0.000,      0.000,         0,      6.3602,      1.9814
       0.1,      0.000,      0.000,         0,      6.4437,      1.9898
       0.1,      0.000,      0.000,         0,      6.5267,      1.9981
       0.1,      0.000,      0.000,         0,      6.6101,      2.0064
       0.1,      0.000,      0.000,         0,      6.6937,      2.0148
       0.1,      0.000,      0.000,         0,      6.7768,      2.0231
       0.1,      0.000,      0.000,         0,      6.8599,      2.0314
       0.1,      0.000,      0.000,         0,      6.9435,      2.0398
       0.1,      0.000,      0.000,         0,      7.0269,      2.0481