File: Alban repo/Quiz 1/suction cup instron tests/oct-dec-2019_raw-data/d30e10-01-inwater-on36grit-diaphragmpump-100mm-test3.raw
Operator: 1

Date,Time,Specimen#
11/09/19,17:54:20,1

---------------------------------------


Area (mm^2):,      1.00,Flat,     25.40,     25.40,     25.40
Gage Len (mm):,     25.40


LOAD (N),STRAIN 1 (mm),STRAIN 2 (mm),STRESS (MPa),POSITION (mm),TIME (min)
      18.8,      0.000,      0.000,         0,     -0.1620,      0.0083
      20.2,      0.000,      0.000,         0,     -0.3287,      0.0167
      20.1,      0.000,      0.000,         0,     -0.4953,      0.0250
      19.8,      0.000,      0.000,         0,     -0.6620,      0.0333
      19.4,      0.000,      0.000,         0,     -0.8286,      0.0417
      18.9,      0.000,      0.000,         0,     -0.9953,      0.0500
      18.5,      0.000,      0.000,         0,     -1.1619,      0.0583
      18.1,      0.000,      0.000,         0,     -1.3284,      0.0667
      17.6,      0.000,      0.000,         0,     -1.4955,      0.0750
      17.2,      0.000,      0.000,         0,     -1.6619,      0.0833
      16.8,      0.000,      0.000,         0,     -1.8286,      0.0917
      16.3,      0.000,      0.000,         0,     -1.9952,      0.1000
      15.9,      0.000,      0.000,         0,     -2.1619,      0.1083
      15.5,      0.000,      0.000,         0,     -2.3285,      0.1167
      15.0,      0.000,      0.000,         0,     -2.4954,      0.1250
      14.6,      0.000,      0.000,         0,     -2.6619,      0.1333
      14.1,      0.000,      0.000,         0,     -2.8285,      0.1417
      13.7,      0.000,      0.000,         0,     -2.9954,      0.1500
      13.2,      0.000,      0.000,         0,     -3.1618,      0.1583
      12.7,      0.000,      0.000,         0,     -3.3285,      0.1667
      12.2,      0.000,      0.000,         0,     -3.4953,      0.1750
      11.7,      0.000,      0.000,         0,     -3.6618,      0.1833
      11.1,      0.000,      0.000,         0,     -3.8284,      0.1917
      10.5,      0.000,      0.000,         0,     -3.9951,      0.2000
       9.9,      0.000,      0.000,         0,     -4.1620,      0.2083
       9.3,      0.000,      0.000,         0,     -4.3284,      0.2167
       8.6,      0.000,      0.000,         0,     -4.4953,      0.2250
       7.9,      0.000,      0.000,         0,     -4.6617,      0.2333
       7.1,      0.000,      0.000,         0,     -4.8286,      0.2417
       6.4,      0.000,      0.000,         0,     -4.9950,      0.2500
       5.5,      0.000,      0.000,         0,     -5.1619,      0.2583
       4.6,      0.000,      0.000,         0,     -5.3284,      0.2667
       3.6,      0.000,      0.000,         0,     -5.4952,      0.2750
       2.5,      0.000,      0.000,         0,     -5.6617,      0.2833
       1.2,      0.000,      0.000,         0,     -5.8285,      0.2917
      -0.2,      0.000,      0.000,         0,     -5.9950,      0.3000
      -1.9,      0.000,      0.000,         0,     -6.1616,      0.3083
      -3.9,      0.000,      0.000,         0,     -6.3285,      0.3167
      -6.3,      0.000,      0.000,         0,     -6.4951,      0.3250
      -9.0,      0.000,      0.000,         0,     -6.6616,      0.3333
     -11.9,      0.000,      0.000,         0,     -6.8285,      0.3417
     -14.9,      0.000,      0.000,         0,     -6.9951,      0.3500
     -14.2,      0.000,      0.000,         0,     -7.0399,      0.3670
     -13.4,      0.000,      0.000,         0,     -7.0399,      0.3837
     -12.9,      0.000,      0.000,         0,     -7.0399,      0.4004
     -12.5,      0.000,      0.000,         0,     -7.0397,      0.4170
     -12.2,      0.000,      0.000,         0,     -7.0397,      0.4337
     -12.0,      0.000,      0.000,         0,     -7.0397,      0.4504
     -11.8,      0.000,      0.000,         0,     -7.0395,      0.4670
     -11.6,      0.000,      0.000,         0,     -7.0393,      0.4837
     -11.4,      0.000,      0.000,         0,     -7.0391,      0.5004
     -11.2,      0.000,      0.000,         0,     -7.0129,      0.5170
     -11.0,      0.000,      0.000,         0,     -7.0046,      0.5337
     -10.9,      0.000,      0.000,         0,     -7.0038,      0.5504
     -10.8,      0.000,      0.000,         0,     -7.0021,      0.5670
     -10.7,      0.000,      0.000,         0,     -7.0021,      0.5837
     -10.6,      0.000,      0.000,         0,     -7.0023,      0.6004
       2.7,      0.000,      0.000,         0,     -6.3347,      0.6087
      11.1,      0.000,      0.000,         0,     -5.5004,      0.6170
      16.7,      0.000,      0.000,         0,     -4.6662,      0.6254
      20.6,      0.000,      0.000,         0,     -3.8323,      0.6337
      23.5,      0.000,      0.000,         0,     -2.9975,      0.6420
      25.9,      0.000,      0.000,         0,     -2.1642,      0.6504
      28.3,      0.000,      0.000,         0,     -1.3309,      0.6587
      30.9,      0.000,      0.000,         0,     -0.4978,      0.6670
      33.1,      0.000,      0.000,         0,      0.3356,      0.6754
      35.6,      0.000,      0.000,         0,      1.1689,      0.6837
      38.1,      0.000,      0.000,         0,      2.0022,      0.6920
      40.8,      0.000,      0.000,         0,      2.8355,      0.7004
      43.4,      0.000,      0.000,         0,      3.6688,      0.7087
      45.9,      0.000,      0.000,         0,      4.5021,      0.7170
      48.3,      0.000,      0.000,         0,      5.3353,      0.7254
      50.6,      0.000,      0.000,         0,      6.1686,      0.7337
      52.8,      0.000,      0.000,         0,      7.0017,      0.7420
      54.7,      0.000,      0.000,         0,      7.8352,      0.7504
      55.7,      0.000,      0.000,         0,      8.6685,      0.7587
       0.1,      0.000,      0.000,         0,      9.5017,      0.7670
       0.1,      0.000,      0.000,         0,     10.3348,      0.7754
       0.1,      0.000,      0.000,         0,     11.1683,      0.7837
       0.1,      0.000,      0.000,         0,     12.0016,      0.7920
       0.1,      0.000,      0.000,         0,     12.8347,      0.8004
       0.2,      0.000,      0.000,         0,     13.6682,      0.8087
       0.2,      0.000,      0.000,         0,     14.5014,      0.8170