File: Alban repo/Quiz 1/suction cup instron tests/oct-dec-2019_raw-data/d30e10-01-inair-onwhiteplatic-diaphragmpump-10mm-test1.raw
Operator: 1

Date,Time,Specimen#
10/25/19,16:14:22,1

---------------------------------------


Area (mm^2):,      1.00,Flat,     25.40,     25.40,     25.40
Gage Len (mm):,     25.40


LOAD (N),STRAIN 1 (mm),STRAIN 2 (mm),STRESS (MPa),POSITION (mm),TIME (min)
      14.2,      0.000,      0.000,         0,     -0.1647,      0.0083
      14.1,      0.000,      0.000,         0,     -0.3316,      0.0167
      13.7,      0.000,      0.000,         0,     -0.4982,      0.0250
      13.3,      0.000,      0.000,         0,     -0.6649,      0.0333
      12.9,      0.000,      0.000,         0,     -0.8316,      0.0417
      12.4,      0.000,      0.000,         0,     -0.9983,      0.0500
      11.9,      0.000,      0.000,         0,     -1.1650,      0.0583
      11.5,      0.000,      0.000,         0,     -1.3317,      0.0667
      11.1,      0.000,      0.000,         0,     -1.4982,      0.0750
      10.7,      0.000,      0.000,         0,     -1.6649,      0.0833
      10.3,      0.000,      0.000,         0,     -1.8316,      0.0917
       9.9,      0.000,      0.000,         0,     -1.9982,      0.1000
       9.5,      0.000,      0.000,         0,     -2.1649,      0.1083
       9.1,      0.000,      0.000,         0,     -2.3314,      0.1167
       8.7,      0.000,      0.000,         0,     -2.4981,      0.1250
       8.3,      0.000,      0.000,         0,     -2.6650,      0.1333
       7.9,      0.000,      0.000,         0,     -2.8314,      0.1417
       7.5,      0.000,      0.000,         0,     -2.9981,      0.1500
       7.1,      0.000,      0.000,         0,     -3.1647,      0.1583
       6.6,      0.000,      0.000,         0,     -3.3315,      0.1667
       6.2,      0.000,      0.000,         0,     -3.4982,      0.1750
       5.8,      0.000,      0.000,         0,     -3.6647,      0.1833
       5.4,      0.000,      0.000,         0,     -3.8315,      0.1917
       4.9,      0.000,      0.000,         0,     -3.9983,      0.2000
       4.5,      0.000,      0.000,         0,     -4.1648,      0.2083
       4.0,      0.000,      0.000,         0,     -4.3314,      0.2167
       3.4,      0.000,      0.000,         0,     -4.4981,      0.2250
       2.9,      0.000,      0.000,         0,     -4.6647,      0.2333
       2.4,      0.000,      0.000,         0,     -4.8314,      0.2417
       1.7,      0.000,      0.000,         0,     -4.9980,      0.2500
       1.1,      0.000,      0.000,         0,     -5.1646,      0.2583
       0.4,      0.000,      0.000,         0,     -5.3313,      0.2667
      -0.3,      0.000,      0.000,         0,     -5.4981,      0.2750
      -1.1,      0.000,      0.000,         0,     -5.6648,      0.2833
      -2.0,      0.000,      0.000,         0,     -5.8314,      0.2917
      -2.8,      0.000,      0.000,         0,     -5.9981,      0.3000
      -3.7,      0.000,      0.000,         0,     -6.1647,      0.3083
      -4.2,      0.000,      0.000,         0,     -6.3314,      0.3167
      -5.1,      0.000,      0.000,         0,     -6.4980,      0.3250
      -6.3,      0.000,      0.000,         0,     -6.6647,      0.3333
      -7.9,      0.000,      0.000,         0,     -6.8315,      0.3417
     -11.0,      0.000,      0.000,         0,     -6.9979,      0.3500
     -14.9,      0.000,      0.000,         0,     -7.1646,      0.3583
     -15.5,      0.000,      0.000,         0,     -7.2051,      0.3751
     -15.2,      0.000,      0.000,         0,     -7.2051,      0.3918
     -15.0,      0.000,      0.000,         0,     -7.2051,      0.4084
     -14.9,      0.000,      0.000,         0,     -7.2051,      0.4251
     -14.8,      0.000,      0.000,         0,     -7.2050,      0.4418
     -14.7,      0.000,      0.000,         0,     -7.2049,      0.4584
     -14.7,      0.000,      0.000,         0,     -7.2048,      0.4751
     -14.6,      0.000,      0.000,         0,     -7.2046,      0.4918
     -14.6,      0.000,      0.000,         0,     -7.2045,      0.5084
     -14.5,      0.000,      0.000,         0,     -7.1763,      0.5251
     -14.2,      0.000,      0.000,         0,     -7.1690,      0.5418
     -14.1,      0.000,      0.000,         0,     -7.1673,      0.5584
     -14.0,      0.000,      0.000,         0,     -7.1654,      0.5751
     -14.0,      0.000,      0.000,         0,     -7.1654,      0.5918
     -14.0,      0.000,      0.000,         0,     -7.1655,      0.6084
     -12.1,      0.000,      0.000,         0,     -7.1032,      0.6168
      -9.9,      0.000,      0.000,         0,     -7.0195,      0.6251
      -8.1,      0.000,      0.000,         0,     -6.9365,      0.6334
      -6.5,      0.000,      0.000,         0,     -6.8525,      0.6418
      -5.1,      0.000,      0.000,         0,     -6.7674,      0.6501
      -3.8,      0.000,      0.000,         0,     -6.6841,      0.6584
      -3.1,      0.000,      0.000,         0,     -6.6010,      0.6668
      -2.6,      0.000,      0.000,         0,     -6.5175,      0.6751
      -2.2,      0.000,      0.000,         0,     -6.4341,      0.6834
      -1.7,      0.000,      0.000,         0,     -6.3510,      0.6918
      -1.2,      0.000,      0.000,         0,     -6.2675,      0.7001
      -0.7,      0.000,      0.000,         0,     -6.1844,      0.7084
      -0.3,      0.000,      0.000,         0,     -6.1009,      0.7168
       0.2,      0.000,      0.000,         0,     -6.0178,      0.7251
       0.6,      0.000,      0.000,         0,     -5.9342,      0.7334
       1.0,      0.000,      0.000,         0,     -5.8509,      0.7418
       1.5,      0.000,      0.000,         0,     -5.7675,      0.7501
       1.6,      0.000,      0.000,         0,     -5.6842,      0.7584
       1.8,      0.000,      0.000,         0,     -5.6010,      0.7668
       2.2,      0.000,      0.000,         0,     -5.5177,      0.7751
       2.6,      0.000,      0.000,         0,     -5.4342,      0.7834
       3.0,      0.000,      0.000,         0,     -5.3509,      0.7918
       3.4,      0.000,      0.000,         0,     -5.2676,      0.8001
       3.8,      0.000,      0.000,         0,     -5.1842,      0.8084
       4.1,      0.000,      0.000,         0,     -5.1010,      0.8168
       4.5,      0.000,      0.000,         0,     -5.0175,      0.8251
       4.8,      0.000,      0.000,         0,     -4.9345,      0.8334
       5.1,      0.000,      0.000,         0,     -4.8509,      0.8418
       5.4,      0.000,      0.000,         0,     -4.7677,      0.8501
       5.7,      0.000,      0.000,         0,     -4.6842,      0.8584
       6.0,      0.000,      0.000,         0,     -4.6010,      0.8668
       6.3,      0.000,      0.000,         0,     -4.5177,      0.8751
       6.6,      0.000,      0.000,         0,     -4.4343,      0.8834
       6.8,      0.000,      0.000,         0,     -4.3508,      0.8918
       7.1,      0.000,      0.000,         0,     -4.2676,      0.9001
       7.3,      0.000,      0.000,         0,     -4.1843,      0.9084
       7.5,      0.000,      0.000,         0,     -4.1008,      0.9168
       7.7,      0.000,      0.000,         0,     -4.0176,      0.9251
       7.9,      0.000,      0.000,         0,     -3.9344,      0.9334
       8.1,      0.000,      0.000,         0,     -3.8511,      0.9418
       8.3,      0.000,      0.000,         0,     -3.7675,      0.9501
       8.5,      0.000,      0.000,         0,     -3.6843,      0.9584
       8.7,      0.000,      0.000,         0,     -3.6011,      0.9668
       9.0,      0.000,      0.000,         0,     -3.5176,      0.9751
       9.2,      0.000,      0.000,         0,     -3.4343,      0.9834
       9.3,      0.000,      0.000,         0,     -3.3511,      0.9918
       9.5,      0.000,      0.000,         0,     -3.2676,      1.0001
       9.8,      0.000,      0.000,         0,     -3.1842,      1.0084
      10.1,      0.000,      0.000,         0,     -3.1011,      1.0168
      10.3,      0.000,      0.000,         0,     -3.0175,      1.0251
      10.4,      0.000,      0.000,         0,     -2.9343,      1.0334
      10.6,      0.000,      0.000,         0,     -2.8509,      1.0418
      10.8,      0.000,      0.000,         0,     -2.7677,      1.0501
      11.0,      0.000,      0.000,         0,     -2.6843,      1.0584
      11.1,      0.000,      0.000,         0,     -2.6011,      1.0668
      11.3,      0.000,      0.000,         0,     -2.5178,      1.0751
      11.5,      0.000,      0.000,         0,     -2.4344,      1.0834
      11.6,      0.000,      0.000,         0,     -2.3510,      1.0918
      11.8,      0.000,      0.000,         0,     -2.2679,      1.1001
      12.0,      0.000,      0.000,         0,     -2.1844,      1.1084
      12.2,      0.000,      0.000,         0,     -2.1009,      1.1168
      12.3,      0.000,      0.000,         0,     -2.0177,      1.1251
      12.5,      0.000,      0.000,         0,     -1.9343,      1.1334
      12.6,      0.000,      0.000,         0,     -1.8510,      1.1418
      12.8,      0.000,      0.000,         0,     -1.7676,      1.1501
      13.0,      0.000,      0.000,         0,     -1.6846,      1.1584
      13.2,      0.000,      0.000,         0,     -1.6011,      1.1668
      13.4,      0.000,      0.000,         0,     -1.5177,      1.1751
      13.5,      0.000,      0.000,         0,     -1.4344,      1.1834
      13.7,      0.000,      0.000,         0,     -1.3512,      1.1918
      13.8,      0.000,      0.000,         0,     -1.2678,      1.2001
      14.0,      0.000,      0.000,         0,     -1.1843,      1.2084
      14.2,      0.000,      0.000,         0,     -1.1010,      1.2168
      14.3,      0.000,      0.000,         0,     -1.0178,      1.2251
      14.5,      0.000,      0.000,         0,     -0.9344,      1.2334
      14.7,      0.000,      0.000,         0,     -0.8511,      1.2418
      14.9,      0.000,      0.000,         0,     -0.7679,      1.2501
      15.1,      0.000,      0.000,         0,     -0.6845,      1.2584
      15.2,      0.000,      0.000,         0,     -0.6011,      1.2668
      15.4,      0.000,      0.000,         0,     -0.5178,      1.2751
      15.6,      0.000,      0.000,         0,     -0.4345,      1.2834
      15.8,      0.000,      0.000,         0,     -0.3511,      1.2918
      16.0,      0.000,      0.000,         0,     -0.2680,      1.3001
      16.1,      0.000,      0.000,         0,     -0.1844,      1.3084
      16.3,      0.000,      0.000,         0,     -0.1013,      1.3168
      16.5,      0.000,      0.000,         0,     -0.0178,      1.3251
      16.7,      0.000,      0.000,         0,      0.0656,      1.3334
      16.8,      0.000,      0.000,         0,      0.1487,      1.3418
      17.0,      0.000,      0.000,         0,      0.2321,      1.3501
      17.1,      0.000,      0.000,         0,      0.3156,      1.3584
      17.3,      0.000,      0.000,         0,      0.3988,      1.3668
      17.4,      0.000,      0.000,         0,      0.4820,      1.3751
      17.6,      0.000,      0.000,         0,      0.5656,      1.3834
      17.7,      0.000,      0.000,         0,      0.6488,      1.3918
      17.9,      0.000,      0.000,         0,      0.7321,      1.4001
      18.0,      0.000,      0.000,         0,      0.8155,      1.4084
      18.2,      0.000,      0.000,         0,      0.8989,      1.4168
      18.4,      0.000,      0.000,         0,      0.9820,      1.4251
      18.5,      0.000,      0.000,         0,      1.0653,      1.4334
      18.7,      0.000,      0.000,         0,      1.1489,      1.4418
      18.8,      0.000,      0.000,         0,      1.2322,      1.4501
      19.0,      0.000,      0.000,         0,      1.3154,      1.4584
      19.1,      0.000,      0.000,         0,      1.3988,      1.4668
      19.3,      0.000,      0.000,         0,      1.4823,      1.4751
      19.4,      0.000,      0.000,         0,      1.5653,      1.4834
      19.6,      0.000,      0.000,         0,      1.6488,      1.4918
      19.7,      0.000,      0.000,         0,      1.7321,      1.5001
      19.9,      0.000,      0.000,         0,      1.8156,      1.5084
      20.1,      0.000,      0.000,         0,      1.8985,      1.5168
      20.2,      0.000,      0.000,         0,      1.9820,      1.5251
      20.4,      0.000,      0.000,         0,      2.0654,      1.5334
      20.5,      0.000,      0.000,         0,      2.1487,      1.5418
      20.7,      0.000,      0.000,         0,      2.2321,      1.5501
      20.8,      0.000,      0.000,         0,      2.3153,      1.5584
      20.9,      0.000,      0.000,         0,      2.3987,      1.5668
      21.1,      0.000,      0.000,         0,      2.4820,      1.5751
      21.2,      0.000,      0.000,         0,      2.5654,      1.5834
      21.3,      0.000,      0.000,         0,      2.6487,      1.5918
      21.5,      0.000,      0.000,         0,      2.7321,      1.6001
      21.6,      0.000,      0.000,         0,      2.8153,      1.6084
      21.7,      0.000,      0.000,         0,      2.8988,      1.6168
      21.8,      0.000,      0.000,         0,      2.9817,      1.6251
      21.9,      0.000,      0.000,         0,      3.0654,      1.6334
      22.0,      0.000,      0.000,         0,      3.1486,      1.6418
      22.0,      0.000,      0.000,         0,      3.2322,      1.6501
      22.1,      0.000,      0.000,         0,      3.3154,      1.6584
      22.2,      0.000,      0.000,         0,      3.3986,      1.6668
      22.3,      0.000,      0.000,         0,      3.4820,      1.6751
      22.3,      0.000,      0.000,         0,      3.5655,      1.6834
      22.4,      0.000,      0.000,         0,      3.6486,      1.6918
      22.5,      0.000,      0.000,         0,      3.7319,      1.7001
      22.5,      0.000,      0.000,         0,      3.8154,      1.7084
      22.6,      0.000,      0.000,         0,      3.8986,      1.7168
      22.7,      0.000,      0.000,         0,      3.9819,      1.7251
      22.7,      0.000,      0.000,         0,      4.0652,      1.7334
      22.8,      0.000,      0.000,         0,      4.1488,      1.7418
      22.8,      0.000,      0.000,         0,      4.2320,      1.7501
      22.8,      0.000,      0.000,         0,      4.3152,      1.7584
      22.8,      0.000,      0.000,         0,      4.3988,      1.7668
      22.9,      0.000,      0.000,         0,      4.4821,      1.7751
      22.9,      0.000,      0.000,         0,      4.5652,      1.7834
      22.9,      0.000,      0.000,         0,      4.6487,      1.7918
      22.9,      0.000,      0.000,         0,      4.7322,      1.8001
       2.0,      0.000,      0.000,         0,      4.8153,      1.8084
       0.0,      0.000,      0.000,         0,      4.8986,      1.8168
       0.0,      0.000,      0.000,         0,      4.9821,      1.8251
       0.0,      0.000,      0.000,         0,      5.0654,      1.8334
       0.0,      0.000,      0.000,         0,      5.1485,      1.8418
       0.0,      0.000,      0.000,         0,      5.2321,      1.8501
       0.0,      0.000,      0.000,         0,      5.3153,      1.8584
       0.0,      0.000,      0.000,         0,      5.3986,      1.8668
       0.0,      0.000,      0.000,         0,      5.4818,      1.8751
       0.0,      0.000,      0.000,         0,      5.5654,      1.8834
       0.0,      0.000,      0.000,         0,      5.6486,      1.8918
       0.0,      0.000,      0.000,         0,      5.7319,      1.9001
       0.0,      0.000,      0.000,         0,      5.8153,      1.9084
       0.0,      0.000,      0.000,         0,      5.8986,      1.9168
       0.0,      0.000,      0.000,         0,      5.9820,      1.9251
       0.0,      0.000,      0.000,         0,      6.0652,      1.9334
       0.0,      0.000,      0.000,         0,      6.1488,      1.9418
       0.0,      0.000,      0.000,         0,      6.2319,      1.9501
       0.0,      0.000,      0.000,         0,      6.3152,      1.9584
       0.0,      0.000,      0.000,         0,      6.3984,      1.9668
       0.0,      0.000,      0.000,         0,      6.4821,      1.9751
       0.0,      0.000,      0.000,         0,      6.5650,      1.9834
       0.0,      0.000,      0.000,         0,      6.6486,      1.9918