File: Alban repo/Quiz 1/suction cup instron tests/oct-dec-2019_raw-data/d30e10-01-inwater-onwhiteplatic-diaphragmpump-10mm-test1.raw
Operator: 1

Date,Time,Specimen#
10/25/19,17:02:39,1

---------------------------------------


Area (mm^2):,      1.00,Flat,     25.40,     25.40,     25.40
Gage Len (mm):,     25.40


LOAD (N),STRAIN 1 (mm),STRAIN 2 (mm),STRESS (MPa),POSITION (mm),TIME (min)
      18.1,      0.000,      0.000,         0,     -0.1620,      0.0083
      21.5,      0.000,      0.000,         0,     -0.3287,      0.0167
      21.7,      0.000,      0.000,         0,     -0.4953,      0.0250
      21.5,      0.000,      0.000,         0,     -0.6621,      0.0333
      21.2,      0.000,      0.000,         0,     -0.8286,      0.0417
      20.8,      0.000,      0.000,         0,     -0.9955,      0.0500
      20.4,      0.000,      0.000,         0,     -1.1621,      0.0583
      20.0,      0.000,      0.000,         0,     -1.3286,      0.0667
      19.6,      0.000,      0.000,         0,     -1.4954,      0.0750
      19.2,      0.000,      0.000,         0,     -1.6619,      0.0833
      18.8,      0.000,      0.000,         0,     -1.8287,      0.0917
      18.3,      0.000,      0.000,         0,     -1.9954,      0.1000
      17.9,      0.000,      0.000,         0,     -2.1618,      0.1083
      17.5,      0.000,      0.000,         0,     -2.3287,      0.1167
      17.1,      0.000,      0.000,         0,     -2.4953,      0.1250
      16.6,      0.000,      0.000,         0,     -2.6619,      0.1333
      16.2,      0.000,      0.000,         0,     -2.8286,      0.1417
      15.7,      0.000,      0.000,         0,     -2.9953,      0.1500
      15.3,      0.000,      0.000,         0,     -3.1619,      0.1583
      14.8,      0.000,      0.000,         0,     -3.3286,      0.1667
      14.3,      0.000,      0.000,         0,     -3.4953,      0.1750
      13.8,      0.000,      0.000,         0,     -3.6620,      0.1833
      13.3,      0.000,      0.000,         0,     -3.8286,      0.1917
      12.8,      0.000,      0.000,         0,     -3.9952,      0.2000
      12.2,      0.000,      0.000,         0,     -4.1619,      0.2083
      11.6,      0.000,      0.000,         0,     -4.3286,      0.2167
      11.0,      0.000,      0.000,         0,     -4.4953,      0.2250
      10.4,      0.000,      0.000,         0,     -4.6617,      0.2333
       9.8,      0.000,      0.000,         0,     -4.8284,      0.2417
       9.2,      0.000,      0.000,         0,     -4.9950,      0.2500
       8.5,      0.000,      0.000,         0,     -5.1618,      0.2583
       7.8,      0.000,      0.000,         0,     -5.3286,      0.2667
       7.1,      0.000,      0.000,         0,     -5.4950,      0.2750
       6.4,      0.000,      0.000,         0,     -5.6618,      0.2833
       5.6,      0.000,      0.000,         0,     -5.8285,      0.2917
       4.8,      0.000,      0.000,         0,     -5.9951,      0.3000
       3.9,      0.000,      0.000,         0,     -6.1620,      0.3083
       3.0,      0.000,      0.000,         0,     -6.3283,      0.3167
       1.8,      0.000,      0.000,         0,     -6.4950,      0.3250
       0.3,      0.000,      0.000,         0,     -6.6617,      0.3333
      -2.0,      0.000,      0.000,         0,     -6.8285,      0.3417
      -3.9,      0.000,      0.000,         0,     -6.9950,      0.3500
      -5.4,      0.000,      0.000,         0,     -7.1617,      0.3583
      -8.5,      0.000,      0.000,         0,     -7.3282,      0.3667
     -11.8,      0.000,      0.000,         0,     -7.4951,      0.3750
     -14.1,      0.000,      0.000,         0,     -7.6759,      0.3989
     -13.3,      0.000,      0.000,         0,     -7.6759,      0.4155
     -12.9,      0.000,      0.000,         0,     -7.6759,      0.4322
     -12.6,      0.000,      0.000,         0,     -7.6758,      0.4489
     -12.3,      0.000,      0.000,         0,     -7.6757,      0.4655
     -12.2,      0.000,      0.000,         0,     -7.6757,      0.4822
     -12.0,      0.000,      0.000,         0,     -7.6756,      0.4989
     -11.9,      0.000,      0.000,         0,     -7.6755,      0.5155
     -11.8,      0.000,      0.000,         0,     -7.6754,      0.5322
     -11.6,      0.000,      0.000,         0,     -7.6500,      0.5489
     -11.4,      0.000,      0.000,         0,     -7.6432,      0.5655
     -11.2,      0.000,      0.000,         0,     -7.6412,      0.5822
     -11.2,      0.000,      0.000,         0,     -7.6402,      0.5989
     -11.1,      0.000,      0.000,         0,     -7.6393,      0.6155
     -11.1,      0.000,      0.000,         0,     -7.6394,      0.6322
      -8.9,      0.000,      0.000,         0,     -7.5770,      0.6405
      -6.3,      0.000,      0.000,         0,     -7.4933,      0.6489
      -3.9,      0.000,      0.000,         0,     -7.4081,      0.6572
      -1.7,      0.000,      0.000,         0,     -7.3247,      0.6655
       0.4,      0.000,      0.000,         0,     -7.2414,      0.6739
       1.3,      0.000,      0.000,         0,     -7.1581,      0.6822
       1.5,      0.000,      0.000,         0,     -7.0749,      0.6905
       3.3,      0.000,      0.000,         0,     -6.9914,      0.6989
       5.0,      0.000,      0.000,         0,     -6.9082,      0.7072
       6.2,      0.000,      0.000,         0,     -6.8247,      0.7155
       7.2,      0.000,      0.000,         0,     -6.7414,      0.7239
       8.1,      0.000,      0.000,         0,     -6.6582,      0.7322
       9.0,      0.000,      0.000,         0,     -6.5748,      0.7405
       9.8,      0.000,      0.000,         0,     -6.4915,      0.7489
      10.5,      0.000,      0.000,         0,     -6.4079,      0.7572
      11.2,      0.000,      0.000,         0,     -6.3250,      0.7655
      11.9,      0.000,      0.000,         0,     -6.2415,      0.7739
      12.5,      0.000,      0.000,         0,     -6.1581,      0.7822
      13.2,      0.000,      0.000,         0,     -6.0747,      0.7905
      13.8,      0.000,      0.000,         0,     -5.9917,      0.7989
      14.4,      0.000,      0.000,         0,     -5.9082,      0.8072
      14.9,      0.000,      0.000,         0,     -5.8248,      0.8155
      15.5,      0.000,      0.000,         0,     -5.7414,      0.8239
      16.0,      0.000,      0.000,         0,     -5.6581,      0.8322
      16.5,      0.000,      0.000,         0,     -5.5749,      0.8405
      17.0,      0.000,      0.000,         0,     -5.4913,      0.8489
      17.5,      0.000,      0.000,         0,     -5.4082,      0.8572
      18.0,      0.000,      0.000,         0,     -5.3249,      0.8655
      18.4,      0.000,      0.000,         0,     -5.2415,      0.8739
      18.8,      0.000,      0.000,         0,     -5.1581,      0.8822
      19.2,      0.000,      0.000,         0,     -5.0748,      0.8905
      19.7,      0.000,      0.000,         0,     -4.9915,      0.8989
      20.0,      0.000,      0.000,         0,     -4.9083,      0.9072
      20.4,      0.000,      0.000,         0,     -4.8247,      0.9155
      20.8,      0.000,      0.000,         0,     -4.7416,      0.9239
      21.1,      0.000,      0.000,         0,     -4.6582,      0.9322
      21.5,      0.000,      0.000,         0,     -4.5750,      0.9405
      21.8,      0.000,      0.000,         0,     -4.4916,      0.9489
      22.1,      0.000,      0.000,         0,     -4.4082,      0.9572
      22.4,      0.000,      0.000,         0,     -4.3249,      0.9655
      22.7,      0.000,      0.000,         0,     -4.2414,      0.9739
      23.0,      0.000,      0.000,         0,     -4.1583,      0.9822
      23.3,      0.000,      0.000,         0,     -4.0748,      0.9905
      23.5,      0.000,      0.000,         0,     -3.9915,      0.9989
      23.8,      0.000,      0.000,         0,     -3.9084,      1.0072
      24.0,      0.000,      0.000,         0,     -3.8249,      1.0155
      24.3,      0.000,      0.000,         0,     -3.7415,      1.0239
      24.5,      0.000,      0.000,         0,     -3.6582,      1.0322
      24.8,      0.000,      0.000,         0,     -3.5751,      1.0405
      25.0,      0.000,      0.000,         0,     -3.4915,      1.0489
      25.3,      0.000,      0.000,         0,     -3.4081,      1.0572
      25.5,      0.000,      0.000,         0,     -3.3255,      1.0655
      25.7,      0.000,      0.000,         0,     -3.2416,      1.0739
      25.9,      0.000,      0.000,         0,     -3.1581,      1.0822
      26.2,      0.000,      0.000,         0,     -3.0751,      1.0905
      26.4,      0.000,      0.000,         0,     -2.9916,      1.0989
      26.6,      0.000,      0.000,         0,     -2.9083,      1.1072
      26.8,      0.000,      0.000,         0,     -2.8248,      1.1155
      27.0,      0.000,      0.000,         0,     -2.7420,      1.1239
      27.2,      0.000,      0.000,         0,     -2.6584,      1.1322
      27.4,      0.000,      0.000,         0,     -2.5748,      1.1405
      27.7,      0.000,      0.000,         0,     -2.4917,      1.1489
      27.9,      0.000,      0.000,         0,     -2.4084,      1.1572
      28.1,      0.000,      0.000,         0,     -2.3250,      1.1655
      28.3,      0.000,      0.000,         0,     -2.2415,      1.1739
      28.5,      0.000,      0.000,         0,     -2.1583,      1.1822
      28.7,      0.000,      0.000,         0,     -2.0751,      1.1905
      28.9,      0.000,      0.000,         0,     -1.9916,      1.1989
      29.2,      0.000,      0.000,         0,     -1.9082,      1.2072
      29.4,      0.000,      0.000,         0,     -1.8250,      1.2155
      29.6,      0.000,      0.000,         0,     -1.7417,      1.2239
      29.9,      0.000,      0.000,         0,     -1.6584,      1.2322
      30.1,      0.000,      0.000,         0,     -1.5749,      1.2405
      30.3,      0.000,      0.000,         0,     -1.4917,      1.2489
      30.5,      0.000,      0.000,         0,     -1.4083,      1.2572
      30.8,      0.000,      0.000,         0,     -1.3252,      1.2655
      31.0,      0.000,      0.000,         0,     -1.2416,      1.2739
      31.2,      0.000,      0.000,         0,     -1.1583,      1.2822
      31.4,      0.000,      0.000,         0,     -1.0749,      1.2905
      31.6,      0.000,      0.000,         0,     -0.9918,      1.2989
      31.8,      0.000,      0.000,         0,     -0.9085,      1.3072
      32.1,      0.000,      0.000,         0,     -0.8250,      1.3155
      32.3,      0.000,      0.000,         0,     -0.7416,      1.3239
      32.5,      0.000,      0.000,         0,     -0.6583,      1.3322
      32.7,      0.000,      0.000,         0,     -0.5750,      1.3405
      32.9,      0.000,      0.000,         0,     -0.4916,      1.3489
      33.2,      0.000,      0.000,         0,     -0.4083,      1.3572
      33.4,      0.000,      0.000,         0,     -0.3250,      1.3655
      33.6,      0.000,      0.000,         0,     -0.2417,      1.3739
      33.8,      0.000,      0.000,         0,     -0.1584,      1.3822
      34.0,      0.000,      0.000,         0,     -0.0751,      1.3905
      34.2,      0.000,      0.000,         0,      0.0082,      1.3989
      34.5,      0.000,      0.000,         0,      0.0917,      1.4072
      34.7,      0.000,      0.000,         0,      0.1749,      1.4155
      34.9,      0.000,      0.000,         0,      0.2582,      1.4239
      35.2,      0.000,      0.000,         0,      0.3416,      1.4322
      35.4,      0.000,      0.000,         0,      0.4251,      1.4405
      35.6,      0.000,      0.000,         0,      0.5082,      1.4489
      35.9,      0.000,      0.000,         0,      0.5917,      1.4572
      36.1,      0.000,      0.000,         0,      0.6750,      1.4655
      36.3,      0.000,      0.000,         0,      0.7583,      1.4739
      36.6,      0.000,      0.000,         0,      0.8414,      1.4822
      36.8,      0.000,      0.000,         0,      0.9249,      1.4905
      37.0,      0.000,      0.000,         0,      1.0081,      1.4989
      37.2,      0.000,      0.000,         0,      1.0916,      1.5072
      37.5,      0.000,      0.000,         0,      1.1749,      1.5155
      37.7,      0.000,      0.000,         0,      1.2582,      1.5239
      38.0,      0.000,      0.000,         0,      1.3415,      1.5322
      38.2,      0.000,      0.000,         0,      1.4248,      1.5405
      38.5,      0.000,      0.000,         0,      1.5083,      1.5489
      38.7,      0.000,      0.000,         0,      1.5914,      1.5572
      38.9,      0.000,      0.000,         0,      1.6748,      1.5655
      39.2,      0.000,      0.000,         0,      1.7580,      1.5739
      39.4,      0.000,      0.000,         0,      1.8417,      1.5822
      39.7,      0.000,      0.000,         0,      1.9246,      1.5905
      39.9,      0.000,      0.000,         0,      2.0082,      1.5989
      40.2,      0.000,      0.000,         0,      2.0915,      1.6072
      40.4,      0.000,      0.000,         0,      2.1749,      1.6155
      40.6,      0.000,      0.000,         0,      2.2581,      1.6239
      40.9,      0.000,      0.000,         0,      2.3411,      1.6322
      41.1,      0.000,      0.000,         0,      2.4249,      1.6405
      41.3,      0.000,      0.000,         0,      2.5082,      1.6489
      41.6,      0.000,      0.000,         0,      2.5914,      1.6572
      41.8,      0.000,      0.000,         0,      2.6748,      1.6655
      42.0,      0.000,      0.000,         0,      2.7583,      1.6739
      42.3,      0.000,      0.000,         0,      2.8415,      1.6822
      42.5,      0.000,      0.000,         0,      2.9248,      1.6905
      42.7,      0.000,      0.000,         0,      3.0080,      1.6989
      42.8,      0.000,      0.000,         0,      3.0915,      1.7072
      43.0,      0.000,      0.000,         0,      3.1747,      1.7155
      43.2,      0.000,      0.000,         0,      3.2580,      1.7239
      43.4,      0.000,      0.000,         0,      3.3414,      1.7322
      43.6,      0.000,      0.000,         0,      3.4247,      1.7405
      43.9,      0.000,      0.000,         0,      3.5080,      1.7489
      44.1,      0.000,      0.000,         0,      3.5915,      1.7572
      44.3,      0.000,      0.000,         0,      3.6747,      1.7655
      44.4,      0.000,      0.000,         0,      3.7579,      1.7739
      44.6,      0.000,      0.000,         0,      3.8414,      1.7822
      44.9,      0.000,      0.000,         0,      3.9248,      1.7905
      45.1,      0.000,      0.000,         0,      4.0081,      1.7989
      45.3,      0.000,      0.000,         0,      4.0913,      1.8072
      45.5,      0.000,      0.000,         0,      4.1749,      1.8155
      45.8,      0.000,      0.000,         0,      4.2581,      1.8239
      46.0,      0.000,      0.000,         0,      4.3412,      1.8322
      46.2,      0.000,      0.000,         0,      4.4248,      1.8405
      46.4,      0.000,      0.000,         0,      4.5081,      1.8489
      46.6,      0.000,      0.000,         0,      4.5913,      1.8572
      46.8,      0.000,      0.000,         0,      4.6747,      1.8655
      47.0,      0.000,      0.000,         0,      4.7582,      1.8739
      47.1,      0.000,      0.000,         0,      4.8413,      1.8822
      47.3,      0.000,      0.000,         0,      4.9247,      1.8905
      47.5,      0.000,      0.000,         0,      5.0080,      1.8989
      47.7,      0.000,      0.000,         0,      5.0915,      1.9072
      47.8,      0.000,      0.000,         0,      5.1744,      1.9155
      48.0,      0.000,      0.000,         0,      5.2581,      1.9239
      48.1,      0.000,      0.000,         0,      5.3413,      1.9322
      48.2,      0.000,      0.000,         0,      5.4248,      1.9405
      48.3,      0.000,      0.000,         0,      5.5081,      1.9489
      48.4,      0.000,      0.000,         0,      5.5913,      1.9572
      48.4,      0.000,      0.000,         0,      5.6746,      1.9655
      48.4,      0.000,      0.000,         0,      5.7581,      1.9739
      48.3,      0.000,      0.000,         0,      5.8415,      1.9822
      48.1,      0.000,      0.000,         0,      5.9247,      1.9905
      47.8,      0.000,      0.000,         0,      6.0079,      1.9989
      47.4,      0.000,      0.000,         0,      6.0912,      2.0072
       0.0,      0.000,      0.000,         0,      6.1748,      2.0155
       0.0,      0.000,      0.000,         0,      6.2579,      2.0239
       0.0,      0.000,      0.000,         0,      6.3414,      2.0322
       0.0,      0.000,      0.000,         0,      6.4247,      2.0405
       0.0,      0.000,      0.000,         0,      6.5079,      2.0489
       0.0,      0.000,      0.000,         0,      6.5911,      2.0572
       0.0,      0.000,      0.000,         0,      6.6747,      2.0655
       0.0,      0.000,      0.000,         0,      6.7579,      2.0739
       0.0,      0.000,      0.000,         0,      6.8413,      2.0822
       0.0,      0.000,      0.000,         0,      6.9246,      2.0905
       0.0,      0.000,      0.000,         0,      7.0080,      2.0989
       0.0,      0.000,      0.000,         0,      7.0913,      2.1072
       0.0,      0.000,      0.000,         0,      7.1747,      2.1155
       0.0,      0.000,      0.000,         0,      7.2579,      2.1239
       0.0,      0.000,      0.000,         0,      7.3413,      2.1322
       0.0,      0.000,      0.000,         0,      7.4247,      2.1405
       0.0,      0.000,      0.000,         0,      7.5078,      2.1489
       0.0,      0.000,      0.000,         0,      7.5911,      2.1572
       0.0,      0.000,      0.000,         0,      7.6745,      2.1655
       0.0,      0.000,      0.000,         0,      7.7580,      2.1739