File: Alban repo/Quiz 1/suction cup instron tests/oct-dec-2019_raw-data/d30e10-01-inair-on80grit-diaphragmpump-10mm-test2.raw
Operator: 1

Date,Time,Specimen#
10/25/19,18:18:08,1

---------------------------------------


Area (mm^2):,      1.00,Flat,     25.40,     25.40,     25.40
Gage Len (mm):,     25.40


LOAD (N),STRAIN 1 (mm),STRAIN 2 (mm),STRESS (MPa),POSITION (mm),TIME (min)
      13.2,      0.000,      0.000,         0,     -0.1621,      0.0083
      12.9,      0.000,      0.000,         0,     -0.3290,      0.0167
      12.5,      0.000,      0.000,         0,     -0.4955,      0.0250
      12.1,      0.000,      0.000,         0,     -0.6622,      0.0333
      11.7,      0.000,      0.000,         0,     -0.8288,      0.0417
      11.3,      0.000,      0.000,         0,     -0.9955,      0.0500
      10.9,      0.000,      0.000,         0,     -1.1622,      0.0583
      10.6,      0.000,      0.000,         0,     -1.3289,      0.0667
      10.2,      0.000,      0.000,         0,     -1.4955,      0.0750
       9.8,      0.000,      0.000,         0,     -1.6622,      0.0833
       9.4,      0.000,      0.000,         0,     -1.8288,      0.0917
       9.0,      0.000,      0.000,         0,     -1.9955,      0.1000
       8.6,      0.000,      0.000,         0,     -2.1621,      0.1083
       8.2,      0.000,      0.000,         0,     -2.3288,      0.1167
       7.9,      0.000,      0.000,         0,     -2.4956,      0.1250
       7.5,      0.000,      0.000,         0,     -2.6619,      0.1333
       7.1,      0.000,      0.000,         0,     -2.8288,      0.1417
       6.7,      0.000,      0.000,         0,     -2.9955,      0.1500
       6.3,      0.000,      0.000,         0,     -3.1621,      0.1583
       5.9,      0.000,      0.000,         0,     -3.3288,      0.1667
       5.4,      0.000,      0.000,         0,     -3.4953,      0.1750
       5.0,      0.000,      0.000,         0,     -3.6623,      0.1833
       4.6,      0.000,      0.000,         0,     -3.8288,      0.1917
       4.1,      0.000,      0.000,         0,     -3.9954,      0.2000
       3.6,      0.000,      0.000,         0,     -4.1621,      0.2083
       3.2,      0.000,      0.000,         0,     -4.3287,      0.2167
       2.7,      0.000,      0.000,         0,     -4.4954,      0.2250
       2.2,      0.000,      0.000,         0,     -4.6619,      0.2333
       1.6,      0.000,      0.000,         0,     -4.8285,      0.2417
       1.0,      0.000,      0.000,         0,     -4.9953,      0.2500
       0.4,      0.000,      0.000,         0,     -5.1620,      0.2583
      -0.2,      0.000,      0.000,         0,     -5.3287,      0.2667
      -0.9,      0.000,      0.000,         0,     -5.4953,      0.2750
      -1.6,      0.000,      0.000,         0,     -5.6621,      0.2833
      -2.4,      0.000,      0.000,         0,     -5.8287,      0.2917
      -3.1,      0.000,      0.000,         0,     -5.9954,      0.3000
      -4.0,      0.000,      0.000,         0,     -6.1619,      0.3083
      -5.0,      0.000,      0.000,         0,     -6.3286,      0.3167
      -6.1,      0.000,      0.000,         0,     -6.4952,      0.3250
      -7.3,      0.000,      0.000,         0,     -6.6620,      0.3333
      -9.0,      0.000,      0.000,         0,     -6.8285,      0.3417
     -11.3,      0.000,      0.000,         0,     -6.9952,      0.3500
     -14.6,      0.000,      0.000,         0,     -7.1620,      0.3583
     -15.5,      0.000,      0.000,         0,     -7.2157,      0.3760
     -15.3,      0.000,      0.000,         0,     -7.2157,      0.3926
     -15.2,      0.000,      0.000,         0,     -7.2157,      0.4093
     -15.1,      0.000,      0.000,         0,     -7.2156,      0.4260
     -15.0,      0.000,      0.000,         0,     -7.2155,      0.4426
     -15.0,      0.000,      0.000,         0,     -7.2155,      0.4593
     -14.9,      0.000,      0.000,         0,     -7.2154,      0.4760
     -14.9,      0.000,      0.000,         0,     -7.2153,      0.4926
     -14.8,      0.000,      0.000,         0,     -7.2151,      0.5093
     -14.8,      0.000,      0.000,         0,     -7.1909,      0.5260
     -14.6,      0.000,      0.000,         0,     -7.1830,      0.5426
     -14.6,      0.000,      0.000,         0,     -7.1828,      0.5593
     -14.5,      0.000,      0.000,         0,     -7.1814,      0.5760
     -14.5,      0.000,      0.000,         0,     -7.1809,      0.5926
     -14.5,      0.000,      0.000,         0,     -7.1810,      0.6093
     -12.8,      0.000,      0.000,         0,     -7.1186,      0.6176
     -10.9,      0.000,      0.000,         0,     -7.0351,      0.6260
      -9.3,      0.000,      0.000,         0,     -6.9514,      0.6343
      -8.0,      0.000,      0.000,         0,     -6.8666,      0.6426
      -6.9,      0.000,      0.000,         0,     -6.7832,      0.6510
      -6.1,      0.000,      0.000,         0,     -6.6998,      0.6593
      -5.4,      0.000,      0.000,         0,     -6.6163,      0.6676
      -4.8,      0.000,      0.000,         0,     -6.5329,      0.6760
      -4.3,      0.000,      0.000,         0,     -6.4498,      0.6843
      -3.8,      0.000,      0.000,         0,     -6.3663,      0.6926
      -3.3,      0.000,      0.000,         0,     -6.2828,      0.7010
      -2.8,      0.000,      0.000,         0,     -6.1996,      0.7093
      -2.3,      0.000,      0.000,         0,     -6.1166,      0.7176
      -1.9,      0.000,      0.000,         0,     -6.0332,      0.7260
      -1.4,      0.000,      0.000,         0,     -5.9496,      0.7343
      -1.0,      0.000,      0.000,         0,     -5.8664,      0.7426
      -0.6,      0.000,      0.000,         0,     -5.7832,      0.7510
      -0.2,      0.000,      0.000,         0,     -5.6997,      0.7593
       0.1,      0.000,      0.000,         0,     -5.6165,      0.7676
       0.5,      0.000,      0.000,         0,     -5.5331,      0.7760
       0.8,      0.000,      0.000,         0,     -5.4498,      0.7843
       1.2,      0.000,      0.000,         0,     -5.3663,      0.7926
       1.5,      0.000,      0.000,         0,     -5.2830,      0.8010
       1.8,      0.000,      0.000,         0,     -5.1998,      0.8093
       2.1,      0.000,      0.000,         0,     -5.1165,      0.8176
       2.4,      0.000,      0.000,         0,     -5.0331,      0.8260
       2.7,      0.000,      0.000,         0,     -4.9498,      0.8343
       3.0,      0.000,      0.000,         0,     -4.8664,      0.8426
       3.3,      0.000,      0.000,         0,     -4.7831,      0.8510
       3.5,      0.000,      0.000,         0,     -4.6998,      0.8593
       3.8,      0.000,      0.000,         0,     -4.6163,      0.8676
       4.0,      0.000,      0.000,         0,     -4.5331,      0.8760
       4.3,      0.000,      0.000,         0,     -4.4498,      0.8843
       4.5,      0.000,      0.000,         0,     -4.3664,      0.8926
       4.8,      0.000,      0.000,         0,     -4.2830,      0.9010
       5.0,      0.000,      0.000,         0,     -4.1999,      0.9093
       5.2,      0.000,      0.000,         0,     -4.1164,      0.9176
       5.4,      0.000,      0.000,         0,     -4.0333,      0.9260
       5.7,      0.000,      0.000,         0,     -3.9498,      0.9343
       5.9,      0.000,      0.000,         0,     -3.8664,      0.9426
       6.1,      0.000,      0.000,         0,     -3.7832,      0.9510
       6.3,      0.000,      0.000,         0,     -3.7000,      0.9593
       6.5,      0.000,      0.000,         0,     -3.6164,      0.9676
       6.7,      0.000,      0.000,         0,     -3.5330,      0.9760
       6.9,      0.000,      0.000,         0,     -3.4498,      0.9843
       7.1,      0.000,      0.000,         0,     -3.3665,      0.9926
       7.3,      0.000,      0.000,         0,     -3.2832,      1.0010
       7.5,      0.000,      0.000,         0,     -3.1998,      1.0093
       7.7,      0.000,      0.000,         0,     -3.1168,      1.0176
       7.9,      0.000,      0.000,         0,     -3.0330,      1.0260
       8.1,      0.000,      0.000,         0,     -2.9498,      1.0343
       8.3,      0.000,      0.000,         0,     -2.8665,      1.0426
       8.4,      0.000,      0.000,         0,     -2.7834,      1.0510
       8.6,      0.000,      0.000,         0,     -2.6998,      1.0593
       8.8,      0.000,      0.000,         0,     -2.6165,      1.0676
       9.0,      0.000,      0.000,         0,     -2.5332,      1.0760
       9.1,      0.000,      0.000,         0,     -2.4499,      1.0843
       9.3,      0.000,      0.000,         0,     -2.3665,      1.0926
       9.5,      0.000,      0.000,         0,     -2.2832,      1.1010
       9.7,      0.000,      0.000,         0,     -2.1998,      1.1093
       9.9,      0.000,      0.000,         0,     -2.1165,      1.1176
      10.0,      0.000,      0.000,         0,     -2.0333,      1.1260
      10.2,      0.000,      0.000,         0,     -1.9498,      1.1343
      10.4,      0.000,      0.000,         0,     -1.8665,      1.1426
      10.5,      0.000,      0.000,         0,     -1.7832,      1.1510
      10.7,      0.000,      0.000,         0,     -1.6999,      1.1593
      10.9,      0.000,      0.000,         0,     -1.6165,      1.1676
      11.1,      0.000,      0.000,         0,     -1.5331,      1.1760
      11.2,      0.000,      0.000,         0,     -1.4500,      1.1843
      11.4,      0.000,      0.000,         0,     -1.3666,      1.1926
      11.6,      0.000,      0.000,         0,     -1.2833,      1.2010
      11.7,      0.000,      0.000,         0,     -1.1999,      1.2093
      11.9,      0.000,      0.000,         0,     -1.1167,      1.2176
      12.1,      0.000,      0.000,         0,     -1.0332,      1.2260
      12.2,      0.000,      0.000,         0,     -0.9499,      1.2343
      12.4,      0.000,      0.000,         0,     -0.8666,      1.2426
      12.6,      0.000,      0.000,         0,     -0.7834,      1.2510
      12.7,      0.000,      0.000,         0,     -0.6999,      1.2593
      12.9,      0.000,      0.000,         0,     -0.6166,      1.2676
      13.1,      0.000,      0.000,         0,     -0.5333,      1.2760
      13.2,      0.000,      0.000,         0,     -0.4499,      1.2843
      13.4,      0.000,      0.000,         0,     -0.3665,      1.2926
      13.5,      0.000,      0.000,         0,     -0.2832,      1.3010
      13.7,      0.000,      0.000,         0,     -0.2001,      1.3093
      13.9,      0.000,      0.000,         0,     -0.1166,      1.3176
      14.0,      0.000,      0.000,         0,     -0.0332,      1.3260
      14.2,      0.000,      0.000,         0,      0.0500,      1.3343
      14.4,      0.000,      0.000,         0,      0.1333,      1.3426
      14.5,      0.000,      0.000,         0,      0.2168,      1.3510
      14.7,      0.000,      0.000,         0,      0.3001,      1.3593
      14.9,      0.000,      0.000,         0,      0.3833,      1.3676
      15.0,      0.000,      0.000,         0,      0.4665,      1.3760
      15.2,      0.000,      0.000,         0,      0.5498,      1.3843
      15.3,      0.000,      0.000,         0,      0.6334,      1.3926
      15.5,      0.000,      0.000,         0,      0.7166,      1.4010
      15.7,      0.000,      0.000,         0,      0.8000,      1.4093
      15.8,      0.000,      0.000,         0,      0.8834,      1.4176
      16.0,      0.000,      0.000,         0,      0.9666,      1.4260
      16.1,      0.000,      0.000,         0,      1.0500,      1.4343
      16.3,      0.000,      0.000,         0,      1.1333,      1.4426
      16.4,      0.000,      0.000,         0,      1.2166,      1.4510
      16.6,      0.000,      0.000,         0,      1.3000,      1.4593
      16.7,      0.000,      0.000,         0,      1.3833,      1.4676
      16.9,      0.000,      0.000,         0,      1.4667,      1.4760
      17.0,      0.000,      0.000,         0,      1.5498,      1.4843
      17.1,      0.000,      0.000,         0,      1.6334,      1.4926
      17.3,      0.000,      0.000,         0,      1.7167,      1.5010
      17.4,      0.000,      0.000,         0,      1.8000,      1.5093
      17.5,      0.000,      0.000,         0,      1.8832,      1.5176
      17.7,      0.000,      0.000,         0,      1.9666,      1.5260
      17.8,      0.000,      0.000,         0,      2.0498,      1.5343
      18.0,      0.000,      0.000,         0,      2.1333,      1.5426
      18.1,      0.000,      0.000,         0,      2.2166,      1.5510
      18.2,      0.000,      0.000,         0,      2.3001,      1.5593
      18.4,      0.000,      0.000,         0,      2.3833,      1.5676
      18.5,      0.000,      0.000,         0,      2.4665,      1.5760
      18.6,      0.000,      0.000,         0,      2.5498,      1.5843
      18.7,      0.000,      0.000,         0,      2.6333,      1.5926
      18.9,      0.000,      0.000,         0,      2.7167,      1.6010
      19.0,      0.000,      0.000,         0,      2.7999,      1.6093
      19.1,      0.000,      0.000,         0,      2.8834,      1.6176
      19.2,      0.000,      0.000,         0,      2.9666,      1.6260
      19.3,      0.000,      0.000,         0,      3.0499,      1.6343
      19.4,      0.000,      0.000,         0,      3.1331,      1.6426
      19.5,      0.000,      0.000,         0,      3.2165,      1.6510
      19.6,      0.000,      0.000,         0,      3.2999,      1.6593
      19.7,      0.000,      0.000,         0,      3.3832,      1.6676
      19.8,      0.000,      0.000,         0,      3.4666,      1.6760
      19.9,      0.000,      0.000,         0,      3.5499,      1.6843
      20.0,      0.000,      0.000,         0,      3.6333,      1.6926
      20.1,      0.000,      0.000,         0,      3.7166,      1.7010
      20.1,      0.000,      0.000,         0,      3.8000,      1.7093
      20.2,      0.000,      0.000,         0,      3.8831,      1.7176
      20.3,      0.000,      0.000,         0,      3.9666,      1.7260
      20.4,      0.000,      0.000,         0,      4.0497,      1.7343
      20.5,      0.000,      0.000,         0,      4.1331,      1.7426
      20.6,      0.000,      0.000,         0,      4.2165,      1.7510
      20.7,      0.000,      0.000,         0,      4.2999,      1.7593
      20.8,      0.000,      0.000,         0,      4.3833,      1.7676
      20.9,      0.000,      0.000,         0,      4.4663,      1.7760
      21.1,      0.000,      0.000,         0,      4.5498,      1.7843
      21.2,      0.000,      0.000,         0,      4.6333,      1.7926
       0.1,      0.000,      0.000,         0,      4.7165,      1.8010
       0.0,      0.000,      0.000,         0,      4.7998,      1.8093
       0.0,      0.000,      0.000,         0,      4.8833,      1.8176
       0.0,      0.000,      0.000,         0,      4.9666,      1.8260
       0.0,      0.000,      0.000,         0,      5.0498,      1.8343
       0.0,      0.000,      0.000,         0,      5.1331,      1.8426
       0.0,      0.000,      0.000,         0,      5.2164,      1.8510
       0.0,      0.000,      0.000,         0,      5.2998,      1.8593