File: Alban repo/Quiz 1/suction cup instron tests/oct-dec-2019_raw-data/d30e10-01-inwater-on36grit-nopump-100mm-test3.raw
Operator: 1

Date,Time,Specimen#
11/09/19,17:47:24,1

---------------------------------------


Area (mm^2):,      1.00,Flat,     25.40,     25.40,     25.40
Gage Len (mm):,     25.40


LOAD (N),STRAIN 1 (mm),STRAIN 2 (mm),STRESS (MPa),POSITION (mm),TIME (min)
       9.6,      0.000,      0.000,         0,      0.8098,      0.0083
      16.4,      0.000,      0.000,         0,      1.6431,      0.0167
      21.5,      0.000,      0.000,         0,      2.4787,      0.0250
      25.7,      0.000,      0.000,         0,      3.3118,      0.0333
      29.3,      0.000,      0.000,         0,      4.1453,      0.0417
      32.6,      0.000,      0.000,         0,      4.9784,      0.0500
      35.7,      0.000,      0.000,         0,      5.8117,      0.0583
      38.9,      0.000,      0.000,         0,      6.6449,      0.0667
      42.0,      0.000,      0.000,         0,      7.4784,      0.0750
      45.1,      0.000,      0.000,         0,      8.3115,      0.0833
      48.0,      0.000,      0.000,         0,      9.1448,      0.0917
      50.8,      0.000,      0.000,         0,      9.9781,      0.1000
      53.5,      0.000,      0.000,         0,     10.8114,      0.1083
      56.0,      0.000,      0.000,         0,     11.6446,      0.1167
      58.3,      0.000,      0.000,         0,     12.4779,      0.1250
      60.5,      0.000,      0.000,         0,     13.3112,      0.1333
      62.1,      0.000,      0.000,         0,     14.1445,      0.1417
      63.5,      0.000,      0.000,         0,     14.9778,      0.1500
      65.1,      0.000,      0.000,         0,     15.8109,      0.1583
      41.5,      0.000,      0.000,         0,     16.6443,      0.1667
       0.1,      0.000,      0.000,         0,     17.4776,      0.1750
       0.1,      0.000,      0.000,         0,     18.3109,      0.1833
       0.2,      0.000,      0.000,         0,     19.1440,      0.1917
       0.2,      0.000,      0.000,         0,     19.9775,      0.2000