File: Alban repo/Quiz 1/suction cup instron tests/oct-dec-2019_raw-data/d30e10-01-inair-onwhiteplatic-nopump-10mm-test1.raw
Operator: 1

Date,Time,Specimen#
10/25/19,16:10:43,1

---------------------------------------


Area (mm^2):,      1.00,Flat,     25.40,     25.40,     25.40
Gage Len (mm):,     25.40


LOAD (N),STRAIN 1 (mm),STRAIN 2 (mm),STRESS (MPa),POSITION (mm),TIME (min)
       2.1,      0.000,      0.000,         0,      0.0825,      0.0083
       2.2,      0.000,      0.000,         0,      0.1656,      0.0167
       2.2,      0.000,      0.000,         0,      0.2491,      0.0250
       2.3,      0.000,      0.000,         0,      0.3323,      0.0333
       2.4,      0.000,      0.000,         0,      0.4159,      0.0417
       2.5,      0.000,      0.000,         0,      0.4991,      0.0500
       2.5,      0.000,      0.000,         0,      0.5824,      0.0583
       2.6,      0.000,      0.000,         0,      0.6657,      0.0667
       2.6,      0.000,      0.000,         0,      0.7492,      0.0750
       2.7,      0.000,      0.000,         0,      0.8325,      0.0833
       2.7,      0.000,      0.000,         0,      0.9155,      0.0917
       2.7,      0.000,      0.000,         0,      0.9991,      0.1000
       2.7,      0.000,      0.000,         0,      1.0824,      0.1083
       2.6,      0.000,      0.000,         0,      1.1657,      0.1167
       2.4,      0.000,      0.000,         0,      1.2490,      0.1250
       2.0,      0.000,      0.000,         0,      1.3325,      0.1333
       0.0,      0.000,      0.000,         0,      1.4155,      0.1417
       0.0,      0.000,      0.000,         0,      1.4990,      0.1500
       0.0,      0.000,      0.000,         0,      1.5823,      0.1583
       0.0,      0.000,      0.000,         0,      1.6656,      0.1667
       0.0,      0.000,      0.000,         0,      1.7491,      0.1750
       0.0,      0.000,      0.000,         0,      1.8325,      0.1833
       0.0,      0.000,      0.000,         0,      1.9157,      0.1917
       0.0,      0.000,      0.000,         0,      1.9989,      0.2000
       0.0,      0.000,      0.000,         0,      2.0824,      0.2083
       0.0,      0.000,      0.000,         0,      2.1659,      0.2167
       0.0,      0.000,      0.000,         0,      2.2491,      0.2250
       0.0,      0.000,      0.000,         0,      2.3322,      0.2333
       0.0,      0.000,      0.000,         0,      2.4158,      0.2417
       0.0,      0.000,      0.000,         0,      2.4990,      0.2500
       0.0,      0.000,      0.000,         0,      2.5822,      0.2583
       0.0,      0.000,      0.000,         0,      2.6654,      0.2667
       0.0,      0.000,      0.000,         0,      2.7491,      0.2750
       0.0,      0.000,      0.000,         0,      2.8323,      0.2833
       0.0,      0.000,      0.000,         0,      2.9156,      0.2917
       0.0,      0.000,      0.000,         0,      2.9990,      0.3000
       0.0,      0.000,      0.000,         0,      3.0823,      0.3083
       0.0,      0.000,      0.000,         0,      3.1656,      0.3167
       0.0,      0.000,      0.000,         0,      3.2490,      0.3250
       0.0,      0.000,      0.000,         0,      3.3325,      0.3333
       0.0,      0.000,      0.000,         0,      3.4155,      0.3417
       0.0,      0.000,      0.000,         0,      3.4990,      0.3500
       0.0,      0.000,      0.000,         0,      3.5823,      0.3583
       0.0,      0.000,      0.000,         0,      3.6657,      0.3667