File: Alban repo/Quiz 1/suction cup instron tests/oct-dec-2019_raw-data/d30e10-01-inwater-on36grit-diaphragmpump-10mm-test1.raw
Operator: 1

Date,Time,Specimen#
11/09/19,17:23:31,1

---------------------------------------


Area (mm^2):,      1.00,Flat,     25.40,     25.40,     25.40
Gage Len (mm):,     25.40


LOAD (N),STRAIN 1 (mm),STRAIN 2 (mm),STRESS (MPa),POSITION (mm),TIME (min)
      18.9,      0.000,      0.000,         0,     -0.1612,      0.0083
      21.0,      0.000,      0.000,         0,     -0.3279,      0.0167
      21.0,      0.000,      0.000,         0,     -0.4943,      0.0250
      20.7,      0.000,      0.000,         0,     -0.6612,      0.0333
      20.3,      0.000,      0.000,         0,     -0.8279,      0.0417
      19.9,      0.000,      0.000,         0,     -0.9945,      0.0500
      19.5,      0.000,      0.000,         0,     -1.1612,      0.0583
      19.1,      0.000,      0.000,         0,     -1.3278,      0.0667
      18.6,      0.000,      0.000,         0,     -1.4945,      0.0750
      18.2,      0.000,      0.000,         0,     -1.6611,      0.0833
      17.7,      0.000,      0.000,         0,     -1.8278,      0.0917
      17.3,      0.000,      0.000,         0,     -1.9943,      0.1000
      16.9,      0.000,      0.000,         0,     -2.1611,      0.1083
      16.4,      0.000,      0.000,         0,     -2.3276,      0.1167
      15.9,      0.000,      0.000,         0,     -2.4944,      0.1250
      15.5,      0.000,      0.000,         0,     -2.6611,      0.1333
      15.1,      0.000,      0.000,         0,     -2.8275,      0.1417
      14.6,      0.000,      0.000,         0,     -2.9944,      0.1500
      14.2,      0.000,      0.000,         0,     -3.1610,      0.1583
      13.7,      0.000,      0.000,         0,     -3.3275,      0.1667
      13.2,      0.000,      0.000,         0,     -3.4944,      0.1750
      12.8,      0.000,      0.000,         0,     -3.6610,      0.1833
      12.2,      0.000,      0.000,         0,     -3.8277,      0.1917
      11.7,      0.000,      0.000,         0,     -3.9943,      0.2000
      11.2,      0.000,      0.000,         0,     -4.1610,      0.2083
      10.6,      0.000,      0.000,         0,     -4.3276,      0.2167
      10.0,      0.000,      0.000,         0,     -4.4943,      0.2250
       9.3,      0.000,      0.000,         0,     -4.6608,      0.2333
       8.6,      0.000,      0.000,         0,     -4.8276,      0.2417
       7.9,      0.000,      0.000,         0,     -4.9943,      0.2500
       7.2,      0.000,      0.000,         0,     -5.1609,      0.2583
       6.4,      0.000,      0.000,         0,     -5.3276,      0.2667
       5.5,      0.000,      0.000,         0,     -5.4940,      0.2750
       4.6,      0.000,      0.000,         0,     -5.6609,      0.2833
       3.6,      0.000,      0.000,         0,     -5.8276,      0.2917
       2.5,      0.000,      0.000,         0,     -5.9942,      0.3000
       1.3,      0.000,      0.000,         0,     -6.1609,      0.3083
      -0.1,      0.000,      0.000,         0,     -6.3275,      0.3167
      -1.6,      0.000,      0.000,         0,     -6.4942,      0.3250
      -3.5,      0.000,      0.000,         0,     -6.6608,      0.3333
      -5.8,      0.000,      0.000,         0,     -6.8277,      0.3417
      -8.5,      0.000,      0.000,         0,     -6.9941,      0.3500
     -11.6,      0.000,      0.000,         0,     -7.1608,      0.3583
     -14.9,      0.000,      0.000,         0,     -7.3275,      0.3667
     -14.5,      0.000,      0.000,         0,     -7.3705,      0.3836
     -13.8,      0.000,      0.000,         0,     -7.3705,      0.4003
     -13.5,      0.000,      0.000,         0,     -7.3705,      0.4169
     -13.2,      0.000,      0.000,         0,     -7.3705,      0.4336
     -13.0,      0.000,      0.000,         0,     -7.3705,      0.4503
     -12.8,      0.000,      0.000,         0,     -7.3705,      0.4669
     -12.7,      0.000,      0.000,         0,     -7.3703,      0.4836
     -12.6,      0.000,      0.000,         0,     -7.3703,      0.5003
     -12.5,      0.000,      0.000,         0,     -7.3701,      0.5169
     -12.3,      0.000,      0.000,         0,     -7.3420,      0.5336
     -12.0,      0.000,      0.000,         0,     -7.3348,      0.5503
     -12.0,      0.000,      0.000,         0,     -7.3335,      0.5669
     -11.9,      0.000,      0.000,         0,     -7.3329,      0.5836
     -11.8,      0.000,      0.000,         0,     -7.3313,      0.6003
     -11.8,      0.000,      0.000,         0,     -7.3313,      0.6169
      -9.9,      0.000,      0.000,         0,     -7.2666,      0.6253
      -7.7,      0.000,      0.000,         0,     -7.1833,      0.6336
      -5.7,      0.000,      0.000,         0,     -7.0982,      0.6419
      -4.0,      0.000,      0.000,         0,     -7.0145,      0.6503
      -2.6,      0.000,      0.000,         0,     -6.9312,      0.6586
      -1.4,      0.000,      0.000,         0,     -6.8478,      0.6669
      -0.3,      0.000,      0.000,         0,     -6.7645,      0.6753
       0.7,      0.000,      0.000,         0,     -6.6812,      0.6836
       1.6,      0.000,      0.000,         0,     -6.5979,      0.6919
       2.4,      0.000,      0.000,         0,     -6.5147,      0.7003
       3.1,      0.000,      0.000,         0,     -6.4310,      0.7086
       3.9,      0.000,      0.000,         0,     -6.3479,      0.7169
       4.5,      0.000,      0.000,         0,     -6.2645,      0.7253
       5.1,      0.000,      0.000,         0,     -6.1812,      0.7336
       5.8,      0.000,      0.000,         0,     -6.0977,      0.7419
       6.3,      0.000,      0.000,         0,     -6.0146,      0.7503
       6.9,      0.000,      0.000,         0,     -5.9312,      0.7586
       7.5,      0.000,      0.000,         0,     -5.8479,      0.7669
       8.0,      0.000,      0.000,         0,     -5.7646,      0.7753
       8.5,      0.000,      0.000,         0,     -5.6810,      0.7836
       9.0,      0.000,      0.000,         0,     -5.5979,      0.7919
       9.5,      0.000,      0.000,         0,     -5.5146,      0.8003
      10.0,      0.000,      0.000,         0,     -5.4313,      0.8086
      10.4,      0.000,      0.000,         0,     -5.3479,      0.8169
      10.9,      0.000,      0.000,         0,     -5.2646,      0.8253
      11.3,      0.000,      0.000,         0,     -5.1813,      0.8336
      11.7,      0.000,      0.000,         0,     -5.0979,      0.8419
      12.1,      0.000,      0.000,         0,     -5.0146,      0.8503
      12.4,      0.000,      0.000,         0,     -4.9313,      0.8586
      12.8,      0.000,      0.000,         0,     -4.8478,      0.8669
      13.2,      0.000,      0.000,         0,     -4.7646,      0.8753
      13.5,      0.000,      0.000,         0,     -4.6813,      0.8836
      13.9,      0.000,      0.000,         0,     -4.5980,      0.8919
      14.2,      0.000,      0.000,         0,     -4.5145,      0.9003
      14.6,      0.000,      0.000,         0,     -4.4311,      0.9086
      14.9,      0.000,      0.000,         0,     -4.3478,      0.9169
      15.2,      0.000,      0.000,         0,     -4.2647,      0.9253
      15.5,      0.000,      0.000,         0,     -4.1813,      0.9336
      15.8,      0.000,      0.000,         0,     -4.0978,      0.9419
      16.0,      0.000,      0.000,         0,     -4.0145,      0.9503
      16.3,      0.000,      0.000,         0,     -3.9313,      0.9586
      16.6,      0.000,      0.000,         0,     -3.8480,      0.9669
      16.8,      0.000,      0.000,         0,     -3.7645,      0.9753
      17.1,      0.000,      0.000,         0,     -3.6812,      0.9836
      17.3,      0.000,      0.000,         0,     -3.5980,      0.9919
      17.6,      0.000,      0.000,         0,     -3.5147,      1.0003
      17.8,      0.000,      0.000,         0,     -3.4314,      1.0086
      18.0,      0.000,      0.000,         0,     -3.3479,      1.0169
      18.3,      0.000,      0.000,         0,     -3.2647,      1.0253
      18.5,      0.000,      0.000,         0,     -3.1812,      1.0336
      18.7,      0.000,      0.000,         0,     -3.0979,      1.0419
      18.9,      0.000,      0.000,         0,     -3.0147,      1.0503
      19.1,      0.000,      0.000,         0,     -2.9312,      1.0586
      19.4,      0.000,      0.000,         0,     -2.8479,      1.0669
      19.6,      0.000,      0.000,         0,     -2.7648,      1.0753
      19.8,      0.000,      0.000,         0,     -2.6812,      1.0836
      20.0,      0.000,      0.000,         0,     -2.5981,      1.0919
      20.2,      0.000,      0.000,         0,     -2.5146,      1.1003
      20.4,      0.000,      0.000,         0,     -2.4314,      1.1086
      20.6,      0.000,      0.000,         0,     -2.3479,      1.1169
      20.8,      0.000,      0.000,         0,     -2.2648,      1.1253
      21.0,      0.000,      0.000,         0,     -2.1815,      1.1336
      21.2,      0.000,      0.000,         0,     -2.0979,      1.1419
      21.4,      0.000,      0.000,         0,     -2.0146,      1.1503
      21.5,      0.000,      0.000,         0,     -1.9315,      1.1586
      21.7,      0.000,      0.000,         0,     -1.8481,      1.1669
      21.9,      0.000,      0.000,         0,     -1.7646,      1.1753
      22.1,      0.000,      0.000,         0,     -1.6813,      1.1836
      22.3,      0.000,      0.000,         0,     -1.5982,      1.1919
      22.5,      0.000,      0.000,         0,     -1.5148,      1.2003
      22.7,      0.000,      0.000,         0,     -1.4311,      1.2086
      22.9,      0.000,      0.000,         0,     -1.3484,      1.2169
      23.1,      0.000,      0.000,         0,     -1.2647,      1.2253
      23.2,      0.000,      0.000,         0,     -1.1813,      1.2336
      23.4,      0.000,      0.000,         0,     -1.0980,      1.2419
      23.6,      0.000,      0.000,         0,     -1.0149,      1.2503
      23.8,      0.000,      0.000,         0,     -0.9315,      1.2586
      24.0,      0.000,      0.000,         0,     -0.8480,      1.2669
      24.2,      0.000,      0.000,         0,     -0.7647,      1.2753
      24.4,      0.000,      0.000,         0,     -0.6814,      1.2836
      24.6,      0.000,      0.000,         0,     -0.5982,      1.2919
      24.8,      0.000,      0.000,         0,     -0.5147,      1.3003
      25.0,      0.000,      0.000,         0,     -0.4314,      1.3086
      25.2,      0.000,      0.000,         0,     -0.3482,      1.3169
      25.4,      0.000,      0.000,         0,     -0.2651,      1.3253
      25.6,      0.000,      0.000,         0,     -0.1812,      1.3336
      25.8,      0.000,      0.000,         0,     -0.0981,      1.3419
      26.0,      0.000,      0.000,         0,     -0.0147,      1.3503
      26.2,      0.000,      0.000,         0,      0.0684,      1.3586
      26.4,      0.000,      0.000,         0,      0.1521,      1.3669
      26.6,      0.000,      0.000,         0,      0.2351,      1.3753
      26.8,      0.000,      0.000,         0,      0.3184,      1.3836
      27.0,      0.000,      0.000,         0,      0.4019,      1.3919
      27.2,      0.000,      0.000,         0,      0.4850,      1.4003
      27.4,      0.000,      0.000,         0,      0.5686,      1.4086
      27.6,      0.000,      0.000,         0,      0.6519,      1.4169
      27.9,      0.000,      0.000,         0,      0.7352,      1.4253
      28.1,      0.000,      0.000,         0,      0.8184,      1.4336
      28.3,      0.000,      0.000,         0,      0.9019,      1.4419
      28.5,      0.000,      0.000,         0,      0.9852,      1.4503
      28.7,      0.000,      0.000,         0,      1.0683,      1.4586
      28.9,      0.000,      0.000,         0,      1.1517,      1.4669
      29.1,      0.000,      0.000,         0,      1.2352,      1.4753
      29.3,      0.000,      0.000,         0,      1.3183,      1.4836
      29.5,      0.000,      0.000,         0,      1.4019,      1.4919
      29.7,      0.000,      0.000,         0,      1.4852,      1.5003
      30.0,      0.000,      0.000,         0,      1.5685,      1.5086
      30.2,      0.000,      0.000,         0,      1.6518,      1.5169
      30.4,      0.000,      0.000,         0,      1.7352,      1.5253
      30.6,      0.000,      0.000,         0,      1.8185,      1.5336
      30.8,      0.000,      0.000,         0,      1.9018,      1.5419
      31.0,      0.000,      0.000,         0,      1.9852,      1.5503
      31.3,      0.000,      0.000,         0,      2.0685,      1.5586
      31.5,      0.000,      0.000,         0,      2.1518,      1.5669
      31.8,      0.000,      0.000,         0,      2.2349,      1.5753
      32.0,      0.000,      0.000,         0,      2.3185,      1.5836
      32.2,      0.000,      0.000,         0,      2.4018,      1.5919
      32.5,      0.000,      0.000,         0,      2.4851,      1.6003
      32.8,      0.000,      0.000,         0,      2.5683,      1.6086
      33.0,      0.000,      0.000,         0,      2.6518,      1.6169
      33.3,      0.000,      0.000,         0,      2.7351,      1.6253
      33.5,      0.000,      0.000,         0,      2.8184,      1.6336
      33.7,      0.000,      0.000,         0,      2.9018,      1.6419
      33.9,      0.000,      0.000,         0,      2.9851,      1.6503
      34.1,      0.000,      0.000,         0,      3.0686,      1.6586
      34.2,      0.000,      0.000,         0,      3.1517,      1.6669
      34.4,      0.000,      0.000,         0,      3.2351,      1.6753
      34.6,      0.000,      0.000,         0,      3.3184,      1.6836
      34.8,      0.000,      0.000,         0,      3.4019,      1.6919
      35.1,      0.000,      0.000,         0,      3.4851,      1.7003
      35.3,      0.000,      0.000,         0,      3.5684,      1.7086
      35.5,      0.000,      0.000,         0,      3.6515,      1.7169
      35.7,      0.000,      0.000,         0,      3.7350,      1.7253
      36.0,      0.000,      0.000,         0,      3.8184,      1.7336
      36.2,      0.000,      0.000,         0,      3.9019,      1.7419
      36.4,      0.000,      0.000,         0,      3.9846,      1.7503
      36.6,      0.000,      0.000,         0,      4.0684,      1.7586
      36.8,      0.000,      0.000,         0,      4.1517,      1.7669
      37.0,      0.000,      0.000,         0,      4.2352,      1.7753
      37.2,      0.000,      0.000,         0,      4.3183,      1.7836
      37.4,      0.000,      0.000,         0,      4.4015,      1.7919
      37.6,      0.000,      0.000,         0,      4.4850,      1.8003
      37.9,      0.000,      0.000,         0,      4.5683,      1.8086
      38.1,      0.000,      0.000,         0,      4.6515,      1.8169
      38.3,      0.000,      0.000,         0,      4.7350,      1.8253
      38.5,      0.000,      0.000,         0,      4.8185,      1.8336
      38.7,      0.000,      0.000,         0,      4.9014,      1.8419
      38.9,      0.000,      0.000,         0,      4.9850,      1.8503
      39.1,      0.000,      0.000,         0,      5.0685,      1.8586
      39.3,      0.000,      0.000,         0,      5.1516,      1.8669
      39.6,      0.000,      0.000,         0,      5.2351,      1.8753
      39.8,      0.000,      0.000,         0,      5.3183,      1.8836
      40.0,      0.000,      0.000,         0,      5.4018,      1.8919
      40.2,      0.000,      0.000,         0,      5.4849,      1.9003
      40.4,      0.000,      0.000,         0,      5.5683,      1.9086
      40.6,      0.000,      0.000,         0,      5.6516,      1.9169
      40.8,      0.000,      0.000,         0,      5.7351,      1.9253
      41.0,      0.000,      0.000,         0,      5.8182,      1.9336
      41.2,      0.000,      0.000,         0,      5.9016,      1.9419
      41.4,      0.000,      0.000,         0,      5.9847,      1.9503
      41.6,      0.000,      0.000,         0,      6.0682,      1.9586
      41.8,      0.000,      0.000,         0,      6.1518,      1.9669
      41.9,      0.000,      0.000,         0,      6.2349,      1.9753
      42.1,      0.000,      0.000,         0,      6.3182,      1.9836
      42.3,      0.000,      0.000,         0,      6.4015,      1.9919
      42.5,      0.000,      0.000,         0,      6.4851,      2.0003
      42.7,      0.000,      0.000,         0,      6.5680,      2.0086
      42.9,      0.000,      0.000,         0,      6.6517,      2.0169
      43.0,      0.000,      0.000,         0,      6.7349,      2.0253
      43.2,      0.000,      0.000,         0,      6.8184,      2.0336
      43.4,      0.000,      0.000,         0,      6.9013,      2.0419
      43.5,      0.000,      0.000,         0,      6.9850,      2.0503
      43.7,      0.000,      0.000,         0,      7.0682,      2.0586
      43.8,      0.000,      0.000,         0,      7.1517,      2.0669
      43.9,      0.000,      0.000,         0,      7.2350,      2.0753
      44.1,      0.000,      0.000,         0,      7.3182,      2.0836
      44.2,      0.000,      0.000,         0,      7.4015,      2.0919
      44.3,      0.000,      0.000,         0,      7.4848,      2.1003
      44.4,      0.000,      0.000,         0,      7.5681,      2.1086
      44.5,      0.000,      0.000,         0,      7.6515,      2.1169
      44.6,      0.000,      0.000,         0,      7.7350,      2.1253
      44.5,      0.000,      0.000,         0,      7.8183,      2.1336
      44.1,      0.000,      0.000,         0,      7.9015,      2.1419
      43.9,      0.000,      0.000,         0,      7.9848,      2.1503
      33.5,      0.000,      0.000,         0,      8.0683,      2.1586
       0.1,      0.000,      0.000,         0,      8.1514,      2.1669
       0.1,      0.000,      0.000,         0,      8.2348,      2.1753
       0.1,      0.000,      0.000,         0,      8.3183,      2.1836
       0.1,      0.000,      0.000,         0,      8.4014,      2.1919
       0.1,      0.000,      0.000,         0,      8.4849,      2.2003
       0.1,      0.000,      0.000,         0,      8.5683,      2.2086
       0.1,      0.000,      0.000,         0,      8.6514,      2.2169
       0.1,      0.000,      0.000,         0,      8.7347,      2.2253
       0.1,      0.000,      0.000,         0,      8.8183,      2.2336
       0.1,      0.000,      0.000,         0,      8.9016,      2.2419
       0.1,      0.000,      0.000,         0,      8.9849,      2.2503
       0.1,      0.000,      0.000,         0,      9.0681,      2.2586
       0.1,      0.000,      0.000,         0,      9.1516,      2.2669
       0.1,      0.000,      0.000,         0,      9.2347,      2.2753