File: Alban repo/Quiz 1/suction cup instron tests/oct-dec-2019_raw-data/d30e10-01-inwater-on80grit-nopump-10mm-test2.raw
Operator: 1

Date,Time,Specimen#
10/25/19,18:38:49,1

---------------------------------------


Area (mm^2):,      1.00,Flat,     25.40,     25.40,     25.40
Gage Len (mm):,     25.40


LOAD (N),STRAIN 1 (mm),STRAIN 2 (mm),STRESS (MPa),POSITION (mm),TIME (min)
       2.6,      0.000,      0.000,         0,      0.0811,      0.0083
       3.3,      0.000,      0.000,         0,      0.1644,      0.0167
       4.0,      0.000,      0.000,         0,      0.2479,      0.0250
       4.6,      0.000,      0.000,         0,      0.3311,      0.0333
       5.2,      0.000,      0.000,         0,      0.4142,      0.0417
       5.9,      0.000,      0.000,         0,      0.4978,      0.0500
       6.5,      0.000,      0.000,         0,      0.5811,      0.0583
       7.1,      0.000,      0.000,         0,      0.6644,      0.0667
       7.7,      0.000,      0.000,         0,      0.7476,      0.0750
       8.3,      0.000,      0.000,         0,      0.8311,      0.0833
       8.9,      0.000,      0.000,         0,      0.9145,      0.0917
       9.5,      0.000,      0.000,         0,      0.9977,      0.1000
      10.1,      0.000,      0.000,         0,      1.0811,      0.1083
      10.6,      0.000,      0.000,         0,      1.1646,      0.1167
      11.1,      0.000,      0.000,         0,      1.2478,      0.1250
      11.7,      0.000,      0.000,         0,      1.3309,      0.1333
      12.2,      0.000,      0.000,         0,      1.4144,      0.1417
      12.7,      0.000,      0.000,         0,      1.4978,      0.1500
      13.2,      0.000,      0.000,         0,      1.5810,      0.1583
      13.7,      0.000,      0.000,         0,      1.6642,      0.1667
      14.1,      0.000,      0.000,         0,      1.7478,      0.1750
      14.6,      0.000,      0.000,         0,      1.8310,      0.1833
      15.1,      0.000,      0.000,         0,      1.9143,      0.1917
      15.5,      0.000,      0.000,         0,      1.9976,      0.2000
      15.9,      0.000,      0.000,         0,      2.0811,      0.2083
      16.3,      0.000,      0.000,         0,      2.1643,      0.2167
      16.7,      0.000,      0.000,         0,      2.2477,      0.2250
      17.1,      0.000,      0.000,         0,      2.3311,      0.2333
      17.5,      0.000,      0.000,         0,      2.4143,      0.2417
      17.9,      0.000,      0.000,         0,      2.4978,      0.2500
      18.2,      0.000,      0.000,         0,      2.5809,      0.2583
      18.6,      0.000,      0.000,         0,      2.6639,      0.2667
      19.0,      0.000,      0.000,         0,      2.7476,      0.2750
      19.3,      0.000,      0.000,         0,      2.8310,      0.2833
      19.6,      0.000,      0.000,         0,      2.9143,      0.2917
      20.0,      0.000,      0.000,         0,      2.9978,      0.3000
      20.3,      0.000,      0.000,         0,      3.0808,      0.3083
      20.6,      0.000,      0.000,         0,      3.1643,      0.3167
      20.9,      0.000,      0.000,         0,      3.2476,      0.3250
      21.2,      0.000,      0.000,         0,      3.3309,      0.3333
      21.5,      0.000,      0.000,         0,      3.4142,      0.3417
      21.8,      0.000,      0.000,         0,      3.4977,      0.3500
      22.1,      0.000,      0.000,         0,      3.5811,      0.3583
      22.5,      0.000,      0.000,         0,      3.6640,      0.3667
      22.8,      0.000,      0.000,         0,      3.7475,      0.3750
      23.1,      0.000,      0.000,         0,      3.8311,      0.3833
      23.4,      0.000,      0.000,         0,      3.9143,      0.3917
      23.7,      0.000,      0.000,         0,      3.9974,      0.4000
      24.0,      0.000,      0.000,         0,      4.0810,      0.4083
      24.3,      0.000,      0.000,         0,      4.1643,      0.4167
      24.6,      0.000,      0.000,         0,      4.2475,      0.4250
      24.9,      0.000,      0.000,         0,      4.3308,      0.4333
      25.2,      0.000,      0.000,         0,      4.4144,      0.4417
      25.5,      0.000,      0.000,         0,      4.4975,      0.4500
      25.8,      0.000,      0.000,         0,      4.5807,      0.4583
      26.1,      0.000,      0.000,         0,      4.6642,      0.4667
      26.4,      0.000,      0.000,         0,      4.7476,      0.4750
      26.7,      0.000,      0.000,         0,      4.8309,      0.4833
      27.0,      0.000,      0.000,         0,      4.9141,      0.4917
      27.3,      0.000,      0.000,         0,      4.9974,      0.5000
      27.6,      0.000,      0.000,         0,      5.0808,      0.5083
      27.9,      0.000,      0.000,         0,      5.1643,      0.5167
      28.2,      0.000,      0.000,         0,      5.2475,      0.5250
      28.5,      0.000,      0.000,         0,      5.3309,      0.5333
      28.8,      0.000,      0.000,         0,      5.4140,      0.5417
      29.1,      0.000,      0.000,         0,      5.4975,      0.5500
      29.3,      0.000,      0.000,         0,      5.5809,      0.5583
      29.6,      0.000,      0.000,         0,      5.6641,      0.5667
      29.9,      0.000,      0.000,         0,      5.7476,      0.5750
      30.2,      0.000,      0.000,         0,      5.8307,      0.5833
      30.5,      0.000,      0.000,         0,      5.9143,      0.5917
      30.8,      0.000,      0.000,         0,      5.9975,      0.6000
      31.1,      0.000,      0.000,         0,      6.0809,      0.6083
      31.4,      0.000,      0.000,         0,      6.1643,      0.6167
      31.7,      0.000,      0.000,         0,      6.2476,      0.6250
      32.0,      0.000,      0.000,         0,      6.3307,      0.6333
      32.3,      0.000,      0.000,         0,      6.4141,      0.6417
      32.6,      0.000,      0.000,         0,      6.4975,      0.6500
      32.9,      0.000,      0.000,         0,      6.5808,      0.6583
      33.3,      0.000,      0.000,         0,      6.6642,      0.6667
      33.6,      0.000,      0.000,         0,      6.7477,      0.6750
      33.9,      0.000,      0.000,         0,      6.8309,      0.6833
      34.2,      0.000,      0.000,         0,      6.9140,      0.6917
      34.5,      0.000,      0.000,         0,      6.9974,      0.7000
      34.9,      0.000,      0.000,         0,      7.0808,      0.7083
      35.2,      0.000,      0.000,         0,      7.1641,      0.7167
      35.5,      0.000,      0.000,         0,      7.2474,      0.7250
      35.8,      0.000,      0.000,         0,      7.3309,      0.7333
      36.1,      0.000,      0.000,         0,      7.4140,      0.7417
      36.5,      0.000,      0.000,         0,      7.4973,      0.7500
      36.8,      0.000,      0.000,         0,      7.5807,      0.7583
      37.1,      0.000,      0.000,         0,      7.6643,      0.7667
      37.4,      0.000,      0.000,         0,      7.7473,      0.7750
      37.7,      0.000,      0.000,         0,      7.8307,      0.7833
      38.0,      0.000,      0.000,         0,      7.9141,      0.7917
      38.4,      0.000,      0.000,         0,      7.9975,      0.8000
      38.7,      0.000,      0.000,         0,      8.0806,      0.8083
      39.0,      0.000,      0.000,         0,      8.1640,      0.8167
      39.3,      0.000,      0.000,         0,      8.2474,      0.8250
      39.6,      0.000,      0.000,         0,      8.3304,      0.8333
      39.8,      0.000,      0.000,         0,      8.4141,      0.8417
      40.1,      0.000,      0.000,         0,      8.4975,      0.8500
      40.4,      0.000,      0.000,         0,      8.5806,      0.8583
      40.7,      0.000,      0.000,         0,      8.6640,      0.8667
      40.9,      0.000,      0.000,         0,      8.7474,      0.8750
      41.2,      0.000,      0.000,         0,      8.8308,      0.8833
      41.5,      0.000,      0.000,         0,      8.9140,      0.8917
      41.8,      0.000,      0.000,         0,      8.9972,      0.9000
      42.1,      0.000,      0.000,         0,      9.0807,      0.9083
      42.3,      0.000,      0.000,         0,      9.1639,      0.9167
      42.6,      0.000,      0.000,         0,      9.2471,      0.9250
      42.9,      0.000,      0.000,         0,      9.3308,      0.9333
      43.2,      0.000,      0.000,         0,      9.4142,      0.9417
      43.5,      0.000,      0.000,         0,      9.4974,      0.9500
      43.7,      0.000,      0.000,         0,      9.5806,      0.9583
      44.0,      0.000,      0.000,         0,      9.6640,      0.9667
      44.3,      0.000,      0.000,         0,      9.7472,      0.9750
      44.6,      0.000,      0.000,         0,      9.8307,      0.9833
      44.9,      0.000,      0.000,         0,      9.9139,      0.9917
      45.2,      0.000,      0.000,         0,      9.9973,      1.0000
      45.5,      0.000,      0.000,         0,     10.0807,      1.0083
      45.8,      0.000,      0.000,         0,     10.1639,      1.0167
      46.1,      0.000,      0.000,         0,     10.2472,      1.0250
      46.4,      0.000,      0.000,         0,     10.3307,      1.0333
      46.7,      0.000,      0.000,         0,     10.4141,      1.0417
      46.9,      0.000,      0.000,         0,     10.4972,      1.0500
      47.2,      0.000,      0.000,         0,     10.5806,      1.0583
      47.5,      0.000,      0.000,         0,     10.6640,      1.0667
      47.8,      0.000,      0.000,         0,     10.7473,      1.0750
      48.1,      0.000,      0.000,         0,     10.8306,      1.0833
      48.3,      0.000,      0.000,         0,     10.9140,      1.0917
      48.6,      0.000,      0.000,         0,     10.9972,      1.1000
      48.8,      0.000,      0.000,         0,     11.0807,      1.1083
      49.0,      0.000,      0.000,         0,     11.1637,      1.1167
      49.3,      0.000,      0.000,         0,     11.2474,      1.1250
      49.5,      0.000,      0.000,         0,     11.3306,      1.1333
      49.8,      0.000,      0.000,         0,     11.4141,      1.1417
      50.0,      0.000,      0.000,         0,     11.4975,      1.1500
      50.3,      0.000,      0.000,         0,     11.5806,      1.1583
      50.5,      0.000,      0.000,         0,     11.6639,      1.1667
      50.7,      0.000,      0.000,         0,     11.7472,      1.1750
      50.9,      0.000,      0.000,         0,     11.8306,      1.1833
      51.2,      0.000,      0.000,         0,     11.9138,      1.1917
      51.4,      0.000,      0.000,         0,     11.9973,      1.2000
      51.6,      0.000,      0.000,         0,     12.0806,      1.2083
      51.9,      0.000,      0.000,         0,     12.1640,      1.2167
      52.1,      0.000,      0.000,         0,     12.2471,      1.2250
      52.3,      0.000,      0.000,         0,     12.3307,      1.2333
      52.5,      0.000,      0.000,         0,     12.4139,      1.2417
      52.8,      0.000,      0.000,         0,     12.4971,      1.2500
      53.0,      0.000,      0.000,         0,     12.5806,      1.2583
      53.3,      0.000,      0.000,         0,     12.6639,      1.2667
      53.5,      0.000,      0.000,         0,     12.7471,      1.2750
      53.7,      0.000,      0.000,         0,     12.8305,      1.2833
      54.0,      0.000,      0.000,         0,     12.9138,      1.2917
      54.2,      0.000,      0.000,         0,     12.9971,      1.3000
      54.5,      0.000,      0.000,         0,     13.0805,      1.3083
      54.7,      0.000,      0.000,         0,     13.1638,      1.3167
      54.9,      0.000,      0.000,         0,     13.2471,      1.3250
      55.2,      0.000,      0.000,         0,     13.3305,      1.3333
      55.4,      0.000,      0.000,         0,     13.4139,      1.3417
      55.7,      0.000,      0.000,         0,     13.4972,      1.3500
      55.9,      0.000,      0.000,         0,     13.5804,      1.3583
      56.1,      0.000,      0.000,         0,     13.6639,      1.3667
      56.4,      0.000,      0.000,         0,     13.7472,      1.3750
      56.6,      0.000,      0.000,         0,     13.8306,      1.3833
      56.8,      0.000,      0.000,         0,     13.9138,      1.3917
      57.0,      0.000,      0.000,         0,     13.9972,      1.4000
      57.1,      0.000,      0.000,         0,     14.0804,      1.4083
      57.1,      0.000,      0.000,         0,     14.1640,      1.4167
      57.2,      0.000,      0.000,         0,     14.2471,      1.4250
      57.4,      0.000,      0.000,         0,     14.3305,      1.4333
      57.5,      0.000,      0.000,         0,     14.4138,      1.4417
      57.6,      0.000,      0.000,         0,     14.4971,      1.4500
      57.6,      0.000,      0.000,         0,     14.5805,      1.4583
      57.6,      0.000,      0.000,         0,     14.6638,      1.4667
      57.3,      0.000,      0.000,         0,     14.7471,      1.4750
      55.4,      0.000,      0.000,         0,     14.8304,      1.4833
       0.2,      0.000,      0.000,         0,     14.9135,      1.4917
       0.1,      0.000,      0.000,         0,     14.9971,      1.5000
       0.1,      0.000,      0.000,         0,     15.0805,      1.5083
       0.1,      0.000,      0.000,         0,     15.1636,      1.5167
       0.1,      0.000,      0.000,         0,     15.2471,      1.5250
       0.1,      0.000,      0.000,         0,     15.3305,      1.5333
       0.1,      0.000,      0.000,         0,     15.4138,      1.5417
       0.1,      0.000,      0.000,         0,     15.4969,      1.5500
       0.1,      0.000,      0.000,         0,     15.5804,      1.5583
       0.1,      0.000,      0.000,         0,     15.6638,      1.5667
       0.1,      0.000,      0.000,         0,     15.7470,      1.5750
       0.1,      0.000,      0.000,         0,     15.8300,      1.5833
       0.1,      0.000,      0.000,         0,     15.9138,      1.5917
       0.1,      0.000,      0.000,         0,     15.9971,      1.6000
       0.1,      0.000,      0.000,         0,     16.0804,      1.6083
       0.1,      0.000,      0.000,         0,     16.1637,      1.6167