File: Alban repo/Quiz 1/suction cup instron tests/oct-dec-2019_raw-data/d30e10-01-inwater-on36grit-diaphragmpump-10mm-test2.raw
Operator: 1

Date,Time,Specimen#
11/09/19,17:27:05,1

---------------------------------------


Area (mm^2):,      1.00,Flat,     25.40,     25.40,     25.40
Gage Len (mm):,     25.40


LOAD (N),STRAIN 1 (mm),STRAIN 2 (mm),STRESS (MPa),POSITION (mm),TIME (min)
      18.6,      0.000,      0.000,         0,     -0.1618,      0.0083
      20.3,      0.000,      0.000,         0,     -0.3285,      0.0167
      20.3,      0.000,      0.000,         0,     -0.4951,      0.0250
      19.9,      0.000,      0.000,         0,     -0.6620,      0.0333
      19.5,      0.000,      0.000,         0,     -0.8284,      0.0417
      19.1,      0.000,      0.000,         0,     -0.9951,      0.0500
      18.6,      0.000,      0.000,         0,     -1.1618,      0.0583
      18.2,      0.000,      0.000,         0,     -1.3284,      0.0667
      17.8,      0.000,      0.000,         0,     -1.4951,      0.0750
      17.4,      0.000,      0.000,         0,     -1.6617,      0.0833
      16.9,      0.000,      0.000,         0,     -1.8286,      0.0917
      16.5,      0.000,      0.000,         0,     -1.9952,      0.1000
      16.1,      0.000,      0.000,         0,     -2.1619,      0.1083
      15.6,      0.000,      0.000,         0,     -2.3285,      0.1167
      15.2,      0.000,      0.000,         0,     -2.4952,      0.1250
      14.7,      0.000,      0.000,         0,     -2.6619,      0.1333
      14.3,      0.000,      0.000,         0,     -2.8285,      0.1417
      13.8,      0.000,      0.000,         0,     -2.9952,      0.1500
      13.4,      0.000,      0.000,         0,     -3.1616,      0.1583
      12.9,      0.000,      0.000,         0,     -3.3283,      0.1667
      12.4,      0.000,      0.000,         0,     -3.4949,      0.1750
      11.9,      0.000,      0.000,         0,     -3.6618,      0.1833
      11.4,      0.000,      0.000,         0,     -3.8284,      0.1917
      10.8,      0.000,      0.000,         0,     -3.9951,      0.2000
      10.3,      0.000,      0.000,         0,     -4.1618,      0.2083
       9.7,      0.000,      0.000,         0,     -4.3284,      0.2167
       9.1,      0.000,      0.000,         0,     -4.4953,      0.2250
       8.4,      0.000,      0.000,         0,     -4.6615,      0.2333
       7.7,      0.000,      0.000,         0,     -4.8284,      0.2417
       7.0,      0.000,      0.000,         0,     -4.9950,      0.2500
       6.2,      0.000,      0.000,         0,     -5.1617,      0.2583
       5.4,      0.000,      0.000,         0,     -5.3282,      0.2667
       4.5,      0.000,      0.000,         0,     -5.4950,      0.2750
       3.5,      0.000,      0.000,         0,     -5.6617,      0.2833
       2.4,      0.000,      0.000,         0,     -5.8285,      0.2917
       1.3,      0.000,      0.000,         0,     -5.9948,      0.3000
      -0.1,      0.000,      0.000,         0,     -6.1616,      0.3083
      -1.6,      0.000,      0.000,         0,     -6.3283,      0.3167
      -3.5,      0.000,      0.000,         0,     -6.4950,      0.3250
      -5.7,      0.000,      0.000,         0,     -6.6616,      0.3333
      -8.3,      0.000,      0.000,         0,     -6.8283,      0.3417
     -11.2,      0.000,      0.000,         0,     -6.9949,      0.3500
     -14.3,      0.000,      0.000,         0,     -7.1616,      0.3583
     -14.3,      0.000,      0.000,         0,     -7.2385,      0.3769
     -13.6,      0.000,      0.000,         0,     -7.2387,      0.3936
     -13.2,      0.000,      0.000,         0,     -7.2385,      0.4103
     -12.8,      0.000,      0.000,         0,     -7.2385,      0.4269
     -12.6,      0.000,      0.000,         0,     -7.2385,      0.4436
     -12.4,      0.000,      0.000,         0,     -7.2383,      0.4603
     -12.2,      0.000,      0.000,         0,     -7.2381,      0.4769
     -12.1,      0.000,      0.000,         0,     -7.2381,      0.4936
     -12.0,      0.000,      0.000,         0,     -7.2379,      0.5103
     -11.8,      0.000,      0.000,         0,     -7.2094,      0.5269
     -11.5,      0.000,      0.000,         0,     -7.2013,      0.5436
     -11.4,      0.000,      0.000,         0,     -7.2011,      0.5603
     -11.4,      0.000,      0.000,         0,     -7.2003,      0.5769
     -11.3,      0.000,      0.000,         0,     -7.1990,      0.5936
     -11.2,      0.000,      0.000,         0,     -7.1992,      0.6103
      -9.4,      0.000,      0.000,         0,     -7.1343,      0.6186
      -7.4,      0.000,      0.000,         0,     -7.0503,      0.6269
      -5.5,      0.000,      0.000,         0,     -6.9659,      0.6353
      -4.0,      0.000,      0.000,         0,     -6.8821,      0.6436
      -2.6,      0.000,      0.000,         0,     -6.7988,      0.6519
      -1.4,      0.000,      0.000,         0,     -6.7157,      0.6603
      -0.3,      0.000,      0.000,         0,     -6.6322,      0.6686
       0.6,      0.000,      0.000,         0,     -6.5488,      0.6769
       1.5,      0.000,      0.000,         0,     -6.4657,      0.6853
       2.3,      0.000,      0.000,         0,     -6.3824,      0.6936
       3.1,      0.000,      0.000,         0,     -6.2988,      0.7019
       3.8,      0.000,      0.000,         0,     -6.2155,      0.7103
       4.4,      0.000,      0.000,         0,     -6.1322,      0.7186
       5.0,      0.000,      0.000,         0,     -6.0489,      0.7269
       5.6,      0.000,      0.000,         0,     -5.9655,      0.7353
       6.2,      0.000,      0.000,         0,     -5.8824,      0.7436
       6.7,      0.000,      0.000,         0,     -5.7989,      0.7519
       7.3,      0.000,      0.000,         0,     -5.7155,      0.7603
       7.8,      0.000,      0.000,         0,     -5.6322,      0.7686
       8.3,      0.000,      0.000,         0,     -5.5493,      0.7769
       8.7,      0.000,      0.000,         0,     -5.4656,      0.7853
       9.2,      0.000,      0.000,         0,     -5.3822,      0.7936
       9.6,      0.000,      0.000,         0,     -5.2989,      0.8019
      10.1,      0.000,      0.000,         0,     -5.2158,      0.8103
      10.5,      0.000,      0.000,         0,     -5.1324,      0.8186
      10.9,      0.000,      0.000,         0,     -5.0489,      0.8269
      11.3,      0.000,      0.000,         0,     -4.9656,      0.8353
      11.6,      0.000,      0.000,         0,     -4.8825,      0.8436
      12.0,      0.000,      0.000,         0,     -4.7991,      0.8519
      12.4,      0.000,      0.000,         0,     -4.7156,      0.8603
      12.7,      0.000,      0.000,         0,     -4.6323,      0.8686
      13.1,      0.000,      0.000,         0,     -4.5491,      0.8769
      13.4,      0.000,      0.000,         0,     -4.4656,      0.8853
      13.7,      0.000,      0.000,         0,     -4.3821,      0.8936
      14.0,      0.000,      0.000,         0,     -4.2992,      0.9019
      14.3,      0.000,      0.000,         0,     -4.2156,      0.9103
      14.6,      0.000,      0.000,         0,     -4.1321,      0.9186
      14.9,      0.000,      0.000,         0,     -4.0490,      0.9269
      15.2,      0.000,      0.000,         0,     -3.9656,      0.9353
      15.5,      0.000,      0.000,         0,     -3.8823,      0.9436
      15.7,      0.000,      0.000,         0,     -3.7988,      0.9519
      16.0,      0.000,      0.000,         0,     -3.7159,      0.9603
      16.3,      0.000,      0.000,         0,     -3.6323,      0.9686
      16.5,      0.000,      0.000,         0,     -3.5490,      0.9769
      16.7,      0.000,      0.000,         0,     -3.4657,      0.9853
      17.0,      0.000,      0.000,         0,     -3.3824,      0.9936
      17.2,      0.000,      0.000,         0,     -3.2990,      1.0019
      17.4,      0.000,      0.000,         0,     -3.2157,      1.0103
      17.7,      0.000,      0.000,         0,     -3.1324,      1.0186
      17.9,      0.000,      0.000,         0,     -3.0490,      1.0269
      18.1,      0.000,      0.000,         0,     -2.9657,      1.0353
      18.3,      0.000,      0.000,         0,     -2.8826,      1.0436
      18.5,      0.000,      0.000,         0,     -2.7991,      1.0519
      18.8,      0.000,      0.000,         0,     -2.7155,      1.0603
      19.0,      0.000,      0.000,         0,     -2.6324,      1.0686
      19.2,      0.000,      0.000,         0,     -2.5491,      1.0769
      19.4,      0.000,      0.000,         0,     -2.4657,      1.0853
      19.6,      0.000,      0.000,         0,     -2.3822,      1.0936
      19.8,      0.000,      0.000,         0,     -2.2993,      1.1019
      20.0,      0.000,      0.000,         0,     -2.2158,      1.1103
      20.2,      0.000,      0.000,         0,     -2.1324,      1.1186
      20.4,      0.000,      0.000,         0,     -2.0489,      1.1269
      20.5,      0.000,      0.000,         0,     -1.9658,      1.1353
      20.7,      0.000,      0.000,         0,     -1.8824,      1.1436
      20.9,      0.000,      0.000,         0,     -1.7989,      1.1519
      21.1,      0.000,      0.000,         0,     -1.7156,      1.1603
      21.3,      0.000,      0.000,         0,     -1.6327,      1.1686
      21.5,      0.000,      0.000,         0,     -1.5491,      1.1769
      21.7,      0.000,      0.000,         0,     -1.4656,      1.1853
      21.8,      0.000,      0.000,         0,     -1.3825,      1.1936
      22.0,      0.000,      0.000,         0,     -1.2991,      1.2019
      22.2,      0.000,      0.000,         0,     -1.2158,      1.2103
      22.4,      0.000,      0.000,         0,     -1.1323,      1.2186
      22.6,      0.000,      0.000,         0,     -1.0492,      1.2269
      22.8,      0.000,      0.000,         0,     -0.9658,      1.2353
      23.0,      0.000,      0.000,         0,     -0.8825,      1.2436
      23.2,      0.000,      0.000,         0,     -0.7992,      1.2519
      23.4,      0.000,      0.000,         0,     -0.7157,      1.2603
      23.5,      0.000,      0.000,         0,     -0.6325,      1.2686
      23.7,      0.000,      0.000,         0,     -0.5492,      1.2769
      23.9,      0.000,      0.000,         0,     -0.4661,      1.2853
      24.1,      0.000,      0.000,         0,     -0.3825,      1.2936
      24.3,      0.000,      0.000,         0,     -0.2992,      1.3019
      24.5,      0.000,      0.000,         0,     -0.2159,      1.3103
      24.7,      0.000,      0.000,         0,     -0.1326,      1.3186
      24.9,      0.000,      0.000,         0,     -0.0490,      1.3269
      25.1,      0.000,      0.000,         0,      0.0341,      1.3353
      25.2,      0.000,      0.000,         0,      0.1174,      1.3436
      25.4,      0.000,      0.000,         0,      0.2010,      1.3519
      25.7,      0.000,      0.000,         0,      0.2841,      1.3603
      25.9,      0.000,      0.000,         0,      0.3674,      1.3686
      26.1,      0.000,      0.000,         0,      0.4507,      1.3769
      26.3,      0.000,      0.000,         0,      0.5343,      1.3853
      26.4,      0.000,      0.000,         0,      0.6174,      1.3936
      26.7,      0.000,      0.000,         0,      0.7007,      1.4019
      26.9,      0.000,      0.000,         0,      0.7841,      1.4103
      27.1,      0.000,      0.000,         0,      0.8674,      1.4186
      27.3,      0.000,      0.000,         0,      0.9507,      1.4269
      27.5,      0.000,      0.000,         0,      1.0340,      1.4353
      27.8,      0.000,      0.000,         0,      1.1176,      1.4436
      28.0,      0.000,      0.000,         0,      1.2007,      1.4519
      28.2,      0.000,      0.000,         0,      1.2840,      1.4603
      28.4,      0.000,      0.000,         0,      1.3676,      1.4686
      28.6,      0.000,      0.000,         0,      1.4507,      1.4769
      28.8,      0.000,      0.000,         0,      1.5342,      1.4853
      29.0,      0.000,      0.000,         0,      1.6173,      1.4936
      29.2,      0.000,      0.000,         0,      1.7007,      1.5019
      29.4,      0.000,      0.000,         0,      1.7840,      1.5103
      29.6,      0.000,      0.000,         0,      1.8673,      1.5186
      29.8,      0.000,      0.000,         0,      1.9508,      1.5269
      30.1,      0.000,      0.000,         0,      2.0340,      1.5353
      30.3,      0.000,      0.000,         0,      2.1173,      1.5436
      30.5,      0.000,      0.000,         0,      2.2006,      1.5519
      30.7,      0.000,      0.000,         0,      2.2842,      1.5603
      30.9,      0.000,      0.000,         0,      2.3675,      1.5686
      31.1,      0.000,      0.000,         0,      2.4506,      1.5769
      31.4,      0.000,      0.000,         0,      2.5341,      1.5853
      31.6,      0.000,      0.000,         0,      2.6173,      1.5936
      31.8,      0.000,      0.000,         0,      2.7006,      1.6019
      32.1,      0.000,      0.000,         0,      2.7839,      1.6103
      32.3,      0.000,      0.000,         0,      2.8675,      1.6186
      32.5,      0.000,      0.000,         0,      2.9508,      1.6269
      32.8,      0.000,      0.000,         0,      3.0339,      1.6353
      33.0,      0.000,      0.000,         0,      3.1173,      1.6436
      33.2,      0.000,      0.000,         0,      3.2008,      1.6519
      33.5,      0.000,      0.000,         0,      3.2839,      1.6603
      33.7,      0.000,      0.000,         0,      3.3672,      1.6686
      33.9,      0.000,      0.000,         0,      3.4506,      1.6769
      34.1,      0.000,      0.000,         0,      3.5341,      1.6853
      34.3,      0.000,      0.000,         0,      3.6172,      1.6936
      34.4,      0.000,      0.000,         0,      3.7005,      1.7019
      34.6,      0.000,      0.000,         0,      3.7841,      1.7103
      34.8,      0.000,      0.000,         0,      3.8672,      1.7186
      35.0,      0.000,      0.000,         0,      3.9507,      1.7269
      35.2,      0.000,      0.000,         0,      4.0335,      1.7353
      35.5,      0.000,      0.000,         0,      4.1174,      1.7436
      35.7,      0.000,      0.000,         0,      4.2005,      1.7519
      35.9,      0.000,      0.000,         0,      4.2842,      1.7603
      36.1,      0.000,      0.000,         0,      4.3674,      1.7686
      36.3,      0.000,      0.000,         0,      4.4505,      1.7769
      36.5,      0.000,      0.000,         0,      4.5338,      1.7853
      36.8,      0.000,      0.000,         0,      4.6174,      1.7936
      37.0,      0.000,      0.000,         0,      4.7005,      1.8019
      37.2,      0.000,      0.000,         0,      4.7838,      1.8103
      37.4,      0.000,      0.000,         0,      4.8673,      1.8186
      37.6,      0.000,      0.000,         0,      4.9507,      1.8269
      37.8,      0.000,      0.000,         0,      5.0338,      1.8353
      38.0,      0.000,      0.000,         0,      5.1173,      1.8436
      38.2,      0.000,      0.000,         0,      5.2008,      1.8519
      38.4,      0.000,      0.000,         0,      5.2838,      1.8603
      38.6,      0.000,      0.000,         0,      5.3673,      1.8686
      38.8,      0.000,      0.000,         0,      5.4506,      1.8769
      39.0,      0.000,      0.000,         0,      5.5340,      1.8853
      39.2,      0.000,      0.000,         0,      5.6171,      1.8936
      39.4,      0.000,      0.000,         0,      5.7006,      1.9019
      39.6,      0.000,      0.000,         0,      5.7839,      1.9103
      39.8,      0.000,      0.000,         0,      5.8673,      1.9186
      40.0,      0.000,      0.000,         0,      5.9506,      1.9269
      40.2,      0.000,      0.000,         0,      6.0337,      1.9353
      40.4,      0.000,      0.000,         0,      6.1173,      1.9436
      40.6,      0.000,      0.000,         0,      6.2006,      1.9519
      40.8,      0.000,      0.000,         0,      6.2839,      1.9603
      41.0,      0.000,      0.000,         0,      6.3672,      1.9686
      41.2,      0.000,      0.000,         0,      6.4506,      1.9769
      41.4,      0.000,      0.000,         0,      6.5337,      1.9853
      41.5,      0.000,      0.000,         0,      6.6172,      1.9936
      41.7,      0.000,      0.000,         0,      6.7004,      2.0019
      41.9,      0.000,      0.000,         0,      6.7839,      2.0103
      42.1,      0.000,      0.000,         0,      6.8670,      2.0186
      42.2,      0.000,      0.000,         0,      6.9505,      2.0269
      42.4,      0.000,      0.000,         0,      7.0339,      2.0353
      42.6,      0.000,      0.000,         0,      7.1172,      2.0436
      42.7,      0.000,      0.000,         0,      7.2005,      2.0519
      42.8,      0.000,      0.000,         0,      7.2839,      2.0603
      43.0,      0.000,      0.000,         0,      7.3672,      2.0686
      43.1,      0.000,      0.000,         0,      7.4505,      2.0769
      43.2,      0.000,      0.000,         0,      7.5338,      2.0853
      43.4,      0.000,      0.000,         0,      7.6172,      2.0936
      43.4,      0.000,      0.000,         0,      7.7003,      2.1019
      43.3,      0.000,      0.000,         0,      7.7838,      2.1103
      43.3,      0.000,      0.000,         0,      7.8673,      2.1186
      43.3,      0.000,      0.000,         0,      7.9505,      2.1269
      43.3,      0.000,      0.000,         0,      8.0338,      2.1353
      42.8,      0.000,      0.000,         0,      8.1171,      2.1436
       0.1,      0.000,      0.000,         0,      8.2005,      2.1519
       0.1,      0.000,      0.000,         0,      8.2836,      2.1603
       0.1,      0.000,      0.000,         0,      8.3671,      2.1686
       0.1,      0.000,      0.000,         0,      8.4505,      2.1769
       0.1,      0.000,      0.000,         0,      8.5336,      2.1853
       0.1,      0.000,      0.000,         0,      8.6171,      2.1936
       0.1,      0.000,      0.000,         0,      8.7004,      2.2019
       0.1,      0.000,      0.000,         0,      8.7838,      2.2103