File: Alban repo/Quiz 1/suction cup instron tests/oct-dec-2019_raw-data/d30e10-01-inwater-on36grit-nopump-10mm-test1.raw
Operator: 1

Date,Time,Specimen#
11/09/19,16:43:03,1

---------------------------------------


Area (mm^2):,      1.00,Flat,     25.40,     25.40,     25.40
Gage Len (mm):,     25.40


LOAD (N),STRAIN 1 (mm),STRAIN 2 (mm),STRESS (MPa),POSITION (mm),TIME (min)
       2.4,      0.000,      0.000,         0,      0.0808,      0.0083
       3.1,      0.000,      0.000,         0,      0.2475,      0.0250
       3.8,      0.000,      0.000,         0,      0.4143,      0.0417
       4.5,      0.000,      0.000,         0,      0.5808,      0.0583
       5.2,      0.000,      0.000,         0,      0.7476,      0.0750
       5.8,      0.000,      0.000,         0,      0.9143,      0.0917
       6.4,      0.000,      0.000,         0,      1.0809,      0.1083
       7.0,      0.000,      0.000,         0,      1.2476,      0.1250
       7.6,      0.000,      0.000,         0,      1.4143,      0.1417
       8.1,      0.000,      0.000,         0,      1.5809,      0.1583
       8.7,      0.000,      0.000,         0,      1.7476,      0.1750
       9.2,      0.000,      0.000,         0,      1.9142,      0.1917
       9.7,      0.000,      0.000,         0,      2.0809,      0.2083
      10.2,      0.000,      0.000,         0,      2.2475,      0.2250
      10.7,      0.000,      0.000,         0,      2.4142,      0.2417
      11.1,      0.000,      0.000,         0,      2.5809,      0.2583
      11.6,      0.000,      0.000,         0,      2.7475,      0.2750
      12.0,      0.000,      0.000,         0,      2.9142,      0.2917
      12.4,      0.000,      0.000,         0,      3.0808,      0.3083
      12.8,      0.000,      0.000,         0,      3.2475,      0.3250
      13.2,      0.000,      0.000,         0,      3.4143,      0.3417
      13.6,      0.000,      0.000,         0,      3.5808,      0.3583
      14.0,      0.000,      0.000,         0,      3.7474,      0.3750
      14.4,      0.000,      0.000,         0,      3.9141,      0.3917
      14.8,      0.000,      0.000,         0,      4.0808,      0.4083
      15.2,      0.000,      0.000,         0,      4.2474,      0.4250
      15.5,      0.000,      0.000,         0,      4.4139,      0.4417
      15.9,      0.000,      0.000,         0,      4.5807,      0.4583
      16.3,      0.000,      0.000,         0,      4.7474,      0.4750
      16.6,      0.000,      0.000,         0,      4.9140,      0.4917
      17.0,      0.000,      0.000,         0,      5.0809,      0.5083
      17.4,      0.000,      0.000,         0,      5.2474,      0.5250
      17.7,      0.000,      0.000,         0,      5.4140,      0.5417
      18.1,      0.000,      0.000,         0,      5.5807,      0.5583
      18.5,      0.000,      0.000,         0,      5.7475,      0.5750
      18.8,      0.000,      0.000,         0,      5.9140,      0.5917
      19.2,      0.000,      0.000,         0,      6.0804,      0.6083
      19.5,      0.000,      0.000,         0,      6.2473,      0.6250
      19.9,      0.000,      0.000,         0,      6.4141,      0.6417
      20.2,      0.000,      0.000,         0,      6.5806,      0.6583
      20.6,      0.000,      0.000,         0,      6.7473,      0.6750
      21.0,      0.000,      0.000,         0,      6.9141,      0.6917
      21.3,      0.000,      0.000,         0,      7.0806,      0.7083
      21.7,      0.000,      0.000,         0,      7.2474,      0.7250
      22.0,      0.000,      0.000,         0,      7.4139,      0.7417
      22.4,      0.000,      0.000,         0,      7.5805,      0.7583
      22.7,      0.000,      0.000,         0,      7.7474,      0.7750
      23.1,      0.000,      0.000,         0,      7.9139,      0.7917
      23.4,      0.000,      0.000,         0,      8.0807,      0.8083
      23.8,      0.000,      0.000,         0,      8.2474,      0.8250
      24.1,      0.000,      0.000,         0,      8.4140,      0.8417
      24.5,      0.000,      0.000,         0,      8.5807,      0.8583
      24.8,      0.000,      0.000,         0,      8.7471,      0.8750
      25.1,      0.000,      0.000,         0,      8.9140,      0.8917
      25.4,      0.000,      0.000,         0,      9.0805,      0.9083
      25.8,      0.000,      0.000,         0,      9.2471,      0.9250
      26.1,      0.000,      0.000,         0,      9.4138,      0.9417
      26.4,      0.000,      0.000,         0,      9.5806,      0.9583
      26.7,      0.000,      0.000,         0,      9.7473,      0.9750
      27.0,      0.000,      0.000,         0,      9.9139,      0.9917
      27.3,      0.000,      0.000,         0,     10.0806,      1.0083
      27.7,      0.000,      0.000,         0,     10.2470,      1.0250
      27.9,      0.000,      0.000,         0,     10.4139,      1.0417
      28.1,      0.000,      0.000,         0,     10.5806,      1.0583
      28.1,      0.000,      0.000,         0,     10.7472,      1.0750
      27.3,      0.000,      0.000,         0,     10.9139,      1.0917
       0.1,      0.000,      0.000,         0,     11.0805,      1.1083
       0.1,      0.000,      0.000,         0,     11.2472,      1.1250
       0.1,      0.000,      0.000,         0,     11.4136,      1.1417
       0.1,      0.000,      0.000,         0,     11.5807,      1.1583
       0.1,      0.000,      0.000,         0,     11.7470,      1.1750
       0.1,      0.000,      0.000,         0,     11.9138,      1.1917
       0.1,      0.000,      0.000,         0,     12.0217,      1.2042
       0.1,      0.000,      0.000,         0,     12.0241,      1.2109
       0.1,      0.000,      0.000,         0,     12.0241,      1.2176
       0.1,      0.000,      0.000,         0,     12.0241,      1.2242
       0.1,      0.000,      0.000,         0,     12.0241,      1.2309
       0.1,      0.000,      0.000,         0,     12.0241,      1.2376
       0.1,      0.000,      0.000,         0,     12.0241,      1.2443
       0.1,      0.000,      0.000,         0,     12.0241,      1.2509
       0.1,      0.000,      0.000,         0,     12.0241,      1.2576
       0.1,      0.000,      0.000,         0,     12.0241,      1.2643
       0.1,      0.000,      0.000,         0,     12.0241,      1.2709
       0.1,      0.000,      0.000,         0,     12.0241,      1.2776
       0.1,      0.000,      0.000,         0,     12.0241,      1.2843
       0.1,      0.000,      0.000,         0,     12.0241,      1.2910
       0.1,      0.000,      0.000,         0,     12.0241,      1.2976
       0.1,      0.000,      0.000,         0,     12.0241,      1.3043
       0.1,      0.000,      0.000,         0,     12.0241,      1.3110
       0.1,      0.000,      0.000,         0,     12.0241,      1.3177
       0.1,      0.000,      0.000,         0,     12.0241,      1.3243
       0.1,      0.000,      0.000,         0,     12.0241,      1.3310
       0.1,      0.000,      0.000,         0,     12.0241,      1.3377
       0.1,      0.000,      0.000,         0,     12.0241,      1.3444
       0.1,      0.000,      0.000,         0,     12.0241,      1.3510
       0.1,      0.000,      0.000,         0,     12.0239,      1.3577
       0.1,      0.000,      0.000,         0,     12.0204,      1.3644
       0.1,      0.000,      0.000,         0,     12.0115,      1.3710
       0.1,      0.000,      0.000,         0,     12.0095,      1.3777
       0.1,      0.000,      0.000,         0,     12.0082,      1.3844
       0.1,      0.000,      0.000,         0,     12.0064,      1.3911
       0.1,      0.000,      0.000,         0,     12.0061,      1.3977
       0.1,      0.000,      0.000,         0,     12.0061,      1.4044
       0.1,      0.000,      0.000,         0,     12.0061,      1.4111
       0.1,      0.000,      0.000,         0,     12.0061,      1.4178
       0.1,      0.000,      0.000,         0,     12.0061,      1.4244
       0.1,      0.000,      0.000,         0,     12.0061,      1.4311
       0.1,      0.000,      0.000,         0,     12.0061,      1.4378
       0.1,      0.000,      0.000,         0,     12.0061,      1.4444
       0.1,      0.000,      0.000,         0,     12.0061,      1.4511
       0.1,      0.000,      0.000,         0,     12.0061,      1.4578
       0.1,      0.000,      0.000,         0,     12.0061,      1.4645
       0.1,      0.000,      0.000,         0,     12.0061,      1.4711
       0.1,      0.000,      0.000,         0,     12.0061,      1.4778
       0.1,      0.000,      0.000,         0,     12.0061,      1.4845
       0.1,      0.000,      0.000,         0,     12.0061,      1.4912
       0.1,      0.000,      0.000,         0,     12.0061,      1.4978
       0.1,      0.000,      0.000,         0,     12.0061,      1.5045
       0.1,      0.000,      0.000,         0,     12.0061,      1.5112
       0.1,      0.000,      0.000,         0,     12.0059,      1.5179
       0.1,      0.000,      0.000,         0,     12.0061,      1.5245
       0.1,      0.000,      0.000,         0,     12.0061,      1.5312
       0.1,      0.000,      0.000,         0,     12.0061,      1.5379
       0.1,      0.000,      0.000,         0,     12.0061,      1.5445
       0.1,      0.000,      0.000,         0,     12.0061,      1.5512
       0.1,      0.000,      0.000,         0,     12.0061,      1.5579
       0.1,      0.000,      0.000,         0,     12.0061,      1.5646
       0.1,      0.000,      0.000,         0,     12.0061,      1.5712
       0.1,      0.000,      0.000,         0,     12.0061,      1.5779
       0.1,      0.000,      0.000,         0,     12.0059,      1.5846
       0.1,      0.000,      0.000,         0,     12.0061,      1.5913
       0.1,      0.000,      0.000,         0,     12.0061,      1.5979
       0.1,      0.000,      0.000,         0,     12.0061,      1.6046
       0.1,      0.000,      0.000,         0,     12.0061,      1.6113
       0.1,      0.000,      0.000,         0,     12.0059,      1.6180
       0.1,      0.000,      0.000,         0,     12.0061,      1.6246
       0.1,      0.000,      0.000,         0,     12.0059,      1.6313
       0.1,      0.000,      0.000,         0,     12.0059,      1.6380
       0.1,      0.000,      0.000,         0,     12.0059,      1.6446
       0.1,      0.000,      0.000,         0,     12.0061,      1.6513
       0.1,      0.000,      0.000,         0,     12.0061,      1.6580
       0.1,      0.000,      0.000,         0,     12.0059,      1.6647
       0.1,      0.000,      0.000,         0,     12.0061,      1.6713
       0.1,      0.000,      0.000,         0,     12.0061,      1.6780
       0.1,      0.000,      0.000,         0,     12.0061,      1.6847
       0.1,      0.000,      0.000,         0,     12.0061,      1.6914
       0.1,      0.000,      0.000,         0,     12.0061,      1.6980
       0.1,      0.000,      0.000,         0,     12.0061,      1.7047
       0.1,      0.000,      0.000,         0,     12.0061,      1.7114
       0.1,      0.000,      0.000,         0,     12.0061,      1.7181
       0.1,      0.000,      0.000,         0,     12.0061,      1.7247
       0.1,      0.000,      0.000,         0,     12.0061,      1.7314
       0.1,      0.000,      0.000,         0,     12.0061,      1.7381
       0.1,      0.000,      0.000,         0,     12.0061,      1.7447
       0.1,      0.000,      0.000,         0,     12.0061,      1.7514
       0.1,      0.000,      0.000,         0,     12.0061,      1.7581
       0.1,      0.000,      0.000,         0,     12.0061,      1.7648
       0.1,      0.000,      0.000,         0,     12.0059,      1.7714
       0.1,      0.000,      0.000,         0,     12.0059,      1.7781
       0.1,      0.000,      0.000,         0,     12.0061,      1.7848
       0.1,      0.000,      0.000,         0,     12.0061,      1.7915
       0.1,      0.000,      0.000,         0,     12.0059,      1.7981
       0.1,      0.000,      0.000,         0,     12.0061,      1.8048
       0.1,      0.000,      0.000,         0,     12.0061,      1.8115
       0.1,      0.000,      0.000,         0,     12.0061,      1.8181
       0.1,      0.000,      0.000,         0,     12.0061,      1.8248
       0.1,      0.000,      0.000,         0,     12.0061,      1.8315
       0.1,      0.000,      0.000,         0,     12.0061,      1.8382
       0.1,      0.000,      0.000,         0,     12.0061,      1.8448
       0.1,      0.000,      0.000,         0,     12.0061,      1.8515
       0.1,      0.000,      0.000,         0,     12.0061,      1.8582
       0.1,      0.000,      0.000,         0,     12.0059,      1.8649
       0.1,      0.000,      0.000,         0,     12.0061,      1.8715
       0.1,      0.000,      0.000,         0,     12.0061,      1.8782
       0.1,      0.000,      0.000,         0,     12.0061,      1.8849
       0.1,      0.000,      0.000,         0,     12.0061,      1.8916
       0.1,      0.000,      0.000,         0,     12.0061,      1.8982
       0.1,      0.000,      0.000,         0,     12.0061,      1.9049
       0.1,      0.000,      0.000,         0,     12.0059,      1.9116
       0.1,      0.000,      0.000,         0,     12.0061,      1.9182
       0.1,      0.000,      0.000,         0,     12.0061,      1.9249
       0.1,      0.000,      0.000,         0,     12.0061,      1.9316
       0.1,      0.000,      0.000,         0,     12.0059,      1.9383
       0.1,      0.000,      0.000,         0,     12.0061,      1.9449
       0.1,      0.000,      0.000,         0,     12.0061,      1.9516
       0.1,      0.000,      0.000,         0,     12.0061,      1.9583
       0.1,      0.000,      0.000,         0,     12.0061,      1.9650
       0.1,      0.000,      0.000,         0,     12.0061,      1.9716
       0.1,      0.000,      0.000,         0,     12.0061,      1.9783
       0.1,      0.000,      0.000,         0,     12.0061,      1.9850
       0.1,      0.000,      0.000,         0,     12.0061,      1.9917
       0.1,      0.000,      0.000,         0,     12.0061,      1.9983
       0.1,      0.000,      0.000,         0,     12.0061,      2.0050
       0.1,      0.000,      0.000,         0,     12.0061,      2.0117
       0.1,      0.000,      0.000,         0,     12.0061,      2.0183
       0.1,      0.000,      0.000,         0,     12.0061,      2.0250
       0.1,      0.000,      0.000,         0,     12.0061,      2.0317
       0.1,      0.000,      0.000,         0,     12.0061,      2.0384
       0.1,      0.000,      0.000,         0,     12.0061,      2.0450
       0.1,      0.000,      0.000,         0,     12.0061,      2.0517
       0.1,      0.000,      0.000,         0,     12.0059,      2.0584
       0.1,      0.000,      0.000,         0,     12.0061,      2.0651
       0.1,      0.000,      0.000,         0,     12.0061,      2.0717
       0.1,      0.000,      0.000,         0,     12.0061,      2.0784
       0.1,      0.000,      0.000,         0,     12.0059,      2.0851
       0.1,      0.000,      0.000,         0,     12.0061,      2.0917
       0.1,      0.000,      0.000,         0,     12.0061,      2.0984
       0.1,      0.000,      0.000,         0,     12.0061,      2.1051
       0.1,      0.000,      0.000,         0,     12.0059,      2.1118
       0.1,      0.000,      0.000,         0,     12.0061,      2.1184
       0.1,      0.000,      0.000,         0,     12.0061,      2.1251
       0.1,      0.000,      0.000,         0,     12.0061,      2.1318
       0.1,      0.000,      0.000,         0,     12.0061,      2.1385
       0.1,      0.000,      0.000,         0,     12.0061,      2.1451
       0.1,      0.000,      0.000,         0,     12.0061,      2.1518
       0.1,      0.000,      0.000,         0,     12.0059,      2.1585
       0.1,      0.000,      0.000,         0,     12.0061,      2.1652
       0.1,      0.000,      0.000,         0,     12.0061,      2.1718
       0.1,      0.000,      0.000,         0,     12.0061,      2.1785
       0.1,      0.000,      0.000,         0,     12.0061,      2.1852
       0.1,      0.000,      0.000,         0,     12.0061,      2.1918
       0.1,      0.000,      0.000,         0,     12.0061,      2.1985
       0.1,      0.000,      0.000,         0,     12.0061,      2.2052
       0.1,      0.000,      0.000,         0,     12.0061,      2.2119
       0.1,      0.000,      0.000,         0,     12.0061,      2.2185
       0.1,      0.000,      0.000,         0,     12.0061,      2.2252
       0.1,      0.000,      0.000,         0,     12.0061,      2.2319
       0.1,      0.000,      0.000,         0,     12.0061,      2.2386
       0.1,      0.000,      0.000,         0,     12.0061,      2.2452
       0.1,      0.000,      0.000,         0,     12.0061,      2.2519
       0.1,      0.000,      0.000,         0,     12.0061,      2.2586
       0.1,      0.000,      0.000,         0,     12.0061,      2.2653
       0.1,      0.000,      0.000,         0,     12.0061,      2.2719
       0.1,      0.000,      0.000,         0,     12.0061,      2.2786
       0.1,      0.000,      0.000,         0,     12.0061,      2.2853
       0.1,      0.000,      0.000,         0,     12.0061,      2.2919
       0.1,      0.000,      0.000,         0,     12.0061,      2.2986
       0.1,      0.000,      0.000,         0,     12.0061,      2.3053
       0.1,      0.000,      0.000,         0,     12.0061,      2.3120
       0.1,      0.000,      0.000,         0,     12.0061,      2.3186
       0.1,      0.000,      0.000,         0,     12.0061,      2.3253
       0.1,      0.000,      0.000,         0,     12.0061,      2.3320
       0.1,      0.000,      0.000,         0,     12.0061,      2.3387
       0.1,      0.000,      0.000,         0,     12.0059,      2.3453
       0.1,      0.000,      0.000,         0,     12.0061,      2.3520
       0.1,      0.000,      0.000,         0,     12.0059,      2.3587
       0.1,      0.000,      0.000,         0,     12.0061,      2.3653
       0.1,      0.000,      0.000,         0,     12.0061,      2.3720
       0.1,      0.000,      0.000,         0,     12.0061,      2.3787
       0.1,      0.000,      0.000,         0,     12.0061,      2.3854
       0.1,      0.000,      0.000,         0,     12.0061,      2.3920
       0.1,      0.000,      0.000,         0,     12.0061,      2.3987
       0.1,      0.000,      0.000,         0,     12.0059,      2.4054
       0.1,      0.000,      0.000,         0,     12.0061,      2.4121
       0.1,      0.000,      0.000,         0,     12.0061,      2.4187
       0.1,      0.000,      0.000,         0,     12.0061,      2.4254
       0.1,      0.000,      0.000,         0,     12.0059,      2.4321
       0.1,      0.000,      0.000,         0,     12.0061,      2.4388
       0.1,      0.000,      0.000,         0,     12.0061,      2.4454
       0.1,      0.000,      0.000,         0,     12.0061,      2.4521
       0.1,      0.000,      0.000,         0,     12.0061,      2.4588
       0.1,      0.000,      0.000,         0,     12.0061,      2.4654
       0.1,      0.000,      0.000,         0,     12.0061,      2.4721
       0.1,      0.000,      0.000,         0,     12.0059,      2.4788
       0.1,      0.000,      0.000,         0,     12.0061,      2.4855
       0.1,      0.000,      0.000,         0,     12.0061,      2.4921
       0.1,      0.000,      0.000,         0,     12.0061,      2.4988
       0.1,      0.000,      0.000,         0,     12.0061,      2.5055
       0.1,      0.000,      0.000,         0,     12.0061,      2.5122
       0.1,      0.000,      0.000,         0,     12.0061,      2.5188
       0.1,      0.000,      0.000,         0,     12.0061,      2.5255
       0.1,      0.000,      0.000,         0,     12.0061,      2.5322
       0.1,      0.000,      0.000,         0,     12.0061,      2.5389
       0.1,      0.000,      0.000,         0,     12.0061,      2.5455
       0.1,      0.000,      0.000,         0,     12.0061,      2.5522
       0.1,      0.000,      0.000,         0,     12.0061,      2.5589
       0.1,      0.000,      0.000,         0,     12.0061,      2.5655
       0.1,      0.000,      0.000,         0,     12.0061,      2.5722
       0.1,      0.000,      0.000,         0,     12.0061,      2.5789
       0.1,      0.000,      0.000,         0,     12.0061,      2.5856
       0.1,      0.000,      0.000,         0,     12.0061,      2.5922
       0.1,      0.000,      0.000,         0,     12.0061,      2.5989
       0.1,      0.000,      0.000,         0,     12.0061,      2.6056
       0.1,      0.000,      0.000,         0,     12.0061,      2.6123
       0.1,      0.000,      0.000,         0,     12.0061,      2.6189
       0.1,      0.000,      0.000,         0,     12.0059,      2.6256
       0.1,      0.000,      0.000,         0,     12.0061,      2.6323
       0.1,      0.000,      0.000,         0,     12.0061,      2.6389
       0.1,      0.000,      0.000,         0,     12.0061,      2.6456
       0.1,      0.000,      0.000,         0,     12.0061,      2.6523
       0.1,      0.000,      0.000,         0,     12.0061,      2.6590
       0.1,      0.000,      0.000,         0,     12.0061,      2.6656
       0.1,      0.000,      0.000,         0,     12.0061,      2.6723
       0.1,      0.000,      0.000,         0,     12.0061,      2.6790
       0.1,      0.000,      0.000,         0,     12.0061,      2.6857
       0.1,      0.000,      0.000,         0,     12.0061,      2.6923
       0.1,      0.000,      0.000,         0,     12.0061,      2.6990
       0.1,      0.000,      0.000,         0,     12.0061,      2.7057
       0.1,      0.000,      0.000,         0,     12.0061,      2.7124
       0.1,      0.000,      0.000,         0,     12.0061,      2.7190
       0.1,      0.000,      0.000,         0,     12.0061,      2.7257
       0.1,      0.000,      0.000,         0,     12.0061,      2.7324
       0.1,      0.000,      0.000,         0,     12.0061,      2.7390
       0.1,      0.000,      0.000,         0,     12.0061,      2.7457
       0.1,      0.000,      0.000,         0,     12.0061,      2.7524
       0.1,      0.000,      0.000,         0,     12.0061,      2.7591
       0.1,      0.000,      0.000,         0,     12.0061,      2.7657
       0.1,      0.000,      0.000,         0,     12.0061,      2.7724
       0.1,      0.000,      0.000,         0,     12.0061,      2.7791
       0.1,      0.000,      0.000,         0,     12.0061,      2.7858
       0.1,      0.000,      0.000,         0,     12.0061,      2.7924
       0.1,      0.000,      0.000,         0,     12.0061,      2.7991
       0.1,      0.000,      0.000,         0,     12.0061,      2.8058
       0.1,      0.000,      0.000,         0,     12.0061,      2.8125
       0.1,      0.000,      0.000,         0,     12.0061,      2.8191
       0.1,      0.000,      0.000,         0,     12.0061,      2.8258
       0.1,      0.000,      0.000,         0,     12.0061,      2.8325
       0.1,      0.000,      0.000,         0,     12.0061,      2.8391
       0.1,      0.000,      0.000,         0,     12.0061,      2.8458
       0.1,      0.000,      0.000,         0,     12.0061,      2.8525
       0.1,      0.000,      0.000,         0,     12.0061,      2.8592
       0.1,      0.000,      0.000,         0,     12.0061,      2.8658
       0.1,      0.000,      0.000,         0,     12.0061,      2.8725
       0.1,      0.000,      0.000,         0,     12.0059,      2.8792
       0.1,      0.000,      0.000,         0,     12.0061,      2.8859
       0.1,      0.000,      0.000,         0,     12.0061,      2.8925
       0.1,      0.000,      0.000,         0,     12.0061,      2.8992
       0.1,      0.000,      0.000,         0,     12.0061,      2.9059
       0.1,      0.000,      0.000,         0,     12.0061,      2.9125
       0.1,      0.000,      0.000,         0,     12.0059,      2.9192
       0.1,      0.000,      0.000,         0,     12.0061,      2.9259
       0.1,      0.000,      0.000,         0,     12.0059,      2.9326
       0.1,      0.000,      0.000,         0,     12.0061,      2.9392
       0.1,      0.000,      0.000,         0,     12.0059,      2.9459
       0.1,      0.000,      0.000,         0,     12.0061,      2.9526
       0.1,      0.000,      0.000,         0,     12.0061,      2.9593
       0.1,      0.000,      0.000,         0,     12.0061,      2.9659
       0.1,      0.000,      0.000,         0,     12.0061,      2.9726
       0.1,      0.000,      0.000,         0,     12.0061,      2.9793
       0.1,      0.000,      0.000,         0,     12.0061,      2.9860
       0.1,      0.000,      0.000,         0,     12.0061,      2.9926
       0.1,      0.000,      0.000,         0,     12.0059,      2.9993
       0.1,      0.000,      0.000,         0,     12.0061,      3.0060
       0.1,      0.000,      0.000,         0,     12.0061,      3.0126
       0.1,      0.000,      0.000,         0,     12.0061,      3.0193
       0.1,      0.000,      0.000,         0,     12.0061,      3.0260
       0.1,      0.000,      0.000,         0,     12.0059,      3.0327
       0.1,      0.000,      0.000,         0,     12.0061,      3.0393
       0.1,      0.000,      0.000,         0,     12.0061,      3.0460
       0.1,      0.000,      0.000,         0,     12.0061,      3.0527
       0.1,      0.000,      0.000,         0,     12.0061,      3.0594
       0.1,      0.000,      0.000,         0,     12.0059,      3.0660
       0.1,      0.000,      0.000,         0,     12.0061,      3.0727
       0.1,      0.000,      0.000,         0,     12.0061,      3.0794
       0.1,      0.000,      0.000,         0,     12.0061,      3.0861
       0.1,      0.000,      0.000,         0,     12.0059,      3.0927
       0.1,      0.000,      0.000,         0,     12.0061,      3.0994
       0.1,      0.000,      0.000,         0,     12.0061,      3.1061
       0.1,      0.000,      0.000,         0,     12.0061,      3.1127
       0.1,      0.000,      0.000,         0,     12.0061,      3.1194
       0.1,      0.000,      0.000,         0,     12.0061,      3.1261
       0.1,      0.000,      0.000,         0,     12.0061,      3.1328
       0.1,      0.000,      0.000,         0,     12.0061,      3.1394
       0.1,      0.000,      0.000,         0,     12.0061,      3.1461
       0.1,      0.000,      0.000,         0,     12.0059,      3.1528
       0.1,      0.000,      0.000,         0,     12.0061,      3.1595
       0.1,      0.000,      0.000,         0,     12.0061,      3.1661
       0.1,      0.000,      0.000,         0,     12.0061,      3.1728
       0.1,      0.000,      0.000,         0,     12.0061,      3.1795
       0.1,      0.000,      0.000,         0,     12.0061,      3.1861
       0.1,      0.000,      0.000,         0,     12.0061,      3.1928
       0.1,      0.000,      0.000,         0,     12.0061,      3.1995
       0.1,      0.000,      0.000,         0,     12.0061,      3.2062
       0.1,      0.000,      0.000,         0,     12.0061,      3.2128
       0.1,      0.000,      0.000,         0,     12.0061,      3.2195
       0.1,      0.000,      0.000,         0,     12.0061,      3.2262
       0.1,      0.000,      0.000,         0,     12.0061,      3.2329
       0.1,      0.000,      0.000,         0,     12.0061,      3.2395
       0.1,      0.000,      0.000,         0,     12.0061,      3.2462
       0.1,      0.000,      0.000,         0,     12.0061,      3.2529
       0.1,      0.000,      0.000,         0,     12.0061,      3.2596
       0.1,      0.000,      0.000,         0,     12.0061,      3.2662
       0.1,      0.000,      0.000,         0,     12.0061,      3.2729
       0.1,      0.000,      0.000,         0,     12.0061,      3.2796
       0.1,      0.000,      0.000,         0,     12.0061,      3.2862
       0.1,      0.000,      0.000,         0,     12.0061,      3.2929
       0.1,      0.000,      0.000,         0,     12.0061,      3.2996
       0.1,      0.000,      0.000,         0,     12.0061,      3.3063
       0.1,      0.000,      0.000,         0,     12.0061,      3.3129
       0.1,      0.000,      0.000,         0,     12.0061,      3.3196
       0.1,      0.000,      0.000,         0,     12.0061,      3.3263
       0.1,      0.000,      0.000,         0,     12.0061,      3.3330
       0.1,      0.000,      0.000,         0,     12.0061,      3.3396
       0.1,      0.000,      0.000,         0,     12.0061,      3.3463
       0.1,      0.000,      0.000,         0,     12.0061,      3.3530
       0.1,      0.000,      0.000,         0,     12.0061,      3.3597
       0.1,      0.000,      0.000,         0,     12.0061,      3.3663
       0.1,      0.000,      0.000,         0,     12.0061,      3.3730
       0.1,      0.000,      0.000,         0,     12.0061,      3.3797
       0.1,      0.000,      0.000,         0,     12.0061,      3.3863
       0.1,      0.000,      0.000,         0,     12.0061,      3.3930
       0.1,      0.000,      0.000,         0,     12.0061,      3.3997
       0.1,      0.000,      0.000,         0,     12.0061,      3.4064
       0.1,      0.000,      0.000,         0,     12.0061,      3.4130
       0.1,      0.000,      0.000,         0,     12.0061,      3.4197
       0.1,      0.000,      0.000,         0,     12.0059,      3.4264
       0.1,      0.000,      0.000,         0,     12.0061,      3.4331
       0.1,      0.000,      0.000,         0,     12.0061,      3.4397
       0.1,      0.000,      0.000,         0,     12.0061,      3.4464
       0.1,      0.000,      0.000,         0,     12.0061,      3.4531
       0.1,      0.000,      0.000,         0,     12.0061,      3.4597
       0.1,      0.000,      0.000,         0,     12.0061,      3.4664
       0.1,      0.000,      0.000,         0,     12.0061,      3.4731
       0.1,      0.000,      0.000,         0,     12.0061,      3.4798
       0.1,      0.000,      0.000,         0,     12.0059,      3.4864
       0.1,      0.000,      0.000,         0,     12.0061,      3.4931
       0.1,      0.000,      0.000,         0,     12.0061,      3.4998
       0.1,      0.000,      0.000,         0,     12.0061,      3.5065
       0.1,      0.000,      0.000,         0,     12.0061,      3.5131
       0.1,      0.000,      0.000,         0,     12.0061,      3.5198
       0.1,      0.000,      0.000,         0,     12.0061,      3.5265
       0.1,      0.000,      0.000,         0,     12.0061,      3.5332
       0.1,      0.000,      0.000,         0,     12.0061,      3.5398
       0.1,      0.000,      0.000,         0,     12.0061,      3.5465
       0.1,      0.000,      0.000,         0,     12.0061,      3.5532
       0.1,      0.000,      0.000,         0,     12.0061,      3.5598
       0.1,      0.000,      0.000,         0,     12.0061,      3.5665
       0.1,      0.000,      0.000,         0,     12.0061,      3.5732
       0.1,      0.000,      0.000,         0,     12.0061,      3.5799
       0.1,      0.000,      0.000,         0,     12.0061,      3.5865
       0.1,      0.000,      0.000,         0,     12.0061,      3.5932
       0.1,      0.000,      0.000,         0,     12.0059,      3.5999
       0.1,      0.000,      0.000,         0,     12.0061,      3.6066
       0.1,      0.000,      0.000,         0,     12.0061,      3.6132
       0.1,      0.000,      0.000,         0,     12.0061,      3.6199
       0.1,      0.000,      0.000,         0,     12.0061,      3.6266
       0.1,      0.000,      0.000,         0,     12.0059,      3.6333
       0.1,      0.000,      0.000,         0,     12.0059,      3.6399
       0.1,      0.000,      0.000,         0,     12.0061,      3.6466
       0.1,      0.000,      0.000,         0,     12.0061,      3.6533
       0.1,      0.000,      0.000,         0,     12.0061,      3.6599
       0.1,      0.000,      0.000,         0,     12.0061,      3.6666
       0.1,      0.000,      0.000,         0,     12.0061,      3.6733
       0.1,      0.000,      0.000,         0,     12.0061,      3.6800
       0.1,      0.000,      0.000,         0,     12.0061,      3.6866
       0.1,      0.000,      0.000,         0,     12.0061,      3.6933
       0.1,      0.000,      0.000,         0,     12.0061,      3.7000
       0.1,      0.000,      0.000,         0,     12.0061,      3.7067
       0.1,      0.000,      0.000,         0,     12.0061,      3.7133
       0.1,      0.000,      0.000,         0,     12.0061,      3.7200
       0.1,      0.000,      0.000,         0,     12.0061,      3.7267
       0.1,      0.000,      0.000,         0,     12.0061,      3.7333
       0.1,      0.000,      0.000,         0,     12.0061,      3.7400
       0.1,      0.000,      0.000,         0,     12.0061,      3.7467
       0.1,      0.000,      0.000,         0,     12.0061,      3.7534
       0.1,      0.000,      0.000,         0,     12.0061,      3.7600
       0.1,      0.000,      0.000,         0,     12.0061,      3.7667
       0.1,      0.000,      0.000,         0,     12.0061,      3.7734
       0.1,      0.000,      0.000,         0,     12.0061,      3.7801
       0.1,      0.000,      0.000,         0,     12.0061,      3.7867
       0.1,      0.000,      0.000,         0,     12.0061,      3.7934
       0.1,      0.000,      0.000,         0,     12.0061,      3.8001
       0.1,      0.000,      0.000,         0,     12.0061,      3.8068
       0.1,      0.000,      0.000,         0,     12.0061,      3.8134
       0.1,      0.000,      0.000,         0,     12.0061,      3.8201
       0.1,      0.000,      0.000,         0,     12.0061,      3.8268
       0.1,      0.000,      0.000,         0,     12.0061,      3.8334
       0.1,      0.000,      0.000,         0,     12.0061,      3.8401
       0.1,      0.000,      0.000,         0,     12.0061,      3.8468
       0.1,      0.000,      0.000,         0,     12.0061,      3.8535
       0.1,      0.000,      0.000,         0,     12.0061,      3.8601
       0.1,      0.000,      0.000,         0,     12.0061,      3.8668
       0.1,      0.000,      0.000,         0,     12.0061,      3.8735
       0.1,      0.000,      0.000,         0,     12.0061,      3.8802
       0.1,      0.000,      0.000,         0,     12.0061,      3.8868
       0.1,      0.000,      0.000,         0,     12.0061,      3.8935
       0.1,      0.000,      0.000,         0,     12.0061,      3.9002
       0.1,      0.000,      0.000,         0,     12.0061,      3.9069
       0.1,      0.000,      0.000,         0,     12.0061,      3.9135
       0.1,      0.000,      0.000,         0,     12.0061,      3.9202
       0.1,      0.000,      0.000,         0,     12.0061,      3.9269
       0.1,      0.000,      0.000,         0,     12.0061,      3.9335
       0.1,      0.000,      0.000,         0,     12.0061,      3.9402
       0.1,      0.000,      0.000,         0,     12.0061,      3.9469
       0.1,      0.000,      0.000,         0,     12.0061,      3.9536
       0.1,      0.000,      0.000,         0,     12.0061,      3.9602
       0.1,      0.000,      0.000,         0,     12.0061,      3.9669
       0.1,      0.000,      0.000,         0,     12.0061,      3.9736
       0.1,      0.000,      0.000,         0,     12.0061,      3.9803
       0.1,      0.000,      0.000,         0,     12.0061,      3.9869
       0.1,      0.000,      0.000,         0,     12.0061,      3.9936
       0.1,      0.000,      0.000,         0,     12.0059,      4.0003
       0.1,      0.000,      0.000,         0,     12.0061,      4.0069
       0.1,      0.000,      0.000,         0,     12.0061,      4.0136
       0.1,      0.000,      0.000,         0,     12.0059,      4.0203
       0.1,      0.000,      0.000,         0,     12.0061,      4.0270
       0.1,      0.000,      0.000,         0,     12.0061,      4.0336
       0.1,      0.000,      0.000,         0,     12.0061,      4.0403
       0.1,      0.000,      0.000,         0,     12.0061,      4.0470
       0.1,      0.000,      0.000,         0,     12.0061,      4.0537
       0.1,      0.000,      0.000,         0,     12.0061,      4.0603
       0.1,      0.000,      0.000,         0,     12.0061,      4.0670
       0.1,      0.000,      0.000,         0,     12.0059,      4.0737
       0.1,      0.000,      0.000,         0,     12.0061,      4.0804
       0.1,      0.000,      0.000,         0,     12.0059,      4.0870
       0.1,      0.000,      0.000,         0,     12.0061,      4.0937
       0.1,      0.000,      0.000,         0,     12.0061,      4.1004
       0.1,      0.000,      0.000,         0,     12.0061,      4.1070
       0.1,      0.000,      0.000,         0,     12.0061,      4.1137
       0.1,      0.000,      0.000,         0,     12.0061,      4.1204
       0.1,      0.000,      0.000,         0,     12.0061,      4.1271
       0.1,      0.000,      0.000,         0,     12.0061,      4.1337
       0.1,      0.000,      0.000,         0,     12.0061,      4.1404
       0.1,      0.000,      0.000,         0,     12.0061,      4.1471
       0.1,      0.000,      0.000,         0,     12.0061,      4.1538
       0.1,      0.000,      0.000,         0,     12.0061,      4.1604
       0.1,      0.000,      0.000,         0,     12.0061,      4.1671
       0.1,      0.000,      0.000,         0,     12.0061,      4.1738
       0.1,      0.000,      0.000,         0,     12.0061,      4.1805
       0.1,      0.000,      0.000,         0,     12.0061,      4.1871
       0.1,      0.000,      0.000,         0,     12.0059,      4.1938
       0.1,      0.000,      0.000,         0,     12.0061,      4.2005
       0.1,      0.000,      0.000,         0,     12.0061,      4.2071
       0.1,      0.000,      0.000,         0,     12.0059,      4.2138
       0.1,      0.000,      0.000,         0,     12.0061,      4.2205
       0.1,      0.000,      0.000,         0,     12.0061,      4.2272
       0.1,      0.000,      0.000,         0,     12.0061,      4.2338
       0.1,      0.000,      0.000,         0,     12.0059,      4.2405
       0.1,      0.000,      0.000,         0,     12.0061,      4.2472
       0.1,      0.000,      0.000,         0,     12.0061,      4.2539
       0.1,      0.000,      0.000,         0,     12.0061,      4.2605
       0.1,      0.000,      0.000,         0,     12.0061,      4.2672
       0.1,      0.000,      0.000,         0,     12.0061,      4.2739
       0.1,      0.000,      0.000,         0,     12.0061,      4.2806
       0.1,      0.000,      0.000,         0,     12.0061,      4.2872
       0.1,      0.000,      0.000,         0,     12.0061,      4.2939
       0.1,      0.000,      0.000,         0,     12.0059,      4.3006
       0.1,      0.000,      0.000,         0,     12.0061,      4.3072
       0.1,      0.000,      0.000,         0,     12.0061,      4.3139
       0.1,      0.000,      0.000,         0,     12.0061,      4.3206
       0.1,      0.000,      0.000,         0,     12.0061,      4.3273
       0.1,      0.000,      0.000,         0,     12.0061,      4.3339
       0.1,      0.000,      0.000,         0,     12.0061,      4.3406
       0.1,      0.000,      0.000,         0,     12.0061,      4.3473
       0.1,      0.000,      0.000,         0,     12.0061,      4.3540
       0.1,      0.000,      0.000,         0,     12.0061,      4.3606
       0.1,      0.000,      0.000,         0,     12.0061,      4.3673
       0.1,      0.000,      0.000,         0,     12.0059,      4.3740
       0.1,      0.000,      0.000,         0,     12.0061,      4.3806
       0.1,      0.000,      0.000,         0,     12.0061,      4.3873
       0.1,      0.000,      0.000,         0,     12.0061,      4.3940
       0.1,      0.000,      0.000,         0,     12.0061,      4.4007
       0.1,      0.000,      0.000,         0,     12.0061,      4.4073
       0.1,      0.000,      0.000,         0,     12.0061,      4.4140
       0.1,      0.000,      0.000,         0,     12.0061,      4.4207
       0.1,      0.000,      0.000,         0,     12.0061,      4.4274
       0.1,      0.000,      0.000,         0,     12.0061,      4.4340
       0.1,      0.000,      0.000,         0,     12.0061,      4.4407
       0.1,      0.000,      0.000,         0,     12.0061,      4.4474
       0.1,      0.000,      0.000,         0,     12.0061,      4.4541
       0.1,      0.000,      0.000,         0,     12.0061,      4.4607
       0.1,      0.000,      0.000,         0,     12.0061,      4.4674
       0.1,      0.000,      0.000,         0,     12.0061,      4.4741
       0.1,      0.000,      0.000,         0,     12.0061,      4.4807
       0.1,      0.000,      0.000,         0,     12.0061,      4.4874
       0.1,      0.000,      0.000,         0,     12.0061,      4.4941
       0.1,      0.000,      0.000,         0,     12.0061,      4.5008
       0.1,      0.000,      0.000,         0,     12.0061,      4.5074
       0.1,      0.000,      0.000,         0,     12.0059,      4.5141
       0.1,      0.000,      0.000,         0,     12.0061,      4.5208
       0.1,      0.000,      0.000,         0,     12.0061,      4.5275
       0.1,      0.000,      0.000,         0,     12.0059,      4.5341
       0.1,      0.000,      0.000,         0,     12.0061,      4.5408
       0.1,      0.000,      0.000,         0,     12.0061,      4.5475
       0.1,      0.000,      0.000,         0,     12.0061,      4.5542
       0.1,      0.000,      0.000,         0,     12.0061,      4.5608
       0.1,      0.000,      0.000,         0,     12.0061,      4.5675
       0.1,      0.000,      0.000,         0,     12.0061,      4.5742
       0.1,      0.000,      0.000,         0,     12.0061,      4.5808
       0.1,      0.000,      0.000,         0,     12.0061,      4.5875
       0.1,      0.000,      0.000,         0,     12.0061,      4.5942
       0.1,      0.000,      0.000,         0,     12.0061,      4.6009
       0.1,      0.000,      0.000,         0,     12.0061,      4.6075
       0.1,      0.000,      0.000,         0,     12.0061,      4.6142
       0.1,      0.000,      0.000,         0,     12.0061,      4.6209
       0.1,      0.000,      0.000,         0,     12.0061,      4.6276
       0.1,      0.000,      0.000,         0,     12.0061,      4.6342
       0.1,      0.000,      0.000,         0,     12.0061,      4.6409
       0.1,      0.000,      0.000,         0,     12.0061,      4.6476
       0.1,      0.000,      0.000,         0,     12.0061,      4.6542
       0.1,      0.000,      0.000,         0,     12.0059,      4.6609
       0.1,      0.000,      0.000,         0,     12.0061,      4.6676
       0.1,      0.000,      0.000,         0,     12.0061,      4.6743
       0.1,      0.000,      0.000,         0,     12.0061,      4.6809
       0.1,      0.000,      0.000,         0,     12.0061,      4.6876
       0.1,      0.000,      0.000,         0,     12.0061,      4.6943
       0.1,      0.000,      0.000,         0,     12.0061,      4.7010
       0.1,      0.000,      0.000,         0,     12.0059,      4.7076
       0.1,      0.000,      0.000,         0,     12.0061,      4.7143
       0.1,      0.000,      0.000,         0,     12.0061,      4.7210
       0.1,      0.000,      0.000,         0,     12.0061,      4.7277
       0.1,      0.000,      0.000,         0,     12.0061,      4.7343
       0.1,      0.000,      0.000,         0,     12.0061,      4.7410
       0.1,      0.000,      0.000,         0,     12.0061,      4.7477
       0.1,      0.000,      0.000,         0,     12.0061,      4.7543
       0.1,      0.000,      0.000,         0,     12.0061,      4.7610
       0.1,      0.000,      0.000,         0,     12.0061,      4.7677
       0.1,      0.000,      0.000,         0,     12.0061,      4.7744
       0.1,      0.000,      0.000,         0,     12.0061,      4.7810
       0.1,      0.000,      0.000,         0,     12.0061,      4.7877
       0.1,      0.000,      0.000,         0,     12.0061,      4.7944
       0.1,      0.000,      0.000,         0,     12.0061,      4.8011
       0.1,      0.000,      0.000,         0,     12.0061,      4.8077
       0.1,      0.000,      0.000,         0,     12.0061,      4.8144
       0.1,      0.000,      0.000,         0,     12.0061,      4.8211
       0.1,      0.000,      0.000,         0,     12.0061,      4.8278
       0.1,      0.000,      0.000,         0,     12.0061,      4.8344
       0.1,      0.000,      0.000,         0,     12.0061,      4.8411
       0.1,      0.000,      0.000,         0,     12.0061,      4.8478
       0.1,      0.000,      0.000,         0,     12.0061,      4.8544
       0.1,      0.000,      0.000,         0,     12.0061,      4.8611
       0.1,      0.000,      0.000,         0,     12.0061,      4.8678
       0.1,      0.000,      0.000,         0,     12.0061,      4.8745
       0.1,      0.000,      0.000,         0,     12.0061,      4.8811
       0.1,      0.000,      0.000,         0,     12.0061,      4.8878
       0.1,      0.000,      0.000,         0,     12.0061,      4.8945
       0.1,      0.000,      0.000,         0,     12.0061,      4.9012
       0.1,      0.000,      0.000,         0,     12.0061,      4.9078
       0.1,      0.000,      0.000,         0,     12.0061,      4.9145
       0.1,      0.000,      0.000,         0,     12.0061,      4.9212
       0.1,      0.000,      0.000,         0,     12.0061,      4.9278
       0.1,      0.000,      0.000,         0,     12.0061,      4.9345
       0.1,      0.000,      0.000,         0,     12.0061,      4.9412
       0.1,      0.000,      0.000,         0,     12.0061,      4.9479
       0.1,      0.000,      0.000,         0,     12.0061,      4.9545
       0.1,      0.000,      0.000,         0,     12.0061,      4.9579