File: Alban repo/Quiz 1/suction cup instron tests/july-2020-force-vs-separaion-speed_raw-data/d30e10-01-inwater-onwhiteplatic-diaphragmpump-06mm-test1.raw
Operator: 1

Date,Time,Specimen#
07/02/20,12:34:29,1

---------------------------------------


Area (mm^2):,      1.00,Flat,     25.40,     25.40,     25.40
Gage Len (mm):,     25.40


LOAD (N),STRAIN 1 (mm),STRAIN 2 (mm),STRESS (MPa),POSITION (mm),TIME (min)
       2.0,      0.000,      0.000,         0,      0.0042,      0.0083
       2.4,      0.000,      0.000,         0,      0.0292,      0.0500
       2.7,      0.000,      0.000,         0,      0.0542,      0.0917
       3.0,      0.000,      0.000,         0,      0.0792,      0.1333
       3.3,      0.000,      0.000,         0,      0.1041,      0.1750
       3.7,      0.000,      0.000,         0,      0.1292,      0.2167
       4.0,      0.000,      0.000,         0,      0.1542,      0.2583
       4.2,      0.000,      0.000,         0,      0.1791,      0.3000
       4.5,      0.000,      0.000,         0,      0.2042,      0.3417
       4.8,      0.000,      0.000,         0,      0.2293,      0.3833
       5.1,      0.000,      0.000,         0,      0.2547,      0.4250
       5.3,      0.000,      0.000,         0,      0.2792,      0.4667
       5.6,      0.000,      0.000,         0,      0.3044,      0.5083
       5.8,      0.000,      0.000,         0,      0.3296,      0.5500
       6.1,      0.000,      0.000,         0,      0.3541,      0.5917
       6.3,      0.000,      0.000,         0,      0.3801,      0.6333
       6.6,      0.000,      0.000,         0,      0.4042,      0.6750
       6.8,      0.000,      0.000,         0,      0.4292,      0.7167
       7.1,      0.000,      0.000,         0,      0.4542,      0.7583
       7.3,      0.000,      0.000,         0,      0.4792,      0.8000
       7.6,      0.000,      0.000,         0,      0.5043,      0.8417
       7.8,      0.000,      0.000,         0,      0.5292,      0.8833
       8.0,      0.000,      0.000,         0,      0.5542,      0.9250
       8.3,      0.000,      0.000,         0,      0.5792,      0.9667
       8.5,      0.000,      0.000,         0,      0.6041,      1.0083
       8.7,      0.000,      0.000,         0,      0.6293,      1.0500
       8.9,      0.000,      0.000,         0,      0.6542,      1.0917
       9.2,      0.000,      0.000,         0,      0.6791,      1.1333
       9.4,      0.000,      0.000,         0,      0.7042,      1.1750
       9.6,      0.000,      0.000,         0,      0.7292,      1.2167
       9.8,      0.000,      0.000,         0,      0.7543,      1.2583
      10.1,      0.000,      0.000,         0,      0.7792,      1.3000
      10.3,      0.000,      0.000,         0,      0.8044,      1.3417
      10.5,      0.000,      0.000,         0,      0.8292,      1.3833
      10.7,      0.000,      0.000,         0,      0.8541,      1.4250
      10.9,      0.000,      0.000,         0,      0.8791,      1.4667
      11.1,      0.000,      0.000,         0,      0.9042,      1.5083
      11.3,      0.000,      0.000,         0,      0.9292,      1.5500
      11.5,      0.000,      0.000,         0,      0.9541,      1.5917
      11.7,      0.000,      0.000,         0,      0.9791,      1.6333
      11.9,      0.000,      0.000,         0,      1.0041,      1.6750
      12.1,      0.000,      0.000,         0,      1.0291,      1.7167
      12.3,      0.000,      0.000,         0,      1.0542,      1.7583
      12.5,      0.000,      0.000,         0,      1.0791,      1.8000
      12.7,      0.000,      0.000,         0,      1.1042,      1.8417
      12.9,      0.000,      0.000,         0,      1.1291,      1.8833
      13.1,      0.000,      0.000,         0,      1.1542,      1.9250
      13.2,      0.000,      0.000,         0,      1.1793,      1.9667
      13.4,      0.000,      0.000,         0,      1.2041,      2.0083
      13.6,      0.000,      0.000,         0,      1.2293,      2.0500
      13.8,      0.000,      0.000,         0,      1.2542,      2.0917
      13.9,      0.000,      0.000,         0,      1.2792,      2.1333
      14.1,      0.000,      0.000,         0,      1.3041,      2.1750
      14.3,      0.000,      0.000,         0,      1.3291,      2.2167
      14.4,      0.000,      0.000,         0,      1.3542,      2.2583
      14.6,      0.000,      0.000,         0,      1.3790,      2.3000
      14.7,      0.000,      0.000,         0,      1.4041,      2.3417
      14.9,      0.000,      0.000,         0,      1.4292,      2.3833
      15.0,      0.000,      0.000,         0,      1.4540,      2.4250
      15.2,      0.000,      0.000,         0,      1.4797,      2.4667
      15.3,      0.000,      0.000,         0,      1.5042,      2.5083
      15.4,      0.000,      0.000,         0,      1.5299,      2.5500
      15.5,      0.000,      0.000,         0,      1.5543,      2.5917
      15.5,      0.000,      0.000,         0,      1.5792,      2.6333
      14.8,      0.000,      0.000,         0,      1.6047,      2.6750
      14.5,      0.000,      0.000,         0,      1.6291,      2.7167
      14.5,      0.000,      0.000,         0,      1.6541,      2.7583
      14.6,      0.000,      0.000,         0,      1.6791,      2.8000
      14.8,      0.000,      0.000,         0,      1.7042,      2.8417
      14.9,      0.000,      0.000,         0,      1.7291,      2.8833
      15.0,      0.000,      0.000,         0,      1.7541,      2.9250
      15.1,      0.000,      0.000,         0,      1.7790,      2.9667
      15.1,      0.000,      0.000,         0,      1.8041,      3.0083
      15.3,      0.000,      0.000,         0,      1.8292,      3.0500
      15.4,      0.000,      0.000,         0,      1.8542,      3.0917
      15.4,      0.000,      0.000,         0,      1.8792,      3.1333
      15.5,      0.000,      0.000,         0,      1.9042,      3.1750
      15.6,      0.000,      0.000,         0,      1.9291,      3.2167
      15.7,      0.000,      0.000,         0,      1.9541,      3.2583
      15.8,      0.000,      0.000,         0,      1.9792,      3.3000
      15.9,      0.000,      0.000,         0,      2.0042,      3.3417
      16.0,      0.000,      0.000,         0,      2.0291,      3.3833
      16.0,      0.000,      0.000,         0,      2.0540,      3.4250
      16.1,      0.000,      0.000,         0,      2.0792,      3.4667
      16.2,      0.000,      0.000,         0,      2.1041,      3.5083
      16.3,      0.000,      0.000,         0,      2.1291,      3.5500
      16.4,      0.000,      0.000,         0,      2.1541,      3.5917
      16.5,      0.000,      0.000,         0,      2.1791,      3.6333
      16.5,      0.000,      0.000,         0,      2.2040,      3.6750
      16.6,      0.000,      0.000,         0,      2.2290,      3.7167
      16.7,      0.000,      0.000,         0,      2.2540,      3.7583
      16.8,      0.000,      0.000,         0,      2.2793,      3.8000
      16.8,      0.000,      0.000,         0,      2.3041,      3.8417
      16.9,      0.000,      0.000,         0,      2.3300,      3.8833
      17.0,      0.000,      0.000,         0,      2.3540,      3.9250
      17.0,      0.000,      0.000,         0,      2.3790,      3.9667
      17.1,      0.000,      0.000,         0,      2.4043,      4.0083
      17.2,      0.000,      0.000,         0,      2.4291,      4.0500
      17.2,      0.000,      0.000,         0,      2.4546,      4.0917
      17.3,      0.000,      0.000,         0,      2.4791,      4.1333
      17.3,      0.000,      0.000,         0,      2.5040,      4.1750
      17.4,      0.000,      0.000,         0,      2.5291,      4.2167
      17.5,      0.000,      0.000,         0,      2.5541,      4.2583
      17.6,      0.000,      0.000,         0,      2.5791,      4.3000
      17.6,      0.000,      0.000,         0,      2.6041,      4.3417
      17.7,      0.000,      0.000,         0,      2.6291,      4.3833
      17.7,      0.000,      0.000,         0,      2.6542,      4.4250
      17.8,      0.000,      0.000,         0,      2.6791,      4.4667
      17.9,      0.000,      0.000,         0,      2.7042,      4.5083
      17.9,      0.000,      0.000,         0,      2.7290,      4.5500
      18.0,      0.000,      0.000,         0,      2.7541,      4.5917
      18.0,      0.000,      0.000,         0,      2.7791,      4.6333
      18.1,      0.000,      0.000,         0,      2.8041,      4.6750
      18.2,      0.000,      0.000,         0,      2.8300,      4.7167
      18.2,      0.000,      0.000,         0,      2.8540,      4.7583
      18.3,      0.000,      0.000,         0,      2.8790,      4.8000
      18.3,      0.000,      0.000,         0,      2.9041,      4.8417
      18.4,      0.000,      0.000,         0,      2.9289,      4.8833
      18.4,      0.000,      0.000,         0,      2.9541,      4.9250
      18.5,      0.000,      0.000,         0,      2.9790,      4.9667
      18.6,      0.000,      0.000,         0,      3.0040,      5.0083
      18.6,      0.000,      0.000,         0,      3.0290,      5.0500
      18.7,      0.000,      0.000,         0,      3.0540,      5.0917
      18.7,      0.000,      0.000,         0,      3.0791,      5.1333
      18.8,      0.000,      0.000,         0,      3.1041,      5.1750
      18.9,      0.000,      0.000,         0,      3.1290,      5.2167
      18.9,      0.000,      0.000,         0,      3.1541,      5.2583
      19.0,      0.000,      0.000,         0,      3.1792,      5.3000
      19.0,      0.000,      0.000,         0,      3.2041,      5.3417
      19.1,      0.000,      0.000,         0,      3.2291,      5.3833
      19.1,      0.000,      0.000,         0,      3.2540,      5.4250
      19.2,      0.000,      0.000,         0,      3.2791,      5.4667
      19.2,      0.000,      0.000,         0,      3.3041,      5.5083
      19.3,      0.000,      0.000,         0,      3.3290,      5.5500
      19.4,      0.000,      0.000,         0,      3.3540,      5.5917
      19.4,      0.000,      0.000,         0,      3.3791,      5.6333
      19.5,      0.000,      0.000,         0,      3.4040,      5.6750
      19.5,      0.000,      0.000,         0,      3.4291,      5.7167
      19.6,      0.000,      0.000,         0,      3.4540,      5.7583
      19.6,      0.000,      0.000,         0,      3.4790,      5.8000
      19.7,      0.000,      0.000,         0,      3.5043,      5.8417
      19.7,      0.000,      0.000,         0,      3.5290,      5.8833
      19.8,      0.000,      0.000,         0,      3.5548,      5.9250
      19.8,      0.000,      0.000,         0,      3.5790,      5.9667
      19.9,      0.000,      0.000,         0,      3.6048,      6.0083
      19.9,      0.000,      0.000,         0,      3.6294,      6.0500
      20.0,      0.000,      0.000,         0,      3.6540,      6.0917
      20.0,      0.000,      0.000,         0,      3.6792,      6.1333
      20.1,      0.000,      0.000,         0,      3.7039,      6.1750
      20.1,      0.000,      0.000,         0,      3.7290,      6.2167
      20.2,      0.000,      0.000,         0,      3.7540,      6.2583
      20.2,      0.000,      0.000,         0,      3.7790,      6.3000
      20.3,      0.000,      0.000,         0,      3.8040,      6.3417
      20.3,      0.000,      0.000,         0,      3.8290,      6.3833
      20.4,      0.000,      0.000,         0,      3.8539,      6.4250
      20.4,      0.000,      0.000,         0,      3.8791,      6.4667
      20.5,      0.000,      0.000,         0,      3.9040,      6.5083
      20.5,      0.000,      0.000,         0,      3.9291,      6.5500
      20.6,      0.000,      0.000,         0,      3.9540,      6.5917
      20.6,      0.000,      0.000,         0,      3.9790,      6.6333
      20.7,      0.000,      0.000,         0,      4.0040,      6.6750
      20.7,      0.000,      0.000,         0,      4.0289,      6.7167
      20.8,      0.000,      0.000,         0,      4.0541,      6.7583
      20.8,      0.000,      0.000,         0,      4.0790,      6.8000
      20.9,      0.000,      0.000,         0,      4.1040,      6.8417
      20.9,      0.000,      0.000,         0,      4.1290,      6.8833
      21.0,      0.000,      0.000,         0,      4.1540,      6.9250
      21.0,      0.000,      0.000,         0,      4.1790,      6.9667
      21.1,      0.000,      0.000,         0,      4.2039,      7.0083
      21.1,      0.000,      0.000,         0,      4.2290,      7.0500
      21.2,      0.000,      0.000,         0,      4.2539,      7.0917
      21.2,      0.000,      0.000,         0,      4.2790,      7.1333
      21.3,      0.000,      0.000,         0,      4.3039,      7.1750
      21.3,      0.000,      0.000,         0,      4.3289,      7.2167
      21.3,      0.000,      0.000,         0,      4.3540,      7.2583
      21.4,      0.000,      0.000,         0,      4.3790,      7.3000
      21.4,      0.000,      0.000,         0,      4.4040,      7.3417
      21.5,      0.000,      0.000,         0,      4.4290,      7.3833
      21.5,      0.000,      0.000,         0,      4.4539,      7.4250
      21.6,      0.000,      0.000,         0,      4.4793,      7.4667
      21.6,      0.000,      0.000,         0,      4.5039,      7.5083
      21.7,      0.000,      0.000,         0,      4.5291,      7.5500
      21.7,      0.000,      0.000,         0,      4.5540,      7.5917
      21.8,      0.000,      0.000,         0,      4.5789,      7.6333
      21.8,      0.000,      0.000,         0,      4.6040,      7.6750
      21.8,      0.000,      0.000,         0,      4.6289,      7.7167
      21.9,      0.000,      0.000,         0,      4.6540,      7.7583
      21.9,      0.000,      0.000,         0,      4.6789,      7.8000
      22.0,      0.000,      0.000,         0,      4.7039,      7.8417
      22.0,      0.000,      0.000,         0,      4.7292,      7.8833
      22.1,      0.000,      0.000,         0,      4.7540,      7.9250
      22.1,      0.000,      0.000,         0,      4.7799,      7.9667
      22.2,      0.000,      0.000,         0,      4.8040,      8.0083
      22.2,      0.000,      0.000,         0,      4.8290,      8.0500
      22.2,      0.000,      0.000,         0,      4.8547,      8.0917
      22.3,      0.000,      0.000,         0,      4.8789,      8.1333
      22.3,      0.000,      0.000,         0,      4.9046,      8.1750
      22.4,      0.000,      0.000,         0,      4.9289,      8.2167
      22.4,      0.000,      0.000,         0,      4.9539,      8.2583
      22.5,      0.000,      0.000,         0,      4.9790,      8.3000
      22.5,      0.000,      0.000,         0,      5.0040,      8.3417
      22.6,      0.000,      0.000,         0,      5.0289,      8.3833
      22.6,      0.000,      0.000,         0,      5.0540,      8.4250
      22.6,      0.000,      0.000,         0,      5.0789,      8.4667
      22.7,      0.000,      0.000,         0,      5.1040,      8.5083
      22.7,      0.000,      0.000,         0,      5.1290,      8.5500
      22.8,      0.000,      0.000,         0,      5.1541,      8.5917
      22.8,      0.000,      0.000,         0,      5.1790,      8.6333
      22.9,      0.000,      0.000,         0,      5.2040,      8.6750
      22.9,      0.000,      0.000,         0,      5.2289,      8.7167
      22.9,      0.000,      0.000,         0,      5.2541,      8.7583
      23.0,      0.000,      0.000,         0,      5.2790,      8.8000
      23.0,      0.000,      0.000,         0,      5.3039,      8.8417
      23.1,      0.000,      0.000,         0,      5.3290,      8.8833
      23.1,      0.000,      0.000,         0,      5.3540,      8.9250
      23.2,      0.000,      0.000,         0,      5.3789,      8.9667
      23.2,      0.000,      0.000,         0,      5.4039,      9.0083
      23.2,      0.000,      0.000,         0,      5.4289,      9.0500
      23.3,      0.000,      0.000,         0,      5.4540,      9.0917
      23.3,      0.000,      0.000,         0,      5.4788,      9.1333
      23.4,      0.000,      0.000,         0,      5.5039,      9.1750
      23.4,      0.000,      0.000,         0,      5.5290,      9.2167
      23.5,      0.000,      0.000,         0,      5.5539,      9.2583
      23.5,      0.000,      0.000,         0,      5.5796,      9.3000
      23.5,      0.000,      0.000,         0,      5.6039,      9.3417
      23.6,      0.000,      0.000,         0,      5.6296,      9.3833
      23.6,      0.000,      0.000,         0,      5.6539,      9.4250
      23.7,      0.000,      0.000,         0,      5.6788,      9.4667
      23.7,      0.000,      0.000,         0,      5.7040,      9.5083
      23.7,      0.000,      0.000,         0,      5.7288,      9.5500
      23.8,      0.000,      0.000,         0,      5.7541,      9.5917
      23.8,      0.000,      0.000,         0,      5.7789,      9.6333
      23.8,      0.000,      0.000,         0,      5.8039,      9.6750
      23.9,      0.000,      0.000,         0,      5.8290,      9.7167
      23.9,      0.000,      0.000,         0,      5.8538,      9.7583
      24.0,      0.000,      0.000,         0,      5.8789,      9.8000
      24.0,      0.000,      0.000,         0,      5.9040,      9.8417
      24.1,      0.000,      0.000,         0,      5.9288,      9.8833
      24.1,      0.000,      0.000,         0,      5.9542,      9.9250
      24.1,      0.000,      0.000,         0,      5.9789,      9.9667
      24.2,      0.000,      0.000,         0,      6.0040,     10.0083
      24.2,      0.000,      0.000,         0,      6.0289,     10.0500
      24.3,      0.000,      0.000,         0,      6.0539,     10.0917
      24.3,      0.000,      0.000,         0,      6.0794,     10.1333
      24.3,      0.000,      0.000,         0,      6.1038,     10.1750
      24.4,      0.000,      0.000,         0,      6.1292,     10.2167
      24.4,      0.000,      0.000,         0,      6.1539,     10.2583
      24.5,      0.000,      0.000,         0,      6.1788,     10.3000
      24.5,      0.000,      0.000,         0,      6.2038,     10.3417
      24.6,      0.000,      0.000,         0,      6.2289,     10.3833
      24.6,      0.000,      0.000,         0,      6.2538,     10.4250
      24.6,      0.000,      0.000,         0,      6.2789,     10.4667
      24.7,      0.000,      0.000,         0,      6.3038,     10.5083
      24.7,      0.000,      0.000,         0,      6.3288,     10.5500
      24.7,      0.000,      0.000,         0,      6.3539,     10.5917
      24.8,      0.000,      0.000,         0,      6.3788,     10.6333
      24.8,      0.000,      0.000,         0,      6.4040,     10.6750
      24.9,      0.000,      0.000,         0,      6.4290,     10.7167
      24.9,      0.000,      0.000,         0,      6.4540,     10.7583
      25.0,      0.000,      0.000,         0,      6.4790,     10.8000
      25.0,      0.000,      0.000,         0,      6.5040,     10.8417
      25.0,      0.000,      0.000,         0,      6.5288,     10.8833
      25.1,      0.000,      0.000,         0,      6.5540,     10.9250
      25.1,      0.000,      0.000,         0,      6.5789,     10.9667
      25.1,      0.000,      0.000,         0,      6.6039,     11.0083
      25.2,      0.000,      0.000,         0,      6.6289,     11.0500
      25.2,      0.000,      0.000,         0,      6.6538,     11.0917
      25.2,      0.000,      0.000,         0,      6.6789,     11.1333
      25.3,      0.000,      0.000,         0,      6.7038,     11.1750
      25.3,      0.000,      0.000,         0,      6.7289,     11.2167
      25.3,      0.000,      0.000,         0,      6.7539,     11.2583
      25.4,      0.000,      0.000,         0,      6.7789,     11.3000
      25.4,      0.000,      0.000,         0,      6.8046,     11.3417
      25.5,      0.000,      0.000,         0,      6.8289,     11.3833
      25.5,      0.000,      0.000,         0,      6.8548,     11.4250
      25.6,      0.000,      0.000,         0,      6.8790,     11.4667
      25.6,      0.000,      0.000,         0,      6.9038,     11.5083
      25.6,      0.000,      0.000,         0,      6.9294,     11.5500
      25.7,      0.000,      0.000,         0,      6.9538,     11.5917
      25.7,      0.000,      0.000,         0,      6.9789,     11.6333
      25.7,      0.000,      0.000,         0,      7.0038,     11.6750
      25.8,      0.000,      0.000,         0,      7.0288,     11.7167
      25.8,      0.000,      0.000,         0,      7.0539,     11.7583
      25.8,      0.000,      0.000,         0,      7.0788,     11.8000
      25.9,      0.000,      0.000,         0,      7.1037,     11.8417
      25.9,      0.000,      0.000,         0,      7.1289,     11.8833
      25.9,      0.000,      0.000,         0,      7.1539,     11.9250
      26.0,      0.000,      0.000,         0,      7.1789,     11.9667
      26.0,      0.000,      0.000,         0,      7.2039,     12.0083
      26.0,      0.000,      0.000,         0,      7.2290,     12.0500
      26.1,      0.000,      0.000,         0,      7.2539,     12.0917
      26.1,      0.000,      0.000,         0,      7.2788,     12.1333
      26.2,      0.000,      0.000,         0,      7.3038,     12.1750
      26.2,      0.000,      0.000,         0,      7.3289,     12.2167
      26.2,      0.000,      0.000,         0,      7.3539,     12.2583
      26.3,      0.000,      0.000,         0,      7.3789,     12.3000
      26.3,      0.000,      0.000,         0,      7.4038,     12.3417
      26.3,      0.000,      0.000,         0,      7.4288,     12.3833
      26.4,      0.000,      0.000,         0,      7.4538,     12.4250
      26.4,      0.000,      0.000,         0,      7.4788,     12.4667
      26.4,      0.000,      0.000,         0,      7.5038,     12.5083
      26.5,      0.000,      0.000,         0,      7.5288,     12.5500
      26.5,      0.000,      0.000,         0,      7.5538,     12.5917
      26.5,      0.000,      0.000,         0,      7.5788,     12.6333
      26.6,      0.000,      0.000,         0,      7.6038,     12.6750
      26.6,      0.000,      0.000,         0,      7.6288,     12.7167
      26.6,      0.000,      0.000,         0,      7.6539,     12.7583
      26.7,      0.000,      0.000,         0,      7.6788,     12.8000
      26.7,      0.000,      0.000,         0,      7.7038,     12.8417
      26.8,      0.000,      0.000,         0,      7.7288,     12.8833
      26.8,      0.000,      0.000,         0,      7.7538,     12.9250
      26.8,      0.000,      0.000,         0,      7.7794,     12.9667
      26.9,      0.000,      0.000,         0,      7.8038,     13.0083
      26.9,      0.000,      0.000,         0,      7.8288,     13.0500
      26.9,      0.000,      0.000,         0,      7.8538,     13.0917
      27.0,      0.000,      0.000,         0,      7.8787,     13.1333
      27.0,      0.000,      0.000,         0,      7.9039,     13.1750
      27.0,      0.000,      0.000,         0,      7.9288,     13.2167
      27.1,      0.000,      0.000,         0,      7.9538,     13.2583
      27.1,      0.000,      0.000,         0,      7.9788,     13.3000
      27.1,      0.000,      0.000,         0,      8.0037,     13.3417
      27.2,      0.000,      0.000,         0,      8.0293,     13.3833
      27.2,      0.000,      0.000,         0,      8.0538,     13.4250
      27.3,      0.000,      0.000,         0,      8.0791,     13.4667
      27.3,      0.000,      0.000,         0,      8.1040,     13.5083
      27.3,      0.000,      0.000,         0,      8.1288,     13.5500
      27.4,      0.000,      0.000,         0,      8.1549,     13.5917
      27.4,      0.000,      0.000,         0,      8.1788,     13.6333
      27.4,      0.000,      0.000,         0,      8.2038,     13.6750
      27.5,      0.000,      0.000,         0,      8.2288,     13.7167
      27.5,      0.000,      0.000,         0,      8.2537,     13.7583
      27.5,      0.000,      0.000,         0,      8.2788,     13.8000
      27.6,      0.000,      0.000,         0,      8.3038,     13.8417
      27.6,      0.000,      0.000,         0,      8.3287,     13.8833
      27.6,      0.000,      0.000,         0,      8.3538,     13.9250
      27.7,      0.000,      0.000,         0,      8.3787,     13.9667
      27.7,      0.000,      0.000,         0,      8.4039,     14.0083
      27.7,      0.000,      0.000,         0,      8.4288,     14.0500
      27.8,      0.000,      0.000,         0,      8.4538,     14.0917
      27.8,      0.000,      0.000,         0,      8.4788,     14.1333
      27.9,      0.000,      0.000,         0,      8.5042,     14.1750
      27.9,      0.000,      0.000,         0,      8.5287,     14.2167
      27.9,      0.000,      0.000,         0,      8.5538,     14.2583
      27.9,      0.000,      0.000,         0,      8.5787,     14.3000
      28.0,      0.000,      0.000,         0,      8.6037,     14.3417
      28.0,      0.000,      0.000,         0,      8.6288,     14.3833
      28.1,      0.000,      0.000,         0,      8.6537,     14.4250
      28.1,      0.000,      0.000,         0,      8.6787,     14.4667
      28.1,      0.000,      0.000,         0,      8.7037,     14.5083
      28.2,      0.000,      0.000,         0,      8.7287,     14.5500
      28.2,      0.000,      0.000,         0,      8.7538,     14.5917
      28.2,      0.000,      0.000,         0,      8.7786,     14.6333
      28.3,      0.000,      0.000,         0,      8.8038,     14.6750
      28.3,      0.000,      0.000,         0,      8.8288,     14.7167
      28.3,      0.000,      0.000,         0,      8.8537,     14.7583
      28.4,      0.000,      0.000,         0,      8.8798,     14.8000
      28.4,      0.000,      0.000,         0,      8.9037,     14.8417
      28.4,      0.000,      0.000,         0,      8.9292,     14.8833
      28.4,      0.000,      0.000,         0,      8.9540,     14.9250
      28.5,      0.000,      0.000,         0,      8.9786,     14.9667
      28.5,      0.000,      0.000,         0,      9.0044,     15.0083
      28.6,      0.000,      0.000,         0,      9.0288,     15.0500
      28.6,      0.000,      0.000,         0,      9.0537,     15.0917
      28.6,      0.000,      0.000,         0,      9.0788,     15.1333
      28.6,      0.000,      0.000,         0,      9.1036,     15.1750
      28.7,      0.000,      0.000,         0,      9.1288,     15.2167
      28.7,      0.000,      0.000,         0,      9.1537,     15.2583
      28.8,      0.000,      0.000,         0,      9.1787,     15.3000
      28.8,      0.000,      0.000,         0,      9.2037,     15.3417
      28.8,      0.000,      0.000,         0,      9.2287,     15.3833
      28.8,      0.000,      0.000,         0,      9.2539,     15.4250
      28.9,      0.000,      0.000,         0,      9.2787,     15.4667
      28.9,      0.000,      0.000,         0,      9.3037,     15.5083
      28.9,      0.000,      0.000,         0,      9.3290,     15.5500
      29.0,      0.000,      0.000,         0,      9.3537,     15.5917
      29.0,      0.000,      0.000,         0,      9.3793,     15.6333
      29.0,      0.000,      0.000,         0,      9.4037,     15.6750
      29.0,      0.000,      0.000,         0,      9.4287,     15.7167
      29.1,      0.000,      0.000,         0,      9.4537,     15.7583
      29.1,      0.000,      0.000,         0,      9.4787,     15.8000
      29.1,      0.000,      0.000,         0,      9.5037,     15.8417
      29.1,      0.000,      0.000,         0,      9.5287,     15.8833
      29.2,      0.000,      0.000,         0,      9.5536,     15.9250
      29.2,      0.000,      0.000,         0,      9.5786,     15.9667
      29.2,      0.000,      0.000,         0,      9.6036,     16.0083
      29.3,      0.000,      0.000,         0,      9.6288,     16.0500
      29.3,      0.000,      0.000,         0,      9.6538,     16.0917
      29.3,      0.000,      0.000,         0,      9.6787,     16.1333
      29.4,      0.000,      0.000,         0,      9.7037,     16.1750
      29.4,      0.000,      0.000,         0,      9.7287,     16.2167
      29.4,      0.000,      0.000,         0,      9.7537,     16.2583
      29.4,      0.000,      0.000,         0,      9.7787,     16.3000
      29.5,      0.000,      0.000,         0,      9.8038,     16.3417
      29.5,      0.000,      0.000,         0,      9.8287,     16.3833
      29.5,      0.000,      0.000,         0,      9.8537,     16.4250
      29.6,      0.000,      0.000,         0,      9.8786,     16.4667
      29.6,      0.000,      0.000,         0,      9.9037,     16.5083
      29.6,      0.000,      0.000,         0,      9.9287,     16.5500
      29.6,      0.000,      0.000,         0,      9.9536,     16.5917
      29.7,      0.000,      0.000,         0,      9.9787,     16.6333
      29.7,      0.000,      0.000,         0,     10.0037,     16.6750
      29.7,      0.000,      0.000,         0,     10.0287,     16.7167
      29.8,      0.000,      0.000,         0,     10.0538,     16.7583
      29.8,      0.000,      0.000,         0,     10.0787,     16.8000
      29.8,      0.000,      0.000,         0,     10.1045,     16.8417
      29.9,      0.000,      0.000,         0,     10.1288,     16.8833
      29.9,      0.000,      0.000,         0,     10.1537,     16.9250
      29.9,      0.000,      0.000,         0,     10.1790,     16.9667
      29.9,      0.000,      0.000,         0,     10.2036,     17.0083
      30.0,      0.000,      0.000,         0,     10.2291,     17.0500
      30.0,      0.000,      0.000,         0,     10.2536,     17.0917
      30.0,      0.000,      0.000,         0,     10.2787,     17.1333
      30.0,      0.000,      0.000,         0,     10.3036,     17.1750
      30.0,      0.000,      0.000,         0,     10.3287,     17.2167
      30.1,      0.000,      0.000,         0,     10.3537,     17.2583
      30.1,      0.000,      0.000,         0,     10.3787,     17.3000
      30.1,      0.000,      0.000,         0,     10.4036,     17.3417
      30.1,      0.000,      0.000,         0,     10.4287,     17.3833
      30.2,      0.000,      0.000,         0,     10.4536,     17.4250
      30.2,      0.000,      0.000,         0,     10.4788,     17.4667
      30.2,      0.000,      0.000,         0,     10.5037,     17.5083
      30.2,      0.000,      0.000,         0,     10.5287,     17.5500
      30.2,      0.000,      0.000,         0,     10.5536,     17.5917
      30.3,      0.000,      0.000,         0,     10.5786,     17.6333
      30.3,      0.000,      0.000,         0,     10.6038,     17.6750
      30.3,      0.000,      0.000,         0,     10.6287,     17.7167
      30.3,      0.000,      0.000,         0,     10.6536,     17.7583
      30.3,      0.000,      0.000,         0,     10.6787,     17.8000
      30.3,      0.000,      0.000,         0,     10.7037,     17.8417
      30.4,      0.000,      0.000,         0,     10.7286,     17.8833
      30.4,      0.000,      0.000,         0,     10.7535,     17.9250
      30.4,      0.000,      0.000,         0,     10.7786,     17.9667
      30.4,      0.000,      0.000,         0,     10.8036,     18.0083
      30.4,      0.000,      0.000,         0,     10.8286,     18.0500
      30.4,      0.000,      0.000,         0,     10.8536,     18.0917
      30.5,      0.000,      0.000,         0,     10.8786,     18.1333
      30.5,      0.000,      0.000,         0,     10.9037,     18.1750
      30.5,      0.000,      0.000,         0,     10.9286,     18.2167
      30.5,      0.000,      0.000,         0,     10.9537,     18.2583
      30.5,      0.000,      0.000,         0,     10.9787,     18.3000
      30.5,      0.000,      0.000,         0,     11.0037,     18.3417
      30.5,      0.000,      0.000,         0,     11.0289,     18.3833
      30.6,      0.000,      0.000,         0,     11.0536,     18.4250
      30.6,      0.000,      0.000,         0,     11.0790,     18.4667
      30.6,      0.000,      0.000,         0,     11.1036,     18.5083
      30.6,      0.000,      0.000,         0,     11.1285,     18.5500
      30.6,      0.000,      0.000,         0,     11.1536,     18.5917
      30.6,      0.000,      0.000,         0,     11.1786,     18.6333
      30.6,      0.000,      0.000,         0,     11.2036,     18.6750
      30.6,      0.000,      0.000,         0,     11.2286,     18.7167
      30.6,      0.000,      0.000,         0,     11.2535,     18.7583
      30.6,      0.000,      0.000,         0,     11.2788,     18.8000
      30.6,      0.000,      0.000,         0,     11.3036,     18.8417
      30.6,      0.000,      0.000,         0,     11.3293,     18.8833
      30.6,      0.000,      0.000,         0,     11.3536,     18.9250
      30.7,      0.000,      0.000,         0,     11.3789,     18.9667
      30.7,      0.000,      0.000,         0,     11.4044,     19.0083
      30.7,      0.000,      0.000,         0,     11.4286,     19.0500
      30.7,      0.000,      0.000,         0,     11.4546,     19.0917
      30.7,      0.000,      0.000,         0,     11.4786,     19.1333
      30.7,      0.000,      0.000,         0,     11.5036,     19.1750
      30.7,      0.000,      0.000,         0,     11.5286,     19.2167
      30.7,      0.000,      0.000,         0,     11.5535,     19.2583
      30.7,      0.000,      0.000,         0,     11.5787,     19.3000
      30.7,      0.000,      0.000,         0,     11.6035,     19.3417
      30.7,      0.000,      0.000,         0,     11.6286,     19.3833
      30.7,      0.000,      0.000,         0,     11.6535,     19.4250
      30.7,      0.000,      0.000,         0,     11.6786,     19.4667
      30.7,      0.000,      0.000,         0,     11.7036,     19.5083
      30.7,      0.000,      0.000,         0,     11.7287,     19.5500
      30.7,      0.000,      0.000,         0,     11.7536,     19.5917
      30.7,      0.000,      0.000,         0,     11.7786,     19.6333
      30.7,      0.000,      0.000,         0,     11.8039,     19.6750
      30.7,      0.000,      0.000,         0,     11.8286,     19.7167
      30.7,      0.000,      0.000,         0,     11.8535,     19.7583
      30.7,      0.000,      0.000,         0,     11.8786,     19.8000
      30.7,      0.000,      0.000,         0,     11.9036,     19.8417
      30.7,      0.000,      0.000,         0,     11.9286,     19.8833
      30.7,      0.000,      0.000,         0,     11.9536,     19.9250
      30.7,      0.000,      0.000,         0,     11.9785,     19.9667
      30.7,      0.000,      0.000,         0,     12.0036,     20.0083
      30.6,      0.000,      0.000,         0,     12.0286,     20.0500
      30.6,      0.000,      0.000,         0,     12.0536,     20.0917
      30.6,      0.000,      0.000,         0,     12.0785,     20.1333
      30.6,      0.000,      0.000,         0,     12.1036,     20.1750
      30.6,      0.000,      0.000,         0,     12.1290,     20.2167
      30.6,      0.000,      0.000,         0,     12.1535,     20.2583
      30.6,      0.000,      0.000,         0,     12.1799,     20.3000
      30.6,      0.000,      0.000,         0,     12.2036,     20.3417
      30.6,      0.000,      0.000,         0,     12.2291,     20.3833
      30.5,      0.000,      0.000,         0,     12.2540,     20.4250
      30.5,      0.000,      0.000,         0,     12.2785,     20.4667
      30.5,      0.000,      0.000,         0,     12.3037,     20.5083
      30.5,      0.000,      0.000,         0,     12.3285,     20.5500
      30.5,      0.000,      0.000,         0,     12.3534,     20.5917
      30.5,      0.000,      0.000,         0,     12.3785,     20.6333
      30.4,      0.000,      0.000,         0,     12.4035,     20.6750
      30.4,      0.000,      0.000,         0,     12.4285,     20.7167
      30.4,      0.000,      0.000,         0,     12.4536,     20.7583
      30.3,      0.000,      0.000,         0,     12.4785,     20.8000
      30.3,      0.000,      0.000,         0,     12.5037,     20.8417
      30.3,      0.000,      0.000,         0,     12.5285,     20.8833
      30.3,      0.000,      0.000,         0,     12.5539,     20.9250
      30.2,      0.000,      0.000,         0,     12.5786,     20.9667
      30.2,      0.000,      0.000,         0,     12.6035,     21.0083
      30.1,      0.000,      0.000,         0,     12.6287,     21.0500
      30.1,      0.000,      0.000,         0,     12.6536,     21.0917
      30.1,      0.000,      0.000,         0,     12.6789,     21.1333
      30.0,      0.000,      0.000,         0,     12.7036,     21.1750
      30.0,      0.000,      0.000,         0,     12.7286,     21.2167
      29.9,      0.000,      0.000,         0,     12.7535,     21.2583
      29.9,      0.000,      0.000,         0,     12.7785,     21.3000
      29.8,      0.000,      0.000,         0,     12.8035,     21.3417
      29.8,      0.000,      0.000,         0,     12.8285,     21.3833
      29.8,      0.000,      0.000,         0,     12.8535,     21.4250
      29.7,      0.000,      0.000,         0,     12.8785,     21.4667
      29.7,      0.000,      0.000,         0,     12.9035,     21.5083
      29.6,      0.000,      0.000,         0,     12.9285,     21.5500
      29.6,      0.000,      0.000,         0,     12.9536,     21.5917
      29.5,      0.000,      0.000,         0,     12.9785,     21.6333
      29.5,      0.000,      0.000,         0,     13.0035,     21.6750
      29.5,      0.000,      0.000,         0,     13.0288,     21.7167
      29.4,      0.000,      0.000,         0,     13.0536,     21.7583
      29.3,      0.000,      0.000,         0,     13.0786,     21.8000
      29.3,      0.000,      0.000,         0,     13.1037,     21.8417
      29.2,      0.000,      0.000,         0,     13.1284,     21.8833
      29.2,      0.000,      0.000,         0,     13.1535,     21.9250
      29.1,      0.000,      0.000,         0,     13.1785,     21.9667
      29.1,      0.000,      0.000,         0,     13.2035,     22.0083
      29.0,      0.000,      0.000,         0,     13.2286,     22.0500
      29.0,      0.000,      0.000,         0,     13.2535,     22.0917
      28.9,      0.000,      0.000,         0,     13.2786,     22.1333
      28.8,      0.000,      0.000,         0,     13.3035,     22.1750
      28.8,      0.000,      0.000,         0,     13.3285,     22.2167
      28.7,      0.000,      0.000,         0,     13.3541,     22.2583
      28.7,      0.000,      0.000,         0,     13.3785,     22.3000
      28.6,      0.000,      0.000,         0,     13.4046,     22.3417
      28.5,      0.000,      0.000,         0,     13.4286,     22.3833
      28.5,      0.000,      0.000,         0,     13.4538,     22.4250
      28.4,      0.000,      0.000,         0,     13.4795,     22.4667
      28.3,      0.000,      0.000,         0,     13.5034,     22.5083
      28.3,      0.000,      0.000,         0,     13.5287,     22.5500
      28.2,      0.000,      0.000,         0,     13.5535,     22.5917
      28.1,      0.000,      0.000,         0,     13.5784,     22.6333
      28.0,      0.000,      0.000,         0,     13.6035,     22.6750
      28.0,      0.000,      0.000,         0,     13.6285,     22.7167
      27.9,      0.000,      0.000,         0,     13.6535,     22.7583
      27.8,      0.000,      0.000,         0,     13.6785,     22.8000
      27.7,      0.000,      0.000,         0,     13.7034,     22.8417
      27.6,      0.000,      0.000,         0,     13.7286,     22.8833
      27.5,      0.000,      0.000,         0,     13.7535,     22.9250
      27.4,      0.000,      0.000,         0,     13.7787,     22.9667
      27.3,      0.000,      0.000,         0,     13.8035,     23.0083
      27.2,      0.000,      0.000,         0,     13.8285,     23.0500
      27.1,      0.000,      0.000,         0,     13.8536,     23.0917
      26.9,      0.000,      0.000,         0,     13.8785,     23.1333
      26.8,      0.000,      0.000,         0,     13.9035,     23.1750
      26.6,      0.000,      0.000,         0,     13.9285,     23.2167
      26.4,      0.000,      0.000,         0,     13.9535,     23.2583
      26.0,      0.000,      0.000,         0,     13.9786,     23.3000
       0.0,      0.000,      0.000,         0,     14.0034,     23.3417
       0.0,      0.000,      0.000,         0,     14.0285,     23.3833
       0.0,      0.000,      0.000,         0,     14.0533,     23.4250
       0.0,      0.000,      0.000,         0,     14.0784,     23.4667
       0.0,      0.000,      0.000,         0,     14.1034,     23.5083