File: Alban repo/Quiz 1/suction cup instron tests/july-2020-force-vs-separaion-speed_raw-data/d30e10-01-inwater-onwhiteplatic-diaphragmpump-6mm-test1.raw
Operator: 1

Date,Time,Specimen#
07/02/20,12:43:50,1

---------------------------------------


Area (mm^2):,      1.00,Flat,     25.40,     25.40,     25.40
Gage Len (mm):,     25.40


LOAD (N),STRAIN 1 (mm),STRAIN 2 (mm),STRESS (MPa),POSITION (mm),TIME (min)
       2.6,      0.000,      0.000,         0,      0.0485,      0.0083
       3.3,      0.000,      0.000,         0,      0.0987,      0.0167
       3.9,      0.000,      0.000,         0,      0.1487,      0.0250
       4.5,      0.000,      0.000,         0,      0.1986,      0.0333
       5.1,      0.000,      0.000,         0,      0.2485,      0.0417
       5.7,      0.000,      0.000,         0,      0.2985,      0.0500
       6.2,      0.000,      0.000,         0,      0.3485,      0.0583
       6.8,      0.000,      0.000,         0,      0.3985,      0.0667
       7.3,      0.000,      0.000,         0,      0.4485,      0.0750
       7.9,      0.000,      0.000,         0,      0.4986,      0.0833
       8.4,      0.000,      0.000,         0,      0.5487,      0.0917
       8.9,      0.000,      0.000,         0,      0.5986,      0.1000
       9.4,      0.000,      0.000,         0,      0.6485,      0.1083
       9.8,      0.000,      0.000,         0,      0.6986,      0.1167
      10.3,      0.000,      0.000,         0,      0.7486,      0.1250
      10.8,      0.000,      0.000,         0,      0.7985,      0.1333
      11.2,      0.000,      0.000,         0,      0.8486,      0.1417
      11.7,      0.000,      0.000,         0,      0.8984,      0.1500
      12.1,      0.000,      0.000,         0,      0.9486,      0.1583
      12.5,      0.000,      0.000,         0,      0.9988,      0.1667
      12.9,      0.000,      0.000,         0,      1.0485,      0.1750
      13.3,      0.000,      0.000,         0,      1.0985,      0.1833
      13.6,      0.000,      0.000,         0,      1.1485,      0.1917
      14.0,      0.000,      0.000,         0,      1.1986,      0.2000
      14.4,      0.000,      0.000,         0,      1.2485,      0.2083
      14.7,      0.000,      0.000,         0,      1.2985,      0.2167
      15.1,      0.000,      0.000,         0,      1.3486,      0.2250
      15.4,      0.000,      0.000,         0,      1.3986,      0.2333
      15.7,      0.000,      0.000,         0,      1.4485,      0.2417
      16.1,      0.000,      0.000,         0,      1.4986,      0.2500
      16.4,      0.000,      0.000,         0,      1.5484,      0.2583
      16.7,      0.000,      0.000,         0,      1.5986,      0.2667
      17.0,      0.000,      0.000,         0,      1.6486,      0.2750
      17.3,      0.000,      0.000,         0,      1.6985,      0.2833
      17.6,      0.000,      0.000,         0,      1.7486,      0.2917
      17.8,      0.000,      0.000,         0,      1.7985,      0.3000
      17.9,      0.000,      0.000,         0,      1.8486,      0.3083
      17.8,      0.000,      0.000,         0,      1.8986,      0.3167
      17.0,      0.000,      0.000,         0,      1.9486,      0.3250
      17.1,      0.000,      0.000,         0,      1.9983,      0.3333
      17.2,      0.000,      0.000,         0,      2.0484,      0.3417
      17.4,      0.000,      0.000,         0,      2.0986,      0.3500
      17.5,      0.000,      0.000,         0,      2.1485,      0.3583
      17.7,      0.000,      0.000,         0,      2.1985,      0.3667
      17.9,      0.000,      0.000,         0,      2.2485,      0.3750
      18.0,      0.000,      0.000,         0,      2.2987,      0.3833
      18.2,      0.000,      0.000,         0,      2.3487,      0.3917
      18.3,      0.000,      0.000,         0,      2.3985,      0.4000
      18.5,      0.000,      0.000,         0,      2.4484,      0.4083
      18.7,      0.000,      0.000,         0,      2.4985,      0.4167
      18.8,      0.000,      0.000,         0,      2.5486,      0.4250
      19.0,      0.000,      0.000,         0,      2.5987,      0.4333
      19.1,      0.000,      0.000,         0,      2.6485,      0.4417
      19.2,      0.000,      0.000,         0,      2.6986,      0.4500
      19.4,      0.000,      0.000,         0,      2.7486,      0.4583
      19.5,      0.000,      0.000,         0,      2.7985,      0.4667
      19.7,      0.000,      0.000,         0,      2.8484,      0.4750
      19.8,      0.000,      0.000,         0,      2.8985,      0.4833
      19.9,      0.000,      0.000,         0,      2.9486,      0.4917
      20.1,      0.000,      0.000,         0,      2.9987,      0.5000
      20.2,      0.000,      0.000,         0,      3.0485,      0.5083
      20.3,      0.000,      0.000,         0,      3.0984,      0.5167
      20.5,      0.000,      0.000,         0,      3.1486,      0.5250
      20.6,      0.000,      0.000,         0,      3.1986,      0.5333
      20.7,      0.000,      0.000,         0,      3.2485,      0.5417
      20.9,      0.000,      0.000,         0,      3.2984,      0.5500
      21.0,      0.000,      0.000,         0,      3.3485,      0.5583
      21.1,      0.000,      0.000,         0,      3.3985,      0.5667
      21.2,      0.000,      0.000,         0,      3.4487,      0.5750
      21.3,      0.000,      0.000,         0,      3.4986,      0.5833
      21.5,      0.000,      0.000,         0,      3.5484,      0.5917
      21.6,      0.000,      0.000,         0,      3.5985,      0.6000
      21.7,      0.000,      0.000,         0,      3.6485,      0.6083
      21.8,      0.000,      0.000,         0,      3.6985,      0.6167
      21.9,      0.000,      0.000,         0,      3.7485,      0.6250
      22.0,      0.000,      0.000,         0,      3.7986,      0.6333
      22.1,      0.000,      0.000,         0,      3.8486,      0.6417
      22.3,      0.000,      0.000,         0,      3.8986,      0.6500
      22.4,      0.000,      0.000,         0,      3.9486,      0.6583
      22.5,      0.000,      0.000,         0,      3.9985,      0.6667
      22.6,      0.000,      0.000,         0,      4.0485,      0.6750
      22.7,      0.000,      0.000,         0,      4.0985,      0.6833
      22.8,      0.000,      0.000,         0,      4.1485,      0.6917
      22.9,      0.000,      0.000,         0,      4.1985,      0.7000
      23.0,      0.000,      0.000,         0,      4.2487,      0.7083
      23.1,      0.000,      0.000,         0,      4.2987,      0.7167
      23.2,      0.000,      0.000,         0,      4.3486,      0.7250
      23.3,      0.000,      0.000,         0,      4.3985,      0.7333
      23.4,      0.000,      0.000,         0,      4.4484,      0.7417
      23.5,      0.000,      0.000,         0,      4.4985,      0.7500
      23.6,      0.000,      0.000,         0,      4.5485,      0.7583
      23.7,      0.000,      0.000,         0,      4.5986,      0.7667
      23.8,      0.000,      0.000,         0,      4.6486,      0.7750
      23.9,      0.000,      0.000,         0,      4.6986,      0.7833
      24.0,      0.000,      0.000,         0,      4.7485,      0.7917
      24.1,      0.000,      0.000,         0,      4.7985,      0.8000
      24.2,      0.000,      0.000,         0,      4.8485,      0.8083
      24.3,      0.000,      0.000,         0,      4.8985,      0.8167
      24.4,      0.000,      0.000,         0,      4.9486,      0.8250
      24.5,      0.000,      0.000,         0,      4.9984,      0.8333
      24.6,      0.000,      0.000,         0,      5.0485,      0.8417
      24.7,      0.000,      0.000,         0,      5.0986,      0.8500
      24.8,      0.000,      0.000,         0,      5.1486,      0.8583
      24.9,      0.000,      0.000,         0,      5.1985,      0.8667
      25.0,      0.000,      0.000,         0,      5.2485,      0.8750
      25.1,      0.000,      0.000,         0,      5.2983,      0.8833
      25.2,      0.000,      0.000,         0,      5.3484,      0.8917
      25.3,      0.000,      0.000,         0,      5.3987,      0.9000
      25.4,      0.000,      0.000,         0,      5.4485,      0.9083
      25.5,      0.000,      0.000,         0,      5.4984,      0.9167
      25.6,      0.000,      0.000,         0,      5.5485,      0.9250
      25.7,      0.000,      0.000,         0,      5.5985,      0.9333
      25.8,      0.000,      0.000,         0,      5.6486,      0.9417
      25.9,      0.000,      0.000,         0,      5.6985,      0.9500
      26.0,      0.000,      0.000,         0,      5.7484,      0.9583
      26.1,      0.000,      0.000,         0,      5.7985,      0.9667
      26.2,      0.000,      0.000,         0,      5.8486,      0.9750
      26.3,      0.000,      0.000,         0,      5.8985,      0.9833
      26.4,      0.000,      0.000,         0,      5.9485,      0.9917
      26.5,      0.000,      0.000,         0,      5.9986,      1.0000
      26.6,      0.000,      0.000,         0,      6.0485,      1.0083
      26.7,      0.000,      0.000,         0,      6.0985,      1.0167
      26.8,      0.000,      0.000,         0,      6.1483,      1.0250
      26.9,      0.000,      0.000,         0,      6.1986,      1.0333
      27.0,      0.000,      0.000,         0,      6.2486,      1.0417
      27.1,      0.000,      0.000,         0,      6.2986,      1.0500
      27.2,      0.000,      0.000,         0,      6.3484,      1.0583
      27.3,      0.000,      0.000,         0,      6.3983,      1.0667
      27.4,      0.000,      0.000,         0,      6.4486,      1.0750
      27.5,      0.000,      0.000,         0,      6.4985,      1.0833
      27.6,      0.000,      0.000,         0,      6.5486,      1.0917
      27.7,      0.000,      0.000,         0,      6.5985,      1.1000
      27.8,      0.000,      0.000,         0,      6.6485,      1.1083
      27.9,      0.000,      0.000,         0,      6.6986,      1.1167
      28.0,      0.000,      0.000,         0,      6.7485,      1.1250
      28.1,      0.000,      0.000,         0,      6.7984,      1.1333
      28.2,      0.000,      0.000,         0,      6.8485,      1.1417
      28.2,      0.000,      0.000,         0,      6.8985,      1.1500
      28.3,      0.000,      0.000,         0,      6.9484,      1.1583
      28.4,      0.000,      0.000,         0,      6.9984,      1.1667
      28.5,      0.000,      0.000,         0,      7.0485,      1.1750
      28.6,      0.000,      0.000,         0,      7.0987,      1.1833
      28.7,      0.000,      0.000,         0,      7.1485,      1.1917
      28.8,      0.000,      0.000,         0,      7.1985,      1.2000
      28.9,      0.000,      0.000,         0,      7.2485,      1.2083
      29.0,      0.000,      0.000,         0,      7.2985,      1.2167
      29.1,      0.000,      0.000,         0,      7.3484,      1.2250
      29.2,      0.000,      0.000,         0,      7.3984,      1.2333
      29.3,      0.000,      0.000,         0,      7.4485,      1.2417
      29.4,      0.000,      0.000,         0,      7.4985,      1.2500
      29.5,      0.000,      0.000,         0,      7.5486,      1.2583
      29.6,      0.000,      0.000,         0,      7.5985,      1.2667
      29.7,      0.000,      0.000,         0,      7.6485,      1.2750
      29.8,      0.000,      0.000,         0,      7.6985,      1.2833
      29.9,      0.000,      0.000,         0,      7.7485,      1.2917
      30.0,      0.000,      0.000,         0,      7.7986,      1.3000
      30.1,      0.000,      0.000,         0,      7.8485,      1.3083
      30.2,      0.000,      0.000,         0,      7.8985,      1.3167
      30.3,      0.000,      0.000,         0,      7.9485,      1.3250
      30.4,      0.000,      0.000,         0,      7.9984,      1.3333
      30.5,      0.000,      0.000,         0,      8.0484,      1.3417
      30.6,      0.000,      0.000,         0,      8.0984,      1.3500
      30.7,      0.000,      0.000,         0,      8.1484,      1.3583
      30.8,      0.000,      0.000,         0,      8.1985,      1.3667
      30.9,      0.000,      0.000,         0,      8.2486,      1.3750
      31.0,      0.000,      0.000,         0,      8.2984,      1.3833
      31.1,      0.000,      0.000,         0,      8.3485,      1.3917
      31.2,      0.000,      0.000,         0,      8.3985,      1.4000
      31.3,      0.000,      0.000,         0,      8.4485,      1.4083
      31.4,      0.000,      0.000,         0,      8.4985,      1.4167
      31.4,      0.000,      0.000,         0,      8.5483,      1.4250
      31.5,      0.000,      0.000,         0,      8.5983,      1.4333
      31.6,      0.000,      0.000,         0,      8.6484,      1.4417
      31.7,      0.000,      0.000,         0,      8.6985,      1.4500
      31.8,      0.000,      0.000,         0,      8.7485,      1.4583
      31.9,      0.000,      0.000,         0,      8.7984,      1.4667
      32.0,      0.000,      0.000,         0,      8.8486,      1.4750
      32.1,      0.000,      0.000,         0,      8.8985,      1.4833
      32.2,      0.000,      0.000,         0,      8.9485,      1.4917
      32.3,      0.000,      0.000,         0,      8.9984,      1.5000
      32.4,      0.000,      0.000,         0,      9.0484,      1.5083
      32.5,      0.000,      0.000,         0,      9.0984,      1.5167
      32.6,      0.000,      0.000,         0,      9.1486,      1.5250
      32.7,      0.000,      0.000,         0,      9.1984,      1.5333
      32.8,      0.000,      0.000,         0,      9.2484,      1.5417
      32.9,      0.000,      0.000,         0,      9.2984,      1.5500
      33.0,      0.000,      0.000,         0,      9.3483,      1.5583
      33.1,      0.000,      0.000,         0,      9.3982,      1.5667
      33.1,      0.000,      0.000,         0,      9.4484,      1.5750
      33.2,      0.000,      0.000,         0,      9.4986,      1.5833
      33.3,      0.000,      0.000,         0,      9.5486,      1.5917
      33.4,      0.000,      0.000,         0,      9.5985,      1.6000
      33.5,      0.000,      0.000,         0,      9.6484,      1.6083
      33.6,      0.000,      0.000,         0,      9.6983,      1.6167
      33.7,      0.000,      0.000,         0,      9.7485,      1.6250
      33.8,      0.000,      0.000,         0,      9.7984,      1.6333
      33.9,      0.000,      0.000,         0,      9.8484,      1.6417
      34.0,      0.000,      0.000,         0,      9.8984,      1.6500
      34.1,      0.000,      0.000,         0,      9.9486,      1.6583
      34.2,      0.000,      0.000,         0,      9.9985,      1.6667
      34.2,      0.000,      0.000,         0,     10.0485,      1.6750
      34.3,      0.000,      0.000,         0,     10.0984,      1.6833
      34.4,      0.000,      0.000,         0,     10.1484,      1.6917
      34.5,      0.000,      0.000,         0,     10.1984,      1.7000
      34.6,      0.000,      0.000,         0,     10.2484,      1.7083
      34.7,      0.000,      0.000,         0,     10.2985,      1.7167
      34.8,      0.000,      0.000,         0,     10.3485,      1.7250
      34.9,      0.000,      0.000,         0,     10.3985,      1.7333
      35.0,      0.000,      0.000,         0,     10.4485,      1.7417
      35.0,      0.000,      0.000,         0,     10.4984,      1.7500
      35.1,      0.000,      0.000,         0,     10.5484,      1.7583
      35.2,      0.000,      0.000,         0,     10.5984,      1.7667
      35.3,      0.000,      0.000,         0,     10.6483,      1.7750
      35.4,      0.000,      0.000,         0,     10.6983,      1.7833
      35.5,      0.000,      0.000,         0,     10.7484,      1.7917
      35.6,      0.000,      0.000,         0,     10.7985,      1.8000
      35.7,      0.000,      0.000,         0,     10.8486,      1.8083
      35.7,      0.000,      0.000,         0,     10.8985,      1.8167
      35.8,      0.000,      0.000,         0,     10.9483,      1.8250
      35.9,      0.000,      0.000,         0,     10.9984,      1.8333
      36.0,      0.000,      0.000,         0,     11.0483,      1.8417
      36.1,      0.000,      0.000,         0,     11.0986,      1.8500
      36.2,      0.000,      0.000,         0,     11.1484,      1.8583
      36.3,      0.000,      0.000,         0,     11.1985,      1.8667
      36.3,      0.000,      0.000,         0,     11.2485,      1.8750
      36.4,      0.000,      0.000,         0,     11.2984,      1.8833
      36.5,      0.000,      0.000,         0,     11.3484,      1.8917
      36.6,      0.000,      0.000,         0,     11.3985,      1.9000
      36.7,      0.000,      0.000,         0,     11.4485,      1.9083
      36.7,      0.000,      0.000,         0,     11.4985,      1.9167
      36.8,      0.000,      0.000,         0,     11.5484,      1.9250
      36.9,      0.000,      0.000,         0,     11.5984,      1.9333
      37.0,      0.000,      0.000,         0,     11.6485,      1.9417
      37.1,      0.000,      0.000,         0,     11.6985,      1.9500
      37.1,      0.000,      0.000,         0,     11.7484,      1.9583
      37.2,      0.000,      0.000,         0,     11.7983,      1.9667
      37.3,      0.000,      0.000,         0,     11.8484,      1.9750
      37.4,      0.000,      0.000,         0,     11.8983,      1.9833
      37.4,      0.000,      0.000,         0,     11.9486,      1.9917
      37.5,      0.000,      0.000,         0,     11.9984,      2.0000
      37.6,      0.000,      0.000,         0,     12.0484,      2.0083
      37.7,      0.000,      0.000,         0,     12.0985,      2.0167
      37.8,      0.000,      0.000,         0,     12.1485,      2.0250
      37.8,      0.000,      0.000,         0,     12.1985,      2.0333
      37.9,      0.000,      0.000,         0,     12.2483,      2.0417
      38.0,      0.000,      0.000,         0,     12.2985,      2.0500
      38.1,      0.000,      0.000,         0,     12.3485,      2.0583
      38.1,      0.000,      0.000,         0,     12.3984,      2.0667
      38.2,      0.000,      0.000,         0,     12.4485,      2.0750
      38.3,      0.000,      0.000,         0,     12.4985,      2.0833
      38.4,      0.000,      0.000,         0,     12.5484,      2.0917
      38.4,      0.000,      0.000,         0,     12.5983,      2.1000
      38.5,      0.000,      0.000,         0,     12.6483,      2.1083
      38.6,      0.000,      0.000,         0,     12.6983,      2.1167
      38.7,      0.000,      0.000,         0,     12.7486,      2.1250
      38.8,      0.000,      0.000,         0,     12.7987,      2.1333
      38.8,      0.000,      0.000,         0,     12.8485,      2.1417
      38.9,      0.000,      0.000,         0,     12.8984,      2.1500
      39.0,      0.000,      0.000,         0,     12.9484,      2.1583
      39.1,      0.000,      0.000,         0,     12.9982,      2.1667
      39.2,      0.000,      0.000,         0,     13.0483,      2.1750
      39.3,      0.000,      0.000,         0,     13.0985,      2.1833
      39.3,      0.000,      0.000,         0,     13.1483,      2.1917
      39.4,      0.000,      0.000,         0,     13.1985,      2.2000
      39.5,      0.000,      0.000,         0,     13.2484,      2.2083
      39.6,      0.000,      0.000,         0,     13.2985,      2.2167
      39.7,      0.000,      0.000,         0,     13.3484,      2.2250
      39.7,      0.000,      0.000,         0,     13.3985,      2.2333
      39.8,      0.000,      0.000,         0,     13.4483,      2.2417
      39.9,      0.000,      0.000,         0,     13.4984,      2.2500
      40.0,      0.000,      0.000,         0,     13.5484,      2.2583
      40.1,      0.000,      0.000,         0,     13.5984,      2.2667
      40.1,      0.000,      0.000,         0,     13.6484,      2.2750
      40.2,      0.000,      0.000,         0,     13.6984,      2.2833
      40.3,      0.000,      0.000,         0,     13.7484,      2.2917
      40.3,      0.000,      0.000,         0,     13.7985,      2.3000
      40.4,      0.000,      0.000,         0,     13.8485,      2.3083
      40.5,      0.000,      0.000,         0,     13.8984,      2.3167
      40.5,      0.000,      0.000,         0,     13.9484,      2.3250
      40.6,      0.000,      0.000,         0,     13.9983,      2.3333
      40.7,      0.000,      0.000,         0,     14.0484,      2.3417
      40.7,      0.000,      0.000,         0,     14.0984,      2.3500
      40.7,      0.000,      0.000,         0,     14.1485,      2.3583
      40.7,      0.000,      0.000,         0,     14.1984,      2.3667
      40.8,      0.000,      0.000,         0,     14.2484,      2.3750
      40.8,      0.000,      0.000,         0,     14.2982,      2.3833
      40.8,      0.000,      0.000,         0,     14.3484,      2.3917
      40.8,      0.000,      0.000,         0,     14.3984,      2.4000
      40.7,      0.000,      0.000,         0,     14.4484,      2.4083
      40.7,      0.000,      0.000,         0,     14.4985,      2.4167
      40.7,      0.000,      0.000,         0,     14.5484,      2.4250
      40.6,      0.000,      0.000,         0,     14.5984,      2.4333
      40.6,      0.000,      0.000,         0,     14.6484,      2.4417
      40.5,      0.000,      0.000,         0,     14.6984,      2.4500
      40.4,      0.000,      0.000,         0,     14.7485,      2.4583
      40.3,      0.000,      0.000,         0,     14.7985,      2.4667
      40.2,      0.000,      0.000,         0,     14.8485,      2.4750
      40.1,      0.000,      0.000,         0,     14.8984,      2.4833
      40.0,      0.000,      0.000,         0,     14.9484,      2.4917
      39.8,      0.000,      0.000,         0,     14.9984,      2.5000
      39.6,      0.000,      0.000,         0,     15.0485,      2.5083
      39.3,      0.000,      0.000,         0,     15.0983,      2.5167
      39.0,      0.000,      0.000,         0,     15.1483,      2.5250
      36.4,      0.000,      0.000,         0,     15.1983,      2.5333
       0.1,      0.000,      0.000,         0,     15.2485,      2.5417
       0.1,      0.000,      0.000,         0,     15.2983,      2.5500
       0.0,      0.000,      0.000,         0,     15.3484,      2.5583
       0.0,      0.000,      0.000,         0,     15.3985,      2.5667
       0.0,      0.000,      0.000,         0,     15.4483,      2.5750
       0.0,      0.000,      0.000,         0,     15.4985,      2.5833