File: Alban repo/Quiz 1/suction cup instron tests/july-2020-force-vs-separaion-speed_raw-data/d30e10-01-inwater-onwhiteplatic-diaphragmpump-6mm-test3.raw
Operator: 1

Date,Time,Specimen#
07/02/20,12:52:36,1

---------------------------------------


Area (mm^2):,      1.00,Flat,     25.40,     25.40,     25.40
Gage Len (mm):,     25.40


LOAD (N),STRAIN 1 (mm),STRAIN 2 (mm),STRESS (MPa),POSITION (mm),TIME (min)
       2.6,      0.000,      0.000,         0,      0.0482,      0.0083
       3.3,      0.000,      0.000,         0,      0.0983,      0.0167
       3.9,      0.000,      0.000,         0,      0.1483,      0.0250
       4.4,      0.000,      0.000,         0,      0.1985,      0.0333
       5.0,      0.000,      0.000,         0,      0.2484,      0.0417
       5.6,      0.000,      0.000,         0,      0.2983,      0.0500
       6.1,      0.000,      0.000,         0,      0.3483,      0.0583
       6.7,      0.000,      0.000,         0,      0.3983,      0.0667
       7.2,      0.000,      0.000,         0,      0.4484,      0.0750
       7.7,      0.000,      0.000,         0,      0.4983,      0.0833
       8.2,      0.000,      0.000,         0,      0.5483,      0.0917
       8.7,      0.000,      0.000,         0,      0.5983,      0.1000
       9.2,      0.000,      0.000,         0,      0.6485,      0.1083
       9.7,      0.000,      0.000,         0,      0.6983,      0.1167
      10.1,      0.000,      0.000,         0,      0.7484,      0.1250
      10.6,      0.000,      0.000,         0,      0.7983,      0.1333
      11.0,      0.000,      0.000,         0,      0.8484,      0.1417
      11.4,      0.000,      0.000,         0,      0.8983,      0.1500
      11.9,      0.000,      0.000,         0,      0.9484,      0.1583
      12.3,      0.000,      0.000,         0,      0.9983,      0.1667
      12.6,      0.000,      0.000,         0,      1.0485,      0.1750
      13.0,      0.000,      0.000,         0,      1.0984,      0.1833
      13.4,      0.000,      0.000,         0,      1.1484,      0.1917
      13.8,      0.000,      0.000,         0,      1.1984,      0.2000
      14.2,      0.000,      0.000,         0,      1.2484,      0.2083
      14.5,      0.000,      0.000,         0,      1.2982,      0.2167
      14.9,      0.000,      0.000,         0,      1.3483,      0.2250
      15.2,      0.000,      0.000,         0,      1.3983,      0.2333
      15.5,      0.000,      0.000,         0,      1.4483,      0.2417
      15.8,      0.000,      0.000,         0,      1.4983,      0.2500
      16.2,      0.000,      0.000,         0,      1.5486,      0.2583
      16.5,      0.000,      0.000,         0,      1.5983,      0.2667
      16.8,      0.000,      0.000,         0,      1.6482,      0.2750
      17.1,      0.000,      0.000,         0,      1.6981,      0.2833
      17.3,      0.000,      0.000,         0,      1.7482,      0.2917
      17.6,      0.000,      0.000,         0,      1.7983,      0.3000
      17.7,      0.000,      0.000,         0,      1.8484,      0.3083
      17.3,      0.000,      0.000,         0,      1.8984,      0.3167
      16.7,      0.000,      0.000,         0,      1.9485,      0.3250
      16.8,      0.000,      0.000,         0,      1.9984,      0.3333
      17.0,      0.000,      0.000,         0,      2.0483,      0.3417
      17.1,      0.000,      0.000,         0,      2.0983,      0.3500
      17.3,      0.000,      0.000,         0,      2.1484,      0.3583
      17.4,      0.000,      0.000,         0,      2.1982,      0.3667
      17.5,      0.000,      0.000,         0,      2.2483,      0.3750
      17.7,      0.000,      0.000,         0,      2.2984,      0.3833
      17.8,      0.000,      0.000,         0,      2.3483,      0.3917
      18.0,      0.000,      0.000,         0,      2.3983,      0.4000
      18.1,      0.000,      0.000,         0,      2.4483,      0.4083
      18.3,      0.000,      0.000,         0,      2.4983,      0.4167
      18.4,      0.000,      0.000,         0,      2.5483,      0.4250
      18.5,      0.000,      0.000,         0,      2.5984,      0.4333
      18.7,      0.000,      0.000,         0,      2.6484,      0.4417
      18.8,      0.000,      0.000,         0,      2.6982,      0.4500
      19.0,      0.000,      0.000,         0,      2.7483,      0.4583
      19.1,      0.000,      0.000,         0,      2.7984,      0.4667
      19.2,      0.000,      0.000,         0,      2.8485,      0.4750
      19.4,      0.000,      0.000,         0,      2.8983,      0.4833
      19.5,      0.000,      0.000,         0,      2.9482,      0.4917
      19.6,      0.000,      0.000,         0,      2.9983,      0.5000
      19.7,      0.000,      0.000,         0,      3.0484,      0.5083
      19.9,      0.000,      0.000,         0,      3.0983,      0.5167
      20.0,      0.000,      0.000,         0,      3.1483,      0.5250
      20.1,      0.000,      0.000,         0,      3.1983,      0.5333
      20.2,      0.000,      0.000,         0,      3.2484,      0.5417
      20.4,      0.000,      0.000,         0,      3.2983,      0.5500
      20.5,      0.000,      0.000,         0,      3.3483,      0.5583
      20.6,      0.000,      0.000,         0,      3.3981,      0.5667
      20.7,      0.000,      0.000,         0,      3.4484,      0.5750
      20.8,      0.000,      0.000,         0,      3.4984,      0.5833
      21.0,      0.000,      0.000,         0,      3.5483,      0.5917
      21.1,      0.000,      0.000,         0,      3.5984,      0.6000
      21.2,      0.000,      0.000,         0,      3.6484,      0.6083
      21.3,      0.000,      0.000,         0,      3.6983,      0.6167
      21.4,      0.000,      0.000,         0,      3.7484,      0.6250
      21.5,      0.000,      0.000,         0,      3.7983,      0.6333
      21.6,      0.000,      0.000,         0,      3.8483,      0.6417
      21.7,      0.000,      0.000,         0,      3.8984,      0.6500
      21.8,      0.000,      0.000,         0,      3.9483,      0.6583
      21.9,      0.000,      0.000,         0,      3.9982,      0.6667
      22.0,      0.000,      0.000,         0,      4.0483,      0.6750
      22.1,      0.000,      0.000,         0,      4.0984,      0.6833
      22.2,      0.000,      0.000,         0,      4.1483,      0.6917
      22.3,      0.000,      0.000,         0,      4.1982,      0.7000
      22.4,      0.000,      0.000,         0,      4.2484,      0.7083
      22.5,      0.000,      0.000,         0,      4.2983,      0.7167
      22.6,      0.000,      0.000,         0,      4.3484,      0.7250
      22.7,      0.000,      0.000,         0,      4.3984,      0.7333
      22.8,      0.000,      0.000,         0,      4.4482,      0.7417
      22.9,      0.000,      0.000,         0,      4.4984,      0.7500
      23.0,      0.000,      0.000,         0,      4.5483,      0.7583
      23.1,      0.000,      0.000,         0,      4.5983,      0.7667
      23.2,      0.000,      0.000,         0,      4.6484,      0.7750
      23.3,      0.000,      0.000,         0,      4.6983,      0.7833
      23.4,      0.000,      0.000,         0,      4.7482,      0.7917
      23.5,      0.000,      0.000,         0,      4.7984,      0.8000
      23.6,      0.000,      0.000,         0,      4.8484,      0.8083
      23.7,      0.000,      0.000,         0,      4.8983,      0.8167
      23.8,      0.000,      0.000,         0,      4.9482,      0.8250
      23.9,      0.000,      0.000,         0,      4.9980,      0.8333
      24.0,      0.000,      0.000,         0,      5.0481,      0.8417
      24.1,      0.000,      0.000,         0,      5.0983,      0.8500
      24.2,      0.000,      0.000,         0,      5.1484,      0.8583
      24.3,      0.000,      0.000,         0,      5.1984,      0.8667
      24.4,      0.000,      0.000,         0,      5.2484,      0.8750
      24.5,      0.000,      0.000,         0,      5.2983,      0.8833
      24.6,      0.000,      0.000,         0,      5.3481,      0.8917
      24.6,      0.000,      0.000,         0,      5.3982,      0.9000
      24.7,      0.000,      0.000,         0,      5.4484,      0.9083
      24.8,      0.000,      0.000,         0,      5.4983,      0.9167
      24.9,      0.000,      0.000,         0,      5.5483,      0.9250
      25.0,      0.000,      0.000,         0,      5.5984,      0.9333
      25.1,      0.000,      0.000,         0,      5.6483,      0.9417
      25.2,      0.000,      0.000,         0,      5.6983,      0.9500
      25.3,      0.000,      0.000,         0,      5.7483,      0.9583
      25.4,      0.000,      0.000,         0,      5.7982,      0.9667
      25.5,      0.000,      0.000,         0,      5.8482,      0.9750
      25.6,      0.000,      0.000,         0,      5.8983,      0.9833
      25.7,      0.000,      0.000,         0,      5.9484,      0.9917
      25.8,      0.000,      0.000,         0,      5.9982,      1.0000
      25.9,      0.000,      0.000,         0,      6.0483,      1.0083
      26.0,      0.000,      0.000,         0,      6.0983,      1.0167
      26.1,      0.000,      0.000,         0,      6.1483,      1.0250
      26.2,      0.000,      0.000,         0,      6.1983,      1.0333
      26.3,      0.000,      0.000,         0,      6.2484,      1.0417
      26.4,      0.000,      0.000,         0,      6.2983,      1.0500
      26.5,      0.000,      0.000,         0,      6.3483,      1.0583
      26.6,      0.000,      0.000,         0,      6.3983,      1.0667
      26.7,      0.000,      0.000,         0,      6.4483,      1.0750
      26.8,      0.000,      0.000,         0,      6.4985,      1.0833
      26.9,      0.000,      0.000,         0,      6.5484,      1.0917
      27.0,      0.000,      0.000,         0,      6.5982,      1.1000
      27.1,      0.000,      0.000,         0,      6.6482,      1.1083
      27.2,      0.000,      0.000,         0,      6.6981,      1.1167
      27.3,      0.000,      0.000,         0,      6.7483,      1.1250
      27.3,      0.000,      0.000,         0,      6.7985,      1.1333
      27.4,      0.000,      0.000,         0,      6.8482,      1.1417
      27.5,      0.000,      0.000,         0,      6.8982,      1.1500
      27.6,      0.000,      0.000,         0,      6.9483,      1.1583
      27.7,      0.000,      0.000,         0,      6.9983,      1.1667
      27.8,      0.000,      0.000,         0,      7.0482,      1.1750
      27.9,      0.000,      0.000,         0,      7.0982,      1.1833
      28.0,      0.000,      0.000,         0,      7.1482,      1.1917
      28.1,      0.000,      0.000,         0,      7.1983,      1.2000
      28.2,      0.000,      0.000,         0,      7.2483,      1.2083
      28.3,      0.000,      0.000,         0,      7.2984,      1.2167
      28.3,      0.000,      0.000,         0,      7.3481,      1.2250
      28.4,      0.000,      0.000,         0,      7.3982,      1.2333
      28.5,      0.000,      0.000,         0,      7.4482,      1.2417
      28.6,      0.000,      0.000,         0,      7.4983,      1.2500
      28.7,      0.000,      0.000,         0,      7.5483,      1.2583
      28.8,      0.000,      0.000,         0,      7.5983,      1.2667
      28.9,      0.000,      0.000,         0,      7.6482,      1.2750
      29.0,      0.000,      0.000,         0,      7.6982,      1.2833
      29.1,      0.000,      0.000,         0,      7.7482,      1.2917
      29.2,      0.000,      0.000,         0,      7.7983,      1.3000
      29.3,      0.000,      0.000,         0,      7.8483,      1.3083
      29.4,      0.000,      0.000,         0,      7.8981,      1.3167
      29.5,      0.000,      0.000,         0,      7.9482,      1.3250
      29.6,      0.000,      0.000,         0,      7.9981,      1.3333
      29.7,      0.000,      0.000,         0,      8.0483,      1.3417
      29.8,      0.000,      0.000,         0,      8.0983,      1.3500
      29.9,      0.000,      0.000,         0,      8.1484,      1.3583
      30.0,      0.000,      0.000,         0,      8.1983,      1.3667
      30.0,      0.000,      0.000,         0,      8.2482,      1.3750
      30.1,      0.000,      0.000,         0,      8.2983,      1.3833
      30.2,      0.000,      0.000,         0,      8.3483,      1.3917
      30.3,      0.000,      0.000,         0,      8.3983,      1.4000
      30.4,      0.000,      0.000,         0,      8.4483,      1.4083
      30.5,      0.000,      0.000,         0,      8.4983,      1.4167
      30.6,      0.000,      0.000,         0,      8.5483,      1.4250
      30.7,      0.000,      0.000,         0,      8.5982,      1.4333
      30.8,      0.000,      0.000,         0,      8.6482,      1.4417
      30.9,      0.000,      0.000,         0,      8.6982,      1.4500
      31.0,      0.000,      0.000,         0,      8.7481,      1.4583
      31.0,      0.000,      0.000,         0,      8.7982,      1.4667
      31.1,      0.000,      0.000,         0,      8.8483,      1.4750
      31.2,      0.000,      0.000,         0,      8.8983,      1.4833
      31.3,      0.000,      0.000,         0,      8.9483,      1.4917
      31.4,      0.000,      0.000,         0,      8.9982,      1.5000
      31.5,      0.000,      0.000,         0,      9.0481,      1.5083
      31.6,      0.000,      0.000,         0,      9.0983,      1.5167
      31.7,      0.000,      0.000,         0,      9.1483,      1.5250
      31.8,      0.000,      0.000,         0,      9.1984,      1.5333
      31.9,      0.000,      0.000,         0,      9.2482,      1.5417
      32.0,      0.000,      0.000,         0,      9.2981,      1.5500
      32.0,      0.000,      0.000,         0,      9.3483,      1.5583
      32.1,      0.000,      0.000,         0,      9.3982,      1.5667
      32.2,      0.000,      0.000,         0,      9.4482,      1.5750
      32.3,      0.000,      0.000,         0,      9.4983,      1.5833
      32.4,      0.000,      0.000,         0,      9.5482,      1.5917
      32.5,      0.000,      0.000,         0,      9.5983,      1.6000
      32.6,      0.000,      0.000,         0,      9.6481,      1.6083
      32.7,      0.000,      0.000,         0,      9.6983,      1.6167
      32.8,      0.000,      0.000,         0,      9.7483,      1.6250
      32.9,      0.000,      0.000,         0,      9.7984,      1.6333
      33.0,      0.000,      0.000,         0,      9.8482,      1.6417
      33.0,      0.000,      0.000,         0,      9.8982,      1.6500
      33.1,      0.000,      0.000,         0,      9.9482,      1.6583
      33.2,      0.000,      0.000,         0,      9.9981,      1.6667
      33.3,      0.000,      0.000,         0,     10.0483,      1.6750
      33.4,      0.000,      0.000,         0,     10.0982,      1.6833
      33.5,      0.000,      0.000,         0,     10.1481,      1.6917
      33.6,      0.000,      0.000,         0,     10.1982,      1.7000
      33.7,      0.000,      0.000,         0,     10.2483,      1.7083
      33.8,      0.000,      0.000,         0,     10.2983,      1.7167
      33.9,      0.000,      0.000,         0,     10.3482,      1.7250
      33.9,      0.000,      0.000,         0,     10.3982,      1.7333
      34.0,      0.000,      0.000,         0,     10.4483,      1.7417
      34.1,      0.000,      0.000,         0,     10.4982,      1.7500
      34.2,      0.000,      0.000,         0,     10.5482,      1.7583
      34.3,      0.000,      0.000,         0,     10.5983,      1.7667
      34.4,      0.000,      0.000,         0,     10.6483,      1.7750
      34.5,      0.000,      0.000,         0,     10.6982,      1.7833
      34.5,      0.000,      0.000,         0,     10.7482,      1.7917
      34.6,      0.000,      0.000,         0,     10.7982,      1.8000
      34.7,      0.000,      0.000,         0,     10.8484,      1.8083
      34.8,      0.000,      0.000,         0,     10.8983,      1.8167
      34.9,      0.000,      0.000,         0,     10.9483,      1.8250
      35.0,      0.000,      0.000,         0,     10.9982,      1.8333
      35.0,      0.000,      0.000,         0,     11.0481,      1.8417
      35.1,      0.000,      0.000,         0,     11.0984,      1.8500
      35.2,      0.000,      0.000,         0,     11.1483,      1.8583
      35.3,      0.000,      0.000,         0,     11.1981,      1.8667
      35.4,      0.000,      0.000,         0,     11.2481,      1.8750
      35.4,      0.000,      0.000,         0,     11.2983,      1.8833
      35.5,      0.000,      0.000,         0,     11.3482,      1.8917
      35.6,      0.000,      0.000,         0,     11.3983,      1.9000
      35.7,      0.000,      0.000,         0,     11.4482,      1.9083
      35.7,      0.000,      0.000,         0,     11.4983,      1.9167
      35.8,      0.000,      0.000,         0,     11.5482,      1.9250
      35.9,      0.000,      0.000,         0,     11.5980,      1.9333
      36.0,      0.000,      0.000,         0,     11.6482,      1.9417
      36.0,      0.000,      0.000,         0,     11.6983,      1.9500
      36.1,      0.000,      0.000,         0,     11.7483,      1.9583
      36.2,      0.000,      0.000,         0,     11.7982,      1.9667
      36.3,      0.000,      0.000,         0,     11.8482,      1.9750
      36.3,      0.000,      0.000,         0,     11.8982,      1.9833
      36.4,      0.000,      0.000,         0,     11.9482,      1.9917
      36.5,      0.000,      0.000,         0,     11.9981,      2.0000
      36.6,      0.000,      0.000,         0,     12.0481,      2.0083
      36.6,      0.000,      0.000,         0,     12.0982,      2.0167
      36.7,      0.000,      0.000,         0,     12.1483,      2.0250
      36.8,      0.000,      0.000,         0,     12.1983,      2.0333
      36.9,      0.000,      0.000,         0,     12.2482,      2.0417
      36.9,      0.000,      0.000,         0,     12.2982,      2.0500
      37.0,      0.000,      0.000,         0,     12.3480,      2.0583
      37.1,      0.000,      0.000,         0,     12.3981,      2.0667
      37.1,      0.000,      0.000,         0,     12.4482,      2.0750
      37.2,      0.000,      0.000,         0,     12.4983,      2.0833
      37.3,      0.000,      0.000,         0,     12.5482,      2.0917
      37.3,      0.000,      0.000,         0,     12.5983,      2.1000
      37.4,      0.000,      0.000,         0,     12.6483,      2.1083
      37.5,      0.000,      0.000,         0,     12.6981,      2.1167
      37.5,      0.000,      0.000,         0,     12.7483,      2.1250
      37.6,      0.000,      0.000,         0,     12.7983,      2.1333
      37.6,      0.000,      0.000,         0,     12.8482,      2.1417
      37.7,      0.000,      0.000,         0,     12.8983,      2.1500
      37.8,      0.000,      0.000,         0,     12.9482,      2.1583
      37.8,      0.000,      0.000,         0,     12.9981,      2.1667
      37.9,      0.000,      0.000,         0,     13.0483,      2.1750
      38.0,      0.000,      0.000,         0,     13.0982,      2.1833
      38.0,      0.000,      0.000,         0,     13.1481,      2.1917
      38.1,      0.000,      0.000,         0,     13.1981,      2.2000
      38.1,      0.000,      0.000,         0,     13.2480,      2.2083
      38.2,      0.000,      0.000,         0,     13.2983,      2.2167
      38.2,      0.000,      0.000,         0,     13.3482,      2.2250
      38.3,      0.000,      0.000,         0,     13.3983,      2.2333
      38.4,      0.000,      0.000,         0,     13.4482,      2.2417
      38.4,      0.000,      0.000,         0,     13.4982,      2.2500
      38.5,      0.000,      0.000,         0,     13.5482,      2.2583
      38.5,      0.000,      0.000,         0,     13.5982,      2.2667
      38.6,      0.000,      0.000,         0,     13.6481,      2.2750
      38.6,      0.000,      0.000,         0,     13.6982,      2.2833
      38.7,      0.000,      0.000,         0,     13.7482,      2.2917
      38.7,      0.000,      0.000,         0,     13.7984,      2.3000
      38.8,      0.000,      0.000,         0,     13.8483,      2.3083
      38.8,      0.000,      0.000,         0,     13.8982,      2.3167
      38.8,      0.000,      0.000,         0,     13.9482,      2.3250
      38.9,      0.000,      0.000,         0,     13.9982,      2.3333
      38.9,      0.000,      0.000,         0,     14.0482,      2.3417
      38.9,      0.000,      0.000,         0,     14.0982,      2.3500
      39.0,      0.000,      0.000,         0,     14.1483,      2.3583
      39.0,      0.000,      0.000,         0,     14.1982,      2.3667
      39.0,      0.000,      0.000,         0,     14.2482,      2.3750
      39.0,      0.000,      0.000,         0,     14.2980,      2.3833
      39.0,      0.000,      0.000,         0,     14.3483,      2.3917
      39.0,      0.000,      0.000,         0,     14.3983,      2.4000
      39.0,      0.000,      0.000,         0,     14.4482,      2.4083
      39.0,      0.000,      0.000,         0,     14.4981,      2.4167
      38.9,      0.000,      0.000,         0,     14.5481,      2.4250
      38.9,      0.000,      0.000,         0,     14.5982,      2.4333
      38.8,      0.000,      0.000,         0,     14.6482,      2.4417
      38.7,      0.000,      0.000,         0,     14.6983,      2.4500
      38.6,      0.000,      0.000,         0,     14.7483,      2.4583
      38.5,      0.000,      0.000,         0,     14.7983,      2.4667
      38.4,      0.000,      0.000,         0,     14.8482,      2.4750
      38.2,      0.000,      0.000,         0,     14.8979,      2.4833
      38.1,      0.000,      0.000,         0,     14.9482,      2.4917
      37.9,      0.000,      0.000,         0,     14.9983,      2.5000
      37.7,      0.000,      0.000,         0,     15.0483,      2.5083
      37.3,      0.000,      0.000,         0,     15.0982,      2.5167
       0.1,      0.000,      0.000,         0,     15.1482,      2.5250
       0.0,      0.000,      0.000,         0,     15.1982,      2.5333
       0.0,      0.000,      0.000,         0,     15.2482,      2.5417
       0.0,      0.000,      0.000,         0,     15.2981,      2.5500
       0.0,      0.000,      0.000,         0,     15.3482,      2.5583
       0.0,      0.000,      0.000,         0,     15.3981,      2.5667
       0.0,      0.000,      0.000,         0,     15.4483,      2.5750
       0.0,      0.000,      0.000,         0,     15.4984,      2.5833