File: Alban repo/Quiz 1/suction cup instron tests/july-2020-force-vs-separaion-speed_raw-data/d30e10-01-inwater-onwhiteplatic-diaphragmpump-60mm-test3.raw
Operator: 1

Date,Time,Specimen#
07/02/20,12:59:16,1

---------------------------------------


Area (mm^2):,      1.00,Flat,     25.40,     25.40,     25.40
Gage Len (mm):,     25.40


LOAD (N),STRAIN 1 (mm),STRAIN 2 (mm),STRESS (MPa),POSITION (mm),TIME (min)
       9.0,      0.000,      0.000,         0,      0.4854,      0.0083
      14.8,      0.000,      0.000,         0,      0.9853,      0.0167
      19.5,      0.000,      0.000,         0,      1.4854,      0.0250
      23.4,      0.000,      0.000,         0,      1.9854,      0.0333
      26.5,      0.000,      0.000,         0,      2.4854,      0.0417
      28.1,      0.000,      0.000,         0,      2.9853,      0.0500
      29.3,      0.000,      0.000,         0,      3.4852,      0.0583
      30.9,      0.000,      0.000,         0,      3.9854,      0.0667
      32.4,      0.000,      0.000,         0,      4.4854,      0.0750
      33.7,      0.000,      0.000,         0,      4.9854,      0.0833
      35.0,      0.000,      0.000,         0,      5.4853,      0.0917
      36.3,      0.000,      0.000,         0,      5.9853,      0.1000
      37.5,      0.000,      0.000,         0,      6.4852,      0.1083
      38.6,      0.000,      0.000,         0,      6.9853,      0.1167
      39.7,      0.000,      0.000,         0,      7.4853,      0.1250
      40.9,      0.000,      0.000,         0,      7.9853,      0.1333
      42.1,      0.000,      0.000,         0,      8.4853,      0.1417
      43.4,      0.000,      0.000,         0,      8.9852,      0.1500
      44.7,      0.000,      0.000,         0,      9.4854,      0.1583
      46.0,      0.000,      0.000,         0,      9.9854,      0.1667
      47.1,      0.000,      0.000,         0,     10.4850,      0.1750
      48.3,      0.000,      0.000,         0,     10.9853,      0.1833
      49.4,      0.000,      0.000,         0,     11.4854,      0.1917
      50.3,      0.000,      0.000,         0,     11.9853,      0.2000
      51.3,      0.000,      0.000,         0,     12.4852,      0.2083
      52.1,      0.000,      0.000,         0,     12.9853,      0.2167
      52.7,      0.000,      0.000,         0,     13.4854,      0.2250
      53.3,      0.000,      0.000,         0,     13.9853,      0.2333
      53.8,      0.000,      0.000,         0,     14.4852,      0.2417
      54.3,      0.000,      0.000,         0,     14.9852,      0.2500
      54.8,      0.000,      0.000,         0,     15.4852,      0.2583
      55.1,      0.000,      0.000,         0,     15.9853,      0.2667
      54.8,      0.000,      0.000,         0,     16.4853,      0.2750
      51.7,      0.000,      0.000,         0,     16.9852,      0.2833
       0.5,      0.000,      0.000,         0,     17.4852,      0.2917
       0.5,      0.000,      0.000,         0,     17.9852,      0.3000