File: Alban repo/Quiz 1/suction cup instron tests/july-2020-force-vs-separaion-speed_raw-data/d30e10-01-inwater-onwhiteplatic-diaphragmpump-60mm-test1.raw
Operator: 1

Date,Time,Specimen#
07/02/20,12:54:33,1

---------------------------------------


Area (mm^2):,      1.00,Flat,     25.40,     25.40,     25.40
Gage Len (mm):,     25.40


LOAD (N),STRAIN 1 (mm),STRAIN 2 (mm),STRESS (MPa),POSITION (mm),TIME (min)
       8.6,      0.000,      0.000,         0,      0.4846,      0.0083
      14.2,      0.000,      0.000,         0,      0.9852,      0.0167
      18.8,      0.000,      0.000,         0,      1.4853,      0.0250
      22.6,      0.000,      0.000,         0,      1.9853,      0.0333
      25.6,      0.000,      0.000,         0,      2.4853,      0.0417
      26.0,      0.000,      0.000,         0,      2.9852,      0.0500
      27.8,      0.000,      0.000,         0,      3.4853,      0.0583
      29.4,      0.000,      0.000,         0,      3.9853,      0.0667
      30.8,      0.000,      0.000,         0,      4.4853,      0.0750
      32.2,      0.000,      0.000,         0,      4.9853,      0.0833
      33.6,      0.000,      0.000,         0,      5.4852,      0.0917
      34.9,      0.000,      0.000,         0,      5.9853,      0.1000
      36.1,      0.000,      0.000,         0,      6.4852,      0.1083
      37.3,      0.000,      0.000,         0,      6.9852,      0.1167
      38.6,      0.000,      0.000,         0,      7.4853,      0.1250
      39.7,      0.000,      0.000,         0,      7.9852,      0.1333
      41.0,      0.000,      0.000,         0,      8.4852,      0.1417
      42.3,      0.000,      0.000,         0,      8.9852,      0.1500
      43.7,      0.000,      0.000,         0,      9.4852,      0.1583
      45.1,      0.000,      0.000,         0,      9.9852,      0.1667
      46.5,      0.000,      0.000,         0,     10.4851,      0.1750
      47.8,      0.000,      0.000,         0,     10.9851,      0.1833
      49.1,      0.000,      0.000,         0,     11.4853,      0.1917
      50.2,      0.000,      0.000,         0,     11.9851,      0.2000
      51.2,      0.000,      0.000,         0,     12.4851,      0.2083
      52.1,      0.000,      0.000,         0,     12.9851,      0.2167
      53.0,      0.000,      0.000,         0,     13.4852,      0.2250
      53.7,      0.000,      0.000,         0,     13.9852,      0.2333
      54.3,      0.000,      0.000,         0,     14.4851,      0.2417
      54.9,      0.000,      0.000,         0,     14.9853,      0.2500
      55.3,      0.000,      0.000,         0,     15.4852,      0.2583
      55.3,      0.000,      0.000,         0,     15.9850,      0.2667
      53.8,      0.000,      0.000,         0,     16.4852,      0.2750
       0.1,      0.000,      0.000,         0,     16.9850,      0.2833
       0.1,      0.000,      0.000,         0,     17.4851,      0.2917