File: Alban repo/Quiz 1/suction cup instron tests/july-2020-force-vs-separaion-speed_raw-data/d30e10-01-inwater-onwhiteplatic-diaphragmpump-60mm-test2.raw
Operator: 1

Date,Time,Specimen#
07/02/20,12:56:36,1

---------------------------------------


Area (mm^2):,      1.00,Flat,     25.40,     25.40,     25.40
Gage Len (mm):,     25.40


LOAD (N),STRAIN 1 (mm),STRAIN 2 (mm),STRESS (MPa),POSITION (mm),TIME (min)
       8.9,      0.000,      0.000,         0,      0.4852,      0.0083
      14.6,      0.000,      0.000,         0,      0.9855,      0.0167
      19.3,      0.000,      0.000,         0,      1.4853,      0.0250
      23.1,      0.000,      0.000,         0,      1.9853,      0.0333
      26.1,      0.000,      0.000,         0,      2.4854,      0.0417
      27.5,      0.000,      0.000,         0,      2.9854,      0.0500
      29.0,      0.000,      0.000,         0,      3.4853,      0.0583
      30.5,      0.000,      0.000,         0,      3.9854,      0.0667
      31.9,      0.000,      0.000,         0,      4.4855,      0.0750
      33.3,      0.000,      0.000,         0,      4.9855,      0.0833
      34.6,      0.000,      0.000,         0,      5.4853,      0.0917
      35.8,      0.000,      0.000,         0,      5.9855,      0.1000
      37.0,      0.000,      0.000,         0,      6.4853,      0.1083
      38.2,      0.000,      0.000,         0,      6.9855,      0.1167
      39.3,      0.000,      0.000,         0,      7.4853,      0.1250
      40.5,      0.000,      0.000,         0,      7.9854,      0.1333
      41.8,      0.000,      0.000,         0,      8.4854,      0.1417
      43.1,      0.000,      0.000,         0,      8.9855,      0.1500
      44.4,      0.000,      0.000,         0,      9.4853,      0.1583
      45.7,      0.000,      0.000,         0,      9.9855,      0.1667
      46.9,      0.000,      0.000,         0,     10.4854,      0.1750
      48.0,      0.000,      0.000,         0,     10.9854,      0.1833
      49.0,      0.000,      0.000,         0,     11.4852,      0.1917
      50.1,      0.000,      0.000,         0,     11.9853,      0.2000
      51.0,      0.000,      0.000,         0,     12.4853,      0.2083
      51.8,      0.000,      0.000,         0,     12.9854,      0.2167
      52.6,      0.000,      0.000,         0,     13.4854,      0.2250
      53.2,      0.000,      0.000,         0,     13.9853,      0.2333
      53.8,      0.000,      0.000,         0,     14.4855,      0.2417
      54.3,      0.000,      0.000,         0,     14.9853,      0.2500
      54.9,      0.000,      0.000,         0,     15.4853,      0.2583
      55.1,      0.000,      0.000,         0,     15.9852,      0.2667
      54.5,      0.000,      0.000,         0,     16.4853,      0.2750
      47.6,      0.000,      0.000,         0,     16.9852,      0.2833
       0.1,      0.000,      0.000,         0,     17.4853,      0.2917
       0.1,      0.000,      0.000,         0,     17.9853,      0.3000
       0.1,      0.000,      0.000,         0,     18.4853,      0.3083
       0.1,      0.000,      0.000,         0,     18.9853,      0.3167
       0.1,      0.000,      0.000,         0,     19.4853,      0.3250