File: Alban repo/Quiz 1/suction cup instron tests/july-2020-force-vs-separaion-speed_raw-data/d30e10-01-inwater-onwhiteplatic-diaphragmpump-6mm-test2.raw
Operator: 1

Date,Time,Specimen#
07/02/20,12:47:54,1

---------------------------------------


Area (mm^2):,      1.00,Flat,     25.40,     25.40,     25.40
Gage Len (mm):,     25.40


LOAD (N),STRAIN 1 (mm),STRAIN 2 (mm),STRESS (MPa),POSITION (mm),TIME (min)
       2.6,      0.000,      0.000,         0,      0.0486,      0.0083
       3.3,      0.000,      0.000,         0,      0.0987,      0.0167
       3.9,      0.000,      0.000,         0,      0.1487,      0.0250
       4.5,      0.000,      0.000,         0,      0.1986,      0.0333
       5.0,      0.000,      0.000,         0,      0.2486,      0.0417
       5.6,      0.000,      0.000,         0,      0.2987,      0.0500
       6.2,      0.000,      0.000,         0,      0.3488,      0.0583
       6.7,      0.000,      0.000,         0,      0.3986,      0.0667
       7.2,      0.000,      0.000,         0,      0.4487,      0.0750
       7.7,      0.000,      0.000,         0,      0.4986,      0.0833
       8.2,      0.000,      0.000,         0,      0.5487,      0.0917
       8.7,      0.000,      0.000,         0,      0.5988,      0.1000
       9.2,      0.000,      0.000,         0,      0.6487,      0.1083
       9.7,      0.000,      0.000,         0,      0.6987,      0.1167
      10.2,      0.000,      0.000,         0,      0.7487,      0.1250
      10.6,      0.000,      0.000,         0,      0.7985,      0.1333
      11.1,      0.000,      0.000,         0,      0.8486,      0.1417
      11.5,      0.000,      0.000,         0,      0.8987,      0.1500
      11.9,      0.000,      0.000,         0,      0.9487,      0.1583
      12.3,      0.000,      0.000,         0,      0.9986,      0.1667
      12.7,      0.000,      0.000,         0,      1.0486,      0.1750
      13.1,      0.000,      0.000,         0,      1.0986,      0.1833
      13.5,      0.000,      0.000,         0,      1.1486,      0.1917
      13.9,      0.000,      0.000,         0,      1.1987,      0.2000
      14.3,      0.000,      0.000,         0,      1.2487,      0.2083
      14.6,      0.000,      0.000,         0,      1.2985,      0.2167
      15.0,      0.000,      0.000,         0,      1.3485,      0.2250
      15.3,      0.000,      0.000,         0,      1.3986,      0.2333
      15.7,      0.000,      0.000,         0,      1.4488,      0.2417
      16.0,      0.000,      0.000,         0,      1.4987,      0.2500
      16.3,      0.000,      0.000,         0,      1.5487,      0.2583
      16.6,      0.000,      0.000,         0,      1.5988,      0.2667
      16.9,      0.000,      0.000,         0,      1.6486,      0.2750
      17.2,      0.000,      0.000,         0,      1.6985,      0.2833
      17.5,      0.000,      0.000,         0,      1.7485,      0.2917
      17.8,      0.000,      0.000,         0,      1.7984,      0.3000
      17.9,      0.000,      0.000,         0,      1.8486,      0.3083
      17.6,      0.000,      0.000,         0,      1.8986,      0.3167
      16.9,      0.000,      0.000,         0,      1.9487,      0.3250
      17.1,      0.000,      0.000,         0,      1.9987,      0.3333
      17.2,      0.000,      0.000,         0,      2.0486,      0.3417
      17.3,      0.000,      0.000,         0,      2.0987,      0.3500
      17.5,      0.000,      0.000,         0,      2.1487,      0.3583
      17.6,      0.000,      0.000,         0,      2.1985,      0.3667
      17.8,      0.000,      0.000,         0,      2.2487,      0.3750
      17.9,      0.000,      0.000,         0,      2.2988,      0.3833
      18.1,      0.000,      0.000,         0,      2.3487,      0.3917
      18.2,      0.000,      0.000,         0,      2.3986,      0.4000
      18.4,      0.000,      0.000,         0,      2.4485,      0.4083
      18.5,      0.000,      0.000,         0,      2.4987,      0.4167
      18.7,      0.000,      0.000,         0,      2.5487,      0.4250
      18.8,      0.000,      0.000,         0,      2.5988,      0.4333
      18.9,      0.000,      0.000,         0,      2.6486,      0.4417
      19.1,      0.000,      0.000,         0,      2.6985,      0.4500
      19.2,      0.000,      0.000,         0,      2.7487,      0.4583
      19.3,      0.000,      0.000,         0,      2.7987,      0.4667
      19.5,      0.000,      0.000,         0,      2.8487,      0.4750
      19.6,      0.000,      0.000,         0,      2.8986,      0.4833
      19.7,      0.000,      0.000,         0,      2.9486,      0.4917
      19.9,      0.000,      0.000,         0,      2.9987,      0.5000
      20.0,      0.000,      0.000,         0,      3.0486,      0.5083
      20.1,      0.000,      0.000,         0,      3.0986,      0.5167
      20.2,      0.000,      0.000,         0,      3.1487,      0.5250
      20.4,      0.000,      0.000,         0,      3.1988,      0.5333
      20.5,      0.000,      0.000,         0,      3.2487,      0.5417
      20.6,      0.000,      0.000,         0,      3.2986,      0.5500
      20.7,      0.000,      0.000,         0,      3.3487,      0.5583
      20.9,      0.000,      0.000,         0,      3.3987,      0.5667
      21.0,      0.000,      0.000,         0,      3.4486,      0.5750
      21.1,      0.000,      0.000,         0,      3.4985,      0.5833
      21.2,      0.000,      0.000,         0,      3.5487,      0.5917
      21.3,      0.000,      0.000,         0,      3.5987,      0.6000
      21.4,      0.000,      0.000,         0,      3.6486,      0.6083
      21.6,      0.000,      0.000,         0,      3.6985,      0.6167
      21.7,      0.000,      0.000,         0,      3.7484,      0.6250
      21.8,      0.000,      0.000,         0,      3.7985,      0.6333
      21.9,      0.000,      0.000,         0,      3.8487,      0.6417
      22.0,      0.000,      0.000,         0,      3.8987,      0.6500
      22.1,      0.000,      0.000,         0,      3.9486,      0.6583
      22.2,      0.000,      0.000,         0,      3.9986,      0.6667
      22.3,      0.000,      0.000,         0,      4.0486,      0.6750
      22.4,      0.000,      0.000,         0,      4.0987,      0.6833
      22.5,      0.000,      0.000,         0,      4.1485,      0.6917
      22.6,      0.000,      0.000,         0,      4.1985,      0.7000
      22.7,      0.000,      0.000,         0,      4.2487,      0.7083
      22.8,      0.000,      0.000,         0,      4.2986,      0.7167
      22.9,      0.000,      0.000,         0,      4.3486,      0.7250
      23.0,      0.000,      0.000,         0,      4.3986,      0.7333
      23.1,      0.000,      0.000,         0,      4.4487,      0.7417
      23.2,      0.000,      0.000,         0,      4.4987,      0.7500
      23.3,      0.000,      0.000,         0,      4.5486,      0.7583
      23.4,      0.000,      0.000,         0,      4.5985,      0.7667
      23.5,      0.000,      0.000,         0,      4.6484,      0.7750
      23.6,      0.000,      0.000,         0,      4.6985,      0.7833
      23.7,      0.000,      0.000,         0,      4.7487,      0.7917
      23.8,      0.000,      0.000,         0,      4.7987,      0.8000
      23.9,      0.000,      0.000,         0,      4.8486,      0.8083
      24.0,      0.000,      0.000,         0,      4.8986,      0.8167
      24.1,      0.000,      0.000,         0,      4.9487,      0.8250
      24.2,      0.000,      0.000,         0,      4.9985,      0.8333
      24.2,      0.000,      0.000,         0,      5.0486,      0.8417
      24.3,      0.000,      0.000,         0,      5.0985,      0.8500
      24.4,      0.000,      0.000,         0,      5.1487,      0.8583
      24.5,      0.000,      0.000,         0,      5.1987,      0.8667
      24.6,      0.000,      0.000,         0,      5.2487,      0.8750
      24.7,      0.000,      0.000,         0,      5.2987,      0.8833
      24.8,      0.000,      0.000,         0,      5.3486,      0.8917
      24.9,      0.000,      0.000,         0,      5.3985,      0.9000
      25.0,      0.000,      0.000,         0,      5.4486,      0.9083
      25.1,      0.000,      0.000,         0,      5.4985,      0.9167
      25.2,      0.000,      0.000,         0,      5.5487,      0.9250
      25.3,      0.000,      0.000,         0,      5.5988,      0.9333
      25.4,      0.000,      0.000,         0,      5.6487,      0.9417
      25.5,      0.000,      0.000,         0,      5.6986,      0.9500
      25.6,      0.000,      0.000,         0,      5.7484,      0.9583
      25.7,      0.000,      0.000,         0,      5.7986,      0.9667
      25.8,      0.000,      0.000,         0,      5.8487,      0.9750
      25.9,      0.000,      0.000,         0,      5.8987,      0.9833
      26.0,      0.000,      0.000,         0,      5.9486,      0.9917
      26.1,      0.000,      0.000,         0,      5.9985,      1.0000
      26.2,      0.000,      0.000,         0,      6.0486,      1.0083
      26.3,      0.000,      0.000,         0,      6.0986,      1.0167
      26.5,      0.000,      0.000,         0,      6.1486,      1.0250
      26.6,      0.000,      0.000,         0,      6.1987,      1.0333
      26.7,      0.000,      0.000,         0,      6.2485,      1.0417
      26.8,      0.000,      0.000,         0,      6.2985,      1.0500
      26.9,      0.000,      0.000,         0,      6.3487,      1.0583
      27.0,      0.000,      0.000,         0,      6.3986,      1.0667
      27.1,      0.000,      0.000,         0,      6.4487,      1.0750
      27.1,      0.000,      0.000,         0,      6.4986,      1.0833
      27.2,      0.000,      0.000,         0,      6.5486,      1.0917
      27.3,      0.000,      0.000,         0,      6.5987,      1.1000
      27.4,      0.000,      0.000,         0,      6.6488,      1.1083
      27.5,      0.000,      0.000,         0,      6.6985,      1.1167
      27.6,      0.000,      0.000,         0,      6.7486,      1.1250
      27.7,      0.000,      0.000,         0,      6.7985,      1.1333
      27.8,      0.000,      0.000,         0,      6.8487,      1.1417
      27.9,      0.000,      0.000,         0,      6.8987,      1.1500
      28.0,      0.000,      0.000,         0,      6.9486,      1.1583
      28.1,      0.000,      0.000,         0,      6.9986,      1.1667
      28.2,      0.000,      0.000,         0,      7.0485,      1.1750
      28.3,      0.000,      0.000,         0,      7.0985,      1.1833
      28.4,      0.000,      0.000,         0,      7.1486,      1.1917
      28.5,      0.000,      0.000,         0,      7.1988,      1.2000
      28.6,      0.000,      0.000,         0,      7.2487,      1.2083
      28.7,      0.000,      0.000,         0,      7.2986,      1.2167
      28.8,      0.000,      0.000,         0,      7.3485,      1.2250
      28.9,      0.000,      0.000,         0,      7.3985,      1.2333
      29.0,      0.000,      0.000,         0,      7.4485,      1.2417
      29.1,      0.000,      0.000,         0,      7.4987,      1.2500
      29.2,      0.000,      0.000,         0,      7.5486,      1.2583
      29.3,      0.000,      0.000,         0,      7.5987,      1.2667
      29.4,      0.000,      0.000,         0,      7.6486,      1.2750
      29.5,      0.000,      0.000,         0,      7.6986,      1.2833
      29.6,      0.000,      0.000,         0,      7.7488,      1.2917
      29.7,      0.000,      0.000,         0,      7.7986,      1.3000
      29.8,      0.000,      0.000,         0,      7.8484,      1.3083
      29.9,      0.000,      0.000,         0,      7.8986,      1.3167
      30.0,      0.000,      0.000,         0,      7.9485,      1.3250
      30.1,      0.000,      0.000,         0,      7.9987,      1.3333
      30.1,      0.000,      0.000,         0,      8.0486,      1.3417
      30.2,      0.000,      0.000,         0,      8.0986,      1.3500
      30.3,      0.000,      0.000,         0,      8.1486,      1.3583
      30.4,      0.000,      0.000,         0,      8.1987,      1.3667
      30.5,      0.000,      0.000,         0,      8.2485,      1.3750
      30.6,      0.000,      0.000,         0,      8.2985,      1.3833
      30.7,      0.000,      0.000,         0,      8.3486,      1.3917
      30.8,      0.000,      0.000,         0,      8.3986,      1.4000
      30.9,      0.000,      0.000,         0,      8.4485,      1.4083
      31.0,      0.000,      0.000,         0,      8.4986,      1.4167
      31.1,      0.000,      0.000,         0,      8.5487,      1.4250
      31.2,      0.000,      0.000,         0,      8.5987,      1.4333
      31.3,      0.000,      0.000,         0,      8.6486,      1.4417
      31.4,      0.000,      0.000,         0,      8.6985,      1.4500
      31.5,      0.000,      0.000,         0,      8.7486,      1.4583
      31.6,      0.000,      0.000,         0,      8.7986,      1.4667
      31.7,      0.000,      0.000,         0,      8.8486,      1.4750
      31.8,      0.000,      0.000,         0,      8.8987,      1.4833
      31.9,      0.000,      0.000,         0,      8.9486,      1.4917
      32.0,      0.000,      0.000,         0,      8.9985,      1.5000
      32.1,      0.000,      0.000,         0,      9.0486,      1.5083
      32.2,      0.000,      0.000,         0,      9.0985,      1.5167
      32.3,      0.000,      0.000,         0,      9.1485,      1.5250
      32.4,      0.000,      0.000,         0,      9.1986,      1.5333
      32.4,      0.000,      0.000,         0,      9.2485,      1.5417
      32.5,      0.000,      0.000,         0,      9.2985,      1.5500
      32.6,      0.000,      0.000,         0,      9.3487,      1.5583
      32.7,      0.000,      0.000,         0,      9.3985,      1.5667
      32.8,      0.000,      0.000,         0,      9.4485,      1.5750
      32.9,      0.000,      0.000,         0,      9.4986,      1.5833
      33.0,      0.000,      0.000,         0,      9.5484,      1.5917
      33.1,      0.000,      0.000,         0,      9.5986,      1.6000
      33.2,      0.000,      0.000,         0,      9.6486,      1.6083
      33.3,      0.000,      0.000,         0,      9.6986,      1.6167
      33.4,      0.000,      0.000,         0,      9.7485,      1.6250
      33.5,      0.000,      0.000,         0,      9.7985,      1.6333
      33.6,      0.000,      0.000,         0,      9.8486,      1.6417
      33.7,      0.000,      0.000,         0,      9.8987,      1.6500
      33.8,      0.000,      0.000,         0,      9.9486,      1.6583
      33.9,      0.000,      0.000,         0,      9.9985,      1.6667
      34.0,      0.000,      0.000,         0,     10.0485,      1.6750
      34.1,      0.000,      0.000,         0,     10.0986,      1.6833
      34.2,      0.000,      0.000,         0,     10.1488,      1.6917
      34.2,      0.000,      0.000,         0,     10.1986,      1.7000
      34.3,      0.000,      0.000,         0,     10.2485,      1.7083
      34.4,      0.000,      0.000,         0,     10.2983,      1.7167
      34.5,      0.000,      0.000,         0,     10.3484,      1.7250
      34.6,      0.000,      0.000,         0,     10.3985,      1.7333
      34.7,      0.000,      0.000,         0,     10.4486,      1.7417
      34.8,      0.000,      0.000,         0,     10.4986,      1.7500
      34.9,      0.000,      0.000,         0,     10.5486,      1.7583
      35.0,      0.000,      0.000,         0,     10.5985,      1.7667
      35.1,      0.000,      0.000,         0,     10.6485,      1.7750
      35.1,      0.000,      0.000,         0,     10.6984,      1.7833
      35.2,      0.000,      0.000,         0,     10.7485,      1.7917
      35.3,      0.000,      0.000,         0,     10.7985,      1.8000
      35.4,      0.000,      0.000,         0,     10.8486,      1.8083
      35.5,      0.000,      0.000,         0,     10.8986,      1.8167
      35.6,      0.000,      0.000,         0,     10.9486,      1.8250
      35.7,      0.000,      0.000,         0,     10.9986,      1.8333
      35.7,      0.000,      0.000,         0,     11.0486,      1.8417
      35.8,      0.000,      0.000,         0,     11.0986,      1.8500
      35.9,      0.000,      0.000,         0,     11.1485,      1.8583
      36.0,      0.000,      0.000,         0,     11.1986,      1.8667
      36.1,      0.000,      0.000,         0,     11.2484,      1.8750
      36.2,      0.000,      0.000,         0,     11.2986,      1.8833
      36.3,      0.000,      0.000,         0,     11.3487,      1.8917
      36.3,      0.000,      0.000,         0,     11.3986,      1.9000
      36.4,      0.000,      0.000,         0,     11.4485,      1.9083
      36.5,      0.000,      0.000,         0,     11.4986,      1.9167
      36.6,      0.000,      0.000,         0,     11.5486,      1.9250
      36.7,      0.000,      0.000,         0,     11.5986,      1.9333
      36.7,      0.000,      0.000,         0,     11.6486,      1.9417
      36.8,      0.000,      0.000,         0,     11.6985,      1.9500
      36.9,      0.000,      0.000,         0,     11.7485,      1.9583
      37.0,      0.000,      0.000,         0,     11.7986,      1.9667
      37.1,      0.000,      0.000,         0,     11.8487,      1.9750
      37.1,      0.000,      0.000,         0,     11.8987,      1.9833
      37.2,      0.000,      0.000,         0,     11.9484,      1.9917
      37.3,      0.000,      0.000,         0,     11.9985,      2.0000
      37.4,      0.000,      0.000,         0,     12.0485,      2.0083
      37.5,      0.000,      0.000,         0,     12.0985,      2.0167
      37.5,      0.000,      0.000,         0,     12.1486,      2.0250
      37.6,      0.000,      0.000,         0,     12.1986,      2.0333
      37.7,      0.000,      0.000,         0,     12.2486,      2.0417
      37.8,      0.000,      0.000,         0,     12.2986,      2.0500
      37.8,      0.000,      0.000,         0,     12.3485,      2.0583
      37.9,      0.000,      0.000,         0,     12.3985,      2.0667
      38.0,      0.000,      0.000,         0,     12.4485,      2.0750
      38.1,      0.000,      0.000,         0,     12.4986,      2.0833
      38.2,      0.000,      0.000,         0,     12.5486,      2.0917
      38.3,      0.000,      0.000,         0,     12.5986,      2.1000
      38.4,      0.000,      0.000,         0,     12.6485,      2.1083
      38.4,      0.000,      0.000,         0,     12.6985,      2.1167
      38.5,      0.000,      0.000,         0,     12.7486,      2.1250
      38.6,      0.000,      0.000,         0,     12.7985,      2.1333
      38.7,      0.000,      0.000,         0,     12.8485,      2.1417
      38.8,      0.000,      0.000,         0,     12.8985,      2.1500
      38.9,      0.000,      0.000,         0,     12.9486,      2.1583
      38.9,      0.000,      0.000,         0,     12.9985,      2.1667
      39.0,      0.000,      0.000,         0,     13.0485,      2.1750
      39.1,      0.000,      0.000,         0,     13.0985,      2.1833
      39.2,      0.000,      0.000,         0,     13.1485,      2.1917
      39.3,      0.000,      0.000,         0,     13.1986,      2.2000
      39.3,      0.000,      0.000,         0,     13.2485,      2.2083
      39.4,      0.000,      0.000,         0,     13.2985,      2.2167
      39.5,      0.000,      0.000,         0,     13.3485,      2.2250
      39.6,      0.000,      0.000,         0,     13.3987,      2.2333
      39.6,      0.000,      0.000,         0,     13.4487,      2.2417
      39.7,      0.000,      0.000,         0,     13.4985,      2.2500
      39.8,      0.000,      0.000,         0,     13.5485,      2.2583
      39.9,      0.000,      0.000,         0,     13.5984,      2.2667
      39.9,      0.000,      0.000,         0,     13.6484,      2.2750
      40.0,      0.000,      0.000,         0,     13.6985,      2.2833
      40.1,      0.000,      0.000,         0,     13.7485,      2.2917
      40.1,      0.000,      0.000,         0,     13.7986,      2.3000
      40.2,      0.000,      0.000,         0,     13.8487,      2.3083
      40.3,      0.000,      0.000,         0,     13.8985,      2.3167
      40.3,      0.000,      0.000,         0,     13.9484,      2.3250
      40.4,      0.000,      0.000,         0,     13.9985,      2.3333
      40.4,      0.000,      0.000,         0,     14.0485,      2.3417
      40.4,      0.000,      0.000,         0,     14.0986,      2.3500
      40.4,      0.000,      0.000,         0,     14.1485,      2.3583
      40.4,      0.000,      0.000,         0,     14.1985,      2.3667
      40.4,      0.000,      0.000,         0,     14.2487,      2.3750
      40.4,      0.000,      0.000,         0,     14.2986,      2.3833
      40.4,      0.000,      0.000,         0,     14.3486,      2.3917
      40.3,      0.000,      0.000,         0,     14.3986,      2.4000
      40.3,      0.000,      0.000,         0,     14.4484,      2.4083
      40.3,      0.000,      0.000,         0,     14.4985,      2.4167
      40.2,      0.000,      0.000,         0,     14.5486,      2.4250
      40.1,      0.000,      0.000,         0,     14.5986,      2.4333
      40.1,      0.000,      0.000,         0,     14.6485,      2.4417
      40.0,      0.000,      0.000,         0,     14.6985,      2.4500
      39.9,      0.000,      0.000,         0,     14.7485,      2.4583
      39.8,      0.000,      0.000,         0,     14.7985,      2.4667
      39.6,      0.000,      0.000,         0,     14.8485,      2.4750
      39.5,      0.000,      0.000,         0,     14.8985,      2.4833
      39.3,      0.000,      0.000,         0,     14.9484,      2.4917
      39.1,      0.000,      0.000,         0,     14.9985,      2.5000
      38.8,      0.000,      0.000,         0,     15.0485,      2.5083
      38.5,      0.000,      0.000,         0,     15.0986,      2.5167
       0.3,      0.000,      0.000,         0,     15.1486,      2.5250
       0.3,      0.000,      0.000,         0,     15.1985,      2.5333
       0.3,      0.000,      0.000,         0,     15.2483,      2.5417