File: Alban repo/Quiz 1/suction cup instron tests/july-2020-force-vs-viscosity_raw-data/D30E10-01-in10-1-onwhiteplatic-diaphragmpump-10mm-test1.raw
Operator: 1

Date,Time,Specimen#
07/22/20,12:30:24,1

---------------------------------------


Area (mm^2):,      1.00,Flat,     25.40,     25.40,     25.40
Gage Len (mm):,     25.40


LOAD (N),STRAIN 1 (mm),STRAIN 2 (mm),STRESS (MPa),POSITION (mm),TIME (min)
       3.3,      0.000,      0.000,         0,      0.0817,      0.0083
       4.6,      0.000,      0.000,         0,      0.1648,      0.0167
       5.9,      0.000,      0.000,         0,      0.2480,      0.0250
       7.1,      0.000,      0.000,         0,      0.3315,      0.0333
       8.3,      0.000,      0.000,         0,      0.4149,      0.0417
       9.4,      0.000,      0.000,         0,      0.4981,      0.0500
      10.6,      0.000,      0.000,         0,      0.5814,      0.0583
      11.7,      0.000,      0.000,         0,      0.6647,      0.0667
      12.7,      0.000,      0.000,         0,      0.7482,      0.0750
      13.8,      0.000,      0.000,         0,      0.8314,      0.0833
      14.8,      0.000,      0.000,         0,      0.9148,      0.0917
      15.7,      0.000,      0.000,         0,      0.9981,      0.1000
      16.7,      0.000,      0.000,         0,      1.0815,      0.1083
      17.6,      0.000,      0.000,         0,      1.1648,      0.1167
      18.5,      0.000,      0.000,         0,      1.2482,      0.1250
      19.4,      0.000,      0.000,         0,      1.3314,      0.1333
      20.3,      0.000,      0.000,         0,      1.4148,      0.1417
      21.2,      0.000,      0.000,         0,      1.4982,      0.1500
      22.0,      0.000,      0.000,         0,      1.5813,      0.1583
      22.8,      0.000,      0.000,         0,      1.6648,      0.1667
      23.5,      0.000,      0.000,         0,      1.7482,      0.1750
      24.3,      0.000,      0.000,         0,      1.8314,      0.1833
      25.0,      0.000,      0.000,         0,      1.9143,      0.1917
      25.6,      0.000,      0.000,         0,      1.9981,      0.2000
      26.3,      0.000,      0.000,         0,      2.0814,      0.2083
      26.9,      0.000,      0.000,         0,      2.1646,      0.2167
      27.5,      0.000,      0.000,         0,      2.2480,      0.2250
      28.1,      0.000,      0.000,         0,      2.3315,      0.2333
      28.5,      0.000,      0.000,         0,      2.4147,      0.2417
      28.4,      0.000,      0.000,         0,      2.4981,      0.2500
      28.6,      0.000,      0.000,         0,      2.5812,      0.2583
      29.1,      0.000,      0.000,         0,      2.6647,      0.2667
      29.5,      0.000,      0.000,         0,      2.7482,      0.2750
      30.0,      0.000,      0.000,         0,      2.8314,      0.2833
      30.4,      0.000,      0.000,         0,      2.9147,      0.2917
      30.8,      0.000,      0.000,         0,      2.9981,      0.3000
      31.2,      0.000,      0.000,         0,      3.0814,      0.3083
      31.6,      0.000,      0.000,         0,      3.1647,      0.3167
      32.0,      0.000,      0.000,         0,      3.2479,      0.3250
      32.4,      0.000,      0.000,         0,      3.3314,      0.3333
      32.8,      0.000,      0.000,         0,      3.4146,      0.3417
      33.2,      0.000,      0.000,         0,      3.4979,      0.3500
      33.6,      0.000,      0.000,         0,      3.5812,      0.3583
      33.9,      0.000,      0.000,         0,      3.6648,      0.3667
      34.2,      0.000,      0.000,         0,      3.7479,      0.3750
      34.6,      0.000,      0.000,         0,      3.8314,      0.3833
      34.9,      0.000,      0.000,         0,      3.9146,      0.3917
      35.2,      0.000,      0.000,         0,      3.9982,      0.4000
      35.5,      0.000,      0.000,         0,      4.0813,      0.4083
      35.8,      0.000,      0.000,         0,      4.1647,      0.4167
      36.1,      0.000,      0.000,         0,      4.2480,      0.4250
      36.4,      0.000,      0.000,         0,      4.3313,      0.4333
      36.7,      0.000,      0.000,         0,      4.4146,      0.4417
      37.0,      0.000,      0.000,         0,      4.4979,      0.4500
      37.3,      0.000,      0.000,         0,      4.5812,      0.4583
      37.5,      0.000,      0.000,         0,      4.6645,      0.4667
      37.8,      0.000,      0.000,         0,      4.7480,      0.4750
      38.1,      0.000,      0.000,         0,      4.8313,      0.4833
      38.3,      0.000,      0.000,         0,      4.9144,      0.4917
      38.6,      0.000,      0.000,         0,      4.9980,      0.5000
      38.8,      0.000,      0.000,         0,      5.0813,      0.5083
      39.1,      0.000,      0.000,         0,      5.1645,      0.5167
      39.3,      0.000,      0.000,         0,      5.2480,      0.5250
      39.6,      0.000,      0.000,         0,      5.3312,      0.5333
      39.8,      0.000,      0.000,         0,      5.4146,      0.5417
      40.0,      0.000,      0.000,         0,      5.4976,      0.5500
      40.3,      0.000,      0.000,         0,      5.5812,      0.5583
      40.5,      0.000,      0.000,         0,      5.6645,      0.5667
      40.7,      0.000,      0.000,         0,      5.7479,      0.5750
      40.9,      0.000,      0.000,         0,      5.8310,      0.5833
      41.2,      0.000,      0.000,         0,      5.9146,      0.5917
      41.4,      0.000,      0.000,         0,      5.9980,      0.6000
      41.6,      0.000,      0.000,         0,      6.0812,      0.6083
      41.8,      0.000,      0.000,         0,      6.1645,      0.6167
      42.0,      0.000,      0.000,         0,      6.2479,      0.6250
      42.2,      0.000,      0.000,         0,      6.3313,      0.6333
      42.4,      0.000,      0.000,         0,      6.4144,      0.6417
      42.7,      0.000,      0.000,         0,      6.4978,      0.6500
      42.9,      0.000,      0.000,         0,      6.5810,      0.6583
      43.1,      0.000,      0.000,         0,      6.6647,      0.6667
      43.3,      0.000,      0.000,         0,      6.7477,      0.6750
      43.5,      0.000,      0.000,         0,      6.8309,      0.6833
      43.7,      0.000,      0.000,         0,      6.9146,      0.6917
      43.9,      0.000,      0.000,         0,      6.9977,      0.7000
      44.1,      0.000,      0.000,         0,      7.0812,      0.7083
      44.3,      0.000,      0.000,         0,      7.1644,      0.7167
      44.5,      0.000,      0.000,         0,      7.2477,      0.7250
      44.7,      0.000,      0.000,         0,      7.3312,      0.7333
      44.9,      0.000,      0.000,         0,      7.4146,      0.7417
      45.1,      0.000,      0.000,         0,      7.4976,      0.7500
      45.3,      0.000,      0.000,         0,      7.5810,      0.7583
      45.5,      0.000,      0.000,         0,      7.6644,      0.7667
      45.7,      0.000,      0.000,         0,      7.7478,      0.7750
      45.9,      0.000,      0.000,         0,      7.8310,      0.7833
      46.1,      0.000,      0.000,         0,      7.9144,      0.7917
      46.3,      0.000,      0.000,         0,      7.9980,      0.8000
      46.4,      0.000,      0.000,         0,      8.0812,      0.8083
      46.6,      0.000,      0.000,         0,      8.1644,      0.8167
      46.8,      0.000,      0.000,         0,      8.2478,      0.8250
      47.0,      0.000,      0.000,         0,      8.3313,      0.8333
      47.2,      0.000,      0.000,         0,      8.4144,      0.8417
      47.4,      0.000,      0.000,         0,      8.4976,      0.8500
      47.6,      0.000,      0.000,         0,      8.5811,      0.8583
      47.8,      0.000,      0.000,         0,      8.6646,      0.8667
      48.0,      0.000,      0.000,         0,      8.7475,      0.8750
      48.2,      0.000,      0.000,         0,      8.8311,      0.8833
      48.4,      0.000,      0.000,         0,      8.9144,      0.8917
      48.6,      0.000,      0.000,         0,      8.9978,      0.9000
      48.7,      0.000,      0.000,         0,      9.0811,      0.9083
      48.9,      0.000,      0.000,         0,      9.1644,      0.9167
      49.1,      0.000,      0.000,         0,      9.2475,      0.9250
      49.3,      0.000,      0.000,         0,      9.3311,      0.9333
      49.4,      0.000,      0.000,         0,      9.4143,      0.9417
      49.6,      0.000,      0.000,         0,      9.4977,      0.9500
      49.8,      0.000,      0.000,         0,      9.5811,      0.9583
      50.0,      0.000,      0.000,         0,      9.6644,      0.9667
      50.1,      0.000,      0.000,         0,      9.7477,      0.9750
      50.3,      0.000,      0.000,         0,      9.8308,      0.9833
      50.5,      0.000,      0.000,         0,      9.9145,      0.9917
      50.6,      0.000,      0.000,         0,      9.9977,      1.0000
      50.8,      0.000,      0.000,         0,     10.0811,      1.0083
      50.9,      0.000,      0.000,         0,     10.1641,      1.0167
      51.1,      0.000,      0.000,         0,     10.2477,      1.0250
      51.2,      0.000,      0.000,         0,     10.3310,      1.0333
      51.4,      0.000,      0.000,         0,     10.4143,      1.0417
      51.5,      0.000,      0.000,         0,     10.4977,      1.0500
      51.6,      0.000,      0.000,         0,     10.5809,      1.0583
      51.8,      0.000,      0.000,         0,     10.6645,      1.0667
      51.9,      0.000,      0.000,         0,     10.7477,      1.0750
      52.0,      0.000,      0.000,         0,     10.8309,      1.0833
      52.2,      0.000,      0.000,         0,     10.9143,      1.0917
      52.3,      0.000,      0.000,         0,     10.9977,      1.1000
      52.4,      0.000,      0.000,         0,     11.0809,      1.1083
      52.5,      0.000,      0.000,         0,     11.1643,      1.1167
      52.6,      0.000,      0.000,         0,     11.2476,      1.1250
      52.7,      0.000,      0.000,         0,     11.3311,      1.1333
      52.8,      0.000,      0.000,         0,     11.4143,      1.1417
      52.9,      0.000,      0.000,         0,     11.4976,      1.1500
      53.0,      0.000,      0.000,         0,     11.5811,      1.1583
      53.0,      0.000,      0.000,         0,     11.6643,      1.1667
      53.1,      0.000,      0.000,         0,     11.7477,      1.1750
      53.2,      0.000,      0.000,         0,     11.8306,      1.1833
      53.3,      0.000,      0.000,         0,     11.9142,      1.1917
      53.3,      0.000,      0.000,         0,     11.9976,      1.2000
      53.4,      0.000,      0.000,         0,     12.0810,      1.2083
      53.4,      0.000,      0.000,         0,     12.1643,      1.2167
      53.5,      0.000,      0.000,         0,     12.2475,      1.2250
      53.5,      0.000,      0.000,         0,     12.3309,      1.2333
      53.5,      0.000,      0.000,         0,     12.4143,      1.2417
      53.5,      0.000,      0.000,         0,     12.4974,      1.2500
      53.5,      0.000,      0.000,         0,     12.5808,      1.2583
      53.5,      0.000,      0.000,         0,     12.6643,      1.2667
      53.5,      0.000,      0.000,         0,     12.7476,      1.2750
      53.4,      0.000,      0.000,         0,     12.8308,      1.2833
      53.3,      0.000,      0.000,         0,     12.9141,      1.2917
      53.2,      0.000,      0.000,         0,     12.9977,      1.3000
      53.0,      0.000,      0.000,         0,     13.0808,      1.3083
      52.8,      0.000,      0.000,         0,     13.1637,      1.3167
      52.4,      0.000,      0.000,         0,     13.2475,      1.3250
      51.8,      0.000,      0.000,         0,     13.3310,      1.3333
      50.9,      0.000,      0.000,         0,     13.4140,      1.3417
      49.0,      0.000,      0.000,         0,     13.4976,      1.3500
       0.0,      0.000,      0.000,         0,     13.5809,      1.3583
       0.0,      0.000,      0.000,         0,     13.6643,      1.3667
       0.0,      0.000,      0.000,         0,     13.7474,      1.3750
       0.0,      0.000,      0.000,         0,     13.8309,      1.3833
       0.0,      0.000,      0.000,         0,     13.9142,      1.3917
       0.0,      0.000,      0.000,         0,     13.9976,      1.4000
       0.0,      0.000,      0.000,         0,     14.0808,      1.4083