File: Alban repo/Quiz 1/suction cup instron tests/july-2020-force-vs-viscosity_raw-data/D30E10-01-in10-1-onwhiteplatic-diaphragmpump-10mm-test3.raw
Operator: 1

Date,Time,Specimen#
07/22/20,12:36:46,1

---------------------------------------


Area (mm^2):,      1.00,Flat,     25.40,     25.40,     25.40
Gage Len (mm):,     25.40


LOAD (N),STRAIN 1 (mm),STRAIN 2 (mm),STRESS (MPa),POSITION (mm),TIME (min)
       3.3,      0.000,      0.000,         0,      0.0815,      0.0083
       4.6,      0.000,      0.000,         0,      0.1649,      0.0167
       5.9,      0.000,      0.000,         0,      0.2478,      0.0250
       7.1,      0.000,      0.000,         0,      0.3315,      0.0333
       8.3,      0.000,      0.000,         0,      0.4149,      0.0417
       9.4,      0.000,      0.000,         0,      0.4983,      0.0500
      10.5,      0.000,      0.000,         0,      0.5814,      0.0583
      11.6,      0.000,      0.000,         0,      0.6648,      0.0667
      12.6,      0.000,      0.000,         0,      0.7481,      0.0750
      13.6,      0.000,      0.000,         0,      0.8315,      0.0833
      14.6,      0.000,      0.000,         0,      0.9148,      0.0917
      15.6,      0.000,      0.000,         0,      0.9982,      0.1000
      16.5,      0.000,      0.000,         0,      1.0817,      0.1083
      17.4,      0.000,      0.000,         0,      1.1648,      0.1167
      18.3,      0.000,      0.000,         0,      1.2481,      0.1250
      19.2,      0.000,      0.000,         0,      1.3314,      0.1333
      20.1,      0.000,      0.000,         0,      1.4149,      0.1417
      20.9,      0.000,      0.000,         0,      1.4981,      0.1500
      21.7,      0.000,      0.000,         0,      1.5814,      0.1583
      22.5,      0.000,      0.000,         0,      1.6648,      0.1667
      23.2,      0.000,      0.000,         0,      1.7481,      0.1750
      23.9,      0.000,      0.000,         0,      1.8315,      0.1833
      24.6,      0.000,      0.000,         0,      1.9145,      0.1917
      25.3,      0.000,      0.000,         0,      1.9981,      0.2000
      25.9,      0.000,      0.000,         0,      2.0813,      0.2083
      26.6,      0.000,      0.000,         0,      2.1648,      0.2167
      27.2,      0.000,      0.000,         0,      2.2481,      0.2250
      27.7,      0.000,      0.000,         0,      2.3314,      0.2333
      28.2,      0.000,      0.000,         0,      2.4147,      0.2417
      28.4,      0.000,      0.000,         0,      2.4981,      0.2500
      27.8,      0.000,      0.000,         0,      2.5814,      0.2583
      28.1,      0.000,      0.000,         0,      2.6646,      0.2667
      28.6,      0.000,      0.000,         0,      2.7483,      0.2750
      29.0,      0.000,      0.000,         0,      2.8315,      0.2833
      29.4,      0.000,      0.000,         0,      2.9147,      0.2917
      29.8,      0.000,      0.000,         0,      2.9980,      0.3000
      30.2,      0.000,      0.000,         0,      3.0814,      0.3083
      30.6,      0.000,      0.000,         0,      3.1648,      0.3167
      31.0,      0.000,      0.000,         0,      3.2480,      0.3250
      31.4,      0.000,      0.000,         0,      3.3314,      0.3333
      31.8,      0.000,      0.000,         0,      3.4148,      0.3417
      32.2,      0.000,      0.000,         0,      3.4978,      0.3500
      32.5,      0.000,      0.000,         0,      3.5812,      0.3583
      32.9,      0.000,      0.000,         0,      3.6647,      0.3667
      33.2,      0.000,      0.000,         0,      3.7480,      0.3750
      33.6,      0.000,      0.000,         0,      3.8314,      0.3833
      33.9,      0.000,      0.000,         0,      3.9147,      0.3917
      34.2,      0.000,      0.000,         0,      3.9979,      0.4000
      34.6,      0.000,      0.000,         0,      4.0813,      0.4083
      34.9,      0.000,      0.000,         0,      4.1648,      0.4167
      35.2,      0.000,      0.000,         0,      4.2479,      0.4250
      35.5,      0.000,      0.000,         0,      4.3314,      0.4333
      35.8,      0.000,      0.000,         0,      4.4147,      0.4417
      36.1,      0.000,      0.000,         0,      4.4981,      0.4500
      36.4,      0.000,      0.000,         0,      4.5812,      0.4583
      36.7,      0.000,      0.000,         0,      4.6647,      0.4667
      37.0,      0.000,      0.000,         0,      4.7479,      0.4750
      37.2,      0.000,      0.000,         0,      4.8313,      0.4833
      37.5,      0.000,      0.000,         0,      4.9144,      0.4917
      37.8,      0.000,      0.000,         0,      4.9979,      0.5000
      38.1,      0.000,      0.000,         0,      5.0814,      0.5083
      38.3,      0.000,      0.000,         0,      5.1647,      0.5167
      38.6,      0.000,      0.000,         0,      5.2479,      0.5250
      38.8,      0.000,      0.000,         0,      5.3312,      0.5333
      39.1,      0.000,      0.000,         0,      5.4147,      0.5417
      39.3,      0.000,      0.000,         0,      5.4978,      0.5500
      39.6,      0.000,      0.000,         0,      5.5812,      0.5583
      39.9,      0.000,      0.000,         0,      5.6645,      0.5667
      40.1,      0.000,      0.000,         0,      5.7482,      0.5750
      40.3,      0.000,      0.000,         0,      5.8313,      0.5833
      40.6,      0.000,      0.000,         0,      5.9143,      0.5917
      40.8,      0.000,      0.000,         0,      5.9978,      0.6000
      41.0,      0.000,      0.000,         0,      6.0813,      0.6083
      41.2,      0.000,      0.000,         0,      6.1646,      0.6167
      41.5,      0.000,      0.000,         0,      6.2479,      0.6250
      41.7,      0.000,      0.000,         0,      6.3314,      0.6333
      41.9,      0.000,      0.000,         0,      6.4146,      0.6417
      42.1,      0.000,      0.000,         0,      6.4979,      0.6500
      42.4,      0.000,      0.000,         0,      6.5812,      0.6583
      42.6,      0.000,      0.000,         0,      6.6646,      0.6667
      42.8,      0.000,      0.000,         0,      6.7477,      0.6750
      43.0,      0.000,      0.000,         0,      6.8313,      0.6833
      43.2,      0.000,      0.000,         0,      6.9145,      0.6917
      43.4,      0.000,      0.000,         0,      6.9979,      0.7000
      43.6,      0.000,      0.000,         0,      7.0811,      0.7083
      43.8,      0.000,      0.000,         0,      7.1647,      0.7167
      44.0,      0.000,      0.000,         0,      7.2476,      0.7250
      44.3,      0.000,      0.000,         0,      7.3312,      0.7333
      44.5,      0.000,      0.000,         0,      7.4147,      0.7417
      44.7,      0.000,      0.000,         0,      7.4978,      0.7500
      44.9,      0.000,      0.000,         0,      7.5811,      0.7583
      45.1,      0.000,      0.000,         0,      7.6645,      0.7667
      45.3,      0.000,      0.000,         0,      7.7479,      0.7750
      45.5,      0.000,      0.000,         0,      7.8309,      0.7833
      45.7,      0.000,      0.000,         0,      7.9145,      0.7917
      45.9,      0.000,      0.000,         0,      7.9978,      0.8000
      46.1,      0.000,      0.000,         0,      8.0814,      0.8083
      46.3,      0.000,      0.000,         0,      8.1643,      0.8167
      46.6,      0.000,      0.000,         0,      8.2478,      0.8250
      46.8,      0.000,      0.000,         0,      8.3312,      0.8333
      47.0,      0.000,      0.000,         0,      8.4145,      0.8417
      47.2,      0.000,      0.000,         0,      8.4975,      0.8500
      47.4,      0.000,      0.000,         0,      8.5812,      0.8583
      47.6,      0.000,      0.000,         0,      8.6646,      0.8667
      47.8,      0.000,      0.000,         0,      8.7478,      0.8750
      48.1,      0.000,      0.000,         0,      8.8312,      0.8833
      48.3,      0.000,      0.000,         0,      8.9145,      0.8917
      48.5,      0.000,      0.000,         0,      8.9978,      0.9000
      48.7,      0.000,      0.000,         0,      9.0812,      0.9083
      48.9,      0.000,      0.000,         0,      9.1644,      0.9167
      49.1,      0.000,      0.000,         0,      9.2473,      0.9250
      49.3,      0.000,      0.000,         0,      9.3312,      0.9333
      49.5,      0.000,      0.000,         0,      9.4143,      0.9417
      49.7,      0.000,      0.000,         0,      9.4978,      0.9500
      49.8,      0.000,      0.000,         0,      9.5812,      0.9583
      50.0,      0.000,      0.000,         0,      9.6643,      0.9667
      50.2,      0.000,      0.000,         0,      9.7478,      0.9750
      50.4,      0.000,      0.000,         0,      9.8309,      0.9833
      50.6,      0.000,      0.000,         0,      9.9144,      0.9917
      50.8,      0.000,      0.000,         0,      9.9976,      1.0000
      50.9,      0.000,      0.000,         0,     10.0812,      1.0083
      51.0,      0.000,      0.000,         0,     10.1644,      1.0167
      51.2,      0.000,      0.000,         0,     10.2478,      1.0250
      51.3,      0.000,      0.000,         0,     10.3309,      1.0333
      51.5,      0.000,      0.000,         0,     10.4145,      1.0417
      51.6,      0.000,      0.000,         0,     10.4976,      1.0500
      51.8,      0.000,      0.000,         0,     10.5810,      1.0583
      51.9,      0.000,      0.000,         0,     10.6643,      1.0667
      52.1,      0.000,      0.000,         0,     10.7477,      1.0750
      52.2,      0.000,      0.000,         0,     10.8310,      1.0833
      52.3,      0.000,      0.000,         0,     10.9144,      1.0917
      52.5,      0.000,      0.000,         0,     10.9978,      1.1000
      52.6,      0.000,      0.000,         0,     11.0809,      1.1083
      52.7,      0.000,      0.000,         0,     11.1644,      1.1167
      52.8,      0.000,      0.000,         0,     11.2477,      1.1250
      52.9,      0.000,      0.000,         0,     11.3311,      1.1333
      53.0,      0.000,      0.000,         0,     11.4142,      1.1417
      53.1,      0.000,      0.000,         0,     11.4977,      1.1500
      53.2,      0.000,      0.000,         0,     11.5811,      1.1583
      53.3,      0.000,      0.000,         0,     11.6643,      1.1667
      53.4,      0.000,      0.000,         0,     11.7476,      1.1750
      53.4,      0.000,      0.000,         0,     11.8311,      1.1833
      53.5,      0.000,      0.000,         0,     11.9143,      1.1917
      53.6,      0.000,      0.000,         0,     11.9977,      1.2000
      53.6,      0.000,      0.000,         0,     12.0808,      1.2083
      53.7,      0.000,      0.000,         0,     12.1643,      1.2167
      53.7,      0.000,      0.000,         0,     12.2477,      1.2250
      53.8,      0.000,      0.000,         0,     12.3311,      1.2333
      53.8,      0.000,      0.000,         0,     12.4144,      1.2417
      53.8,      0.000,      0.000,         0,     12.4973,      1.2500
      53.8,      0.000,      0.000,         0,     12.5810,      1.2583
      53.8,      0.000,      0.000,         0,     12.6644,      1.2667
      53.8,      0.000,      0.000,         0,     12.7477,      1.2750
      53.8,      0.000,      0.000,         0,     12.8308,      1.2833
      53.7,      0.000,      0.000,         0,     12.9142,      1.2917
      53.6,      0.000,      0.000,         0,     12.9976,      1.3000
      53.4,      0.000,      0.000,         0,     13.0810,      1.3083
      53.2,      0.000,      0.000,         0,     13.1640,      1.3167
      53.0,      0.000,      0.000,         0,     13.2475,      1.3250
      52.5,      0.000,      0.000,         0,     13.3309,      1.3333
      51.9,      0.000,      0.000,         0,     13.4143,      1.3417
      50.7,      0.000,      0.000,         0,     13.4976,      1.3500
      48.3,      0.000,      0.000,         0,     13.5809,      1.3583
       0.0,      0.000,      0.000,         0,     13.6644,      1.3667
       0.0,      0.000,      0.000,         0,     13.7476,      1.3750
       0.0,      0.000,      0.000,         0,     13.8309,      1.3833
       0.0,      0.000,      0.000,         0,     13.9142,      1.3917
       0.0,      0.000,      0.000,         0,     13.9976,      1.4000
       0.0,      0.000,      0.000,         0,     14.0809,      1.4083
       0.0,      0.000,      0.000,         0,     14.1642,      1.4167