File: Alban repo/Quiz 1/suction cup instron tests/july-2020-force-vs-viscosity_raw-data/D30E10-01-in6-1x10-3-onwhiteplatic-diaphragmpump-10mm-test3.raw
Operator: 1

Date,Time,Specimen#
07/22/20,13:40:38,1

---------------------------------------


Area (mm^2):,      1.00,Flat,     25.40,     25.40,     25.40
Gage Len (mm):,     25.40


LOAD (N),STRAIN 1 (mm),STRAIN 2 (mm),STRESS (MPa),POSITION (mm),TIME (min)
       3.2,      0.000,      0.000,         0,      0.0804,      0.0083
       4.4,      0.000,      0.000,         0,      0.1636,      0.0167
       5.6,      0.000,      0.000,         0,      0.2471,      0.0250
       6.7,      0.000,      0.000,         0,      0.3304,      0.0333
       7.8,      0.000,      0.000,         0,      0.4136,      0.0417
       8.8,      0.000,      0.000,         0,      0.4971,      0.0500
       9.8,      0.000,      0.000,         0,      0.5803,      0.0583
      10.8,      0.000,      0.000,         0,      0.6637,      0.0667
      11.7,      0.000,      0.000,         0,      0.7468,      0.0750
      12.7,      0.000,      0.000,         0,      0.8304,      0.0833
      13.6,      0.000,      0.000,         0,      0.9136,      0.0917
      14.5,      0.000,      0.000,         0,      0.9969,      0.1000
      15.4,      0.000,      0.000,         0,      1.0803,      0.1083
      16.2,      0.000,      0.000,         0,      1.1637,      0.1167
      17.1,      0.000,      0.000,         0,      1.2468,      0.1250
      17.9,      0.000,      0.000,         0,      1.3303,      0.1333
      18.7,      0.000,      0.000,         0,      1.4138,      0.1417
      19.4,      0.000,      0.000,         0,      1.4969,      0.1500
      20.1,      0.000,      0.000,         0,      1.5803,      0.1583
      20.7,      0.000,      0.000,         0,      1.6637,      0.1667
      21.1,      0.000,      0.000,         0,      1.7470,      0.1750
      21.1,      0.000,      0.000,         0,      1.8300,      0.1833
      21.0,      0.000,      0.000,         0,      1.9132,      0.1917
      21.5,      0.000,      0.000,         0,      1.9970,      0.2000
      22.1,      0.000,      0.000,         0,      2.0803,      0.2083
      22.6,      0.000,      0.000,         0,      2.1633,      0.2167
      23.1,      0.000,      0.000,         0,      2.2471,      0.2250
      23.6,      0.000,      0.000,         0,      2.3303,      0.2333
      24.1,      0.000,      0.000,         0,      2.4137,      0.2417
      24.6,      0.000,      0.000,         0,      2.4968,      0.2500
      25.0,      0.000,      0.000,         0,      2.5803,      0.2583
      25.5,      0.000,      0.000,         0,      2.6637,      0.2667
      26.0,      0.000,      0.000,         0,      2.7467,      0.2750
      26.4,      0.000,      0.000,         0,      2.8302,      0.2833
      26.8,      0.000,      0.000,         0,      2.9136,      0.2917
      27.3,      0.000,      0.000,         0,      2.9970,      0.3000
      27.7,      0.000,      0.000,         0,      3.0802,      0.3083
      28.1,      0.000,      0.000,         0,      3.1635,      0.3167
      28.5,      0.000,      0.000,         0,      3.2466,      0.3250
      28.9,      0.000,      0.000,         0,      3.3304,      0.3333
      29.3,      0.000,      0.000,         0,      3.4135,      0.3417
      29.7,      0.000,      0.000,         0,      3.4969,      0.3500
      30.0,      0.000,      0.000,         0,      3.5801,      0.3583
      30.4,      0.000,      0.000,         0,      3.6636,      0.3667
      30.8,      0.000,      0.000,         0,      3.7469,      0.3750
      31.1,      0.000,      0.000,         0,      3.8302,      0.3833
      31.5,      0.000,      0.000,         0,      3.9133,      0.3917
      31.8,      0.000,      0.000,         0,      3.9969,      0.4000
      32.2,      0.000,      0.000,         0,      4.0803,      0.4083
      32.5,      0.000,      0.000,         0,      4.1633,      0.4167
      32.9,      0.000,      0.000,         0,      4.2468,      0.4250
      33.2,      0.000,      0.000,         0,      4.3301,      0.4333
      33.5,      0.000,      0.000,         0,      4.4136,      0.4417
      33.8,      0.000,      0.000,         0,      4.4969,      0.4500
      34.1,      0.000,      0.000,         0,      4.5801,      0.4583
      34.4,      0.000,      0.000,         0,      4.6635,      0.4667
      34.8,      0.000,      0.000,         0,      4.7468,      0.4750
      35.1,      0.000,      0.000,         0,      4.8302,      0.4833
      35.4,      0.000,      0.000,         0,      4.9136,      0.4917
      35.7,      0.000,      0.000,         0,      4.9970,      0.5000
      36.0,      0.000,      0.000,         0,      5.0802,      0.5083
      36.3,      0.000,      0.000,         0,      5.1635,      0.5167
      36.5,      0.000,      0.000,         0,      5.2468,      0.5250
      36.8,      0.000,      0.000,         0,      5.3302,      0.5333
      37.1,      0.000,      0.000,         0,      5.4133,      0.5417
      37.4,      0.000,      0.000,         0,      5.4968,      0.5500
      37.6,      0.000,      0.000,         0,      5.5802,      0.5583
      37.9,      0.000,      0.000,         0,      5.6634,      0.5667
      38.2,      0.000,      0.000,         0,      5.7468,      0.5750
      38.4,      0.000,      0.000,         0,      5.8302,      0.5833
      38.7,      0.000,      0.000,         0,      5.9135,      0.5917
      38.9,      0.000,      0.000,         0,      5.9969,      0.6000
      39.2,      0.000,      0.000,         0,      6.0801,      0.6083
      39.4,      0.000,      0.000,         0,      6.1635,      0.6167
      39.7,      0.000,      0.000,         0,      6.2468,      0.6250
      39.9,      0.000,      0.000,         0,      6.3301,      0.6333
      40.2,      0.000,      0.000,         0,      6.4135,      0.6417
      40.4,      0.000,      0.000,         0,      6.4966,      0.6500
      40.6,      0.000,      0.000,         0,      6.5801,      0.6583
      40.9,      0.000,      0.000,         0,      6.6635,      0.6667
      41.1,      0.000,      0.000,         0,      6.7468,      0.6750
      41.4,      0.000,      0.000,         0,      6.8300,      0.6833
      41.6,      0.000,      0.000,         0,      6.9135,      0.6917
      41.8,      0.000,      0.000,         0,      6.9967,      0.7000
      42.1,      0.000,      0.000,         0,      7.0800,      0.7083
      42.3,      0.000,      0.000,         0,      7.1632,      0.7167
      42.5,      0.000,      0.000,         0,      7.2467,      0.7250
      42.7,      0.000,      0.000,         0,      7.3301,      0.7333
      43.0,      0.000,      0.000,         0,      7.4133,      0.7417
      43.2,      0.000,      0.000,         0,      7.4964,      0.7500
      43.4,      0.000,      0.000,         0,      7.5801,      0.7583
      43.6,      0.000,      0.000,         0,      7.6635,      0.7667
      43.8,      0.000,      0.000,         0,      7.7466,      0.7750
      44.1,      0.000,      0.000,         0,      7.8300,      0.7833
      44.3,      0.000,      0.000,         0,      7.9134,      0.7917
      44.5,      0.000,      0.000,         0,      7.9969,      0.8000
      44.7,      0.000,      0.000,         0,      8.0799,      0.8083
      44.9,      0.000,      0.000,         0,      8.1633,      0.8167
      45.2,      0.000,      0.000,         0,      8.2467,      0.8250
      45.4,      0.000,      0.000,         0,      8.3300,      0.8333
      45.6,      0.000,      0.000,         0,      8.4133,      0.8417
      45.8,      0.000,      0.000,         0,      8.4966,      0.8500
      46.0,      0.000,      0.000,         0,      8.5802,      0.8583
      46.3,      0.000,      0.000,         0,      8.6632,      0.8667
      46.5,      0.000,      0.000,         0,      8.7467,      0.8750
      46.6,      0.000,      0.000,         0,      8.8301,      0.8833
      46.8,      0.000,      0.000,         0,      8.9133,      0.8917
      47.0,      0.000,      0.000,         0,      8.9966,      0.9000
      47.2,      0.000,      0.000,         0,      9.0801,      0.9083
      47.4,      0.000,      0.000,         0,      9.1630,      0.9167
      47.6,      0.000,      0.000,         0,      9.2466,      0.9250
      47.8,      0.000,      0.000,         0,      9.3301,      0.9333
      48.0,      0.000,      0.000,         0,      9.4133,      0.9417
      48.2,      0.000,      0.000,         0,      9.4966,      0.9500
      48.4,      0.000,      0.000,         0,      9.5800,      0.9583
      48.6,      0.000,      0.000,         0,      9.6635,      0.9667
      48.8,      0.000,      0.000,         0,      9.7465,      0.9750
      49.0,      0.000,      0.000,         0,      9.8296,      0.9833
      49.3,      0.000,      0.000,         0,      9.9133,      0.9917
      49.5,      0.000,      0.000,         0,      9.9968,      1.0000
      49.7,      0.000,      0.000,         0,     10.0798,      1.0083
      49.9,      0.000,      0.000,         0,     10.1633,      1.0167
      50.1,      0.000,      0.000,         0,     10.2466,      1.0250
      50.4,      0.000,      0.000,         0,     10.3299,      1.0333
      50.6,      0.000,      0.000,         0,     10.4131,      1.0417
      50.9,      0.000,      0.000,         0,     10.4966,      1.0500
      51.1,      0.000,      0.000,         0,     10.5798,      1.0583
      51.3,      0.000,      0.000,         0,     10.6632,      1.0667
      51.6,      0.000,      0.000,         0,     10.7466,      1.0750
      51.8,      0.000,      0.000,         0,     10.8299,      1.0833
      52.0,      0.000,      0.000,         0,     10.9132,      1.0917
      52.3,      0.000,      0.000,         0,     10.9965,      1.1000
      52.5,      0.000,      0.000,         0,     11.0799,      1.1083
      52.7,      0.000,      0.000,         0,     11.1631,      1.1167
      52.9,      0.000,      0.000,         0,     11.2466,      1.1250
      53.1,      0.000,      0.000,         0,     11.3299,      1.1333
      53.2,      0.000,      0.000,         0,     11.4132,      1.1417
      53.4,      0.000,      0.000,         0,     11.4964,      1.1500
      53.5,      0.000,      0.000,         0,     11.5799,      1.1583
      53.7,      0.000,      0.000,         0,     11.6633,      1.1667
      53.8,      0.000,      0.000,         0,     11.7463,      1.1750
      54.0,      0.000,      0.000,         0,     11.8298,      1.1833
      54.1,      0.000,      0.000,         0,     11.9132,      1.1917
      54.2,      0.000,      0.000,         0,     11.9965,      1.2000
      54.3,      0.000,      0.000,         0,     12.0798,      1.2083
      54.3,      0.000,      0.000,         0,     12.1632,      1.2167
      54.4,      0.000,      0.000,         0,     12.2465,      1.2250
      54.5,      0.000,      0.000,         0,     12.3301,      1.2333
      54.5,      0.000,      0.000,         0,     12.4131,      1.2417
      54.5,      0.000,      0.000,         0,     12.4965,      1.2500
      54.5,      0.000,      0.000,         0,     12.5798,      1.2583
      54.5,      0.000,      0.000,         0,     12.6632,      1.2667
      54.5,      0.000,      0.000,         0,     12.7464,      1.2750
      54.4,      0.000,      0.000,         0,     12.8298,      1.2833
      54.4,      0.000,      0.000,         0,     12.9132,      1.2917
      54.3,      0.000,      0.000,         0,     12.9965,      1.3000
      54.2,      0.000,      0.000,         0,     13.0798,      1.3083
      54.0,      0.000,      0.000,         0,     13.1630,      1.3167
      53.8,      0.000,      0.000,         0,     13.2465,      1.3250
      53.5,      0.000,      0.000,         0,     13.3296,      1.3333
      53.1,      0.000,      0.000,         0,     13.4130,      1.3417
      52.6,      0.000,      0.000,         0,     13.4965,      1.3500
      51.8,      0.000,      0.000,         0,     13.5797,      1.3583
      50.6,      0.000,      0.000,         0,     13.6630,      1.3667
      48.4,      0.000,      0.000,         0,     13.7466,      1.3750
      41.4,      0.000,      0.000,         0,     13.8297,      1.3833
       0.0,      0.000,      0.000,         0,     13.9132,      1.3917
       0.0,      0.000,      0.000,         0,     13.9964,      1.4000
       0.0,      0.000,      0.000,         0,     14.0798,      1.4083
       0.0,      0.000,      0.000,         0,     14.1631,      1.4167
       0.0,      0.000,      0.000,         0,     14.2464,      1.4250