File: Alban repo/Quiz 1/suction cup instron tests/july-2020-force-vs-viscosity_raw-data/D30E10-01-inwater-onwhiteplatic-diaphragmpump-10mm-test4.raw
Operator: 1

Date,Time,Specimen#
07/22/20,14:08:48,1

---------------------------------------


Area (mm^2):,      1.00,Flat,     25.40,     25.40,     25.40
Gage Len (mm):,     25.40


LOAD (N),STRAIN 1 (mm),STRAIN 2 (mm),STRESS (MPa),POSITION (mm),TIME (min)
       3.1,      0.000,      0.000,         0,      0.0810,      0.0083
       4.3,      0.000,      0.000,         0,      0.1645,      0.0167
       5.3,      0.000,      0.000,         0,      0.2475,      0.0250
       6.4,      0.000,      0.000,         0,      0.3310,      0.0333
       7.4,      0.000,      0.000,         0,      0.4144,      0.0417
       8.3,      0.000,      0.000,         0,      0.4977,      0.0500
       9.2,      0.000,      0.000,         0,      0.5808,      0.0583
      10.1,      0.000,      0.000,         0,      0.6644,      0.0667
      11.0,      0.000,      0.000,         0,      0.7477,      0.0750
      11.8,      0.000,      0.000,         0,      0.8309,      0.0833
      12.7,      0.000,      0.000,         0,      0.9142,      0.0917
      13.4,      0.000,      0.000,         0,      0.9976,      0.1000
      14.2,      0.000,      0.000,         0,      1.0811,      0.1083
      14.9,      0.000,      0.000,         0,      1.1643,      0.1167
      15.4,      0.000,      0.000,         0,      1.2475,      0.1250
      15.8,      0.000,      0.000,         0,      1.3310,      0.1333
      15.5,      0.000,      0.000,         0,      1.4145,      0.1417
      15.8,      0.000,      0.000,         0,      1.4976,      0.1500
      16.2,      0.000,      0.000,         0,      1.5809,      0.1583
      16.7,      0.000,      0.000,         0,      1.6642,      0.1667
      17.1,      0.000,      0.000,         0,      1.7476,      0.1750
      17.6,      0.000,      0.000,         0,      1.8311,      0.1833
      18.0,      0.000,      0.000,         0,      1.9139,      0.1917
      18.4,      0.000,      0.000,         0,      1.9975,      0.2000
      18.9,      0.000,      0.000,         0,      2.0808,      0.2083
      19.3,      0.000,      0.000,         0,      2.1643,      0.2167
      19.6,      0.000,      0.000,         0,      2.2477,      0.2250
      20.0,      0.000,      0.000,         0,      2.3310,      0.2333
      20.4,      0.000,      0.000,         0,      2.4142,      0.2417
      20.8,      0.000,      0.000,         0,      2.4977,      0.2500
      21.1,      0.000,      0.000,         0,      2.5810,      0.2583
      21.5,      0.000,      0.000,         0,      2.6642,      0.2667
      21.8,      0.000,      0.000,         0,      2.7477,      0.2750
      22.2,      0.000,      0.000,         0,      2.8308,      0.2833
      22.5,      0.000,      0.000,         0,      2.9141,      0.2917
      22.9,      0.000,      0.000,         0,      2.9976,      0.3000
      23.2,      0.000,      0.000,         0,      3.0810,      0.3083
      23.5,      0.000,      0.000,         0,      3.1643,      0.3167
      23.8,      0.000,      0.000,         0,      3.2475,      0.3250
      24.1,      0.000,      0.000,         0,      3.3308,      0.3333
      24.5,      0.000,      0.000,         0,      3.4143,      0.3417
      24.8,      0.000,      0.000,         0,      3.4974,      0.3500
      25.1,      0.000,      0.000,         0,      3.5806,      0.3583
      25.4,      0.000,      0.000,         0,      3.6643,      0.3667
      25.7,      0.000,      0.000,         0,      3.7475,      0.3750
      26.0,      0.000,      0.000,         0,      3.8309,      0.3833
      26.3,      0.000,      0.000,         0,      3.9142,      0.3917
      26.6,      0.000,      0.000,         0,      3.9975,      0.4000
      26.9,      0.000,      0.000,         0,      4.0809,      0.4083
      27.2,      0.000,      0.000,         0,      4.1643,      0.4167
      27.5,      0.000,      0.000,         0,      4.2475,      0.4250
      27.7,      0.000,      0.000,         0,      4.3308,      0.4333
      28.0,      0.000,      0.000,         0,      4.4142,      0.4417
      28.3,      0.000,      0.000,         0,      4.4975,      0.4500
      28.6,      0.000,      0.000,         0,      4.5807,      0.4583
      28.8,      0.000,      0.000,         0,      4.6642,      0.4667
      29.1,      0.000,      0.000,         0,      4.7476,      0.4750
      29.4,      0.000,      0.000,         0,      4.8309,      0.4833
      29.6,      0.000,      0.000,         0,      4.9140,      0.4917
      29.9,      0.000,      0.000,         0,      4.9974,      0.5000
      30.2,      0.000,      0.000,         0,      5.0809,      0.5083
      30.4,      0.000,      0.000,         0,      5.1642,      0.5167
      30.7,      0.000,      0.000,         0,      5.2473,      0.5250
      31.0,      0.000,      0.000,         0,      5.3308,      0.5333
      31.2,      0.000,      0.000,         0,      5.4143,      0.5417
      31.5,      0.000,      0.000,         0,      5.4975,      0.5500
      31.7,      0.000,      0.000,         0,      5.5808,      0.5583
      32.0,      0.000,      0.000,         0,      5.6641,      0.5667
      32.2,      0.000,      0.000,         0,      5.7475,      0.5750
      32.5,      0.000,      0.000,         0,      5.8307,      0.5833
      32.7,      0.000,      0.000,         0,      5.9138,      0.5917
      32.9,      0.000,      0.000,         0,      5.9975,      0.6000
      33.2,      0.000,      0.000,         0,      6.0809,      0.6083
      33.4,      0.000,      0.000,         0,      6.1641,      0.6167
      33.6,      0.000,      0.000,         0,      6.2475,      0.6250
      33.9,      0.000,      0.000,         0,      6.3309,      0.6333
      34.1,      0.000,      0.000,         0,      6.4140,      0.6417
      34.3,      0.000,      0.000,         0,      6.4974,      0.6500
      34.5,      0.000,      0.000,         0,      6.5807,      0.6583
      34.7,      0.000,      0.000,         0,      6.6642,      0.6667
      35.0,      0.000,      0.000,         0,      6.7473,      0.6750
      35.2,      0.000,      0.000,         0,      6.8307,      0.6833
      35.4,      0.000,      0.000,         0,      6.9141,      0.6917
      35.6,      0.000,      0.000,         0,      6.9974,      0.7000
      35.8,      0.000,      0.000,         0,      7.0808,      0.7083
      36.0,      0.000,      0.000,         0,      7.1641,      0.7167
      36.2,      0.000,      0.000,         0,      7.2471,      0.7250
      36.4,      0.000,      0.000,         0,      7.3307,      0.7333
      36.7,      0.000,      0.000,         0,      7.4142,      0.7417
      36.9,      0.000,      0.000,         0,      7.4974,      0.7500
      37.1,      0.000,      0.000,         0,      7.5803,      0.7583
      37.3,      0.000,      0.000,         0,      7.6640,      0.7667
      37.5,      0.000,      0.000,         0,      7.7474,      0.7750
      37.7,      0.000,      0.000,         0,      7.8305,      0.7833
      37.9,      0.000,      0.000,         0,      7.9141,      0.7917
      38.1,      0.000,      0.000,         0,      7.9973,      0.8000
      38.3,      0.000,      0.000,         0,      8.0807,      0.8083
      38.5,      0.000,      0.000,         0,      8.1639,      0.8167
      38.6,      0.000,      0.000,         0,      8.2474,      0.8250
      38.8,      0.000,      0.000,         0,      8.3307,      0.8333
      39.0,      0.000,      0.000,         0,      8.4140,      0.8417
      39.2,      0.000,      0.000,         0,      8.4970,      0.8500
      39.4,      0.000,      0.000,         0,      8.5808,      0.8583
      39.6,      0.000,      0.000,         0,      8.6641,      0.8667
      39.8,      0.000,      0.000,         0,      8.7473,      0.8750
      40.0,      0.000,      0.000,         0,      8.8307,      0.8833
      40.2,      0.000,      0.000,         0,      8.9140,      0.8917
      40.3,      0.000,      0.000,         0,      8.9974,      0.9000
      40.5,      0.000,      0.000,         0,      9.0808,      0.9083
      40.7,      0.000,      0.000,         0,      9.1640,      0.9167
      40.9,      0.000,      0.000,         0,      9.2469,      0.9250
      41.1,      0.000,      0.000,         0,      9.3308,      0.9333
      41.2,      0.000,      0.000,         0,      9.4139,      0.9417
      41.4,      0.000,      0.000,         0,      9.4973,      0.9500
      41.6,      0.000,      0.000,         0,      9.5806,      0.9583
      41.8,      0.000,      0.000,         0,      9.6640,      0.9667
      42.0,      0.000,      0.000,         0,      9.7473,      0.9750
      42.2,      0.000,      0.000,         0,      9.8306,      0.9833
      42.3,      0.000,      0.000,         0,      9.9138,      0.9917
      42.5,      0.000,      0.000,         0,      9.9973,      1.0000
      42.7,      0.000,      0.000,         0,     10.0807,      1.0083
      42.8,      0.000,      0.000,         0,     10.1640,      1.0167
      43.0,      0.000,      0.000,         0,     10.2472,      1.0250
      43.2,      0.000,      0.000,         0,     10.3306,      1.0333
      43.3,      0.000,      0.000,         0,     10.4140,      1.0417
      43.5,      0.000,      0.000,         0,     10.4972,      1.0500
      43.6,      0.000,      0.000,         0,     10.5805,      1.0583
      43.8,      0.000,      0.000,         0,     10.6639,      1.0667
      43.9,      0.000,      0.000,         0,     10.7472,      1.0750
      44.1,      0.000,      0.000,         0,     10.8305,      1.0833
      44.2,      0.000,      0.000,         0,     10.9139,      1.0917
      44.3,      0.000,      0.000,         0,     10.9973,      1.1000
      44.5,      0.000,      0.000,         0,     11.0805,      1.1083
      44.6,      0.000,      0.000,         0,     11.1639,      1.1167
      44.7,      0.000,      0.000,         0,     11.2472,      1.1250
      44.9,      0.000,      0.000,         0,     11.3306,      1.1333
      45.0,      0.000,      0.000,         0,     11.4138,      1.1417
      45.1,      0.000,      0.000,         0,     11.4973,      1.1500
      45.3,      0.000,      0.000,         0,     11.5806,      1.1583
      45.4,      0.000,      0.000,         0,     11.6639,      1.1667
      45.5,      0.000,      0.000,         0,     11.7472,      1.1750
      45.6,      0.000,      0.000,         0,     11.8302,      1.1833
      45.7,      0.000,      0.000,         0,     11.9138,      1.1917
      45.7,      0.000,      0.000,         0,     11.9972,      1.2000
      45.8,      0.000,      0.000,         0,     12.0804,      1.2083
      45.9,      0.000,      0.000,         0,     12.1638,      1.2167
      45.9,      0.000,      0.000,         0,     12.2472,      1.2250
      45.9,      0.000,      0.000,         0,     12.3305,      1.2333
      45.9,      0.000,      0.000,         0,     12.4140,      1.2417
      45.9,      0.000,      0.000,         0,     12.4970,      1.2500
      45.9,      0.000,      0.000,         0,     12.5805,      1.2583
      45.9,      0.000,      0.000,         0,     12.6637,      1.2667
      45.9,      0.000,      0.000,         0,     12.7472,      1.2750
      45.8,      0.000,      0.000,         0,     12.8303,      1.2833
      45.7,      0.000,      0.000,         0,     12.9137,      1.2917
      45.5,      0.000,      0.000,         0,     12.9972,      1.3000
      45.3,      0.000,      0.000,         0,     13.0804,      1.3083
      45.1,      0.000,      0.000,         0,     13.1635,      1.3167
      44.8,      0.000,      0.000,         0,     13.2472,      1.3250
      44.5,      0.000,      0.000,         0,     13.3305,      1.3333
      44.1,      0.000,      0.000,         0,     13.4138,      1.3417
      43.5,      0.000,      0.000,         0,     13.4971,      1.3500
      42.7,      0.000,      0.000,         0,     13.5805,      1.3583
      41.2,      0.000,      0.000,         0,     13.6639,      1.3667
       0.0,      0.000,      0.000,         0,     13.7469,      1.3750
       0.0,      0.000,      0.000,         0,     13.8305,      1.3833
       0.0,      0.000,      0.000,         0,     13.9136,      1.3917
       0.0,      0.000,      0.000,         0,     13.9972,      1.4000