File: Alban repo/Quiz 1/suction cup instron tests/july-2020-force-vs-viscosity_raw-data/D30E10-01-inair-si-oil-onwhiteplatic-diaphragmpump-10mm-test1.raw
Operator: 1

Date,Time,Specimen#
07/22/20,16:14:14,1

---------------------------------------


Area (mm^2):,      1.00,Flat,     25.40,     25.40,     25.40
Gage Len (mm):,     25.40


LOAD (N),STRAIN 1 (mm),STRAIN 2 (mm),STRESS (MPa),POSITION (mm),TIME (min)
       2.1,      0.000,      0.000,         0,     -0.1609,      0.0083
       1.7,      0.000,      0.000,         0,     -0.3200,      0.0167
       0.1,      0.000,      0.000,         0,     -0.4832,      0.0250
       0.5,      0.000,      0.000,         0,     -0.6497,      0.0333
       0.0,      0.000,      0.000,         0,     -0.8165,      0.0417
       2.6,      0.000,      0.000,         0,     -0.9829,      0.0500
       3.7,      0.000,      0.000,         0,     -1.1498,      0.0583
       2.5,      0.000,      0.000,         0,     -1.3164,      0.0667
       2.1,      0.000,      0.000,         0,     -1.4830,      0.0750
       2.2,      0.000,      0.000,         0,     -1.6497,      0.0833
       3.3,      0.000,      0.000,         0,     -1.8164,      0.0917
       3.8,      0.000,      0.000,         0,     -1.9829,      0.1000
       2.3,      0.000,      0.000,         0,     -2.1497,      0.1083
       1.9,      0.000,      0.000,         0,     -2.3164,      0.1167
       2.2,      0.000,      0.000,         0,     -2.4832,      0.1250
       2.4,      0.000,      0.000,         0,     -2.6496,      0.1333
       3.2,      0.000,      0.000,         0,     -2.8164,      0.1417
       4.2,      0.000,      0.000,         0,     -2.9831,      0.1500
       4.6,      0.000,      0.000,         0,     -3.1496,      0.1583
       4.5,      0.000,      0.000,         0,     -3.3163,      0.1667
       4.0,      0.000,      0.000,         0,     -3.4829,      0.1750
       4.0,      0.000,      0.000,         0,     -3.6495,      0.1833
       4.7,      0.000,      0.000,         0,     -3.8163,      0.1917
       2.5,      0.000,      0.000,         0,     -3.9829,      0.2000
       4.2,      0.000,      0.000,         0,     -4.1497,      0.2083
       3.7,      0.000,      0.000,         0,     -4.3163,      0.2167
       5.0,      0.000,      0.000,         0,     -4.4829,      0.2250
       5.2,      0.000,      0.000,         0,     -4.6497,      0.2333
       2.8,      0.000,      0.000,         0,     -4.8163,      0.2417
       1.7,      0.000,      0.000,         0,     -4.9829,      0.2500
       2.4,      0.000,      0.000,         0,     -5.1496,      0.2583
      -2.6,      0.000,      0.000,         0,     -5.3162,      0.2667
      -2.8,      0.000,      0.000,         0,     -5.4829,      0.2750
      -0.3,      0.000,      0.000,         0,     -5.6494,      0.2833
       0.2,      0.000,      0.000,         0,     -5.8163,      0.2917
       3.5,      0.000,      0.000,         0,     -5.9829,      0.3000
       2.6,      0.000,      0.000,         0,     -6.1494,      0.3083
       5.6,      0.000,      0.000,         0,     -6.3162,      0.3167
       4.8,      0.000,      0.000,         0,     -6.4828,      0.3250
       2.4,      0.000,      0.000,         0,     -6.6496,      0.3333
       0.9,      0.000,      0.000,         0,     -6.8162,      0.3417
       0.5,      0.000,      0.000,         0,     -6.9828,      0.3500
      -9.2,      0.000,      0.000,         0,     -7.1496,      0.3583
      -9.1,      0.000,      0.000,         0,     -7.3161,      0.3667
      -8.1,      0.000,      0.000,         0,     -7.4827,      0.3750
      -8.0,      0.000,      0.000,         0,     -7.6494,      0.3833
      -7.1,      0.000,      0.000,         0,     -7.8161,      0.3917
      -7.9,      0.000,      0.000,         0,     -7.9828,      0.4000
     -10.3,      0.000,      0.000,         0,     -8.1495,      0.4083
      -9.6,      0.000,      0.000,         0,     -8.5355,      0.4329
      -5.5,      0.000,      0.000,         0,     -8.6215,      0.4496
      -5.4,      0.000,      0.000,         0,     -8.6555,      0.4662
      -5.3,      0.000,      0.000,         0,     -8.6680,      0.4829
       8.7,      0.000,      0.000,         0,     -8.6680,      0.4996
       8.8,      0.000,      0.000,         0,     -8.6680,      0.5162
       8.8,      0.000,      0.000,         0,     -8.6679,      0.5329
       8.9,      0.000,      0.000,         0,     -8.6678,      0.5496
       8.9,      0.000,      0.000,         0,     -8.6677,      0.5662
       9.0,      0.000,      0.000,         0,     -8.6154,      0.5829
       9.5,      0.000,      0.000,         0,     -8.4584,      0.5996
       9.6,      0.000,      0.000,         0,     -8.3800,      0.6162
       9.6,      0.000,      0.000,         0,     -8.3461,      0.6329
       9.6,      0.000,      0.000,         0,     -8.3278,      0.6496
       9.6,      0.000,      0.000,         0,     -8.3264,      0.6662
       9.6,      0.000,      0.000,         0,     -8.3128,      0.6746
       9.7,      0.000,      0.000,         0,     -8.2723,      0.6829
       9.9,      0.000,      0.000,         0,     -8.2149,      0.6912
      10.1,      0.000,      0.000,         0,     -8.1496,      0.6996
      10.2,      0.000,      0.000,         0,     -8.0749,      0.7079
      10.4,      0.000,      0.000,         0,     -8.0015,      0.7162
      10.5,      0.000,      0.000,         0,     -7.9216,      0.7246
      10.7,      0.000,      0.000,         0,     -7.8383,      0.7329
      10.8,      0.000,      0.000,         0,     -7.7552,      0.7412
      10.9,      0.000,      0.000,         0,     -7.6716,      0.7496
      11.1,      0.000,      0.000,         0,     -7.5883,      0.7579
      11.2,      0.000,      0.000,         0,     -7.5051,      0.7662
      11.3,      0.000,      0.000,         0,     -7.4216,      0.7746
      11.4,      0.000,      0.000,         0,     -7.3383,      0.7829
      11.5,      0.000,      0.000,         0,     -7.2550,      0.7912
      11.5,      0.000,      0.000,         0,     -7.1719,      0.7996
      11.6,      0.000,      0.000,         0,     -7.0884,      0.8079
      11.7,      0.000,      0.000,         0,     -7.0052,      0.8162
      11.8,      0.000,      0.000,         0,     -6.9217,      0.8246
      11.8,      0.000,      0.000,         0,     -6.8384,      0.8329
      11.9,      0.000,      0.000,         0,     -6.7550,      0.8412
      11.9,      0.000,      0.000,         0,     -6.6718,      0.8496
      12.0,      0.000,      0.000,         0,     -6.5884,      0.8579
      12.0,      0.000,      0.000,         0,     -6.5053,      0.8662
      12.1,      0.000,      0.000,         0,     -6.4217,      0.8746
      12.1,      0.000,      0.000,         0,     -6.3385,      0.8829
      12.2,      0.000,      0.000,         0,     -6.2550,      0.8912
      12.2,      0.000,      0.000,         0,     -6.1716,      0.8996
      12.2,      0.000,      0.000,         0,     -6.0887,      0.9079
      12.3,      0.000,      0.000,         0,     -6.0050,      0.9162
      12.3,      0.000,      0.000,         0,     -5.9216,      0.9246
      12.3,      0.000,      0.000,         0,     -5.8385,      0.9329
      12.3,      0.000,      0.000,         0,     -5.7554,      0.9412
      12.3,      0.000,      0.000,         0,     -5.6717,      0.9496
      12.3,      0.000,      0.000,         0,     -5.5885,      0.9579
      12.3,      0.000,      0.000,         0,     -5.5053,      0.9662
      12.3,      0.000,      0.000,         0,     -5.4219,      0.9746
      12.3,      0.000,      0.000,         0,     -5.3384,      0.9829
      12.3,      0.000,      0.000,         0,     -5.2550,      0.9912
      12.3,      0.000,      0.000,         0,     -5.1718,      0.9996
      12.2,      0.000,      0.000,         0,     -5.0885,      1.0079
      12.2,      0.000,      0.000,         0,     -5.0052,      1.0162
      12.2,      0.000,      0.000,         0,     -4.9218,      1.0246
      12.2,      0.000,      0.000,         0,     -4.8384,      1.0329
      12.1,      0.000,      0.000,         0,     -4.7551,      1.0412
      12.1,      0.000,      0.000,         0,     -4.6718,      1.0496
      12.1,      0.000,      0.000,         0,     -4.5884,      1.0579
      12.1,      0.000,      0.000,         0,     -4.5051,      1.0662
      12.1,      0.000,      0.000,         0,     -4.4221,      1.0746
      12.0,      0.000,      0.000,         0,     -4.3386,      1.0829
      12.0,      0.000,      0.000,         0,     -4.2552,      1.0912
      12.0,      0.000,      0.000,         0,     -4.1718,      1.0996
      12.0,      0.000,      0.000,         0,     -4.0887,      1.1079
      12.0,      0.000,      0.000,         0,     -4.0051,      1.1162
      12.0,      0.000,      0.000,         0,     -3.9218,      1.1246
      12.0,      0.000,      0.000,         0,     -3.8385,      1.1329
      12.0,      0.000,      0.000,         0,     -3.7552,      1.1412
      12.0,      0.000,      0.000,         0,     -3.6718,      1.1496
      12.0,      0.000,      0.000,         0,     -3.5886,      1.1579
      12.1,      0.000,      0.000,         0,     -3.5052,      1.1662
      12.1,      0.000,      0.000,         0,     -3.4219,      1.1746
      12.2,      0.000,      0.000,         0,     -3.3385,      1.1829
      12.3,      0.000,      0.000,         0,     -3.2552,      1.1912
      12.3,      0.000,      0.000,         0,     -3.1718,      1.1996
      12.4,      0.000,      0.000,         0,     -3.0886,      1.2079
      12.5,      0.000,      0.000,         0,     -3.0052,      1.2162
      12.6,      0.000,      0.000,         0,     -2.9218,      1.2246
      12.7,      0.000,      0.000,         0,     -2.8386,      1.2329
      12.8,      0.000,      0.000,         0,     -2.7558,      1.2412
      13.0,      0.000,      0.000,         0,     -2.6718,      1.2496
      13.1,      0.000,      0.000,         0,     -2.5885,      1.2579
      13.2,      0.000,      0.000,         0,     -2.5053,      1.2662
      13.4,      0.000,      0.000,         0,     -2.4218,      1.2746
      13.5,      0.000,      0.000,         0,     -2.3385,      1.2829
      13.7,      0.000,      0.000,         0,     -2.2552,      1.2912
      13.8,      0.000,      0.000,         0,     -2.1721,      1.2996
      14.0,      0.000,      0.000,         0,     -2.0886,      1.3079
      14.2,      0.000,      0.000,         0,     -2.0053,      1.3162
      14.4,      0.000,      0.000,         0,     -1.9220,      1.3246
      14.5,      0.000,      0.000,         0,     -1.8388,      1.3329
      14.7,      0.000,      0.000,         0,     -1.7553,      1.3412
      14.9,      0.000,      0.000,         0,     -1.6720,      1.3496
      15.1,      0.000,      0.000,         0,     -1.5886,      1.3579
      15.3,      0.000,      0.000,         0,     -1.5053,      1.3662
      15.5,      0.000,      0.000,         0,     -1.4222,      1.3746
      15.7,      0.000,      0.000,         0,     -1.3386,      1.3829
      15.9,      0.000,      0.000,         0,     -1.2552,      1.3912
      16.0,      0.000,      0.000,         0,     -1.1720,      1.3996
      16.2,      0.000,      0.000,         0,     -1.0888,      1.4079
      16.4,      0.000,      0.000,         0,     -1.0053,      1.4162
      16.6,      0.000,      0.000,         0,     -0.9221,      1.4246
      16.8,      0.000,      0.000,         0,     -0.8388,      1.4329
      16.9,      0.000,      0.000,         0,     -0.7555,      1.4412
       6.2,      0.000,      0.000,         0,     -0.6719,      1.4496
       0.0,      0.000,      0.000,         0,     -0.5887,      1.4579
       0.0,      0.000,      0.000,         0,     -0.5054,      1.4662
       0.0,      0.000,      0.000,         0,     -0.4219,      1.4746
       0.0,      0.000,      0.000,         0,     -0.3387,      1.4829
       0.0,      0.000,      0.000,         0,     -0.2553,      1.4912