File: Alban repo/Quiz 1/suction cup instron tests/july-2020-force-vs-viscosity_raw-data/D30E10-01-in1-1x10-2-onwhiteplatic-diaphragmpump-10mm-test4.raw
Operator: 1

Date,Time,Specimen#
07/22/20,13:07:06,1

---------------------------------------


Area (mm^2):,      1.00,Flat,     25.40,     25.40,     25.40
Gage Len (mm):,     25.40


LOAD (N),STRAIN 1 (mm),STRAIN 2 (mm),STRESS (MPa),POSITION (mm),TIME (min)
       3.2,      0.000,      0.000,         0,      0.0813,      0.0083
       4.5,      0.000,      0.000,         0,      0.1648,      0.0167
       5.7,      0.000,      0.000,         0,      0.2478,      0.0250
       6.8,      0.000,      0.000,         0,      0.3314,      0.0333
       7.9,      0.000,      0.000,         0,      0.4148,      0.0417
       9.0,      0.000,      0.000,         0,      0.4980,      0.0500
      10.0,      0.000,      0.000,         0,      0.5813,      0.0583
      11.0,      0.000,      0.000,         0,      0.6645,      0.0667
      12.0,      0.000,      0.000,         0,      0.7481,      0.0750
      13.0,      0.000,      0.000,         0,      0.8313,      0.0833
      14.0,      0.000,      0.000,         0,      0.9146,      0.0917
      14.9,      0.000,      0.000,         0,      0.9979,      0.1000
      15.8,      0.000,      0.000,         0,      1.0813,      0.1083
      16.7,      0.000,      0.000,         0,      1.1646,      0.1167
      17.6,      0.000,      0.000,         0,      1.2479,      0.1250
      18.4,      0.000,      0.000,         0,      1.3314,      0.1333
      19.3,      0.000,      0.000,         0,      1.4146,      0.1417
      20.1,      0.000,      0.000,         0,      1.4981,      0.1500
      20.8,      0.000,      0.000,         0,      1.5813,      0.1583
      21.5,      0.000,      0.000,         0,      1.6646,      0.1667
      22.1,      0.000,      0.000,         0,      1.7480,      0.1750
      22.7,      0.000,      0.000,         0,      1.8315,      0.1833
      23.2,      0.000,      0.000,         0,      1.9142,      0.1917
      23.3,      0.000,      0.000,         0,      1.9978,      0.2000
      23.2,      0.000,      0.000,         0,      2.0815,      0.2083
      23.7,      0.000,      0.000,         0,      2.1646,      0.2167
      24.2,      0.000,      0.000,         0,      2.2478,      0.2250
      24.7,      0.000,      0.000,         0,      2.3314,      0.2333
      25.2,      0.000,      0.000,         0,      2.4147,      0.2417
      25.7,      0.000,      0.000,         0,      2.4979,      0.2500
      26.2,      0.000,      0.000,         0,      2.5813,      0.2583
      26.7,      0.000,      0.000,         0,      2.6647,      0.2667
      27.2,      0.000,      0.000,         0,      2.7480,      0.2750
      27.6,      0.000,      0.000,         0,      2.8310,      0.2833
      28.1,      0.000,      0.000,         0,      2.9145,      0.2917
      28.5,      0.000,      0.000,         0,      2.9979,      0.3000
      29.0,      0.000,      0.000,         0,      3.0812,      0.3083
      29.4,      0.000,      0.000,         0,      3.1646,      0.3167
      29.8,      0.000,      0.000,         0,      3.2480,      0.3250
      30.2,      0.000,      0.000,         0,      3.3312,      0.3333
      30.6,      0.000,      0.000,         0,      3.4146,      0.3417
      31.0,      0.000,      0.000,         0,      3.4979,      0.3500
      31.4,      0.000,      0.000,         0,      3.5812,      0.3583
      31.8,      0.000,      0.000,         0,      3.6646,      0.3667
      32.2,      0.000,      0.000,         0,      3.7479,      0.3750
      32.5,      0.000,      0.000,         0,      3.8313,      0.3833
      32.9,      0.000,      0.000,         0,      3.9143,      0.3917
      33.2,      0.000,      0.000,         0,      3.9979,      0.4000
      33.6,      0.000,      0.000,         0,      4.0812,      0.4083
      33.9,      0.000,      0.000,         0,      4.1646,      0.4167
      34.3,      0.000,      0.000,         0,      4.2477,      0.4250
      34.6,      0.000,      0.000,         0,      4.3313,      0.4333
      34.9,      0.000,      0.000,         0,      4.4146,      0.4417
      35.3,      0.000,      0.000,         0,      4.4980,      0.4500
      35.6,      0.000,      0.000,         0,      4.5811,      0.4583
      35.9,      0.000,      0.000,         0,      4.6645,      0.4667
      36.2,      0.000,      0.000,         0,      4.7479,      0.4750
      36.5,      0.000,      0.000,         0,      4.8313,      0.4833
      36.8,      0.000,      0.000,         0,      4.9145,      0.4917
      37.1,      0.000,      0.000,         0,      4.9978,      0.5000
      37.4,      0.000,      0.000,         0,      5.0813,      0.5083
      37.7,      0.000,      0.000,         0,      5.1644,      0.5167
      38.0,      0.000,      0.000,         0,      5.2478,      0.5250
      38.2,      0.000,      0.000,         0,      5.3312,      0.5333
      38.5,      0.000,      0.000,         0,      5.4146,      0.5417
      38.8,      0.000,      0.000,         0,      5.4976,      0.5500
      39.0,      0.000,      0.000,         0,      5.5811,      0.5583
      39.3,      0.000,      0.000,         0,      5.6644,      0.5667
      39.6,      0.000,      0.000,         0,      5.7478,      0.5750
      39.8,      0.000,      0.000,         0,      5.8311,      0.5833
      40.1,      0.000,      0.000,         0,      5.9141,      0.5917
      40.3,      0.000,      0.000,         0,      5.9979,      0.6000
      40.6,      0.000,      0.000,         0,      6.0810,      0.6083
      40.8,      0.000,      0.000,         0,      6.1644,      0.6167
      41.0,      0.000,      0.000,         0,      6.2478,      0.6250
      41.3,      0.000,      0.000,         0,      6.3311,      0.6333
      41.5,      0.000,      0.000,         0,      6.4144,      0.6417
      41.8,      0.000,      0.000,         0,      6.4978,      0.6500
      42.0,      0.000,      0.000,         0,      6.5809,      0.6583
      42.2,      0.000,      0.000,         0,      6.6644,      0.6667
      42.5,      0.000,      0.000,         0,      6.7478,      0.6750
      42.7,      0.000,      0.000,         0,      6.8310,      0.6833
      42.9,      0.000,      0.000,         0,      6.9144,      0.6917
      43.2,      0.000,      0.000,         0,      6.9977,      0.7000
      43.4,      0.000,      0.000,         0,      7.0813,      0.7083
      43.6,      0.000,      0.000,         0,      7.1643,      0.7167
      43.8,      0.000,      0.000,         0,      7.2478,      0.7250
      44.1,      0.000,      0.000,         0,      7.3311,      0.7333
      44.3,      0.000,      0.000,         0,      7.4145,      0.7417
      44.5,      0.000,      0.000,         0,      7.4974,      0.7500
      44.7,      0.000,      0.000,         0,      7.5810,      0.7583
      44.9,      0.000,      0.000,         0,      7.6644,      0.7667
      45.1,      0.000,      0.000,         0,      7.7478,      0.7750
      45.3,      0.000,      0.000,         0,      7.8307,      0.7833
      45.6,      0.000,      0.000,         0,      7.9144,      0.7917
      45.8,      0.000,      0.000,         0,      7.9977,      0.8000
      46.0,      0.000,      0.000,         0,      8.0811,      0.8083
      46.2,      0.000,      0.000,         0,      8.1643,      0.8167
      46.4,      0.000,      0.000,         0,      8.2476,      0.8250
      46.6,      0.000,      0.000,         0,      8.3310,      0.8333
      46.8,      0.000,      0.000,         0,      8.4144,      0.8417
      47.0,      0.000,      0.000,         0,      8.4976,      0.8500
      47.3,      0.000,      0.000,         0,      8.5809,      0.8583
      47.5,      0.000,      0.000,         0,      8.6644,      0.8667
      47.7,      0.000,      0.000,         0,      8.7476,      0.8750
      47.9,      0.000,      0.000,         0,      8.8310,      0.8833
      48.1,      0.000,      0.000,         0,      8.9142,      0.8917
      48.3,      0.000,      0.000,         0,      8.9976,      0.9000
      48.5,      0.000,      0.000,         0,      9.0810,      0.9083
      48.7,      0.000,      0.000,         0,      9.1643,      0.9167
      48.9,      0.000,      0.000,         0,      9.2471,      0.9250
      49.1,      0.000,      0.000,         0,      9.3309,      0.9333
      49.3,      0.000,      0.000,         0,      9.4144,      0.9417
      49.6,      0.000,      0.000,         0,      9.4976,      0.9500
      49.8,      0.000,      0.000,         0,      9.5811,      0.9583
      50.0,      0.000,      0.000,         0,      9.6643,      0.9667
      50.2,      0.000,      0.000,         0,      9.7478,      0.9750
      50.5,      0.000,      0.000,         0,      9.8309,      0.9833
      50.7,      0.000,      0.000,         0,      9.9143,      0.9917
      51.0,      0.000,      0.000,         0,      9.9976,      1.0000
      51.2,      0.000,      0.000,         0,     10.0810,      1.0083
      51.4,      0.000,      0.000,         0,     10.1642,      1.0167
      51.7,      0.000,      0.000,         0,     10.2476,      1.0250
      51.9,      0.000,      0.000,         0,     10.3311,      1.0333
      52.1,      0.000,      0.000,         0,     10.4142,      1.0417
      52.4,      0.000,      0.000,         0,     10.4975,      1.0500
      52.6,      0.000,      0.000,         0,     10.5809,      1.0583
      52.8,      0.000,      0.000,         0,     10.6643,      1.0667
      53.0,      0.000,      0.000,         0,     10.7474,      1.0750
      53.2,      0.000,      0.000,         0,     10.8310,      1.0833
      53.4,      0.000,      0.000,         0,     10.9142,      1.0917
      53.6,      0.000,      0.000,         0,     10.9975,      1.1000
      53.7,      0.000,      0.000,         0,     11.0809,      1.1083
      53.9,      0.000,      0.000,         0,     11.1643,      1.1167
      54.1,      0.000,      0.000,         0,     11.2474,      1.1250
      54.2,      0.000,      0.000,         0,     11.3309,      1.1333
      54.4,      0.000,      0.000,         0,     11.4142,      1.1417
      54.5,      0.000,      0.000,         0,     11.4974,      1.1500
      54.6,      0.000,      0.000,         0,     11.5808,      1.1583
      54.7,      0.000,      0.000,         0,     11.6642,      1.1667
      54.8,      0.000,      0.000,         0,     11.7475,      1.1750
      54.9,      0.000,      0.000,         0,     11.8306,      1.1833
      55.0,      0.000,      0.000,         0,     11.9143,      1.1917
      55.1,      0.000,      0.000,         0,     11.9976,      1.2000
      55.2,      0.000,      0.000,         0,     12.0809,      1.2083
      55.2,      0.000,      0.000,         0,     12.1640,      1.2167
      55.3,      0.000,      0.000,         0,     12.2475,      1.2250
      55.3,      0.000,      0.000,         0,     12.3310,      1.2333
      55.4,      0.000,      0.000,         0,     12.4142,      1.2417
      55.4,      0.000,      0.000,         0,     12.4973,      1.2500
      55.4,      0.000,      0.000,         0,     12.5808,      1.2583
      55.4,      0.000,      0.000,         0,     12.6643,      1.2667
      55.4,      0.000,      0.000,         0,     12.7476,      1.2750
      55.4,      0.000,      0.000,         0,     12.8308,      1.2833
      55.3,      0.000,      0.000,         0,     12.9141,      1.2917
      55.3,      0.000,      0.000,         0,     12.9976,      1.3000
      55.2,      0.000,      0.000,         0,     13.0808,      1.3083
      55.1,      0.000,      0.000,         0,     13.1637,      1.3167
      54.9,      0.000,      0.000,         0,     13.2474,      1.3250
      54.7,      0.000,      0.000,         0,     13.3308,      1.3333
      54.4,      0.000,      0.000,         0,     13.4140,      1.3417
      54.0,      0.000,      0.000,         0,     13.4974,      1.3500
      53.5,      0.000,      0.000,         0,     13.5809,      1.3583
      52.6,      0.000,      0.000,         0,     13.6642,      1.3667
      51.0,      0.000,      0.000,         0,     13.7474,      1.3750
      47.5,      0.000,      0.000,         0,     13.8308,      1.3833
       0.1,      0.000,      0.000,         0,     13.9141,      1.3917
       0.0,      0.000,      0.000,         0,     13.9974,      1.4000
       0.0,      0.000,      0.000,         0,     14.0808,      1.4083
       0.0,      0.000,      0.000,         0,     14.1641,      1.4167