File: Alban repo/Quiz 1/suction cup instron tests/july-2020-force-vs-viscosity_raw-data/D30E10-01-inair-si-oil-onwhiteplatic-diaphragmpump-10mm-test4.raw
Operator: 1

Date,Time,Specimen#
07/22/20,16:44:24,1

---------------------------------------


Area (mm^2):,      1.00,Flat,     25.40,     25.40,     25.40
Gage Len (mm):,     25.40


LOAD (N),STRAIN 1 (mm),STRAIN 2 (mm),STRESS (MPa),POSITION (mm),TIME (min)
       2.6,      0.000,      0.000,         0,      0.0796,      0.0083
       3.3,      0.000,      0.000,         0,      0.1633,      0.0167
       3.9,      0.000,      0.000,         0,      0.2466,      0.0250
       4.5,      0.000,      0.000,         0,      0.3300,      0.0333
       5.1,      0.000,      0.000,         0,      0.4131,      0.0417
       5.7,      0.000,      0.000,         0,      0.4967,      0.0500
       6.3,      0.000,      0.000,         0,      0.5800,      0.0583
       6.9,      0.000,      0.000,         0,      0.6633,      0.0667
       7.4,      0.000,      0.000,         0,      0.7465,      0.0750
       8.0,      0.000,      0.000,         0,      0.8300,      0.0833
       7.9,      0.000,      0.000,         0,      0.9130,      0.0917
       7.2,      0.000,      0.000,         0,      0.9965,      0.1000
       6.6,      0.000,      0.000,         0,      1.0799,      0.1083
       6.2,      0.000,      0.000,         0,      1.1634,      0.1167
       6.3,      0.000,      0.000,         0,      1.2466,      0.1250
       6.4,      0.000,      0.000,         0,      1.3297,      0.1333
       6.7,      0.000,      0.000,         0,      1.4125,      0.1417
       6.8,      0.000,      0.000,         0,      1.4967,      0.1500
       7.1,      0.000,      0.000,         0,      1.5798,      0.1583
       7.3,      0.000,      0.000,         0,      1.6631,      0.1667
       7.5,      0.000,      0.000,         0,      1.7466,      0.1750
       7.7,      0.000,      0.000,         0,      1.8298,      0.1833
       7.8,      0.000,      0.000,         0,      1.9133,      0.1917
       8.0,      0.000,      0.000,         0,      1.9963,      0.2000
       8.2,      0.000,      0.000,         0,      2.0799,      0.2083
       8.4,      0.000,      0.000,         0,      2.1630,      0.2167
       8.6,      0.000,      0.000,         0,      2.2464,      0.2250
       8.7,      0.000,      0.000,         0,      2.3297,      0.2333
       8.9,      0.000,      0.000,         0,      2.4131,      0.2417
       9.0,      0.000,      0.000,         0,      2.4964,      0.2500
       9.2,      0.000,      0.000,         0,      2.5800,      0.2583
       9.3,      0.000,      0.000,         0,      2.6632,      0.2667
       9.5,      0.000,      0.000,         0,      2.7463,      0.2750
       9.6,      0.000,      0.000,         0,      2.8298,      0.2833
       9.7,      0.000,      0.000,         0,      2.9132,      0.2917
       9.9,      0.000,      0.000,         0,      2.9963,      0.3000
      10.0,      0.000,      0.000,         0,      3.0797,      0.3083
      10.1,      0.000,      0.000,         0,      3.1633,      0.3167
      10.2,      0.000,      0.000,         0,      3.2464,      0.3250
      10.4,      0.000,      0.000,         0,      3.3297,      0.3333
      10.5,      0.000,      0.000,         0,      3.4130,      0.3417
      10.6,      0.000,      0.000,         0,      3.4965,      0.3500
      10.7,      0.000,      0.000,         0,      3.5798,      0.3583
      10.8,      0.000,      0.000,         0,      3.6630,      0.3667
      10.9,      0.000,      0.000,         0,      3.7466,      0.3750
      11.0,      0.000,      0.000,         0,      3.8298,      0.3833
      11.0,      0.000,      0.000,         0,      3.9131,      0.3917
      11.2,      0.000,      0.000,         0,      3.9964,      0.4000
      11.2,      0.000,      0.000,         0,      4.0798,      0.4083
      11.3,      0.000,      0.000,         0,      4.1629,      0.4167
      11.3,      0.000,      0.000,         0,      4.2464,      0.4250
      11.4,      0.000,      0.000,         0,      4.3298,      0.4333
      11.5,      0.000,      0.000,         0,      4.4129,      0.4417
      11.6,      0.000,      0.000,         0,      4.4964,      0.4500
      11.6,      0.000,      0.000,         0,      4.5798,      0.4583
      11.7,      0.000,      0.000,         0,      4.6631,      0.4667
      11.7,      0.000,      0.000,         0,      4.7462,      0.4750
      11.8,      0.000,      0.000,         0,      4.8297,      0.4833
      11.8,      0.000,      0.000,         0,      4.9130,      0.4917
      11.9,      0.000,      0.000,         0,      4.9964,      0.5000
      11.9,      0.000,      0.000,         0,      5.0797,      0.5083
      11.9,      0.000,      0.000,         0,      5.1632,      0.5167
      11.9,      0.000,      0.000,         0,      5.2463,      0.5250
      11.9,      0.000,      0.000,         0,      5.3298,      0.5333
      12.0,      0.000,      0.000,         0,      5.4130,      0.5417
      12.0,      0.000,      0.000,         0,      5.4963,      0.5500
      12.0,      0.000,      0.000,         0,      5.5794,      0.5583
      12.1,      0.000,      0.000,         0,      5.6631,      0.5667
      12.1,      0.000,      0.000,         0,      5.7463,      0.5750
      12.1,      0.000,      0.000,         0,      5.8298,      0.5833
      12.0,      0.000,      0.000,         0,      5.9131,      0.5917
      12.1,      0.000,      0.000,         0,      5.9963,      0.6000
      12.0,      0.000,      0.000,         0,      6.0798,      0.6083
      12.0,      0.000,      0.000,         0,      6.1632,      0.6167
      12.0,      0.000,      0.000,         0,      6.2463,      0.6250
      12.0,      0.000,      0.000,         0,      6.3296,      0.6333
      11.9,      0.000,      0.000,         0,      6.4130,      0.6417
      11.9,      0.000,      0.000,         0,      6.4964,      0.6500
      11.9,      0.000,      0.000,         0,      6.5796,      0.6583
      11.8,      0.000,      0.000,         0,      6.6626,      0.6667
      11.8,      0.000,      0.000,         0,      6.7465,      0.6750
      11.8,      0.000,      0.000,         0,      6.8297,      0.6833
      11.8,      0.000,      0.000,         0,      6.9130,      0.6917
      11.7,      0.000,      0.000,         0,      6.9958,      0.7000
      11.7,      0.000,      0.000,         0,      7.0795,      0.7083
      11.7,      0.000,      0.000,         0,      7.1629,      0.7167
      11.7,      0.000,      0.000,         0,      7.2463,      0.7250
      11.7,      0.000,      0.000,         0,      7.3297,      0.7333
      11.7,      0.000,      0.000,         0,      7.4129,      0.7417
      11.7,      0.000,      0.000,         0,      7.4962,      0.7500
      11.7,      0.000,      0.000,         0,      7.5796,      0.7583
      11.7,      0.000,      0.000,         0,      7.6629,      0.7667
      11.7,      0.000,      0.000,         0,      7.7462,      0.7750
      11.7,      0.000,      0.000,         0,      7.8297,      0.7833
      11.8,      0.000,      0.000,         0,      7.9128,      0.7917
      11.8,      0.000,      0.000,         0,      7.9961,      0.8000
      11.9,      0.000,      0.000,         0,      8.0796,      0.8083
      12.0,      0.000,      0.000,         0,      8.1630,      0.8167
      12.0,      0.000,      0.000,         0,      8.2462,      0.8250
      12.2,      0.000,      0.000,         0,      8.3296,      0.8333
      12.3,      0.000,      0.000,         0,      8.4129,      0.8417
      12.3,      0.000,      0.000,         0,      8.4962,      0.8500
      12.5,      0.000,      0.000,         0,      8.5795,      0.8583
      12.6,      0.000,      0.000,         0,      8.6624,      0.8667
      12.7,      0.000,      0.000,         0,      8.7463,      0.8750
      12.9,      0.000,      0.000,         0,      8.8296,      0.8833
      13.0,      0.000,      0.000,         0,      8.9130,      0.8917
      13.1,      0.000,      0.000,         0,      8.9963,      0.9000
      13.3,      0.000,      0.000,         0,      9.0795,      0.9083
      13.4,      0.000,      0.000,         0,      9.1630,      0.9167
      13.6,      0.000,      0.000,         0,      9.2462,      0.9250
      13.8,      0.000,      0.000,         0,      9.3293,      0.9333
      13.9,      0.000,      0.000,         0,      9.4129,      0.9417
      14.1,      0.000,      0.000,         0,      9.4962,      0.9500
      14.3,      0.000,      0.000,         0,      9.5795,      0.9583
      14.4,      0.000,      0.000,         0,      9.6629,      0.9667
      14.6,      0.000,      0.000,         0,      9.7461,      0.9750
      14.7,      0.000,      0.000,         0,      9.8296,      0.9833
      14.9,      0.000,      0.000,         0,      9.9128,      0.9917
      15.1,      0.000,      0.000,         0,      9.9962,      1.0000
      15.2,      0.000,      0.000,         0,     10.0795,      1.0083
      15.4,      0.000,      0.000,         0,     10.1627,      1.0167
      15.2,      0.000,      0.000,         0,     10.2461,      1.0250
       0.0,      0.000,      0.000,         0,     10.3295,      1.0333
       0.0,      0.000,      0.000,         0,     10.4128,      1.0417