File: Alban repo/Quiz 1/suction cup instron tests/july-2020-force-vs-viscosity_raw-data/D30E10-01-inglycerol-onwhiteplatic-diaphragmpump-10mm-test4.raw
Operator: 1

Date,Time,Specimen#
07/22/20,12:11:54,1

---------------------------------------


Area (mm^2):,      1.00,Flat,     25.40,     25.40,     25.40
Gage Len (mm):,     25.40


LOAD (N),STRAIN 1 (mm),STRAIN 2 (mm),STRESS (MPa),POSITION (mm),TIME (min)
       3.2,      0.000,      0.000,         0,      0.0810,      0.0083
       4.4,      0.000,      0.000,         0,      0.1643,      0.0167
       5.5,      0.000,      0.000,         0,      0.2477,      0.0250
       6.6,      0.000,      0.000,         0,      0.3309,      0.0333
       7.7,      0.000,      0.000,         0,      0.4142,      0.0417
       8.7,      0.000,      0.000,         0,      0.4974,      0.0500
       9.7,      0.000,      0.000,         0,      0.5811,      0.0583
      10.6,      0.000,      0.000,         0,      0.6643,      0.0667
      11.6,      0.000,      0.000,         0,      0.7472,      0.0750
      12.5,      0.000,      0.000,         0,      0.8305,      0.0833
      13.4,      0.000,      0.000,         0,      0.9142,      0.0917
      14.3,      0.000,      0.000,         0,      0.9977,      0.1000
      15.2,      0.000,      0.000,         0,      1.0809,      0.1083
      16.0,      0.000,      0.000,         0,      1.1644,      0.1167
      16.8,      0.000,      0.000,         0,      1.2477,      0.1250
      17.6,      0.000,      0.000,         0,      1.3311,      0.1333
      18.4,      0.000,      0.000,         0,      1.4142,      0.1417
      19.2,      0.000,      0.000,         0,      1.4976,      0.1500
      20.0,      0.000,      0.000,         0,      1.5808,      0.1583
      20.7,      0.000,      0.000,         0,      1.6643,      0.1667
      21.5,      0.000,      0.000,         0,      1.7475,      0.1750
      22.2,      0.000,      0.000,         0,      1.8310,      0.1833
      22.9,      0.000,      0.000,         0,      1.9142,      0.1917
      23.5,      0.000,      0.000,         0,      1.9975,      0.2000
      24.2,      0.000,      0.000,         0,      2.0809,      0.2083
      24.8,      0.000,      0.000,         0,      2.1641,      0.2167
      25.4,      0.000,      0.000,         0,      2.2476,      0.2250
      25.9,      0.000,      0.000,         0,      2.3308,      0.2333
      26.4,      0.000,      0.000,         0,      2.4141,      0.2417
      27.0,      0.000,      0.000,         0,      2.4976,      0.2500
      27.4,      0.000,      0.000,         0,      2.5809,      0.2583
      27.9,      0.000,      0.000,         0,      2.6641,      0.2667
      28.3,      0.000,      0.000,         0,      2.7477,      0.2750
      28.7,      0.000,      0.000,         0,      2.8306,      0.2833
      29.1,      0.000,      0.000,         0,      2.9143,      0.2917
      29.5,      0.000,      0.000,         0,      2.9973,      0.3000
      29.7,      0.000,      0.000,         0,      3.0809,      0.3083
      29.8,      0.000,      0.000,         0,      3.1641,      0.3167
      29.9,      0.000,      0.000,         0,      3.2475,      0.3250
      30.2,      0.000,      0.000,         0,      3.3310,      0.3333
      30.6,      0.000,      0.000,         0,      3.4140,      0.3417
      30.9,      0.000,      0.000,         0,      3.4974,      0.3500
      31.3,      0.000,      0.000,         0,      3.5809,      0.3583
      31.6,      0.000,      0.000,         0,      3.6641,      0.3667
      31.9,      0.000,      0.000,         0,      3.7473,      0.3750
      32.3,      0.000,      0.000,         0,      3.8308,      0.3833
      32.6,      0.000,      0.000,         0,      3.9142,      0.3917
      32.9,      0.000,      0.000,         0,      3.9974,      0.4000
      33.2,      0.000,      0.000,         0,      4.0805,      0.4083
      33.5,      0.000,      0.000,         0,      4.1642,      0.4167
      33.8,      0.000,      0.000,         0,      4.2476,      0.4250
      34.1,      0.000,      0.000,         0,      4.3308,      0.4333
      34.4,      0.000,      0.000,         0,      4.4142,      0.4417
      34.7,      0.000,      0.000,         0,      4.4974,      0.4500
      34.9,      0.000,      0.000,         0,      4.5808,      0.4583
      35.2,      0.000,      0.000,         0,      4.6642,      0.4667
      35.5,      0.000,      0.000,         0,      4.7473,      0.4750
      35.7,      0.000,      0.000,         0,      4.8307,      0.4833
      36.0,      0.000,      0.000,         0,      4.9142,      0.4917
      36.2,      0.000,      0.000,         0,      4.9974,      0.5000
      36.4,      0.000,      0.000,         0,      5.0806,      0.5083
      36.7,      0.000,      0.000,         0,      5.1640,      0.5167
      36.9,      0.000,      0.000,         0,      5.2475,      0.5250
      37.1,      0.000,      0.000,         0,      5.3307,      0.5333
      37.4,      0.000,      0.000,         0,      5.4138,      0.5417
      37.6,      0.000,      0.000,         0,      5.4975,      0.5500
      37.8,      0.000,      0.000,         0,      5.5808,      0.5583
      38.0,      0.000,      0.000,         0,      5.6640,      0.5667
      38.2,      0.000,      0.000,         0,      5.7473,      0.5750
      38.5,      0.000,      0.000,         0,      5.8308,      0.5833
      38.7,      0.000,      0.000,         0,      5.9141,      0.5917
      38.9,      0.000,      0.000,         0,      5.9975,      0.6000
      39.1,      0.000,      0.000,         0,      6.0806,      0.6083
      39.3,      0.000,      0.000,         0,      6.1641,      0.6167
      39.5,      0.000,      0.000,         0,      6.2473,      0.6250
      39.7,      0.000,      0.000,         0,      6.3306,      0.6333
      39.9,      0.000,      0.000,         0,      6.4138,      0.6417
      40.1,      0.000,      0.000,         0,      6.4975,      0.6500
      40.4,      0.000,      0.000,         0,      6.5807,      0.6583
      40.6,      0.000,      0.000,         0,      6.6639,      0.6667
      40.8,      0.000,      0.000,         0,      6.7473,      0.6750
      41.0,      0.000,      0.000,         0,      6.8307,      0.6833
      41.2,      0.000,      0.000,         0,      6.9140,      0.6917
      41.4,      0.000,      0.000,         0,      6.9973,      0.7000
      41.6,      0.000,      0.000,         0,      7.0808,      0.7083
      41.7,      0.000,      0.000,         0,      7.1640,      0.7167
      41.9,      0.000,      0.000,         0,      7.2474,      0.7250
      42.1,      0.000,      0.000,         0,      7.3304,      0.7333
      42.3,      0.000,      0.000,         0,      7.4141,      0.7417
      42.5,      0.000,      0.000,         0,      7.4972,      0.7500
      42.7,      0.000,      0.000,         0,      7.5805,      0.7583
      42.8,      0.000,      0.000,         0,      7.6639,      0.7667
      43.0,      0.000,      0.000,         0,      7.7472,      0.7750
      43.2,      0.000,      0.000,         0,      7.8305,      0.7833
      43.4,      0.000,      0.000,         0,      7.9140,      0.7917
      43.6,      0.000,      0.000,         0,      7.9973,      0.8000
      43.7,      0.000,      0.000,         0,      8.0802,      0.8083
      43.9,      0.000,      0.000,         0,      8.1640,      0.8167
      44.1,      0.000,      0.000,         0,      8.2473,      0.8250
      44.2,      0.000,      0.000,         0,      8.3306,      0.8333
      44.4,      0.000,      0.000,         0,      8.4140,      0.8417
      44.6,      0.000,      0.000,         0,      8.4973,      0.8500
      44.7,      0.000,      0.000,         0,      8.5806,      0.8583
      44.9,      0.000,      0.000,         0,      8.6638,      0.8667
      45.0,      0.000,      0.000,         0,      8.7470,      0.8750
      45.2,      0.000,      0.000,         0,      8.8306,      0.8833
      45.4,      0.000,      0.000,         0,      8.9137,      0.8917
      45.5,      0.000,      0.000,         0,      8.9972,      0.9000
      45.6,      0.000,      0.000,         0,      9.0807,      0.9083
      45.8,      0.000,      0.000,         0,      9.1640,      0.9167
      45.9,      0.000,      0.000,         0,      9.2472,      0.9250
      46.1,      0.000,      0.000,         0,      9.3305,      0.9333
      46.2,      0.000,      0.000,         0,      9.4140,      0.9417
      46.4,      0.000,      0.000,         0,      9.4972,      0.9500
      46.5,      0.000,      0.000,         0,      9.5806,      0.9583
      46.6,      0.000,      0.000,         0,      9.6639,      0.9667
      46.8,      0.000,      0.000,         0,      9.7472,      0.9750
      46.9,      0.000,      0.000,         0,      9.8305,      0.9833
      47.0,      0.000,      0.000,         0,      9.9139,      0.9917
      47.1,      0.000,      0.000,         0,      9.9972,      1.0000
      47.3,      0.000,      0.000,         0,     10.0805,      1.0083
      47.4,      0.000,      0.000,         0,     10.1639,      1.0167
      47.5,      0.000,      0.000,         0,     10.2472,      1.0250
      47.6,      0.000,      0.000,         0,     10.3306,      1.0333
      47.7,      0.000,      0.000,         0,     10.4139,      1.0417
      47.8,      0.000,      0.000,         0,     10.4972,      1.0500
      47.9,      0.000,      0.000,         0,     10.5805,      1.0583
      48.0,      0.000,      0.000,         0,     10.6638,      1.0667
      48.1,      0.000,      0.000,         0,     10.7470,      1.0750
      48.1,      0.000,      0.000,         0,     10.8305,      1.0833
      48.2,      0.000,      0.000,         0,     10.9137,      1.0917
      48.3,      0.000,      0.000,         0,     10.9972,      1.1000
      48.4,      0.000,      0.000,         0,     11.0805,      1.1083
      48.4,      0.000,      0.000,         0,     11.1639,      1.1167
      48.5,      0.000,      0.000,         0,     11.2473,      1.1250
      48.5,      0.000,      0.000,         0,     11.3302,      1.1333
      48.6,      0.000,      0.000,         0,     11.4138,      1.1417
      48.6,      0.000,      0.000,         0,     11.4973,      1.1500
      48.6,      0.000,      0.000,         0,     11.5805,      1.1583
      48.6,      0.000,      0.000,         0,     11.6638,      1.1667
      48.6,      0.000,      0.000,         0,     11.7473,      1.1750
      48.6,      0.000,      0.000,         0,     11.8304,      1.1833
      48.5,      0.000,      0.000,         0,     11.9138,      1.1917
      48.4,      0.000,      0.000,         0,     11.9969,      1.2000
      48.3,      0.000,      0.000,         0,     12.0805,      1.2083
      48.1,      0.000,      0.000,         0,     12.1637,      1.2167
      47.7,      0.000,      0.000,         0,     12.2471,      1.2250
      41.8,      0.000,      0.000,         0,     12.3303,      1.2333
       0.0,      0.000,      0.000,         0,     12.4138,      1.2417
       0.0,      0.000,      0.000,         0,     12.4971,      1.2500
       0.0,      0.000,      0.000,         0,     12.5805,      1.2583
       0.0,      0.000,      0.000,         0,     12.6636,      1.2667