File: Alban repo/Quiz 1/suction cup instron tests/july-2020-force-vs-viscosity_raw-data/D30E10-01-inwater-onwhiteplatic-diaphragmpump-10mm-test5.raw
Operator: 1

Date,Time,Specimen#
07/22/20,14:11:44,1

---------------------------------------


Area (mm^2):,      1.00,Flat,     25.40,     25.40,     25.40
Gage Len (mm):,     25.40


LOAD (N),STRAIN 1 (mm),STRAIN 2 (mm),STRESS (MPa),POSITION (mm),TIME (min)
       3.1,      0.000,      0.000,         0,      0.0819,      0.0083
       4.3,      0.000,      0.000,         0,      0.1652,      0.0167
       5.3,      0.000,      0.000,         0,      0.2485,      0.0250
       6.4,      0.000,      0.000,         0,      0.3318,      0.0333
       7.3,      0.000,      0.000,         0,      0.4152,      0.0417
       8.3,      0.000,      0.000,         0,      0.4986,      0.0500
       9.2,      0.000,      0.000,         0,      0.5817,      0.0583
      10.1,      0.000,      0.000,         0,      0.6651,      0.0667
      11.0,      0.000,      0.000,         0,      0.7485,      0.0750
      11.8,      0.000,      0.000,         0,      0.8319,      0.0833
      12.6,      0.000,      0.000,         0,      0.9150,      0.0917
      13.4,      0.000,      0.000,         0,      0.9984,      0.1000
      14.1,      0.000,      0.000,         0,      1.0818,      0.1083
      14.7,      0.000,      0.000,         0,      1.1653,      0.1167
      15.4,      0.000,      0.000,         0,      1.2484,      0.1250
      16.1,      0.000,      0.000,         0,      1.3319,      0.1333
      16.2,      0.000,      0.000,         0,      1.4153,      0.1417
      15.9,      0.000,      0.000,         0,      1.4986,      0.1500
      16.3,      0.000,      0.000,         0,      1.5818,      0.1583
      16.8,      0.000,      0.000,         0,      1.6651,      0.1667
      17.3,      0.000,      0.000,         0,      1.7486,      0.1750
      17.7,      0.000,      0.000,         0,      1.8318,      0.1833
      18.2,      0.000,      0.000,         0,      1.9147,      0.1917
      18.6,      0.000,      0.000,         0,      1.9985,      0.2000
      19.1,      0.000,      0.000,         0,      2.0818,      0.2083
      19.5,      0.000,      0.000,         0,      2.1649,      0.2167
      19.9,      0.000,      0.000,         0,      2.2486,      0.2250
      20.3,      0.000,      0.000,         0,      2.3317,      0.2333
      20.7,      0.000,      0.000,         0,      2.4152,      0.2417
      21.1,      0.000,      0.000,         0,      2.4984,      0.2500
      21.4,      0.000,      0.000,         0,      2.5819,      0.2583
      21.8,      0.000,      0.000,         0,      2.6651,      0.2667
      22.1,      0.000,      0.000,         0,      2.7485,      0.2750
      22.5,      0.000,      0.000,         0,      2.8316,      0.2833
      22.8,      0.000,      0.000,         0,      2.9150,      0.2917
      23.2,      0.000,      0.000,         0,      2.9985,      0.3000
      23.5,      0.000,      0.000,         0,      3.0818,      0.3083
      23.9,      0.000,      0.000,         0,      3.1652,      0.3167
      24.2,      0.000,      0.000,         0,      3.2482,      0.3250
      24.5,      0.000,      0.000,         0,      3.3317,      0.3333
      24.9,      0.000,      0.000,         0,      3.4152,      0.3417
      25.2,      0.000,      0.000,         0,      3.4984,      0.3500
      25.5,      0.000,      0.000,         0,      3.5814,      0.3583
      25.8,      0.000,      0.000,         0,      3.6651,      0.3667
      26.1,      0.000,      0.000,         0,      3.7483,      0.3750
      26.5,      0.000,      0.000,         0,      3.8318,      0.3833
      26.8,      0.000,      0.000,         0,      3.9148,      0.3917
      27.1,      0.000,      0.000,         0,      3.9984,      0.4000
      27.4,      0.000,      0.000,         0,      4.0818,      0.4083
      27.7,      0.000,      0.000,         0,      4.1650,      0.4167
      28.0,      0.000,      0.000,         0,      4.2484,      0.4250
      28.2,      0.000,      0.000,         0,      4.3317,      0.4333
      28.5,      0.000,      0.000,         0,      4.4151,      0.4417
      28.8,      0.000,      0.000,         0,      4.4984,      0.4500
      29.1,      0.000,      0.000,         0,      4.5818,      0.4583
      29.4,      0.000,      0.000,         0,      4.6650,      0.4667
      29.7,      0.000,      0.000,         0,      4.7483,      0.4750
      30.0,      0.000,      0.000,         0,      4.8317,      0.4833
      30.2,      0.000,      0.000,         0,      4.9150,      0.4917
      30.5,      0.000,      0.000,         0,      4.9982,      0.5000
      30.8,      0.000,      0.000,         0,      5.0817,      0.5083
      31.0,      0.000,      0.000,         0,      5.1650,      0.5167
      31.3,      0.000,      0.000,         0,      5.2482,      0.5250
      31.5,      0.000,      0.000,         0,      5.3316,      0.5333
      31.8,      0.000,      0.000,         0,      5.4150,      0.5417
      32.1,      0.000,      0.000,         0,      5.4984,      0.5500
      32.3,      0.000,      0.000,         0,      5.5816,      0.5583
      32.6,      0.000,      0.000,         0,      5.6650,      0.5667
      32.8,      0.000,      0.000,         0,      5.7483,      0.5750
      33.1,      0.000,      0.000,         0,      5.8317,      0.5833
      33.3,      0.000,      0.000,         0,      5.9148,      0.5917
      33.6,      0.000,      0.000,         0,      5.9983,      0.6000
      33.8,      0.000,      0.000,         0,      6.0817,      0.6083
      34.0,      0.000,      0.000,         0,      6.1649,      0.6167
      34.3,      0.000,      0.000,         0,      6.2482,      0.6250
      34.5,      0.000,      0.000,         0,      6.3316,      0.6333
      34.7,      0.000,      0.000,         0,      6.4151,      0.6417
      34.9,      0.000,      0.000,         0,      6.4981,      0.6500
      35.2,      0.000,      0.000,         0,      6.5814,      0.6583
      35.4,      0.000,      0.000,         0,      6.6650,      0.6667
      35.6,      0.000,      0.000,         0,      6.7484,      0.6750
      35.9,      0.000,      0.000,         0,      6.8314,      0.6833
      36.1,      0.000,      0.000,         0,      6.9150,      0.6917
      36.3,      0.000,      0.000,         0,      6.9982,      0.7000
      36.5,      0.000,      0.000,         0,      7.0815,      0.7083
      36.7,      0.000,      0.000,         0,      7.1649,      0.7167
      36.9,      0.000,      0.000,         0,      7.2483,      0.7250
      37.2,      0.000,      0.000,         0,      7.3317,      0.7333
      37.4,      0.000,      0.000,         0,      7.4149,      0.7417
      37.6,      0.000,      0.000,         0,      7.4980,      0.7500
      37.8,      0.000,      0.000,         0,      7.5815,      0.7583
      38.0,      0.000,      0.000,         0,      7.6648,      0.7667
      38.2,      0.000,      0.000,         0,      7.7482,      0.7750
      38.4,      0.000,      0.000,         0,      7.8316,      0.7833
      38.6,      0.000,      0.000,         0,      7.9147,      0.7917
      38.8,      0.000,      0.000,         0,      7.9982,      0.8000
      39.0,      0.000,      0.000,         0,      8.0815,      0.8083
      39.2,      0.000,      0.000,         0,      8.1649,      0.8167
      39.5,      0.000,      0.000,         0,      8.2482,      0.8250
      39.7,      0.000,      0.000,         0,      8.3316,      0.8333
      39.8,      0.000,      0.000,         0,      8.4150,      0.8417
      40.0,      0.000,      0.000,         0,      8.4981,      0.8500
      40.2,      0.000,      0.000,         0,      8.5816,      0.8583
      40.4,      0.000,      0.000,         0,      8.6649,      0.8667
      40.6,      0.000,      0.000,         0,      8.7482,      0.8750
      40.8,      0.000,      0.000,         0,      8.8314,      0.8833
      41.0,      0.000,      0.000,         0,      8.9149,      0.8917
      41.2,      0.000,      0.000,         0,      8.9981,      0.9000
      41.4,      0.000,      0.000,         0,      9.0816,      0.9083
      41.6,      0.000,      0.000,         0,      9.1648,      0.9167
      41.8,      0.000,      0.000,         0,      9.2477,      0.9250
      42.0,      0.000,      0.000,         0,      9.3315,      0.9333
      42.1,      0.000,      0.000,         0,      9.4148,      0.9417
      42.3,      0.000,      0.000,         0,      9.4981,      0.9500
      42.5,      0.000,      0.000,         0,      9.5814,      0.9583
      42.7,      0.000,      0.000,         0,      9.6650,      0.9667
      42.9,      0.000,      0.000,         0,      9.7480,      0.9750
      43.0,      0.000,      0.000,         0,      9.8314,      0.9833
      43.2,      0.000,      0.000,         0,      9.9148,      0.9917
      43.4,      0.000,      0.000,         0,      9.9982,      1.0000
      43.6,      0.000,      0.000,         0,     10.0814,      1.0083
      43.8,      0.000,      0.000,         0,     10.1649,      1.0167
      43.9,      0.000,      0.000,         0,     10.2480,      1.0250
      44.1,      0.000,      0.000,         0,     10.3313,      1.0333
      44.3,      0.000,      0.000,         0,     10.4148,      1.0417
      44.5,      0.000,      0.000,         0,     10.4982,      1.0500
      44.6,      0.000,      0.000,         0,     10.5813,      1.0583
      44.8,      0.000,      0.000,         0,     10.6647,      1.0667
      45.0,      0.000,      0.000,         0,     10.7481,      1.0750
      45.1,      0.000,      0.000,         0,     10.8313,      1.0833
      45.3,      0.000,      0.000,         0,     10.9147,      1.0917
      45.5,      0.000,      0.000,         0,     10.9981,      1.1000
      45.7,      0.000,      0.000,         0,     11.0814,      1.1083
      45.8,      0.000,      0.000,         0,     11.1645,      1.1167
      46.0,      0.000,      0.000,         0,     11.2481,      1.1250
      46.1,      0.000,      0.000,         0,     11.3314,      1.1333
      46.2,      0.000,      0.000,         0,     11.4146,      1.1417
      46.3,      0.000,      0.000,         0,     11.4978,      1.1500
      46.4,      0.000,      0.000,         0,     11.5814,      1.1583
      46.6,      0.000,      0.000,         0,     11.6647,      1.1667
      46.6,      0.000,      0.000,         0,     11.7480,      1.1750
      46.7,      0.000,      0.000,         0,     11.8311,      1.1833
      46.8,      0.000,      0.000,         0,     11.9147,      1.1917
      46.9,      0.000,      0.000,         0,     11.9981,      1.2000
      47.0,      0.000,      0.000,         0,     12.0812,      1.2083
      47.0,      0.000,      0.000,         0,     12.1648,      1.2167
      47.1,      0.000,      0.000,         0,     12.2481,      1.2250
      47.2,      0.000,      0.000,         0,     12.3315,      1.2333
      47.2,      0.000,      0.000,         0,     12.4146,      1.2417
      47.2,      0.000,      0.000,         0,     12.4980,      1.2500
      47.3,      0.000,      0.000,         0,     12.5813,      1.2583
      47.3,      0.000,      0.000,         0,     12.6647,      1.2667
      47.3,      0.000,      0.000,         0,     12.7480,      1.2750
      47.3,      0.000,      0.000,         0,     12.8313,      1.2833
      47.2,      0.000,      0.000,         0,     12.9145,      1.2917
      47.1,      0.000,      0.000,         0,     12.9979,      1.3000
      46.9,      0.000,      0.000,         0,     13.0814,      1.3083
      46.7,      0.000,      0.000,         0,     13.1643,      1.3167
      46.4,      0.000,      0.000,         0,     13.2479,      1.3250
      46.1,      0.000,      0.000,         0,     13.3313,      1.3333
      45.6,      0.000,      0.000,         0,     13.4146,      1.3417
      45.0,      0.000,      0.000,         0,     13.4978,      1.3500
      44.1,      0.000,      0.000,         0,     13.5814,      1.3583
      42.7,      0.000,      0.000,         0,     13.6645,      1.3667
       2.0,      0.000,      0.000,         0,     13.7480,      1.3750
       0.0,      0.000,      0.000,         0,     13.8311,      1.3833
       0.0,      0.000,      0.000,         0,     13.9145,      1.3917
       0.0,      0.000,      0.000,         0,     13.9980,      1.4000