File: Alban repo/Quiz 1/suction cup instron tests/july-2020-force-vs-viscosity_raw-data/D30E10-01-inglycerol-onwhiteplatic-diaphragmpump-10mm-test2.raw
Operator: 1

Date,Time,Specimen#
07/22/20,12:05:29,1

---------------------------------------


Area (mm^2):,      1.00,Flat,     25.40,     25.40,     25.40
Gage Len (mm):,     25.40


LOAD (N),STRAIN 1 (mm),STRAIN 2 (mm),STRESS (MPa),POSITION (mm),TIME (min)
       3.2,      0.000,      0.000,         0,      0.0807,      0.0083
       4.4,      0.000,      0.000,         0,      0.1640,      0.0167
       5.5,      0.000,      0.000,         0,      0.2474,      0.0250
       6.6,      0.000,      0.000,         0,      0.3308,      0.0333
       7.7,      0.000,      0.000,         0,      0.4141,      0.0417
       8.7,      0.000,      0.000,         0,      0.4973,      0.0500
       9.7,      0.000,      0.000,         0,      0.5807,      0.0583
      10.6,      0.000,      0.000,         0,      0.6641,      0.0667
      11.5,      0.000,      0.000,         0,      0.7471,      0.0750
      12.4,      0.000,      0.000,         0,      0.8302,      0.0833
      13.4,      0.000,      0.000,         0,      0.9140,      0.0917
      14.2,      0.000,      0.000,         0,      0.9975,      0.1000
      15.1,      0.000,      0.000,         0,      1.0804,      0.1083
      15.9,      0.000,      0.000,         0,      1.1641,      0.1167
      16.7,      0.000,      0.000,         0,      1.2473,      0.1250
      17.5,      0.000,      0.000,         0,      1.3308,      0.1333
      18.2,      0.000,      0.000,         0,      1.4141,      0.1417
      19.0,      0.000,      0.000,         0,      1.4973,      0.1500
      19.7,      0.000,      0.000,         0,      1.5807,      0.1583
      20.5,      0.000,      0.000,         0,      1.6641,      0.1667
      21.2,      0.000,      0.000,         0,      1.7472,      0.1750
      21.8,      0.000,      0.000,         0,      1.8306,      0.1833
      22.5,      0.000,      0.000,         0,      1.9142,      0.1917
      23.2,      0.000,      0.000,         0,      1.9973,      0.2000
      23.8,      0.000,      0.000,         0,      2.0807,      0.2083
      24.4,      0.000,      0.000,         0,      2.1636,      0.2167
      25.0,      0.000,      0.000,         0,      2.2473,      0.2250
      25.4,      0.000,      0.000,         0,      2.3307,      0.2333
      26.0,      0.000,      0.000,         0,      2.4139,      0.2417
      26.5,      0.000,      0.000,         0,      2.4970,      0.2500
      26.9,      0.000,      0.000,         0,      2.5806,      0.2583
      27.4,      0.000,      0.000,         0,      2.6639,      0.2667
      27.8,      0.000,      0.000,         0,      2.7473,      0.2750
      28.2,      0.000,      0.000,         0,      2.8305,      0.2833
      28.5,      0.000,      0.000,         0,      2.9138,      0.2917
      28.8,      0.000,      0.000,         0,      2.9974,      0.3000
      29.0,      0.000,      0.000,         0,      3.0807,      0.3083
      29.0,      0.000,      0.000,         0,      3.1639,      0.3167
      29.2,      0.000,      0.000,         0,      3.2472,      0.3250
      29.5,      0.000,      0.000,         0,      3.3307,      0.3333
      29.8,      0.000,      0.000,         0,      3.4139,      0.3417
      30.2,      0.000,      0.000,         0,      3.4972,      0.3500
      30.5,      0.000,      0.000,         0,      3.5806,      0.3583
      30.8,      0.000,      0.000,         0,      3.6640,      0.3667
      31.1,      0.000,      0.000,         0,      3.7472,      0.3750
      31.5,      0.000,      0.000,         0,      3.8305,      0.3833
      31.8,      0.000,      0.000,         0,      3.9139,      0.3917
      32.1,      0.000,      0.000,         0,      3.9972,      0.4000
      32.4,      0.000,      0.000,         0,      4.0806,      0.4083
      32.7,      0.000,      0.000,         0,      4.1639,      0.4167
      33.0,      0.000,      0.000,         0,      4.2472,      0.4250
      33.3,      0.000,      0.000,         0,      4.3304,      0.4333
      33.6,      0.000,      0.000,         0,      4.4139,      0.4417
      33.9,      0.000,      0.000,         0,      4.4972,      0.4500
      34.1,      0.000,      0.000,         0,      4.5806,      0.4583
      34.4,      0.000,      0.000,         0,      4.6638,      0.4667
      34.7,      0.000,      0.000,         0,      4.7472,      0.4750
      34.9,      0.000,      0.000,         0,      4.8301,      0.4833
      35.2,      0.000,      0.000,         0,      4.9138,      0.4917
      35.4,      0.000,      0.000,         0,      4.9972,      0.5000
      35.7,      0.000,      0.000,         0,      5.0804,      0.5083
      35.9,      0.000,      0.000,         0,      5.1638,      0.5167
      36.1,      0.000,      0.000,         0,      5.2472,      0.5250
      36.4,      0.000,      0.000,         0,      5.3305,      0.5333
      36.6,      0.000,      0.000,         0,      5.4137,      0.5417
      36.8,      0.000,      0.000,         0,      5.4971,      0.5500
      37.1,      0.000,      0.000,         0,      5.5804,      0.5583
      37.3,      0.000,      0.000,         0,      5.6638,      0.5667
      37.5,      0.000,      0.000,         0,      5.7469,      0.5750
      37.8,      0.000,      0.000,         0,      5.8304,      0.5833
      38.0,      0.000,      0.000,         0,      5.9138,      0.5917
      38.2,      0.000,      0.000,         0,      5.9972,      0.6000
      38.4,      0.000,      0.000,         0,      6.0805,      0.6083
      38.6,      0.000,      0.000,         0,      6.1637,      0.6167
      38.9,      0.000,      0.000,         0,      6.2473,      0.6250
      39.1,      0.000,      0.000,         0,      6.3305,      0.6333
      39.3,      0.000,      0.000,         0,      6.4136,      0.6417
      39.5,      0.000,      0.000,         0,      6.4970,      0.6500
      39.7,      0.000,      0.000,         0,      6.5805,      0.6583
      40.0,      0.000,      0.000,         0,      6.6638,      0.6667
      40.2,      0.000,      0.000,         0,      6.7471,      0.6750
      40.4,      0.000,      0.000,         0,      6.8303,      0.6833
      40.6,      0.000,      0.000,         0,      6.9139,      0.6917
      40.8,      0.000,      0.000,         0,      6.9969,      0.7000
      41.0,      0.000,      0.000,         0,      7.0803,      0.7083
      41.2,      0.000,      0.000,         0,      7.1639,      0.7167
      41.4,      0.000,      0.000,         0,      7.2470,      0.7250
      41.6,      0.000,      0.000,         0,      7.3303,      0.7333
      41.8,      0.000,      0.000,         0,      7.4136,      0.7417
      42.1,      0.000,      0.000,         0,      7.4970,      0.7500
      42.2,      0.000,      0.000,         0,      7.5802,      0.7583
      42.5,      0.000,      0.000,         0,      7.6637,      0.7667
      42.6,      0.000,      0.000,         0,      7.7471,      0.7750
      42.8,      0.000,      0.000,         0,      7.8303,      0.7833
      43.0,      0.000,      0.000,         0,      7.9137,      0.7917
      43.2,      0.000,      0.000,         0,      7.9972,      0.8000
      43.4,      0.000,      0.000,         0,      8.0804,      0.8083
      43.6,      0.000,      0.000,         0,      8.1635,      0.8167
      43.8,      0.000,      0.000,         0,      8.2471,      0.8250
      43.9,      0.000,      0.000,         0,      8.3304,      0.8333
      44.1,      0.000,      0.000,         0,      8.4136,      0.8417
      44.2,      0.000,      0.000,         0,      8.4970,      0.8500
      44.4,      0.000,      0.000,         0,      8.5804,      0.8583
      44.6,      0.000,      0.000,         0,      8.6638,      0.8667
      44.7,      0.000,      0.000,         0,      8.7470,      0.8750
      44.9,      0.000,      0.000,         0,      8.8303,      0.8833
      45.1,      0.000,      0.000,         0,      8.9137,      0.8917
      45.2,      0.000,      0.000,         0,      8.9967,      0.9000
      45.4,      0.000,      0.000,         0,      9.0804,      0.9083
      45.5,      0.000,      0.000,         0,      9.1637,      0.9167
      45.6,      0.000,      0.000,         0,      9.2471,      0.9250
      45.8,      0.000,      0.000,         0,      9.3302,      0.9333
      45.9,      0.000,      0.000,         0,      9.4135,      0.9417
      46.1,      0.000,      0.000,         0,      9.4968,      0.9500
      46.2,      0.000,      0.000,         0,      9.5804,      0.9583
      46.3,      0.000,      0.000,         0,      9.6637,      0.9667
      46.4,      0.000,      0.000,         0,      9.7469,      0.9750
      46.5,      0.000,      0.000,         0,      9.8304,      0.9833
      46.6,      0.000,      0.000,         0,      9.9136,      0.9917
      46.8,      0.000,      0.000,         0,      9.9969,      1.0000
      46.9,      0.000,      0.000,         0,     10.0801,      1.0083
      47.0,      0.000,      0.000,         0,     10.1637,      1.0167
      47.1,      0.000,      0.000,         0,     10.2469,      1.0250
      47.2,      0.000,      0.000,         0,     10.3302,      1.0333
      47.4,      0.000,      0.000,         0,     10.4134,      1.0417
      47.5,      0.000,      0.000,         0,     10.4970,      1.0500
      47.6,      0.000,      0.000,         0,     10.5803,      1.0583
      47.7,      0.000,      0.000,         0,     10.6636,      1.0667
      47.7,      0.000,      0.000,         0,     10.7466,      1.0750
      47.8,      0.000,      0.000,         0,     10.8302,      1.0833
      47.9,      0.000,      0.000,         0,     10.9136,      1.0917
      48.0,      0.000,      0.000,         0,     10.9968,      1.1000
      48.1,      0.000,      0.000,         0,     11.0802,      1.1083
      48.2,      0.000,      0.000,         0,     11.1636,      1.1167
      48.2,      0.000,      0.000,         0,     11.2470,      1.1250
      48.3,      0.000,      0.000,         0,     11.3303,      1.1333
      48.3,      0.000,      0.000,         0,     11.4133,      1.1417
      48.4,      0.000,      0.000,         0,     11.4969,      1.1500
      48.4,      0.000,      0.000,         0,     11.5804,      1.1583
      48.4,      0.000,      0.000,         0,     11.6635,      1.1667
      48.4,      0.000,      0.000,         0,     11.7469,      1.1750
      48.4,      0.000,      0.000,         0,     11.8303,      1.1833
      48.4,      0.000,      0.000,         0,     11.9136,      1.1917
      48.3,      0.000,      0.000,         0,     11.9970,      1.2000
      48.2,      0.000,      0.000,         0,     12.0798,      1.2083
      48.1,      0.000,      0.000,         0,     12.1636,      1.2167
      47.9,      0.000,      0.000,         0,     12.2467,      1.2250
      47.7,      0.000,      0.000,         0,     12.3303,      1.2333
      47.2,      0.000,      0.000,         0,     12.4135,      1.2417
       5.4,      0.000,      0.000,         0,     12.4969,      1.2500
       0.0,      0.000,      0.000,         0,     12.5802,      1.2583
       0.0,      0.000,      0.000,         0,     12.6636,      1.2667
       0.0,      0.000,      0.000,         0,     12.7466,      1.2750
       0.0,      0.000,      0.000,         0,     12.8302,      1.2833
       0.0,      0.000,      0.000,         0,     12.9136,      1.2917