File: Alban repo/Quiz 1/suction cup instron tests/july-2020-force-vs-viscosity_raw-data/D30E10-01-inglycerol-onwhiteplatic-diaphragmpump-10mm-test5.raw
Operator: 1

Date,Time,Specimen#
07/22/20,12:15:06,1

---------------------------------------


Area (mm^2):,      1.00,Flat,     25.40,     25.40,     25.40
Gage Len (mm):,     25.40


LOAD (N),STRAIN 1 (mm),STRAIN 2 (mm),STRESS (MPa),POSITION (mm),TIME (min)
       3.2,      0.000,      0.000,         0,      0.0811,      0.0083
       4.4,      0.000,      0.000,         0,      0.1641,      0.0167
       5.6,      0.000,      0.000,         0,      0.2476,      0.0250
       6.7,      0.000,      0.000,         0,      0.3310,      0.0333
       7.8,      0.000,      0.000,         0,      0.4144,      0.0417
       8.9,      0.000,      0.000,         0,      0.4975,      0.0500
       9.9,      0.000,      0.000,         0,      0.5811,      0.0583
      10.9,      0.000,      0.000,         0,      0.6642,      0.0667
      11.8,      0.000,      0.000,         0,      0.7476,      0.0750
      12.7,      0.000,      0.000,         0,      0.8307,      0.0833
      13.7,      0.000,      0.000,         0,      0.9141,      0.0917
      14.6,      0.000,      0.000,         0,      0.9977,      0.1000
      15.4,      0.000,      0.000,         0,      1.0809,      0.1083
      16.3,      0.000,      0.000,         0,      1.1642,      0.1167
      17.1,      0.000,      0.000,         0,      1.2477,      0.1250
      17.9,      0.000,      0.000,         0,      1.3310,      0.1333
      18.7,      0.000,      0.000,         0,      1.4142,      0.1417
      19.5,      0.000,      0.000,         0,      1.4977,      0.1500
      20.2,      0.000,      0.000,         0,      1.5807,      0.1583
      21.0,      0.000,      0.000,         0,      1.6642,      0.1667
      21.7,      0.000,      0.000,         0,      1.7475,      0.1750
      22.4,      0.000,      0.000,         0,      1.8309,      0.1833
      23.1,      0.000,      0.000,         0,      1.9142,      0.1917
      23.8,      0.000,      0.000,         0,      1.9976,      0.2000
      24.5,      0.000,      0.000,         0,      2.0810,      0.2083
      25.1,      0.000,      0.000,         0,      2.1643,      0.2167
      25.7,      0.000,      0.000,         0,      2.2473,      0.2250
      26.3,      0.000,      0.000,         0,      2.3310,      0.2333
      26.9,      0.000,      0.000,         0,      2.4143,      0.2417
      27.4,      0.000,      0.000,         0,      2.4973,      0.2500
      27.9,      0.000,      0.000,         0,      2.5809,      0.2583
      28.3,      0.000,      0.000,         0,      2.6642,      0.2667
      28.8,      0.000,      0.000,         0,      2.7476,      0.2750
      29.2,      0.000,      0.000,         0,      2.8309,      0.2833
      29.6,      0.000,      0.000,         0,      2.9142,      0.2917
      30.0,      0.000,      0.000,         0,      2.9975,      0.3000
      30.3,      0.000,      0.000,         0,      3.0809,      0.3083
      30.6,      0.000,      0.000,         0,      3.1642,      0.3167
      30.9,      0.000,      0.000,         0,      3.2475,      0.3250
      30.9,      0.000,      0.000,         0,      3.3309,      0.3333
      31.0,      0.000,      0.000,         0,      3.4142,      0.3417
      31.4,      0.000,      0.000,         0,      3.4975,      0.3500
      31.7,      0.000,      0.000,         0,      3.5807,      0.3583
      32.0,      0.000,      0.000,         0,      3.6641,      0.3667
      32.3,      0.000,      0.000,         0,      3.7474,      0.3750
      32.7,      0.000,      0.000,         0,      3.8308,      0.3833
      33.0,      0.000,      0.000,         0,      3.9142,      0.3917
      33.3,      0.000,      0.000,         0,      3.9974,      0.4000
      33.6,      0.000,      0.000,         0,      4.0808,      0.4083
      33.9,      0.000,      0.000,         0,      4.1642,      0.4167
      34.2,      0.000,      0.000,         0,      4.2473,      0.4250
      34.5,      0.000,      0.000,         0,      4.3308,      0.4333
      34.7,      0.000,      0.000,         0,      4.4140,      0.4417
      35.0,      0.000,      0.000,         0,      4.4973,      0.4500
      35.3,      0.000,      0.000,         0,      4.5807,      0.4583
      35.5,      0.000,      0.000,         0,      4.6641,      0.4667
      35.8,      0.000,      0.000,         0,      4.7476,      0.4750
      36.0,      0.000,      0.000,         0,      4.8305,      0.4833
      36.3,      0.000,      0.000,         0,      4.9142,      0.4917
      36.5,      0.000,      0.000,         0,      4.9974,      0.5000
      36.8,      0.000,      0.000,         0,      5.0808,      0.5083
      37.0,      0.000,      0.000,         0,      5.1640,      0.5167
      37.2,      0.000,      0.000,         0,      5.2476,      0.5250
      37.4,      0.000,      0.000,         0,      5.3308,      0.5333
      37.6,      0.000,      0.000,         0,      5.4140,      0.5417
      37.9,      0.000,      0.000,         0,      5.4972,      0.5500
      38.1,      0.000,      0.000,         0,      5.5807,      0.5583
      38.3,      0.000,      0.000,         0,      5.6641,      0.5667
      38.5,      0.000,      0.000,         0,      5.7473,      0.5750
      38.7,      0.000,      0.000,         0,      5.8308,      0.5833
      38.9,      0.000,      0.000,         0,      5.9141,      0.5917
      39.1,      0.000,      0.000,         0,      5.9973,      0.6000
      39.4,      0.000,      0.000,         0,      6.0807,      0.6083
      39.6,      0.000,      0.000,         0,      6.1641,      0.6167
      39.8,      0.000,      0.000,         0,      6.2473,      0.6250
      40.0,      0.000,      0.000,         0,      6.3309,      0.6333
      40.2,      0.000,      0.000,         0,      6.4141,      0.6417
      40.4,      0.000,      0.000,         0,      6.4971,      0.6500
      40.6,      0.000,      0.000,         0,      6.5806,      0.6583
      40.8,      0.000,      0.000,         0,      6.6641,      0.6667
      41.0,      0.000,      0.000,         0,      6.7473,      0.6750
      41.2,      0.000,      0.000,         0,      6.8305,      0.6833
      41.4,      0.000,      0.000,         0,      6.9140,      0.6917
      41.6,      0.000,      0.000,         0,      6.9972,      0.7000
      41.8,      0.000,      0.000,         0,      7.0807,      0.7083
      42.0,      0.000,      0.000,         0,      7.1640,      0.7167
      42.1,      0.000,      0.000,         0,      7.2475,      0.7250
      42.3,      0.000,      0.000,         0,      7.3307,      0.7333
      42.5,      0.000,      0.000,         0,      7.4140,      0.7417
      42.7,      0.000,      0.000,         0,      7.4972,      0.7500
      42.8,      0.000,      0.000,         0,      7.5808,      0.7583
      43.0,      0.000,      0.000,         0,      7.6640,      0.7667
      43.1,      0.000,      0.000,         0,      7.7474,      0.7750
      43.3,      0.000,      0.000,         0,      7.8305,      0.7833
      43.5,      0.000,      0.000,         0,      7.9140,      0.7917
      43.7,      0.000,      0.000,         0,      7.9974,      0.8000
      43.9,      0.000,      0.000,         0,      8.0806,      0.8083
      44.0,      0.000,      0.000,         0,      8.1635,      0.8167
      44.2,      0.000,      0.000,         0,      8.2475,      0.8250
      44.4,      0.000,      0.000,         0,      8.3306,      0.8333
      44.6,      0.000,      0.000,         0,      8.4139,      0.8417
      44.7,      0.000,      0.000,         0,      8.4974,      0.8500
      44.9,      0.000,      0.000,         0,      8.5806,      0.8583
      45.0,      0.000,      0.000,         0,      8.6639,      0.8667
      45.2,      0.000,      0.000,         0,      8.7472,      0.8750
      45.4,      0.000,      0.000,         0,      8.8306,      0.8833
      45.5,      0.000,      0.000,         0,      8.9137,      0.8917
      45.7,      0.000,      0.000,         0,      8.9972,      0.9000
      45.8,      0.000,      0.000,         0,      9.0805,      0.9083
      46.0,      0.000,      0.000,         0,      9.1640,      0.9167
      46.1,      0.000,      0.000,         0,      9.2472,      0.9250
      46.3,      0.000,      0.000,         0,      9.3306,      0.9333
      46.4,      0.000,      0.000,         0,      9.4141,      0.9417
      46.5,      0.000,      0.000,         0,      9.4970,      0.9500
      46.7,      0.000,      0.000,         0,      9.5806,      0.9583
      46.8,      0.000,      0.000,         0,      9.6639,      0.9667
      46.9,      0.000,      0.000,         0,      9.7472,      0.9750
      47.1,      0.000,      0.000,         0,      9.8305,      0.9833
      47.2,      0.000,      0.000,         0,      9.9139,      0.9917
      47.3,      0.000,      0.000,         0,      9.9972,      1.0000
      47.4,      0.000,      0.000,         0,     10.0804,      1.0083
      47.6,      0.000,      0.000,         0,     10.1639,      1.0167
      47.7,      0.000,      0.000,         0,     10.2473,      1.0250
      47.8,      0.000,      0.000,         0,     10.3305,      1.0333
      47.9,      0.000,      0.000,         0,     10.4138,      1.0417
      48.0,      0.000,      0.000,         0,     10.4972,      1.0500
      48.1,      0.000,      0.000,         0,     10.5805,      1.0583
      48.2,      0.000,      0.000,         0,     10.6640,      1.0667
      48.3,      0.000,      0.000,         0,     10.7468,      1.0750
      48.4,      0.000,      0.000,         0,     10.8303,      1.0833
      48.5,      0.000,      0.000,         0,     10.9138,      1.0917
      48.6,      0.000,      0.000,         0,     10.9972,      1.1000
      48.6,      0.000,      0.000,         0,     11.0805,      1.1083
      48.7,      0.000,      0.000,         0,     11.1638,      1.1167
      48.8,      0.000,      0.000,         0,     11.2471,      1.1250
      48.8,      0.000,      0.000,         0,     11.3305,      1.1333
      48.9,      0.000,      0.000,         0,     11.4136,      1.1417
      48.9,      0.000,      0.000,         0,     11.4972,      1.1500
      48.9,      0.000,      0.000,         0,     11.5806,      1.1583
      48.9,      0.000,      0.000,         0,     11.6637,      1.1667
      49.0,      0.000,      0.000,         0,     11.7471,      1.1750
      48.9,      0.000,      0.000,         0,     11.8304,      1.1833
      48.9,      0.000,      0.000,         0,     11.9137,      1.1917
      48.9,      0.000,      0.000,         0,     11.9970,      1.2000
      48.8,      0.000,      0.000,         0,     12.0805,      1.2083
      48.7,      0.000,      0.000,         0,     12.1633,      1.2167
      48.5,      0.000,      0.000,         0,     12.2472,      1.2250
      48.2,      0.000,      0.000,         0,     12.3302,      1.2333
      47.6,      0.000,      0.000,         0,     12.4137,      1.2417
       0.1,      0.000,      0.000,         0,     12.4971,      1.2500
       0.0,      0.000,      0.000,         0,     12.5805,      1.2583
       0.0,      0.000,      0.000,         0,     12.6638,      1.2667
       0.0,      0.000,      0.000,         0,     12.7471,      1.2750
       0.0,      0.000,      0.000,         0,     12.8305,      1.2833