File: Alban repo/Quiz 1/suction cup instron tests/july-2020-force-vs-viscosity_raw-data/D30E10-01-inair-onwhiteplatic-diaphragmpump-10mm-test1.raw
Operator: 1

Date,Time,Specimen#
07/22/20,14:23:37,1

---------------------------------------


Area (mm^2):,      1.00,Flat,     25.40,     25.40,     25.40
Gage Len (mm):,     25.40


LOAD (N),STRAIN 1 (mm),STRAIN 2 (mm),STRESS (MPa),POSITION (mm),TIME (min)
       2.9,      0.000,      0.000,         0,      0.0804,      0.0083
       3.7,      0.000,      0.000,         0,      0.1636,      0.0167
       4.6,      0.000,      0.000,         0,      0.2471,      0.0250
       5.3,      0.000,      0.000,         0,      0.3302,      0.0333
       5.9,      0.000,      0.000,         0,      0.4136,      0.0417
       6.0,      0.000,      0.000,         0,      0.4970,      0.0500
       4.0,      0.000,      0.000,         0,      0.5803,      0.0583
       4.2,      0.000,      0.000,         0,      0.6636,      0.0667
       4.6,      0.000,      0.000,         0,      0.7470,      0.0750
       4.9,      0.000,      0.000,         0,      0.8304,      0.0833
       5.2,      0.000,      0.000,         0,      0.9135,      0.0917
       5.6,      0.000,      0.000,         0,      0.9969,      0.1000
       5.9,      0.000,      0.000,         0,      1.0804,      0.1083
       6.2,      0.000,      0.000,         0,      1.1638,      0.1167
       6.5,      0.000,      0.000,         0,      1.2469,      0.1250
       6.7,      0.000,      0.000,         0,      1.3302,      0.1333
       7.0,      0.000,      0.000,         0,      1.4138,      0.1417
       7.3,      0.000,      0.000,         0,      1.4969,      0.1500
       7.5,      0.000,      0.000,         0,      1.5802,      0.1583
       7.7,      0.000,      0.000,         0,      1.6633,      0.1667
       8.0,      0.000,      0.000,         0,      1.7472,      0.1750
       8.2,      0.000,      0.000,         0,      1.8303,      0.1833
       8.4,      0.000,      0.000,         0,      1.9136,      0.1917
       8.7,      0.000,      0.000,         0,      1.9970,      0.2000
       8.9,      0.000,      0.000,         0,      2.0803,      0.2083
       9.1,      0.000,      0.000,         0,      2.1635,      0.2167
       9.4,      0.000,      0.000,         0,      2.2469,      0.2250
       9.6,      0.000,      0.000,         0,      2.3302,      0.2333
       9.8,      0.000,      0.000,         0,      2.4135,      0.2417
      10.0,      0.000,      0.000,         0,      2.4969,      0.2500
      10.2,      0.000,      0.000,         0,      2.5802,      0.2583
      10.4,      0.000,      0.000,         0,      2.6634,      0.2667
      10.5,      0.000,      0.000,         0,      2.7469,      0.2750
      10.7,      0.000,      0.000,         0,      2.8304,      0.2833
      10.9,      0.000,      0.000,         0,      2.9136,      0.2917
      11.1,      0.000,      0.000,         0,      2.9968,      0.3000
      11.2,      0.000,      0.000,         0,      3.0802,      0.3083
      11.4,      0.000,      0.000,         0,      3.1636,      0.3167
      11.6,      0.000,      0.000,         0,      3.2466,      0.3250
      11.8,      0.000,      0.000,         0,      3.3301,      0.3333
      11.9,      0.000,      0.000,         0,      3.4136,      0.3417
      12.0,      0.000,      0.000,         0,      3.4969,      0.3500
      12.2,      0.000,      0.000,         0,      3.5802,      0.3583
      12.4,      0.000,      0.000,         0,      3.6634,      0.3667
      12.6,      0.000,      0.000,         0,      3.7469,      0.3750
      12.7,      0.000,      0.000,         0,      3.8302,      0.3833
      12.9,      0.000,      0.000,         0,      3.9134,      0.3917
      13.1,      0.000,      0.000,         0,      3.9968,      0.4000
      13.3,      0.000,      0.000,         0,      4.0803,      0.4083
      13.4,      0.000,      0.000,         0,      4.1634,      0.4167
      13.6,      0.000,      0.000,         0,      4.2468,      0.4250
      13.6,      0.000,      0.000,         0,      4.3301,      0.4333
      13.7,      0.000,      0.000,         0,      4.4135,      0.4417
      13.9,      0.000,      0.000,         0,      4.4968,      0.4500
      14.0,      0.000,      0.000,         0,      4.5801,      0.4583
      14.2,      0.000,      0.000,         0,      4.6635,      0.4667
      14.4,      0.000,      0.000,         0,      4.7467,      0.4750
      14.6,      0.000,      0.000,         0,      4.8301,      0.4833
      14.7,      0.000,      0.000,         0,      4.9134,      0.4917
      14.8,      0.000,      0.000,         0,      4.9968,      0.5000
      14.8,      0.000,      0.000,         0,      5.0800,      0.5083
      15.0,      0.000,      0.000,         0,      5.1635,      0.5167
      15.1,      0.000,      0.000,         0,      5.2468,      0.5250
      15.3,      0.000,      0.000,         0,      5.3300,      0.5333
      15.4,      0.000,      0.000,         0,      5.4135,      0.5417
      15.5,      0.000,      0.000,         0,      5.4969,      0.5500
      15.6,      0.000,      0.000,         0,      5.5800,      0.5583
      15.6,      0.000,      0.000,         0,      5.6634,      0.5667
      15.7,      0.000,      0.000,         0,      5.7468,      0.5750
      15.8,      0.000,      0.000,         0,      5.8302,      0.5833
      15.8,      0.000,      0.000,         0,      5.9134,      0.5917
      16.0,      0.000,      0.000,         0,      5.9968,      0.6000
      16.1,      0.000,      0.000,         0,      6.0802,      0.6083
      16.2,      0.000,      0.000,         0,      6.1633,      0.6167
      16.2,      0.000,      0.000,         0,      6.2467,      0.6250
      16.3,      0.000,      0.000,         0,      6.3301,      0.6333
      16.4,      0.000,      0.000,         0,      6.4135,      0.6417
      16.5,      0.000,      0.000,         0,      6.4964,      0.6500
      16.6,      0.000,      0.000,         0,      6.5801,      0.6583
      16.7,      0.000,      0.000,         0,      6.6634,      0.6667
      16.8,      0.000,      0.000,         0,      6.7468,      0.6750
      16.8,      0.000,      0.000,         0,      6.8299,      0.6833
      16.9,      0.000,      0.000,         0,      6.9133,      0.6917
      17.0,      0.000,      0.000,         0,      6.9967,      0.7000
      17.0,      0.000,      0.000,         0,      7.0800,      0.7083
      17.0,      0.000,      0.000,         0,      7.1634,      0.7167
      17.0,      0.000,      0.000,         0,      7.2467,      0.7250
      17.2,      0.000,      0.000,         0,      7.3300,      0.7333
      17.2,      0.000,      0.000,         0,      7.4134,      0.7417
      17.2,      0.000,      0.000,         0,      7.4967,      0.7500
      17.2,      0.000,      0.000,         0,      7.5797,      0.7583
      17.3,      0.000,      0.000,         0,      7.6633,      0.7667
      17.4,      0.000,      0.000,         0,      7.7466,      0.7750
      17.4,      0.000,      0.000,         0,      7.8300,      0.7833
      17.4,      0.000,      0.000,         0,      7.9132,      0.7917
      17.5,      0.000,      0.000,         0,      7.9967,      0.8000
      17.5,      0.000,      0.000,         0,      8.0799,      0.8083
      17.6,      0.000,      0.000,         0,      8.1634,      0.8167
      17.7,      0.000,      0.000,         0,      8.2465,      0.8250
      17.7,      0.000,      0.000,         0,      8.3300,      0.8333
      17.8,      0.000,      0.000,         0,      8.4134,      0.8417
      17.9,      0.000,      0.000,         0,      8.4965,      0.8500
      18.0,      0.000,      0.000,         0,      8.5800,      0.8583
      18.0,      0.000,      0.000,         0,      8.6632,      0.8667
      18.1,      0.000,      0.000,         0,      8.7467,      0.8750
      18.1,      0.000,      0.000,         0,      8.8299,      0.8833
      18.1,      0.000,      0.000,         0,      8.9130,      0.8917
      18.2,      0.000,      0.000,         0,      8.9967,      0.9000
      18.2,      0.000,      0.000,         0,      9.0801,      0.9083
      18.3,      0.000,      0.000,         0,      9.1632,      0.9167
      18.3,      0.000,      0.000,         0,      9.2467,      0.9250
      18.3,      0.000,      0.000,         0,      9.3300,      0.9333
      18.3,      0.000,      0.000,         0,      9.4133,      0.9417
      18.4,      0.000,      0.000,         0,      9.4965,      0.9500
      18.4,      0.000,      0.000,         0,      9.5798,      0.9583
      18.4,      0.000,      0.000,         0,      9.6634,      0.9667
      18.5,      0.000,      0.000,         0,      9.7465,      0.9750
      18.5,      0.000,      0.000,         0,      9.8299,      0.9833
      18.5,      0.000,      0.000,         0,      9.9133,      0.9917
      18.5,      0.000,      0.000,         0,      9.9966,      1.0000
      18.6,      0.000,      0.000,         0,     10.0799,      1.0083
      18.6,      0.000,      0.000,         0,     10.1634,      1.0167
      18.6,      0.000,      0.000,         0,     10.2464,      1.0250
      18.7,      0.000,      0.000,         0,     10.3299,      1.0333
      18.7,      0.000,      0.000,         0,     10.4134,      1.0417
      18.7,      0.000,      0.000,         0,     10.4966,      1.0500
      18.8,      0.000,      0.000,         0,     10.5798,      1.0583
      18.8,      0.000,      0.000,         0,     10.6633,      1.0667
      18.8,      0.000,      0.000,         0,     10.7467,      1.0750
      18.8,      0.000,      0.000,         0,     10.8299,      1.0833
      18.8,      0.000,      0.000,         0,     10.9133,      1.0917
      18.7,      0.000,      0.000,         0,     10.9966,      1.1000
       0.1,      0.000,      0.000,         0,     11.0800,      1.1083
       0.0,      0.000,      0.000,         0,     11.1630,      1.1167
       0.0,      0.000,      0.000,         0,     11.2465,      1.1250
       0.0,      0.000,      0.000,         0,     11.3299,      1.1333