File: Alban repo/Quiz 1/suction cup instron tests/july-2020-force-vs-viscosity_raw-data/D30E10-01-in10-1-onwhiteplatic-diaphragmpump-10mm-test5.raw
Operator: 1

Date,Time,Specimen#
07/22/20,12:42:51,1

---------------------------------------


Area (mm^2):,      1.00,Flat,     25.40,     25.40,     25.40
Gage Len (mm):,     25.40


LOAD (N),STRAIN 1 (mm),STRAIN 2 (mm),STRESS (MPa),POSITION (mm),TIME (min)
       3.3,      0.000,      0.000,         0,      0.0818,      0.0083
       4.6,      0.000,      0.000,         0,      0.1651,      0.0167
       5.8,      0.000,      0.000,         0,      0.2480,      0.0250
       7.0,      0.000,      0.000,         0,      0.3318,      0.0333
       8.1,      0.000,      0.000,         0,      0.4151,      0.0417
       9.2,      0.000,      0.000,         0,      0.4984,      0.0500
      10.3,      0.000,      0.000,         0,      0.5814,      0.0583
      11.4,      0.000,      0.000,         0,      0.6650,      0.0667
      12.4,      0.000,      0.000,         0,      0.7482,      0.0750
      13.4,      0.000,      0.000,         0,      0.8315,      0.0833
      14.4,      0.000,      0.000,         0,      0.9150,      0.0917
      15.3,      0.000,      0.000,         0,      0.9983,      0.1000
      16.2,      0.000,      0.000,         0,      1.0817,      0.1083
      17.1,      0.000,      0.000,         0,      1.1649,      0.1167
      18.0,      0.000,      0.000,         0,      1.2484,      0.1250
      18.9,      0.000,      0.000,         0,      1.3316,      0.1333
      19.7,      0.000,      0.000,         0,      1.4149,      0.1417
      20.5,      0.000,      0.000,         0,      1.4983,      0.1500
      21.3,      0.000,      0.000,         0,      1.5816,      0.1583
      22.1,      0.000,      0.000,         0,      1.6647,      0.1667
      22.8,      0.000,      0.000,         0,      1.7483,      0.1750
      23.5,      0.000,      0.000,         0,      1.8317,      0.1833
      24.2,      0.000,      0.000,         0,      1.9146,      0.1917
      24.9,      0.000,      0.000,         0,      1.9981,      0.2000
      25.5,      0.000,      0.000,         0,      2.0816,      0.2083
      26.1,      0.000,      0.000,         0,      2.1650,      0.2167
      26.7,      0.000,      0.000,         0,      2.2483,      0.2250
      27.2,      0.000,      0.000,         0,      2.3315,      0.2333
      27.7,      0.000,      0.000,         0,      2.4149,      0.2417
      27.8,      0.000,      0.000,         0,      2.4984,      0.2500
      27.0,      0.000,      0.000,         0,      2.5815,      0.2583
      27.4,      0.000,      0.000,         0,      2.6649,      0.2667
      27.8,      0.000,      0.000,         0,      2.7484,      0.2750
      28.2,      0.000,      0.000,         0,      2.8316,      0.2833
      28.6,      0.000,      0.000,         0,      2.9148,      0.2917
      29.0,      0.000,      0.000,         0,      2.9983,      0.3000
      29.5,      0.000,      0.000,         0,      3.0817,      0.3083
      29.9,      0.000,      0.000,         0,      3.1648,      0.3167
      30.2,      0.000,      0.000,         0,      3.2482,      0.3250
      30.6,      0.000,      0.000,         0,      3.3316,      0.3333
      31.0,      0.000,      0.000,         0,      3.4150,      0.3417
      31.4,      0.000,      0.000,         0,      3.4980,      0.3500
      31.8,      0.000,      0.000,         0,      3.5816,      0.3583
      32.1,      0.000,      0.000,         0,      3.6649,      0.3667
      32.5,      0.000,      0.000,         0,      3.7481,      0.3750
      32.8,      0.000,      0.000,         0,      3.8315,      0.3833
      33.2,      0.000,      0.000,         0,      3.9149,      0.3917
      33.5,      0.000,      0.000,         0,      3.9981,      0.4000
      33.8,      0.000,      0.000,         0,      4.0815,      0.4083
      34.2,      0.000,      0.000,         0,      4.1649,      0.4167
      34.5,      0.000,      0.000,         0,      4.2481,      0.4250
      34.8,      0.000,      0.000,         0,      4.3315,      0.4333
      35.1,      0.000,      0.000,         0,      4.4149,      0.4417
      35.4,      0.000,      0.000,         0,      4.4983,      0.4500
      35.7,      0.000,      0.000,         0,      4.5814,      0.4583
      36.0,      0.000,      0.000,         0,      4.6649,      0.4667
      36.3,      0.000,      0.000,         0,      4.7482,      0.4750
      36.6,      0.000,      0.000,         0,      4.8316,      0.4833
      36.9,      0.000,      0.000,         0,      4.9147,      0.4917
      37.1,      0.000,      0.000,         0,      4.9982,      0.5000
      37.4,      0.000,      0.000,         0,      5.0815,      0.5083
      37.7,      0.000,      0.000,         0,      5.1649,      0.5167
      38.0,      0.000,      0.000,         0,      5.2479,      0.5250
      38.2,      0.000,      0.000,         0,      5.3315,      0.5333
      38.5,      0.000,      0.000,         0,      5.4148,      0.5417
      38.7,      0.000,      0.000,         0,      5.4981,      0.5500
      39.0,      0.000,      0.000,         0,      5.5814,      0.5583
      39.2,      0.000,      0.000,         0,      5.6648,      0.5667
      39.5,      0.000,      0.000,         0,      5.7481,      0.5750
      39.7,      0.000,      0.000,         0,      5.8314,      0.5833
      39.9,      0.000,      0.000,         0,      5.9146,      0.5917
      40.2,      0.000,      0.000,         0,      5.9980,      0.6000
      40.4,      0.000,      0.000,         0,      6.0815,      0.6083
      40.6,      0.000,      0.000,         0,      6.1647,      0.6167
      40.9,      0.000,      0.000,         0,      6.2481,      0.6250
      41.1,      0.000,      0.000,         0,      6.3313,      0.6333
      41.3,      0.000,      0.000,         0,      6.4148,      0.6417
      41.6,      0.000,      0.000,         0,      6.4981,      0.6500
      41.8,      0.000,      0.000,         0,      6.5812,      0.6583
      42.0,      0.000,      0.000,         0,      6.6647,      0.6667
      42.2,      0.000,      0.000,         0,      6.7480,      0.6750
      42.5,      0.000,      0.000,         0,      6.8313,      0.6833
      42.7,      0.000,      0.000,         0,      6.9146,      0.6917
      42.9,      0.000,      0.000,         0,      6.9980,      0.7000
      43.1,      0.000,      0.000,         0,      7.0813,      0.7083
      43.3,      0.000,      0.000,         0,      7.1649,      0.7167
      43.5,      0.000,      0.000,         0,      7.2478,      0.7250
      43.8,      0.000,      0.000,         0,      7.3314,      0.7333
      44.0,      0.000,      0.000,         0,      7.4148,      0.7417
      44.2,      0.000,      0.000,         0,      7.4980,      0.7500
      44.4,      0.000,      0.000,         0,      7.5812,      0.7583
      44.6,      0.000,      0.000,         0,      7.6646,      0.7667
      44.8,      0.000,      0.000,         0,      7.7480,      0.7750
      45.1,      0.000,      0.000,         0,      7.8312,      0.7833
      45.3,      0.000,      0.000,         0,      7.9147,      0.7917
      45.5,      0.000,      0.000,         0,      7.9981,      0.8000
      45.7,      0.000,      0.000,         0,      8.0814,      0.8083
      45.9,      0.000,      0.000,         0,      8.1645,      0.8167
      46.1,      0.000,      0.000,         0,      8.2480,      0.8250
      46.4,      0.000,      0.000,         0,      8.3314,      0.8333
      46.6,      0.000,      0.000,         0,      8.4145,      0.8417
      46.8,      0.000,      0.000,         0,      8.4978,      0.8500
      47.1,      0.000,      0.000,         0,      8.5813,      0.8583
      47.3,      0.000,      0.000,         0,      8.6647,      0.8667
      47.5,      0.000,      0.000,         0,      8.7480,      0.8750
      47.7,      0.000,      0.000,         0,      8.8314,      0.8833
      48.0,      0.000,      0.000,         0,      8.9146,      0.8917
      48.2,      0.000,      0.000,         0,      8.9979,      0.9000
      48.4,      0.000,      0.000,         0,      9.0813,      0.9083
      48.6,      0.000,      0.000,         0,      9.1647,      0.9167
      48.8,      0.000,      0.000,         0,      9.2476,      0.9250
      49.1,      0.000,      0.000,         0,      9.3313,      0.9333
      49.3,      0.000,      0.000,         0,      9.4146,      0.9417
      49.5,      0.000,      0.000,         0,      9.4980,      0.9500
      49.7,      0.000,      0.000,         0,      9.5813,      0.9583
      49.9,      0.000,      0.000,         0,      9.6647,      0.9667
      50.1,      0.000,      0.000,         0,      9.7480,      0.9750
      50.3,      0.000,      0.000,         0,      9.8311,      0.9833
      50.5,      0.000,      0.000,         0,      9.9144,      0.9917
      50.7,      0.000,      0.000,         0,      9.9980,      1.0000
      50.9,      0.000,      0.000,         0,     10.0813,      1.0083
      51.0,      0.000,      0.000,         0,     10.1645,      1.0167
      51.2,      0.000,      0.000,         0,     10.2480,      1.0250
      51.4,      0.000,      0.000,         0,     10.3312,      1.0333
      51.6,      0.000,      0.000,         0,     10.4146,      1.0417
      51.7,      0.000,      0.000,         0,     10.4979,      1.0500
      51.9,      0.000,      0.000,         0,     10.5812,      1.0583
      52.0,      0.000,      0.000,         0,     10.6645,      1.0667
      52.2,      0.000,      0.000,         0,     10.7479,      1.0750
      52.3,      0.000,      0.000,         0,     10.8312,      1.0833
      52.5,      0.000,      0.000,         0,     10.9145,      1.0917
      52.6,      0.000,      0.000,         0,     10.9979,      1.1000
      52.7,      0.000,      0.000,         0,     11.0811,      1.1083
      52.8,      0.000,      0.000,         0,     11.1644,      1.1167
      53.0,      0.000,      0.000,         0,     11.2479,      1.1250
      53.1,      0.000,      0.000,         0,     11.3312,      1.1333
      53.2,      0.000,      0.000,         0,     11.4143,      1.1417
      53.3,      0.000,      0.000,         0,     11.4979,      1.1500
      53.4,      0.000,      0.000,         0,     11.5812,      1.1583
      53.5,      0.000,      0.000,         0,     11.6645,      1.1667
      53.5,      0.000,      0.000,         0,     11.7478,      1.1750
      53.6,      0.000,      0.000,         0,     11.8311,      1.1833
      53.7,      0.000,      0.000,         0,     11.9145,      1.1917
      53.8,      0.000,      0.000,         0,     11.9978,      1.2000
      53.8,      0.000,      0.000,         0,     12.0810,      1.2083
      53.9,      0.000,      0.000,         0,     12.1644,      1.2167
      53.9,      0.000,      0.000,         0,     12.2479,      1.2250
      54.0,      0.000,      0.000,         0,     12.3311,      1.2333
      54.0,      0.000,      0.000,         0,     12.4146,      1.2417
      54.0,      0.000,      0.000,         0,     12.4976,      1.2500
      54.0,      0.000,      0.000,         0,     12.5812,      1.2583
      54.0,      0.000,      0.000,         0,     12.6645,      1.2667
      54.0,      0.000,      0.000,         0,     12.7478,      1.2750
      53.9,      0.000,      0.000,         0,     12.8310,      1.2833
      53.9,      0.000,      0.000,         0,     12.9145,      1.2917
      53.8,      0.000,      0.000,         0,     12.9977,      1.3000
      53.7,      0.000,      0.000,         0,     13.0811,      1.3083
      53.5,      0.000,      0.000,         0,     13.1641,      1.3167
      53.3,      0.000,      0.000,         0,     13.2478,      1.3250
      52.9,      0.000,      0.000,         0,     13.3310,      1.3333
      52.3,      0.000,      0.000,         0,     13.4144,      1.3417
      51.4,      0.000,      0.000,         0,     13.4977,      1.3500
      49.5,      0.000,      0.000,         0,     13.5812,      1.3583
       0.1,      0.000,      0.000,         0,     13.6644,      1.3667
       0.0,      0.000,      0.000,         0,     13.7476,      1.3750
       0.0,      0.000,      0.000,         0,     13.8310,      1.3833
       0.0,      0.000,      0.000,         0,     13.9142,      1.3917