File: Alban repo/Quiz 1/suction cup instron tests/july-2020-force-vs-viscosity_raw-data/D30E10-01-in1-1x10-2-onwhiteplatic-diaphragmpump-10mm-test2.raw
Operator: 1

Date,Time,Specimen#
07/22/20,13:01:13,1

---------------------------------------


Area (mm^2):,      1.00,Flat,     25.40,     25.40,     25.40
Gage Len (mm):,     25.40


LOAD (N),STRAIN 1 (mm),STRAIN 2 (mm),STRESS (MPa),POSITION (mm),TIME (min)
       3.3,      0.000,      0.000,         0,      0.0815,      0.0083
       4.6,      0.000,      0.000,         0,      0.1646,      0.0167
       5.8,      0.000,      0.000,         0,      0.2482,      0.0250
       7.0,      0.000,      0.000,         0,      0.3315,      0.0333
       8.1,      0.000,      0.000,         0,      0.4147,      0.0417
       9.2,      0.000,      0.000,         0,      0.4980,      0.0500
      10.3,      0.000,      0.000,         0,      0.5814,      0.0583
      11.3,      0.000,      0.000,         0,      0.6647,      0.0667
      12.4,      0.000,      0.000,         0,      0.7480,      0.0750
      13.4,      0.000,      0.000,         0,      0.8314,      0.0833
      14.3,      0.000,      0.000,         0,      0.9148,      0.0917
      15.3,      0.000,      0.000,         0,      0.9980,      0.1000
      16.2,      0.000,      0.000,         0,      1.0813,      0.1083
      17.1,      0.000,      0.000,         0,      1.1649,      0.1167
      18.0,      0.000,      0.000,         0,      1.2480,      0.1250
      18.9,      0.000,      0.000,         0,      1.3314,      0.1333
      19.7,      0.000,      0.000,         0,      1.4147,      0.1417
      20.6,      0.000,      0.000,         0,      1.4981,      0.1500
      21.4,      0.000,      0.000,         0,      1.5812,      0.1583
      22.2,      0.000,      0.000,         0,      1.6647,      0.1667
      22.8,      0.000,      0.000,         0,      1.7481,      0.1750
      23.5,      0.000,      0.000,         0,      1.8314,      0.1833
      24.1,      0.000,      0.000,         0,      1.9142,      0.1917
      23.9,      0.000,      0.000,         0,      1.9980,      0.2000
      24.3,      0.000,      0.000,         0,      2.0813,      0.2083
      24.9,      0.000,      0.000,         0,      2.1645,      0.2167
      25.5,      0.000,      0.000,         0,      2.2480,      0.2250
      26.0,      0.000,      0.000,         0,      2.3314,      0.2333
      26.6,      0.000,      0.000,         0,      2.4146,      0.2417
      27.1,      0.000,      0.000,         0,      2.4980,      0.2500
      27.6,      0.000,      0.000,         0,      2.5814,      0.2583
      28.1,      0.000,      0.000,         0,      2.6643,      0.2667
      28.6,      0.000,      0.000,         0,      2.7481,      0.2750
      29.1,      0.000,      0.000,         0,      2.8313,      0.2833
      29.5,      0.000,      0.000,         0,      2.9146,      0.2917
      30.0,      0.000,      0.000,         0,      2.9979,      0.3000
      30.4,      0.000,      0.000,         0,      3.0812,      0.3083
      30.9,      0.000,      0.000,         0,      3.1646,      0.3167
      31.3,      0.000,      0.000,         0,      3.2479,      0.3250
      31.7,      0.000,      0.000,         0,      3.3312,      0.3333
      32.1,      0.000,      0.000,         0,      3.4145,      0.3417
      32.5,      0.000,      0.000,         0,      3.4980,      0.3500
      32.9,      0.000,      0.000,         0,      3.5810,      0.3583
      33.2,      0.000,      0.000,         0,      3.6645,      0.3667
      33.6,      0.000,      0.000,         0,      3.7479,      0.3750
      34.0,      0.000,      0.000,         0,      3.8314,      0.3833
      34.3,      0.000,      0.000,         0,      3.9145,      0.3917
      34.6,      0.000,      0.000,         0,      3.9979,      0.4000
      35.0,      0.000,      0.000,         0,      4.0813,      0.4083
      35.3,      0.000,      0.000,         0,      4.1646,      0.4167
      35.6,      0.000,      0.000,         0,      4.2479,      0.4250
      36.0,      0.000,      0.000,         0,      4.3312,      0.4333
      36.3,      0.000,      0.000,         0,      4.4147,      0.4417
      36.6,      0.000,      0.000,         0,      4.4979,      0.4500
      36.9,      0.000,      0.000,         0,      4.5812,      0.4583
      37.2,      0.000,      0.000,         0,      4.6645,      0.4667
      37.5,      0.000,      0.000,         0,      4.7480,      0.4750
      37.8,      0.000,      0.000,         0,      4.8310,      0.4833
      38.1,      0.000,      0.000,         0,      4.9146,      0.4917
      38.3,      0.000,      0.000,         0,      4.9978,      0.5000
      38.6,      0.000,      0.000,         0,      5.0813,      0.5083
      38.9,      0.000,      0.000,         0,      5.1644,      0.5167
      39.2,      0.000,      0.000,         0,      5.2479,      0.5250
      39.4,      0.000,      0.000,         0,      5.3310,      0.5333
      39.7,      0.000,      0.000,         0,      5.4145,      0.5417
      39.9,      0.000,      0.000,         0,      5.4978,      0.5500
      40.2,      0.000,      0.000,         0,      5.5812,      0.5583
      40.4,      0.000,      0.000,         0,      5.6644,      0.5667
      40.7,      0.000,      0.000,         0,      5.7477,      0.5750
      40.9,      0.000,      0.000,         0,      5.8312,      0.5833
      41.1,      0.000,      0.000,         0,      5.9142,      0.5917
      41.4,      0.000,      0.000,         0,      5.9977,      0.6000
      41.6,      0.000,      0.000,         0,      6.0812,      0.6083
      41.8,      0.000,      0.000,         0,      6.1645,      0.6167
      42.1,      0.000,      0.000,         0,      6.2475,      0.6250
      42.3,      0.000,      0.000,         0,      6.3312,      0.6333
      42.5,      0.000,      0.000,         0,      6.4145,      0.6417
      42.7,      0.000,      0.000,         0,      6.4978,      0.6500
      42.9,      0.000,      0.000,         0,      6.5808,      0.6583
      43.2,      0.000,      0.000,         0,      6.6645,      0.6667
      43.4,      0.000,      0.000,         0,      6.7479,      0.6750
      43.6,      0.000,      0.000,         0,      6.8310,      0.6833
      43.8,      0.000,      0.000,         0,      6.9144,      0.6917
      44.0,      0.000,      0.000,         0,      6.9978,      0.7000
      44.2,      0.000,      0.000,         0,      7.0812,      0.7083
      44.5,      0.000,      0.000,         0,      7.1644,      0.7167
      44.7,      0.000,      0.000,         0,      7.2478,      0.7250
      44.9,      0.000,      0.000,         0,      7.3309,      0.7333
      45.1,      0.000,      0.000,         0,      7.4144,      0.7417
      45.3,      0.000,      0.000,         0,      7.4977,      0.7500
      45.5,      0.000,      0.000,         0,      7.5808,      0.7583
      45.7,      0.000,      0.000,         0,      7.6644,      0.7667
      45.9,      0.000,      0.000,         0,      7.7476,      0.7750
      46.1,      0.000,      0.000,         0,      7.8311,      0.7833
      46.3,      0.000,      0.000,         0,      7.9144,      0.7917
      46.5,      0.000,      0.000,         0,      7.9978,      0.8000
      46.7,      0.000,      0.000,         0,      8.0810,      0.8083
      46.9,      0.000,      0.000,         0,      8.1644,      0.8167
      47.1,      0.000,      0.000,         0,      8.2478,      0.8250
      47.3,      0.000,      0.000,         0,      8.3309,      0.8333
      47.5,      0.000,      0.000,         0,      8.4144,      0.8417
      47.7,      0.000,      0.000,         0,      8.4978,      0.8500
      47.9,      0.000,      0.000,         0,      8.5808,      0.8583
      48.1,      0.000,      0.000,         0,      8.6643,      0.8667
      48.3,      0.000,      0.000,         0,      8.7478,      0.8750
      48.5,      0.000,      0.000,         0,      8.8311,      0.8833
      48.7,      0.000,      0.000,         0,      8.9142,      0.8917
      48.9,      0.000,      0.000,         0,      8.9977,      0.9000
      49.1,      0.000,      0.000,         0,      9.0811,      0.9083
      49.3,      0.000,      0.000,         0,      9.1643,      0.9167
      49.5,      0.000,      0.000,         0,      9.2473,      0.9250
      49.7,      0.000,      0.000,         0,      9.3310,      0.9333
      50.0,      0.000,      0.000,         0,      9.4144,      0.9417
      50.2,      0.000,      0.000,         0,      9.4974,      0.9500
      50.4,      0.000,      0.000,         0,      9.5810,      0.9583
      50.6,      0.000,      0.000,         0,      9.6642,      0.9667
      50.8,      0.000,      0.000,         0,      9.7476,      0.9750
      51.0,      0.000,      0.000,         0,      9.8310,      0.9833
      51.1,      0.000,      0.000,         0,      9.9144,      0.9917
      51.3,      0.000,      0.000,         0,      9.9976,      1.0000
      51.5,      0.000,      0.000,         0,     10.0810,      1.0083
      51.7,      0.000,      0.000,         0,     10.1642,      1.0167
      51.9,      0.000,      0.000,         0,     10.2477,      1.0250
      52.1,      0.000,      0.000,         0,     10.3310,      1.0333
      52.2,      0.000,      0.000,         0,     10.4143,      1.0417
      52.4,      0.000,      0.000,         0,     10.4977,      1.0500
      52.6,      0.000,      0.000,         0,     10.5806,      1.0583
      52.7,      0.000,      0.000,         0,     10.6644,      1.0667
      52.9,      0.000,      0.000,         0,     10.7476,      1.0750
      53.0,      0.000,      0.000,         0,     10.8310,      1.0833
      53.2,      0.000,      0.000,         0,     10.9142,      1.0917
      53.3,      0.000,      0.000,         0,     10.9976,      1.1000
      53.5,      0.000,      0.000,         0,     11.0810,      1.1083
      53.6,      0.000,      0.000,         0,     11.1642,      1.1167
      53.7,      0.000,      0.000,         0,     11.2476,      1.1250
      53.9,      0.000,      0.000,         0,     11.3308,      1.1333
      54.0,      0.000,      0.000,         0,     11.4143,      1.1417
      54.1,      0.000,      0.000,         0,     11.4976,      1.1500
      54.2,      0.000,      0.000,         0,     11.5808,      1.1583
      54.3,      0.000,      0.000,         0,     11.6642,      1.1667
      54.4,      0.000,      0.000,         0,     11.7476,      1.1750
      54.5,      0.000,      0.000,         0,     11.8307,      1.1833
      54.6,      0.000,      0.000,         0,     11.9143,      1.1917
      54.7,      0.000,      0.000,         0,     11.9976,      1.2000
      54.7,      0.000,      0.000,         0,     12.0809,      1.2083
      54.8,      0.000,      0.000,         0,     12.1641,      1.2167
      54.9,      0.000,      0.000,         0,     12.2475,      1.2250
      54.9,      0.000,      0.000,         0,     12.3310,      1.2333
      54.9,      0.000,      0.000,         0,     12.4142,      1.2417
      55.0,      0.000,      0.000,         0,     12.4974,      1.2500
      55.0,      0.000,      0.000,         0,     12.5809,      1.2583
      55.0,      0.000,      0.000,         0,     12.6642,      1.2667
      55.0,      0.000,      0.000,         0,     12.7474,      1.2750
      54.9,      0.000,      0.000,         0,     12.8309,      1.2833
      54.9,      0.000,      0.000,         0,     12.9141,      1.2917
      54.8,      0.000,      0.000,         0,     12.9975,      1.3000
      54.7,      0.000,      0.000,         0,     13.0808,      1.3083
      54.6,      0.000,      0.000,         0,     13.1643,      1.3167
      54.4,      0.000,      0.000,         0,     13.2469,      1.3250
      54.2,      0.000,      0.000,         0,     13.3308,      1.3333
      53.9,      0.000,      0.000,         0,     13.4142,      1.3417
      53.4,      0.000,      0.000,         0,     13.4974,      1.3500
      52.8,      0.000,      0.000,         0,     13.5809,      1.3583
      51.7,      0.000,      0.000,         0,     13.6642,      1.3667
      49.7,      0.000,      0.000,         0,     13.7475,      1.3750
      43.2,      0.000,      0.000,         0,     13.8307,      1.3833
       0.0,      0.000,      0.000,         0,     13.9142,      1.3917
       0.0,      0.000,      0.000,         0,     13.9976,      1.4000
       0.0,      0.000,      0.000,         0,     14.0808,      1.4083