File: Alban repo/Quiz 1/suction cup instron tests/july-2020-force-vs-viscosity_raw-data/D30E10-01-in1-1x10-2-onwhiteplatic-diaphragmpump-10mm-test5.raw
Operator: 1

Date,Time,Specimen#
07/22/20,13:10:00,1

---------------------------------------


Area (mm^2):,      1.00,Flat,     25.40,     25.40,     25.40
Gage Len (mm):,     25.40


LOAD (N),STRAIN 1 (mm),STRAIN 2 (mm),STRESS (MPa),POSITION (mm),TIME (min)
       3.3,      0.000,      0.000,         0,      0.0830,      0.0083
       4.5,      0.000,      0.000,         0,      0.1664,      0.0167
       5.7,      0.000,      0.000,         0,      0.2494,      0.0250
       6.8,      0.000,      0.000,         0,      0.3330,      0.0333
       7.9,      0.000,      0.000,         0,      0.4165,      0.0417
       8.9,      0.000,      0.000,         0,      0.4996,      0.0500
      10.0,      0.000,      0.000,         0,      0.5829,      0.0583
      11.0,      0.000,      0.000,         0,      0.6662,      0.0667
      12.0,      0.000,      0.000,         0,      0.7498,      0.0750
      12.9,      0.000,      0.000,         0,      0.8328,      0.0833
      13.9,      0.000,      0.000,         0,      0.9163,      0.0917
      14.8,      0.000,      0.000,         0,      0.9997,      0.1000
      15.7,      0.000,      0.000,         0,      1.0830,      0.1083
      16.6,      0.000,      0.000,         0,      1.1664,      0.1167
      17.5,      0.000,      0.000,         0,      1.2496,      0.1250
      18.3,      0.000,      0.000,         0,      1.3330,      0.1333
      19.2,      0.000,      0.000,         0,      1.4164,      0.1417
      20.0,      0.000,      0.000,         0,      1.4997,      0.1500
      20.7,      0.000,      0.000,         0,      1.5829,      0.1583
      21.4,      0.000,      0.000,         0,      1.6662,      0.1667
      22.0,      0.000,      0.000,         0,      1.7496,      0.1750
      22.6,      0.000,      0.000,         0,      1.8330,      0.1833
      23.0,      0.000,      0.000,         0,      1.9159,      0.1917
      22.5,      0.000,      0.000,         0,      1.9995,      0.2000
      22.9,      0.000,      0.000,         0,      2.0830,      0.2083
      23.4,      0.000,      0.000,         0,      2.1663,      0.2167
      23.9,      0.000,      0.000,         0,      2.2495,      0.2250
      24.4,      0.000,      0.000,         0,      2.3329,      0.2333
      24.9,      0.000,      0.000,         0,      2.4163,      0.2417
      25.4,      0.000,      0.000,         0,      2.4995,      0.2500
      25.9,      0.000,      0.000,         0,      2.5829,      0.2583
      26.4,      0.000,      0.000,         0,      2.6663,      0.2667
      26.8,      0.000,      0.000,         0,      2.7497,      0.2750
      27.3,      0.000,      0.000,         0,      2.8327,      0.2833
      27.7,      0.000,      0.000,         0,      2.9163,      0.2917
      28.2,      0.000,      0.000,         0,      2.9996,      0.3000
      28.6,      0.000,      0.000,         0,      3.0829,      0.3083
      29.0,      0.000,      0.000,         0,      3.1663,      0.3167
      29.4,      0.000,      0.000,         0,      3.2495,      0.3250
      29.8,      0.000,      0.000,         0,      3.3328,      0.3333
      30.2,      0.000,      0.000,         0,      3.4162,      0.3417
      30.6,      0.000,      0.000,         0,      3.4995,      0.3500
      31.0,      0.000,      0.000,         0,      3.5827,      0.3583
      31.4,      0.000,      0.000,         0,      3.6663,      0.3667
      31.7,      0.000,      0.000,         0,      3.7496,      0.3750
      32.1,      0.000,      0.000,         0,      3.8329,      0.3833
      32.4,      0.000,      0.000,         0,      3.9161,      0.3917
      32.8,      0.000,      0.000,         0,      3.9997,      0.4000
      33.1,      0.000,      0.000,         0,      4.0828,      0.4083
      33.5,      0.000,      0.000,         0,      4.1662,      0.4167
      33.8,      0.000,      0.000,         0,      4.2494,      0.4250
      34.2,      0.000,      0.000,         0,      4.3328,      0.4333
      34.5,      0.000,      0.000,         0,      4.4162,      0.4417
      34.8,      0.000,      0.000,         0,      4.4996,      0.4500
      35.1,      0.000,      0.000,         0,      4.5827,      0.4583
      35.4,      0.000,      0.000,         0,      4.6661,      0.4667
      35.7,      0.000,      0.000,         0,      4.7496,      0.4750
      36.1,      0.000,      0.000,         0,      4.8328,      0.4833
      36.4,      0.000,      0.000,         0,      4.9162,      0.4917
      36.7,      0.000,      0.000,         0,      4.9994,      0.5000
      36.9,      0.000,      0.000,         0,      5.0830,      0.5083
      37.2,      0.000,      0.000,         0,      5.1661,      0.5167
      37.5,      0.000,      0.000,         0,      5.2493,      0.5250
      37.8,      0.000,      0.000,         0,      5.3329,      0.5333
      38.1,      0.000,      0.000,         0,      5.4162,      0.5417
      38.4,      0.000,      0.000,         0,      5.4993,      0.5500
      38.6,      0.000,      0.000,         0,      5.5828,      0.5583
      38.9,      0.000,      0.000,         0,      5.6662,      0.5667
      39.1,      0.000,      0.000,         0,      5.7495,      0.5750
      39.4,      0.000,      0.000,         0,      5.8327,      0.5833
      39.7,      0.000,      0.000,         0,      5.9157,      0.5917
      39.9,      0.000,      0.000,         0,      5.9996,      0.6000
      40.2,      0.000,      0.000,         0,      6.0827,      0.6083
      40.4,      0.000,      0.000,         0,      6.1661,      0.6167
      40.7,      0.000,      0.000,         0,      6.2494,      0.6250
      40.9,      0.000,      0.000,         0,      6.3328,      0.6333
      41.1,      0.000,      0.000,         0,      6.4160,      0.6417
      41.4,      0.000,      0.000,         0,      6.4995,      0.6500
      41.6,      0.000,      0.000,         0,      6.5826,      0.6583
      41.9,      0.000,      0.000,         0,      6.6659,      0.6667
      42.1,      0.000,      0.000,         0,      6.7494,      0.6750
      42.3,      0.000,      0.000,         0,      6.8327,      0.6833
      42.6,      0.000,      0.000,         0,      6.9161,      0.6917
      42.8,      0.000,      0.000,         0,      6.9994,      0.7000
      43.0,      0.000,      0.000,         0,      7.0828,      0.7083
      43.3,      0.000,      0.000,         0,      7.1659,      0.7167
      43.5,      0.000,      0.000,         0,      7.2492,      0.7250
      43.7,      0.000,      0.000,         0,      7.3327,      0.7333
      43.9,      0.000,      0.000,         0,      7.4160,      0.7417
      44.1,      0.000,      0.000,         0,      7.4990,      0.7500
      44.4,      0.000,      0.000,         0,      7.5827,      0.7583
      44.6,      0.000,      0.000,         0,      7.6660,      0.7667
      44.8,      0.000,      0.000,         0,      7.7494,      0.7750
      45.0,      0.000,      0.000,         0,      7.8326,      0.7833
      45.2,      0.000,      0.000,         0,      7.9160,      0.7917
      45.4,      0.000,      0.000,         0,      7.9994,      0.8000
      45.6,      0.000,      0.000,         0,      8.0827,      0.8083
      45.9,      0.000,      0.000,         0,      8.1661,      0.8167
      46.1,      0.000,      0.000,         0,      8.2493,      0.8250
      46.3,      0.000,      0.000,         0,      8.3328,      0.8333
      46.5,      0.000,      0.000,         0,      8.4159,      0.8417
      46.7,      0.000,      0.000,         0,      8.4991,      0.8500
      46.9,      0.000,      0.000,         0,      8.5825,      0.8583
      47.1,      0.000,      0.000,         0,      8.6660,      0.8667
      47.4,      0.000,      0.000,         0,      8.7492,      0.8750
      47.6,      0.000,      0.000,         0,      8.8326,      0.8833
      47.8,      0.000,      0.000,         0,      8.9159,      0.8917
      48.0,      0.000,      0.000,         0,      8.9994,      0.9000
      48.2,      0.000,      0.000,         0,      9.0826,      0.9083
      48.4,      0.000,      0.000,         0,      9.1660,      0.9167
      48.6,      0.000,      0.000,         0,      9.2489,      0.9250
      48.8,      0.000,      0.000,         0,      9.3325,      0.9333
      49.0,      0.000,      0.000,         0,      9.4159,      0.9417
      49.3,      0.000,      0.000,         0,      9.4993,      0.9500
      49.5,      0.000,      0.000,         0,      9.5825,      0.9583
      49.7,      0.000,      0.000,         0,      9.6659,      0.9667
      49.9,      0.000,      0.000,         0,      9.7493,      0.9750
      50.2,      0.000,      0.000,         0,      9.8325,      0.9833
      50.4,      0.000,      0.000,         0,      9.9159,      0.9917
      50.7,      0.000,      0.000,         0,      9.9994,      1.0000
      50.9,      0.000,      0.000,         0,     10.0826,      1.0083
      51.2,      0.000,      0.000,         0,     10.1658,      1.0167
      51.4,      0.000,      0.000,         0,     10.2492,      1.0250
      51.7,      0.000,      0.000,         0,     10.3327,      1.0333
      52.0,      0.000,      0.000,         0,     10.4158,      1.0417
      52.2,      0.000,      0.000,         0,     10.4993,      1.0500
      52.5,      0.000,      0.000,         0,     10.5825,      1.0583
      52.7,      0.000,      0.000,         0,     10.6660,      1.0667
      52.9,      0.000,      0.000,         0,     10.7491,      1.0750
      53.2,      0.000,      0.000,         0,     10.8326,      1.0833
      53.4,      0.000,      0.000,         0,     10.9158,      1.0917
      53.6,      0.000,      0.000,         0,     10.9993,      1.1000
      53.8,      0.000,      0.000,         0,     11.0826,      1.1083
      53.9,      0.000,      0.000,         0,     11.1659,      1.1167
      54.1,      0.000,      0.000,         0,     11.2492,      1.1250
      54.3,      0.000,      0.000,         0,     11.3325,      1.1333
      54.4,      0.000,      0.000,         0,     11.4160,      1.1417
      54.6,      0.000,      0.000,         0,     11.4992,      1.1500
      54.7,      0.000,      0.000,         0,     11.5826,      1.1583
      54.8,      0.000,      0.000,         0,     11.6659,      1.1667
      54.9,      0.000,      0.000,         0,     11.7492,      1.1750
      55.0,      0.000,      0.000,         0,     11.8322,      1.1833
      55.1,      0.000,      0.000,         0,     11.9159,      1.1917
      55.2,      0.000,      0.000,         0,     11.9992,      1.2000
      55.3,      0.000,      0.000,         0,     12.0824,      1.2083
      55.4,      0.000,      0.000,         0,     12.1656,      1.2167
      55.4,      0.000,      0.000,         0,     12.2492,      1.2250
      55.5,      0.000,      0.000,         0,     12.3325,      1.2333
      55.5,      0.000,      0.000,         0,     12.4159,      1.2417
      55.5,      0.000,      0.000,         0,     12.4989,      1.2500
      55.5,      0.000,      0.000,         0,     12.5824,      1.2583
      55.5,      0.000,      0.000,         0,     12.6658,      1.2667
      55.5,      0.000,      0.000,         0,     12.7491,      1.2750
      55.5,      0.000,      0.000,         0,     12.8325,      1.2833
      55.5,      0.000,      0.000,         0,     12.9157,      1.2917
      55.4,      0.000,      0.000,         0,     12.9991,      1.3000
      55.3,      0.000,      0.000,         0,     13.0825,      1.3083
      55.2,      0.000,      0.000,         0,     13.1655,      1.3167
      55.0,      0.000,      0.000,         0,     13.2490,      1.3250
      54.8,      0.000,      0.000,         0,     13.3324,      1.3333
      54.6,      0.000,      0.000,         0,     13.4156,      1.3417
      54.2,      0.000,      0.000,         0,     13.4991,      1.3500
      53.6,      0.000,      0.000,         0,     13.5827,      1.3583
      52.7,      0.000,      0.000,         0,     13.6658,      1.3667
      51.1,      0.000,      0.000,         0,     13.7491,      1.3750
      47.2,      0.000,      0.000,         0,     13.8324,      1.3833
       0.0,      0.000,      0.000,         0,     13.9158,      1.3917
       0.0,      0.000,      0.000,         0,     13.9990,      1.4000
       0.0,      0.000,      0.000,         0,     14.0825,      1.4083
       0.0,      0.000,      0.000,         0,     14.1656,      1.4167
       0.0,      0.000,      0.000,         0,     14.2491,      1.4250
       0.0,      0.000,      0.000,         0,     14.3324,      1.4333
       0.0,      0.000,      0.000,         0,     14.4158,      1.4417