File: Alban repo/Quiz 1/suction cup instron tests/july-2020-force-vs-viscosity_raw-data/D30E10-01-inglycerol-onwhiteplatic-diaphragmpump-10mm-test1.raw
Operator: 1

Date,Time,Specimen#
07/22/20,12:01:22,1

---------------------------------------


Area (mm^2):,      1.00,Flat,     25.40,     25.40,     25.40
Gage Len (mm):,     25.40


LOAD (N),STRAIN 1 (mm),STRAIN 2 (mm),STRESS (MPa),POSITION (mm),TIME (min)
       3.1,      0.000,      0.000,         0,      0.0807,      0.0083
       4.3,      0.000,      0.000,         0,      0.1640,      0.0167
       5.4,      0.000,      0.000,         0,      0.2474,      0.0250
       6.4,      0.000,      0.000,         0,      0.3308,      0.0333
       7.4,      0.000,      0.000,         0,      0.4140,      0.0417
       8.4,      0.000,      0.000,         0,      0.4974,      0.0500
       9.3,      0.000,      0.000,         0,      0.5806,      0.0583
      10.2,      0.000,      0.000,         0,      0.6640,      0.0667
      11.1,      0.000,      0.000,         0,      0.7474,      0.0750
      12.0,      0.000,      0.000,         0,      0.8309,      0.0833
      12.8,      0.000,      0.000,         0,      0.9134,      0.0917
      13.7,      0.000,      0.000,         0,      0.9975,      0.1000
      14.5,      0.000,      0.000,         0,      1.0807,      0.1083
      15.3,      0.000,      0.000,         0,      1.1640,      0.1167
      16.1,      0.000,      0.000,         0,      1.2473,      0.1250
      16.8,      0.000,      0.000,         0,      1.3307,      0.1333
      17.6,      0.000,      0.000,         0,      1.4141,      0.1417
      18.3,      0.000,      0.000,         0,      1.4973,      0.1500
      19.0,      0.000,      0.000,         0,      1.5805,      0.1583
      19.7,      0.000,      0.000,         0,      1.6641,      0.1667
      20.4,      0.000,      0.000,         0,      1.7473,      0.1750
      21.1,      0.000,      0.000,         0,      1.8305,      0.1833
      21.7,      0.000,      0.000,         0,      1.9142,      0.1917
      22.3,      0.000,      0.000,         0,      1.9973,      0.2000
      23.0,      0.000,      0.000,         0,      2.0806,      0.2083
      23.5,      0.000,      0.000,         0,      2.1641,      0.2167
      24.1,      0.000,      0.000,         0,      2.2474,      0.2250
      24.6,      0.000,      0.000,         0,      2.3307,      0.2333
      25.1,      0.000,      0.000,         0,      2.4141,      0.2417
      25.6,      0.000,      0.000,         0,      2.4971,      0.2500
      26.0,      0.000,      0.000,         0,      2.5806,      0.2583
      26.4,      0.000,      0.000,         0,      2.6638,      0.2667
      26.7,      0.000,      0.000,         0,      2.7473,      0.2750
      27.0,      0.000,      0.000,         0,      2.8308,      0.2833
      27.3,      0.000,      0.000,         0,      2.9137,      0.2917
      26.9,      0.000,      0.000,         0,      2.9974,      0.3000
      26.8,      0.000,      0.000,         0,      3.0806,      0.3083
      27.1,      0.000,      0.000,         0,      3.1639,      0.3167
      27.4,      0.000,      0.000,         0,      3.2472,      0.3250
      27.8,      0.000,      0.000,         0,      3.3307,      0.3333
      28.1,      0.000,      0.000,         0,      3.4140,      0.3417
      28.5,      0.000,      0.000,         0,      3.4971,      0.3500
      28.8,      0.000,      0.000,         0,      3.5806,      0.3583
      29.1,      0.000,      0.000,         0,      3.6640,      0.3667
      29.4,      0.000,      0.000,         0,      3.7473,      0.3750
      29.7,      0.000,      0.000,         0,      3.8307,      0.3833
      30.1,      0.000,      0.000,         0,      3.9139,      0.3917
      30.4,      0.000,      0.000,         0,      3.9973,      0.4000
      30.7,      0.000,      0.000,         0,      4.0807,      0.4083
      31.0,      0.000,      0.000,         0,      4.1639,      0.4167
      31.3,      0.000,      0.000,         0,      4.2472,      0.4250
      31.5,      0.000,      0.000,         0,      4.3306,      0.4333
      31.8,      0.000,      0.000,         0,      4.4139,      0.4417
      32.1,      0.000,      0.000,         0,      4.4971,      0.4500
      32.4,      0.000,      0.000,         0,      4.5806,      0.4583
      32.6,      0.000,      0.000,         0,      4.6640,      0.4667
      32.9,      0.000,      0.000,         0,      4.7472,      0.4750
      33.1,      0.000,      0.000,         0,      4.8304,      0.4833
      33.4,      0.000,      0.000,         0,      4.9138,      0.4917
      33.7,      0.000,      0.000,         0,      4.9973,      0.5000
      33.9,      0.000,      0.000,         0,      5.0803,      0.5083
      34.2,      0.000,      0.000,         0,      5.1639,      0.5167
      34.4,      0.000,      0.000,         0,      5.2472,      0.5250
      34.6,      0.000,      0.000,         0,      5.3306,      0.5333
      34.9,      0.000,      0.000,         0,      5.4139,      0.5417
      35.1,      0.000,      0.000,         0,      5.4973,      0.5500
      35.4,      0.000,      0.000,         0,      5.5805,      0.5583
      35.6,      0.000,      0.000,         0,      5.6640,      0.5667
      35.8,      0.000,      0.000,         0,      5.7472,      0.5750
      36.1,      0.000,      0.000,         0,      5.8305,      0.5833
      36.3,      0.000,      0.000,         0,      5.9138,      0.5917
      36.5,      0.000,      0.000,         0,      5.9972,      0.6000
      36.8,      0.000,      0.000,         0,      6.0806,      0.6083
      37.0,      0.000,      0.000,         0,      6.1637,      0.6167
      37.2,      0.000,      0.000,         0,      6.2472,      0.6250
      37.4,      0.000,      0.000,         0,      6.3305,      0.6333
      37.6,      0.000,      0.000,         0,      6.4139,      0.6417
      37.8,      0.000,      0.000,         0,      6.4969,      0.6500
      38.0,      0.000,      0.000,         0,      6.5805,      0.6583
      38.2,      0.000,      0.000,         0,      6.6638,      0.6667
      38.4,      0.000,      0.000,         0,      6.7470,      0.6750
      38.7,      0.000,      0.000,         0,      6.8302,      0.6833
      38.9,      0.000,      0.000,         0,      6.9138,      0.6917
      39.1,      0.000,      0.000,         0,      6.9972,      0.7000
      39.3,      0.000,      0.000,         0,      7.0803,      0.7083
      39.5,      0.000,      0.000,         0,      7.1637,      0.7167
      39.7,      0.000,      0.000,         0,      7.2472,      0.7250
      39.9,      0.000,      0.000,         0,      7.3305,      0.7333
      40.1,      0.000,      0.000,         0,      7.4137,      0.7417
      40.3,      0.000,      0.000,         0,      7.4971,      0.7500
      40.5,      0.000,      0.000,         0,      7.5804,      0.7583
      40.7,      0.000,      0.000,         0,      7.6638,      0.7667
      40.9,      0.000,      0.000,         0,      7.7471,      0.7750
      41.1,      0.000,      0.000,         0,      7.8304,      0.7833
      41.3,      0.000,      0.000,         0,      7.9136,      0.7917
      41.5,      0.000,      0.000,         0,      7.9970,      0.8000
      41.7,      0.000,      0.000,         0,      8.0805,      0.8083
      41.9,      0.000,      0.000,         0,      8.1633,      0.8167
      42.0,      0.000,      0.000,         0,      8.2471,      0.8250
      42.2,      0.000,      0.000,         0,      8.3304,      0.8333
      42.4,      0.000,      0.000,         0,      8.4138,      0.8417
      42.6,      0.000,      0.000,         0,      8.4970,      0.8500
      42.8,      0.000,      0.000,         0,      8.5803,      0.8583
      42.9,      0.000,      0.000,         0,      8.6637,      0.8667
      43.1,      0.000,      0.000,         0,      8.7472,      0.8750
      43.3,      0.000,      0.000,         0,      8.8299,      0.8833
      43.4,      0.000,      0.000,         0,      8.9136,      0.8917
      43.6,      0.000,      0.000,         0,      8.9971,      0.9000
      43.7,      0.000,      0.000,         0,      9.0804,      0.9083
      43.8,      0.000,      0.000,         0,      9.1637,      0.9167
      44.0,      0.000,      0.000,         0,      9.2470,      0.9250
      44.1,      0.000,      0.000,         0,      9.3304,      0.9333
      44.3,      0.000,      0.000,         0,      9.4135,      0.9417
      44.5,      0.000,      0.000,         0,      9.4970,      0.9500
      44.6,      0.000,      0.000,         0,      9.5804,      0.9583
      44.7,      0.000,      0.000,         0,      9.6638,      0.9667
      44.9,      0.000,      0.000,         0,      9.7469,      0.9750
      45.0,      0.000,      0.000,         0,      9.8304,      0.9833
      45.2,      0.000,      0.000,         0,      9.9137,      0.9917
      45.3,      0.000,      0.000,         0,      9.9968,      1.0000
      45.4,      0.000,      0.000,         0,     10.0801,      1.0083
      45.6,      0.000,      0.000,         0,     10.1638,      1.0167
      45.7,      0.000,      0.000,         0,     10.2470,      1.0250
      45.8,      0.000,      0.000,         0,     10.3302,      1.0333
      45.9,      0.000,      0.000,         0,     10.4137,      1.0417
      46.0,      0.000,      0.000,         0,     10.4970,      1.0500
      46.1,      0.000,      0.000,         0,     10.5803,      1.0583
      46.2,      0.000,      0.000,         0,     10.6636,      1.0667
      46.3,      0.000,      0.000,         0,     10.7468,      1.0750
      46.4,      0.000,      0.000,         0,     10.8298,      1.0833
      46.5,      0.000,      0.000,         0,     10.9136,      1.0917
      46.6,      0.000,      0.000,         0,     10.9970,      1.1000
      46.7,      0.000,      0.000,         0,     11.0803,      1.1083
      46.8,      0.000,      0.000,         0,     11.1635,      1.1167
      46.8,      0.000,      0.000,         0,     11.2470,      1.1250
      46.9,      0.000,      0.000,         0,     11.3303,      1.1333
      47.0,      0.000,      0.000,         0,     11.4135,      1.1417
      47.0,      0.000,      0.000,         0,     11.4968,      1.1500
      47.1,      0.000,      0.000,         0,     11.5802,      1.1583
      47.1,      0.000,      0.000,         0,     11.6636,      1.1667
      47.1,      0.000,      0.000,         0,     11.7468,      1.1750
      47.1,      0.000,      0.000,         0,     11.8303,      1.1833
      47.1,      0.000,      0.000,         0,     11.9135,      1.1917
      47.1,      0.000,      0.000,         0,     11.9970,      1.2000
      47.0,      0.000,      0.000,         0,     12.0802,      1.2083
      47.0,      0.000,      0.000,         0,     12.1632,      1.2167
      46.9,      0.000,      0.000,         0,     12.2470,      1.2250
      46.7,      0.000,      0.000,         0,     12.3302,      1.2333
      46.5,      0.000,      0.000,         0,     12.4134,      1.2417
      46.2,      0.000,      0.000,         0,     12.4969,      1.2500
      45.7,      0.000,      0.000,         0,     12.5803,      1.2583
       0.1,      0.000,      0.000,         0,     12.6634,      1.2667
       0.0,      0.000,      0.000,         0,     12.7468,      1.2750
       0.0,      0.000,      0.000,         0,     12.8302,      1.2833
       0.0,      0.000,      0.000,         0,     12.9137,      1.2917
       0.0,      0.000,      0.000,         0,     12.9968,      1.3000