File: Alban repo/Quiz 1/suction cup instron tests/july-2020-force-vs-viscosity_raw-data/D30E10-01-inwater-onwhiteplatic-diaphragmpump-10mm-test1.raw
Operator: 1

Date,Time,Specimen#
07/22/20,13:59:46,1

---------------------------------------


Area (mm^2):,      1.00,Flat,     25.40,     25.40,     25.40
Gage Len (mm):,     25.40


LOAD (N),STRAIN 1 (mm),STRAIN 2 (mm),STRESS (MPa),POSITION (mm),TIME (min)
       3.1,      0.000,      0.000,         0,      0.0817,      0.0083
       4.2,      0.000,      0.000,         0,      0.1650,      0.0167
       5.3,      0.000,      0.000,         0,      0.2481,      0.0250
       6.3,      0.000,      0.000,         0,      0.3316,      0.0333
       7.3,      0.000,      0.000,         0,      0.4149,      0.0417
       8.2,      0.000,      0.000,         0,      0.4982,      0.0500
       9.1,      0.000,      0.000,         0,      0.5815,      0.0583
      10.0,      0.000,      0.000,         0,      0.6650,      0.0667
      10.9,      0.000,      0.000,         0,      0.7482,      0.0750
      11.7,      0.000,      0.000,         0,      0.8315,      0.0833
      12.5,      0.000,      0.000,         0,      0.9147,      0.0917
      13.3,      0.000,      0.000,         0,      0.9983,      0.1000
      14.0,      0.000,      0.000,         0,      1.0815,      0.1083
      14.6,      0.000,      0.000,         0,      1.1650,      0.1167
      15.2,      0.000,      0.000,         0,      1.2482,      0.1250
      15.7,      0.000,      0.000,         0,      1.3314,      0.1333
      15.4,      0.000,      0.000,         0,      1.4149,      0.1417
      15.8,      0.000,      0.000,         0,      1.4982,      0.1500
      16.2,      0.000,      0.000,         0,      1.5815,      0.1583
      16.6,      0.000,      0.000,         0,      1.6648,      0.1667
      17.1,      0.000,      0.000,         0,      1.7484,      0.1750
      17.5,      0.000,      0.000,         0,      1.8316,      0.1833
      17.9,      0.000,      0.000,         0,      1.9146,      0.1917
      18.3,      0.000,      0.000,         0,      1.9980,      0.2000
      18.7,      0.000,      0.000,         0,      2.0815,      0.2083
      19.1,      0.000,      0.000,         0,      2.1649,      0.2167
      19.5,      0.000,      0.000,         0,      2.2481,      0.2250
      19.8,      0.000,      0.000,         0,      2.3315,      0.2333
      20.2,      0.000,      0.000,         0,      2.4150,      0.2417
      20.6,      0.000,      0.000,         0,      2.4982,      0.2500
      20.9,      0.000,      0.000,         0,      2.5814,      0.2583
      21.3,      0.000,      0.000,         0,      2.6649,      0.2667
      21.6,      0.000,      0.000,         0,      2.7481,      0.2750
      21.9,      0.000,      0.000,         0,      2.8315,      0.2833
      22.3,      0.000,      0.000,         0,      2.9149,      0.2917
      22.6,      0.000,      0.000,         0,      2.9981,      0.3000
      22.9,      0.000,      0.000,         0,      3.0815,      0.3083
      23.2,      0.000,      0.000,         0,      3.1648,      0.3167
      23.4,      0.000,      0.000,         0,      3.2481,      0.3250
      23.7,      0.000,      0.000,         0,      3.3313,      0.3333
      24.0,      0.000,      0.000,         0,      3.4149,      0.3417
      24.3,      0.000,      0.000,         0,      3.4980,      0.3500
      24.6,      0.000,      0.000,         0,      3.5813,      0.3583
      24.9,      0.000,      0.000,         0,      3.6647,      0.3667
      25.1,      0.000,      0.000,         0,      3.7482,      0.3750
      25.4,      0.000,      0.000,         0,      3.8314,      0.3833
      25.7,      0.000,      0.000,         0,      3.9148,      0.3917
      26.0,      0.000,      0.000,         0,      3.9981,      0.4000
      26.2,      0.000,      0.000,         0,      4.0815,      0.4083
      26.5,      0.000,      0.000,         0,      4.1646,      0.4167
      26.8,      0.000,      0.000,         0,      4.2480,      0.4250
      27.0,      0.000,      0.000,         0,      4.3315,      0.4333
      27.3,      0.000,      0.000,         0,      4.4148,      0.4417
      27.5,      0.000,      0.000,         0,      4.4982,      0.4500
      27.8,      0.000,      0.000,         0,      4.5813,      0.4583
      28.1,      0.000,      0.000,         0,      4.6647,      0.4667
      28.3,      0.000,      0.000,         0,      4.7481,      0.4750
      28.6,      0.000,      0.000,         0,      4.8314,      0.4833
      28.8,      0.000,      0.000,         0,      4.9147,      0.4917
      29.0,      0.000,      0.000,         0,      4.9982,      0.5000
      29.3,      0.000,      0.000,         0,      5.0815,      0.5083
      29.5,      0.000,      0.000,         0,      5.1648,      0.5167
      29.8,      0.000,      0.000,         0,      5.2479,      0.5250
      30.0,      0.000,      0.000,         0,      5.3314,      0.5333
      30.3,      0.000,      0.000,         0,      5.4147,      0.5417
      30.5,      0.000,      0.000,         0,      5.4979,      0.5500
      30.7,      0.000,      0.000,         0,      5.5814,      0.5583
      31.0,      0.000,      0.000,         0,      5.6647,      0.5667
      31.2,      0.000,      0.000,         0,      5.7480,      0.5750
      31.4,      0.000,      0.000,         0,      5.8314,      0.5833
      31.7,      0.000,      0.000,         0,      5.9145,      0.5917
      31.9,      0.000,      0.000,         0,      5.9981,      0.6000
      32.1,      0.000,      0.000,         0,      6.0814,      0.6083
      32.3,      0.000,      0.000,         0,      6.1646,      0.6167
      32.6,      0.000,      0.000,         0,      6.2480,      0.6250
      32.8,      0.000,      0.000,         0,      6.3313,      0.6333
      33.0,      0.000,      0.000,         0,      6.4147,      0.6417
      33.2,      0.000,      0.000,         0,      6.4980,      0.6500
      33.4,      0.000,      0.000,         0,      6.5812,      0.6583
      33.6,      0.000,      0.000,         0,      6.6648,      0.6667
      33.9,      0.000,      0.000,         0,      6.7480,      0.6750
      34.1,      0.000,      0.000,         0,      6.8313,      0.6833
      34.3,      0.000,      0.000,         0,      6.9147,      0.6917
      34.5,      0.000,      0.000,         0,      6.9981,      0.7000
      34.7,      0.000,      0.000,         0,      7.0812,      0.7083
      34.9,      0.000,      0.000,         0,      7.1647,      0.7167
      35.1,      0.000,      0.000,         0,      7.2478,      0.7250
      35.3,      0.000,      0.000,         0,      7.3313,      0.7333
      35.5,      0.000,      0.000,         0,      7.4146,      0.7417
      35.7,      0.000,      0.000,         0,      7.4978,      0.7500
      35.9,      0.000,      0.000,         0,      7.5810,      0.7583
      36.1,      0.000,      0.000,         0,      7.6647,      0.7667
      36.3,      0.000,      0.000,         0,      7.7480,      0.7750
      36.5,      0.000,      0.000,         0,      7.8312,      0.7833
      36.7,      0.000,      0.000,         0,      7.9146,      0.7917
      36.9,      0.000,      0.000,         0,      7.9980,      0.8000
      37.1,      0.000,      0.000,         0,      8.0813,      0.8083
      37.3,      0.000,      0.000,         0,      8.1646,      0.8167
      37.5,      0.000,      0.000,         0,      8.2480,      0.8250
      37.6,      0.000,      0.000,         0,      8.3313,      0.8333
      37.8,      0.000,      0.000,         0,      8.4145,      0.8417
      38.0,      0.000,      0.000,         0,      8.4976,      0.8500
      38.2,      0.000,      0.000,         0,      8.5812,      0.8583
      38.4,      0.000,      0.000,         0,      8.6644,      0.8667
      38.6,      0.000,      0.000,         0,      8.7478,      0.8750
      38.7,      0.000,      0.000,         0,      8.8311,      0.8833
      38.9,      0.000,      0.000,         0,      8.9146,      0.8917
      39.1,      0.000,      0.000,         0,      8.9979,      0.9000
      39.3,      0.000,      0.000,         0,      9.0813,      0.9083
      39.5,      0.000,      0.000,         0,      9.1646,      0.9167
      39.6,      0.000,      0.000,         0,      9.2476,      0.9250
      39.8,      0.000,      0.000,         0,      9.3312,      0.9333
      40.0,      0.000,      0.000,         0,      9.4146,      0.9417
      40.2,      0.000,      0.000,         0,      9.4978,      0.9500
      40.3,      0.000,      0.000,         0,      9.5812,      0.9583
      40.5,      0.000,      0.000,         0,      9.6646,      0.9667
      40.7,      0.000,      0.000,         0,      9.7479,      0.9750
      40.9,      0.000,      0.000,         0,      9.8311,      0.9833
      41.0,      0.000,      0.000,         0,      9.9144,      0.9917
      41.2,      0.000,      0.000,         0,      9.9979,      1.0000
      41.4,      0.000,      0.000,         0,     10.0812,      1.0083
      41.5,      0.000,      0.000,         0,     10.1644,      1.0167
      41.7,      0.000,      0.000,         0,     10.2480,      1.0250
      41.9,      0.000,      0.000,         0,     10.3311,      1.0333
      42.0,      0.000,      0.000,         0,     10.4144,      1.0417
      42.2,      0.000,      0.000,         0,     10.4978,      1.0500
      42.3,      0.000,      0.000,         0,     10.5812,      1.0583
      42.5,      0.000,      0.000,         0,     10.6644,      1.0667
      42.6,      0.000,      0.000,         0,     10.7479,      1.0750
      42.7,      0.000,      0.000,         0,     10.8311,      1.0833
      42.9,      0.000,      0.000,         0,     10.9144,      1.0917
      43.0,      0.000,      0.000,         0,     10.9978,      1.1000
      43.1,      0.000,      0.000,         0,     11.0811,      1.1083
      43.2,      0.000,      0.000,         0,     11.1644,      1.1167
      43.3,      0.000,      0.000,         0,     11.2478,      1.1250
      43.4,      0.000,      0.000,         0,     11.3312,      1.1333
      43.5,      0.000,      0.000,         0,     11.4145,      1.1417
      43.5,      0.000,      0.000,         0,     11.4978,      1.1500
      43.6,      0.000,      0.000,         0,     11.5811,      1.1583
      43.6,      0.000,      0.000,         0,     11.6644,      1.1667
      43.7,      0.000,      0.000,         0,     11.7476,      1.1750
      43.7,      0.000,      0.000,         0,     11.8309,      1.1833
      43.7,      0.000,      0.000,         0,     11.9143,      1.1917
      43.8,      0.000,      0.000,         0,     11.9977,      1.2000
      43.8,      0.000,      0.000,         0,     12.0807,      1.2083
      43.8,      0.000,      0.000,         0,     12.1645,      1.2167
      43.7,      0.000,      0.000,         0,     12.2477,      1.2250
      43.7,      0.000,      0.000,         0,     12.3312,      1.2333
      43.7,      0.000,      0.000,         0,     12.4145,      1.2417
      43.6,      0.000,      0.000,         0,     12.4976,      1.2500
      43.6,      0.000,      0.000,         0,     12.5811,      1.2583
      43.5,      0.000,      0.000,         0,     12.6644,      1.2667
      43.3,      0.000,      0.000,         0,     12.7477,      1.2750
      43.2,      0.000,      0.000,         0,     12.8310,      1.2833
      43.1,      0.000,      0.000,         0,     12.9145,      1.2917
      42.9,      0.000,      0.000,         0,     12.9978,      1.3000
      42.8,      0.000,      0.000,         0,     13.0809,      1.3083
      42.5,      0.000,      0.000,         0,     13.1640,      1.3167
      42.3,      0.000,      0.000,         0,     13.2477,      1.3250
      42.0,      0.000,      0.000,         0,     13.3311,      1.3333
      41.6,      0.000,      0.000,         0,     13.4143,      1.3417
      41.0,      0.000,      0.000,         0,     13.4976,      1.3500
      40.1,      0.000,      0.000,         0,     13.5811,      1.3583
       0.0,      0.000,      0.000,         0,     13.6644,      1.3667
       0.0,      0.000,      0.000,         0,     13.7476,      1.3750
       0.0,      0.000,      0.000,         0,     13.8309,      1.3833
       0.0,      0.000,      0.000,         0,     13.9142,      1.3917
       0.0,      0.000,      0.000,         0,     13.9977,      1.4000