File: Alban repo/Quiz 1/suction cup instron tests/july-2020-force-vs-viscosity_raw-data/D30E10-01-inglycerol-onwhiteplatic-diaphragmpump-10mm-test3.raw
Operator: 1

Date,Time,Specimen#
07/22/20,12:08:31,1

---------------------------------------


Area (mm^2):,      1.00,Flat,     25.40,     25.40,     25.40
Gage Len (mm):,     25.40


LOAD (N),STRAIN 1 (mm),STRAIN 2 (mm),STRESS (MPa),POSITION (mm),TIME (min)
       1.8,      0.000,      0.000,         0,     -0.1621,      0.0083
       1.8,      0.000,      0.000,         0,     -0.3286,      0.0167
       1.9,      0.000,      0.000,         0,     -0.4953,      0.0250
       1.7,      0.000,      0.000,         0,     -0.6620,      0.0333
       1.7,      0.000,      0.000,         0,     -0.8286,      0.0417
       1.9,      0.000,      0.000,         0,     -0.9953,      0.0500
       2.0,      0.000,      0.000,         0,     -1.1621,      0.0583
       2.0,      0.000,      0.000,         0,     -1.3287,      0.0667
       1.9,      0.000,      0.000,         0,     -1.4954,      0.0750
       1.9,      0.000,      0.000,         0,     -1.6619,      0.0833
       1.9,      0.000,      0.000,         0,     -1.8287,      0.0917
       1.8,      0.000,      0.000,         0,     -1.9953,      0.1000
       1.8,      0.000,      0.000,         0,     -2.1619,      0.1083
       1.6,      0.000,      0.000,         0,     -2.3287,      0.1167
       1.5,      0.000,      0.000,         0,     -2.4952,      0.1250
       1.3,      0.000,      0.000,         0,     -2.6620,      0.1333
       1.0,      0.000,      0.000,         0,     -2.8287,      0.1417
       0.8,      0.000,      0.000,         0,     -2.9952,      0.1500
       0.4,      0.000,      0.000,         0,     -3.1621,      0.1583
       0.0,      0.000,      0.000,         0,     -3.3284,      0.1667
      -0.5,      0.000,      0.000,         0,     -3.4954,      0.1750
      -1.0,      0.000,      0.000,         0,     -3.6619,      0.1833
      -1.5,      0.000,      0.000,         0,     -3.8286,      0.1917
      -1.9,      0.000,      0.000,         0,     -3.9952,      0.2000
      -2.3,      0.000,      0.000,         0,     -4.1619,      0.2083
      -2.8,      0.000,      0.000,         0,     -4.3286,      0.2167
      -3.4,      0.000,      0.000,         0,     -4.4953,      0.2250
      -4.7,      0.000,      0.000,         0,     -4.6619,      0.2333
      -5.1,      0.000,      0.000,         0,     -4.8286,      0.2417
      -4.9,      0.000,      0.000,         0,     -4.9951,      0.2500
      -5.1,      0.000,      0.000,         0,     -5.1618,      0.2583
      -5.3,      0.000,      0.000,         0,     -5.3284,      0.2667
      -5.1,      0.000,      0.000,         0,     -5.4951,      0.2750
      -5.0,      0.000,      0.000,         0,     -5.6618,      0.2833
      -6.1,      0.000,      0.000,         0,     -5.8285,      0.2917
      -6.4,      0.000,      0.000,         0,     -5.9951,      0.3000
      -6.6,      0.000,      0.000,         0,     -6.1620,      0.3083
      -6.9,      0.000,      0.000,         0,     -6.3285,      0.3167
      -7.0,      0.000,      0.000,         0,     -6.4952,      0.3250
      -7.3,      0.000,      0.000,         0,     -6.6617,      0.3333
      -7.4,      0.000,      0.000,         0,     -6.8284,      0.3417
      -7.5,      0.000,      0.000,         0,     -6.9952,      0.3500
      -7.4,      0.000,      0.000,         0,     -7.1617,      0.3583
      -7.5,      0.000,      0.000,         0,     -7.3284,      0.3667
      -7.6,      0.000,      0.000,         0,     -7.4952,      0.3750
      -7.8,      0.000,      0.000,         0,     -7.6617,      0.3833
      -8.0,      0.000,      0.000,         0,     -7.8285,      0.3917
      -8.3,      0.000,      0.000,         0,     -7.9949,      0.4000
      -8.3,      0.000,      0.000,         0,     -8.1618,      0.4083
      -8.5,      0.000,      0.000,         0,     -8.3284,      0.4167
      -8.8,      0.000,      0.000,         0,     -8.4951,      0.4250
      -9.4,      0.000,      0.000,         0,     -8.6617,      0.4333
      -9.4,      0.000,      0.000,         0,     -8.8284,      0.4417
      -9.3,      0.000,      0.000,         0,     -8.9950,      0.4500
      -9.6,      0.000,      0.000,         0,     -9.1617,      0.4583
      -9.5,      0.000,      0.000,         0,     -9.3282,      0.4667
      -9.8,      0.000,      0.000,         0,     -9.4950,      0.4750
     -10.1,      0.000,      0.000,         0,     -9.6616,      0.4833
     -10.7,      0.000,      0.000,         0,     -9.8283,      0.4917
     -11.0,      0.000,      0.000,         0,     -9.9949,      0.5000
     -11.3,      0.000,      0.000,         0,    -10.1615,      0.5083
     -11.6,      0.000,      0.000,         0,    -10.3283,      0.5167
     -11.8,      0.000,      0.000,         0,    -10.4950,      0.5250
     -12.2,      0.000,      0.000,         0,    -10.6614,      0.5333
     -12.5,      0.000,      0.000,         0,    -10.8283,      0.5417
     -13.0,      0.000,      0.000,         0,    -10.9950,      0.5500
     -13.5,      0.000,      0.000,         0,    -11.1617,      0.5583
     -14.3,      0.000,      0.000,         0,    -11.3282,      0.5667
     -16.7,      0.000,      0.000,         0,    -11.6617,      0.5886
     -16.5,      0.000,      0.000,         0,    -11.7490,      0.6053
     -14.7,      0.000,      0.000,         0,    -11.7801,      0.6219
     -14.4,      0.000,      0.000,         0,    -11.7947,      0.6386
     -14.1,      0.000,      0.000,         0,    -11.7950,      0.6553
     -13.8,      0.000,      0.000,         0,    -11.7950,      0.6719
     -13.5,      0.000,      0.000,         0,    -11.7949,      0.6886
     -13.3,      0.000,      0.000,         0,    -11.7949,      0.7053
     -13.2,      0.000,      0.000,         0,    -11.7949,      0.7219
     -12.2,      0.000,      0.000,         0,    -11.7428,      0.7386
      -8.5,      0.000,      0.000,         0,    -11.5849,      0.7553
      -7.0,      0.000,      0.000,         0,    -11.5040,      0.7719
      -6.3,      0.000,      0.000,         0,    -11.4680,      0.7886
      -6.0,      0.000,      0.000,         0,    -11.4524,      0.8053
      -6.0,      0.000,      0.000,         0,    -11.4506,      0.8219
      -5.6,      0.000,      0.000,         0,    -11.4379,      0.8303
      -4.7,      0.000,      0.000,         0,    -11.3982,      0.8386
      -3.5,      0.000,      0.000,         0,    -11.3408,      0.8469
      -2.2,      0.000,      0.000,         0,    -11.2747,      0.8553
      -0.8,      0.000,      0.000,         0,    -11.1988,      0.8636
       0.4,      0.000,      0.000,         0,    -11.1255,      0.8719
       1.6,      0.000,      0.000,         0,    -11.0458,      0.8803
       2.9,      0.000,      0.000,         0,    -10.9625,      0.8886
       4.1,      0.000,      0.000,         0,    -10.8791,      0.8969
       5.2,      0.000,      0.000,         0,    -10.7961,      0.9053
       6.4,      0.000,      0.000,         0,    -10.7125,      0.9136
       7.5,      0.000,      0.000,         0,    -10.6291,      0.9219
       8.5,      0.000,      0.000,         0,    -10.5458,      0.9303
       9.4,      0.000,      0.000,         0,    -10.4628,      0.9386
      10.4,      0.000,      0.000,         0,    -10.3793,      0.9469
      11.3,      0.000,      0.000,         0,    -10.2957,      0.9553
      12.2,      0.000,      0.000,         0,    -10.2126,      0.9636
      13.1,      0.000,      0.000,         0,    -10.1296,      0.9719
      14.0,      0.000,      0.000,         0,    -10.0459,      0.9803
      14.9,      0.000,      0.000,         0,     -9.9626,      0.9886
      15.7,      0.000,      0.000,         0,     -9.8792,      0.9969
      16.5,      0.000,      0.000,         0,     -9.7958,      1.0053
      17.2,      0.000,      0.000,         0,     -9.7125,      1.0136
      18.0,      0.000,      0.000,         0,     -9.6292,      1.0219
      18.8,      0.000,      0.000,         0,     -9.5459,      1.0303
      19.5,      0.000,      0.000,         0,     -9.4627,      1.0386
      20.3,      0.000,      0.000,         0,     -9.3792,      1.0469
      21.0,      0.000,      0.000,         0,     -9.2959,      1.0553
      21.7,      0.000,      0.000,         0,     -9.2125,      1.0636
      22.3,      0.000,      0.000,         0,     -9.1292,      1.0719
      23.0,      0.000,      0.000,         0,     -9.0459,      1.0803
      23.7,      0.000,      0.000,         0,     -8.9627,      1.0886
      24.3,      0.000,      0.000,         0,     -8.8792,      1.0969
      24.9,      0.000,      0.000,         0,     -8.7961,      1.1053
      25.4,      0.000,      0.000,         0,     -8.7127,      1.1136
      26.0,      0.000,      0.000,         0,     -8.6292,      1.1219
      26.5,      0.000,      0.000,         0,     -8.5460,      1.1303
      27.0,      0.000,      0.000,         0,     -8.4628,      1.1386
      27.5,      0.000,      0.000,         0,     -8.3793,      1.1469
      27.9,      0.000,      0.000,         0,     -8.2958,      1.1553
      28.3,      0.000,      0.000,         0,     -8.2129,      1.1636
      28.7,      0.000,      0.000,         0,     -8.1296,      1.1719
      29.1,      0.000,      0.000,         0,     -8.0460,      1.1803
      29.5,      0.000,      0.000,         0,     -7.9625,      1.1886
      29.8,      0.000,      0.000,         0,     -7.8796,      1.1969
      30.0,      0.000,      0.000,         0,     -7.7961,      1.2053
      30.2,      0.000,      0.000,         0,     -7.7126,      1.2136
      30.0,      0.000,      0.000,         0,     -7.6293,      1.2219
      30.2,      0.000,      0.000,         0,     -7.5460,      1.2303
      30.5,      0.000,      0.000,         0,     -7.4628,      1.2386
      30.9,      0.000,      0.000,         0,     -7.3793,      1.2469
      31.2,      0.000,      0.000,         0,     -7.2960,      1.2553
      31.5,      0.000,      0.000,         0,     -7.2128,      1.2636
      31.8,      0.000,      0.000,         0,     -7.1295,      1.2719
      32.1,      0.000,      0.000,         0,     -7.0459,      1.2803
      32.4,      0.000,      0.000,         0,     -6.9628,      1.2886
      32.7,      0.000,      0.000,         0,     -6.8793,      1.2969
      33.0,      0.000,      0.000,         0,     -6.7963,      1.3053
      33.3,      0.000,      0.000,         0,     -6.7126,      1.3136
      33.6,      0.000,      0.000,         0,     -6.6294,      1.3219
      33.9,      0.000,      0.000,         0,     -6.5460,      1.3303
      34.2,      0.000,      0.000,         0,     -6.4628,      1.3386
      34.4,      0.000,      0.000,         0,     -6.3795,      1.3469
      34.7,      0.000,      0.000,         0,     -6.2960,      1.3553
      34.9,      0.000,      0.000,         0,     -6.2128,      1.3636
      35.2,      0.000,      0.000,         0,     -6.1294,      1.3719
      35.5,      0.000,      0.000,         0,     -6.0461,      1.3803
      35.7,      0.000,      0.000,         0,     -5.9627,      1.3886
      35.9,      0.000,      0.000,         0,     -5.8795,      1.3969
      36.2,      0.000,      0.000,         0,     -5.7961,      1.4053
      36.4,      0.000,      0.000,         0,     -5.7128,      1.4136
      36.7,      0.000,      0.000,         0,     -5.6293,      1.4219
      36.9,      0.000,      0.000,         0,     -5.5462,      1.4303
      37.1,      0.000,      0.000,         0,     -5.4628,      1.4386
      37.3,      0.000,      0.000,         0,     -5.3793,      1.4469
      37.6,      0.000,      0.000,         0,     -5.2961,      1.4553
      37.8,      0.000,      0.000,         0,     -5.2131,      1.4636
      38.0,      0.000,      0.000,         0,     -5.1294,      1.4719
      38.2,      0.000,      0.000,         0,     -5.0461,      1.4803
      38.4,      0.000,      0.000,         0,     -4.9628,      1.4886
      38.6,      0.000,      0.000,         0,     -4.8795,      1.4969
      38.8,      0.000,      0.000,         0,     -4.7962,      1.5053
      39.0,      0.000,      0.000,         0,     -4.7128,      1.5136
      39.3,      0.000,      0.000,         0,     -4.6296,      1.5219
      39.5,      0.000,      0.000,         0,     -4.5462,      1.5303
      39.7,      0.000,      0.000,         0,     -4.4628,      1.5386
      39.9,      0.000,      0.000,         0,     -4.3795,      1.5469
      40.1,      0.000,      0.000,         0,     -4.2962,      1.5553
      40.3,      0.000,      0.000,         0,     -4.2128,      1.5636
      40.6,      0.000,      0.000,         0,     -4.1295,      1.5719
      40.8,      0.000,      0.000,         0,     -4.0461,      1.5803
      41.0,      0.000,      0.000,         0,     -3.9628,      1.5886
      41.2,      0.000,      0.000,         0,     -3.8795,      1.5969
      41.4,      0.000,      0.000,         0,     -3.7963,      1.6053
      41.5,      0.000,      0.000,         0,     -3.7128,      1.6136
      41.7,      0.000,      0.000,         0,     -3.6296,      1.6219
      41.9,      0.000,      0.000,         0,     -3.5463,      1.6303
      42.1,      0.000,      0.000,         0,     -3.4628,      1.6386
      42.3,      0.000,      0.000,         0,     -3.3796,      1.6469
      42.5,      0.000,      0.000,         0,     -3.2961,      1.6553
      42.7,      0.000,      0.000,         0,     -3.2131,      1.6636
      42.9,      0.000,      0.000,         0,     -3.1297,      1.6719
      43.1,      0.000,      0.000,         0,     -3.0462,      1.6803
      43.3,      0.000,      0.000,         0,     -2.9628,      1.6886
      43.4,      0.000,      0.000,         0,     -2.8799,      1.6969
      43.6,      0.000,      0.000,         0,     -2.7962,      1.7053
      43.8,      0.000,      0.000,         0,     -2.7127,      1.7136
      43.9,      0.000,      0.000,         0,     -2.6295,      1.7219
      44.1,      0.000,      0.000,         0,     -2.5462,      1.7303
      44.2,      0.000,      0.000,         0,     -2.4629,      1.7386
      44.4,      0.000,      0.000,         0,     -2.3794,      1.7469
      44.5,      0.000,      0.000,         0,     -2.2964,      1.7553
      44.7,      0.000,      0.000,         0,     -2.2131,      1.7636
      44.8,      0.000,      0.000,         0,     -2.1296,      1.7719
      45.0,      0.000,      0.000,         0,     -2.0461,      1.7803
      45.2,      0.000,      0.000,         0,     -1.9630,      1.7886
      45.3,      0.000,      0.000,         0,     -1.8796,      1.7969
      45.5,      0.000,      0.000,         0,     -1.7962,      1.8053
      45.6,      0.000,      0.000,         0,     -1.7129,      1.8136
      45.8,      0.000,      0.000,         0,     -1.6296,      1.8219
      45.9,      0.000,      0.000,         0,     -1.5464,      1.8303
      46.1,      0.000,      0.000,         0,     -1.4630,      1.8386
      46.2,      0.000,      0.000,         0,     -1.3798,      1.8469
      46.4,      0.000,      0.000,         0,     -1.2961,      1.8553
      46.5,      0.000,      0.000,         0,     -1.2130,      1.8636
      46.6,      0.000,      0.000,         0,     -1.1295,      1.8719
      46.8,      0.000,      0.000,         0,     -1.0463,      1.8803
      46.9,      0.000,      0.000,         0,     -0.9630,      1.8886
      47.0,      0.000,      0.000,         0,     -0.8797,      1.8969
      47.1,      0.000,      0.000,         0,     -0.7964,      1.9053
      47.2,      0.000,      0.000,         0,     -0.7129,      1.9136
      47.4,      0.000,      0.000,         0,     -0.6297,      1.9219
      47.5,      0.000,      0.000,         0,     -0.5464,      1.9303
      47.6,      0.000,      0.000,         0,     -0.4630,      1.9386
      47.7,      0.000,      0.000,         0,     -0.3796,      1.9469
      47.8,      0.000,      0.000,         0,     -0.2964,      1.9553
      47.9,      0.000,      0.000,         0,     -0.2134,      1.9636
      48.0,      0.000,      0.000,         0,     -0.1296,      1.9719
      48.0,      0.000,      0.000,         0,     -0.0462,      1.9803
      48.1,      0.000,      0.000,         0,      0.0368,      1.9886
      48.2,      0.000,      0.000,         0,      0.1204,      1.9969
      48.3,      0.000,      0.000,         0,      0.2037,      2.0053
      48.3,      0.000,      0.000,         0,      0.2869,      2.0136
      48.4,      0.000,      0.000,         0,      0.3702,      2.0219
      48.4,      0.000,      0.000,         0,      0.4536,      2.0303
      48.5,      0.000,      0.000,         0,      0.5371,      2.0386
      48.5,      0.000,      0.000,         0,      0.6203,      2.0469
      48.5,      0.000,      0.000,         0,      0.7035,      2.0553
      48.5,      0.000,      0.000,         0,      0.7869,      2.0636
      48.5,      0.000,      0.000,         0,      0.8704,      2.0719
      48.5,      0.000,      0.000,         0,      0.9536,      2.0803
      48.4,      0.000,      0.000,         0,      1.0369,      2.0886
      48.3,      0.000,      0.000,         0,      1.1196,      2.0969
      48.2,      0.000,      0.000,         0,      1.2037,      2.1053
      48.0,      0.000,      0.000,         0,      1.2869,      2.1136
      47.6,      0.000,      0.000,         0,      1.3701,      2.1219
      46.9,      0.000,      0.000,         0,      1.4536,      2.1303
       0.0,      0.000,      0.000,         0,      1.5369,      2.1386
       0.0,      0.000,      0.000,         0,      1.6203,      2.1469
       0.0,      0.000,      0.000,         0,      1.7035,      2.1553
       0.0,      0.000,      0.000,         0,      1.7868,      2.1636
       0.0,      0.000,      0.000,         0,      1.8701,      2.1719
       0.0,      0.000,      0.000,         0,      1.9537,      2.1803