File: Alban repo/Quiz 1/suction cup instron tests/july-2020-force-vs-viscosity_raw-data/D30E10-01-inair-onwhiteplatic-diaphragmpump-10mm-test2.raw
Operator: 1

Date,Time,Specimen#
07/22/20,14:26:19,1

---------------------------------------


Area (mm^2):,      1.00,Flat,     25.40,     25.40,     25.40
Gage Len (mm):,     25.40


LOAD (N),STRAIN 1 (mm),STRAIN 2 (mm),STRESS (MPa),POSITION (mm),TIME (min)
       2.9,      0.000,      0.000,         0,      0.0826,      0.0083
       3.8,      0.000,      0.000,         0,      0.1658,      0.0167
       4.7,      0.000,      0.000,         0,      0.2490,      0.0250
       5.5,      0.000,      0.000,         0,      0.3326,      0.0333
       6.2,      0.000,      0.000,         0,      0.4158,      0.0417
       3.8,      0.000,      0.000,         0,      0.4992,      0.0500
       3.9,      0.000,      0.000,         0,      0.5824,      0.0583
       4.3,      0.000,      0.000,         0,      0.6657,      0.0667
       4.6,      0.000,      0.000,         0,      0.7492,      0.0750
       4.9,      0.000,      0.000,         0,      0.8324,      0.0833
       5.3,      0.000,      0.000,         0,      0.9158,      0.0917
       5.6,      0.000,      0.000,         0,      0.9990,      0.1000
       5.9,      0.000,      0.000,         0,      1.0825,      0.1083
       6.2,      0.000,      0.000,         0,      1.1658,      0.1167
       6.4,      0.000,      0.000,         0,      1.2491,      0.1250
       6.7,      0.000,      0.000,         0,      1.3324,      0.1333
       7.0,      0.000,      0.000,         0,      1.4158,      0.1417
       7.2,      0.000,      0.000,         0,      1.4992,      0.1500
       7.5,      0.000,      0.000,         0,      1.5821,      0.1583
       7.7,      0.000,      0.000,         0,      1.6656,      0.1667
       8.0,      0.000,      0.000,         0,      1.7491,      0.1750
       8.2,      0.000,      0.000,         0,      1.8324,      0.1833
       8.4,      0.000,      0.000,         0,      1.9157,      0.1917
       8.6,      0.000,      0.000,         0,      1.9991,      0.2000
       8.8,      0.000,      0.000,         0,      2.0825,      0.2083
       9.0,      0.000,      0.000,         0,      2.1659,      0.2167
       9.2,      0.000,      0.000,         0,      2.2491,      0.2250
       9.4,      0.000,      0.000,         0,      2.3325,      0.2333
       9.7,      0.000,      0.000,         0,      2.4158,      0.2417
       9.8,      0.000,      0.000,         0,      2.4991,      0.2500
      10.1,      0.000,      0.000,         0,      2.5824,      0.2583
      10.2,      0.000,      0.000,         0,      2.6658,      0.2667
      10.4,      0.000,      0.000,         0,      2.7491,      0.2750
      10.6,      0.000,      0.000,         0,      2.8323,      0.2833
      10.8,      0.000,      0.000,         0,      2.9157,      0.2917
      10.9,      0.000,      0.000,         0,      2.9990,      0.3000
      11.1,      0.000,      0.000,         0,      3.0825,      0.3083
      11.3,      0.000,      0.000,         0,      3.1657,      0.3167
      11.4,      0.000,      0.000,         0,      3.2490,      0.3250
      11.7,      0.000,      0.000,         0,      3.3324,      0.3333
      11.7,      0.000,      0.000,         0,      3.4158,      0.3417
      11.9,      0.000,      0.000,         0,      3.4989,      0.3500
      12.1,      0.000,      0.000,         0,      3.5825,      0.3583
      12.2,      0.000,      0.000,         0,      3.6656,      0.3667
      12.4,      0.000,      0.000,         0,      3.7490,      0.3750
      12.6,      0.000,      0.000,         0,      3.8321,      0.3833
      12.8,      0.000,      0.000,         0,      3.9157,      0.3917
      12.9,      0.000,      0.000,         0,      3.9989,      0.4000
      13.0,      0.000,      0.000,         0,      4.0825,      0.4083
      13.2,      0.000,      0.000,         0,      4.1657,      0.4167
      13.4,      0.000,      0.000,         0,      4.2487,      0.4250
      13.5,      0.000,      0.000,         0,      4.3323,      0.4333
      13.6,      0.000,      0.000,         0,      4.4157,      0.4417
      13.7,      0.000,      0.000,         0,      4.4990,      0.4500
      13.9,      0.000,      0.000,         0,      4.5822,      0.4583
      14.0,      0.000,      0.000,         0,      4.6657,      0.4667
      14.2,      0.000,      0.000,         0,      4.7491,      0.4750
      14.3,      0.000,      0.000,         0,      4.8321,      0.4833
      14.4,      0.000,      0.000,         0,      4.9152,      0.4917
      14.5,      0.000,      0.000,         0,      4.9990,      0.5000
      14.6,      0.000,      0.000,         0,      5.0824,      0.5083
      14.7,      0.000,      0.000,         0,      5.1655,      0.5167
      14.8,      0.000,      0.000,         0,      5.2491,      0.5250
      15.0,      0.000,      0.000,         0,      5.3321,      0.5333
      15.1,      0.000,      0.000,         0,      5.4157,      0.5417
      15.2,      0.000,      0.000,         0,      5.4989,      0.5500
      15.3,      0.000,      0.000,         0,      5.5820,      0.5583
      15.4,      0.000,      0.000,         0,      5.6655,      0.5667
      15.4,      0.000,      0.000,         0,      5.7490,      0.5750
      15.6,      0.000,      0.000,         0,      5.8322,      0.5833
      15.6,      0.000,      0.000,         0,      5.9156,      0.5917
      15.7,      0.000,      0.000,         0,      5.9988,      0.6000
      15.8,      0.000,      0.000,         0,      6.0821,      0.6083
      15.9,      0.000,      0.000,         0,      6.1656,      0.6167
      16.0,      0.000,      0.000,         0,      6.2487,      0.6250
      16.1,      0.000,      0.000,         0,      6.3322,      0.6333
      16.2,      0.000,      0.000,         0,      6.4156,      0.6417
      16.3,      0.000,      0.000,         0,      6.4989,      0.6500
      16.3,      0.000,      0.000,         0,      6.5822,      0.6583
      16.4,      0.000,      0.000,         0,      6.6656,      0.6667
      16.5,      0.000,      0.000,         0,      6.7488,      0.6750
      16.6,      0.000,      0.000,         0,      6.8323,      0.6833
      16.6,      0.000,      0.000,         0,      6.9154,      0.6917
      16.7,      0.000,      0.000,         0,      6.9989,      0.7000
      16.8,      0.000,      0.000,         0,      7.0821,      0.7083
      16.8,      0.000,      0.000,         0,      7.1654,      0.7167
      16.8,      0.000,      0.000,         0,      7.2487,      0.7250
      16.9,      0.000,      0.000,         0,      7.3323,      0.7333
      16.9,      0.000,      0.000,         0,      7.4156,      0.7417
      17.0,      0.000,      0.000,         0,      7.4986,      0.7500
      17.0,      0.000,      0.000,         0,      7.5822,      0.7583
      17.1,      0.000,      0.000,         0,      7.6656,      0.7667
      17.1,      0.000,      0.000,         0,      7.7488,      0.7750
      17.2,      0.000,      0.000,         0,      7.8322,      0.7833
      17.2,      0.000,      0.000,         0,      7.9155,      0.7917
      17.3,      0.000,      0.000,         0,      7.9989,      0.8000
      17.3,      0.000,      0.000,         0,      8.0822,      0.8083
      17.4,      0.000,      0.000,         0,      8.1652,      0.8167
      17.4,      0.000,      0.000,         0,      8.2490,      0.8250
      17.5,      0.000,      0.000,         0,      8.3320,      0.8333
      17.6,      0.000,      0.000,         0,      8.4154,      0.8417
      17.7,      0.000,      0.000,         0,      8.4986,      0.8500
      17.8,      0.000,      0.000,         0,      8.5821,      0.8583
      17.8,      0.000,      0.000,         0,      8.6654,      0.8667
      18.0,      0.000,      0.000,         0,      8.7487,      0.8750
      18.0,      0.000,      0.000,         0,      8.8322,      0.8833
      18.1,      0.000,      0.000,         0,      8.9151,      0.8917
      18.1,      0.000,      0.000,         0,      8.9987,      0.9000
      18.2,      0.000,      0.000,         0,      9.0821,      0.9083
      18.3,      0.000,      0.000,         0,      9.1655,      0.9167
      18.3,      0.000,      0.000,         0,      9.2488,      0.9250
      18.4,      0.000,      0.000,         0,      9.3321,      0.9333
      18.4,      0.000,      0.000,         0,      9.4154,      0.9417
      18.5,      0.000,      0.000,         0,      9.4987,      0.9500
      18.5,      0.000,      0.000,         0,      9.5818,      0.9583
      18.6,      0.000,      0.000,         0,      9.6655,      0.9667
      18.6,      0.000,      0.000,         0,      9.7488,      0.9750
      18.6,      0.000,      0.000,         0,      9.8320,      0.9833
      18.6,      0.000,      0.000,         0,      9.9155,      0.9917
      18.6,      0.000,      0.000,         0,      9.9988,      1.0000
      18.6,      0.000,      0.000,         0,     10.0820,      1.0083
      18.7,      0.000,      0.000,         0,     10.1654,      1.0167
      18.7,      0.000,      0.000,         0,     10.2486,      1.0250
      18.7,      0.000,      0.000,         0,     10.3320,      1.0333
      18.7,      0.000,      0.000,         0,     10.4154,      1.0417
      18.8,      0.000,      0.000,         0,     10.4986,      1.0500
      18.8,      0.000,      0.000,         0,     10.5819,      1.0583
      18.8,      0.000,      0.000,         0,     10.6654,      1.0667
      18.8,      0.000,      0.000,         0,     10.7487,      1.0750
      18.8,      0.000,      0.000,         0,     10.8319,      1.0833
      18.7,      0.000,      0.000,         0,     10.9153,      1.0917
      18.7,      0.000,      0.000,         0,     10.9987,      1.1000
      18.6,      0.000,      0.000,         0,     11.0819,      1.1083
       0.0,      0.000,      0.000,         0,     11.1654,      1.1167
       0.0,      0.000,      0.000,         0,     11.2486,      1.1250
       0.0,      0.000,      0.000,         0,     11.3320,      1.1333
       0.0,      0.000,      0.000,         0,     11.4152,      1.1417