File: Alban repo/Quiz 1/suction cup instron tests/july-2020-force-vs-viscosity_raw-data/D30E10-01-inair-si-oil-onwhiteplatic-diaphragmpump-10mm-test5.raw
Operator: 1

Date,Time,Specimen#
07/22/20,16:48:36,1

---------------------------------------


Area (mm^2):,      1.00,Flat,     25.40,     25.40,     25.40
Gage Len (mm):,     25.40


LOAD (N),STRAIN 1 (mm),STRAIN 2 (mm),STRESS (MPa),POSITION (mm),TIME (min)
       1.7,      0.000,      0.000,         0,     -0.1618,      0.0083
       1.7,      0.000,      0.000,         0,     -0.3286,      0.0167
       1.1,      0.000,      0.000,         0,     -0.4951,      0.0250
       0.8,      0.000,      0.000,         0,     -0.6617,      0.0333
      -2.2,      0.000,      0.000,         0,     -0.8284,      0.0417
      -1.5,      0.000,      0.000,         0,     -0.9951,      0.0500
      -1.1,      0.000,      0.000,         0,     -1.1616,      0.0583
      -1.6,      0.000,      0.000,         0,     -1.3283,      0.0667
      -1.0,      0.000,      0.000,         0,     -1.4950,      0.0750
      -0.7,      0.000,      0.000,         0,     -1.6618,      0.0833
      -0.6,      0.000,      0.000,         0,     -1.8282,      0.0917
      -0.8,      0.000,      0.000,         0,     -1.9951,      0.1000
      -1.6,      0.000,      0.000,         0,     -2.1617,      0.1083
      -6.3,      0.000,      0.000,         0,     -2.3283,      0.1167
      -8.4,      0.000,      0.000,         0,     -2.4951,      0.1250
     -11.0,      0.000,      0.000,         0,     -2.6616,      0.1333
      -8.6,      0.000,      0.000,         0,     -2.9633,      0.1536
      -2.3,      0.000,      0.000,         0,     -3.0493,      0.1703
      -2.4,      0.000,      0.000,         0,     -3.0790,      0.1870
      -2.3,      0.000,      0.000,         0,     -3.0950,      0.2036
      -2.4,      0.000,      0.000,         0,     -3.0950,      0.2203
      -2.1,      0.000,      0.000,         0,     -3.0950,      0.2370
      -2.1,      0.000,      0.000,         0,     -3.0949,      0.2536
      -2.1,      0.000,      0.000,         0,     -3.0949,      0.2703
      -2.1,      0.000,      0.000,         0,     -3.0950,      0.2870
      -2.0,      0.000,      0.000,         0,     -3.0450,      0.3036
      10.5,      0.000,      0.000,         0,     -2.8922,      0.3203
      10.4,      0.000,      0.000,         0,     -2.8074,      0.3370
      10.2,      0.000,      0.000,         0,     -2.7717,      0.3536
      10.1,      0.000,      0.000,         0,     -2.7564,      0.3703
      10.0,      0.000,      0.000,         0,     -2.7554,      0.3870
      10.0,      0.000,      0.000,         0,     -2.7411,      0.3953
      10.1,      0.000,      0.000,         0,     -2.7016,      0.4036
      10.2,      0.000,      0.000,         0,     -2.6448,      0.4120
      10.3,      0.000,      0.000,         0,     -2.5803,      0.4203
      10.4,      0.000,      0.000,         0,     -2.5053,      0.4286
      10.5,      0.000,      0.000,         0,     -2.4277,      0.4370
      10.6,      0.000,      0.000,         0,     -2.3506,      0.4453
      10.7,      0.000,      0.000,         0,     -2.2680,      0.4536
      10.8,      0.000,      0.000,         0,     -2.1840,      0.4620
      10.8,      0.000,      0.000,         0,     -2.1007,      0.4703
      10.9,      0.000,      0.000,         0,     -2.0174,      0.4786
      11.0,      0.000,      0.000,         0,     -1.9344,      0.4870
      11.1,      0.000,      0.000,         0,     -1.8506,      0.4953
      11.1,      0.000,      0.000,         0,     -1.7673,      0.5036
      11.2,      0.000,      0.000,         0,     -1.6840,      0.5120
      11.3,      0.000,      0.000,         0,     -1.6006,      0.5203
      11.3,      0.000,      0.000,         0,     -1.5172,      0.5286
      11.4,      0.000,      0.000,         0,     -1.4339,      0.5370
      11.5,      0.000,      0.000,         0,     -1.3506,      0.5453
      11.6,      0.000,      0.000,         0,     -1.2675,      0.5536
      11.7,      0.000,      0.000,         0,     -1.1840,      0.5620
      11.8,      0.000,      0.000,         0,     -1.1009,      0.5703
      11.9,      0.000,      0.000,         0,     -1.0173,      0.5786
      12.1,      0.000,      0.000,         0,     -0.9341,      0.5870
      12.2,      0.000,      0.000,         0,     -0.8506,      0.5953
      12.3,      0.000,      0.000,         0,     -0.7674,      0.6036
      12.4,      0.000,      0.000,         0,     -0.6841,      0.6120
      12.6,      0.000,      0.000,         0,     -0.6012,      0.6203
      12.7,      0.000,      0.000,         0,     -0.5173,      0.6286
      12.8,      0.000,      0.000,         0,     -0.4340,      0.6370
      13.0,      0.000,      0.000,         0,     -0.3508,      0.6453
      13.1,      0.000,      0.000,         0,     -0.2674,      0.6536
      13.3,      0.000,      0.000,         0,     -0.1841,      0.6620
      13.5,      0.000,      0.000,         0,     -0.1007,      0.6703
      13.6,      0.000,      0.000,         0,     -0.0175,      0.6786
      13.8,      0.000,      0.000,         0,      0.0657,      0.6870
      14.0,      0.000,      0.000,         0,      0.1491,      0.6953
      14.2,      0.000,      0.000,         0,      0.2326,      0.7036
      14.3,      0.000,      0.000,         0,      0.3156,      0.7120
      14.5,      0.000,      0.000,         0,      0.3993,      0.7203
      14.7,      0.000,      0.000,         0,      0.4824,      0.7286
      14.9,      0.000,      0.000,         0,      0.5658,      0.7370
      15.1,      0.000,      0.000,         0,      0.6493,      0.7453
      15.2,      0.000,      0.000,         0,      0.7324,      0.7536
      15.4,      0.000,      0.000,         0,      0.8160,      0.7620
      15.5,      0.000,      0.000,         0,      0.8993,      0.7703
      15.7,      0.000,      0.000,         0,      0.9826,      0.7786
       1.8,      0.000,      0.000,         0,      1.0658,      0.7870
       0.0,      0.000,      0.000,         0,      1.1494,      0.7953
       0.0,      0.000,      0.000,         0,      1.2326,      0.8036
       0.0,      0.000,      0.000,         0,      1.3157,      0.8120
       0.0,      0.000,      0.000,         0,      1.3990,      0.8203
       0.0,      0.000,      0.000,         0,      1.4827,      0.8286
       0.0,      0.000,      0.000,         0,      1.5658,      0.8370
       0.0,      0.000,      0.000,         0,      1.6491,      0.8453
       0.0,      0.000,      0.000,         0,      1.7325,      0.8536