File: Alban repo/Quiz 1/suction cup instron tests/july-2020-force-vs-viscosity_raw-data/D30E10-01-inwater-onwhiteplatic-diaphragmpump-10mm-test2.raw
Operator: 1

Date,Time,Specimen#
07/22/20,14:03:00,1

---------------------------------------


Area (mm^2):,      1.00,Flat,     25.40,     25.40,     25.40
Gage Len (mm):,     25.40


LOAD (N),STRAIN 1 (mm),STRAIN 2 (mm),STRESS (MPa),POSITION (mm),TIME (min)
       3.1,      0.000,      0.000,         0,      0.0816,      0.0083
       4.2,      0.000,      0.000,         0,      0.1647,      0.0167
       5.3,      0.000,      0.000,         0,      0.2480,      0.0250
       6.3,      0.000,      0.000,         0,      0.3316,      0.0333
       7.3,      0.000,      0.000,         0,      0.4148,      0.0417
       8.2,      0.000,      0.000,         0,      0.4982,      0.0500
       9.1,      0.000,      0.000,         0,      0.5813,      0.0583
      10.0,      0.000,      0.000,         0,      0.6648,      0.0667
      10.9,      0.000,      0.000,         0,      0.7481,      0.0750
      11.7,      0.000,      0.000,         0,      0.8315,      0.0833
      12.5,      0.000,      0.000,         0,      0.9146,      0.0917
      13.3,      0.000,      0.000,         0,      0.9981,      0.1000
      14.0,      0.000,      0.000,         0,      1.0815,      0.1083
      14.5,      0.000,      0.000,         0,      1.1649,      0.1167
      15.2,      0.000,      0.000,         0,      1.2482,      0.1250
      15.6,      0.000,      0.000,         0,      1.3314,      0.1333
      15.2,      0.000,      0.000,         0,      1.4147,      0.1417
      15.5,      0.000,      0.000,         0,      1.4982,      0.1500
      15.9,      0.000,      0.000,         0,      1.5815,      0.1583
      16.3,      0.000,      0.000,         0,      1.6646,      0.1667
      16.7,      0.000,      0.000,         0,      1.7483,      0.1750
      17.1,      0.000,      0.000,         0,      1.8314,      0.1833
      17.5,      0.000,      0.000,         0,      1.9144,      0.1917
      17.9,      0.000,      0.000,         0,      1.9979,      0.2000
      18.3,      0.000,      0.000,         0,      2.0815,      0.2083
      18.7,      0.000,      0.000,         0,      2.1647,      0.2167
      19.0,      0.000,      0.000,         0,      2.2480,      0.2250
      19.4,      0.000,      0.000,         0,      2.3315,      0.2333
      19.7,      0.000,      0.000,         0,      2.4148,      0.2417
      20.0,      0.000,      0.000,         0,      2.4980,      0.2500
      20.3,      0.000,      0.000,         0,      2.5814,      0.2583
      20.7,      0.000,      0.000,         0,      2.6648,      0.2667
      21.0,      0.000,      0.000,         0,      2.7480,      0.2750
      21.3,      0.000,      0.000,         0,      2.8313,      0.2833
      21.6,      0.000,      0.000,         0,      2.9147,      0.2917
      22.0,      0.000,      0.000,         0,      2.9979,      0.3000
      22.3,      0.000,      0.000,         0,      3.0813,      0.3083
      22.6,      0.000,      0.000,         0,      3.1647,      0.3167
      22.9,      0.000,      0.000,         0,      3.2481,      0.3250
      23.2,      0.000,      0.000,         0,      3.3312,      0.3333
      23.5,      0.000,      0.000,         0,      3.4148,      0.3417
      23.7,      0.000,      0.000,         0,      3.4979,      0.3500
      24.0,      0.000,      0.000,         0,      3.5811,      0.3583
      24.3,      0.000,      0.000,         0,      3.6647,      0.3667
      24.6,      0.000,      0.000,         0,      3.7481,      0.3750
      24.9,      0.000,      0.000,         0,      3.8313,      0.3833
      25.2,      0.000,      0.000,         0,      3.9147,      0.3917
      25.5,      0.000,      0.000,         0,      3.9979,      0.4000
      25.8,      0.000,      0.000,         0,      4.0813,      0.4083
      26.0,      0.000,      0.000,         0,      4.1645,      0.4167
      26.3,      0.000,      0.000,         0,      4.2480,      0.4250
      26.6,      0.000,      0.000,         0,      4.3313,      0.4333
      26.9,      0.000,      0.000,         0,      4.4147,      0.4417
      27.1,      0.000,      0.000,         0,      4.4980,      0.4500
      27.4,      0.000,      0.000,         0,      4.5812,      0.4583
      27.6,      0.000,      0.000,         0,      4.6646,      0.4667
      27.9,      0.000,      0.000,         0,      4.7480,      0.4750
      28.2,      0.000,      0.000,         0,      4.8312,      0.4833
      28.4,      0.000,      0.000,         0,      4.9145,      0.4917
      28.7,      0.000,      0.000,         0,      4.9980,      0.5000
      28.9,      0.000,      0.000,         0,      5.0813,      0.5083
      29.2,      0.000,      0.000,         0,      5.1647,      0.5167
      29.4,      0.000,      0.000,         0,      5.2477,      0.5250
      29.7,      0.000,      0.000,         0,      5.3314,      0.5333
      29.9,      0.000,      0.000,         0,      5.4145,      0.5417
      30.2,      0.000,      0.000,         0,      5.4979,      0.5500
      30.4,      0.000,      0.000,         0,      5.5812,      0.5583
      30.6,      0.000,      0.000,         0,      5.6645,      0.5667
      30.8,      0.000,      0.000,         0,      5.7479,      0.5750
      31.1,      0.000,      0.000,         0,      5.8314,      0.5833
      31.3,      0.000,      0.000,         0,      5.9143,      0.5917
      31.5,      0.000,      0.000,         0,      5.9978,      0.6000
      31.8,      0.000,      0.000,         0,      6.0813,      0.6083
      32.0,      0.000,      0.000,         0,      6.1646,      0.6167
      32.2,      0.000,      0.000,         0,      6.2479,      0.6250
      32.4,      0.000,      0.000,         0,      6.3313,      0.6333
      32.7,      0.000,      0.000,         0,      6.4146,      0.6417
      32.9,      0.000,      0.000,         0,      6.4980,      0.6500
      33.1,      0.000,      0.000,         0,      6.5811,      0.6583
      33.3,      0.000,      0.000,         0,      6.6645,      0.6667
      33.5,      0.000,      0.000,         0,      6.7478,      0.6750
      33.7,      0.000,      0.000,         0,      6.8311,      0.6833
      34.0,      0.000,      0.000,         0,      6.9145,      0.6917
      34.2,      0.000,      0.000,         0,      6.9979,      0.7000
      34.4,      0.000,      0.000,         0,      7.0812,      0.7083
      34.6,      0.000,      0.000,         0,      7.1646,      0.7167
      34.8,      0.000,      0.000,         0,      7.2477,      0.7250
      35.0,      0.000,      0.000,         0,      7.3314,      0.7333
      35.2,      0.000,      0.000,         0,      7.4144,      0.7417
      35.4,      0.000,      0.000,         0,      7.4978,      0.7500
      35.6,      0.000,      0.000,         0,      7.5810,      0.7583
      35.8,      0.000,      0.000,         0,      7.6646,      0.7667
      36.0,      0.000,      0.000,         0,      7.7478,      0.7750
      36.2,      0.000,      0.000,         0,      7.8311,      0.7833
      36.4,      0.000,      0.000,         0,      7.9144,      0.7917
      36.6,      0.000,      0.000,         0,      7.9979,      0.8000
      36.8,      0.000,      0.000,         0,      8.0813,      0.8083
      36.9,      0.000,      0.000,         0,      8.1645,      0.8167
      37.1,      0.000,      0.000,         0,      8.2478,      0.8250
      37.3,      0.000,      0.000,         0,      8.3311,      0.8333
      37.5,      0.000,      0.000,         0,      8.4145,      0.8417
      37.7,      0.000,      0.000,         0,      8.4975,      0.8500
      37.9,      0.000,      0.000,         0,      8.5812,      0.8583
      38.1,      0.000,      0.000,         0,      8.6644,      0.8667
      38.2,      0.000,      0.000,         0,      8.7478,      0.8750
      38.4,      0.000,      0.000,         0,      8.8310,      0.8833
      38.6,      0.000,      0.000,         0,      8.9144,      0.8917
      38.8,      0.000,      0.000,         0,      8.9977,      0.9000
      39.0,      0.000,      0.000,         0,      9.0811,      0.9083
      39.1,      0.000,      0.000,         0,      9.1644,      0.9167
      39.3,      0.000,      0.000,         0,      9.2475,      0.9250
      39.5,      0.000,      0.000,         0,      9.3311,      0.9333
      39.7,      0.000,      0.000,         0,      9.4145,      0.9417
      39.8,      0.000,      0.000,         0,      9.4977,      0.9500
      40.0,      0.000,      0.000,         0,      9.5811,      0.9583
      40.2,      0.000,      0.000,         0,      9.6645,      0.9667
      40.4,      0.000,      0.000,         0,      9.7477,      0.9750
      40.5,      0.000,      0.000,         0,      9.8310,      0.9833
      40.7,      0.000,      0.000,         0,      9.9143,      0.9917
      40.9,      0.000,      0.000,         0,      9.9978,      1.0000
      41.1,      0.000,      0.000,         0,     10.0810,      1.0083
      41.2,      0.000,      0.000,         0,     10.1643,      1.0167
      41.4,      0.000,      0.000,         0,     10.2478,      1.0250
      41.6,      0.000,      0.000,         0,     10.3310,      1.0333
      41.7,      0.000,      0.000,         0,     10.4143,      1.0417
      41.9,      0.000,      0.000,         0,     10.4977,      1.0500
      42.0,      0.000,      0.000,         0,     10.5811,      1.0583
      42.1,      0.000,      0.000,         0,     10.6644,      1.0667
      42.3,      0.000,      0.000,         0,     10.7476,      1.0750
      42.4,      0.000,      0.000,         0,     10.8311,      1.0833
      42.5,      0.000,      0.000,         0,     10.9144,      1.0917
      42.7,      0.000,      0.000,         0,     10.9977,      1.1000
      42.8,      0.000,      0.000,         0,     11.0810,      1.1083
      42.9,      0.000,      0.000,         0,     11.1643,      1.1167
      43.0,      0.000,      0.000,         0,     11.2475,      1.1250
      43.1,      0.000,      0.000,         0,     11.3310,      1.1333
      43.2,      0.000,      0.000,         0,     11.4142,      1.1417
      43.3,      0.000,      0.000,         0,     11.4976,      1.1500
      43.3,      0.000,      0.000,         0,     11.5809,      1.1583
      43.4,      0.000,      0.000,         0,     11.6645,      1.1667
      43.4,      0.000,      0.000,         0,     11.7477,      1.1750
      43.4,      0.000,      0.000,         0,     11.8306,      1.1833
      43.5,      0.000,      0.000,         0,     11.9142,      1.1917
      43.5,      0.000,      0.000,         0,     11.9978,      1.2000
      43.6,      0.000,      0.000,         0,     12.0807,      1.2083
      43.6,      0.000,      0.000,         0,     12.1642,      1.2167
      43.5,      0.000,      0.000,         0,     12.2475,      1.2250
      43.5,      0.000,      0.000,         0,     12.3311,      1.2333
      43.4,      0.000,      0.000,         0,     12.4143,      1.2417
      43.4,      0.000,      0.000,         0,     12.4976,      1.2500
      43.3,      0.000,      0.000,         0,     12.5810,      1.2583
      43.2,      0.000,      0.000,         0,     12.6644,      1.2667
      43.1,      0.000,      0.000,         0,     12.7477,      1.2750
      43.0,      0.000,      0.000,         0,     12.8309,      1.2833
      42.9,      0.000,      0.000,         0,     12.9144,      1.2917
      42.7,      0.000,      0.000,         0,     12.9975,      1.3000
      42.5,      0.000,      0.000,         0,     13.0809,      1.3083
      42.3,      0.000,      0.000,         0,     13.1638,      1.3167
      42.0,      0.000,      0.000,         0,     13.2474,      1.3250
      41.6,      0.000,      0.000,         0,     13.3308,      1.3333
      41.2,      0.000,      0.000,         0,     13.4142,      1.3417
      40.5,      0.000,      0.000,         0,     13.4975,      1.3500
      34.6,      0.000,      0.000,         0,     13.5809,      1.3583
       0.0,      0.000,      0.000,         0,     13.6642,      1.3667
       0.0,      0.000,      0.000,         0,     13.7476,      1.3750
       0.0,      0.000,      0.000,         0,     13.8307,      1.3833
       0.0,      0.000,      0.000,         0,     13.9141,      1.3917