File: Alban repo/Quiz 1/suction cup instron tests/july-2020-force-vs-viscosity_raw-data/D30E10-01-in6-1x10-3-onwhiteplatic-diaphragmpump-10mm-test1.raw
Operator: 1

Date,Time,Specimen#
07/22/20,13:33:58,1

---------------------------------------


Area (mm^2):,      1.00,Flat,     25.40,     25.40,     25.40
Gage Len (mm):,     25.40


LOAD (N),STRAIN 1 (mm),STRAIN 2 (mm),STRESS (MPa),POSITION (mm),TIME (min)
       3.2,      0.000,      0.000,         0,      0.0805,      0.0083
       4.4,      0.000,      0.000,         0,      0.1637,      0.0167
       5.6,      0.000,      0.000,         0,      0.2471,      0.0250
       6.7,      0.000,      0.000,         0,      0.3305,      0.0333
       7.8,      0.000,      0.000,         0,      0.4138,      0.0417
       8.8,      0.000,      0.000,         0,      0.4971,      0.0500
       9.8,      0.000,      0.000,         0,      0.5804,      0.0583
      10.8,      0.000,      0.000,         0,      0.6637,      0.0667
      11.8,      0.000,      0.000,         0,      0.7471,      0.0750
      12.7,      0.000,      0.000,         0,      0.8304,      0.0833
      13.7,      0.000,      0.000,         0,      0.9138,      0.0917
      14.6,      0.000,      0.000,         0,      0.9971,      0.1000
      15.5,      0.000,      0.000,         0,      1.0803,      0.1083
      16.3,      0.000,      0.000,         0,      1.1639,      0.1167
      17.1,      0.000,      0.000,         0,      1.2469,      0.1250
      18.0,      0.000,      0.000,         0,      1.3303,      0.1333
      18.8,      0.000,      0.000,         0,      1.4138,      0.1417
      19.5,      0.000,      0.000,         0,      1.4971,      0.1500
      20.2,      0.000,      0.000,         0,      1.5804,      0.1583
      20.9,      0.000,      0.000,         0,      1.6638,      0.1667
      21.5,      0.000,      0.000,         0,      1.7472,      0.1750
      21.5,      0.000,      0.000,         0,      1.8302,      0.1833
      21.4,      0.000,      0.000,         0,      1.9135,      0.1917
      22.0,      0.000,      0.000,         0,      1.9972,      0.2000
      22.5,      0.000,      0.000,         0,      2.0804,      0.2083
      23.0,      0.000,      0.000,         0,      2.1635,      0.2167
      23.6,      0.000,      0.000,         0,      2.2472,      0.2250
      24.1,      0.000,      0.000,         0,      2.3304,      0.2333
      24.6,      0.000,      0.000,         0,      2.4137,      0.2417
      25.0,      0.000,      0.000,         0,      2.4968,      0.2500
      25.5,      0.000,      0.000,         0,      2.5804,      0.2583
      26.0,      0.000,      0.000,         0,      2.6636,      0.2667
      26.5,      0.000,      0.000,         0,      2.7469,      0.2750
      26.9,      0.000,      0.000,         0,      2.8302,      0.2833
      27.4,      0.000,      0.000,         0,      2.9137,      0.2917
      27.8,      0.000,      0.000,         0,      2.9971,      0.3000
      28.2,      0.000,      0.000,         0,      3.0803,      0.3083
      28.6,      0.000,      0.000,         0,      3.1637,      0.3167
      29.0,      0.000,      0.000,         0,      3.2469,      0.3250
      29.4,      0.000,      0.000,         0,      3.3303,      0.3333
      29.8,      0.000,      0.000,         0,      3.4137,      0.3417
      30.2,      0.000,      0.000,         0,      3.4968,      0.3500
      30.6,      0.000,      0.000,         0,      3.5802,      0.3583
      31.0,      0.000,      0.000,         0,      3.6636,      0.3667
      31.3,      0.000,      0.000,         0,      3.7470,      0.3750
      31.7,      0.000,      0.000,         0,      3.8304,      0.3833
      32.0,      0.000,      0.000,         0,      3.9134,      0.3917
      32.4,      0.000,      0.000,         0,      3.9969,      0.4000
      32.7,      0.000,      0.000,         0,      4.0804,      0.4083
      33.1,      0.000,      0.000,         0,      4.1635,      0.4167
      33.4,      0.000,      0.000,         0,      4.2469,      0.4250
      33.7,      0.000,      0.000,         0,      4.3303,      0.4333
      34.1,      0.000,      0.000,         0,      4.4137,      0.4417
      34.4,      0.000,      0.000,         0,      4.4968,      0.4500
      34.7,      0.000,      0.000,         0,      4.5803,      0.4583
      35.0,      0.000,      0.000,         0,      4.6636,      0.4667
      35.3,      0.000,      0.000,         0,      4.7469,      0.4750
      35.6,      0.000,      0.000,         0,      4.8302,      0.4833
      35.9,      0.000,      0.000,         0,      4.9135,      0.4917
      36.2,      0.000,      0.000,         0,      4.9970,      0.5000
      36.5,      0.000,      0.000,         0,      5.0801,      0.5083
      36.8,      0.000,      0.000,         0,      5.1635,      0.5167
      37.1,      0.000,      0.000,         0,      5.2470,      0.5250
      37.3,      0.000,      0.000,         0,      5.3302,      0.5333
      37.6,      0.000,      0.000,         0,      5.4134,      0.5417
      37.8,      0.000,      0.000,         0,      5.4970,      0.5500
      38.1,      0.000,      0.000,         0,      5.5801,      0.5583
      38.4,      0.000,      0.000,         0,      5.6635,      0.5667
      38.6,      0.000,      0.000,         0,      5.7468,      0.5750
      38.9,      0.000,      0.000,         0,      5.8303,      0.5833
      39.1,      0.000,      0.000,         0,      5.9135,      0.5917
      39.4,      0.000,      0.000,         0,      5.9970,      0.6000
      39.6,      0.000,      0.000,         0,      6.0799,      0.6083
      39.9,      0.000,      0.000,         0,      6.1636,      0.6167
      40.1,      0.000,      0.000,         0,      6.2468,      0.6250
      40.3,      0.000,      0.000,         0,      6.3301,      0.6333
      40.6,      0.000,      0.000,         0,      6.4137,      0.6417
      40.8,      0.000,      0.000,         0,      6.4966,      0.6500
      41.0,      0.000,      0.000,         0,      6.5802,      0.6583
      41.3,      0.000,      0.000,         0,      6.6635,      0.6667
      41.5,      0.000,      0.000,         0,      6.7469,      0.6750
      41.7,      0.000,      0.000,         0,      6.8300,      0.6833
      42.0,      0.000,      0.000,         0,      6.9136,      0.6917
      42.2,      0.000,      0.000,         0,      6.9968,      0.7000
      42.4,      0.000,      0.000,         0,      7.0800,      0.7083
      42.6,      0.000,      0.000,         0,      7.1632,      0.7167
      42.9,      0.000,      0.000,         0,      7.2468,      0.7250
      43.1,      0.000,      0.000,         0,      7.3301,      0.7333
      43.3,      0.000,      0.000,         0,      7.4134,      0.7417
      43.5,      0.000,      0.000,         0,      7.4965,      0.7500
      43.7,      0.000,      0.000,         0,      7.5802,      0.7583
      43.9,      0.000,      0.000,         0,      7.6635,      0.7667
      44.2,      0.000,      0.000,         0,      7.7467,      0.7750
      44.4,      0.000,      0.000,         0,      7.8301,      0.7833
      44.6,      0.000,      0.000,         0,      7.9134,      0.7917
      44.8,      0.000,      0.000,         0,      7.9969,      0.8000
      45.0,      0.000,      0.000,         0,      8.0800,      0.8083
      45.2,      0.000,      0.000,         0,      8.1635,      0.8167
      45.4,      0.000,      0.000,         0,      8.2468,      0.8250
      45.6,      0.000,      0.000,         0,      8.3300,      0.8333
      45.8,      0.000,      0.000,         0,      8.4134,      0.8417
      46.0,      0.000,      0.000,         0,      8.4967,      0.8500
      46.2,      0.000,      0.000,         0,      8.5802,      0.8583
      46.4,      0.000,      0.000,         0,      8.6633,      0.8667
      46.6,      0.000,      0.000,         0,      8.7468,      0.8750
      46.8,      0.000,      0.000,         0,      8.8301,      0.8833
      47.0,      0.000,      0.000,         0,      8.9133,      0.8917
      47.2,      0.000,      0.000,         0,      8.9967,      0.9000
      47.4,      0.000,      0.000,         0,      9.0800,      0.9083
      47.6,      0.000,      0.000,         0,      9.1631,      0.9167
      47.8,      0.000,      0.000,         0,      9.2468,      0.9250
      48.0,      0.000,      0.000,         0,      9.3301,      0.9333
      48.2,      0.000,      0.000,         0,      9.4134,      0.9417
      48.4,      0.000,      0.000,         0,      9.4966,      0.9500
      48.6,      0.000,      0.000,         0,      9.5800,      0.9583
      48.8,      0.000,      0.000,         0,      9.6634,      0.9667
      49.0,      0.000,      0.000,         0,      9.7465,      0.9750
      49.2,      0.000,      0.000,         0,      9.8297,      0.9833
      49.4,      0.000,      0.000,         0,      9.9134,      0.9917
      49.6,      0.000,      0.000,         0,      9.9966,      1.0000
      49.8,      0.000,      0.000,         0,     10.0798,      1.0083
      50.0,      0.000,      0.000,         0,     10.1635,      1.0167
      50.2,      0.000,      0.000,         0,     10.2467,      1.0250
      50.5,      0.000,      0.000,         0,     10.3300,      1.0333
      50.7,      0.000,      0.000,         0,     10.4133,      1.0417
      50.9,      0.000,      0.000,         0,     10.4966,      1.0500
      51.1,      0.000,      0.000,         0,     10.5799,      1.0583
      51.3,      0.000,      0.000,         0,     10.6632,      1.0667
      51.5,      0.000,      0.000,         0,     10.7466,      1.0750
      51.6,      0.000,      0.000,         0,     10.8300,      1.0833
      51.8,      0.000,      0.000,         0,     10.9133,      1.0917
      52.0,      0.000,      0.000,         0,     10.9966,      1.1000
      52.2,      0.000,      0.000,         0,     11.0801,      1.1083
      52.3,      0.000,      0.000,         0,     11.1631,      1.1167
      52.5,      0.000,      0.000,         0,     11.2466,      1.1250
      52.6,      0.000,      0.000,         0,     11.3300,      1.1333
      52.7,      0.000,      0.000,         0,     11.4132,      1.1417
      52.9,      0.000,      0.000,         0,     11.4964,      1.1500
      53.0,      0.000,      0.000,         0,     11.5799,      1.1583
      53.1,      0.000,      0.000,         0,     11.6634,      1.1667
      53.2,      0.000,      0.000,         0,     11.7465,      1.1750
      53.3,      0.000,      0.000,         0,     11.8299,      1.1833
      53.4,      0.000,      0.000,         0,     11.9133,      1.1917
      53.5,      0.000,      0.000,         0,     11.9965,      1.2000
      53.6,      0.000,      0.000,         0,     12.0799,      1.2083
      53.6,      0.000,      0.000,         0,     12.1633,      1.2167
      53.7,      0.000,      0.000,         0,     12.2466,      1.2250
      53.7,      0.000,      0.000,         0,     12.3301,      1.2333
      53.8,      0.000,      0.000,         0,     12.4132,      1.2417
      53.8,      0.000,      0.000,         0,     12.4965,      1.2500
      53.8,      0.000,      0.000,         0,     12.5798,      1.2583
      53.8,      0.000,      0.000,         0,     12.6633,      1.2667
      53.7,      0.000,      0.000,         0,     12.7465,      1.2750
      53.7,      0.000,      0.000,         0,     12.8299,      1.2833
      53.6,      0.000,      0.000,         0,     12.9132,      1.2917
      53.5,      0.000,      0.000,         0,     12.9966,      1.3000
      53.4,      0.000,      0.000,         0,     13.0798,      1.3083
      53.2,      0.000,      0.000,         0,     13.1631,      1.3167
      53.0,      0.000,      0.000,         0,     13.2466,      1.3250
      52.7,      0.000,      0.000,         0,     13.3297,      1.3333
      52.3,      0.000,      0.000,         0,     13.4132,      1.3417
      51.7,      0.000,      0.000,         0,     13.4965,      1.3500
      50.9,      0.000,      0.000,         0,     13.5799,      1.3583
      49.5,      0.000,      0.000,         0,     13.6632,      1.3667
      46.8,      0.000,      0.000,         0,     13.7465,      1.3750
       0.9,      0.000,      0.000,         0,     13.8298,      1.3833
       0.0,      0.000,      0.000,         0,     13.9132,      1.3917
       0.0,      0.000,      0.000,         0,     13.9963,      1.4000
       0.0,      0.000,      0.000,         0,     14.0798,      1.4083
       0.0,      0.000,      0.000,         0,     14.1632,      1.4167
       0.0,      0.000,      0.000,         0,     14.2465,      1.4250
       0.0,      0.000,      0.000,         0,     14.3299,      1.4333