File: Alban repo/Quiz 1/suction cup instron tests/july-2020-force-vs-viscosity_raw-data/D30E10-01-in1-1x10-2-onwhiteplatic-diaphragmpump-10mm-test1.raw
Operator: 1

Date,Time,Specimen#
07/22/20,12:56:52,1

---------------------------------------


Area (mm^2):,      1.00,Flat,     25.40,     25.40,     25.40
Gage Len (mm):,     25.40


LOAD (N),STRAIN 1 (mm),STRAIN 2 (mm),STRESS (MPa),POSITION (mm),TIME (min)
       3.3,      0.000,      0.000,         0,      0.0816,      0.0083
       4.5,      0.000,      0.000,         0,      0.1648,      0.0167
       5.8,      0.000,      0.000,         0,      0.2482,      0.0250
       7.0,      0.000,      0.000,         0,      0.3315,      0.0333
       8.1,      0.000,      0.000,         0,      0.4150,      0.0417
       9.2,      0.000,      0.000,         0,      0.4984,      0.0500
      10.2,      0.000,      0.000,         0,      0.5814,      0.0583
      11.3,      0.000,      0.000,         0,      0.6647,      0.0667
      12.3,      0.000,      0.000,         0,      0.7482,      0.0750
      13.3,      0.000,      0.000,         0,      0.8316,      0.0833
      14.3,      0.000,      0.000,         0,      0.9147,      0.0917
      15.2,      0.000,      0.000,         0,      0.9983,      0.1000
      16.2,      0.000,      0.000,         0,      1.0816,      0.1083
      17.0,      0.000,      0.000,         0,      1.1649,      0.1167
      17.9,      0.000,      0.000,         0,      1.2481,      0.1250
      18.7,      0.000,      0.000,         0,      1.3316,      0.1333
      19.5,      0.000,      0.000,         0,      1.4148,      0.1417
      20.3,      0.000,      0.000,         0,      1.4981,      0.1500
      21.1,      0.000,      0.000,         0,      1.5814,      0.1583
      21.9,      0.000,      0.000,         0,      1.6647,      0.1667
      22.5,      0.000,      0.000,         0,      1.7482,      0.1750
      23.2,      0.000,      0.000,         0,      1.8316,      0.1833
      23.7,      0.000,      0.000,         0,      1.9145,      0.1917
      23.7,      0.000,      0.000,         0,      1.9979,      0.2000
      24.2,      0.000,      0.000,         0,      2.0815,      0.2083
      24.7,      0.000,      0.000,         0,      2.1649,      0.2167
      25.3,      0.000,      0.000,         0,      2.2482,      0.2250
      25.8,      0.000,      0.000,         0,      2.3315,      0.2333
      26.3,      0.000,      0.000,         0,      2.4148,      0.2417
      26.8,      0.000,      0.000,         0,      2.4982,      0.2500
      27.3,      0.000,      0.000,         0,      2.5813,      0.2583
      27.8,      0.000,      0.000,         0,      2.6647,      0.2667
      28.3,      0.000,      0.000,         0,      2.7481,      0.2750
      28.7,      0.000,      0.000,         0,      2.8314,      0.2833
      29.2,      0.000,      0.000,         0,      2.9146,      0.2917
      29.6,      0.000,      0.000,         0,      2.9982,      0.3000
      30.1,      0.000,      0.000,         0,      3.0814,      0.3083
      30.5,      0.000,      0.000,         0,      3.1649,      0.3167
      30.9,      0.000,      0.000,         0,      3.2481,      0.3250
      31.3,      0.000,      0.000,         0,      3.3314,      0.3333
      31.7,      0.000,      0.000,         0,      3.4147,      0.3417
      32.1,      0.000,      0.000,         0,      3.4981,      0.3500
      32.5,      0.000,      0.000,         0,      3.5814,      0.3583
      32.9,      0.000,      0.000,         0,      3.6648,      0.3667
      33.2,      0.000,      0.000,         0,      3.7482,      0.3750
      33.6,      0.000,      0.000,         0,      3.8314,      0.3833
      33.9,      0.000,      0.000,         0,      3.9148,      0.3917
      34.3,      0.000,      0.000,         0,      3.9982,      0.4000
      34.6,      0.000,      0.000,         0,      4.0814,      0.4083
      34.9,      0.000,      0.000,         0,      4.1646,      0.4167
      35.2,      0.000,      0.000,         0,      4.2481,      0.4250
      35.6,      0.000,      0.000,         0,      4.3314,      0.4333
      35.9,      0.000,      0.000,         0,      4.4147,      0.4417
      36.2,      0.000,      0.000,         0,      4.4981,      0.4500
      36.5,      0.000,      0.000,         0,      4.5815,      0.4583
      36.8,      0.000,      0.000,         0,      4.6646,      0.4667
      37.1,      0.000,      0.000,         0,      4.7480,      0.4750
      37.4,      0.000,      0.000,         0,      4.8314,      0.4833
      37.6,      0.000,      0.000,         0,      4.9147,      0.4917
      37.9,      0.000,      0.000,         0,      4.9980,      0.5000
      38.2,      0.000,      0.000,         0,      5.0814,      0.5083
      38.5,      0.000,      0.000,         0,      5.1649,      0.5167
      38.7,      0.000,      0.000,         0,      5.2478,      0.5250
      39.0,      0.000,      0.000,         0,      5.3314,      0.5333
      39.3,      0.000,      0.000,         0,      5.4147,      0.5417
      39.5,      0.000,      0.000,         0,      5.4981,      0.5500
      39.8,      0.000,      0.000,         0,      5.5811,      0.5583
      40.0,      0.000,      0.000,         0,      5.6648,      0.5667
      40.3,      0.000,      0.000,         0,      5.7480,      0.5750
      40.5,      0.000,      0.000,         0,      5.8313,      0.5833
      40.7,      0.000,      0.000,         0,      5.9144,      0.5917
      41.0,      0.000,      0.000,         0,      5.9982,      0.6000
      41.2,      0.000,      0.000,         0,      6.0814,      0.6083
      41.4,      0.000,      0.000,         0,      6.1645,      0.6167
      41.7,      0.000,      0.000,         0,      6.2480,      0.6250
      41.9,      0.000,      0.000,         0,      6.3314,      0.6333
      42.1,      0.000,      0.000,         0,      6.4146,      0.6417
      42.3,      0.000,      0.000,         0,      6.4979,      0.6500
      42.6,      0.000,      0.000,         0,      6.5813,      0.6583
      42.8,      0.000,      0.000,         0,      6.6645,      0.6667
      43.0,      0.000,      0.000,         0,      6.7481,      0.6750
      43.2,      0.000,      0.000,         0,      6.8313,      0.6833
      43.4,      0.000,      0.000,         0,      6.9147,      0.6917
      43.7,      0.000,      0.000,         0,      6.9979,      0.7000
      43.9,      0.000,      0.000,         0,      7.0814,      0.7083
      44.1,      0.000,      0.000,         0,      7.1646,      0.7167
      44.3,      0.000,      0.000,         0,      7.2477,      0.7250
      44.5,      0.000,      0.000,         0,      7.3313,      0.7333
      44.7,      0.000,      0.000,         0,      7.4146,      0.7417
      44.9,      0.000,      0.000,         0,      7.4980,      0.7500
      45.1,      0.000,      0.000,         0,      7.5811,      0.7583
      45.3,      0.000,      0.000,         0,      7.6646,      0.7667
      45.5,      0.000,      0.000,         0,      7.7480,      0.7750
      45.7,      0.000,      0.000,         0,      7.8314,      0.7833
      45.9,      0.000,      0.000,         0,      7.9145,      0.7917
      46.1,      0.000,      0.000,         0,      7.9979,      0.8000
      46.3,      0.000,      0.000,         0,      8.0811,      0.8083
      46.5,      0.000,      0.000,         0,      8.1645,      0.8167
      46.7,      0.000,      0.000,         0,      8.2479,      0.8250
      46.9,      0.000,      0.000,         0,      8.3312,      0.8333
      47.1,      0.000,      0.000,         0,      8.4147,      0.8417
      47.3,      0.000,      0.000,         0,      8.4979,      0.8500
      47.5,      0.000,      0.000,         0,      8.5811,      0.8583
      47.7,      0.000,      0.000,         0,      8.6646,      0.8667
      47.9,      0.000,      0.000,         0,      8.7480,      0.8750
      48.1,      0.000,      0.000,         0,      8.8311,      0.8833
      48.3,      0.000,      0.000,         0,      8.9146,      0.8917
      48.5,      0.000,      0.000,         0,      8.9978,      0.9000
      48.8,      0.000,      0.000,         0,      9.0812,      0.9083
      49.0,      0.000,      0.000,         0,      9.1644,      0.9167
      49.2,      0.000,      0.000,         0,      9.2477,      0.9250
      49.4,      0.000,      0.000,         0,      9.3312,      0.9333
      49.6,      0.000,      0.000,         0,      9.4145,      0.9417
      49.8,      0.000,      0.000,         0,      9.4978,      0.9500
      50.0,      0.000,      0.000,         0,      9.5812,      0.9583
      50.1,      0.000,      0.000,         0,      9.6645,      0.9667
      50.3,      0.000,      0.000,         0,      9.7478,      0.9750
      50.5,      0.000,      0.000,         0,      9.8311,      0.9833
      50.7,      0.000,      0.000,         0,      9.9144,      0.9917
      50.9,      0.000,      0.000,         0,      9.9978,      1.0000
      51.1,      0.000,      0.000,         0,     10.0811,      1.0083
      51.3,      0.000,      0.000,         0,     10.1645,      1.0167
      51.4,      0.000,      0.000,         0,     10.2477,      1.0250
      51.6,      0.000,      0.000,         0,     10.3312,      1.0333
      51.8,      0.000,      0.000,         0,     10.4144,      1.0417
      52.0,      0.000,      0.000,         0,     10.4978,      1.0500
      52.1,      0.000,      0.000,         0,     10.5812,      1.0583
      52.3,      0.000,      0.000,         0,     10.6644,      1.0667
      52.5,      0.000,      0.000,         0,     10.7478,      1.0750
      52.6,      0.000,      0.000,         0,     10.8311,      1.0833
      52.8,      0.000,      0.000,         0,     10.9146,      1.0917
      52.9,      0.000,      0.000,         0,     10.9978,      1.1000
      53.1,      0.000,      0.000,         0,     11.0812,      1.1083
      53.2,      0.000,      0.000,         0,     11.1643,      1.1167
      53.3,      0.000,      0.000,         0,     11.2478,      1.1250
      53.4,      0.000,      0.000,         0,     11.3310,      1.1333
      53.5,      0.000,      0.000,         0,     11.4145,      1.1417
      53.7,      0.000,      0.000,         0,     11.4977,      1.1500
      53.8,      0.000,      0.000,         0,     11.5811,      1.1583
      53.9,      0.000,      0.000,         0,     11.6645,      1.1667
      54.0,      0.000,      0.000,         0,     11.7477,      1.1750
      54.1,      0.000,      0.000,         0,     11.8306,      1.1833
      54.1,      0.000,      0.000,         0,     11.9145,      1.1917
      54.2,      0.000,      0.000,         0,     11.9978,      1.2000
      54.3,      0.000,      0.000,         0,     12.0810,      1.2083
      54.3,      0.000,      0.000,         0,     12.1645,      1.2167
      54.4,      0.000,      0.000,         0,     12.2476,      1.2250
      54.4,      0.000,      0.000,         0,     12.3310,      1.2333
      54.5,      0.000,      0.000,         0,     12.4143,      1.2417
      54.5,      0.000,      0.000,         0,     12.4977,      1.2500
      54.5,      0.000,      0.000,         0,     12.5810,      1.2583
      54.5,      0.000,      0.000,         0,     12.6644,      1.2667
      54.5,      0.000,      0.000,         0,     12.7475,      1.2750
      54.5,      0.000,      0.000,         0,     12.8311,      1.2833
      54.4,      0.000,      0.000,         0,     12.9144,      1.2917
      54.3,      0.000,      0.000,         0,     12.9978,      1.3000
      54.2,      0.000,      0.000,         0,     13.0812,      1.3083
      54.1,      0.000,      0.000,         0,     13.1641,      1.3167
      53.9,      0.000,      0.000,         0,     13.2474,      1.3250
      53.7,      0.000,      0.000,         0,     13.3310,      1.3333
      53.4,      0.000,      0.000,         0,     13.4143,      1.3417
      52.9,      0.000,      0.000,         0,     13.4975,      1.3500
      52.2,      0.000,      0.000,         0,     13.5812,      1.3583
      51.1,      0.000,      0.000,         0,     13.6642,      1.3667
      49.1,      0.000,      0.000,         0,     13.7475,      1.3750
      42.1,      0.000,      0.000,         0,     13.8310,      1.3833
       0.1,      0.000,      0.000,         0,     13.9144,      1.3917
       0.0,      0.000,      0.000,         0,     13.9977,      1.4000
       0.0,      0.000,      0.000,         0,     14.0808,      1.4083