File: Alban repo/Quiz 1/suction cup instron tests/july-2020-force-vs-viscosity_raw-data/D30E10-01-in1-1x10-2-onwhiteplatic-diaphragmpump-10mm-test3.raw
Operator: 1

Date,Time,Specimen#
07/22/20,13:04:16,1

---------------------------------------


Area (mm^2):,      1.00,Flat,     25.40,     25.40,     25.40
Gage Len (mm):,     25.40


LOAD (N),STRAIN 1 (mm),STRAIN 2 (mm),STRESS (MPa),POSITION (mm),TIME (min)
       3.3,      0.000,      0.000,         0,      0.0811,      0.0083
       4.5,      0.000,      0.000,         0,      0.1647,      0.0167
       5.7,      0.000,      0.000,         0,      0.2477,      0.0250
       6.9,      0.000,      0.000,         0,      0.3314,      0.0333
       8.0,      0.000,      0.000,         0,      0.4147,      0.0417
       9.1,      0.000,      0.000,         0,      0.4981,      0.0500
      10.1,      0.000,      0.000,         0,      0.5814,      0.0583
      11.2,      0.000,      0.000,         0,      0.6645,      0.0667
      12.2,      0.000,      0.000,         0,      0.7481,      0.0750
      13.2,      0.000,      0.000,         0,      0.8314,      0.0833
      14.1,      0.000,      0.000,         0,      0.9146,      0.0917
      15.0,      0.000,      0.000,         0,      0.9978,      0.1000
      15.9,      0.000,      0.000,         0,      1.0813,      0.1083
      16.8,      0.000,      0.000,         0,      1.1646,      0.1167
      17.7,      0.000,      0.000,         0,      1.2479,      0.1250
      18.6,      0.000,      0.000,         0,      1.3314,      0.1333
      19.4,      0.000,      0.000,         0,      1.4147,      0.1417
      20.2,      0.000,      0.000,         0,      1.4980,      0.1500
      21.0,      0.000,      0.000,         0,      1.5811,      0.1583
      21.7,      0.000,      0.000,         0,      1.6647,      0.1667
      22.4,      0.000,      0.000,         0,      1.7480,      0.1750
      23.0,      0.000,      0.000,         0,      1.8313,      0.1833
      23.5,      0.000,      0.000,         0,      1.9141,      0.1917
      23.8,      0.000,      0.000,         0,      1.9980,      0.2000
      23.5,      0.000,      0.000,         0,      2.0811,      0.2083
      24.0,      0.000,      0.000,         0,      2.1645,      0.2167
      24.6,      0.000,      0.000,         0,      2.2479,      0.2250
      25.1,      0.000,      0.000,         0,      2.3313,      0.2333
      25.6,      0.000,      0.000,         0,      2.4146,      0.2417
      26.1,      0.000,      0.000,         0,      2.4979,      0.2500
      26.6,      0.000,      0.000,         0,      2.5813,      0.2583
      27.1,      0.000,      0.000,         0,      2.6646,      0.2667
      27.6,      0.000,      0.000,         0,      2.7480,      0.2750
      28.0,      0.000,      0.000,         0,      2.8311,      0.2833
      28.5,      0.000,      0.000,         0,      2.9145,      0.2917
      28.9,      0.000,      0.000,         0,      2.9979,      0.3000
      29.4,      0.000,      0.000,         0,      3.0813,      0.3083
      29.8,      0.000,      0.000,         0,      3.1646,      0.3167
      30.2,      0.000,      0.000,         0,      3.2479,      0.3250
      30.6,      0.000,      0.000,         0,      3.3311,      0.3333
      31.0,      0.000,      0.000,         0,      3.4145,      0.3417
      31.4,      0.000,      0.000,         0,      3.4978,      0.3500
      31.8,      0.000,      0.000,         0,      3.5811,      0.3583
      32.2,      0.000,      0.000,         0,      3.6645,      0.3667
      32.5,      0.000,      0.000,         0,      3.7479,      0.3750
      32.9,      0.000,      0.000,         0,      3.8314,      0.3833
      33.3,      0.000,      0.000,         0,      3.9143,      0.3917
      33.6,      0.000,      0.000,         0,      3.9979,      0.4000
      34.0,      0.000,      0.000,         0,      4.0812,      0.4083
      34.3,      0.000,      0.000,         0,      4.1646,      0.4167
      34.6,      0.000,      0.000,         0,      4.2477,      0.4250
      35.0,      0.000,      0.000,         0,      4.3312,      0.4333
      35.3,      0.000,      0.000,         0,      4.4146,      0.4417
      35.6,      0.000,      0.000,         0,      4.4978,      0.4500
      35.9,      0.000,      0.000,         0,      4.5809,      0.4583
      36.3,      0.000,      0.000,         0,      4.6645,      0.4667
      36.6,      0.000,      0.000,         0,      4.7478,      0.4750
      36.9,      0.000,      0.000,         0,      4.8310,      0.4833
      37.2,      0.000,      0.000,         0,      4.9145,      0.4917
      37.5,      0.000,      0.000,         0,      4.9978,      0.5000
      37.7,      0.000,      0.000,         0,      5.0813,      0.5083
      38.0,      0.000,      0.000,         0,      5.1644,      0.5167
      38.3,      0.000,      0.000,         0,      5.2477,      0.5250
      38.6,      0.000,      0.000,         0,      5.3310,      0.5333
      38.8,      0.000,      0.000,         0,      5.4145,      0.5417
      39.1,      0.000,      0.000,         0,      5.4978,      0.5500
      39.4,      0.000,      0.000,         0,      5.5810,      0.5583
      39.6,      0.000,      0.000,         0,      5.6644,      0.5667
      39.9,      0.000,      0.000,         0,      5.7477,      0.5750
      40.1,      0.000,      0.000,         0,      5.8311,      0.5833
      40.4,      0.000,      0.000,         0,      5.9141,      0.5917
      40.6,      0.000,      0.000,         0,      5.9978,      0.6000
      40.8,      0.000,      0.000,         0,      6.0812,      0.6083
      41.1,      0.000,      0.000,         0,      6.1643,      0.6167
      41.3,      0.000,      0.000,         0,      6.2477,      0.6250
      41.5,      0.000,      0.000,         0,      6.3310,      0.6333
      41.8,      0.000,      0.000,         0,      6.4144,      0.6417
      42.0,      0.000,      0.000,         0,      6.4978,      0.6500
      42.2,      0.000,      0.000,         0,      6.5809,      0.6583
      42.5,      0.000,      0.000,         0,      6.6644,      0.6667
      42.7,      0.000,      0.000,         0,      6.7477,      0.6750
      42.9,      0.000,      0.000,         0,      6.8309,      0.6833
      43.1,      0.000,      0.000,         0,      6.9145,      0.6917
      43.4,      0.000,      0.000,         0,      6.9978,      0.7000
      43.6,      0.000,      0.000,         0,      7.0811,      0.7083
      43.8,      0.000,      0.000,         0,      7.1643,      0.7167
      44.0,      0.000,      0.000,         0,      7.2475,      0.7250
      44.3,      0.000,      0.000,         0,      7.3312,      0.7333
      44.5,      0.000,      0.000,         0,      7.4145,      0.7417
      44.7,      0.000,      0.000,         0,      7.4975,      0.7500
      44.9,      0.000,      0.000,         0,      7.5810,      0.7583
      45.1,      0.000,      0.000,         0,      7.6644,      0.7667
      45.3,      0.000,      0.000,         0,      7.7477,      0.7750
      45.5,      0.000,      0.000,         0,      7.8307,      0.7833
      45.7,      0.000,      0.000,         0,      7.9143,      0.7917
      45.9,      0.000,      0.000,         0,      7.9975,      0.8000
      46.1,      0.000,      0.000,         0,      8.0809,      0.8083
      46.4,      0.000,      0.000,         0,      8.1642,      0.8167
      46.6,      0.000,      0.000,         0,      8.2476,      0.8250
      46.8,      0.000,      0.000,         0,      8.3310,      0.8333
      47.0,      0.000,      0.000,         0,      8.4143,      0.8417
      47.2,      0.000,      0.000,         0,      8.4976,      0.8500
      47.4,      0.000,      0.000,         0,      8.5809,      0.8583
      47.6,      0.000,      0.000,         0,      8.6643,      0.8667
      47.8,      0.000,      0.000,         0,      8.7477,      0.8750
      48.1,      0.000,      0.000,         0,      8.8311,      0.8833
      48.3,      0.000,      0.000,         0,      8.9143,      0.8917
      48.5,      0.000,      0.000,         0,      8.9977,      0.9000
      48.7,      0.000,      0.000,         0,      9.0810,      0.9083
      49.0,      0.000,      0.000,         0,      9.1642,      0.9167
      49.2,      0.000,      0.000,         0,      9.2473,      0.9250
      49.4,      0.000,      0.000,         0,      9.3311,      0.9333
      49.6,      0.000,      0.000,         0,      9.4143,      0.9417
      49.9,      0.000,      0.000,         0,      9.4975,      0.9500
      50.1,      0.000,      0.000,         0,      9.5810,      0.9583
      50.3,      0.000,      0.000,         0,      9.6642,      0.9667
      50.6,      0.000,      0.000,         0,      9.7476,      0.9750
      50.8,      0.000,      0.000,         0,      9.8309,      0.9833
      51.0,      0.000,      0.000,         0,      9.9143,      0.9917
      51.2,      0.000,      0.000,         0,      9.9975,      1.0000
      51.5,      0.000,      0.000,         0,     10.0808,      1.0083
      51.7,      0.000,      0.000,         0,     10.1642,      1.0167
      51.9,      0.000,      0.000,         0,     10.2477,      1.0250
      52.1,      0.000,      0.000,         0,     10.3308,      1.0333
      52.3,      0.000,      0.000,         0,     10.4142,      1.0417
      52.5,      0.000,      0.000,         0,     10.4976,      1.0500
      52.7,      0.000,      0.000,         0,     10.5809,      1.0583
      52.8,      0.000,      0.000,         0,     10.6643,      1.0667
      53.0,      0.000,      0.000,         0,     10.7475,      1.0750
      53.2,      0.000,      0.000,         0,     10.8309,      1.0833
      53.4,      0.000,      0.000,         0,     10.9142,      1.0917
      53.5,      0.000,      0.000,         0,     10.9976,      1.1000
      53.7,      0.000,      0.000,         0,     11.0809,      1.1083
      53.8,      0.000,      0.000,         0,     11.1642,      1.1167
      54.0,      0.000,      0.000,         0,     11.2474,      1.1250
      54.1,      0.000,      0.000,         0,     11.3309,      1.1333
      54.2,      0.000,      0.000,         0,     11.4141,      1.1417
      54.4,      0.000,      0.000,         0,     11.4975,      1.1500
      54.5,      0.000,      0.000,         0,     11.5808,      1.1583
      54.6,      0.000,      0.000,         0,     11.6642,      1.1667
      54.7,      0.000,      0.000,         0,     11.7476,      1.1750
      54.8,      0.000,      0.000,         0,     11.8307,      1.1833
      54.9,      0.000,      0.000,         0,     11.9142,      1.1917
      55.0,      0.000,      0.000,         0,     11.9976,      1.2000
      55.0,      0.000,      0.000,         0,     12.0808,      1.2083
      55.1,      0.000,      0.000,         0,     12.1640,      1.2167
      55.1,      0.000,      0.000,         0,     12.2476,      1.2250
      55.2,      0.000,      0.000,         0,     12.3309,      1.2333
      55.2,      0.000,      0.000,         0,     12.4142,      1.2417
      55.2,      0.000,      0.000,         0,     12.4972,      1.2500
      55.3,      0.000,      0.000,         0,     12.5809,      1.2583
      55.2,      0.000,      0.000,         0,     12.6641,      1.2667
      55.2,      0.000,      0.000,         0,     12.7475,      1.2750
      55.2,      0.000,      0.000,         0,     12.8307,      1.2833
      55.2,      0.000,      0.000,         0,     12.9141,      1.2917
      55.1,      0.000,      0.000,         0,     12.9974,      1.3000
      55.0,      0.000,      0.000,         0,     13.0808,      1.3083
      54.9,      0.000,      0.000,         0,     13.1638,      1.3167
      54.7,      0.000,      0.000,         0,     13.2474,      1.3250
      54.5,      0.000,      0.000,         0,     13.3308,      1.3333
      54.2,      0.000,      0.000,         0,     13.4141,      1.3417
      53.8,      0.000,      0.000,         0,     13.4975,      1.3500
      53.1,      0.000,      0.000,         0,     13.5807,      1.3583
      52.1,      0.000,      0.000,         0,     13.6641,      1.3667
      50.1,      0.000,      0.000,         0,     13.7474,      1.3750
      44.1,      0.000,      0.000,         0,     13.8307,      1.3833
       0.0,      0.000,      0.000,         0,     13.9141,      1.3917
       0.0,      0.000,      0.000,         0,     13.9974,      1.4000
       0.0,      0.000,      0.000,         0,     14.0807,      1.4083
       0.0,      0.000,      0.000,         0,     14.1640,      1.4167