File: Alban repo/Quiz 1/suction cup instron tests/july-2020-force-vs-viscosity_raw-data/D30E10-01-inair-si-oil-onwhiteplatic-diaphragmpump-10mm-test2.raw
Operator: 1

Date,Time,Specimen#
07/22/20,16:22:09,1

---------------------------------------


Area (mm^2):,      1.00,Flat,     25.40,     25.40,     25.40
Gage Len (mm):,     25.40


LOAD (N),STRAIN 1 (mm),STRAIN 2 (mm),STRESS (MPa),POSITION (mm),TIME (min)
       3.8,      0.000,      0.000,         0,     -0.1617,      0.0083
       3.1,      0.000,      0.000,         0,     -0.3284,      0.0167
       2.4,      0.000,      0.000,         0,     -0.4951,      0.0250
       1.6,      0.000,      0.000,         0,     -0.6617,      0.0333
       0.8,      0.000,      0.000,         0,     -0.8284,      0.0417
      -0.2,      0.000,      0.000,         0,     -0.9950,      0.0500
      -1.6,      0.000,      0.000,         0,     -1.1617,      0.0583
      -3.3,      0.000,      0.000,         0,     -1.3284,      0.0667
      -5.3,      0.000,      0.000,         0,     -1.4948,      0.0750
      -7.5,      0.000,      0.000,         0,     -1.6616,      0.0833
      -9.8,      0.000,      0.000,         0,     -1.8283,      0.0917
     -12.4,      0.000,      0.000,         0,     -1.9949,      0.1000
     -18.8,      0.000,      0.000,         0,     -2.3776,      0.1244
     -20.0,      0.000,      0.000,         0,     -2.4628,      0.1410
     -18.7,      0.000,      0.000,         0,     -2.4943,      0.1577
     -18.6,      0.000,      0.000,         0,     -2.5094,      0.1744
     -18.3,      0.000,      0.000,         0,     -2.5094,      0.1910
     -18.0,      0.000,      0.000,         0,     -2.5093,      0.2077
     -17.8,      0.000,      0.000,         0,     -2.5093,      0.2244
     -17.7,      0.000,      0.000,         0,     -2.5093,      0.2410
     -17.5,      0.000,      0.000,         0,     -2.5093,      0.2577
     -16.5,      0.000,      0.000,         0,     -2.4588,      0.2744
     -12.8,      0.000,      0.000,         0,     -2.3051,      0.2910
     -11.5,      0.000,      0.000,         0,     -2.2237,      0.3077
     -11.1,      0.000,      0.000,         0,     -2.1861,      0.3244
     -11.0,      0.000,      0.000,         0,     -2.1709,      0.3410
     -11.1,      0.000,      0.000,         0,     -2.1705,      0.3577
     -10.7,      0.000,      0.000,         0,     -2.1551,      0.3660
      -9.9,      0.000,      0.000,         0,     -2.1148,      0.3744
      -9.0,      0.000,      0.000,         0,     -2.0589,      0.3827
      -7.7,      0.000,      0.000,         0,     -1.9946,      0.3910
      -6.4,      0.000,      0.000,         0,     -1.9200,      0.3994
      -5.2,      0.000,      0.000,         0,     -1.8448,      0.4077
      -4.1,      0.000,      0.000,         0,     -1.7658,      0.4160
      -3.1,      0.000,      0.000,         0,     -1.6824,      0.4244
      -2.5,      0.000,      0.000,         0,     -1.5999,      0.4327
      -1.6,      0.000,      0.000,         0,     -1.5157,      0.4410
      -0.9,      0.000,      0.000,         0,     -1.4325,      0.4494
      -0.1,      0.000,      0.000,         0,     -1.3493,      0.4577
       0.6,      0.000,      0.000,         0,     -1.2656,      0.4660
       1.3,      0.000,      0.000,         0,     -1.1824,      0.4744
       1.9,      0.000,      0.000,         0,     -1.0992,      0.4827
       2.6,      0.000,      0.000,         0,     -1.0158,      0.4910
       3.2,      0.000,      0.000,         0,     -0.9324,      0.4994
       3.7,      0.000,      0.000,         0,     -0.8492,      0.5077
       4.3,      0.000,      0.000,         0,     -0.7657,      0.5160
       4.9,      0.000,      0.000,         0,     -0.6825,      0.5244
       5.5,      0.000,      0.000,         0,     -0.5991,      0.5327
       6.0,      0.000,      0.000,         0,     -0.5157,      0.5410
       6.5,      0.000,      0.000,         0,     -0.4323,      0.5494
       7.1,      0.000,      0.000,         0,     -0.3493,      0.5577
       7.1,      0.000,      0.000,         0,     -0.2658,      0.5660
       6.8,      0.000,      0.000,         0,     -0.1824,      0.5744
       6.5,      0.000,      0.000,         0,     -0.0992,      0.5827
       6.4,      0.000,      0.000,         0,     -0.0158,      0.5910
       6.3,      0.000,      0.000,         0,      0.0675,      0.5994
       6.3,      0.000,      0.000,         0,      0.1510,      0.6077
       6.5,      0.000,      0.000,         0,      0.2341,      0.6160
       6.6,      0.000,      0.000,         0,      0.3171,      0.6244
       6.8,      0.000,      0.000,         0,      0.4008,      0.6327
       7.1,      0.000,      0.000,         0,      0.4843,      0.6410
       7.2,      0.000,      0.000,         0,      0.5673,      0.6494
       7.4,      0.000,      0.000,         0,      0.6508,      0.6577
       7.6,      0.000,      0.000,         0,      0.7342,      0.6660
       7.8,      0.000,      0.000,         0,      0.8176,      0.6744
       8.0,      0.000,      0.000,         0,      0.9008,      0.6827
       8.2,      0.000,      0.000,         0,      0.9842,      0.6910
       8.3,      0.000,      0.000,         0,      1.0675,      0.6994
       8.5,      0.000,      0.000,         0,      1.1509,      0.7077
       8.7,      0.000,      0.000,         0,      1.2341,      0.7160
       8.8,      0.000,      0.000,         0,      1.3175,      0.7244
       9.0,      0.000,      0.000,         0,      1.4009,      0.7327
       9.1,      0.000,      0.000,         0,      1.4842,      0.7410
       9.3,      0.000,      0.000,         0,      1.5675,      0.7494
       9.4,      0.000,      0.000,         0,      1.6506,      0.7577
       9.6,      0.000,      0.000,         0,      1.7342,      0.7660
       9.7,      0.000,      0.000,         0,      1.8175,      0.7744
       9.9,      0.000,      0.000,         0,      1.9008,      0.7827
      10.0,      0.000,      0.000,         0,      1.9838,      0.7910
      10.1,      0.000,      0.000,         0,      2.0673,      0.7994
      10.2,      0.000,      0.000,         0,      2.1508,      0.8077
      10.3,      0.000,      0.000,         0,      2.2341,      0.8160
      10.5,      0.000,      0.000,         0,      2.3173,      0.8244
      10.6,      0.000,      0.000,         0,      2.4008,      0.8327
      10.7,      0.000,      0.000,         0,      2.4841,      0.8410
      10.8,      0.000,      0.000,         0,      2.5674,      0.8494
      10.9,      0.000,      0.000,         0,      2.6507,      0.8577
      11.0,      0.000,      0.000,         0,      2.7340,      0.8660
      11.1,      0.000,      0.000,         0,      2.8175,      0.8744
      11.2,      0.000,      0.000,         0,      2.9007,      0.8827
      11.3,      0.000,      0.000,         0,      2.9839,      0.8910
      11.3,      0.000,      0.000,         0,      3.0673,      0.8994
      11.4,      0.000,      0.000,         0,      3.1509,      0.9077
      11.5,      0.000,      0.000,         0,      3.2338,      0.9160
      11.6,      0.000,      0.000,         0,      3.3174,      0.9244
      11.6,      0.000,      0.000,         0,      3.4009,      0.9327
      11.7,      0.000,      0.000,         0,      3.4841,      0.9410
      11.8,      0.000,      0.000,         0,      3.5673,      0.9494
      11.8,      0.000,      0.000,         0,      3.6506,      0.9577
      11.9,      0.000,      0.000,         0,      3.7341,      0.9660
      11.9,      0.000,      0.000,         0,      3.8171,      0.9744
      11.9,      0.000,      0.000,         0,      3.9007,      0.9827
      12.0,      0.000,      0.000,         0,      3.9840,      0.9910
      12.0,      0.000,      0.000,         0,      4.0674,      0.9994
      12.1,      0.000,      0.000,         0,      4.1506,      1.0077
      12.1,      0.000,      0.000,         0,      4.2340,      1.0160
      12.1,      0.000,      0.000,         0,      4.3168,      1.0244
      12.1,      0.000,      0.000,         0,      4.4007,      1.0327
      12.1,      0.000,      0.000,         0,      4.4840,      1.0410
      12.2,      0.000,      0.000,         0,      4.5673,      1.0494
      12.1,      0.000,      0.000,         0,      4.6507,      1.0577
      12.2,      0.000,      0.000,         0,      4.7339,      1.0660
      12.1,      0.000,      0.000,         0,      4.8174,      1.0744
      12.1,      0.000,      0.000,         0,      4.9006,      1.0827
      12.1,      0.000,      0.000,         0,      4.9838,      1.0910
      12.1,      0.000,      0.000,         0,      5.0673,      1.0994
      12.1,      0.000,      0.000,         0,      5.1506,      1.1077
      12.1,      0.000,      0.000,         0,      5.2336,      1.1160
      12.0,      0.000,      0.000,         0,      5.3172,      1.1244
      12.0,      0.000,      0.000,         0,      5.4006,      1.1327
      12.0,      0.000,      0.000,         0,      5.4840,      1.1410
      11.9,      0.000,      0.000,         0,      5.5673,      1.1494
      11.9,      0.000,      0.000,         0,      5.6506,      1.1577
      11.8,      0.000,      0.000,         0,      5.7340,      1.1660
      11.8,      0.000,      0.000,         0,      5.8173,      1.1744
      11.7,      0.000,      0.000,         0,      5.9003,      1.1827
      11.7,      0.000,      0.000,         0,      5.9838,      1.1910
      11.6,      0.000,      0.000,         0,      6.0673,      1.1994
      11.6,      0.000,      0.000,         0,      6.1505,      1.2077
      11.6,      0.000,      0.000,         0,      6.2338,      1.2160
      11.6,      0.000,      0.000,         0,      6.3172,      1.2244
      11.5,      0.000,      0.000,         0,      6.4007,      1.2327
      11.6,      0.000,      0.000,         0,      6.4838,      1.2410
      11.6,      0.000,      0.000,         0,      6.5672,      1.2494
      11.6,      0.000,      0.000,         0,      6.6506,      1.2577
      11.6,      0.000,      0.000,         0,      6.7338,      1.2660
      11.6,      0.000,      0.000,         0,      6.8172,      1.2744
      11.7,      0.000,      0.000,         0,      6.9004,      1.2827
      11.8,      0.000,      0.000,         0,      6.9838,      1.2910
      11.8,      0.000,      0.000,         0,      7.0671,      1.2994
      11.9,      0.000,      0.000,         0,      7.1506,      1.3077
      12.0,      0.000,      0.000,         0,      7.2339,      1.3160
      12.1,      0.000,      0.000,         0,      7.3172,      1.3244
      12.2,      0.000,      0.000,         0,      7.4003,      1.3327
      12.3,      0.000,      0.000,         0,      7.4839,      1.3410
      12.5,      0.000,      0.000,         0,      7.5671,      1.3494
      12.6,      0.000,      0.000,         0,      7.6500,      1.3577
      12.7,      0.000,      0.000,         0,      7.7340,      1.3660
      12.9,      0.000,      0.000,         0,      7.8173,      1.3744
      13.0,      0.000,      0.000,         0,      7.9004,      1.3827
      13.2,      0.000,      0.000,         0,      7.9838,      1.3910
      13.3,      0.000,      0.000,         0,      8.0672,      1.3994
      13.5,      0.000,      0.000,         0,      8.1504,      1.4077
      13.7,      0.000,      0.000,         0,      8.2338,      1.4160
      13.9,      0.000,      0.000,         0,      8.3171,      1.4244
      14.0,      0.000,      0.000,         0,      8.4006,      1.4327
      14.2,      0.000,      0.000,         0,      8.4835,      1.4410
      14.4,      0.000,      0.000,         0,      8.5672,      1.4494
      14.6,      0.000,      0.000,         0,      8.6505,      1.4577
      14.7,      0.000,      0.000,         0,      8.7338,      1.4660
      14.9,      0.000,      0.000,         0,      8.8172,      1.4744
      15.0,      0.000,      0.000,         0,      8.9004,      1.4827
      15.2,      0.000,      0.000,         0,      8.9837,      1.4910
      15.3,      0.000,      0.000,         0,      9.0672,      1.4994
       1.1,      0.000,      0.000,         0,      9.1505,      1.5077
       0.0,      0.000,      0.000,         0,      9.2337,      1.5160
       0.0,      0.000,      0.000,         0,      9.3171,      1.5244
       0.0,      0.000,      0.000,         0,      9.4003,      1.5327