File: Alban repo/Quiz 1/suction cup instron tests/july-2020-force-vs-viscosity_raw-data/D30E10-01-in6-1x10-3-onwhiteplatic-diaphragmpump-10mm-test2.raw
Operator: 1

Date,Time,Specimen#
07/22/20,13:37:27,1

---------------------------------------


Area (mm^2):,      1.00,Flat,     25.40,     25.40,     25.40
Gage Len (mm):,     25.40


LOAD (N),STRAIN 1 (mm),STRAIN 2 (mm),STRESS (MPa),POSITION (mm),TIME (min)
       3.2,      0.000,      0.000,         0,      0.0803,      0.0083
       4.4,      0.000,      0.000,         0,      0.1635,      0.0167
       5.6,      0.000,      0.000,         0,      0.2470,      0.0250
       6.7,      0.000,      0.000,         0,      0.3303,      0.0333
       7.7,      0.000,      0.000,         0,      0.4136,      0.0417
       8.7,      0.000,      0.000,         0,      0.4969,      0.0500
       9.7,      0.000,      0.000,         0,      0.5802,      0.0583
      10.7,      0.000,      0.000,         0,      0.6637,      0.0667
      11.7,      0.000,      0.000,         0,      0.7468,      0.0750
      12.6,      0.000,      0.000,         0,      0.8303,      0.0833
      13.5,      0.000,      0.000,         0,      0.9136,      0.0917
      14.4,      0.000,      0.000,         0,      0.9969,      0.1000
      15.3,      0.000,      0.000,         0,      1.0802,      0.1083
      16.1,      0.000,      0.000,         0,      1.1637,      0.1167
      16.9,      0.000,      0.000,         0,      1.2468,      0.1250
      17.7,      0.000,      0.000,         0,      1.3303,      0.1333
      18.5,      0.000,      0.000,         0,      1.4137,      0.1417
      19.2,      0.000,      0.000,         0,      1.4968,      0.1500
      19.8,      0.000,      0.000,         0,      1.5801,      0.1583
      20.3,      0.000,      0.000,         0,      1.6635,      0.1667
      20.7,      0.000,      0.000,         0,      1.7470,      0.1750
      20.3,      0.000,      0.000,         0,      1.8299,      0.1833
      20.8,      0.000,      0.000,         0,      1.9132,      0.1917
      21.3,      0.000,      0.000,         0,      1.9969,      0.2000
      21.9,      0.000,      0.000,         0,      2.0803,      0.2083
      22.4,      0.000,      0.000,         0,      2.1633,      0.2167
      22.9,      0.000,      0.000,         0,      2.2469,      0.2250
      23.4,      0.000,      0.000,         0,      2.3303,      0.2333
      23.9,      0.000,      0.000,         0,      2.4135,      0.2417
      24.3,      0.000,      0.000,         0,      2.4966,      0.2500
      24.8,      0.000,      0.000,         0,      2.5802,      0.2583
      25.3,      0.000,      0.000,         0,      2.6636,      0.2667
      25.7,      0.000,      0.000,         0,      2.7468,      0.2750
      26.2,      0.000,      0.000,         0,      2.8300,      0.2833
      26.6,      0.000,      0.000,         0,      2.9134,      0.2917
      27.0,      0.000,      0.000,         0,      2.9968,      0.3000
      27.5,      0.000,      0.000,         0,      3.0801,      0.3083
      27.9,      0.000,      0.000,         0,      3.1635,      0.3167
      28.3,      0.000,      0.000,         0,      3.2466,      0.3250
      28.6,      0.000,      0.000,         0,      3.3301,      0.3333
      29.0,      0.000,      0.000,         0,      3.4135,      0.3417
      29.4,      0.000,      0.000,         0,      3.4967,      0.3500
      29.8,      0.000,      0.000,         0,      3.5800,      0.3583
      30.2,      0.000,      0.000,         0,      3.6634,      0.3667
      30.5,      0.000,      0.000,         0,      3.7468,      0.3750
      30.9,      0.000,      0.000,         0,      3.8301,      0.3833
      31.2,      0.000,      0.000,         0,      3.9132,      0.3917
      31.6,      0.000,      0.000,         0,      3.9968,      0.4000
      31.9,      0.000,      0.000,         0,      4.0802,      0.4083
      32.3,      0.000,      0.000,         0,      4.1635,      0.4167
      32.6,      0.000,      0.000,         0,      4.2467,      0.4250
      32.9,      0.000,      0.000,         0,      4.3301,      0.4333
      33.2,      0.000,      0.000,         0,      4.4136,      0.4417
      33.6,      0.000,      0.000,         0,      4.4967,      0.4500
      33.9,      0.000,      0.000,         0,      4.5801,      0.4583
      34.2,      0.000,      0.000,         0,      4.6634,      0.4667
      34.5,      0.000,      0.000,         0,      4.7469,      0.4750
      34.8,      0.000,      0.000,         0,      4.8300,      0.4833
      35.1,      0.000,      0.000,         0,      4.9134,      0.4917
      35.4,      0.000,      0.000,         0,      4.9969,      0.5000
      35.7,      0.000,      0.000,         0,      5.0801,      0.5083
      36.0,      0.000,      0.000,         0,      5.1634,      0.5167
      36.3,      0.000,      0.000,         0,      5.2468,      0.5250
      36.5,      0.000,      0.000,         0,      5.3301,      0.5333
      36.8,      0.000,      0.000,         0,      5.4131,      0.5417
      37.1,      0.000,      0.000,         0,      5.4968,      0.5500
      37.3,      0.000,      0.000,         0,      5.5801,      0.5583
      37.6,      0.000,      0.000,         0,      5.6634,      0.5667
      37.9,      0.000,      0.000,         0,      5.7466,      0.5750
      38.1,      0.000,      0.000,         0,      5.8301,      0.5833
      38.4,      0.000,      0.000,         0,      5.9134,      0.5917
      38.7,      0.000,      0.000,         0,      5.9967,      0.6000
      38.9,      0.000,      0.000,         0,      6.0800,      0.6083
      39.2,      0.000,      0.000,         0,      6.1633,      0.6167
      39.4,      0.000,      0.000,         0,      6.2467,      0.6250
      39.7,      0.000,      0.000,         0,      6.3300,      0.6333
      39.9,      0.000,      0.000,         0,      6.4135,      0.6417
      40.1,      0.000,      0.000,         0,      6.4964,      0.6500
      40.4,      0.000,      0.000,         0,      6.5800,      0.6583
      40.6,      0.000,      0.000,         0,      6.6634,      0.6667
      40.9,      0.000,      0.000,         0,      6.7467,      0.6750
      41.1,      0.000,      0.000,         0,      6.8298,      0.6833
      41.3,      0.000,      0.000,         0,      6.9135,      0.6917
      41.6,      0.000,      0.000,         0,      6.9966,      0.7000
      41.8,      0.000,      0.000,         0,      7.0799,      0.7083
      42.0,      0.000,      0.000,         0,      7.1633,      0.7167
      42.2,      0.000,      0.000,         0,      7.2466,      0.7250
      42.5,      0.000,      0.000,         0,      7.3301,      0.7333
      42.7,      0.000,      0.000,         0,      7.4133,      0.7417
      42.9,      0.000,      0.000,         0,      7.4964,      0.7500
      43.1,      0.000,      0.000,         0,      7.5800,      0.7583
      43.3,      0.000,      0.000,         0,      7.6633,      0.7667
      43.5,      0.000,      0.000,         0,      7.7466,      0.7750
      43.8,      0.000,      0.000,         0,      7.8298,      0.7833
      44.0,      0.000,      0.000,         0,      7.9133,      0.7917
      44.2,      0.000,      0.000,         0,      7.9967,      0.8000
      44.4,      0.000,      0.000,         0,      8.0799,      0.8083
      44.6,      0.000,      0.000,         0,      8.1632,      0.8167
      44.8,      0.000,      0.000,         0,      8.2465,      0.8250
      45.0,      0.000,      0.000,         0,      8.3300,      0.8333
      45.3,      0.000,      0.000,         0,      8.4133,      0.8417
      45.5,      0.000,      0.000,         0,      8.4964,      0.8500
      45.7,      0.000,      0.000,         0,      8.5799,      0.8583
      45.9,      0.000,      0.000,         0,      8.6632,      0.8667
      46.1,      0.000,      0.000,         0,      8.7467,      0.8750
      46.3,      0.000,      0.000,         0,      8.8299,      0.8833
      46.4,      0.000,      0.000,         0,      8.9131,      0.8917
      46.6,      0.000,      0.000,         0,      8.9965,      0.9000
      46.8,      0.000,      0.000,         0,      9.0800,      0.9083
      47.0,      0.000,      0.000,         0,      9.1628,      0.9167
      47.2,      0.000,      0.000,         0,      9.2466,      0.9250
      47.4,      0.000,      0.000,         0,      9.3299,      0.9333
      47.6,      0.000,      0.000,         0,      9.4133,      0.9417
      47.8,      0.000,      0.000,         0,      9.4965,      0.9500
      48.0,      0.000,      0.000,         0,      9.5799,      0.9583
      48.2,      0.000,      0.000,         0,      9.6634,      0.9667
      48.3,      0.000,      0.000,         0,      9.7464,      0.9750
      48.6,      0.000,      0.000,         0,      9.8298,      0.9833
      48.8,      0.000,      0.000,         0,      9.9133,      0.9917
      49.0,      0.000,      0.000,         0,      9.9966,      1.0000
      49.2,      0.000,      0.000,         0,     10.0796,      1.0083
      49.4,      0.000,      0.000,         0,     10.1632,      1.0167
      49.6,      0.000,      0.000,         0,     10.2466,      1.0250
      49.9,      0.000,      0.000,         0,     10.3298,      1.0333
      50.1,      0.000,      0.000,         0,     10.4131,      1.0417
      50.3,      0.000,      0.000,         0,     10.4964,      1.0500
      50.5,      0.000,      0.000,         0,     10.5798,      1.0583
      50.8,      0.000,      0.000,         0,     10.6632,      1.0667
      51.0,      0.000,      0.000,         0,     10.7463,      1.0750
      51.2,      0.000,      0.000,         0,     10.8299,      1.0833
      51.4,      0.000,      0.000,         0,     10.9131,      1.0917
      51.6,      0.000,      0.000,         0,     10.9965,      1.1000
      51.8,      0.000,      0.000,         0,     11.0798,      1.1083
      52.0,      0.000,      0.000,         0,     11.1630,      1.1167
      52.2,      0.000,      0.000,         0,     11.2465,      1.1250
      52.4,      0.000,      0.000,         0,     11.3298,      1.1333
      52.5,      0.000,      0.000,         0,     11.4132,      1.1417
      52.7,      0.000,      0.000,         0,     11.4963,      1.1500
      52.9,      0.000,      0.000,         0,     11.5798,      1.1583
      53.0,      0.000,      0.000,         0,     11.6632,      1.1667
      53.1,      0.000,      0.000,         0,     11.7463,      1.1750
      53.2,      0.000,      0.000,         0,     11.8296,      1.1833
      53.4,      0.000,      0.000,         0,     11.9130,      1.1917
      53.5,      0.000,      0.000,         0,     11.9963,      1.2000
      53.6,      0.000,      0.000,         0,     12.0797,      1.2083
      53.6,      0.000,      0.000,         0,     12.1630,      1.2167
      53.7,      0.000,      0.000,         0,     12.2464,      1.2250
      53.8,      0.000,      0.000,         0,     12.3299,      1.2333
      53.8,      0.000,      0.000,         0,     12.4129,      1.2417
      53.8,      0.000,      0.000,         0,     12.4964,      1.2500
      53.9,      0.000,      0.000,         0,     12.5798,      1.2583
      53.9,      0.000,      0.000,         0,     12.6631,      1.2667
      53.9,      0.000,      0.000,         0,     12.7464,      1.2750
      53.8,      0.000,      0.000,         0,     12.8297,      1.2833
      53.8,      0.000,      0.000,         0,     12.9131,      1.2917
      53.7,      0.000,      0.000,         0,     12.9963,      1.3000
      53.5,      0.000,      0.000,         0,     13.0798,      1.3083
      53.4,      0.000,      0.000,         0,     13.1625,      1.3167
      53.2,      0.000,      0.000,         0,     13.2464,      1.3250
      52.9,      0.000,      0.000,         0,     13.3296,      1.3333
      52.5,      0.000,      0.000,         0,     13.4127,      1.3417
      51.9,      0.000,      0.000,         0,     13.4964,      1.3500
      51.1,      0.000,      0.000,         0,     13.5798,      1.3583
      49.8,      0.000,      0.000,         0,     13.6630,      1.3667
      47.3,      0.000,      0.000,         0,     13.7465,      1.3750
      31.4,      0.000,      0.000,         0,     13.8295,      1.3833
       0.0,      0.000,      0.000,         0,     13.9131,      1.3917
       0.0,      0.000,      0.000,         0,     13.9962,      1.4000
       0.0,      0.000,      0.000,         0,     14.0796,      1.4083
       0.0,      0.000,      0.000,         0,     14.1629,      1.4167
       0.0,      0.000,      0.000,         0,     14.2463,      1.4250
       0.0,      0.000,      0.000,         0,     14.3297,      1.4333