File: Alban repo/Quiz 1/suction cup instron tests/july-2020-force-vs-viscosity_raw-data/D30E10-01-in10-1-onwhiteplatic-diaphragmpump-10mm-test4.raw
Operator: 1

Date,Time,Specimen#
07/22/20,12:40:03,1

---------------------------------------


Area (mm^2):,      1.00,Flat,     25.40,     25.40,     25.40
Gage Len (mm):,     25.40


LOAD (N),STRAIN 1 (mm),STRAIN 2 (mm),STRESS (MPa),POSITION (mm),TIME (min)
       3.3,      0.000,      0.000,         0,      0.0815,      0.0083
       4.6,      0.000,      0.000,         0,      0.1648,      0.0167
       5.8,      0.000,      0.000,         0,      0.2481,      0.0250
       7.0,      0.000,      0.000,         0,      0.3316,      0.0333
       8.2,      0.000,      0.000,         0,      0.4148,      0.0417
       9.3,      0.000,      0.000,         0,      0.4982,      0.0500
      10.3,      0.000,      0.000,         0,      0.5814,      0.0583
      11.4,      0.000,      0.000,         0,      0.6649,      0.0667
      12.4,      0.000,      0.000,         0,      0.7479,      0.0750
      13.5,      0.000,      0.000,         0,      0.8316,      0.0833
      14.4,      0.000,      0.000,         0,      0.9146,      0.0917
      15.4,      0.000,      0.000,         0,      0.9981,      0.1000
      16.3,      0.000,      0.000,         0,      1.0815,      0.1083
      17.2,      0.000,      0.000,         0,      1.1648,      0.1167
      18.1,      0.000,      0.000,         0,      1.2482,      0.1250
      19.0,      0.000,      0.000,         0,      1.3314,      0.1333
      19.8,      0.000,      0.000,         0,      1.4149,      0.1417
      20.7,      0.000,      0.000,         0,      1.4982,      0.1500
      21.5,      0.000,      0.000,         0,      1.5815,      0.1583
      22.2,      0.000,      0.000,         0,      1.6647,      0.1667
      23.0,      0.000,      0.000,         0,      1.7483,      0.1750
      23.7,      0.000,      0.000,         0,      1.8315,      0.1833
      24.4,      0.000,      0.000,         0,      1.9144,      0.1917
      25.1,      0.000,      0.000,         0,      1.9978,      0.2000
      25.7,      0.000,      0.000,         0,      2.0815,      0.2083
      26.4,      0.000,      0.000,         0,      2.1646,      0.2167
      27.0,      0.000,      0.000,         0,      2.2481,      0.2250
      27.5,      0.000,      0.000,         0,      2.3314,      0.2333
      27.9,      0.000,      0.000,         0,      2.4148,      0.2417
      28.2,      0.000,      0.000,         0,      2.4981,      0.2500
      27.5,      0.000,      0.000,         0,      2.5814,      0.2583
      27.8,      0.000,      0.000,         0,      2.6649,      0.2667
      28.2,      0.000,      0.000,         0,      2.7479,      0.2750
      28.6,      0.000,      0.000,         0,      2.8314,      0.2833
      29.0,      0.000,      0.000,         0,      2.9148,      0.2917
      29.5,      0.000,      0.000,         0,      2.9981,      0.3000
      29.9,      0.000,      0.000,         0,      3.0813,      0.3083
      30.3,      0.000,      0.000,         0,      3.1648,      0.3167
      30.7,      0.000,      0.000,         0,      3.2480,      0.3250
      31.1,      0.000,      0.000,         0,      3.3313,      0.3333
      31.4,      0.000,      0.000,         0,      3.4149,      0.3417
      31.8,      0.000,      0.000,         0,      3.4980,      0.3500
      32.2,      0.000,      0.000,         0,      3.5811,      0.3583
      32.5,      0.000,      0.000,         0,      3.6647,      0.3667
      32.9,      0.000,      0.000,         0,      3.7480,      0.3750
      33.2,      0.000,      0.000,         0,      3.8314,      0.3833
      33.6,      0.000,      0.000,         0,      3.9147,      0.3917
      33.9,      0.000,      0.000,         0,      3.9980,      0.4000
      34.2,      0.000,      0.000,         0,      4.0814,      0.4083
      34.6,      0.000,      0.000,         0,      4.1645,      0.4167
      34.9,      0.000,      0.000,         0,      4.2480,      0.4250
      35.2,      0.000,      0.000,         0,      4.3313,      0.4333
      35.5,      0.000,      0.000,         0,      4.4146,      0.4417
      35.8,      0.000,      0.000,         0,      4.4980,      0.4500
      36.1,      0.000,      0.000,         0,      4.5813,      0.4583
      36.4,      0.000,      0.000,         0,      4.6647,      0.4667
      36.7,      0.000,      0.000,         0,      4.7481,      0.4750
      37.0,      0.000,      0.000,         0,      4.8313,      0.4833
      37.2,      0.000,      0.000,         0,      4.9145,      0.4917
      37.5,      0.000,      0.000,         0,      4.9980,      0.5000
      37.8,      0.000,      0.000,         0,      5.0814,      0.5083
      38.1,      0.000,      0.000,         0,      5.1645,      0.5167
      38.3,      0.000,      0.000,         0,      5.2478,      0.5250
      38.6,      0.000,      0.000,         0,      5.3314,      0.5333
      38.8,      0.000,      0.000,         0,      5.4146,      0.5417
      39.1,      0.000,      0.000,         0,      5.4980,      0.5500
      39.3,      0.000,      0.000,         0,      5.5813,      0.5583
      39.6,      0.000,      0.000,         0,      5.6645,      0.5667
      39.8,      0.000,      0.000,         0,      5.7479,      0.5750
      40.1,      0.000,      0.000,         0,      5.8314,      0.5833
      40.3,      0.000,      0.000,         0,      5.9144,      0.5917
      40.5,      0.000,      0.000,         0,      5.9978,      0.6000
      40.8,      0.000,      0.000,         0,      6.0814,      0.6083
      41.0,      0.000,      0.000,         0,      6.1646,      0.6167
      41.2,      0.000,      0.000,         0,      6.2479,      0.6250
      41.4,      0.000,      0.000,         0,      6.3312,      0.6333
      41.7,      0.000,      0.000,         0,      6.4146,      0.6417
      41.9,      0.000,      0.000,         0,      6.4980,      0.6500
      42.1,      0.000,      0.000,         0,      6.5810,      0.6583
      42.3,      0.000,      0.000,         0,      6.6646,      0.6667
      42.5,      0.000,      0.000,         0,      6.7479,      0.6750
      42.8,      0.000,      0.000,         0,      6.8312,      0.6833
      43.0,      0.000,      0.000,         0,      6.9146,      0.6917
      43.2,      0.000,      0.000,         0,      6.9980,      0.7000
      43.4,      0.000,      0.000,         0,      7.0811,      0.7083
      43.6,      0.000,      0.000,         0,      7.1646,      0.7167
      43.9,      0.000,      0.000,         0,      7.2478,      0.7250
      44.1,      0.000,      0.000,         0,      7.3312,      0.7333
      44.3,      0.000,      0.000,         0,      7.4145,      0.7417
      44.5,      0.000,      0.000,         0,      7.4979,      0.7500
      44.7,      0.000,      0.000,         0,      7.5808,      0.7583
      44.9,      0.000,      0.000,         0,      7.6645,      0.7667
      45.1,      0.000,      0.000,         0,      7.7479,      0.7750
      45.4,      0.000,      0.000,         0,      7.8311,      0.7833
      45.6,      0.000,      0.000,         0,      7.9145,      0.7917
      45.8,      0.000,      0.000,         0,      7.9979,      0.8000
      46.0,      0.000,      0.000,         0,      8.0812,      0.8083
      46.2,      0.000,      0.000,         0,      8.1645,      0.8167
      46.4,      0.000,      0.000,         0,      8.2478,      0.8250
      46.7,      0.000,      0.000,         0,      8.3311,      0.8333
      46.9,      0.000,      0.000,         0,      8.4145,      0.8417
      47.1,      0.000,      0.000,         0,      8.4976,      0.8500
      47.3,      0.000,      0.000,         0,      8.5812,      0.8583
      47.5,      0.000,      0.000,         0,      8.6643,      0.8667
      47.8,      0.000,      0.000,         0,      8.7478,      0.8750
      48.0,      0.000,      0.000,         0,      8.8311,      0.8833
      48.2,      0.000,      0.000,         0,      8.9145,      0.8917
      48.4,      0.000,      0.000,         0,      8.9978,      0.9000
      48.6,      0.000,      0.000,         0,      9.0813,      0.9083
      48.9,      0.000,      0.000,         0,      9.1644,      0.9167
      49.1,      0.000,      0.000,         0,      9.2476,      0.9250
      49.3,      0.000,      0.000,         0,      9.3312,      0.9333
      49.5,      0.000,      0.000,         0,      9.4146,      0.9417
      49.7,      0.000,      0.000,         0,      9.4978,      0.9500
      49.9,      0.000,      0.000,         0,      9.5810,      0.9583
      50.1,      0.000,      0.000,         0,      9.6645,      0.9667
      50.3,      0.000,      0.000,         0,      9.7477,      0.9750
      50.5,      0.000,      0.000,         0,      9.8311,      0.9833
      50.6,      0.000,      0.000,         0,      9.9143,      0.9917
      50.8,      0.000,      0.000,         0,      9.9978,      1.0000
      51.0,      0.000,      0.000,         0,     10.0810,      1.0083
      51.2,      0.000,      0.000,         0,     10.1643,      1.0167
      51.3,      0.000,      0.000,         0,     10.2478,      1.0250
      51.5,      0.000,      0.000,         0,     10.3309,      1.0333
      51.7,      0.000,      0.000,         0,     10.4143,      1.0417
      51.8,      0.000,      0.000,         0,     10.4977,      1.0500
      52.0,      0.000,      0.000,         0,     10.5811,      1.0583
      52.1,      0.000,      0.000,         0,     10.6643,      1.0667
      52.3,      0.000,      0.000,         0,     10.7478,      1.0750
      52.4,      0.000,      0.000,         0,     10.8310,      1.0833
      52.5,      0.000,      0.000,         0,     10.9143,      1.0917
      52.7,      0.000,      0.000,         0,     10.9976,      1.1000
      52.8,      0.000,      0.000,         0,     11.0810,      1.1083
      52.9,      0.000,      0.000,         0,     11.1644,      1.1167
      53.0,      0.000,      0.000,         0,     11.2477,      1.1250
      53.1,      0.000,      0.000,         0,     11.3311,      1.1333
      53.2,      0.000,      0.000,         0,     11.4143,      1.1417
      53.3,      0.000,      0.000,         0,     11.4977,      1.1500
      53.4,      0.000,      0.000,         0,     11.5810,      1.1583
      53.5,      0.000,      0.000,         0,     11.6645,      1.1667
      53.6,      0.000,      0.000,         0,     11.7476,      1.1750
      53.6,      0.000,      0.000,         0,     11.8306,      1.1833
      53.7,      0.000,      0.000,         0,     11.9143,      1.1917
      53.8,      0.000,      0.000,         0,     11.9977,      1.2000
      53.8,      0.000,      0.000,         0,     12.0806,      1.2083
      53.9,      0.000,      0.000,         0,     12.1644,      1.2167
      53.9,      0.000,      0.000,         0,     12.2477,      1.2250
      53.9,      0.000,      0.000,         0,     12.3311,      1.2333
      54.0,      0.000,      0.000,         0,     12.4144,      1.2417
      54.0,      0.000,      0.000,         0,     12.4976,      1.2500
      54.0,      0.000,      0.000,         0,     12.5809,      1.2583
      54.0,      0.000,      0.000,         0,     12.6645,      1.2667
      54.0,      0.000,      0.000,         0,     12.7476,      1.2750
      53.9,      0.000,      0.000,         0,     12.8309,      1.2833
      53.9,      0.000,      0.000,         0,     12.9144,      1.2917
      53.8,      0.000,      0.000,         0,     12.9976,      1.3000
      53.6,      0.000,      0.000,         0,     13.0810,      1.3083
      53.5,      0.000,      0.000,         0,     13.1640,      1.3167
      53.2,      0.000,      0.000,         0,     13.2474,      1.3250
      52.8,      0.000,      0.000,         0,     13.3309,      1.3333
      52.2,      0.000,      0.000,         0,     13.4143,      1.3417
      51.2,      0.000,      0.000,         0,     13.4973,      1.3500
      49.2,      0.000,      0.000,         0,     13.5809,      1.3583
       0.0,      0.000,      0.000,         0,     13.6643,      1.3667
       0.0,      0.000,      0.000,         0,     13.7476,      1.3750
       0.0,      0.000,      0.000,         0,     13.8308,      1.3833
       0.0,      0.000,      0.000,         0,     13.9141,      1.3917
       0.0,      0.000,      0.000,         0,     13.9977,      1.4000